{"run_id":"29526913bab7446286864a321c124486","channel":"market","event_type":"price_change","market":"0x8032d8355d335c6ccbfc2508d99fbc87eb13f437bd275c93ee56fd1558e517ff","asset_id":null,"source":"market_ws:sub:active:1","t_event_ms":1770839722756,"t_recv_wall_ms":1770839722665,"t_recv_wall_iso":"2026-02-11T19:55:22.665Z","t_recv_mono_ns":618588006080375,"raw":{"market":"0x8032d8355d335c6ccbfc2508d99fbc87eb13f437bd275c93ee56fd1558e517ff","price_changes":[{"asset_id":"40652734036737240317526188612064032143639112324786051284480877037991580442979","price":"0.96","size":"3810.95","side":"BUY","hash":"8aa0ec9e333740146b6eeebf919c334c12c612e9","best_bid":"0.96","best_ask":"0.97"},{"asset_id":"20773614133833886322101538939702011175545796528197617633926164254913649353392","price":"0.04","size":"3810.95","side":"SELL","hash":"3c3b42e2364e7604419f8b135809810363b3d5fc","best_bid":"0.03","best_ask":"0.04"}],"timestamp":"1770839722756","event_type":"price_change","_sub_state":"active","_subscription_id":1,"_active_subscription_id":1},"parse_warnings":[],"out_of_order":false}
{"run_id":"29526913bab7446286864a321c124486","channel":"market","event_type":"price_change","market":"0x8032d8355d335c6ccbfc2508d99fbc87eb13f437bd275c93ee56fd1558e517ff","asset_id":null,"source":"market_ws:sub:active:1","t_event_ms":1770839722759,"t_recv_wall_ms":1770839722671,"t_recv_wall_iso":"2026-02-11T19:55:22.671Z","t_recv_mono_ns":618588011801708,"raw":{"market":"0x8032d8355d335c6ccbfc2508d99fbc87eb13f437bd275c93ee56fd1558e517ff","price_changes":[{"asset_id":"40652734036737240317526188612064032143639112324786051284480877037991580442979","price":"0.95","size":"3229.45","side":"BUY","hash":"fde0ac58f297a37249d21523a306421155ddd089","best_bid":"0.96","best_ask":"0.97"},{"asset_id":"20773614133833886322101538939702011175545796528197617633926164254913649353392","price":"0.05","size":"3229.45","side":"SELL","hash":"fbe8f9c2e734c6a76193ecda434c76ad32736ba7","best_bid":"0.03","best_ask":"0.04"}],"timestamp":"1770839722759","event_type":"price_change","_sub_state":"active","_subscription_id":1,"_active_subscription_id":1},"parse_warnings":[],"out_of_order":false}
{"run_id":"29526913bab7446286864a321c124486","channel":"market","event_type":"price_change","market":"0x8032d8355d335c6ccbfc2508d99fbc87eb13f437bd275c93ee56fd1558e517ff","asset_id":null,"source":"market_ws:sub:active:1","t_event_ms":1770839722761,"t_recv_wall_ms":1770839722671,"t_recv_wall_iso":"2026-02-11T19:55:22.671Z","t_recv_mono_ns":618588011895333,"raw":{"market":"0x8032d8355d335c6ccbfc2508d99fbc87eb13f437bd275c93ee56fd1558e517ff","price_changes":[{"asset_id":"40652734036737240317526188612064032143639112324786051284480877037991580442979","price":"0.93","size":"3360.43","side":"BUY","hash":"5daf5e7c331e5041f78fa9f916f1e2f43678bd1d","best_bid":"0.96","best_ask":"0.97"},{"asset_id":"20773614133833886322101538939702011175545796528197617633926164254913649353392","price":"0.07","size":"3360.43","side":"SELL","hash":"3dcb4111762935908ca47a3ec32fbf61af99a66f","best_bid":"0.03","best_ask":"0.04"}],"timestamp":"1770839722761","event_type":"price_change","_sub_state":"active","_subscription_id":1,"_active_subscription_id":1},"parse_warnings":[],"out_of_order":false}
{"run_id":"29526913bab7446286864a321c124486","channel":"market","event_type":"price_change","market":"0x8032d8355d335c6ccbfc2508d99fbc87eb13f437bd275c93ee56fd1558e517ff","asset_id":null,"source":"market_ws:sub:active:1","t_event_ms":1770839722762,"t_recv_wall_ms":1770839722671,"t_recv_wall_iso":"2026-02-11T19:55:22.671Z","t_recv_mono_ns":618588011958708,"raw":{"market":"0x8032d8355d335c6ccbfc2508d99fbc87eb13f437bd275c93ee56fd1558e517ff","price_changes":[{"asset_id":"40652734036737240317526188612064032143639112324786051284480877037991580442979","price":"0.96","size":"3750.95","side":"BUY","hash":"745eb21015566d2988d29ac0e73a6a0c88aa765b","best_bid":"0.96","best_ask":"0.97"},{"asset_id":"20773614133833886322101538939702011175545796528197617633926164254913649353392","price":"0.04","size":"3750.95","side":"SELL","hash":"c900be3dd6fd63e2c16ac8d9aa999b59a1386b29","best_bid":"0.03","best_ask":"0.04"}],"timestamp":"1770839722762","event_type":"price_change","_sub_state":"active","_subscription_id":1,"_active_subscription_id":1},"parse_warnings":[],"out_of_order":false}
{"run_id":"29526913bab7446286864a321c124486","channel":"market","event_type":"price_change","market":"0x8032d8355d335c6ccbfc2508d99fbc87eb13f437bd275c93ee56fd1558e517ff","asset_id":null,"source":"market_ws:sub:active:1","t_event_ms":1770839722764,"t_recv_wall_ms":1770839722671,"t_recv_wall_iso":"2026-02-11T19:55:22.671Z","t_recv_mono_ns":618588012012041,"raw":{"market":"0x8032d8355d335c6ccbfc2508d99fbc87eb13f437bd275c93ee56fd1558e517ff","price_changes":[{"asset_id":"40652734036737240317526188612064032143639112324786051284480877037991580442979","price":"0.96","size":"3810.95","side":"BUY","hash":"611dea648ad902d078a8f45b3d42d8bed0455206","best_bid":"0.96","best_ask":"0.97"},{"asset_id":"20773614133833886322101538939702011175545796528197617633926164254913649353392","price":"0.04","size":"3810.95","side":"SELL","hash":"78d4974987d5b0dc2ab5099cc1d5b223b5151a00","best_bid":"0.03","best_ask":"0.04"}],"timestamp":"1770839722764","event_type":"price_change","_sub_state":"active","_subscription_id":1,"_active_subscription_id":1},"parse_warnings":[],"out_of_order":false}
{"run_id":"29526913bab7446286864a321c124486","channel":"market","event_type":"price_change","market":"0x8032d8355d335c6ccbfc2508d99fbc87eb13f437bd275c93ee56fd1558e517ff","asset_id":null,"source":"market_ws:sub:active:1","t_event_ms":1770839722766,"t_recv_wall_ms":1770839722671,"t_recv_wall_iso":"2026-02-11T19:55:22.671Z","t_recv_mono_ns":618588012062875,"raw":{"market":"0x8032d8355d335c6ccbfc2508d99fbc87eb13f437bd275c93ee56fd1558e517ff","price_changes":[{"asset_id":"20773614133833886322101538939702011175545796528197617633926164254913649353392","price":"0.01","size":"30829.91","side":"BUY","hash":"751ebe229fd9d867f867811e75862097685b68ec","best_bid":"0.03","best_ask":"0.04"},{"asset_id":"40652734036737240317526188612064032143639112324786051284480877037991580442979","price":"0.99","size":"30829.91","side":"SELL","hash":"03f5b40156fac3afb7b9fe1684b438721020cf31","best_bid":"0.96","best_ask":"0.97"}],"timestamp":"1770839722766","event_type":"price_change","_sub_state":"active","_subscription_id":1,"_active_subscription_id":1},"parse_warnings":[],"out_of_order":false}
{"run_id":"29526913bab7446286864a321c124486","channel":"market","event_type":"price_change","market":"0x8032d8355d335c6ccbfc2508d99fbc87eb13f437bd275c93ee56fd1558e517ff","asset_id":null,"source":"market_ws:sub:active:1","t_event_ms":1770839722790,"t_recv_wall_ms":1770839722701,"t_recv_wall_iso":"2026-02-11T19:55:22.701Z","t_recv_mono_ns":618588041873083,"raw":{"market":"0x8032d8355d335c6ccbfc2508d99fbc87eb13f437bd275c93ee56fd1558e517ff","price_changes":[{"asset_id":"40652734036737240317526188612064032143639112324786051284480877037991580442979","price":"0.93","size":"3340.43","side":"BUY","hash":"2b1992067e82f857c6879cf580540663e70920bf","best_bid":"0.96","best_ask":"0.97"},{"asset_id":"20773614133833886322101538939702011175545796528197617633926164254913649353392","price":"0.07","size":"3340.43","side":"SELL","hash":"580727769fe3c2a3e502246d9873aacb814b0599","best_bid":"0.03","best_ask":"0.04"}],"timestamp":"1770839722790","event_type":"price_change","_sub_state":"active","_subscription_id":1,"_active_subscription_id":1},"parse_warnings":[],"out_of_order":false}
{"run_id":"29526913bab7446286864a321c124486","channel":"market","event_type":"price_change","market":"0x8032d8355d335c6ccbfc2508d99fbc87eb13f437bd275c93ee56fd1558e517ff","asset_id":null,"source":"market_ws:sub:active:1","t_event_ms":1770839722794,"t_recv_wall_ms":1770839722701,"t_recv_wall_iso":"2026-02-11T19:55:22.701Z","t_recv_mono_ns":618588041960625,"raw":{"market":"0x8032d8355d335c6ccbfc2508d99fbc87eb13f437bd275c93ee56fd1558e517ff","price_changes":[{"asset_id":"40652734036737240317526188612064032143639112324786051284480877037991580442979","price":"0.96","size":"3750.95","side":"BUY","hash":"1fc0cad693ca6ca5a3de89cc88036d5759acbbf7","best_bid":"0.96","best_ask":"0.97"},{"asset_id":"20773614133833886322101538939702011175545796528197617633926164254913649353392","price":"0.04","size":"3750.95","side":"SELL","hash":"e57f972f68de80f0184ce192e03dc51d2282a933","best_bid":"0.03","best_ask":"0.04"}],"timestamp":"1770839722794","event_type":"price_change","_sub_state":"active","_subscription_id":1,"_active_subscription_id":1},"parse_warnings":[],"out_of_order":false}
{"run_id":"29526913bab7446286864a321c124486","channel":"market","event_type":"price_change","market":"0x8032d8355d335c6ccbfc2508d99fbc87eb13f437bd275c93ee56fd1558e517ff","asset_id":null,"source":"market_ws:sub:active:1","t_event_ms":1770839722798,"t_recv_wall_ms":1770839722704,"t_recv_wall_iso":"2026-02-11T19:55:22.704Z","t_recv_mono_ns":618588045050875,"raw":{"market":"0x8032d8355d335c6ccbfc2508d99fbc87eb13f437bd275c93ee56fd1558e517ff","price_changes":[{"asset_id":"40652734036737240317526188612064032143639112324786051284480877037991580442979","price":"0.96","size":"3810.95","side":"BUY","hash":"e1fa81ffa17424fc70aaea584df5c49f3463ebe5","best_bid":"0.96","best_ask":"0.97"},{"asset_id":"20773614133833886322101538939702011175545796528197617633926164254913649353392","price":"0.04","size":"3810.95","side":"SELL","hash":"b319dc749d06b1fa87f02b52379ecc44762fa5bc","best_bid":"0.03","best_ask":"0.04"}],"timestamp":"1770839722798","event_type":"price_change","_sub_state":"active","_subscription_id":1,"_active_subscription_id":1},"parse_warnings":[],"out_of_order":false}
{"run_id":"29526913bab7446286864a321c124486","channel":"market","event_type":"price_change","market":"0x8032d8355d335c6ccbfc2508d99fbc87eb13f437bd275c93ee56fd1558e517ff","asset_id":null,"source":"market_ws:sub:active:1","t_event_ms":1770839722830,"t_recv_wall_ms":1770839722738,"t_recv_wall_iso":"2026-02-11T19:55:22.738Z","t_recv_mono_ns":618588079627375,"raw":{"market":"0x8032d8355d335c6ccbfc2508d99fbc87eb13f437bd275c93ee56fd1558e517ff","price_changes":[{"asset_id":"20773614133833886322101538939702011175545796528197617633926164254913649353392","price":"0.02","size":"8642.23","side":"BUY","hash":"12c17c55fc1df3516ae4ac3b13d4e9c057e96d24","best_bid":"0.03","best_ask":"0.04"},{"asset_id":"40652734036737240317526188612064032143639112324786051284480877037991580442979","price":"0.98","size":"8642.23","side":"SELL","hash":"69bfee3bcd861ef04ca9ba41d9afe2ac36d08a39","best_bid":"0.96","best_ask":"0.97"}],"timestamp":"1770839722830","event_type":"price_change","_sub_state":"active","_subscription_id":1,"_active_subscription_id":1},"parse_warnings":[],"out_of_order":false}
{"run_id":"29526913bab7446286864a321c124486","channel":"market","event_type":"price_change","market":"0x8032d8355d335c6ccbfc2508d99fbc87eb13f437bd275c93ee56fd1558e517ff","asset_id":null,"source":"market_ws:sub:active:1","t_event_ms":1770839722831,"t_recv_wall_ms":1770839722739,"t_recv_wall_iso":"2026-02-11T19:55:22.739Z","t_recv_mono_ns":618588079858208,"raw":{"market":"0x8032d8355d335c6ccbfc2508d99fbc87eb13f437bd275c93ee56fd1558e517ff","price_changes":[{"asset_id":"40652734036737240317526188612064032143639112324786051284480877037991580442979","price":"0.95","size":"3295.45","side":"BUY","hash":"e4338734a370bb9dcba84ddfd126d6bf000a6c9b","best_bid":"0.96","best_ask":"0.97"},{"asset_id":"20773614133833886322101538939702011175545796528197617633926164254913649353392","price":"0.05","size":"3295.45","side":"SELL","hash":"ed726c8cf6c6beb6c23b321672d25a4840b05783","best_bid":"0.03","best_ask":"0.04"}],"timestamp":"1770839722831","event_type":"price_change","_sub_state":"active","_subscription_id":1,"_active_subscription_id":1},"parse_warnings":[],"out_of_order":false}
{"run_id":"29526913bab7446286864a321c124486","channel":"market","event_type":"price_change","market":"0x8032d8355d335c6ccbfc2508d99fbc87eb13f437bd275c93ee56fd1558e517ff","asset_id":null,"source":"market_ws:sub:active:1","t_event_ms":1770839722833,"t_recv_wall_ms":1770839722739,"t_recv_wall_iso":"2026-02-11T19:55:22.739Z","t_recv_mono_ns":618588079958791,"raw":{"market":"0x8032d8355d335c6ccbfc2508d99fbc87eb13f437bd275c93ee56fd1558e517ff","price_changes":[{"asset_id":"20773614133833886322101538939702011175545796528197617633926164254913649353392","price":"0.01","size":"30889.91","side":"BUY","hash":"3e6a60473be7bdf0f2b4da37a23026edd8792d3e","best_bid":"0.03","best_ask":"0.04"},{"asset_id":"40652734036737240317526188612064032143639112324786051284480877037991580442979","price":"0.99","size":"30889.91","side":"SELL","hash":"eeac3461da0e599ed8bdf032c65d157212897c20","best_bid":"0.96","best_ask":"0.97"}],"timestamp":"1770839722833","event_type":"price_change","_sub_state":"active","_subscription_id":1,"_active_subscription_id":1},"parse_warnings":[],"out_of_order":false}
{"run_id":"29526913bab7446286864a321c124486","channel":"market","event_type":"price_change","market":"0x8032d8355d335c6ccbfc2508d99fbc87eb13f437bd275c93ee56fd1558e517ff","asset_id":null,"source":"market_ws:sub:active:1","t_event_ms":1770839722833,"t_recv_wall_ms":1770839722739,"t_recv_wall_iso":"2026-02-11T19:55:22.739Z","t_recv_mono_ns":618588080035500,"raw":{"market":"0x8032d8355d335c6ccbfc2508d99fbc87eb13f437bd275c93ee56fd1558e517ff","price_changes":[{"asset_id":"40652734036737240317526188612064032143639112324786051284480877037991580442979","price":"0.94","size":"3250.34","side":"BUY","hash":"e5b7b628ddb891d42022519de22b9e0c412ccb1e","best_bid":"0.96","best_ask":"0.97"},{"asset_id":"20773614133833886322101538939702011175545796528197617633926164254913649353392","price":"0.06","size":"3250.34","side":"SELL","hash":"ca27979f9896517814df0901c612bdf418ca1b38","best_bid":"0.03","best_ask":"0.04"}],"timestamp":"1770839722833","event_type":"price_change","_sub_state":"active","_subscription_id":1,"_active_subscription_id":1},"parse_warnings":[],"out_of_order":false}
{"run_id":"29526913bab7446286864a321c124486","channel":"market","event_type":"price_change","market":"0x8032d8355d335c6ccbfc2508d99fbc87eb13f437bd275c93ee56fd1558e517ff","asset_id":null,"source":"market_ws:sub:active:1","t_event_ms":1770839722835,"t_recv_wall_ms":1770839722743,"t_recv_wall_iso":"2026-02-11T19:55:22.743Z","t_recv_mono_ns":618588083833583,"raw":{"market":"0x8032d8355d335c6ccbfc2508d99fbc87eb13f437bd275c93ee56fd1558e517ff","price_changes":[{"asset_id":"40652734036737240317526188612064032143639112324786051284480877037991580442979","price":"0.95","size":"3235.45","side":"BUY","hash":"6a4202d820aeb7f925c2ff66bd4b0dbd56dce94f","best_bid":"0.96","best_ask":"0.97"},{"asset_id":"20773614133833886322101538939702011175545796528197617633926164254913649353392","price":"0.05","size":"3235.45","side":"SELL","hash":"65529d7d36d3d245499806d2f0390e558886ee81","best_bid":"0.03","best_ask":"0.04"}],"timestamp":"1770839722835","event_type":"price_change","_sub_state":"active","_subscription_id":1,"_active_subscription_id":1},"parse_warnings":[],"out_of_order":false}
{"run_id":"29526913bab7446286864a321c124486","channel":"market","event_type":"price_change","market":"0x8032d8355d335c6ccbfc2508d99fbc87eb13f437bd275c93ee56fd1558e517ff","asset_id":null,"source":"market_ws:sub:active:1","t_event_ms":1770839722837,"t_recv_wall_ms":1770839722743,"t_recv_wall_iso":"2026-02-11T19:55:22.743Z","t_recv_mono_ns":618588083917166,"raw":{"market":"0x8032d8355d335c6ccbfc2508d99fbc87eb13f437bd275c93ee56fd1558e517ff","price_changes":[{"asset_id":"20773614133833886322101538939702011175545796528197617633926164254913649353392","price":"0.02","size":"8708.23","side":"BUY","hash":"93bf877e783dff13f719ba191608bb261765c696","best_bid":"0.03","best_ask":"0.04"},{"asset_id":"40652734036737240317526188612064032143639112324786051284480877037991580442979","price":"0.98","size":"8708.23","side":"SELL","hash":"045af2b2a16d956272cabeefaaefee4c6563cd3e","best_bid":"0.96","best_ask":"0.97"}],"timestamp":"1770839722837","event_type":"price_change","_sub_state":"active","_subscription_id":1,"_active_subscription_id":1},"parse_warnings":[],"out_of_order":false}
{"run_id":"29526913bab7446286864a321c124486","channel":"market","event_type":"price_change","market":"0x8032d8355d335c6ccbfc2508d99fbc87eb13f437bd275c93ee56fd1558e517ff","asset_id":null,"source":"market_ws:sub:active:1","t_event_ms":1770839722837,"t_recv_wall_ms":1770839722751,"t_recv_wall_iso":"2026-02-11T19:55:22.751Z","t_recv_mono_ns":618588092584958,"raw":{"market":"0x8032d8355d335c6ccbfc2508d99fbc87eb13f437bd275c93ee56fd1558e517ff","price_changes":[{"asset_id":"40652734036737240317526188612064032143639112324786051284480877037991580442979","price":"0.95","size":"3169.45","side":"BUY","hash":"dc711e213a9d3e13840e3b9aa5d0e610b969c60b","best_bid":"0.96","best_ask":"0.97"},{"asset_id":"20773614133833886322101538939702011175545796528197617633926164254913649353392","price":"0.05","size":"3169.45","side":"SELL","hash":"ccd8b6949673673c125a16ec9f0fbfe738b8e21e","best_bid":"0.03","best_ask":"0.04"}],"timestamp":"1770839722837","event_type":"price_change","_sub_state":"active","_subscription_id":1,"_active_subscription_id":1},"parse_warnings":[],"out_of_order":false}
{"run_id":"29526913bab7446286864a321c124486","channel":"market","event_type":"price_change","market":"0x8032d8355d335c6ccbfc2508d99fbc87eb13f437bd275c93ee56fd1558e517ff","asset_id":null,"source":"market_ws:sub:active:1","t_event_ms":1770839722839,"t_recv_wall_ms":1770839722752,"t_recv_wall_iso":"2026-02-11T19:55:22.752Z","t_recv_mono_ns":618588092770833,"raw":{"market":"0x8032d8355d335c6ccbfc2508d99fbc87eb13f437bd275c93ee56fd1558e517ff","price_changes":[{"asset_id":"40652734036737240317526188612064032143639112324786051284480877037991580442979","price":"0.95","size":"3109.45","side":"BUY","hash":"2e4062559fc41a3f4c956dd872ab02be76650ff0","best_bid":"0.96","best_ask":"0.97"},{"asset_id":"20773614133833886322101538939702011175545796528197617633926164254913649353392","price":"0.05","size":"3109.45","side":"SELL","hash":"6b7ab43914f28a8e0cf08cbeaf3f89d9ecd0ae3b","best_bid":"0.03","best_ask":"0.04"}],"timestamp":"1770839722839","event_type":"price_change","_sub_state":"active","_subscription_id":1,"_active_subscription_id":1},"parse_warnings":[],"out_of_order":false}
{"run_id":"29526913bab7446286864a321c124486","channel":"market","event_type":"price_change","market":"0x8032d8355d335c6ccbfc2508d99fbc87eb13f437bd275c93ee56fd1558e517ff","asset_id":null,"source":"market_ws:sub:active:1","t_event_ms":1770839722840,"t_recv_wall_ms":1770839722752,"t_recv_wall_iso":"2026-02-11T19:55:22.752Z","t_recv_mono_ns":618588092876791,"raw":{"market":"0x8032d8355d335c6ccbfc2508d99fbc87eb13f437bd275c93ee56fd1558e517ff","price_changes":[{"asset_id":"40652734036737240317526188612064032143639112324786051284480877037991580442979","price":"0.96","size":"3870.95","side":"BUY","hash":"7f4f07cbb6c22d9065425189d4aa2de4a129b7d5","best_bid":"0.96","best_ask":"0.97"},{"asset_id":"20773614133833886322101538939702011175545796528197617633926164254913649353392","price":"0.04","size":"3870.95","side":"SELL","hash":"439a1c3acf8a06366a5ef3e09f7cbe1eb5b74c11","best_bid":"0.03","best_ask":"0.04"}],"timestamp":"1770839722840","event_type":"price_change","_sub_state":"active","_subscription_id":1,"_active_subscription_id":1},"parse_warnings":[],"out_of_order":false}
{"run_id":"29526913bab7446286864a321c124486","channel":"market","event_type":"price_change","market":"0x8032d8355d335c6ccbfc2508d99fbc87eb13f437bd275c93ee56fd1558e517ff","asset_id":null,"source":"market_ws:sub:active:1","t_event_ms":1770839722842,"t_recv_wall_ms":1770839722752,"t_recv_wall_iso":"2026-02-11T19:55:22.752Z","t_recv_mono_ns":618588092976541,"raw":{"market":"0x8032d8355d335c6ccbfc2508d99fbc87eb13f437bd275c93ee56fd1558e517ff","price_changes":[{"asset_id":"20773614133833886322101538939702011175545796528197617633926164254913649353392","price":"0.03","size":"137.36","side":"BUY","hash":"328907102ac2a3ca4b12018f1b0e1a8b69e81197","best_bid":"0.03","best_ask":"0.04"},{"asset_id":"40652734036737240317526188612064032143639112324786051284480877037991580442979","price":"0.97","size":"137.36","side":"SELL","hash":"29554d117762cbb4d356d85b345b1eb9181bffec","best_bid":"0.96","best_ask":"0.97"}],"timestamp":"1770839722842","event_type":"price_change","_sub_state":"active","_subscription_id":1,"_active_subscription_id":1},"parse_warnings":[],"out_of_order":false}
{"run_id":"29526913bab7446286864a321c124486","channel":"market","event_type":"price_change","market":"0x8032d8355d335c6ccbfc2508d99fbc87eb13f437bd275c93ee56fd1558e517ff","asset_id":null,"source":"market_ws:sub:active:1","t_event_ms":1770839722842,"t_recv_wall_ms":1770839722752,"t_recv_wall_iso":"2026-02-11T19:55:22.752Z","t_recv_mono_ns":618588093060541,"raw":{"market":"0x8032d8355d335c6ccbfc2508d99fbc87eb13f437bd275c93ee56fd1558e517ff","price_changes":[{"asset_id":"40652734036737240317526188612064032143639112324786051284480877037991580442979","price":"0.96","size":"3930.95","side":"BUY","hash":"e9f44c7f2c3e79faf14a8db33996a3ee36201e2f","best_bid":"0.96","best_ask":"0.97"},{"asset_id":"20773614133833886322101538939702011175545796528197617633926164254913649353392","price":"0.04","size":"3930.95","side":"SELL","hash":"647df47d783f0a999facfa376c882fdf75c2a531","best_bid":"0.03","best_ask":"0.04"}],"timestamp":"1770839722842","event_type":"price_change","_sub_state":"active","_subscription_id":1,"_active_subscription_id":1},"parse_warnings":[],"out_of_order":false}
{"run_id":"29526913bab7446286864a321c124486","channel":"market","event_type":"price_change","market":"0x8032d8355d335c6ccbfc2508d99fbc87eb13f437bd275c93ee56fd1558e517ff","asset_id":null,"source":"market_ws:sub:active:1","t_event_ms":1770839722844,"t_recv_wall_ms":1770839722752,"t_recv_wall_iso":"2026-02-11T19:55:22.752Z","t_recv_mono_ns":618588093139916,"raw":{"market":"0x8032d8355d335c6ccbfc2508d99fbc87eb13f437bd275c93ee56fd1558e517ff","price_changes":[{"asset_id":"40652734036737240317526188612064032143639112324786051284480877037991580442979","price":"0.96","size":"3996.95","side":"BUY","hash":"6fb673dea8ec0cad79ee4327fc660e0eac3c56d9","best_bid":"0.96","best_ask":"0.97"},{"asset_id":"20773614133833886322101538939702011175545796528197617633926164254913649353392","price":"0.04","size":"3996.95","side":"SELL","hash":"bf07cf18ed48ba1ca5ae1914230bed7c238eb85b","best_bid":"0.03","best_ask":"0.04"}],"timestamp":"1770839722844","event_type":"price_change","_sub_state":"active","_subscription_id":1,"_active_subscription_id":1},"parse_warnings":[],"out_of_order":false}
{"run_id":"29526913bab7446286864a321c124486","channel":"market","event_type":"price_change","market":"0x8032d8355d335c6ccbfc2508d99fbc87eb13f437bd275c93ee56fd1558e517ff","asset_id":null,"source":"market_ws:sub:active:1","t_event_ms":1770839722849,"t_recv_wall_ms":1770839722764,"t_recv_wall_iso":"2026-02-11T19:55:22.764Z","t_recv_mono_ns":618588105291541,"raw":{"market":"0x8032d8355d335c6ccbfc2508d99fbc87eb13f437bd275c93ee56fd1558e517ff","price_changes":[{"asset_id":"40652734036737240317526188612064032143639112324786051284480877037991580442979","price":"0.83","size":"958.39","side":"BUY","hash":"dd05e3413af7b68fa9eacb197c0fd7d9d94fb1ca","best_bid":"0.96","best_ask":"0.97"},{"asset_id":"20773614133833886322101538939702011175545796528197617633926164254913649353392","price":"0.17","size":"958.39","side":"SELL","hash":"a02c33416f48138baefcd68d3640465fbb508395","best_bid":"0.03","best_ask":"0.04"}],"timestamp":"1770839722849","event_type":"price_change","_sub_state":"active","_subscription_id":1,"_active_subscription_id":1},"parse_warnings":[],"out_of_order":false}
{"run_id":"29526913bab7446286864a321c124486","channel":"market","event_type":"price_change","market":"0x8032d8355d335c6ccbfc2508d99fbc87eb13f437bd275c93ee56fd1558e517ff","asset_id":null,"source":"market_ws:sub:active:1","t_event_ms":1770839722855,"t_recv_wall_ms":1770839722764,"t_recv_wall_iso":"2026-02-11T19:55:22.764Z","t_recv_mono_ns":618588105476166,"raw":{"market":"0x8032d8355d335c6ccbfc2508d99fbc87eb13f437bd275c93ee56fd1558e517ff","price_changes":[{"asset_id":"40652734036737240317526188612064032143639112324786051284480877037991580442979","price":"0.96","size":"3936.95","side":"BUY","hash":"bb2233453edd6b86be4fc339e7a043ade8a77ddf","best_bid":"0.96","best_ask":"0.97"},{"asset_id":"20773614133833886322101538939702011175545796528197617633926164254913649353392","price":"0.04","size":"3936.95","side":"SELL","hash":"bb35650147d18dad874d4d2629029f2c67d1c6f3","best_bid":"0.03","best_ask":"0.04"}],"timestamp":"1770839722855","event_type":"price_change","_sub_state":"active","_subscription_id":1,"_active_subscription_id":1},"parse_warnings":[],"out_of_order":false}
{"run_id":"29526913bab7446286864a321c124486","channel":"market","event_type":"price_change","market":"0x8032d8355d335c6ccbfc2508d99fbc87eb13f437bd275c93ee56fd1558e517ff","asset_id":null,"source":"market_ws:sub:active:1","t_event_ms":1770839722861,"t_recv_wall_ms":1770839722768,"t_recv_wall_iso":"2026-02-11T19:55:22.768Z","t_recv_mono_ns":618588109454250,"raw":{"market":"0x8032d8355d335c6ccbfc2508d99fbc87eb13f437bd275c93ee56fd1558e517ff","price_changes":[{"asset_id":"40652734036737240317526188612064032143639112324786051284480877037991580442979","price":"0.96","size":"3996.95","side":"BUY","hash":"9da79e629fad20c2a7c5ae9eed4a9a5d4c5458a9","best_bid":"0.96","best_ask":"0.97"},{"asset_id":"20773614133833886322101538939702011175545796528197617633926164254913649353392","price":"0.04","size":"3996.95","side":"SELL","hash":"3ce8bfc4a5fb9447edb43fc46e8aabf7e5825564","best_bid":"0.03","best_ask":"0.04"}],"timestamp":"1770839722861","event_type":"price_change","_sub_state":"active","_subscription_id":1,"_active_subscription_id":1},"parse_warnings":[],"out_of_order":false}
{"run_id":"29526913bab7446286864a321c124486","channel":"market","event_type":"price_change","market":"0x8032d8355d335c6ccbfc2508d99fbc87eb13f437bd275c93ee56fd1558e517ff","asset_id":null,"source":"market_ws:sub:active:1","t_event_ms":1770839722880,"t_recv_wall_ms":1770839722785,"t_recv_wall_iso":"2026-02-11T19:55:22.785Z","t_recv_mono_ns":618588126612125,"raw":{"market":"0x8032d8355d335c6ccbfc2508d99fbc87eb13f437bd275c93ee56fd1558e517ff","price_changes":[{"asset_id":"40652734036737240317526188612064032143639112324786051284480877037991580442979","price":"0.96","size":"3981.95","side":"BUY","hash":"d28cb59c9e49e9dccbcce298bb2b11b332dd1199","best_bid":"0.96","best_ask":"0.97"},{"asset_id":"20773614133833886322101538939702011175545796528197617633926164254913649353392","price":"0.04","size":"3981.95","side":"SELL","hash":"62f1ce7d1fd8017c01aace9e3cfec93af1f6db78","best_bid":"0.03","best_ask":"0.04"}],"timestamp":"1770839722880","event_type":"price_change","_sub_state":"active","_subscription_id":1,"_active_subscription_id":1},"parse_warnings":[],"out_of_order":false}
{"run_id":"29526913bab7446286864a321c124486","channel":"market","event_type":"price_change","market":"0x8032d8355d335c6ccbfc2508d99fbc87eb13f437bd275c93ee56fd1558e517ff","asset_id":null,"source":"market_ws:sub:active:1","t_event_ms":1770839722915,"t_recv_wall_ms":1770839722820,"t_recv_wall_iso":"2026-02-11T19:55:22.820Z","t_recv_mono_ns":618588161341875,"raw":{"market":"0x8032d8355d335c6ccbfc2508d99fbc87eb13f437bd275c93ee56fd1558e517ff","price_changes":[{"asset_id":"40652734036737240317526188612064032143639112324786051284480877037991580442979","price":"0.94","size":"3245.34","side":"BUY","hash":"e4b222fce3b858be20ed52570971c2fef21fbdb1","best_bid":"0.96","best_ask":"0.97"},{"asset_id":"20773614133833886322101538939702011175545796528197617633926164254913649353392","price":"0.06","size":"3245.34","side":"SELL","hash":"639d84713bac987390f955de7f5ec3801fc70cc1","best_bid":"0.03","best_ask":"0.04"}],"timestamp":"1770839722915","event_type":"price_change","_sub_state":"active","_subscription_id":1,"_active_subscription_id":1},"parse_warnings":[],"out_of_order":false}
{"run_id":"29526913bab7446286864a321c124486","channel":"market","event_type":"price_change","market":"0x8032d8355d335c6ccbfc2508d99fbc87eb13f437bd275c93ee56fd1558e517ff","asset_id":null,"source":"market_ws:sub:active:1","t_event_ms":1770839722918,"t_recv_wall_ms":1770839722823,"t_recv_wall_iso":"2026-02-11T19:55:22.823Z","t_recv_mono_ns":618588164689708,"raw":{"market":"0x8032d8355d335c6ccbfc2508d99fbc87eb13f437bd275c93ee56fd1558e517ff","price_changes":[{"asset_id":"40652734036737240317526188612064032143639112324786051284480877037991580442979","price":"0.96","size":"3921.95","side":"BUY","hash":"6c7371afada3723670553d14929d7b7e99506eea","best_bid":"0.96","best_ask":"0.97"},{"asset_id":"20773614133833886322101538939702011175545796528197617633926164254913649353392","price":"0.04","size":"3921.95","side":"SELL","hash":"d24e208bffd246e16775d7149659fcb54840205b","best_bid":"0.03","best_ask":"0.04"}],"timestamp":"1770839722918","event_type":"price_change","_sub_state":"active","_subscription_id":1,"_active_subscription_id":1},"parse_warnings":[],"out_of_order":false}
{"run_id":"29526913bab7446286864a321c124486","channel":"market","event_type":"price_change","market":"0x8032d8355d335c6ccbfc2508d99fbc87eb13f437bd275c93ee56fd1558e517ff","asset_id":null,"source":"market_ws:sub:active:1","t_event_ms":1770839722925,"t_recv_wall_ms":1770839722833,"t_recv_wall_iso":"2026-02-11T19:55:22.833Z","t_recv_mono_ns":618588174613666,"raw":{"market":"0x8032d8355d335c6ccbfc2508d99fbc87eb13f437bd275c93ee56fd1558e517ff","price_changes":[{"asset_id":"40652734036737240317526188612064032143639112324786051284480877037991580442979","price":"0.91","size":"579.6","side":"BUY","hash":"48f6f245d8d04b748b37743660e27eb4c34cbc02","best_bid":"0.96","best_ask":"0.97"},{"asset_id":"20773614133833886322101538939702011175545796528197617633926164254913649353392","price":"0.09","size":"579.6","side":"SELL","hash":"e7c4990849ed295d8f559c0b657fa081eb2079d3","best_bid":"0.03","best_ask":"0.04"}],"timestamp":"1770839722925","event_type":"price_change","_sub_state":"active","_subscription_id":1,"_active_subscription_id":1},"parse_warnings":[],"out_of_order":false}
{"run_id":"29526913bab7446286864a321c124486","channel":"market","event_type":"price_change","market":"0x8032d8355d335c6ccbfc2508d99fbc87eb13f437bd275c93ee56fd1558e517ff","asset_id":null,"source":"market_ws:sub:active:1","t_event_ms":1770839722926,"t_recv_wall_ms":1770839722834,"t_recv_wall_iso":"2026-02-11T19:55:22.834Z","t_recv_mono_ns":618588175062166,"raw":{"market":"0x8032d8355d335c6ccbfc2508d99fbc87eb13f437bd275c93ee56fd1558e517ff","price_changes":[{"asset_id":"40652734036737240317526188612064032143639112324786051284480877037991580442979","price":"0.96","size":"3981.95","side":"BUY","hash":"d5873cdcd1f50200ccc2fb44fed62c6cf19ae50a","best_bid":"0.96","best_ask":"0.97"},{"asset_id":"20773614133833886322101538939702011175545796528197617633926164254913649353392","price":"0.04","size":"3981.95","side":"SELL","hash":"45b3af7d15adb53b63d6f3577316bee4d4b99c4b","best_bid":"0.03","best_ask":"0.04"}],"timestamp":"1770839722926","event_type":"price_change","_sub_state":"active","_subscription_id":1,"_active_subscription_id":1},"parse_warnings":[],"out_of_order":false}
{"run_id":"29526913bab7446286864a321c124486","channel":"market","event_type":"price_change","market":"0x8032d8355d335c6ccbfc2508d99fbc87eb13f437bd275c93ee56fd1558e517ff","asset_id":null,"source":"market_ws:sub:active:1","t_event_ms":1770839722937,"t_recv_wall_ms":1770839722843,"t_recv_wall_iso":"2026-02-11T19:55:22.843Z","t_recv_mono_ns":618588184044291,"raw":{"market":"0x8032d8355d335c6ccbfc2508d99fbc87eb13f437bd275c93ee56fd1558e517ff","price_changes":[{"asset_id":"40652734036737240317526188612064032143639112324786051284480877037991580442979","price":"0.96","size":"4011.95","side":"BUY","hash":"122443f7ebf0c9febd5951341066a47114b5598b","best_bid":"0.96","best_ask":"0.97"},{"asset_id":"20773614133833886322101538939702011175545796528197617633926164254913649353392","price":"0.04","size":"4011.95","side":"SELL","hash":"bf7f9747e0c7592583fc687e1aa1adff23fefa93","best_bid":"0.03","best_ask":"0.04"}],"timestamp":"1770839722937","event_type":"price_change","_sub_state":"active","_subscription_id":1,"_active_subscription_id":1},"parse_warnings":[],"out_of_order":false}
{"run_id":"29526913bab7446286864a321c124486","channel":"market","event_type":"price_change","market":"0x8032d8355d335c6ccbfc2508d99fbc87eb13f437bd275c93ee56fd1558e517ff","asset_id":null,"source":"market_ws:sub:active:1","t_event_ms":1770839722940,"t_recv_wall_ms":1770839722846,"t_recv_wall_iso":"2026-02-11T19:55:22.846Z","t_recv_mono_ns":618588186892750,"raw":{"market":"0x8032d8355d335c6ccbfc2508d99fbc87eb13f437bd275c93ee56fd1558e517ff","price_changes":[{"asset_id":"40652734036737240317526188612064032143639112324786051284480877037991580442979","price":"0.96","size":"4041.95","side":"BUY","hash":"1fc15b041ccfa3383931eb883c585e48c5f62e02","best_bid":"0.96","best_ask":"0.97"},{"asset_id":"20773614133833886322101538939702011175545796528197617633926164254913649353392","price":"0.04","size":"4041.95","side":"SELL","hash":"51de1390f69fac3677139f2029d8c40c08d351ef","best_bid":"0.03","best_ask":"0.04"}],"timestamp":"1770839722940","event_type":"price_change","_sub_state":"active","_subscription_id":1,"_active_subscription_id":1},"parse_warnings":[],"out_of_order":false}
{"run_id":"29526913bab7446286864a321c124486","channel":"market","event_type":"price_change","market":"0x8032d8355d335c6ccbfc2508d99fbc87eb13f437bd275c93ee56fd1558e517ff","asset_id":null,"source":"market_ws:sub:active:1","t_event_ms":1770839722944,"t_recv_wall_ms":1770839722854,"t_recv_wall_iso":"2026-02-11T19:55:22.854Z","t_recv_mono_ns":618588194763416,"raw":{"market":"0x8032d8355d335c6ccbfc2508d99fbc87eb13f437bd275c93ee56fd1558e517ff","price_changes":[{"asset_id":"40652734036737240317526188612064032143639112324786051284480877037991580442979","price":"0.88","size":"1060.55","side":"BUY","hash":"5b59017b5554683a0f483c9a8c2e396a43343967","best_bid":"0.96","best_ask":"0.97"},{"asset_id":"20773614133833886322101538939702011175545796528197617633926164254913649353392","price":"0.12","size":"1060.55","side":"SELL","hash":"6642f6e012e0ec9bbeef9f1b6d4bade586600e28","best_bid":"0.03","best_ask":"0.04"}],"timestamp":"1770839722944","event_type":"price_change","_sub_state":"active","_subscription_id":1,"_active_subscription_id":1},"parse_warnings":[],"out_of_order":false}
{"run_id":"29526913bab7446286864a321c124486","channel":"market","event_type":"price_change","market":"0x8032d8355d335c6ccbfc2508d99fbc87eb13f437bd275c93ee56fd1558e517ff","asset_id":null,"source":"market_ws:sub:active:1","t_event_ms":1770839722946,"t_recv_wall_ms":1770839722854,"t_recv_wall_iso":"2026-02-11T19:55:22.854Z","t_recv_mono_ns":618588195080666,"raw":{"market":"0x8032d8355d335c6ccbfc2508d99fbc87eb13f437bd275c93ee56fd1558e517ff","price_changes":[{"asset_id":"40652734036737240317526188612064032143639112324786051284480877037991580442979","price":"0.87","size":"1041.8","side":"BUY","hash":"a21332f113140ee7df6dd651079129543df5c301","best_bid":"0.96","best_ask":"0.97"},{"asset_id":"20773614133833886322101538939702011175545796528197617633926164254913649353392","price":"0.13","size":"1041.8","side":"SELL","hash":"db1757bd8b36272e2e8d43763525db0a2e41579b","best_bid":"0.03","best_ask":"0.04"}],"timestamp":"1770839722946","event_type":"price_change","_sub_state":"active","_subscription_id":1,"_active_subscription_id":1},"parse_warnings":[],"out_of_order":false}
{"run_id":"29526913bab7446286864a321c124486","channel":"market","event_type":"price_change","market":"0x8032d8355d335c6ccbfc2508d99fbc87eb13f437bd275c93ee56fd1558e517ff","asset_id":null,"source":"market_ws:sub:active:1","t_event_ms":1770839722948,"t_recv_wall_ms":1770839722854,"t_recv_wall_iso":"2026-02-11T19:55:22.854Z","t_recv_mono_ns":618588195491333,"raw":{"market":"0x8032d8355d335c6ccbfc2508d99fbc87eb13f437bd275c93ee56fd1558e517ff","price_changes":[{"asset_id":"40652734036737240317526188612064032143639112324786051284480877037991580442979","price":"0.96","size":"4071.95","side":"BUY","hash":"e1530d4a247b5637ebe6d5a31727b4ceb8d1db4a","best_bid":"0.96","best_ask":"0.97"},{"asset_id":"20773614133833886322101538939702011175545796528197617633926164254913649353392","price":"0.04","size":"4071.95","side":"SELL","hash":"40666498661727f25e6f2a7620cd3c681e3be975","best_bid":"0.03","best_ask":"0.04"}],"timestamp":"1770839722948","event_type":"price_change","_sub_state":"active","_subscription_id":1,"_active_subscription_id":1},"parse_warnings":[],"out_of_order":false}
{"run_id":"29526913bab7446286864a321c124486","channel":"market","event_type":"price_change","market":"0x8032d8355d335c6ccbfc2508d99fbc87eb13f437bd275c93ee56fd1558e517ff","asset_id":null,"source":"market_ws:sub:active:1","t_event_ms":1770839722952,"t_recv_wall_ms":1770839722858,"t_recv_wall_iso":"2026-02-11T19:55:22.858Z","t_recv_mono_ns":618588199703833,"raw":{"market":"0x8032d8355d335c6ccbfc2508d99fbc87eb13f437bd275c93ee56fd1558e517ff","price_changes":[{"asset_id":"40652734036737240317526188612064032143639112324786051284480877037991580442979","price":"0.83","size":"963.39","side":"BUY","hash":"adda7105b79c3a4a96f1acaa781c5036bffd98d1","best_bid":"0.96","best_ask":"0.97"},{"asset_id":"20773614133833886322101538939702011175545796528197617633926164254913649353392","price":"0.17","size":"963.39","side":"SELL","hash":"f9443dd3d431d929a0ecac49196362b188a5b6ec","best_bid":"0.03","best_ask":"0.04"}],"timestamp":"1770839722952","event_type":"price_change","_sub_state":"active","_subscription_id":1,"_active_subscription_id":1},"parse_warnings":[],"out_of_order":false}
{"run_id":"29526913bab7446286864a321c124486","channel":"market","event_type":"price_change","market":"0x8032d8355d335c6ccbfc2508d99fbc87eb13f437bd275c93ee56fd1558e517ff","asset_id":null,"source":"market_ws:sub:active:1","t_event_ms":1770839722962,"t_recv_wall_ms":1770839722887,"t_recv_wall_iso":"2026-02-11T19:55:22.887Z","t_recv_mono_ns":618588228313166,"raw":{"market":"0x8032d8355d335c6ccbfc2508d99fbc87eb13f437bd275c93ee56fd1558e517ff","price_changes":[{"asset_id":"40652734036737240317526188612064032143639112324786051284480877037991580442979","price":"0.96","size":"4011.95","side":"BUY","hash":"8a73ef96c0381ed66234ae53516044ec6a673d08","best_bid":"0.96","best_ask":"0.97"},{"asset_id":"20773614133833886322101538939702011175545796528197617633926164254913649353392","price":"0.04","size":"4011.95","side":"SELL","hash":"460ec385fc815434f22d71458daecf1f48eac973","best_bid":"0.03","best_ask":"0.04"}],"timestamp":"1770839722962","event_type":"price_change","_sub_state":"active","_subscription_id":1,"_active_subscription_id":1},"parse_warnings":[],"out_of_order":false}
{"run_id":"29526913bab7446286864a321c124486","channel":"market","event_type":"price_change","market":"0x8032d8355d335c6ccbfc2508d99fbc87eb13f437bd275c93ee56fd1558e517ff","asset_id":null,"source":"market_ws:sub:active:1","t_event_ms":1770839722964,"t_recv_wall_ms":1770839722887,"t_recv_wall_iso":"2026-02-11T19:55:22.887Z","t_recv_mono_ns":618588228726625,"raw":{"market":"0x8032d8355d335c6ccbfc2508d99fbc87eb13f437bd275c93ee56fd1558e517ff","price_changes":[{"asset_id":"40652734036737240317526188612064032143639112324786051284480877037991580442979","price":"0.96","size":"4071.95","side":"BUY","hash":"85c7ec268c6b006b8e45a80e8bb2daadf690d5ce","best_bid":"0.96","best_ask":"0.97"},{"asset_id":"20773614133833886322101538939702011175545796528197617633926164254913649353392","price":"0.04","size":"4071.95","side":"SELL","hash":"462bd6de07553a2b7a483aa611ccfa9873d78d71","best_bid":"0.03","best_ask":"0.04"}],"timestamp":"1770839722964","event_type":"price_change","_sub_state":"active","_subscription_id":1,"_active_subscription_id":1},"parse_warnings":[],"out_of_order":false}
{"run_id":"29526913bab7446286864a321c124486","channel":"market","event_type":"price_change","market":"0x8032d8355d335c6ccbfc2508d99fbc87eb13f437bd275c93ee56fd1558e517ff","asset_id":null,"source":"market_ws:sub:active:1","t_event_ms":1770839722966,"t_recv_wall_ms":1770839722888,"t_recv_wall_iso":"2026-02-11T19:55:22.888Z","t_recv_mono_ns":618588228874041,"raw":{"market":"0x8032d8355d335c6ccbfc2508d99fbc87eb13f437bd275c93ee56fd1558e517ff","price_changes":[{"asset_id":"40652734036737240317526188612064032143639112324786051284480877037991580442979","price":"0.92","size":"3419.35","side":"BUY","hash":"19c425628eff4d7cdfe2d63a5e43099cebfae070","best_bid":"0.96","best_ask":"0.97"},{"asset_id":"20773614133833886322101538939702011175545796528197617633926164254913649353392","price":"0.08","size":"3419.35","side":"SELL","hash":"adb0c1933d4cfe6552a383ac7538395ad30acea4","best_bid":"0.03","best_ask":"0.04"}],"timestamp":"1770839722966","event_type":"price_change","_sub_state":"active","_subscription_id":1,"_active_subscription_id":1},"parse_warnings":[],"out_of_order":false}
{"run_id":"29526913bab7446286864a321c124486","channel":"market","event_type":"price_change","market":"0x8032d8355d335c6ccbfc2508d99fbc87eb13f437bd275c93ee56fd1558e517ff","asset_id":null,"source":"market_ws:sub:active:1","t_event_ms":1770839722968,"t_recv_wall_ms":1770839722888,"t_recv_wall_iso":"2026-02-11T19:55:22.888Z","t_recv_mono_ns":618588228995541,"raw":{"market":"0x8032d8355d335c6ccbfc2508d99fbc87eb13f437bd275c93ee56fd1558e517ff","price_changes":[{"asset_id":"40652734036737240317526188612064032143639112324786051284480877037991580442979","price":"0.94","size":"3250.34","side":"BUY","hash":"5554bbaa0ee0c32b0f08f056a0d7da7d32fcb819","best_bid":"0.96","best_ask":"0.97"},{"asset_id":"20773614133833886322101538939702011175545796528197617633926164254913649353392","price":"0.06","size":"3250.34","side":"SELL","hash":"a1c96d7f8794fbaafedd467141a78871c7dc55e7","best_bid":"0.03","best_ask":"0.04"}],"timestamp":"1770839722968","event_type":"price_change","_sub_state":"active","_subscription_id":1,"_active_subscription_id":1},"parse_warnings":[],"out_of_order":false}
{"run_id":"29526913bab7446286864a321c124486","channel":"market","event_type":"price_change","market":"0x8032d8355d335c6ccbfc2508d99fbc87eb13f437bd275c93ee56fd1558e517ff","asset_id":null,"source":"market_ws:sub:active:1","t_event_ms":1770839722974,"t_recv_wall_ms":1770839722888,"t_recv_wall_iso":"2026-02-11T19:55:22.888Z","t_recv_mono_ns":618588229106958,"raw":{"market":"0x8032d8355d335c6ccbfc2508d99fbc87eb13f437bd275c93ee56fd1558e517ff","price_changes":[{"asset_id":"20773614133833886322101538939702011175545796528197617633926164254913649353392","price":"0.04","size":"4065.95","side":"SELL","hash":"839ea4ad90942480bec3d5d8932b355b81520fb0","best_bid":"0.03","best_ask":"0.04"},{"asset_id":"40652734036737240317526188612064032143639112324786051284480877037991580442979","price":"0.96","size":"4065.95","side":"BUY","hash":"7373bd4a63090e415003b94741c815c190609189","best_bid":"0.96","best_ask":"0.97"}],"timestamp":"1770839722974","event_type":"price_change","_sub_state":"active","_subscription_id":1,"_active_subscription_id":1},"parse_warnings":[],"out_of_order":false}
{"run_id":"29526913bab7446286864a321c124486","channel":"market","event_type":"price_change","market":"0x8032d8355d335c6ccbfc2508d99fbc87eb13f437bd275c93ee56fd1558e517ff","asset_id":null,"source":"market_ws:sub:active:1","t_event_ms":1770839722992,"t_recv_wall_ms":1770839722902,"t_recv_wall_iso":"2026-02-11T19:55:22.902Z","t_recv_mono_ns":618588243740708,"raw":{"market":"0x8032d8355d335c6ccbfc2508d99fbc87eb13f437bd275c93ee56fd1558e517ff","price_changes":[{"asset_id":"40652734036737240317526188612064032143639112324786051284480877037991580442979","price":"0.96","size":"4005.95","side":"BUY","hash":"0942a662145b7a076e20706b5885edad194efdd4","best_bid":"0.96","best_ask":"0.97"},{"asset_id":"20773614133833886322101538939702011175545796528197617633926164254913649353392","price":"0.04","size":"4005.95","side":"SELL","hash":"14ab88682d8dc83754393eb6691852646b8a18ba","best_bid":"0.03","best_ask":"0.04"}],"timestamp":"1770839722992","event_type":"price_change","_sub_state":"active","_subscription_id":1,"_active_subscription_id":1},"parse_warnings":[],"out_of_order":false}
{"run_id":"29526913bab7446286864a321c124486","channel":"market","event_type":"price_change","market":"0x8032d8355d335c6ccbfc2508d99fbc87eb13f437bd275c93ee56fd1558e517ff","asset_id":null,"source":"market_ws:sub:active:1","t_event_ms":1770839723000,"t_recv_wall_ms":1770839722909,"t_recv_wall_iso":"2026-02-11T19:55:22.909Z","t_recv_mono_ns":618588250005333,"raw":{"market":"0x8032d8355d335c6ccbfc2508d99fbc87eb13f437bd275c93ee56fd1558e517ff","price_changes":[{"asset_id":"40652734036737240317526188612064032143639112324786051284480877037991580442979","price":"0.96","size":"4065.95","side":"BUY","hash":"4bdf1ba0936d4f8b93e01dae6d95db60aadbdd8e","best_bid":"0.96","best_ask":"0.97"},{"asset_id":"20773614133833886322101538939702011175545796528197617633926164254913649353392","price":"0.04","size":"4065.95","side":"SELL","hash":"91b2223c7bb24e3455824dd9e2f39ea345de7f55","best_bid":"0.03","best_ask":"0.04"}],"timestamp":"1770839723000","event_type":"price_change","_sub_state":"active","_subscription_id":1,"_active_subscription_id":1},"parse_warnings":[],"out_of_order":false}
{"run_id":"29526913bab7446286864a321c124486","channel":"market","event_type":"price_change","market":"0x8032d8355d335c6ccbfc2508d99fbc87eb13f437bd275c93ee56fd1558e517ff","asset_id":null,"source":"market_ws:sub:active:1","t_event_ms":1770839723027,"t_recv_wall_ms":1770839722934,"t_recv_wall_iso":"2026-02-11T19:55:22.934Z","t_recv_mono_ns":618588274874916,"raw":{"market":"0x8032d8355d335c6ccbfc2508d99fbc87eb13f437bd275c93ee56fd1558e517ff","price_changes":[{"asset_id":"40652734036737240317526188612064032143639112324786051284480877037991580442979","price":"0.98","size":"8759.25","side":"SELL","hash":"46e08ee1de981311f1baa20394b88fa42266a597","best_bid":"0.96","best_ask":"0.97"},{"asset_id":"20773614133833886322101538939702011175545796528197617633926164254913649353392","price":"0.02","size":"8759.25","side":"BUY","hash":"d6e28fc969c856dc230c2c1a4a25b1a221aeb5d8","best_bid":"0.03","best_ask":"0.04"}],"timestamp":"1770839723027","event_type":"price_change","_sub_state":"active","_subscription_id":1,"_active_subscription_id":1},"parse_warnings":[],"out_of_order":false}
{"run_id":"29526913bab7446286864a321c124486","channel":"market","event_type":"price_change","market":"0x8032d8355d335c6ccbfc2508d99fbc87eb13f437bd275c93ee56fd1558e517ff","asset_id":null,"source":"market_ws:sub:active:1","t_event_ms":1770839723031,"t_recv_wall_ms":1770839722937,"t_recv_wall_iso":"2026-02-11T19:55:22.937Z","t_recv_mono_ns":618588278335625,"raw":{"market":"0x8032d8355d335c6ccbfc2508d99fbc87eb13f437bd275c93ee56fd1558e517ff","price_changes":[{"asset_id":"40652734036737240317526188612064032143639112324786051284480877037991580442979","price":"0.91","size":"574.6","side":"BUY","hash":"9d77f5c89f1ecaf6e8e9357de343ec4ab9caadb0","best_bid":"0.96","best_ask":"0.97"},{"asset_id":"20773614133833886322101538939702011175545796528197617633926164254913649353392","price":"0.09","size":"574.6","side":"SELL","hash":"564cd381b2c016cf53a69dc77b099a7660e21b15","best_bid":"0.03","best_ask":"0.04"}],"timestamp":"1770839723031","event_type":"price_change","_sub_state":"active","_subscription_id":1,"_active_subscription_id":1},"parse_warnings":[],"out_of_order":false}
{"run_id":"29526913bab7446286864a321c124486","channel":"market","event_type":"price_change","market":"0x8032d8355d335c6ccbfc2508d99fbc87eb13f437bd275c93ee56fd1558e517ff","asset_id":null,"source":"market_ws:sub:active:1","t_event_ms":1770839723033,"t_recv_wall_ms":1770839722937,"t_recv_wall_iso":"2026-02-11T19:55:22.937Z","t_recv_mono_ns":618588278630541,"raw":{"market":"0x8032d8355d335c6ccbfc2508d99fbc87eb13f437bd275c93ee56fd1558e517ff","price_changes":[{"asset_id":"40652734036737240317526188612064032143639112324786051284480877037991580442979","price":"0.96","size":"4005.95","side":"BUY","hash":"5601d989057e410e6562307c179f655ac23e80f9","best_bid":"0.96","best_ask":"0.97"},{"asset_id":"20773614133833886322101538939702011175545796528197617633926164254913649353392","price":"0.04","size":"4005.95","side":"SELL","hash":"f44b513c7a4a98fe143ca8cd43db0bcf4f140315","best_bid":"0.03","best_ask":"0.04"}],"timestamp":"1770839723033","event_type":"price_change","_sub_state":"active","_subscription_id":1,"_active_subscription_id":1},"parse_warnings":[],"out_of_order":false}
{"run_id":"29526913bab7446286864a321c124486","channel":"market","event_type":"price_change","market":"0x8032d8355d335c6ccbfc2508d99fbc87eb13f437bd275c93ee56fd1558e517ff","asset_id":null,"source":"market_ws:sub:active:1","t_event_ms":1770839723034,"t_recv_wall_ms":1770839722938,"t_recv_wall_iso":"2026-02-11T19:55:22.938Z","t_recv_mono_ns":618588278833541,"raw":{"market":"0x8032d8355d335c6ccbfc2508d99fbc87eb13f437bd275c93ee56fd1558e517ff","price_changes":[{"asset_id":"40652734036737240317526188612064032143639112324786051284480877037991580442979","price":"0.98","size":"8754.25","side":"SELL","hash":"4029f714c840e99a413667cea141cc37d84ab198","best_bid":"0.96","best_ask":"0.97"},{"asset_id":"20773614133833886322101538939702011175545796528197617633926164254913649353392","price":"0.02","size":"8754.25","side":"BUY","hash":"6d4decd85e76af00314b10aea42d32ba19545720","best_bid":"0.03","best_ask":"0.04"}],"timestamp":"1770839723034","event_type":"price_change","_sub_state":"active","_subscription_id":1,"_active_subscription_id":1},"parse_warnings":[],"out_of_order":false}
{"run_id":"29526913bab7446286864a321c124486","channel":"market","event_type":"price_change","market":"0x8032d8355d335c6ccbfc2508d99fbc87eb13f437bd275c93ee56fd1558e517ff","asset_id":null,"source":"market_ws:sub:active:1","t_event_ms":1770839723035,"t_recv_wall_ms":1770839722944,"t_recv_wall_iso":"2026-02-11T19:55:22.944Z","t_recv_mono_ns":618588285714291,"raw":{"market":"0x8032d8355d335c6ccbfc2508d99fbc87eb13f437bd275c93ee56fd1558e517ff","price_changes":[{"asset_id":"40652734036737240317526188612064032143639112324786051284480877037991580442979","price":"0.92","size":"3424.35","side":"BUY","hash":"164063efd65da1bdf85ddda3e12e81526091f7cf","best_bid":"0.96","best_ask":"0.97"},{"asset_id":"20773614133833886322101538939702011175545796528197617633926164254913649353392","price":"0.08","size":"3424.35","side":"SELL","hash":"a153e2a49c89d62afb7cc87b349cfa16c49f2c24","best_bid":"0.03","best_ask":"0.04"}],"timestamp":"1770839723035","event_type":"price_change","_sub_state":"active","_subscription_id":1,"_active_subscription_id":1},"parse_warnings":[],"out_of_order":false}
{"run_id":"29526913bab7446286864a321c124486","channel":"market","event_type":"price_change","market":"0x8032d8355d335c6ccbfc2508d99fbc87eb13f437bd275c93ee56fd1558e517ff","asset_id":null,"source":"market_ws:sub:active:1","t_event_ms":1770839723037,"t_recv_wall_ms":1770839722945,"t_recv_wall_iso":"2026-02-11T19:55:22.945Z","t_recv_mono_ns":618588286255375,"raw":{"market":"0x8032d8355d335c6ccbfc2508d99fbc87eb13f437bd275c93ee56fd1558e517ff","price_changes":[{"asset_id":"40652734036737240317526188612064032143639112324786051284480877037991580442979","price":"0.99","size":"30894.91","side":"SELL","hash":"ee0bf28dc80fb39558e8152cae7648557ca3d5ec","best_bid":"0.96","best_ask":"0.97"},{"asset_id":"20773614133833886322101538939702011175545796528197617633926164254913649353392","price":"0.01","size":"30894.91","side":"BUY","hash":"caed00b6d16203e09bcc239fa1871033bf2ded3e","best_bid":"0.03","best_ask":"0.04"}],"timestamp":"1770839723037","event_type":"price_change","_sub_state":"active","_subscription_id":1,"_active_subscription_id":1},"parse_warnings":[],"out_of_order":false}
{"run_id":"29526913bab7446286864a321c124486","channel":"market","event_type":"price_change","market":"0x8032d8355d335c6ccbfc2508d99fbc87eb13f437bd275c93ee56fd1558e517ff","asset_id":null,"source":"market_ws:sub:active:1","t_event_ms":1770839723045,"t_recv_wall_ms":1770839722951,"t_recv_wall_iso":"2026-02-11T19:55:22.951Z","t_recv_mono_ns":618588292340375,"raw":{"market":"0x8032d8355d335c6ccbfc2508d99fbc87eb13f437bd275c93ee56fd1558e517ff","price_changes":[{"asset_id":"40652734036737240317526188612064032143639112324786051284480877037991580442979","price":"0.96","size":"4065.95","side":"BUY","hash":"33023f168010d483f8d23dc6d188900476102e80","best_bid":"0.96","best_ask":"0.97"},{"asset_id":"20773614133833886322101538939702011175545796528197617633926164254913649353392","price":"0.04","size":"4065.95","side":"SELL","hash":"0b08b07d1325e241177b0f357d8a53329edcf6d2","best_bid":"0.03","best_ask":"0.04"}],"timestamp":"1770839723045","event_type":"price_change","_sub_state":"active","_subscription_id":1,"_active_subscription_id":1},"parse_warnings":[],"out_of_order":false}
{"run_id":"29526913bab7446286864a321c124486","channel":"market","event_type":"price_change","market":"0x8032d8355d335c6ccbfc2508d99fbc87eb13f437bd275c93ee56fd1558e517ff","asset_id":null,"source":"market_ws:sub:active:1","t_event_ms":1770839723053,"t_recv_wall_ms":1770839722958,"t_recv_wall_iso":"2026-02-11T19:55:22.958Z","t_recv_mono_ns":618588299740083,"raw":{"market":"0x8032d8355d335c6ccbfc2508d99fbc87eb13f437bd275c93ee56fd1558e517ff","price_changes":[{"asset_id":"40652734036737240317526188612064032143639112324786051284480877037991580442979","price":"0.83","size":"958.39","side":"BUY","hash":"878f63621d481388599a00736a1e946e23afc496","best_bid":"0.96","best_ask":"0.97"},{"asset_id":"20773614133833886322101538939702011175545796528197617633926164254913649353392","price":"0.17","size":"958.39","side":"SELL","hash":"a8ed781581f356ee8828d8db8580f97c38b81b46","best_bid":"0.03","best_ask":"0.04"}],"timestamp":"1770839723053","event_type":"price_change","_sub_state":"active","_subscription_id":1,"_active_subscription_id":1},"parse_warnings":[],"out_of_order":false}
{"run_id":"29526913bab7446286864a321c124486","channel":"market","event_type":"price_change","market":"0x8032d8355d335c6ccbfc2508d99fbc87eb13f437bd275c93ee56fd1558e517ff","asset_id":null,"source":"market_ws:sub:active:1","t_event_ms":1770839723055,"t_recv_wall_ms":1770839722964,"t_recv_wall_iso":"2026-02-11T19:55:22.964Z","t_recv_mono_ns":618588305020291,"raw":{"market":"0x8032d8355d335c6ccbfc2508d99fbc87eb13f437bd275c93ee56fd1558e517ff","price_changes":[{"asset_id":"40652734036737240317526188612064032143639112324786051284480877037991580442979","price":"0.87","size":"995.8","side":"BUY","hash":"69af4fa2c9434aa2ec9ee5b486fa497595b5e7af","best_bid":"0.96","best_ask":"0.97"},{"asset_id":"20773614133833886322101538939702011175545796528197617633926164254913649353392","price":"0.13","size":"995.8","side":"SELL","hash":"01fb77ce74e109f8bb44e8895d46186a41d79ff6","best_bid":"0.03","best_ask":"0.04"}],"timestamp":"1770839723055","event_type":"price_change","_sub_state":"active","_subscription_id":1,"_active_subscription_id":1},"parse_warnings":[],"out_of_order":false}
{"run_id":"29526913bab7446286864a321c124486","channel":"market","event_type":"price_change","market":"0x8032d8355d335c6ccbfc2508d99fbc87eb13f437bd275c93ee56fd1558e517ff","asset_id":null,"source":"market_ws:sub:active:1","t_event_ms":1770839723058,"t_recv_wall_ms":1770839722964,"t_recv_wall_iso":"2026-02-11T19:55:22.964Z","t_recv_mono_ns":618588305301458,"raw":{"market":"0x8032d8355d335c6ccbfc2508d99fbc87eb13f437bd275c93ee56fd1558e517ff","price_changes":[{"asset_id":"40652734036737240317526188612064032143639112324786051284480877037991580442979","price":"0.88","size":"1105.55","side":"BUY","hash":"18e76b33318f12114bce0cf2a961abbb54954ee7","best_bid":"0.96","best_ask":"0.97"},{"asset_id":"20773614133833886322101538939702011175545796528197617633926164254913649353392","price":"0.12","size":"1105.55","side":"SELL","hash":"336e0ca23822bfc17082720b67fd9f9a4ac7b481","best_bid":"0.03","best_ask":"0.04"}],"timestamp":"1770839723058","event_type":"price_change","_sub_state":"active","_subscription_id":1,"_active_subscription_id":1},"parse_warnings":[],"out_of_order":false}
{"run_id":"29526913bab7446286864a321c124486","channel":"market","event_type":"price_change","market":"0x8032d8355d335c6ccbfc2508d99fbc87eb13f437bd275c93ee56fd1558e517ff","asset_id":null,"source":"market_ws:sub:active:1","t_event_ms":1770839723071,"t_recv_wall_ms":1770839722976,"t_recv_wall_iso":"2026-02-11T19:55:22.976Z","t_recv_mono_ns":618588317668000,"raw":{"market":"0x8032d8355d335c6ccbfc2508d99fbc87eb13f437bd275c93ee56fd1558e517ff","price_changes":[{"asset_id":"40652734036737240317526188612064032143639112324786051284480877037991580442979","price":"0.96","size":"4005.95","side":"BUY","hash":"8d09ecea96c9abcbbdae6c839cf077e99d5a9751","best_bid":"0.96","best_ask":"0.97"},{"asset_id":"20773614133833886322101538939702011175545796528197617633926164254913649353392","price":"0.04","size":"4005.95","side":"SELL","hash":"805eb97d10252e41f8fe975af62c95d41130f0e1","best_bid":"0.03","best_ask":"0.04"}],"timestamp":"1770839723071","event_type":"price_change","_sub_state":"active","_subscription_id":1,"_active_subscription_id":1},"parse_warnings":[],"out_of_order":false}
{"run_id":"29526913bab7446286864a321c124486","channel":"market","event_type":"price_change","market":"0x8032d8355d335c6ccbfc2508d99fbc87eb13f437bd275c93ee56fd1558e517ff","asset_id":null,"source":"market_ws:sub:active:1","t_event_ms":1770839723077,"t_recv_wall_ms":1770839722982,"t_recv_wall_iso":"2026-02-11T19:55:22.982Z","t_recv_mono_ns":618588323360583,"raw":{"market":"0x8032d8355d335c6ccbfc2508d99fbc87eb13f437bd275c93ee56fd1558e517ff","price_changes":[{"asset_id":"40652734036737240317526188612064032143639112324786051284480877037991580442979","price":"0.96","size":"4065.95","side":"BUY","hash":"4502b39e0c8e7304e9f2d0ca7c5e958d4f81e09a","best_bid":"0.96","best_ask":"0.97"},{"asset_id":"20773614133833886322101538939702011175545796528197617633926164254913649353392","price":"0.04","size":"4065.95","side":"SELL","hash":"b5a669302ce08ed15d9f6b18fca212e47eef2a1b","best_bid":"0.03","best_ask":"0.04"}],"timestamp":"1770839723077","event_type":"price_change","_sub_state":"active","_subscription_id":1,"_active_subscription_id":1},"parse_warnings":[],"out_of_order":false}
{"run_id":"29526913bab7446286864a321c124486","channel":"market","event_type":"price_change","market":"0x8032d8355d335c6ccbfc2508d99fbc87eb13f437bd275c93ee56fd1558e517ff","asset_id":null,"source":"market_ws:sub:active:1","t_event_ms":1770839723097,"t_recv_wall_ms":1770839723006,"t_recv_wall_iso":"2026-02-11T19:55:23.006Z","t_recv_mono_ns":618588347171083,"raw":{"market":"0x8032d8355d335c6ccbfc2508d99fbc87eb13f437bd275c93ee56fd1558e517ff","price_changes":[{"asset_id":"20773614133833886322101538939702011175545796528197617633926164254913649353392","price":"0.03","size":"132.3","side":"BUY","hash":"bd0220d9e707564520cd2c1a741cd48a89424a23","best_bid":"0.03","best_ask":"0.04"},{"asset_id":"40652734036737240317526188612064032143639112324786051284480877037991580442979","price":"0.97","size":"132.3","side":"SELL","hash":"d558961477cc06a84f2308314cf5c74f4d5d5146","best_bid":"0.96","best_ask":"0.97"}],"timestamp":"1770839723097","event_type":"price_change","_sub_state":"active","_subscription_id":1,"_active_subscription_id":1},"parse_warnings":[],"out_of_order":false}
{"run_id":"29526913bab7446286864a321c124486","channel":"market","event_type":"book","market":"0x8032d8355d335c6ccbfc2508d99fbc87eb13f437bd275c93ee56fd1558e517ff","asset_id":"20773614133833886322101538939702011175545796528197617633926164254913649353392","source":"market_ws:sub:active:1","t_event_ms":1770839723097,"t_recv_wall_ms":1770839723006,"t_recv_wall_iso":"2026-02-11T19:55:23.006Z","t_recv_mono_ns":618588347722666,"raw":{"market":"0x8032d8355d335c6ccbfc2508d99fbc87eb13f437bd275c93ee56fd1558e517ff","asset_id":"20773614133833886322101538939702011175545796528197617633926164254913649353392","bids":[{"price":"0.01","size":"30894.91"},{"price":"0.02","size":"8754.25"},{"price":"0.03","size":"132.3"}],"asks":[{"price":"0.99","size":"30822.26"},{"price":"0.98","size":"12559.04"},{"price":"0.97","size":"7433.03"},{"price":"0.96","size":"5453.8"},{"price":"0.95","size":"6815.8"},{"price":"0.94","size":"5105"},{"price":"0.93","size":"5421.38"},{"price":"0.92","size":"5139.4"},{"price":"0.91","size":"5225.8"},{"price":"0.9","size":"5102.8"},{"price":"0.89","size":"120.6"},{"price":"0.88","size":"63.6"},{"price":"0.87","size":"63"},{"price":"0.86","size":"61.6"},{"price":"0.85","size":"107.39"},{"price":"0.84","size":"69.39"},{"price":"0.83","size":"58.39"},{"price":"0.82","size":"66.71"},{"price":"0.81","size":"56.8"},{"price":"0.8","size":"92.14"},{"price":"0.79","size":"60.8"},{"price":"0.78","size":"55.2"},{"price":"0.77","size":"64.48"},{"price":"0.76","size":"54.2"},{"price":"0.75","size":"375.8"},{"price":"0.74","size":"68.6"},{"price":"0.73","size":"53.2"},{"price":"0.72","size":"63.26"},{"price":"0.71","size":"52.6"},{"price":"0.7","size":"402.4"},{"price":"0.69","size":"72.2"},{"price":"0.68","size":"87.88"},{"price":"0.67","size":"188.46"},{"price":"0.66","size":"123.6"},{"price":"0.65","size":"317.03"},{"price":"0.64","size":"582.36"},{"price":"0.63","size":"559.2"},{"price":"0.62","size":"559"},{"price":"0.61","size":"594"},{"price":"0.6","size":"2915.41"},{"price":"0.59","size":"576.8"},{"price":"0.58","size":"575.5"},{"price":"0.57","size":"558.6"},{"price":"0.56","size":"572.68"},{"price":"0.55","size":"566.4"},{"price":"0.54","size":"561.94"},{"price":"0.53","size":"631.57"},{"price":"0.52","size":"611.4"},{"price":"0.51","size":"705.2"},{"price":"0.5","size":"1011.55"},{"price":"0.49","size":"692.4"},{"price":"0.48","size":"628.4"},{"price":"0.47","size":"633.4"},{"price":"0.46","size":"711.65"},{"price":"0.45","size":"866.59"},{"price":"0.44","size":"905.69"},{"price":"0.43","size":"641.6"},{"price":"0.42","size":"645.58"},{"price":"0.41","size":"564"},{"price":"0.4","size":"20642.9"},{"price":"0.39","size":"650.23"},{"price":"0.38","size":"593"},{"price":"0.37","size":"755.73"},{"price":"0.36","size":"558"},{"price":"0.35","size":"1144.32"},{"price":"0.34","size":"649.59"},{"price":"0.33","size":"624.8"},{"price":"0.32","size":"574"},{"price":"0.31","size":"594.2"},{"price":"0.3","size":"735.66"},{"price":"0.29","size":"918.6"},{"price":"0.28","size":"356.8"},{"price":"0.27","size":"869.2"},{"price":"0.26","size":"967.6"},{"price":"0.25","size":"1673.8"},{"price":"0.24","size":"869.2"},{"price":"0.23","size":"864.6"},{"price":"0.22","size":"870.2"},{"price":"0.21","size":"871.6"},{"price":"0.2","size":"987.2"},{"price":"0.19","size":"876.8"},{"price":"0.18","size":"1091.55"},{"price":"0.17","size":"958.39"},{"price":"0.16","size":"1119.39"},{"price":"0.15","size":"1149.13"},{"price":"0.14","size":"962.6"},{"price":"0.13","size":"995.8"},{"price":"0.12","size":"1105.55"},{"price":"0.11","size":"1124.49"},{"price":"0.1","size":"1191.79"},{"price":"0.09","size":"574.6"},{"price":"0.08","size":"3424.35"},{"price":"0.07","size":"3340.43"},{"price":"0.06","size":"3250.34"},{"price":"0.05","size":"3109.45"},{"price":"0.04","size":"4065.95"}],"hash":"bd0220d9e707564520cd2c1a741cd48a89424a23","timestamp":"1770839723097","event_type":"book","_sub_state":"active","_subscription_id":1,"_active_subscription_id":1},"parse_warnings":[],"out_of_order":false}
{"run_id":"29526913bab7446286864a321c124486","channel":"market","event_type":"book","market":"0x8032d8355d335c6ccbfc2508d99fbc87eb13f437bd275c93ee56fd1558e517ff","asset_id":"40652734036737240317526188612064032143639112324786051284480877037991580442979","source":"market_ws:sub:active:1","t_event_ms":1770839723097,"t_recv_wall_ms":1770839723007,"t_recv_wall_iso":"2026-02-11T19:55:23.007Z","t_recv_mono_ns":618588348711750,"raw":{"market":"0x8032d8355d335c6ccbfc2508d99fbc87eb13f437bd275c93ee56fd1558e517ff","asset_id":"40652734036737240317526188612064032143639112324786051284480877037991580442979","bids":[{"price":"0.01","size":"30822.26"},{"price":"0.02","size":"12559.04"},{"price":"0.03","size":"7433.03"},{"price":"0.04","size":"5453.8"},{"price":"0.05","size":"6815.8"},{"price":"0.06","size":"5105"},{"price":"0.07","size":"5421.38"},{"price":"0.08","size":"5139.4"},{"price":"0.09","size":"5225.8"},{"price":"0.1","size":"5102.8"},{"price":"0.11","size":"120.6"},{"price":"0.12","size":"63.6"},{"price":"0.13","size":"63"},{"price":"0.14","size":"61.6"},{"price":"0.15","size":"107.39"},{"price":"0.16","size":"69.39"},{"price":"0.17","size":"58.39"},{"price":"0.18","size":"66.71"},{"price":"0.19","size":"56.8"},{"price":"0.2","size":"92.14"},{"price":"0.21","size":"60.8"},{"price":"0.22","size":"55.2"},{"price":"0.23","size":"64.48"},{"price":"0.24","size":"54.2"},{"price":"0.25","size":"375.8"},{"price":"0.26","size":"68.6"},{"price":"0.27","size":"53.2"},{"price":"0.28","size":"63.26"},{"price":"0.29","size":"52.6"},{"price":"0.3","size":"402.4"},{"price":"0.31","size":"72.2"},{"price":"0.32","size":"87.88"},{"price":"0.33","size":"188.46"},{"price":"0.34","size":"123.6"},{"price":"0.35","size":"317.03"},{"price":"0.36","size":"582.36"},{"price":"0.37","size":"559.2"},{"price":"0.38","size":"559"},{"price":"0.39","size":"594"},{"price":"0.4","size":"2915.41"},{"price":"0.41","size":"576.8"},{"price":"0.42","size":"575.5"},{"price":"0.43","size":"558.6"},{"price":"0.44","size":"572.68"},{"price":"0.45","size":"566.4"},{"price":"0.46","size":"561.94"},{"price":"0.47","size":"631.57"},{"price":"0.48","size":"611.4"},{"price":"0.49","size":"705.2"},{"price":"0.5","size":"1011.55"},{"price":"0.51","size":"692.4"},{"price":"0.52","size":"628.4"},{"price":"0.53","size":"633.4"},{"price":"0.54","size":"711.65"},{"price":"0.55","size":"866.59"},{"price":"0.56","size":"905.69"},{"price":"0.57","size":"641.6"},{"price":"0.58","size":"645.58"},{"price":"0.59","size":"564"},{"price":"0.6","size":"20642.9"},{"price":"0.61","size":"650.23"},{"price":"0.62","size":"593"},{"price":"0.63","size":"755.73"},{"price":"0.64","size":"558"},{"price":"0.65","size":"1144.32"},{"price":"0.66","size":"649.59"},{"price":"0.67","size":"624.8"},{"price":"0.68","size":"574"},{"price":"0.69","size":"594.2"},{"price":"0.7","size":"735.66"},{"price":"0.71","size":"918.6"},{"price":"0.72","size":"356.8"},{"price":"0.73","size":"869.2"},{"price":"0.74","size":"967.6"},{"price":"0.75","size":"1673.8"},{"price":"0.76","size":"869.2"},{"price":"0.77","size":"864.6"},{"price":"0.78","size":"870.2"},{"price":"0.79","size":"871.6"},{"price":"0.8","size":"987.2"},{"price":"0.81","size":"876.8"},{"price":"0.82","size":"1091.55"},{"price":"0.83","size":"958.39"},{"price":"0.84","size":"1119.39"},{"price":"0.85","size":"1149.13"},{"price":"0.86","size":"962.6"},{"price":"0.87","size":"995.8"},{"price":"0.88","size":"1105.55"},{"price":"0.89","size":"1124.49"},{"price":"0.9","size":"1191.79"},{"price":"0.91","size":"574.6"},{"price":"0.92","size":"3424.35"},{"price":"0.93","size":"3340.43"},{"price":"0.94","size":"3250.34"},{"price":"0.95","size":"3109.45"},{"price":"0.96","size":"4065.95"}],"asks":[{"price":"0.99","size":"30894.91"},{"price":"0.98","size":"8754.25"},{"price":"0.97","size":"132.3"}],"hash":"d558961477cc06a84f2308314cf5c74f4d5d5146","timestamp":"1770839723097","event_type":"book","_sub_state":"active","_subscription_id":1,"_active_subscription_id":1},"parse_warnings":[],"out_of_order":false}
{"run_id":"29526913bab7446286864a321c124486","channel":"market","event_type":"price_change","market":"0x8032d8355d335c6ccbfc2508d99fbc87eb13f437bd275c93ee56fd1558e517ff","asset_id":null,"source":"market_ws:sub:active:1","t_event_ms":1770839723101,"t_recv_wall_ms":1770839723009,"t_recv_wall_iso":"2026-02-11T19:55:23.009Z","t_recv_mono_ns":618588349793666,"raw":{"market":"0x8032d8355d335c6ccbfc2508d99fbc87eb13f437bd275c93ee56fd1558e517ff","price_changes":[{"asset_id":"40652734036737240317526188612064032143639112324786051284480877037991580442979","price":"0.96","size":"4005.95","side":"BUY","hash":"16a78461dabb7ff89030c79d23bcdcc0ffbea591","best_bid":"0.96","best_ask":"0.97"},{"asset_id":"20773614133833886322101538939702011175545796528197617633926164254913649353392","price":"0.04","size":"4005.95","side":"SELL","hash":"7911b4d429da14d31367c7ccf758f4d01a3c3f24","best_bid":"0.03","best_ask":"0.04"}],"timestamp":"1770839723101","event_type":"price_change","_sub_state":"active","_subscription_id":1,"_active_subscription_id":1},"parse_warnings":[],"out_of_order":false}
{"run_id":"29526913bab7446286864a321c124486","channel":"market","event_type":"price_change","market":"0x8032d8355d335c6ccbfc2508d99fbc87eb13f437bd275c93ee56fd1558e517ff","asset_id":null,"source":"market_ws:sub:active:1","t_event_ms":1770839723122,"t_recv_wall_ms":1770839723031,"t_recv_wall_iso":"2026-02-11T19:55:23.031Z","t_recv_mono_ns":618588371938166,"raw":{"market":"0x8032d8355d335c6ccbfc2508d99fbc87eb13f437bd275c93ee56fd1558e517ff","price_changes":[{"asset_id":"40652734036737240317526188612064032143639112324786051284480877037991580442979","price":"0.96","size":"4065.95","side":"BUY","hash":"685a602a9f6960cb524556c9d69645b7132a13d2","best_bid":"0.96","best_ask":"0.97"},{"asset_id":"20773614133833886322101538939702011175545796528197617633926164254913649353392","price":"0.04","size":"4065.95","side":"SELL","hash":"5f1fc09f9dd43c5b33ebb0747b6230ddd866de67","best_bid":"0.03","best_ask":"0.04"}],"timestamp":"1770839723122","event_type":"price_change","_sub_state":"active","_subscription_id":1,"_active_subscription_id":1},"parse_warnings":[],"out_of_order":false}
{"run_id":"29526913bab7446286864a321c124486","channel":"market","event_type":"last_trade_price","market":"0x8032d8355d335c6ccbfc2508d99fbc87eb13f437bd275c93ee56fd1558e517ff","asset_id":"40652734036737240317526188612064032143639112324786051284480877037991580442979","source":"market_ws:sub:unknown","t_event_ms":1770839723126,"t_recv_wall_ms":1770839723034,"t_recv_wall_iso":"2026-02-11T19:55:23.034Z","t_recv_mono_ns":618588374841666,"raw":{"market":"0x8032d8355d335c6ccbfc2508d99fbc87eb13f437bd275c93ee56fd1558e517ff","asset_id":"40652734036737240317526188612064032143639112324786051284480877037991580442979","price":"0.97","size":"5.051533","fee_rate_bps":"1000","side":"BUY","timestamp":"1770839723126","event_type":"last_trade_price","transaction_hash":"0x8db580fde95370218631eea2729221ca73fd0812a3b090ded6c1a420015d15ca","_sub_state":"unknown","_subscription_id":null,"_active_subscription_id":1},"parse_warnings":["unknown_message_schema"],"out_of_order":false}
{"run_id":"29526913bab7446286864a321c124486","channel":"market","event_type":"price_change","market":"0x8032d8355d335c6ccbfc2508d99fbc87eb13f437bd275c93ee56fd1558e517ff","asset_id":null,"source":"market_ws:sub:active:1","t_event_ms":1770839723160,"t_recv_wall_ms":1770839723067,"t_recv_wall_iso":"2026-02-11T19:55:23.067Z","t_recv_mono_ns":618588408392000,"raw":{"market":"0x8032d8355d335c6ccbfc2508d99fbc87eb13f437bd275c93ee56fd1558e517ff","price_changes":[{"asset_id":"20773614133833886322101538939702011175545796528197617633926164254913649353392","price":"0.03","size":"90.3","side":"BUY","hash":"3df55891fcdd01f5f10a1a7fd93667999502f18d","best_bid":"0.03","best_ask":"0.04"},{"asset_id":"40652734036737240317526188612064032143639112324786051284480877037991580442979","price":"0.97","size":"90.3","side":"SELL","hash":"3962d3cd1e809690dd9dfdb2738fdd1c0df69797","best_bid":"0.96","best_ask":"0.97"}],"timestamp":"1770839723160","event_type":"price_change","_sub_state":"active","_subscription_id":1,"_active_subscription_id":1},"parse_warnings":[],"out_of_order":false}
{"run_id":"29526913bab7446286864a321c124486","channel":"market","event_type":"book","market":"0x8032d8355d335c6ccbfc2508d99fbc87eb13f437bd275c93ee56fd1558e517ff","asset_id":"20773614133833886322101538939702011175545796528197617633926164254913649353392","source":"market_ws:sub:active:1","t_event_ms":1770839723160,"t_recv_wall_ms":1770839723068,"t_recv_wall_iso":"2026-02-11T19:55:23.068Z","t_recv_mono_ns":618588409340958,"raw":{"market":"0x8032d8355d335c6ccbfc2508d99fbc87eb13f437bd275c93ee56fd1558e517ff","asset_id":"20773614133833886322101538939702011175545796528197617633926164254913649353392","bids":[{"price":"0.01","size":"30894.91"},{"price":"0.02","size":"8754.25"},{"price":"0.03","size":"90.3"}],"asks":[{"price":"0.99","size":"30822.26"},{"price":"0.98","size":"12559.04"},{"price":"0.97","size":"7433.03"},{"price":"0.96","size":"5453.8"},{"price":"0.95","size":"6815.8"},{"price":"0.94","size":"5105"},{"price":"0.93","size":"5421.38"},{"price":"0.92","size":"5139.4"},{"price":"0.91","size":"5225.8"},{"price":"0.9","size":"5102.8"},{"price":"0.89","size":"120.6"},{"price":"0.88","size":"63.6"},{"price":"0.87","size":"63"},{"price":"0.86","size":"61.6"},{"price":"0.85","size":"107.39"},{"price":"0.84","size":"69.39"},{"price":"0.83","size":"58.39"},{"price":"0.82","size":"66.71"},{"price":"0.81","size":"56.8"},{"price":"0.8","size":"92.14"},{"price":"0.79","size":"60.8"},{"price":"0.78","size":"55.2"},{"price":"0.77","size":"64.48"},{"price":"0.76","size":"54.2"},{"price":"0.75","size":"375.8"},{"price":"0.74","size":"68.6"},{"price":"0.73","size":"53.2"},{"price":"0.72","size":"63.26"},{"price":"0.71","size":"52.6"},{"price":"0.7","size":"402.4"},{"price":"0.69","size":"72.2"},{"price":"0.68","size":"87.88"},{"price":"0.67","size":"188.46"},{"price":"0.66","size":"123.6"},{"price":"0.65","size":"317.03"},{"price":"0.64","size":"582.36"},{"price":"0.63","size":"559.2"},{"price":"0.62","size":"559"},{"price":"0.61","size":"594"},{"price":"0.6","size":"2915.41"},{"price":"0.59","size":"576.8"},{"price":"0.58","size":"575.5"},{"price":"0.57","size":"558.6"},{"price":"0.56","size":"572.68"},{"price":"0.55","size":"566.4"},{"price":"0.54","size":"561.94"},{"price":"0.53","size":"631.57"},{"price":"0.52","size":"611.4"},{"price":"0.51","size":"705.2"},{"price":"0.5","size":"1011.55"},{"price":"0.49","size":"692.4"},{"price":"0.48","size":"628.4"},{"price":"0.47","size":"633.4"},{"price":"0.46","size":"711.65"},{"price":"0.45","size":"866.59"},{"price":"0.44","size":"905.69"},{"price":"0.43","size":"641.6"},{"price":"0.42","size":"645.58"},{"price":"0.41","size":"564"},{"price":"0.4","size":"20642.9"},{"price":"0.39","size":"650.23"},{"price":"0.38","size":"593"},{"price":"0.37","size":"755.73"},{"price":"0.36","size":"558"},{"price":"0.35","size":"1144.32"},{"price":"0.34","size":"649.59"},{"price":"0.33","size":"624.8"},{"price":"0.32","size":"574"},{"price":"0.31","size":"594.2"},{"price":"0.3","size":"735.66"},{"price":"0.29","size":"918.6"},{"price":"0.28","size":"356.8"},{"price":"0.27","size":"869.2"},{"price":"0.26","size":"967.6"},{"price":"0.25","size":"1673.8"},{"price":"0.24","size":"869.2"},{"price":"0.23","size":"864.6"},{"price":"0.22","size":"870.2"},{"price":"0.21","size":"871.6"},{"price":"0.2","size":"987.2"},{"price":"0.19","size":"876.8"},{"price":"0.18","size":"1091.55"},{"price":"0.17","size":"958.39"},{"price":"0.16","size":"1119.39"},{"price":"0.15","size":"1149.13"},{"price":"0.14","size":"962.6"},{"price":"0.13","size":"995.8"},{"price":"0.12","size":"1105.55"},{"price":"0.11","size":"1124.49"},{"price":"0.1","size":"1191.79"},{"price":"0.09","size":"574.6"},{"price":"0.08","size":"3424.35"},{"price":"0.07","size":"3340.43"},{"price":"0.06","size":"3250.34"},{"price":"0.05","size":"3109.45"},{"price":"0.04","size":"4065.95"}],"hash":"3df55891fcdd01f5f10a1a7fd93667999502f18d","timestamp":"1770839723160","event_type":"book","_sub_state":"active","_subscription_id":1,"_active_subscription_id":1},"parse_warnings":[],"out_of_order":false}
{"run_id":"29526913bab7446286864a321c124486","channel":"market","event_type":"book","market":"0x8032d8355d335c6ccbfc2508d99fbc87eb13f437bd275c93ee56fd1558e517ff","asset_id":"40652734036737240317526188612064032143639112324786051284480877037991580442979","source":"market_ws:sub:active:1","t_event_ms":1770839723160,"t_recv_wall_ms":1770839723069,"t_recv_wall_iso":"2026-02-11T19:55:23.069Z","t_recv_mono_ns":618588410333083,"raw":{"market":"0x8032d8355d335c6ccbfc2508d99fbc87eb13f437bd275c93ee56fd1558e517ff","asset_id":"40652734036737240317526188612064032143639112324786051284480877037991580442979","bids":[{"price":"0.01","size":"30822.26"},{"price":"0.02","size":"12559.04"},{"price":"0.03","size":"7433.03"},{"price":"0.04","size":"5453.8"},{"price":"0.05","size":"6815.8"},{"price":"0.06","size":"5105"},{"price":"0.07","size":"5421.38"},{"price":"0.08","size":"5139.4"},{"price":"0.09","size":"5225.8"},{"price":"0.1","size":"5102.8"},{"price":"0.11","size":"120.6"},{"price":"0.12","size":"63.6"},{"price":"0.13","size":"63"},{"price":"0.14","size":"61.6"},{"price":"0.15","size":"107.39"},{"price":"0.16","size":"69.39"},{"price":"0.17","size":"58.39"},{"price":"0.18","size":"66.71"},{"price":"0.19","size":"56.8"},{"price":"0.2","size":"92.14"},{"price":"0.21","size":"60.8"},{"price":"0.22","size":"55.2"},{"price":"0.23","size":"64.48"},{"price":"0.24","size":"54.2"},{"price":"0.25","size":"375.8"},{"price":"0.26","size":"68.6"},{"price":"0.27","size":"53.2"},{"price":"0.28","size":"63.26"},{"price":"0.29","size":"52.6"},{"price":"0.3","size":"402.4"},{"price":"0.31","size":"72.2"},{"price":"0.32","size":"87.88"},{"price":"0.33","size":"188.46"},{"price":"0.34","size":"123.6"},{"price":"0.35","size":"317.03"},{"price":"0.36","size":"582.36"},{"price":"0.37","size":"559.2"},{"price":"0.38","size":"559"},{"price":"0.39","size":"594"},{"price":"0.4","size":"2915.41"},{"price":"0.41","size":"576.8"},{"price":"0.42","size":"575.5"},{"price":"0.43","size":"558.6"},{"price":"0.44","size":"572.68"},{"price":"0.45","size":"566.4"},{"price":"0.46","size":"561.94"},{"price":"0.47","size":"631.57"},{"price":"0.48","size":"611.4"},{"price":"0.49","size":"705.2"},{"price":"0.5","size":"1011.55"},{"price":"0.51","size":"692.4"},{"price":"0.52","size":"628.4"},{"price":"0.53","size":"633.4"},{"price":"0.54","size":"711.65"},{"price":"0.55","size":"866.59"},{"price":"0.56","size":"905.69"},{"price":"0.57","size":"641.6"},{"price":"0.58","size":"645.58"},{"price":"0.59","size":"564"},{"price":"0.6","size":"20642.9"},{"price":"0.61","size":"650.23"},{"price":"0.62","size":"593"},{"price":"0.63","size":"755.73"},{"price":"0.64","size":"558"},{"price":"0.65","size":"1144.32"},{"price":"0.66","size":"649.59"},{"price":"0.67","size":"624.8"},{"price":"0.68","size":"574"},{"price":"0.69","size":"594.2"},{"price":"0.7","size":"735.66"},{"price":"0.71","size":"918.6"},{"price":"0.72","size":"356.8"},{"price":"0.73","size":"869.2"},{"price":"0.74","size":"967.6"},{"price":"0.75","size":"1673.8"},{"price":"0.76","size":"869.2"},{"price":"0.77","size":"864.6"},{"price":"0.78","size":"870.2"},{"price":"0.79","size":"871.6"},{"price":"0.8","size":"987.2"},{"price":"0.81","size":"876.8"},{"price":"0.82","size":"1091.55"},{"price":"0.83","size":"958.39"},{"price":"0.84","size":"1119.39"},{"price":"0.85","size":"1149.13"},{"price":"0.86","size":"962.6"},{"price":"0.87","size":"995.8"},{"price":"0.88","size":"1105.55"},{"price":"0.89","size":"1124.49"},{"price":"0.9","size":"1191.79"},{"price":"0.91","size":"574.6"},{"price":"0.92","size":"3424.35"},{"price":"0.93","size":"3340.43"},{"price":"0.94","size":"3250.34"},{"price":"0.95","size":"3109.45"},{"price":"0.96","size":"4065.95"}],"asks":[{"price":"0.99","size":"30894.91"},{"price":"0.98","size":"8754.25"},{"price":"0.97","size":"90.3"}],"hash":"3962d3cd1e809690dd9dfdb2738fdd1c0df69797","timestamp":"1770839723160","event_type":"book","_sub_state":"active","_subscription_id":1,"_active_subscription_id":1},"parse_warnings":[],"out_of_order":false}
{"run_id":"29526913bab7446286864a321c124486","channel":"market","event_type":"price_change","market":"0x8032d8355d335c6ccbfc2508d99fbc87eb13f437bd275c93ee56fd1558e517ff","asset_id":null,"source":"market_ws:sub:active:1","t_event_ms":1770839723162,"t_recv_wall_ms":1770839723070,"t_recv_wall_iso":"2026-02-11T19:55:23.070Z","t_recv_mono_ns":618588411175916,"raw":{"market":"0x8032d8355d335c6ccbfc2508d99fbc87eb13f437bd275c93ee56fd1558e517ff","price_changes":[{"asset_id":"40652734036737240317526188612064032143639112324786051284480877037991580442979","price":"0.96","size":"4060.95","side":"BUY","hash":"3d65d9224ef3e10c831c2292cc14822608247f94","best_bid":"0.96","best_ask":"0.97"},{"asset_id":"20773614133833886322101538939702011175545796528197617633926164254913649353392","price":"0.04","size":"4060.95","side":"SELL","hash":"9aceb5f678e787c036ef6219a83ed5af23d8e3e4","best_bid":"0.03","best_ask":"0.04"}],"timestamp":"1770839723162","event_type":"price_change","_sub_state":"active","_subscription_id":1,"_active_subscription_id":1},"parse_warnings":[],"out_of_order":false}
{"run_id":"29526913bab7446286864a321c124486","channel":"market","event_type":"price_change","market":"0x8032d8355d335c6ccbfc2508d99fbc87eb13f437bd275c93ee56fd1558e517ff","asset_id":null,"source":"market_ws:sub:active:1","t_event_ms":1770839723163,"t_recv_wall_ms":1770839723070,"t_recv_wall_iso":"2026-02-11T19:55:23.070Z","t_recv_mono_ns":618588411454541,"raw":{"market":"0x8032d8355d335c6ccbfc2508d99fbc87eb13f437bd275c93ee56fd1558e517ff","price_changes":[{"asset_id":"40652734036737240317526188612064032143639112324786051284480877037991580442979","price":"0.96","size":"4000.95","side":"BUY","hash":"6a54abca8b7738c28005de072acacf9c9bb6cd38","best_bid":"0.96","best_ask":"0.97"},{"asset_id":"20773614133833886322101538939702011175545796528197617633926164254913649353392","price":"0.04","size":"4000.95","side":"SELL","hash":"59d28ea96c22dd74b27b58d87dcb1837e9e2a99b","best_bid":"0.03","best_ask":"0.04"}],"timestamp":"1770839723163","event_type":"price_change","_sub_state":"active","_subscription_id":1,"_active_subscription_id":1},"parse_warnings":[],"out_of_order":false}
{"run_id":"29526913bab7446286864a321c124486","channel":"market","event_type":"price_change","market":"0x8032d8355d335c6ccbfc2508d99fbc87eb13f437bd275c93ee56fd1558e517ff","asset_id":null,"source":"market_ws:sub:active:1","t_event_ms":1770839723165,"t_recv_wall_ms":1770839723070,"t_recv_wall_iso":"2026-02-11T19:55:23.070Z","t_recv_mono_ns":618588411603916,"raw":{"market":"0x8032d8355d335c6ccbfc2508d99fbc87eb13f437bd275c93ee56fd1558e517ff","price_changes":[{"asset_id":"40652734036737240317526188612064032143639112324786051284480877037991580442979","price":"0.83","size":"963.39","side":"BUY","hash":"b023c5c5129de55ce9f68b113a6b57cc150f338b","best_bid":"0.96","best_ask":"0.97"},{"asset_id":"20773614133833886322101538939702011175545796528197617633926164254913649353392","price":"0.17","size":"963.39","side":"SELL","hash":"9bf79e983a34ac541558daa8d4fc938bc6d6a106","best_bid":"0.03","best_ask":"0.04"}],"timestamp":"1770839723165","event_type":"price_change","_sub_state":"active","_subscription_id":1,"_active_subscription_id":1},"parse_warnings":[],"out_of_order":false}
{"run_id":"29526913bab7446286864a321c124486","channel":"market","event_type":"price_change","market":"0x8032d8355d335c6ccbfc2508d99fbc87eb13f437bd275c93ee56fd1558e517ff","asset_id":null,"source":"market_ws:sub:active:1","t_event_ms":1770839723167,"t_recv_wall_ms":1770839723072,"t_recv_wall_iso":"2026-02-11T19:55:23.072Z","t_recv_mono_ns":618588413050208,"raw":{"market":"0x8032d8355d335c6ccbfc2508d99fbc87eb13f437bd275c93ee56fd1558e517ff","price_changes":[{"asset_id":"40652734036737240317526188612064032143639112324786051284480877037991580442979","price":"0.96","size":"4060.95","side":"BUY","hash":"f91523afb610a1ee8d38403ebd9a99929c76de72","best_bid":"0.96","best_ask":"0.97"},{"asset_id":"20773614133833886322101538939702011175545796528197617633926164254913649353392","price":"0.04","size":"4060.95","side":"SELL","hash":"34515f039328ff94b08a19e2e7b59ea09f2cfe5e","best_bid":"0.03","best_ask":"0.04"}],"timestamp":"1770839723167","event_type":"price_change","_sub_state":"active","_subscription_id":1,"_active_subscription_id":1},"parse_warnings":[],"out_of_order":false}
{"run_id":"29526913bab7446286864a321c124486","channel":"market","event_type":"price_change","market":"0x8032d8355d335c6ccbfc2508d99fbc87eb13f437bd275c93ee56fd1558e517ff","asset_id":null,"source":"market_ws:sub:active:1","t_event_ms":1770839723187,"t_recv_wall_ms":1770839723095,"t_recv_wall_iso":"2026-02-11T19:55:23.095Z","t_recv_mono_ns":618588436495500,"raw":{"market":"0x8032d8355d335c6ccbfc2508d99fbc87eb13f437bd275c93ee56fd1558e517ff","price_changes":[{"asset_id":"20773614133833886322101538939702011175545796528197617633926164254913649353392","price":"0.03","size":"69.68","side":"BUY","hash":"41def389d5e25103660861bd10d25547a1395405","best_bid":"0.03","best_ask":"0.04"},{"asset_id":"40652734036737240317526188612064032143639112324786051284480877037991580442979","price":"0.97","size":"69.68","side":"SELL","hash":"6d4b6547c80170b699acd0d1fe463d4e93efb817","best_bid":"0.96","best_ask":"0.97"}],"timestamp":"1770839723187","event_type":"price_change","_sub_state":"active","_subscription_id":1,"_active_subscription_id":1},"parse_warnings":[],"out_of_order":false}
{"run_id":"29526913bab7446286864a321c124486","channel":"market","event_type":"book","market":"0x8032d8355d335c6ccbfc2508d99fbc87eb13f437bd275c93ee56fd1558e517ff","asset_id":"20773614133833886322101538939702011175545796528197617633926164254913649353392","source":"market_ws:sub:active:1","t_event_ms":1770839723187,"t_recv_wall_ms":1770839723095,"t_recv_wall_iso":"2026-02-11T19:55:23.095Z","t_recv_mono_ns":618588436689333,"raw":{"market":"0x8032d8355d335c6ccbfc2508d99fbc87eb13f437bd275c93ee56fd1558e517ff","asset_id":"20773614133833886322101538939702011175545796528197617633926164254913649353392","bids":[{"price":"0.01","size":"30894.91"},{"price":"0.02","size":"8754.25"},{"price":"0.03","size":"69.68"}],"asks":[{"price":"0.99","size":"30822.26"},{"price":"0.98","size":"12559.04"},{"price":"0.97","size":"7433.03"},{"price":"0.96","size":"5453.8"},{"price":"0.95","size":"6815.8"},{"price":"0.94","size":"5105"},{"price":"0.93","size":"5421.38"},{"price":"0.92","size":"5139.4"},{"price":"0.91","size":"5225.8"},{"price":"0.9","size":"5102.8"},{"price":"0.89","size":"120.6"},{"price":"0.88","size":"63.6"},{"price":"0.87","size":"63"},{"price":"0.86","size":"61.6"},{"price":"0.85","size":"107.39"},{"price":"0.84","size":"69.39"},{"price":"0.83","size":"58.39"},{"price":"0.82","size":"66.71"},{"price":"0.81","size":"56.8"},{"price":"0.8","size":"92.14"},{"price":"0.79","size":"60.8"},{"price":"0.78","size":"55.2"},{"price":"0.77","size":"64.48"},{"price":"0.76","size":"54.2"},{"price":"0.75","size":"375.8"},{"price":"0.74","size":"68.6"},{"price":"0.73","size":"53.2"},{"price":"0.72","size":"63.26"},{"price":"0.71","size":"52.6"},{"price":"0.7","size":"402.4"},{"price":"0.69","size":"72.2"},{"price":"0.68","size":"87.88"},{"price":"0.67","size":"188.46"},{"price":"0.66","size":"123.6"},{"price":"0.65","size":"317.03"},{"price":"0.64","size":"582.36"},{"price":"0.63","size":"559.2"},{"price":"0.62","size":"559"},{"price":"0.61","size":"594"},{"price":"0.6","size":"2915.41"},{"price":"0.59","size":"576.8"},{"price":"0.58","size":"575.5"},{"price":"0.57","size":"558.6"},{"price":"0.56","size":"572.68"},{"price":"0.55","size":"566.4"},{"price":"0.54","size":"561.94"},{"price":"0.53","size":"631.57"},{"price":"0.52","size":"611.4"},{"price":"0.51","size":"705.2"},{"price":"0.5","size":"1011.55"},{"price":"0.49","size":"692.4"},{"price":"0.48","size":"628.4"},{"price":"0.47","size":"633.4"},{"price":"0.46","size":"711.65"},{"price":"0.45","size":"866.59"},{"price":"0.44","size":"905.69"},{"price":"0.43","size":"641.6"},{"price":"0.42","size":"645.58"},{"price":"0.41","size":"564"},{"price":"0.4","size":"20642.9"},{"price":"0.39","size":"650.23"},{"price":"0.38","size":"593"},{"price":"0.37","size":"755.73"},{"price":"0.36","size":"558"},{"price":"0.35","size":"1144.32"},{"price":"0.34","size":"649.59"},{"price":"0.33","size":"624.8"},{"price":"0.32","size":"574"},{"price":"0.31","size":"594.2"},{"price":"0.3","size":"735.66"},{"price":"0.29","size":"918.6"},{"price":"0.28","size":"356.8"},{"price":"0.27","size":"869.2"},{"price":"0.26","size":"967.6"},{"price":"0.25","size":"1673.8"},{"price":"0.24","size":"869.2"},{"price":"0.23","size":"864.6"},{"price":"0.22","size":"870.2"},{"price":"0.21","size":"871.6"},{"price":"0.2","size":"987.2"},{"price":"0.19","size":"876.8"},{"price":"0.18","size":"1091.55"},{"price":"0.17","size":"963.39"},{"price":"0.16","size":"1119.39"},{"price":"0.15","size":"1149.13"},{"price":"0.14","size":"962.6"},{"price":"0.13","size":"995.8"},{"price":"0.12","size":"1105.55"},{"price":"0.11","size":"1124.49"},{"price":"0.1","size":"1191.79"},{"price":"0.09","size":"574.6"},{"price":"0.08","size":"3424.35"},{"price":"0.07","size":"3340.43"},{"price":"0.06","size":"3250.34"},{"price":"0.05","size":"3109.45"},{"price":"0.04","size":"4060.95"}],"hash":"41def389d5e25103660861bd10d25547a1395405","timestamp":"1770839723187","event_type":"book","_sub_state":"active","_subscription_id":1,"_active_subscription_id":1},"parse_warnings":[],"out_of_order":false}
{"run_id":"29526913bab7446286864a321c124486","channel":"market","event_type":"book","market":"0x8032d8355d335c6ccbfc2508d99fbc87eb13f437bd275c93ee56fd1558e517ff","asset_id":"40652734036737240317526188612064032143639112324786051284480877037991580442979","source":"market_ws:sub:active:1","t_event_ms":1770839723187,"t_recv_wall_ms":1770839723096,"t_recv_wall_iso":"2026-02-11T19:55:23.096Z","t_recv_mono_ns":618588437051375,"raw":{"market":"0x8032d8355d335c6ccbfc2508d99fbc87eb13f437bd275c93ee56fd1558e517ff","asset_id":"40652734036737240317526188612064032143639112324786051284480877037991580442979","bids":[{"price":"0.01","size":"30822.26"},{"price":"0.02","size":"12559.04"},{"price":"0.03","size":"7433.03"},{"price":"0.04","size":"5453.8"},{"price":"0.05","size":"6815.8"},{"price":"0.06","size":"5105"},{"price":"0.07","size":"5421.38"},{"price":"0.08","size":"5139.4"},{"price":"0.09","size":"5225.8"},{"price":"0.1","size":"5102.8"},{"price":"0.11","size":"120.6"},{"price":"0.12","size":"63.6"},{"price":"0.13","size":"63"},{"price":"0.14","size":"61.6"},{"price":"0.15","size":"107.39"},{"price":"0.16","size":"69.39"},{"price":"0.17","size":"58.39"},{"price":"0.18","size":"66.71"},{"price":"0.19","size":"56.8"},{"price":"0.2","size":"92.14"},{"price":"0.21","size":"60.8"},{"price":"0.22","size":"55.2"},{"price":"0.23","size":"64.48"},{"price":"0.24","size":"54.2"},{"price":"0.25","size":"375.8"},{"price":"0.26","size":"68.6"},{"price":"0.27","size":"53.2"},{"price":"0.28","size":"63.26"},{"price":"0.29","size":"52.6"},{"price":"0.3","size":"402.4"},{"price":"0.31","size":"72.2"},{"price":"0.32","size":"87.88"},{"price":"0.33","size":"188.46"},{"price":"0.34","size":"123.6"},{"price":"0.35","size":"317.03"},{"price":"0.36","size":"582.36"},{"price":"0.37","size":"559.2"},{"price":"0.38","size":"559"},{"price":"0.39","size":"594"},{"price":"0.4","size":"2915.41"},{"price":"0.41","size":"576.8"},{"price":"0.42","size":"575.5"},{"price":"0.43","size":"558.6"},{"price":"0.44","size":"572.68"},{"price":"0.45","size":"566.4"},{"price":"0.46","size":"561.94"},{"price":"0.47","size":"631.57"},{"price":"0.48","size":"611.4"},{"price":"0.49","size":"705.2"},{"price":"0.5","size":"1011.55"},{"price":"0.51","size":"692.4"},{"price":"0.52","size":"628.4"},{"price":"0.53","size":"633.4"},{"price":"0.54","size":"711.65"},{"price":"0.55","size":"866.59"},{"price":"0.56","size":"905.69"},{"price":"0.57","size":"641.6"},{"price":"0.58","size":"645.58"},{"price":"0.59","size":"564"},{"price":"0.6","size":"20642.9"},{"price":"0.61","size":"650.23"},{"price":"0.62","size":"593"},{"price":"0.63","size":"755.73"},{"price":"0.64","size":"558"},{"price":"0.65","size":"1144.32"},{"price":"0.66","size":"649.59"},{"price":"0.67","size":"624.8"},{"price":"0.68","size":"574"},{"price":"0.69","size":"594.2"},{"price":"0.7","size":"735.66"},{"price":"0.71","size":"918.6"},{"price":"0.72","size":"356.8"},{"price":"0.73","size":"869.2"},{"price":"0.74","size":"967.6"},{"price":"0.75","size":"1673.8"},{"price":"0.76","size":"869.2"},{"price":"0.77","size":"864.6"},{"price":"0.78","size":"870.2"},{"price":"0.79","size":"871.6"},{"price":"0.8","size":"987.2"},{"price":"0.81","size":"876.8"},{"price":"0.82","size":"1091.55"},{"price":"0.83","size":"963.39"},{"price":"0.84","size":"1119.39"},{"price":"0.85","size":"1149.13"},{"price":"0.86","size":"962.6"},{"price":"0.87","size":"995.8"},{"price":"0.88","size":"1105.55"},{"price":"0.89","size":"1124.49"},{"price":"0.9","size":"1191.79"},{"price":"0.91","size":"574.6"},{"price":"0.92","size":"3424.35"},{"price":"0.93","size":"3340.43"},{"price":"0.94","size":"3250.34"},{"price":"0.95","size":"3109.45"},{"price":"0.96","size":"4060.95"}],"asks":[{"price":"0.99","size":"30894.91"},{"price":"0.98","size":"8754.25"},{"price":"0.97","size":"69.68"}],"hash":"6d4b6547c80170b699acd0d1fe463d4e93efb817","timestamp":"1770839723187","event_type":"book","_sub_state":"active","_subscription_id":1,"_active_subscription_id":1},"parse_warnings":[],"out_of_order":false}
{"run_id":"29526913bab7446286864a321c124486","channel":"market","event_type":"price_change","market":"0x8032d8355d335c6ccbfc2508d99fbc87eb13f437bd275c93ee56fd1558e517ff","asset_id":null,"source":"market_ws:sub:active:1","t_event_ms":1770839723190,"t_recv_wall_ms":1770839723096,"t_recv_wall_iso":"2026-02-11T19:55:23.096Z","t_recv_mono_ns":618588437396791,"raw":{"market":"0x8032d8355d335c6ccbfc2508d99fbc87eb13f437bd275c93ee56fd1558e517ff","price_changes":[{"asset_id":"20773614133833886322101538939702011175545796528197617633926164254913649353392","price":"0.03","size":"64.68","side":"BUY","hash":"fd6be4d26945b654ff3132c17c2f454ec4511ed7","best_bid":"0.03","best_ask":"0.04"},{"asset_id":"40652734036737240317526188612064032143639112324786051284480877037991580442979","price":"0.97","size":"64.68","side":"SELL","hash":"a8a97cdb4377f9e6b6c6d4847b77ed6d29d29290","best_bid":"0.96","best_ask":"0.97"}],"timestamp":"1770839723190","event_type":"price_change","_sub_state":"active","_subscription_id":1,"_active_subscription_id":1},"parse_warnings":[],"out_of_order":false}
{"run_id":"29526913bab7446286864a321c124486","channel":"market","event_type":"last_trade_price","market":"0x8032d8355d335c6ccbfc2508d99fbc87eb13f437bd275c93ee56fd1558e517ff","asset_id":"20773614133833886322101538939702011175545796528197617633926164254913649353392","source":"market_ws:sub:unknown","t_event_ms":1770839723193,"t_recv_wall_ms":1770839723104,"t_recv_wall_iso":"2026-02-11T19:55:23.104Z","t_recv_mono_ns":618588445498666,"raw":{"market":"0x8032d8355d335c6ccbfc2508d99fbc87eb13f437bd275c93ee56fd1558e517ff","asset_id":"20773614133833886322101538939702011175545796528197617633926164254913649353392","price":"0.03","size":"42","fee_rate_bps":"1000","side":"SELL","timestamp":"1770839723193","event_type":"last_trade_price","transaction_hash":"0xffd95671582df54fd340d535a83fc41ba8289e12584ef5207f06ddf88826cf33","_sub_state":"unknown","_subscription_id":null,"_active_subscription_id":1},"parse_warnings":["unknown_message_schema"],"out_of_order":false}
{"run_id":"29526913bab7446286864a321c124486","channel":"market","event_type":"price_change","market":"0x8032d8355d335c6ccbfc2508d99fbc87eb13f437bd275c93ee56fd1558e517ff","asset_id":null,"source":"market_ws:sub:active:1","t_event_ms":1770839723193,"t_recv_wall_ms":1770839723105,"t_recv_wall_iso":"2026-02-11T19:55:23.105Z","t_recv_mono_ns":618588445810458,"raw":{"market":"0x8032d8355d335c6ccbfc2508d99fbc87eb13f437bd275c93ee56fd1558e517ff","price_changes":[{"asset_id":"40652734036737240317526188612064032143639112324786051284480877037991580442979","price":"0.94","size":"3245.34","side":"BUY","hash":"adfabe2629f11e34b97e994e644c4536f3b6912d","best_bid":"0.96","best_ask":"0.97"},{"asset_id":"20773614133833886322101538939702011175545796528197617633926164254913649353392","price":"0.06","size":"3245.34","side":"SELL","hash":"58d1031d31feb72103d0eddb92643930b6fde25d","best_bid":"0.03","best_ask":"0.04"}],"timestamp":"1770839723193","event_type":"price_change","_sub_state":"active","_subscription_id":1,"_active_subscription_id":1},"parse_warnings":[],"out_of_order":false}
{"run_id":"29526913bab7446286864a321c124486","channel":"market","event_type":"price_change","market":"0x8032d8355d335c6ccbfc2508d99fbc87eb13f437bd275c93ee56fd1558e517ff","asset_id":null,"source":"market_ws:sub:active:1","t_event_ms":1770839723197,"t_recv_wall_ms":1770839723105,"t_recv_wall_iso":"2026-02-11T19:55:23.105Z","t_recv_mono_ns":618588446031000,"raw":{"market":"0x8032d8355d335c6ccbfc2508d99fbc87eb13f437bd275c93ee56fd1558e517ff","price_changes":[{"asset_id":"40652734036737240317526188612064032143639112324786051284480877037991580442979","price":"0.96","size":"4000.95","side":"BUY","hash":"ad81d93522eec2e890fe924fbceb62630ec4ce7b","best_bid":"0.96","best_ask":"0.97"},{"asset_id":"20773614133833886322101538939702011175545796528197617633926164254913649353392","price":"0.04","size":"4000.95","side":"SELL","hash":"c18c33597178df8c8b8116183e1c581850233370","best_bid":"0.03","best_ask":"0.04"}],"timestamp":"1770839723197","event_type":"price_change","_sub_state":"active","_subscription_id":1,"_active_subscription_id":1},"parse_warnings":[],"out_of_order":false}
{"run_id":"29526913bab7446286864a321c124486","channel":"market","event_type":"price_change","market":"0x8032d8355d335c6ccbfc2508d99fbc87eb13f437bd275c93ee56fd1558e517ff","asset_id":null,"source":"market_ws:sub:active:1","t_event_ms":1770839723198,"t_recv_wall_ms":1770839723106,"t_recv_wall_iso":"2026-02-11T19:55:23.106Z","t_recv_mono_ns":618588447396250,"raw":{"market":"0x8032d8355d335c6ccbfc2508d99fbc87eb13f437bd275c93ee56fd1558e517ff","price_changes":[{"asset_id":"40652734036737240317526188612064032143639112324786051284480877037991580442979","price":"0.96","size":"4060.95","side":"BUY","hash":"f870aaa90c2a8dd78761a0e7825abb64e8bfe406","best_bid":"0.96","best_ask":"0.97"},{"asset_id":"20773614133833886322101538939702011175545796528197617633926164254913649353392","price":"0.04","size":"4060.95","side":"SELL","hash":"ca0c2d7d6d3b744f99977917f7caed380f31ba78","best_bid":"0.03","best_ask":"0.04"}],"timestamp":"1770839723198","event_type":"price_change","_sub_state":"active","_subscription_id":1,"_active_subscription_id":1},"parse_warnings":[],"out_of_order":false}
{"run_id":"29526913bab7446286864a321c124486","channel":"market","event_type":"price_change","market":"0x8032d8355d335c6ccbfc2508d99fbc87eb13f437bd275c93ee56fd1558e517ff","asset_id":null,"source":"market_ws:sub:active:1","t_event_ms":1770839723208,"t_recv_wall_ms":1770839723120,"t_recv_wall_iso":"2026-02-11T19:55:23.120Z","t_recv_mono_ns":618588461050583,"raw":{"market":"0x8032d8355d335c6ccbfc2508d99fbc87eb13f437bd275c93ee56fd1558e517ff","price_changes":[{"asset_id":"40652734036737240317526188612064032143639112324786051284480877037991580442979","price":"0.96","size":"4077.95","side":"BUY","hash":"16e6d54d4bb7e782b730b3228169bd09e7384047","best_bid":"0.96","best_ask":"0.97"},{"asset_id":"20773614133833886322101538939702011175545796528197617633926164254913649353392","price":"0.04","size":"4077.95","side":"SELL","hash":"99a04424709eb017d9da8f50e890fd3d14e1a5c8","best_bid":"0.03","best_ask":"0.04"}],"timestamp":"1770839723208","event_type":"price_change","_sub_state":"active","_subscription_id":1,"_active_subscription_id":1},"parse_warnings":[],"out_of_order":false}
{"run_id":"29526913bab7446286864a321c124486","channel":"market","event_type":"price_change","market":"0x8032d8355d335c6ccbfc2508d99fbc87eb13f437bd275c93ee56fd1558e517ff","asset_id":null,"source":"market_ws:sub:active:1","t_event_ms":1770839723214,"t_recv_wall_ms":1770839723120,"t_recv_wall_iso":"2026-02-11T19:55:23.120Z","t_recv_mono_ns":618588461327166,"raw":{"market":"0x8032d8355d335c6ccbfc2508d99fbc87eb13f437bd275c93ee56fd1558e517ff","price_changes":[{"asset_id":"40652734036737240317526188612064032143639112324786051284480877037991580442979","price":"0.96","size":"4082.95","side":"BUY","hash":"e87b41f71a3d8c6032dca36f9f552279bb26aafb","best_bid":"0.96","best_ask":"0.97"},{"asset_id":"20773614133833886322101538939702011175545796528197617633926164254913649353392","price":"0.04","size":"4082.95","side":"SELL","hash":"8f455a4a1b1c5b376816a558a861d1481cada2de","best_bid":"0.03","best_ask":"0.04"}],"timestamp":"1770839723214","event_type":"price_change","_sub_state":"active","_subscription_id":1,"_active_subscription_id":1},"parse_warnings":[],"out_of_order":false}
{"run_id":"29526913bab7446286864a321c124486","channel":"market","event_type":"price_change","market":"0x8032d8355d335c6ccbfc2508d99fbc87eb13f437bd275c93ee56fd1558e517ff","asset_id":null,"source":"market_ws:sub:active:1","t_event_ms":1770839723219,"t_recv_wall_ms":1770839723123,"t_recv_wall_iso":"2026-02-11T19:55:23.123Z","t_recv_mono_ns":618588464204416,"raw":{"market":"0x8032d8355d335c6ccbfc2508d99fbc87eb13f437bd275c93ee56fd1558e517ff","price_changes":[{"asset_id":"20773614133833886322101538939702011175545796528197617633926164254913649353392","price":"0.02","size":"8759.25","side":"BUY","hash":"c4db76525261e565ef1b4219a8e89a3f7918331e","best_bid":"0.03","best_ask":"0.04"},{"asset_id":"40652734036737240317526188612064032143639112324786051284480877037991580442979","price":"0.98","size":"8759.25","side":"SELL","hash":"d4e2707e120a5e8c3ee082b79ec0e4b4e46341f8","best_bid":"0.96","best_ask":"0.97"}],"timestamp":"1770839723219","event_type":"price_change","_sub_state":"active","_subscription_id":1,"_active_subscription_id":1},"parse_warnings":[],"out_of_order":false}
{"run_id":"29526913bab7446286864a321c124486","channel":"market","event_type":"last_trade_price","market":"0x8032d8355d335c6ccbfc2508d99fbc87eb13f437bd275c93ee56fd1558e517ff","asset_id":"40652734036737240317526188612064032143639112324786051284480877037991580442979","source":"market_ws:sub:unknown","t_event_ms":1770839723227,"t_recv_wall_ms":1770839723146,"t_recv_wall_iso":"2026-02-11T19:55:23.146Z","t_recv_mono_ns":618588487483666,"raw":{"market":"0x8032d8355d335c6ccbfc2508d99fbc87eb13f437bd275c93ee56fd1558e517ff","asset_id":"40652734036737240317526188612064032143639112324786051284480877037991580442979","price":"0.97","size":"20.618533","fee_rate_bps":"1000","side":"BUY","timestamp":"1770839723227","event_type":"last_trade_price","transaction_hash":"0x49016e14d9a1f09bdc331b74a8a41d66a6936a92ee9e71267b9ef5281db6ca30","_sub_state":"unknown","_subscription_id":null,"_active_subscription_id":1},"parse_warnings":["unknown_message_schema"],"out_of_order":false}
{"run_id":"29526913bab7446286864a321c124486","channel":"market","event_type":"price_change","market":"0x8032d8355d335c6ccbfc2508d99fbc87eb13f437bd275c93ee56fd1558e517ff","asset_id":null,"source":"market_ws:sub:active:1","t_event_ms":1770839723247,"t_recv_wall_ms":1770839723156,"t_recv_wall_iso":"2026-02-11T19:55:23.156Z","t_recv_mono_ns":618588497672958,"raw":{"market":"0x8032d8355d335c6ccbfc2508d99fbc87eb13f437bd275c93ee56fd1558e517ff","price_changes":[{"asset_id":"40652734036737240317526188612064032143639112324786051284480877037991580442979","price":"0.96","size":"4022.95","side":"BUY","hash":"3069fdaeb4676aa1a83ec1328f699f643c4cf60a","best_bid":"0.96","best_ask":"0.97"},{"asset_id":"20773614133833886322101538939702011175545796528197617633926164254913649353392","price":"0.04","size":"4022.95","side":"SELL","hash":"ae736a22e71fddd95f4c1f8352253289f644a62e","best_bid":"0.03","best_ask":"0.04"}],"timestamp":"1770839723247","event_type":"price_change","_sub_state":"active","_subscription_id":1,"_active_subscription_id":1},"parse_warnings":[],"out_of_order":false}
{"run_id":"29526913bab7446286864a321c124486","channel":"market","event_type":"price_change","market":"0x8032d8355d335c6ccbfc2508d99fbc87eb13f437bd275c93ee56fd1558e517ff","asset_id":null,"source":"market_ws:sub:active:1","t_event_ms":1770839723250,"t_recv_wall_ms":1770839723157,"t_recv_wall_iso":"2026-02-11T19:55:23.157Z","t_recv_mono_ns":618588497874708,"raw":{"market":"0x8032d8355d335c6ccbfc2508d99fbc87eb13f437bd275c93ee56fd1558e517ff","price_changes":[{"asset_id":"40652734036737240317526188612064032143639112324786051284480877037991580442979","price":"0.96","size":"4082.95","side":"BUY","hash":"b569d2168ff0f403554bbfb4615e6a9bad23f06f","best_bid":"0.96","best_ask":"0.97"},{"asset_id":"20773614133833886322101538939702011175545796528197617633926164254913649353392","price":"0.04","size":"4082.95","side":"SELL","hash":"2ac64a8fb465704808731fe4b14f954f9438240c","best_bid":"0.03","best_ask":"0.04"}],"timestamp":"1770839723250","event_type":"price_change","_sub_state":"active","_subscription_id":1,"_active_subscription_id":1},"parse_warnings":[],"out_of_order":false}
{"run_id":"29526913bab7446286864a321c124486","channel":"market","event_type":"price_change","market":"0x8032d8355d335c6ccbfc2508d99fbc87eb13f437bd275c93ee56fd1558e517ff","asset_id":null,"source":"market_ws:sub:active:1","t_event_ms":1770839723253,"t_recv_wall_ms":1770839723159,"t_recv_wall_iso":"2026-02-11T19:55:23.159Z","t_recv_mono_ns":618588500005083,"raw":{"market":"0x8032d8355d335c6ccbfc2508d99fbc87eb13f437bd275c93ee56fd1558e517ff","price_changes":[{"asset_id":"40652734036737240317526188612064032143639112324786051284480877037991580442979","price":"0.94","size":"3250.34","side":"BUY","hash":"d76abdf8ba2a2ac2a5b50bb90f920fe6a0b9f247","best_bid":"0.96","best_ask":"0.97"},{"asset_id":"20773614133833886322101538939702011175545796528197617633926164254913649353392","price":"0.06","size":"3250.34","side":"SELL","hash":"66cb47dc42bce1eb5286a78912bd951a76909a45","best_bid":"0.03","best_ask":"0.04"}],"timestamp":"1770839723253","event_type":"price_change","_sub_state":"active","_subscription_id":1,"_active_subscription_id":1},"parse_warnings":[],"out_of_order":false}
{"run_id":"29526913bab7446286864a321c124486","channel":"market","event_type":"price_change","market":"0x8032d8355d335c6ccbfc2508d99fbc87eb13f437bd275c93ee56fd1558e517ff","asset_id":null,"source":"market_ws:sub:active:1","t_event_ms":1770839723255,"t_recv_wall_ms":1770839723162,"t_recv_wall_iso":"2026-02-11T19:55:23.162Z","t_recv_mono_ns":618588503344916,"raw":{"market":"0x8032d8355d335c6ccbfc2508d99fbc87eb13f437bd275c93ee56fd1558e517ff","price_changes":[{"asset_id":"40652734036737240317526188612064032143639112324786051284480877037991580442979","price":"0.83","size":"958.39","side":"BUY","hash":"baa6201bfd49527e6c29c84f08b85c55d4d6ffac","best_bid":"0.96","best_ask":"0.97"},{"asset_id":"20773614133833886322101538939702011175545796528197617633926164254913649353392","price":"0.17","size":"958.39","side":"SELL","hash":"150f57d8cae247ab35edd722d35fbb4cbba54672","best_bid":"0.03","best_ask":"0.04"}],"timestamp":"1770839723255","event_type":"price_change","_sub_state":"active","_subscription_id":1,"_active_subscription_id":1},"parse_warnings":[],"out_of_order":false}
{"run_id":"29526913bab7446286864a321c124486","channel":"market","event_type":"price_change","market":"0x8032d8355d335c6ccbfc2508d99fbc87eb13f437bd275c93ee56fd1558e517ff","asset_id":null,"source":"market_ws:sub:active:1","t_event_ms":1770839723278,"t_recv_wall_ms":1770839723187,"t_recv_wall_iso":"2026-02-11T19:55:23.187Z","t_recv_mono_ns":618588528183333,"raw":{"market":"0x8032d8355d335c6ccbfc2508d99fbc87eb13f437bd275c93ee56fd1558e517ff","price_changes":[{"asset_id":"40652734036737240317526188612064032143639112324786051284480877037991580442979","price":"0.95","size":"3175.79","side":"BUY","hash":"e7be3180a1d8227b1fafd17eb15368295d2aa469","best_bid":"0.96","best_ask":"0.97"},{"asset_id":"20773614133833886322101538939702011175545796528197617633926164254913649353392","price":"0.05","size":"3175.79","side":"SELL","hash":"4ad5b5675c312d6fefff40d97fa9cf7c244b8110","best_bid":"0.03","best_ask":"0.04"}],"timestamp":"1770839723278","event_type":"price_change","_sub_state":"active","_subscription_id":1,"_active_subscription_id":1},"parse_warnings":[],"out_of_order":false}
{"run_id":"29526913bab7446286864a321c124486","channel":"market","event_type":"price_change","market":"0x8032d8355d335c6ccbfc2508d99fbc87eb13f437bd275c93ee56fd1558e517ff","asset_id":null,"source":"market_ws:sub:active:1","t_event_ms":1770839723280,"t_recv_wall_ms":1770839723187,"t_recv_wall_iso":"2026-02-11T19:55:23.187Z","t_recv_mono_ns":618588528597250,"raw":{"market":"0x8032d8355d335c6ccbfc2508d99fbc87eb13f437bd275c93ee56fd1558e517ff","price_changes":[{"asset_id":"40652734036737240317526188612064032143639112324786051284480877037991580442979","price":"0.96","size":"4022.95","side":"BUY","hash":"5f01959ec1cae57e106978de5b73389308834c5d","best_bid":"0.96","best_ask":"0.97"},{"asset_id":"20773614133833886322101538939702011175545796528197617633926164254913649353392","price":"0.04","size":"4022.95","side":"SELL","hash":"6594c83240998e1f4e15c449b9dad9e3f81a3b13","best_bid":"0.03","best_ask":"0.04"}],"timestamp":"1770839723280","event_type":"price_change","_sub_state":"active","_subscription_id":1,"_active_subscription_id":1},"parse_warnings":[],"out_of_order":false}
{"run_id":"29526913bab7446286864a321c124486","channel":"market","event_type":"price_change","market":"0x8032d8355d335c6ccbfc2508d99fbc87eb13f437bd275c93ee56fd1558e517ff","asset_id":null,"source":"market_ws:sub:active:1","t_event_ms":1770839723281,"t_recv_wall_ms":1770839723188,"t_recv_wall_iso":"2026-02-11T19:55:23.188Z","t_recv_mono_ns":618588529068250,"raw":{"market":"0x8032d8355d335c6ccbfc2508d99fbc87eb13f437bd275c93ee56fd1558e517ff","price_changes":[{"asset_id":"40652734036737240317526188612064032143639112324786051284480877037991580442979","price":"0.96","size":"4082.95","side":"BUY","hash":"293f1c9b10d5cc8a4f4d830a504f2f86fc105a5a","best_bid":"0.96","best_ask":"0.97"},{"asset_id":"20773614133833886322101538939702011175545796528197617633926164254913649353392","price":"0.04","size":"4082.95","side":"SELL","hash":"4d04ed65092999ad44a706afe2bd302d644c293d","best_bid":"0.03","best_ask":"0.04"}],"timestamp":"1770839723281","event_type":"price_change","_sub_state":"active","_subscription_id":1,"_active_subscription_id":1},"parse_warnings":[],"out_of_order":false}
{"run_id":"29526913bab7446286864a321c124486","channel":"market","event_type":"price_change","market":"0x8032d8355d335c6ccbfc2508d99fbc87eb13f437bd275c93ee56fd1558e517ff","asset_id":null,"source":"market_ws:sub:active:1","t_event_ms":1770839723283,"t_recv_wall_ms":1770839723188,"t_recv_wall_iso":"2026-02-11T19:55:23.188Z","t_recv_mono_ns":618588529426875,"raw":{"market":"0x8032d8355d335c6ccbfc2508d99fbc87eb13f437bd275c93ee56fd1558e517ff","price_changes":[{"asset_id":"40652734036737240317526188612064032143639112324786051284480877037991580442979","price":"0.95","size":"3109.79","side":"BUY","hash":"c346252bb929786405a7e0f73585a0c605eec599","best_bid":"0.96","best_ask":"0.97"},{"asset_id":"20773614133833886322101538939702011175545796528197617633926164254913649353392","price":"0.05","size":"3109.79","side":"SELL","hash":"a12b4484a15cfd891666cb162e38322174746342","best_bid":"0.03","best_ask":"0.04"}],"timestamp":"1770839723283","event_type":"price_change","_sub_state":"active","_subscription_id":1,"_active_subscription_id":1},"parse_warnings":[],"out_of_order":false}
{"run_id":"29526913bab7446286864a321c124486","channel":"market","event_type":"price_change","market":"0x8032d8355d335c6ccbfc2508d99fbc87eb13f437bd275c93ee56fd1558e517ff","asset_id":null,"source":"market_ws:sub:active:1","t_event_ms":1770839723284,"t_recv_wall_ms":1770839723192,"t_recv_wall_iso":"2026-02-11T19:55:23.192Z","t_recv_mono_ns":618588532870208,"raw":{"market":"0x8032d8355d335c6ccbfc2508d99fbc87eb13f437bd275c93ee56fd1558e517ff","price_changes":[{"asset_id":"40652734036737240317526188612064032143639112324786051284480877037991580442979","price":"0.96","size":"4142.95","side":"BUY","hash":"120463be4a421d9290f25744e4dba6111f75fadb","best_bid":"0.96","best_ask":"0.97"},{"asset_id":"20773614133833886322101538939702011175545796528197617633926164254913649353392","price":"0.04","size":"4142.95","side":"SELL","hash":"0f6f109187d757a811585881ad8108ffa0225180","best_bid":"0.03","best_ask":"0.04"}],"timestamp":"1770839723284","event_type":"price_change","_sub_state":"active","_subscription_id":1,"_active_subscription_id":1},"parse_warnings":[],"out_of_order":false}
{"run_id":"29526913bab7446286864a321c124486","channel":"market","event_type":"price_change","market":"0x8032d8355d335c6ccbfc2508d99fbc87eb13f437bd275c93ee56fd1558e517ff","asset_id":null,"source":"market_ws:sub:active:1","t_event_ms":1770839723286,"t_recv_wall_ms":1770839723192,"t_recv_wall_iso":"2026-02-11T19:55:23.192Z","t_recv_mono_ns":618588533182458,"raw":{"market":"0x8032d8355d335c6ccbfc2508d99fbc87eb13f437bd275c93ee56fd1558e517ff","price_changes":[{"asset_id":"40652734036737240317526188612064032143639112324786051284480877037991580442979","price":"0.96","size":"4082.95","side":"BUY","hash":"40a01760f1eadc86b78f6c9aefeb0c98da8dab29","best_bid":"0.96","best_ask":"0.97"},{"asset_id":"20773614133833886322101538939702011175545796528197617633926164254913649353392","price":"0.04","size":"4082.95","side":"SELL","hash":"e0a8441f0ff78d39b3f8b166f563d601b4a428e0","best_bid":"0.03","best_ask":"0.04"}],"timestamp":"1770839723286","event_type":"price_change","_sub_state":"active","_subscription_id":1,"_active_subscription_id":1},"parse_warnings":[],"out_of_order":false}
{"run_id":"29526913bab7446286864a321c124486","channel":"market","event_type":"price_change","market":"0x8032d8355d335c6ccbfc2508d99fbc87eb13f437bd275c93ee56fd1558e517ff","asset_id":null,"source":"market_ws:sub:active:1","t_event_ms":1770839723311,"t_recv_wall_ms":1770839723216,"t_recv_wall_iso":"2026-02-11T19:55:23.216Z","t_recv_mono_ns":618588556997291,"raw":{"market":"0x8032d8355d335c6ccbfc2508d99fbc87eb13f437bd275c93ee56fd1558e517ff","price_changes":[{"asset_id":"40652734036737240317526188612064032143639112324786051284480877037991580442979","price":"0.96","size":"4022.95","side":"BUY","hash":"ea9ad7fdcee8a305617820eba4742536446b3b97","best_bid":"0.96","best_ask":"0.97"},{"asset_id":"20773614133833886322101538939702011175545796528197617633926164254913649353392","price":"0.04","size":"4022.95","side":"SELL","hash":"9e971bcae1171ef36e1c431f1e046dd798bd6cbe","best_bid":"0.03","best_ask":"0.04"}],"timestamp":"1770839723311","event_type":"price_change","_sub_state":"active","_subscription_id":1,"_active_subscription_id":1},"parse_warnings":[],"out_of_order":false}
{"run_id":"29526913bab7446286864a321c124486","channel":"market","event_type":"price_change","market":"0x8032d8355d335c6ccbfc2508d99fbc87eb13f437bd275c93ee56fd1558e517ff","asset_id":null,"source":"market_ws:sub:active:1","t_event_ms":1770839723315,"t_recv_wall_ms":1770839723220,"t_recv_wall_iso":"2026-02-11T19:55:23.220Z","t_recv_mono_ns":618588561188291,"raw":{"market":"0x8032d8355d335c6ccbfc2508d99fbc87eb13f437bd275c93ee56fd1558e517ff","price_changes":[{"asset_id":"40652734036737240317526188612064032143639112324786051284480877037991580442979","price":"0.96","size":"4082.95","side":"BUY","hash":"7b900208a6dbb99c6a4fe3b09ddc4c8b45b2e872","best_bid":"0.96","best_ask":"0.97"},{"asset_id":"20773614133833886322101538939702011175545796528197617633926164254913649353392","price":"0.04","size":"4082.95","side":"SELL","hash":"8392ef9aba69495dbee649e7359627c05b2b3104","best_bid":"0.03","best_ask":"0.04"}],"timestamp":"1770839723315","event_type":"price_change","_sub_state":"active","_subscription_id":1,"_active_subscription_id":1},"parse_warnings":[],"out_of_order":false}
{"run_id":"29526913bab7446286864a321c124486","channel":"market","event_type":"price_change","market":"0x8032d8355d335c6ccbfc2508d99fbc87eb13f437bd275c93ee56fd1558e517ff","asset_id":null,"source":"market_ws:sub:active:1","t_event_ms":1770839723327,"t_recv_wall_ms":1770839723231,"t_recv_wall_iso":"2026-02-11T19:55:23.231Z","t_recv_mono_ns":618588571910500,"raw":{"market":"0x8032d8355d335c6ccbfc2508d99fbc87eb13f437bd275c93ee56fd1558e517ff","price_changes":[{"asset_id":"40652734036737240317526188612064032143639112324786051284480877037991580442979","price":"0.71","size":"924.6","side":"BUY","hash":"7e0f59736fb612eed230773315ea61a979391017","best_bid":"0.96","best_ask":"0.97"},{"asset_id":"20773614133833886322101538939702011175545796528197617633926164254913649353392","price":"0.29","size":"924.6","side":"SELL","hash":"57d1607d1a2a42e6e2cd0c2e0977fa7d3c9943aa","best_bid":"0.03","best_ask":"0.04"}],"timestamp":"1770839723327","event_type":"price_change","_sub_state":"active","_subscription_id":1,"_active_subscription_id":1},"parse_warnings":[],"out_of_order":false}
{"run_id":"29526913bab7446286864a321c124486","channel":"market","event_type":"price_change","market":"0x8032d8355d335c6ccbfc2508d99fbc87eb13f437bd275c93ee56fd1558e517ff","asset_id":null,"source":"market_ws:sub:active:1","t_event_ms":1770839723333,"t_recv_wall_ms":1770839723238,"t_recv_wall_iso":"2026-02-11T19:55:23.238Z","t_recv_mono_ns":618588579629458,"raw":{"market":"0x8032d8355d335c6ccbfc2508d99fbc87eb13f437bd275c93ee56fd1558e517ff","price_changes":[{"asset_id":"40652734036737240317526188612064032143639112324786051284480877037991580442979","price":"0.91","size":"589.6","side":"BUY","hash":"3061b97bf38790ef70b63d66442471a7512e375c","best_bid":"0.96","best_ask":"0.97"},{"asset_id":"20773614133833886322101538939702011175545796528197617633926164254913649353392","price":"0.09","size":"589.6","side":"SELL","hash":"f6ad1c4e4913509fe11e1bb7708fa49e5948a855","best_bid":"0.03","best_ask":"0.04"}],"timestamp":"1770839723333","event_type":"price_change","_sub_state":"active","_subscription_id":1,"_active_subscription_id":1},"parse_warnings":[],"out_of_order":false}
{"run_id":"29526913bab7446286864a321c124486","channel":"market","event_type":"price_change","market":"0x8032d8355d335c6ccbfc2508d99fbc87eb13f437bd275c93ee56fd1558e517ff","asset_id":null,"source":"market_ws:sub:active:1","t_event_ms":1770839723342,"t_recv_wall_ms":1770839723258,"t_recv_wall_iso":"2026-02-11T19:55:23.258Z","t_recv_mono_ns":618588599319958,"raw":{"market":"0x8032d8355d335c6ccbfc2508d99fbc87eb13f437bd275c93ee56fd1558e517ff","price_changes":[{"asset_id":"40652734036737240317526188612064032143639112324786051284480877037991580442979","price":"0.96","size":"4022.95","side":"BUY","hash":"842cd25fe32a28d75ebcd5ae4b3a75684ffc2301","best_bid":"0.96","best_ask":"0.97"},{"asset_id":"20773614133833886322101538939702011175545796528197617633926164254913649353392","price":"0.04","size":"4022.95","side":"SELL","hash":"f4c4d3c63ec6945c7452787e413db9263d562d3d","best_bid":"0.03","best_ask":"0.04"}],"timestamp":"1770839723342","event_type":"price_change","_sub_state":"active","_subscription_id":1,"_active_subscription_id":1},"parse_warnings":[],"out_of_order":false}
{"run_id":"29526913bab7446286864a321c124486","channel":"market","event_type":"price_change","market":"0x8032d8355d335c6ccbfc2508d99fbc87eb13f437bd275c93ee56fd1558e517ff","asset_id":null,"source":"market_ws:sub:active:1","t_event_ms":1770839723346,"t_recv_wall_ms":1770839723258,"t_recv_wall_iso":"2026-02-11T19:55:23.258Z","t_recv_mono_ns":618588599570458,"raw":{"market":"0x8032d8355d335c6ccbfc2508d99fbc87eb13f437bd275c93ee56fd1558e517ff","price_changes":[{"asset_id":"20773614133833886322101538939702011175545796528197617633926164254913649353392","price":"0.03","size":"57.68","side":"BUY","hash":"b858fbc1d0479d0f49687d51fc336f290af4a175","best_bid":"0.03","best_ask":"0.04"},{"asset_id":"40652734036737240317526188612064032143639112324786051284480877037991580442979","price":"0.97","size":"57.68","side":"SELL","hash":"29c546e670f46d15394b199d65c7462d05993e25","best_bid":"0.96","best_ask":"0.97"}],"timestamp":"1770839723346","event_type":"price_change","_sub_state":"active","_subscription_id":1,"_active_subscription_id":1},"parse_warnings":[],"out_of_order":false}
{"run_id":"29526913bab7446286864a321c124486","channel":"market","event_type":"book","market":"0x8032d8355d335c6ccbfc2508d99fbc87eb13f437bd275c93ee56fd1558e517ff","asset_id":"20773614133833886322101538939702011175545796528197617633926164254913649353392","source":"market_ws:sub:active:1","t_event_ms":1770839723346,"t_recv_wall_ms":1770839723258,"t_recv_wall_iso":"2026-02-11T19:55:23.258Z","t_recv_mono_ns":618588599707000,"raw":{"market":"0x8032d8355d335c6ccbfc2508d99fbc87eb13f437bd275c93ee56fd1558e517ff","asset_id":"20773614133833886322101538939702011175545796528197617633926164254913649353392","bids":[{"price":"0.01","size":"30894.91"},{"price":"0.02","size":"8759.25"},{"price":"0.03","size":"57.68"}],"asks":[{"price":"0.99","size":"30822.26"},{"price":"0.98","size":"12559.04"},{"price":"0.97","size":"7433.03"},{"price":"0.96","size":"5453.8"},{"price":"0.95","size":"6815.8"},{"price":"0.94","size":"5105"},{"price":"0.93","size":"5421.38"},{"price":"0.92","size":"5139.4"},{"price":"0.91","size":"5225.8"},{"price":"0.9","size":"5102.8"},{"price":"0.89","size":"120.6"},{"price":"0.88","size":"63.6"},{"price":"0.87","size":"63"},{"price":"0.86","size":"61.6"},{"price":"0.85","size":"107.39"},{"price":"0.84","size":"69.39"},{"price":"0.83","size":"58.39"},{"price":"0.82","size":"66.71"},{"price":"0.81","size":"56.8"},{"price":"0.8","size":"92.14"},{"price":"0.79","size":"60.8"},{"price":"0.78","size":"55.2"},{"price":"0.77","size":"64.48"},{"price":"0.76","size":"54.2"},{"price":"0.75","size":"375.8"},{"price":"0.74","size":"68.6"},{"price":"0.73","size":"53.2"},{"price":"0.72","size":"63.26"},{"price":"0.71","size":"52.6"},{"price":"0.7","size":"402.4"},{"price":"0.69","size":"72.2"},{"price":"0.68","size":"87.88"},{"price":"0.67","size":"188.46"},{"price":"0.66","size":"123.6"},{"price":"0.65","size":"317.03"},{"price":"0.64","size":"582.36"},{"price":"0.63","size":"559.2"},{"price":"0.62","size":"559"},{"price":"0.61","size":"594"},{"price":"0.6","size":"2915.41"},{"price":"0.59","size":"576.8"},{"price":"0.58","size":"575.5"},{"price":"0.57","size":"558.6"},{"price":"0.56","size":"572.68"},{"price":"0.55","size":"566.4"},{"price":"0.54","size":"561.94"},{"price":"0.53","size":"631.57"},{"price":"0.52","size":"611.4"},{"price":"0.51","size":"705.2"},{"price":"0.5","size":"1011.55"},{"price":"0.49","size":"692.4"},{"price":"0.48","size":"628.4"},{"price":"0.47","size":"633.4"},{"price":"0.46","size":"711.65"},{"price":"0.45","size":"866.59"},{"price":"0.44","size":"905.69"},{"price":"0.43","size":"641.6"},{"price":"0.42","size":"645.58"},{"price":"0.41","size":"564"},{"price":"0.4","size":"20642.9"},{"price":"0.39","size":"650.23"},{"price":"0.38","size":"593"},{"price":"0.37","size":"755.73"},{"price":"0.36","size":"558"},{"price":"0.35","size":"1144.32"},{"price":"0.34","size":"649.59"},{"price":"0.33","size":"624.8"},{"price":"0.32","size":"574"},{"price":"0.31","size":"594.2"},{"price":"0.3","size":"735.66"},{"price":"0.29","size":"924.6"},{"price":"0.28","size":"356.8"},{"price":"0.27","size":"869.2"},{"price":"0.26","size":"967.6"},{"price":"0.25","size":"1673.8"},{"price":"0.24","size":"869.2"},{"price":"0.23","size":"864.6"},{"price":"0.22","size":"870.2"},{"price":"0.21","size":"871.6"},{"price":"0.2","size":"987.2"},{"price":"0.19","size":"876.8"},{"price":"0.18","size":"1091.55"},{"price":"0.17","size":"958.39"},{"price":"0.16","size":"1119.39"},{"price":"0.15","size":"1149.13"},{"price":"0.14","size":"962.6"},{"price":"0.13","size":"995.8"},{"price":"0.12","size":"1105.55"},{"price":"0.11","size":"1124.49"},{"price":"0.1","size":"1191.79"},{"price":"0.09","size":"589.6"},{"price":"0.08","size":"3424.35"},{"price":"0.07","size":"3340.43"},{"price":"0.06","size":"3250.34"},{"price":"0.05","size":"3109.79"},{"price":"0.04","size":"4022.95"}],"hash":"b858fbc1d0479d0f49687d51fc336f290af4a175","timestamp":"1770839723346","event_type":"book","_sub_state":"active","_subscription_id":1,"_active_subscription_id":1},"parse_warnings":[],"out_of_order":false}
{"run_id":"29526913bab7446286864a321c124486","channel":"market","event_type":"book","market":"0x8032d8355d335c6ccbfc2508d99fbc87eb13f437bd275c93ee56fd1558e517ff","asset_id":"40652734036737240317526188612064032143639112324786051284480877037991580442979","source":"market_ws:sub:active:1","t_event_ms":1770839723346,"t_recv_wall_ms":1770839723259,"t_recv_wall_iso":"2026-02-11T19:55:23.259Z","t_recv_mono_ns":618588600134375,"raw":{"market":"0x8032d8355d335c6ccbfc2508d99fbc87eb13f437bd275c93ee56fd1558e517ff","asset_id":"40652734036737240317526188612064032143639112324786051284480877037991580442979","bids":[{"price":"0.01","size":"30822.26"},{"price":"0.02","size":"12559.04"},{"price":"0.03","size":"7433.03"},{"price":"0.04","size":"5453.8"},{"price":"0.05","size":"6815.8"},{"price":"0.06","size":"5105"},{"price":"0.07","size":"5421.38"},{"price":"0.08","size":"5139.4"},{"price":"0.09","size":"5225.8"},{"price":"0.1","size":"5102.8"},{"price":"0.11","size":"120.6"},{"price":"0.12","size":"63.6"},{"price":"0.13","size":"63"},{"price":"0.14","size":"61.6"},{"price":"0.15","size":"107.39"},{"price":"0.16","size":"69.39"},{"price":"0.17","size":"58.39"},{"price":"0.18","size":"66.71"},{"price":"0.19","size":"56.8"},{"price":"0.2","size":"92.14"},{"price":"0.21","size":"60.8"},{"price":"0.22","size":"55.2"},{"price":"0.23","size":"64.48"},{"price":"0.24","size":"54.2"},{"price":"0.25","size":"375.8"},{"price":"0.26","size":"68.6"},{"price":"0.27","size":"53.2"},{"price":"0.28","size":"63.26"},{"price":"0.29","size":"52.6"},{"price":"0.3","size":"402.4"},{"price":"0.31","size":"72.2"},{"price":"0.32","size":"87.88"},{"price":"0.33","size":"188.46"},{"price":"0.34","size":"123.6"},{"price":"0.35","size":"317.03"},{"price":"0.36","size":"582.36"},{"price":"0.37","size":"559.2"},{"price":"0.38","size":"559"},{"price":"0.39","size":"594"},{"price":"0.4","size":"2915.41"},{"price":"0.41","size":"576.8"},{"price":"0.42","size":"575.5"},{"price":"0.43","size":"558.6"},{"price":"0.44","size":"572.68"},{"price":"0.45","size":"566.4"},{"price":"0.46","size":"561.94"},{"price":"0.47","size":"631.57"},{"price":"0.48","size":"611.4"},{"price":"0.49","size":"705.2"},{"price":"0.5","size":"1011.55"},{"price":"0.51","size":"692.4"},{"price":"0.52","size":"628.4"},{"price":"0.53","size":"633.4"},{"price":"0.54","size":"711.65"},{"price":"0.55","size":"866.59"},{"price":"0.56","size":"905.69"},{"price":"0.57","size":"641.6"},{"price":"0.58","size":"645.58"},{"price":"0.59","size":"564"},{"price":"0.6","size":"20642.9"},{"price":"0.61","size":"650.23"},{"price":"0.62","size":"593"},{"price":"0.63","size":"755.73"},{"price":"0.64","size":"558"},{"price":"0.65","size":"1144.32"},{"price":"0.66","size":"649.59"},{"price":"0.67","size":"624.8"},{"price":"0.68","size":"574"},{"price":"0.69","size":"594.2"},{"price":"0.7","size":"735.66"},{"price":"0.71","size":"924.6"},{"price":"0.72","size":"356.8"},{"price":"0.73","size":"869.2"},{"price":"0.74","size":"967.6"},{"price":"0.75","size":"1673.8"},{"price":"0.76","size":"869.2"},{"price":"0.77","size":"864.6"},{"price":"0.78","size":"870.2"},{"price":"0.79","size":"871.6"},{"price":"0.8","size":"987.2"},{"price":"0.81","size":"876.8"},{"price":"0.82","size":"1091.55"},{"price":"0.83","size":"958.39"},{"price":"0.84","size":"1119.39"},{"price":"0.85","size":"1149.13"},{"price":"0.86","size":"962.6"},{"price":"0.87","size":"995.8"},{"price":"0.88","size":"1105.55"},{"price":"0.89","size":"1124.49"},{"price":"0.9","size":"1191.79"},{"price":"0.91","size":"589.6"},{"price":"0.92","size":"3424.35"},{"price":"0.93","size":"3340.43"},{"price":"0.94","size":"3250.34"},{"price":"0.95","size":"3109.79"},{"price":"0.96","size":"4022.95"}],"asks":[{"price":"0.99","size":"30894.91"},{"price":"0.98","size":"8759.25"},{"price":"0.97","size":"57.68"}],"hash":"29c546e670f46d15394b199d65c7462d05993e25","timestamp":"1770839723346","event_type":"book","_sub_state":"active","_subscription_id":1,"_active_subscription_id":1},"parse_warnings":[],"out_of_order":false}
{"run_id":"29526913bab7446286864a321c124486","channel":"market","event_type":"price_change","market":"0x8032d8355d335c6ccbfc2508d99fbc87eb13f437bd275c93ee56fd1558e517ff","asset_id":null,"source":"market_ws:sub:active:1","t_event_ms":1770839723348,"t_recv_wall_ms":1770839723259,"t_recv_wall_iso":"2026-02-11T19:55:23.259Z","t_recv_mono_ns":618588600517083,"raw":{"market":"0x8032d8355d335c6ccbfc2508d99fbc87eb13f437bd275c93ee56fd1558e517ff","price_changes":[{"asset_id":"40652734036737240317526188612064032143639112324786051284480877037991580442979","price":"0.96","size":"4027.95","side":"BUY","hash":"c6246ad6a27d4faa4f43eff287ab343a3ee02c47","best_bid":"0.96","best_ask":"0.97"},{"asset_id":"20773614133833886322101538939702011175545796528197617633926164254913649353392","price":"0.04","size":"4027.95","side":"SELL","hash":"88af5ca79def5ff87fb8685a0e8d292b93c8b515","best_bid":"0.03","best_ask":"0.04"}],"timestamp":"1770839723348","event_type":"price_change","_sub_state":"active","_subscription_id":1,"_active_subscription_id":1},"parse_warnings":[],"out_of_order":false}
{"run_id":"29526913bab7446286864a321c124486","channel":"market","event_type":"price_change","market":"0x8032d8355d335c6ccbfc2508d99fbc87eb13f437bd275c93ee56fd1558e517ff","asset_id":null,"source":"market_ws:sub:active:1","t_event_ms":1770839723352,"t_recv_wall_ms":1770839723259,"t_recv_wall_iso":"2026-02-11T19:55:23.259Z","t_recv_mono_ns":618588600628458,"raw":{"market":"0x8032d8355d335c6ccbfc2508d99fbc87eb13f437bd275c93ee56fd1558e517ff","price_changes":[{"asset_id":"40652734036737240317526188612064032143639112324786051284480877037991580442979","price":"0.96","size":"4087.95","side":"BUY","hash":"de0a99775078642b3db805c3499e076463d445c2","best_bid":"0.96","best_ask":"0.97"},{"asset_id":"20773614133833886322101538939702011175545796528197617633926164254913649353392","price":"0.04","size":"4087.95","side":"SELL","hash":"e4369e6bb8f54c81ac8bef1deb17de751967f99f","best_bid":"0.03","best_ask":"0.04"}],"timestamp":"1770839723352","event_type":"price_change","_sub_state":"active","_subscription_id":1,"_active_subscription_id":1},"parse_warnings":[],"out_of_order":false}
{"run_id":"29526913bab7446286864a321c124486","channel":"market","event_type":"price_change","market":"0x8032d8355d335c6ccbfc2508d99fbc87eb13f437bd275c93ee56fd1558e517ff","asset_id":null,"source":"market_ws:sub:active:1","t_event_ms":1770839723364,"t_recv_wall_ms":1770839723271,"t_recv_wall_iso":"2026-02-11T19:55:23.271Z","t_recv_mono_ns":618588612626208,"raw":{"market":"0x8032d8355d335c6ccbfc2508d99fbc87eb13f437bd275c93ee56fd1558e517ff","price_changes":[{"asset_id":"40652734036737240317526188612064032143639112324786051284480877037991580442979","price":"0.96","size":"4081.17","side":"BUY","hash":"e65922a113f9d84899b64acf3abc5c95b21b9cfb","best_bid":"0.96","best_ask":"0.97"},{"asset_id":"20773614133833886322101538939702011175545796528197617633926164254913649353392","price":"0.04","size":"4081.17","side":"SELL","hash":"bb96659cf9ab6c7c12fd4523323a7440b0714ffd","best_bid":"0.03","best_ask":"0.04"}],"timestamp":"1770839723364","event_type":"price_change","_sub_state":"active","_subscription_id":1,"_active_subscription_id":1},"parse_warnings":[],"out_of_order":false}
{"run_id":"29526913bab7446286864a321c124486","channel":"market","event_type":"book","market":"0x8032d8355d335c6ccbfc2508d99fbc87eb13f437bd275c93ee56fd1558e517ff","asset_id":"20773614133833886322101538939702011175545796528197617633926164254913649353392","source":"market_ws:sub:active:1","t_event_ms":1770839723364,"t_recv_wall_ms":1770839723272,"t_recv_wall_iso":"2026-02-11T19:55:23.272Z","t_recv_mono_ns":618588612892125,"raw":{"market":"0x8032d8355d335c6ccbfc2508d99fbc87eb13f437bd275c93ee56fd1558e517ff","asset_id":"20773614133833886322101538939702011175545796528197617633926164254913649353392","bids":[{"price":"0.01","size":"30894.91"},{"price":"0.02","size":"8759.25"},{"price":"0.03","size":"57.68"}],"asks":[{"price":"0.99","size":"30822.26"},{"price":"0.98","size":"12559.04"},{"price":"0.97","size":"7433.03"},{"price":"0.96","size":"5453.8"},{"price":"0.95","size":"6815.8"},{"price":"0.94","size":"5105"},{"price":"0.93","size":"5421.38"},{"price":"0.92","size":"5139.4"},{"price":"0.91","size":"5225.8"},{"price":"0.9","size":"5102.8"},{"price":"0.89","size":"120.6"},{"price":"0.88","size":"63.6"},{"price":"0.87","size":"63"},{"price":"0.86","size":"61.6"},{"price":"0.85","size":"107.39"},{"price":"0.84","size":"69.39"},{"price":"0.83","size":"58.39"},{"price":"0.82","size":"66.71"},{"price":"0.81","size":"56.8"},{"price":"0.8","size":"92.14"},{"price":"0.79","size":"60.8"},{"price":"0.78","size":"55.2"},{"price":"0.77","size":"64.48"},{"price":"0.76","size":"54.2"},{"price":"0.75","size":"375.8"},{"price":"0.74","size":"68.6"},{"price":"0.73","size":"53.2"},{"price":"0.72","size":"63.26"},{"price":"0.71","size":"52.6"},{"price":"0.7","size":"402.4"},{"price":"0.69","size":"72.2"},{"price":"0.68","size":"87.88"},{"price":"0.67","size":"188.46"},{"price":"0.66","size":"123.6"},{"price":"0.65","size":"317.03"},{"price":"0.64","size":"582.36"},{"price":"0.63","size":"559.2"},{"price":"0.62","size":"559"},{"price":"0.61","size":"594"},{"price":"0.6","size":"2915.41"},{"price":"0.59","size":"576.8"},{"price":"0.58","size":"575.5"},{"price":"0.57","size":"558.6"},{"price":"0.56","size":"572.68"},{"price":"0.55","size":"566.4"},{"price":"0.54","size":"561.94"},{"price":"0.53","size":"631.57"},{"price":"0.52","size":"611.4"},{"price":"0.51","size":"705.2"},{"price":"0.5","size":"1011.55"},{"price":"0.49","size":"692.4"},{"price":"0.48","size":"628.4"},{"price":"0.47","size":"633.4"},{"price":"0.46","size":"711.65"},{"price":"0.45","size":"866.59"},{"price":"0.44","size":"905.69"},{"price":"0.43","size":"641.6"},{"price":"0.42","size":"645.58"},{"price":"0.41","size":"564"},{"price":"0.4","size":"20642.9"},{"price":"0.39","size":"650.23"},{"price":"0.38","size":"593"},{"price":"0.37","size":"755.73"},{"price":"0.36","size":"558"},{"price":"0.35","size":"1144.32"},{"price":"0.34","size":"649.59"},{"price":"0.33","size":"624.8"},{"price":"0.32","size":"574"},{"price":"0.31","size":"594.2"},{"price":"0.3","size":"735.66"},{"price":"0.29","size":"924.6"},{"price":"0.28","size":"356.8"},{"price":"0.27","size":"869.2"},{"price":"0.26","size":"967.6"},{"price":"0.25","size":"1673.8"},{"price":"0.24","size":"869.2"},{"price":"0.23","size":"864.6"},{"price":"0.22","size":"870.2"},{"price":"0.21","size":"871.6"},{"price":"0.2","size":"987.2"},{"price":"0.19","size":"876.8"},{"price":"0.18","size":"1091.55"},{"price":"0.17","size":"958.39"},{"price":"0.16","size":"1119.39"},{"price":"0.15","size":"1149.13"},{"price":"0.14","size":"962.6"},{"price":"0.13","size":"995.8"},{"price":"0.12","size":"1105.55"},{"price":"0.11","size":"1124.49"},{"price":"0.1","size":"1191.79"},{"price":"0.09","size":"589.6"},{"price":"0.08","size":"3424.35"},{"price":"0.07","size":"3340.43"},{"price":"0.06","size":"3250.34"},{"price":"0.05","size":"3109.79"},{"price":"0.04","size":"4081.17"}],"hash":"bb96659cf9ab6c7c12fd4523323a7440b0714ffd","timestamp":"1770839723364","event_type":"book","_sub_state":"active","_subscription_id":1,"_active_subscription_id":1},"parse_warnings":[],"out_of_order":false}
{"run_id":"29526913bab7446286864a321c124486","channel":"market","event_type":"book","market":"0x8032d8355d335c6ccbfc2508d99fbc87eb13f437bd275c93ee56fd1558e517ff","asset_id":"40652734036737240317526188612064032143639112324786051284480877037991580442979","source":"market_ws:sub:active:1","t_event_ms":1770839723364,"t_recv_wall_ms":1770839723272,"t_recv_wall_iso":"2026-02-11T19:55:23.272Z","t_recv_mono_ns":618588613399833,"raw":{"market":"0x8032d8355d335c6ccbfc2508d99fbc87eb13f437bd275c93ee56fd1558e517ff","asset_id":"40652734036737240317526188612064032143639112324786051284480877037991580442979","bids":[{"price":"0.01","size":"30822.26"},{"price":"0.02","size":"12559.04"},{"price":"0.03","size":"7433.03"},{"price":"0.04","size":"5453.8"},{"price":"0.05","size":"6815.8"},{"price":"0.06","size":"5105"},{"price":"0.07","size":"5421.38"},{"price":"0.08","size":"5139.4"},{"price":"0.09","size":"5225.8"},{"price":"0.1","size":"5102.8"},{"price":"0.11","size":"120.6"},{"price":"0.12","size":"63.6"},{"price":"0.13","size":"63"},{"price":"0.14","size":"61.6"},{"price":"0.15","size":"107.39"},{"price":"0.16","size":"69.39"},{"price":"0.17","size":"58.39"},{"price":"0.18","size":"66.71"},{"price":"0.19","size":"56.8"},{"price":"0.2","size":"92.14"},{"price":"0.21","size":"60.8"},{"price":"0.22","size":"55.2"},{"price":"0.23","size":"64.48"},{"price":"0.24","size":"54.2"},{"price":"0.25","size":"375.8"},{"price":"0.26","size":"68.6"},{"price":"0.27","size":"53.2"},{"price":"0.28","size":"63.26"},{"price":"0.29","size":"52.6"},{"price":"0.3","size":"402.4"},{"price":"0.31","size":"72.2"},{"price":"0.32","size":"87.88"},{"price":"0.33","size":"188.46"},{"price":"0.34","size":"123.6"},{"price":"0.35","size":"317.03"},{"price":"0.36","size":"582.36"},{"price":"0.37","size":"559.2"},{"price":"0.38","size":"559"},{"price":"0.39","size":"594"},{"price":"0.4","size":"2915.41"},{"price":"0.41","size":"576.8"},{"price":"0.42","size":"575.5"},{"price":"0.43","size":"558.6"},{"price":"0.44","size":"572.68"},{"price":"0.45","size":"566.4"},{"price":"0.46","size":"561.94"},{"price":"0.47","size":"631.57"},{"price":"0.48","size":"611.4"},{"price":"0.49","size":"705.2"},{"price":"0.5","size":"1011.55"},{"price":"0.51","size":"692.4"},{"price":"0.52","size":"628.4"},{"price":"0.53","size":"633.4"},{"price":"0.54","size":"711.65"},{"price":"0.55","size":"866.59"},{"price":"0.56","size":"905.69"},{"price":"0.57","size":"641.6"},{"price":"0.58","size":"645.58"},{"price":"0.59","size":"564"},{"price":"0.6","size":"20642.9"},{"price":"0.61","size":"650.23"},{"price":"0.62","size":"593"},{"price":"0.63","size":"755.73"},{"price":"0.64","size":"558"},{"price":"0.65","size":"1144.32"},{"price":"0.66","size":"649.59"},{"price":"0.67","size":"624.8"},{"price":"0.68","size":"574"},{"price":"0.69","size":"594.2"},{"price":"0.7","size":"735.66"},{"price":"0.71","size":"924.6"},{"price":"0.72","size":"356.8"},{"price":"0.73","size":"869.2"},{"price":"0.74","size":"967.6"},{"price":"0.75","size":"1673.8"},{"price":"0.76","size":"869.2"},{"price":"0.77","size":"864.6"},{"price":"0.78","size":"870.2"},{"price":"0.79","size":"871.6"},{"price":"0.8","size":"987.2"},{"price":"0.81","size":"876.8"},{"price":"0.82","size":"1091.55"},{"price":"0.83","size":"958.39"},{"price":"0.84","size":"1119.39"},{"price":"0.85","size":"1149.13"},{"price":"0.86","size":"962.6"},{"price":"0.87","size":"995.8"},{"price":"0.88","size":"1105.55"},{"price":"0.89","size":"1124.49"},{"price":"0.9","size":"1191.79"},{"price":"0.91","size":"589.6"},{"price":"0.92","size":"3424.35"},{"price":"0.93","size":"3340.43"},{"price":"0.94","size":"3250.34"},{"price":"0.95","size":"3109.79"},{"price":"0.96","size":"4081.17"}],"asks":[{"price":"0.99","size":"30894.91"},{"price":"0.98","size":"8759.25"},{"price":"0.97","size":"57.68"}],"hash":"e65922a113f9d84899b64acf3abc5c95b21b9cfb","timestamp":"1770839723364","event_type":"book","_sub_state":"active","_subscription_id":1,"_active_subscription_id":1},"parse_warnings":[],"out_of_order":false}
{"run_id":"29526913bab7446286864a321c124486","channel":"market","event_type":"price_change","market":"0x8032d8355d335c6ccbfc2508d99fbc87eb13f437bd275c93ee56fd1558e517ff","asset_id":null,"source":"market_ws:sub:active:1","t_event_ms":1770839723366,"t_recv_wall_ms":1770839723273,"t_recv_wall_iso":"2026-02-11T19:55:23.273Z","t_recv_mono_ns":618588613930416,"raw":{"market":"0x8032d8355d335c6ccbfc2508d99fbc87eb13f437bd275c93ee56fd1558e517ff","price_changes":[{"asset_id":"40652734036737240317526188612064032143639112324786051284480877037991580442979","price":"0.83","size":"963.39","side":"BUY","hash":"00211e11697264389d2a97301217b2f1f78eff50","best_bid":"0.96","best_ask":"0.97"},{"asset_id":"20773614133833886322101538939702011175545796528197617633926164254913649353392","price":"0.17","size":"963.39","side":"SELL","hash":"3fb35b13a62b05f9e82c6013f3f665270841d0bd","best_bid":"0.03","best_ask":"0.04"}],"timestamp":"1770839723366","event_type":"price_change","_sub_state":"active","_subscription_id":1,"_active_subscription_id":1},"parse_warnings":[],"out_of_order":false}
{"run_id":"29526913bab7446286864a321c124486","channel":"market","event_type":"price_change","market":"0x8032d8355d335c6ccbfc2508d99fbc87eb13f437bd275c93ee56fd1558e517ff","asset_id":null,"source":"market_ws:sub:active:1","t_event_ms":1770839723380,"t_recv_wall_ms":1770839723288,"t_recv_wall_iso":"2026-02-11T19:55:23.288Z","t_recv_mono_ns":618588629405541,"raw":{"market":"0x8032d8355d335c6ccbfc2508d99fbc87eb13f437bd275c93ee56fd1558e517ff","price_changes":[{"asset_id":"40652734036737240317526188612064032143639112324786051284480877037991580442979","price":"0.87","size":"1041.8","side":"BUY","hash":"a177c2d246a5c17d65d4fa0801766746f086bd79","best_bid":"0.96","best_ask":"0.97"},{"asset_id":"20773614133833886322101538939702011175545796528197617633926164254913649353392","price":"0.13","size":"1041.8","side":"SELL","hash":"5992ef93ed9fb1cffb1e3c4d9fa8052c3e945e84","best_bid":"0.03","best_ask":"0.04"}],"timestamp":"1770839723380","event_type":"price_change","_sub_state":"active","_subscription_id":1,"_active_subscription_id":1},"parse_warnings":[],"out_of_order":false}
{"run_id":"29526913bab7446286864a321c124486","channel":"market","event_type":"price_change","market":"0x8032d8355d335c6ccbfc2508d99fbc87eb13f437bd275c93ee56fd1558e517ff","asset_id":null,"source":"market_ws:sub:active:1","t_event_ms":1770839723381,"t_recv_wall_ms":1770839723289,"t_recv_wall_iso":"2026-02-11T19:55:23.289Z","t_recv_mono_ns":618588629769916,"raw":{"market":"0x8032d8355d335c6ccbfc2508d99fbc87eb13f437bd275c93ee56fd1558e517ff","price_changes":[{"asset_id":"40652734036737240317526188612064032143639112324786051284480877037991580442979","price":"0.96","size":"4021.17","side":"BUY","hash":"df01b9147b3069b72ef87c30f33d7f3e731d509a","best_bid":"0.96","best_ask":"0.97"},{"asset_id":"20773614133833886322101538939702011175545796528197617633926164254913649353392","price":"0.04","size":"4021.17","side":"SELL","hash":"364011627fd3c37af4559b4b181e94cb745c67fe","best_bid":"0.03","best_ask":"0.04"}],"timestamp":"1770839723381","event_type":"price_change","_sub_state":"active","_subscription_id":1,"_active_subscription_id":1},"parse_warnings":[],"out_of_order":false}
{"run_id":"29526913bab7446286864a321c124486","channel":"market","event_type":"last_trade_price","market":"0x8032d8355d335c6ccbfc2508d99fbc87eb13f437bd275c93ee56fd1558e517ff","asset_id":"40652734036737240317526188612064032143639112324786051284480877037991580442979","source":"market_ws:sub:unknown","t_event_ms":1770839723381,"t_recv_wall_ms":1770839723289,"t_recv_wall_iso":"2026-02-11T19:55:23.289Z","t_recv_mono_ns":618588629997458,"raw":{"market":"0x8032d8355d335c6ccbfc2508d99fbc87eb13f437bd275c93ee56fd1558e517ff","asset_id":"40652734036737240317526188612064032143639112324786051284480877037991580442979","price":"0.97","size":"7","fee_rate_bps":"1000","side":"BUY","timestamp":"1770839723381","event_type":"last_trade_price","transaction_hash":"0x704d5033e2a72ab44ba063aef9a5f46333290f6e69c4a7a211b56edc4f8d2754","_sub_state":"unknown","_subscription_id":null,"_active_subscription_id":1},"parse_warnings":["unknown_message_schema"],"out_of_order":false}
{"run_id":"29526913bab7446286864a321c124486","channel":"market","event_type":"price_change","market":"0x8032d8355d335c6ccbfc2508d99fbc87eb13f437bd275c93ee56fd1558e517ff","asset_id":null,"source":"market_ws:sub:active:1","t_event_ms":1770839723382,"t_recv_wall_ms":1770839723289,"t_recv_wall_iso":"2026-02-11T19:55:23.289Z","t_recv_mono_ns":618588630184416,"raw":{"market":"0x8032d8355d335c6ccbfc2508d99fbc87eb13f437bd275c93ee56fd1558e517ff","price_changes":[{"asset_id":"40652734036737240317526188612064032143639112324786051284480877037991580442979","price":"0.88","size":"1060.55","side":"BUY","hash":"07cc820b2dec3a2b1f90d181a292e73ca4726e79","best_bid":"0.96","best_ask":"0.97"},{"asset_id":"20773614133833886322101538939702011175545796528197617633926164254913649353392","price":"0.12","size":"1060.55","side":"SELL","hash":"0b91a02022bf1032eabf46bdf63a5204136b1c79","best_bid":"0.03","best_ask":"0.04"}],"timestamp":"1770839723382","event_type":"price_change","_sub_state":"active","_subscription_id":1,"_active_subscription_id":1},"parse_warnings":[],"out_of_order":false}
{"run_id":"29526913bab7446286864a321c124486","channel":"market","event_type":"last_trade_price","market":"0x8032d8355d335c6ccbfc2508d99fbc87eb13f437bd275c93ee56fd1558e517ff","asset_id":"40652734036737240317526188612064032143639112324786051284480877037991580442979","source":"market_ws:sub:unknown","t_event_ms":1770839723391,"t_recv_wall_ms":1770839723298,"t_recv_wall_iso":"2026-02-11T19:55:23.298Z","t_recv_mono_ns":618588639380125,"raw":{"market":"0x8032d8355d335c6ccbfc2508d99fbc87eb13f437bd275c93ee56fd1558e517ff","asset_id":"40652734036737240317526188612064032143639112324786051284480877037991580442979","price":"0.96","size":"6.78","fee_rate_bps":"1000","side":"SELL","timestamp":"1770839723391","event_type":"last_trade_price","transaction_hash":"0xaf94bf83ea3684c1e498ebdb83ebd8d4c4a06c01b84d0a187a18bbb1f09f585d","_sub_state":"unknown","_subscription_id":null,"_active_subscription_id":1},"parse_warnings":["unknown_message_schema"],"out_of_order":false}
{"run_id":"29526913bab7446286864a321c124486","channel":"market","event_type":"price_change","market":"0x8032d8355d335c6ccbfc2508d99fbc87eb13f437bd275c93ee56fd1558e517ff","asset_id":null,"source":"market_ws:sub:active:1","t_event_ms":1770839723393,"t_recv_wall_ms":1770839723303,"t_recv_wall_iso":"2026-02-11T19:55:23.303Z","t_recv_mono_ns":618588644653583,"raw":{"market":"0x8032d8355d335c6ccbfc2508d99fbc87eb13f437bd275c93ee56fd1558e517ff","price_changes":[{"asset_id":"40652734036737240317526188612064032143639112324786051284480877037991580442979","price":"0.96","size":"4081.17","side":"BUY","hash":"4126de242035cf722805d0af46ffcd23a677ad20","best_bid":"0.96","best_ask":"0.97"},{"asset_id":"20773614133833886322101538939702011175545796528197617633926164254913649353392","price":"0.04","size":"4081.17","side":"SELL","hash":"39d46e5e254c05b96c7bc0d95b7409d6408f23c5","best_bid":"0.03","best_ask":"0.04"}],"timestamp":"1770839723393","event_type":"price_change","_sub_state":"active","_subscription_id":1,"_active_subscription_id":1},"parse_warnings":[],"out_of_order":false}
{"run_id":"29526913bab7446286864a321c124486","channel":"market","event_type":"price_change","market":"0x8032d8355d335c6ccbfc2508d99fbc87eb13f437bd275c93ee56fd1558e517ff","asset_id":null,"source":"market_ws:sub:active:1","t_event_ms":1770839723420,"t_recv_wall_ms":1770839723325,"t_recv_wall_iso":"2026-02-11T19:55:23.325Z","t_recv_mono_ns":618588665783916,"raw":{"market":"0x8032d8355d335c6ccbfc2508d99fbc87eb13f437bd275c93ee56fd1558e517ff","price_changes":[{"asset_id":"40652734036737240317526188612064032143639112324786051284480877037991580442979","price":"0.96","size":"4021.17","side":"BUY","hash":"bae579ca8f7578b00905e60e1b3daa467a120d88","best_bid":"0.96","best_ask":"0.97"},{"asset_id":"20773614133833886322101538939702011175545796528197617633926164254913649353392","price":"0.04","size":"4021.17","side":"SELL","hash":"1e0a01131e232412c746e7e930604446cf1f8bca","best_bid":"0.03","best_ask":"0.04"}],"timestamp":"1770839723420","event_type":"price_change","_sub_state":"active","_subscription_id":1,"_active_subscription_id":1},"parse_warnings":[],"out_of_order":false}
{"run_id":"29526913bab7446286864a321c124486","channel":"market","event_type":"price_change","market":"0x8032d8355d335c6ccbfc2508d99fbc87eb13f437bd275c93ee56fd1558e517ff","asset_id":null,"source":"market_ws:sub:active:1","t_event_ms":1770839723422,"t_recv_wall_ms":1770839723327,"t_recv_wall_iso":"2026-02-11T19:55:23.327Z","t_recv_mono_ns":618588668115250,"raw":{"market":"0x8032d8355d335c6ccbfc2508d99fbc87eb13f437bd275c93ee56fd1558e517ff","price_changes":[{"asset_id":"40652734036737240317526188612064032143639112324786051284480877037991580442979","price":"0.96","size":"4081.17","side":"BUY","hash":"4763d546bdd481bd0f0faab1412c31f8a057717b","best_bid":"0.96","best_ask":"0.97"},{"asset_id":"20773614133833886322101538939702011175545796528197617633926164254913649353392","price":"0.04","size":"4081.17","side":"SELL","hash":"45de31f4a899b4fe9622cc711e41d3c0b4c17901","best_bid":"0.03","best_ask":"0.04"}],"timestamp":"1770839723422","event_type":"price_change","_sub_state":"active","_subscription_id":1,"_active_subscription_id":1},"parse_warnings":[],"out_of_order":false}
{"run_id":"29526913bab7446286864a321c124486","channel":"market","event_type":"price_change","market":"0x8032d8355d335c6ccbfc2508d99fbc87eb13f437bd275c93ee56fd1558e517ff","asset_id":null,"source":"market_ws:sub:active:1","t_event_ms":1770839723439,"t_recv_wall_ms":1770839723353,"t_recv_wall_iso":"2026-02-11T19:55:23.353Z","t_recv_mono_ns":618588694083083,"raw":{"market":"0x8032d8355d335c6ccbfc2508d99fbc87eb13f437bd275c93ee56fd1558e517ff","price_changes":[{"asset_id":"40652734036737240317526188612064032143639112324786051284480877037991580442979","price":"0.94","size":"3220.34","side":"BUY","hash":"f9e1afd3de7a7d84b4cb27d99c801301b2cc2766","best_bid":"0.96","best_ask":"0.97"},{"asset_id":"20773614133833886322101538939702011175545796528197617633926164254913649353392","price":"0.06","size":"3220.34","side":"SELL","hash":"7f86b42d07aaf47f20791092504bcf202631030f","best_bid":"0.03","best_ask":"0.04"}],"timestamp":"1770839723439","event_type":"price_change","_sub_state":"active","_subscription_id":1,"_active_subscription_id":1},"parse_warnings":[],"out_of_order":false}
{"run_id":"29526913bab7446286864a321c124486","channel":"market","event_type":"price_change","market":"0x8032d8355d335c6ccbfc2508d99fbc87eb13f437bd275c93ee56fd1558e517ff","asset_id":null,"source":"market_ws:sub:active:1","t_event_ms":1770839723452,"t_recv_wall_ms":1770839723361,"t_recv_wall_iso":"2026-02-11T19:55:23.361Z","t_recv_mono_ns":618588701778166,"raw":{"market":"0x8032d8355d335c6ccbfc2508d99fbc87eb13f437bd275c93ee56fd1558e517ff","price_changes":[{"asset_id":"40652734036737240317526188612064032143639112324786051284480877037991580442979","price":"0.96","size":"4021.17","side":"BUY","hash":"97eb8acb1e66169920b7705e389a940db9a0bf1d","best_bid":"0.96","best_ask":"0.97"},{"asset_id":"20773614133833886322101538939702011175545796528197617633926164254913649353392","price":"0.04","size":"4021.17","side":"SELL","hash":"6d2c2b32abc0f0d0fe58037fe8daba183957ac5f","best_bid":"0.03","best_ask":"0.04"}],"timestamp":"1770839723452","event_type":"price_change","_sub_state":"active","_subscription_id":1,"_active_subscription_id":1},"parse_warnings":[],"out_of_order":false}
{"run_id":"29526913bab7446286864a321c124486","channel":"market","event_type":"price_change","market":"0x8032d8355d335c6ccbfc2508d99fbc87eb13f437bd275c93ee56fd1558e517ff","asset_id":null,"source":"market_ws:sub:active:1","t_event_ms":1770839723460,"t_recv_wall_ms":1770839723371,"t_recv_wall_iso":"2026-02-11T19:55:23.371Z","t_recv_mono_ns":618588712667541,"raw":{"market":"0x8032d8355d335c6ccbfc2508d99fbc87eb13f437bd275c93ee56fd1558e517ff","price_changes":[{"asset_id":"40652734036737240317526188612064032143639112324786051284480877037991580442979","price":"0.83","size":"958.39","side":"BUY","hash":"d1fb53d8641762974c2c00c200ae8ffecc7054d1","best_bid":"0.96","best_ask":"0.97"},{"asset_id":"20773614133833886322101538939702011175545796528197617633926164254913649353392","price":"0.17","size":"958.39","side":"SELL","hash":"3e1e000a6f61e97dfde430e81fe20e472c11833e","best_bid":"0.03","best_ask":"0.04"}],"timestamp":"1770839723460","event_type":"price_change","_sub_state":"active","_subscription_id":1,"_active_subscription_id":1},"parse_warnings":[],"out_of_order":false}
{"run_id":"29526913bab7446286864a321c124486","channel":"market","event_type":"price_change","market":"0x8032d8355d335c6ccbfc2508d99fbc87eb13f437bd275c93ee56fd1558e517ff","asset_id":null,"source":"market_ws:sub:active:1","t_event_ms":1770839723472,"t_recv_wall_ms":1770839723387,"t_recv_wall_iso":"2026-02-11T19:55:23.387Z","t_recv_mono_ns":618588728127458,"raw":{"market":"0x8032d8355d335c6ccbfc2508d99fbc87eb13f437bd275c93ee56fd1558e517ff","price_changes":[{"asset_id":"40652734036737240317526188612064032143639112324786051284480877037991580442979","price":"0.96","size":"4081.17","side":"BUY","hash":"1044b63a3840129512e62c5f840e661128aa29e3","best_bid":"0.96","best_ask":"0.97"},{"asset_id":"20773614133833886322101538939702011175545796528197617633926164254913649353392","price":"0.04","size":"4081.17","side":"SELL","hash":"39dfe695b4f49a4fe6f4ef93c3c595584b8ccb9d","best_bid":"0.03","best_ask":"0.04"}],"timestamp":"1770839723472","event_type":"price_change","_sub_state":"active","_subscription_id":1,"_active_subscription_id":1},"parse_warnings":[],"out_of_order":false}
{"run_id":"29526913bab7446286864a321c124486","channel":"market","event_type":"price_change","market":"0x8032d8355d335c6ccbfc2508d99fbc87eb13f437bd275c93ee56fd1558e517ff","asset_id":null,"source":"market_ws:sub:active:1","t_event_ms":1770839723477,"t_recv_wall_ms":1770839723387,"t_recv_wall_iso":"2026-02-11T19:55:23.387Z","t_recv_mono_ns":618588728467958,"raw":{"market":"0x8032d8355d335c6ccbfc2508d99fbc87eb13f437bd275c93ee56fd1558e517ff","price_changes":[{"asset_id":"40652734036737240317526188612064032143639112324786051284480877037991580442979","price":"0.94","size":"3215.34","side":"BUY","hash":"a0c76f1d1e224e68519ac48f3b75b9d1684f359d","best_bid":"0.96","best_ask":"0.97"},{"asset_id":"20773614133833886322101538939702011175545796528197617633926164254913649353392","price":"0.06","size":"3215.34","side":"SELL","hash":"94a88ad62a47490ac28c775c3fd23316e59ce8d0","best_bid":"0.03","best_ask":"0.04"}],"timestamp":"1770839723477","event_type":"price_change","_sub_state":"active","_subscription_id":1,"_active_subscription_id":1},"parse_warnings":[],"out_of_order":false}
{"run_id":"29526913bab7446286864a321c124486","channel":"market","event_type":"price_change","market":"0x8032d8355d335c6ccbfc2508d99fbc87eb13f437bd275c93ee56fd1558e517ff","asset_id":null,"source":"market_ws:sub:active:1","t_event_ms":1770839723503,"t_recv_wall_ms":1770839723410,"t_recv_wall_iso":"2026-02-11T19:55:23.410Z","t_recv_mono_ns":618588750785958,"raw":{"market":"0x8032d8355d335c6ccbfc2508d99fbc87eb13f437bd275c93ee56fd1558e517ff","price_changes":[{"asset_id":"40652734036737240317526188612064032143639112324786051284480877037991580442979","price":"0.96","size":"4021.17","side":"BUY","hash":"8e6f67afb9030a5af21179eb599eb35f36714064","best_bid":"0.96","best_ask":"0.97"},{"asset_id":"20773614133833886322101538939702011175545796528197617633926164254913649353392","price":"0.04","size":"4021.17","side":"SELL","hash":"883275bb4aaa26d2580dbedd1fe96db8bff2093b","best_bid":"0.03","best_ask":"0.04"}],"timestamp":"1770839723503","event_type":"price_change","_sub_state":"active","_subscription_id":1,"_active_subscription_id":1},"parse_warnings":[],"out_of_order":false}
{"run_id":"29526913bab7446286864a321c124486","channel":"market","event_type":"price_change","market":"0x8032d8355d335c6ccbfc2508d99fbc87eb13f437bd275c93ee56fd1558e517ff","asset_id":null,"source":"market_ws:sub:active:1","t_event_ms":1770839723506,"t_recv_wall_ms":1770839723411,"t_recv_wall_iso":"2026-02-11T19:55:23.411Z","t_recv_mono_ns":618588751927083,"raw":{"market":"0x8032d8355d335c6ccbfc2508d99fbc87eb13f437bd275c93ee56fd1558e517ff","price_changes":[{"asset_id":"40652734036737240317526188612064032143639112324786051284480877037991580442979","price":"0.96","size":"4081.17","side":"BUY","hash":"e634dbf2297fc8a164586042956e931f4d2cf208","best_bid":"0.96","best_ask":"0.97"},{"asset_id":"20773614133833886322101538939702011175545796528197617633926164254913649353392","price":"0.04","size":"4081.17","side":"SELL","hash":"0eb3608096ab9759a3fae3b4d72cd991f0d44297","best_bid":"0.03","best_ask":"0.04"}],"timestamp":"1770839723506","event_type":"price_change","_sub_state":"active","_subscription_id":1,"_active_subscription_id":1},"parse_warnings":[],"out_of_order":false}
{"run_id":"29526913bab7446286864a321c124486","channel":"market","event_type":"price_change","market":"0x8032d8355d335c6ccbfc2508d99fbc87eb13f437bd275c93ee56fd1558e517ff","asset_id":null,"source":"market_ws:sub:active:1","t_event_ms":1770839723530,"t_recv_wall_ms":1770839723441,"t_recv_wall_iso":"2026-02-11T19:55:23.441Z","t_recv_mono_ns":618588782223541,"raw":{"market":"0x8032d8355d335c6ccbfc2508d99fbc87eb13f437bd275c93ee56fd1558e517ff","price_changes":[{"asset_id":"40652734036737240317526188612064032143639112324786051284480877037991580442979","price":"0.94","size":"3220.34","side":"BUY","hash":"57c7540d6df656b4bf8ebbfd6dfe5df51e7bf904","best_bid":"0.96","best_ask":"0.97"},{"asset_id":"20773614133833886322101538939702011175545796528197617633926164254913649353392","price":"0.06","size":"3220.34","side":"SELL","hash":"6dcb8265b673ca7f18a263eb312e7c9696bae389","best_bid":"0.03","best_ask":"0.04"}],"timestamp":"1770839723530","event_type":"price_change","_sub_state":"active","_subscription_id":1,"_active_subscription_id":1},"parse_warnings":[],"out_of_order":false}
{"run_id":"29526913bab7446286864a321c124486","channel":"market","event_type":"price_change","market":"0x8032d8355d335c6ccbfc2508d99fbc87eb13f437bd275c93ee56fd1558e517ff","asset_id":null,"source":"market_ws:sub:active:1","t_event_ms":1770839723533,"t_recv_wall_ms":1770839723442,"t_recv_wall_iso":"2026-02-11T19:55:23.442Z","t_recv_mono_ns":618588782831208,"raw":{"market":"0x8032d8355d335c6ccbfc2508d99fbc87eb13f437bd275c93ee56fd1558e517ff","price_changes":[{"asset_id":"40652734036737240317526188612064032143639112324786051284480877037991580442979","price":"0.96","size":"4021.17","side":"BUY","hash":"101f5de9aaf3b5fc9bf32c0c4a55a8f998344fd1","best_bid":"0.96","best_ask":"0.97"},{"asset_id":"20773614133833886322101538939702011175545796528197617633926164254913649353392","price":"0.04","size":"4021.17","side":"SELL","hash":"d24e9793b85d0cc357c1ef231fcc7d5c8352bfbe","best_bid":"0.03","best_ask":"0.04"}],"timestamp":"1770839723533","event_type":"price_change","_sub_state":"active","_subscription_id":1,"_active_subscription_id":1},"parse_warnings":[],"out_of_order":false}
{"run_id":"29526913bab7446286864a321c124486","channel":"market","event_type":"price_change","market":"0x8032d8355d335c6ccbfc2508d99fbc87eb13f437bd275c93ee56fd1558e517ff","asset_id":null,"source":"market_ws:sub:active:1","t_event_ms":1770839723537,"t_recv_wall_ms":1770839723445,"t_recv_wall_iso":"2026-02-11T19:55:23.445Z","t_recv_mono_ns":618588786479916,"raw":{"market":"0x8032d8355d335c6ccbfc2508d99fbc87eb13f437bd275c93ee56fd1558e517ff","price_changes":[{"asset_id":"40652734036737240317526188612064032143639112324786051284480877037991580442979","price":"0.96","size":"4081.17","side":"BUY","hash":"84ce0ee7ca5106efa53c16c6a2d6d164b5ea9b75","best_bid":"0.96","best_ask":"0.97"},{"asset_id":"20773614133833886322101538939702011175545796528197617633926164254913649353392","price":"0.04","size":"4081.17","side":"SELL","hash":"7be9362344ed70fd99c8cec21ecb6518d854058c","best_bid":"0.03","best_ask":"0.04"}],"timestamp":"1770839723537","event_type":"price_change","_sub_state":"active","_subscription_id":1,"_active_subscription_id":1},"parse_warnings":[],"out_of_order":false}
{"run_id":"29526913bab7446286864a321c124486","channel":"market","event_type":"price_change","market":"0x8032d8355d335c6ccbfc2508d99fbc87eb13f437bd275c93ee56fd1558e517ff","asset_id":null,"source":"market_ws:sub:active:1","t_event_ms":1770839723572,"t_recv_wall_ms":1770839723479,"t_recv_wall_iso":"2026-02-11T19:55:23.479Z","t_recv_mono_ns":618588820632166,"raw":{"market":"0x8032d8355d335c6ccbfc2508d99fbc87eb13f437bd275c93ee56fd1558e517ff","price_changes":[{"asset_id":"20773614133833886322101538939702011175545796528197617633926164254913649353392","price":"0.03","size":"48.68","side":"BUY","hash":"c0325cb589d5c654d935218e7fa2fa33fd9f7bf4","best_bid":"0.03","best_ask":"0.04"},{"asset_id":"40652734036737240317526188612064032143639112324786051284480877037991580442979","price":"0.97","size":"48.68","side":"SELL","hash":"5ddf437e4ad0df002902872686e44a58ef77d775","best_bid":"0.96","best_ask":"0.97"}],"timestamp":"1770839723572","event_type":"price_change","_sub_state":"active","_subscription_id":1,"_active_subscription_id":1},"parse_warnings":[],"out_of_order":false}
