{"run_id":"29526913bab7446286864a321c124486","channel":"market","event_type":"book","market":"0x8032d8355d335c6ccbfc2508d99fbc87eb13f437bd275c93ee56fd1558e517ff","asset_id":"20773614133833886322101538939702011175545796528197617633926164254913649353392","source":"market_ws:sub:active:1","t_event_ms":1770839723572,"t_recv_wall_ms":1770839723480,"t_recv_wall_iso":"2026-02-11T19:55:23.480Z","t_recv_mono_ns":618588821103625,"raw":{"market":"0x8032d8355d335c6ccbfc2508d99fbc87eb13f437bd275c93ee56fd1558e517ff","asset_id":"20773614133833886322101538939702011175545796528197617633926164254913649353392","bids":[{"price":"0.01","size":"30894.91"},{"price":"0.02","size":"8759.25"},{"price":"0.03","size":"48.68"}],"asks":[{"price":"0.99","size":"30822.26"},{"price":"0.98","size":"12559.04"},{"price":"0.97","size":"7433.03"},{"price":"0.96","size":"5453.8"},{"price":"0.95","size":"6815.8"},{"price":"0.94","size":"5105"},{"price":"0.93","size":"5421.38"},{"price":"0.92","size":"5139.4"},{"price":"0.91","size":"5225.8"},{"price":"0.9","size":"5102.8"},{"price":"0.89","size":"120.6"},{"price":"0.88","size":"63.6"},{"price":"0.87","size":"63"},{"price":"0.86","size":"61.6"},{"price":"0.85","size":"107.39"},{"price":"0.84","size":"69.39"},{"price":"0.83","size":"58.39"},{"price":"0.82","size":"66.71"},{"price":"0.81","size":"56.8"},{"price":"0.8","size":"92.14"},{"price":"0.79","size":"60.8"},{"price":"0.78","size":"55.2"},{"price":"0.77","size":"64.48"},{"price":"0.76","size":"54.2"},{"price":"0.75","size":"375.8"},{"price":"0.74","size":"68.6"},{"price":"0.73","size":"53.2"},{"price":"0.72","size":"63.26"},{"price":"0.71","size":"52.6"},{"price":"0.7","size":"402.4"},{"price":"0.69","size":"72.2"},{"price":"0.68","size":"87.88"},{"price":"0.67","size":"188.46"},{"price":"0.66","size":"123.6"},{"price":"0.65","size":"317.03"},{"price":"0.64","size":"582.36"},{"price":"0.63","size":"559.2"},{"price":"0.62","size":"559"},{"price":"0.61","size":"594"},{"price":"0.6","size":"2915.41"},{"price":"0.59","size":"576.8"},{"price":"0.58","size":"575.5"},{"price":"0.57","size":"558.6"},{"price":"0.56","size":"572.68"},{"price":"0.55","size":"566.4"},{"price":"0.54","size":"561.94"},{"price":"0.53","size":"631.57"},{"price":"0.52","size":"611.4"},{"price":"0.51","size":"705.2"},{"price":"0.5","size":"1011.55"},{"price":"0.49","size":"692.4"},{"price":"0.48","size":"628.4"},{"price":"0.47","size":"633.4"},{"price":"0.46","size":"711.65"},{"price":"0.45","size":"866.59"},{"price":"0.44","size":"905.69"},{"price":"0.43","size":"641.6"},{"price":"0.42","size":"645.58"},{"price":"0.41","size":"564"},{"price":"0.4","size":"20642.9"},{"price":"0.39","size":"650.23"},{"price":"0.38","size":"593"},{"price":"0.37","size":"755.73"},{"price":"0.36","size":"558"},{"price":"0.35","size":"1144.32"},{"price":"0.34","size":"649.59"},{"price":"0.33","size":"624.8"},{"price":"0.32","size":"574"},{"price":"0.31","size":"594.2"},{"price":"0.3","size":"735.66"},{"price":"0.29","size":"924.6"},{"price":"0.28","size":"356.8"},{"price":"0.27","size":"869.2"},{"price":"0.26","size":"967.6"},{"price":"0.25","size":"1673.8"},{"price":"0.24","size":"869.2"},{"price":"0.23","size":"864.6"},{"price":"0.22","size":"870.2"},{"price":"0.21","size":"871.6"},{"price":"0.2","size":"987.2"},{"price":"0.19","size":"876.8"},{"price":"0.18","size":"1091.55"},{"price":"0.17","size":"958.39"},{"price":"0.16","size":"1119.39"},{"price":"0.15","size":"1149.13"},{"price":"0.14","size":"962.6"},{"price":"0.13","size":"1041.8"},{"price":"0.12","size":"1060.55"},{"price":"0.11","size":"1124.49"},{"price":"0.1","size":"1191.79"},{"price":"0.09","size":"589.6"},{"price":"0.08","size":"3424.35"},{"price":"0.07","size":"3340.43"},{"price":"0.06","size":"3220.34"},{"price":"0.05","size":"3109.79"},{"price":"0.04","size":"4081.17"}],"hash":"c0325cb589d5c654d935218e7fa2fa33fd9f7bf4","timestamp":"1770839723572","event_type":"book","_sub_state":"active","_subscription_id":1,"_active_subscription_id":1},"parse_warnings":[],"out_of_order":false}
{"run_id":"29526913bab7446286864a321c124486","channel":"market","event_type":"book","market":"0x8032d8355d335c6ccbfc2508d99fbc87eb13f437bd275c93ee56fd1558e517ff","asset_id":"40652734036737240317526188612064032143639112324786051284480877037991580442979","source":"market_ws:sub:active:1","t_event_ms":1770839723572,"t_recv_wall_ms":1770839723481,"t_recv_wall_iso":"2026-02-11T19:55:23.481Z","t_recv_mono_ns":618588821928291,"raw":{"market":"0x8032d8355d335c6ccbfc2508d99fbc87eb13f437bd275c93ee56fd1558e517ff","asset_id":"40652734036737240317526188612064032143639112324786051284480877037991580442979","bids":[{"price":"0.01","size":"30822.26"},{"price":"0.02","size":"12559.04"},{"price":"0.03","size":"7433.03"},{"price":"0.04","size":"5453.8"},{"price":"0.05","size":"6815.8"},{"price":"0.06","size":"5105"},{"price":"0.07","size":"5421.38"},{"price":"0.08","size":"5139.4"},{"price":"0.09","size":"5225.8"},{"price":"0.1","size":"5102.8"},{"price":"0.11","size":"120.6"},{"price":"0.12","size":"63.6"},{"price":"0.13","size":"63"},{"price":"0.14","size":"61.6"},{"price":"0.15","size":"107.39"},{"price":"0.16","size":"69.39"},{"price":"0.17","size":"58.39"},{"price":"0.18","size":"66.71"},{"price":"0.19","size":"56.8"},{"price":"0.2","size":"92.14"},{"price":"0.21","size":"60.8"},{"price":"0.22","size":"55.2"},{"price":"0.23","size":"64.48"},{"price":"0.24","size":"54.2"},{"price":"0.25","size":"375.8"},{"price":"0.26","size":"68.6"},{"price":"0.27","size":"53.2"},{"price":"0.28","size":"63.26"},{"price":"0.29","size":"52.6"},{"price":"0.3","size":"402.4"},{"price":"0.31","size":"72.2"},{"price":"0.32","size":"87.88"},{"price":"0.33","size":"188.46"},{"price":"0.34","size":"123.6"},{"price":"0.35","size":"317.03"},{"price":"0.36","size":"582.36"},{"price":"0.37","size":"559.2"},{"price":"0.38","size":"559"},{"price":"0.39","size":"594"},{"price":"0.4","size":"2915.41"},{"price":"0.41","size":"576.8"},{"price":"0.42","size":"575.5"},{"price":"0.43","size":"558.6"},{"price":"0.44","size":"572.68"},{"price":"0.45","size":"566.4"},{"price":"0.46","size":"561.94"},{"price":"0.47","size":"631.57"},{"price":"0.48","size":"611.4"},{"price":"0.49","size":"705.2"},{"price":"0.5","size":"1011.55"},{"price":"0.51","size":"692.4"},{"price":"0.52","size":"628.4"},{"price":"0.53","size":"633.4"},{"price":"0.54","size":"711.65"},{"price":"0.55","size":"866.59"},{"price":"0.56","size":"905.69"},{"price":"0.57","size":"641.6"},{"price":"0.58","size":"645.58"},{"price":"0.59","size":"564"},{"price":"0.6","size":"20642.9"},{"price":"0.61","size":"650.23"},{"price":"0.62","size":"593"},{"price":"0.63","size":"755.73"},{"price":"0.64","size":"558"},{"price":"0.65","size":"1144.32"},{"price":"0.66","size":"649.59"},{"price":"0.67","size":"624.8"},{"price":"0.68","size":"574"},{"price":"0.69","size":"594.2"},{"price":"0.7","size":"735.66"},{"price":"0.71","size":"924.6"},{"price":"0.72","size":"356.8"},{"price":"0.73","size":"869.2"},{"price":"0.74","size":"967.6"},{"price":"0.75","size":"1673.8"},{"price":"0.76","size":"869.2"},{"price":"0.77","size":"864.6"},{"price":"0.78","size":"870.2"},{"price":"0.79","size":"871.6"},{"price":"0.8","size":"987.2"},{"price":"0.81","size":"876.8"},{"price":"0.82","size":"1091.55"},{"price":"0.83","size":"958.39"},{"price":"0.84","size":"1119.39"},{"price":"0.85","size":"1149.13"},{"price":"0.86","size":"962.6"},{"price":"0.87","size":"1041.8"},{"price":"0.88","size":"1060.55"},{"price":"0.89","size":"1124.49"},{"price":"0.9","size":"1191.79"},{"price":"0.91","size":"589.6"},{"price":"0.92","size":"3424.35"},{"price":"0.93","size":"3340.43"},{"price":"0.94","size":"3220.34"},{"price":"0.95","size":"3109.79"},{"price":"0.96","size":"4081.17"}],"asks":[{"price":"0.99","size":"30894.91"},{"price":"0.98","size":"8759.25"},{"price":"0.97","size":"48.68"}],"hash":"5ddf437e4ad0df002902872686e44a58ef77d775","timestamp":"1770839723572","event_type":"book","_sub_state":"active","_subscription_id":1,"_active_subscription_id":1},"parse_warnings":[],"out_of_order":false}
{"run_id":"29526913bab7446286864a321c124486","channel":"market","event_type":"price_change","market":"0x8032d8355d335c6ccbfc2508d99fbc87eb13f437bd275c93ee56fd1558e517ff","asset_id":null,"source":"market_ws:sub:active:1","t_event_ms":1770839723575,"t_recv_wall_ms":1770839723482,"t_recv_wall_iso":"2026-02-11T19:55:23.482Z","t_recv_mono_ns":618588822819041,"raw":{"market":"0x8032d8355d335c6ccbfc2508d99fbc87eb13f437bd275c93ee56fd1558e517ff","price_changes":[{"asset_id":"40652734036737240317526188612064032143639112324786051284480877037991580442979","price":"0.96","size":"4021.17","side":"BUY","hash":"fed12d9e79411aa765bfadb29f2f1945ed49ef56","best_bid":"0.96","best_ask":"0.97"},{"asset_id":"20773614133833886322101538939702011175545796528197617633926164254913649353392","price":"0.04","size":"4021.17","side":"SELL","hash":"05e0308bd15225da179b64fed26e3bf92e08da71","best_bid":"0.03","best_ask":"0.04"}],"timestamp":"1770839723575","event_type":"price_change","_sub_state":"active","_subscription_id":1,"_active_subscription_id":1},"parse_warnings":[],"out_of_order":false}
{"run_id":"29526913bab7446286864a321c124486","channel":"market","event_type":"price_change","market":"0x8032d8355d335c6ccbfc2508d99fbc87eb13f437bd275c93ee56fd1558e517ff","asset_id":null,"source":"market_ws:sub:active:1","t_event_ms":1770839723576,"t_recv_wall_ms":1770839723482,"t_recv_wall_iso":"2026-02-11T19:55:23.482Z","t_recv_mono_ns":618588823253041,"raw":{"market":"0x8032d8355d335c6ccbfc2508d99fbc87eb13f437bd275c93ee56fd1558e517ff","price_changes":[{"asset_id":"40652734036737240317526188612064032143639112324786051284480877037991580442979","price":"0.83","size":"963.39","side":"BUY","hash":"1b620b858a1abee592f6cfb2a40559f81f15f96b","best_bid":"0.96","best_ask":"0.97"},{"asset_id":"20773614133833886322101538939702011175545796528197617633926164254913649353392","price":"0.17","size":"963.39","side":"SELL","hash":"627725128a85d1e37b23315af738f7b2b05d38ae","best_bid":"0.03","best_ask":"0.04"}],"timestamp":"1770839723576","event_type":"price_change","_sub_state":"active","_subscription_id":1,"_active_subscription_id":1},"parse_warnings":[],"out_of_order":false}
{"run_id":"29526913bab7446286864a321c124486","channel":"market","event_type":"price_change","market":"0x8032d8355d335c6ccbfc2508d99fbc87eb13f437bd275c93ee56fd1558e517ff","asset_id":null,"source":"market_ws:sub:active:1","t_event_ms":1770839723578,"t_recv_wall_ms":1770839723483,"t_recv_wall_iso":"2026-02-11T19:55:23.483Z","t_recv_mono_ns":618588824044166,"raw":{"market":"0x8032d8355d335c6ccbfc2508d99fbc87eb13f437bd275c93ee56fd1558e517ff","price_changes":[{"asset_id":"40652734036737240317526188612064032143639112324786051284480877037991580442979","price":"0.96","size":"4081.17","side":"BUY","hash":"d8f4f4959cc24fc6492acbb5b28f01b2f1718aa4","best_bid":"0.96","best_ask":"0.97"},{"asset_id":"20773614133833886322101538939702011175545796528197617633926164254913649353392","price":"0.04","size":"4081.17","side":"SELL","hash":"646c43f0ea75fa012a2cb0c3b3976e39558c3a21","best_bid":"0.03","best_ask":"0.04"}],"timestamp":"1770839723578","event_type":"price_change","_sub_state":"active","_subscription_id":1,"_active_subscription_id":1},"parse_warnings":[],"out_of_order":false}
{"run_id":"29526913bab7446286864a321c124486","channel":"market","event_type":"price_change","market":"0x8032d8355d335c6ccbfc2508d99fbc87eb13f437bd275c93ee56fd1558e517ff","asset_id":null,"source":"market_ws:sub:active:1","t_event_ms":1770839723580,"t_recv_wall_ms":1770839723483,"t_recv_wall_iso":"2026-02-11T19:55:23.483Z","t_recv_mono_ns":618588824300625,"raw":{"market":"0x8032d8355d335c6ccbfc2508d99fbc87eb13f437bd275c93ee56fd1558e517ff","price_changes":[{"asset_id":"20773614133833886322101538939702011175545796528197617633926164254913649353392","price":"0.01","size":"30914.91","side":"BUY","hash":"e1604ca7e2ab24b34426488a3186140bc39ae48c","best_bid":"0.03","best_ask":"0.04"},{"asset_id":"40652734036737240317526188612064032143639112324786051284480877037991580442979","price":"0.99","size":"30914.91","side":"SELL","hash":"b2cb1ce888fc27add18210f652e89383714fdd72","best_bid":"0.96","best_ask":"0.97"}],"timestamp":"1770839723580","event_type":"price_change","_sub_state":"active","_subscription_id":1,"_active_subscription_id":1},"parse_warnings":[],"out_of_order":false}
{"run_id":"29526913bab7446286864a321c124486","channel":"market","event_type":"price_change","market":"0x8032d8355d335c6ccbfc2508d99fbc87eb13f437bd275c93ee56fd1558e517ff","asset_id":null,"source":"market_ws:sub:active:1","t_event_ms":1770839723592,"t_recv_wall_ms":1770839723497,"t_recv_wall_iso":"2026-02-11T19:55:23.497Z","t_recv_mono_ns":618588838597791,"raw":{"market":"0x8032d8355d335c6ccbfc2508d99fbc87eb13f437bd275c93ee56fd1558e517ff","price_changes":[{"asset_id":"20773614133833886322101538939702011175545796528197617633926164254913649353392","price":"0.01","size":"30854.91","side":"BUY","hash":"1d6e2dd317b08b9f12d11bf5cbe390161ca72a64","best_bid":"0.03","best_ask":"0.04"},{"asset_id":"40652734036737240317526188612064032143639112324786051284480877037991580442979","price":"0.99","size":"30854.91","side":"SELL","hash":"f996b739db5aa698607744d1bf3d922be373c5eb","best_bid":"0.96","best_ask":"0.97"}],"timestamp":"1770839723592","event_type":"price_change","_sub_state":"active","_subscription_id":1,"_active_subscription_id":1},"parse_warnings":[],"out_of_order":false}
{"run_id":"29526913bab7446286864a321c124486","channel":"market","event_type":"price_change","market":"0x8032d8355d335c6ccbfc2508d99fbc87eb13f437bd275c93ee56fd1558e517ff","asset_id":null,"source":"market_ws:sub:active:1","t_event_ms":1770839723595,"t_recv_wall_ms":1770839723503,"t_recv_wall_iso":"2026-02-11T19:55:23.503Z","t_recv_mono_ns":618588844577666,"raw":{"market":"0x8032d8355d335c6ccbfc2508d99fbc87eb13f437bd275c93ee56fd1558e517ff","price_changes":[{"asset_id":"40652734036737240317526188612064032143639112324786051284480877037991580442979","price":"0.95","size":"3175.79","side":"BUY","hash":"2aa4957e8fc907e7b8de78a1ab6beb0caf7455ab","best_bid":"0.96","best_ask":"0.97"},{"asset_id":"20773614133833886322101538939702011175545796528197617633926164254913649353392","price":"0.05","size":"3175.79","side":"SELL","hash":"b82e27eaeada1df81187485997389ab40c4a4ed1","best_bid":"0.03","best_ask":"0.04"}],"timestamp":"1770839723595","event_type":"price_change","_sub_state":"active","_subscription_id":1,"_active_subscription_id":1},"parse_warnings":[],"out_of_order":false}
{"run_id":"29526913bab7446286864a321c124486","channel":"market","event_type":"price_change","market":"0x8032d8355d335c6ccbfc2508d99fbc87eb13f437bd275c93ee56fd1558e517ff","asset_id":null,"source":"market_ws:sub:active:1","t_event_ms":1770839723596,"t_recv_wall_ms":1770839723504,"t_recv_wall_iso":"2026-02-11T19:55:23.504Z","t_recv_mono_ns":618588844897666,"raw":{"market":"0x8032d8355d335c6ccbfc2508d99fbc87eb13f437bd275c93ee56fd1558e517ff","price_changes":[{"asset_id":"40652734036737240317526188612064032143639112324786051284480877037991580442979","price":"0.95","size":"3235.79","side":"BUY","hash":"4582a17911b016310e1d7cec18f35847ca25e91d","best_bid":"0.96","best_ask":"0.97"},{"asset_id":"20773614133833886322101538939702011175545796528197617633926164254913649353392","price":"0.05","size":"3235.79","side":"SELL","hash":"58832fcdc185aa1ff26dbc360c81c2b53c40b7b3","best_bid":"0.03","best_ask":"0.04"}],"timestamp":"1770839723596","event_type":"price_change","_sub_state":"active","_subscription_id":1,"_active_subscription_id":1},"parse_warnings":[],"out_of_order":false}
{"run_id":"29526913bab7446286864a321c124486","channel":"market","event_type":"price_change","market":"0x8032d8355d335c6ccbfc2508d99fbc87eb13f437bd275c93ee56fd1558e517ff","asset_id":null,"source":"market_ws:sub:active:1","t_event_ms":1770839723598,"t_recv_wall_ms":1770839723512,"t_recv_wall_iso":"2026-02-11T19:55:23.512Z","t_recv_mono_ns":618588853135666,"raw":{"market":"0x8032d8355d335c6ccbfc2508d99fbc87eb13f437bd275c93ee56fd1558e517ff","price_changes":[{"asset_id":"40652734036737240317526188612064032143639112324786051284480877037991580442979","price":"0.96","size":"4021.17","side":"BUY","hash":"94b9510c191ae40833d647f478cc287dee60af88","best_bid":"0.96","best_ask":"0.97"},{"asset_id":"20773614133833886322101538939702011175545796528197617633926164254913649353392","price":"0.04","size":"4021.17","side":"SELL","hash":"48d0b2674035aed16441cb9e7125fae045b78f30","best_bid":"0.03","best_ask":"0.04"}],"timestamp":"1770839723598","event_type":"price_change","_sub_state":"active","_subscription_id":1,"_active_subscription_id":1},"parse_warnings":[],"out_of_order":false}
{"run_id":"29526913bab7446286864a321c124486","channel":"market","event_type":"price_change","market":"0x8032d8355d335c6ccbfc2508d99fbc87eb13f437bd275c93ee56fd1558e517ff","asset_id":null,"source":"market_ws:sub:active:1","t_event_ms":1770839723600,"t_recv_wall_ms":1770839723512,"t_recv_wall_iso":"2026-02-11T19:55:23.512Z","t_recv_mono_ns":618588853729291,"raw":{"market":"0x8032d8355d335c6ccbfc2508d99fbc87eb13f437bd275c93ee56fd1558e517ff","price_changes":[{"asset_id":"40652734036737240317526188612064032143639112324786051284480877037991580442979","price":"0.96","size":"4081.17","side":"BUY","hash":"d0c0036093a6b025edbe6c397392cf4f84da77e9","best_bid":"0.96","best_ask":"0.97"},{"asset_id":"20773614133833886322101538939702011175545796528197617633926164254913649353392","price":"0.04","size":"4081.17","side":"SELL","hash":"c6cb11271ee6be23f710404d575b10b9f502fbd7","best_bid":"0.03","best_ask":"0.04"}],"timestamp":"1770839723600","event_type":"price_change","_sub_state":"active","_subscription_id":1,"_active_subscription_id":1},"parse_warnings":[],"out_of_order":false}
{"run_id":"29526913bab7446286864a321c124486","channel":"market","event_type":"price_change","market":"0x8032d8355d335c6ccbfc2508d99fbc87eb13f437bd275c93ee56fd1558e517ff","asset_id":null,"source":"market_ws:sub:active:1","t_event_ms":1770839723602,"t_recv_wall_ms":1770839723513,"t_recv_wall_iso":"2026-02-11T19:55:23.513Z","t_recv_mono_ns":618588853915041,"raw":{"market":"0x8032d8355d335c6ccbfc2508d99fbc87eb13f437bd275c93ee56fd1558e517ff","price_changes":[{"asset_id":"40652734036737240317526188612064032143639112324786051284480877037991580442979","price":"0.95","size":"3169.45","side":"BUY","hash":"ef26db5fc008e94f2824359b713b8033f29c79fb","best_bid":"0.96","best_ask":"0.97"},{"asset_id":"20773614133833886322101538939702011175545796528197617633926164254913649353392","price":"0.05","size":"3169.45","side":"SELL","hash":"d3e39f42a54c8b967d35927a1c1724dab4a72625","best_bid":"0.03","best_ask":"0.04"}],"timestamp":"1770839723602","event_type":"price_change","_sub_state":"active","_subscription_id":1,"_active_subscription_id":1},"parse_warnings":[],"out_of_order":false}
{"run_id":"29526913bab7446286864a321c124486","channel":"market","event_type":"price_change","market":"0x8032d8355d335c6ccbfc2508d99fbc87eb13f437bd275c93ee56fd1558e517ff","asset_id":null,"source":"market_ws:sub:active:1","t_event_ms":1770839723604,"t_recv_wall_ms":1770839723513,"t_recv_wall_iso":"2026-02-11T19:55:23.513Z","t_recv_mono_ns":618588854052000,"raw":{"market":"0x8032d8355d335c6ccbfc2508d99fbc87eb13f437bd275c93ee56fd1558e517ff","price_changes":[{"asset_id":"20773614133833886322101538939702011175545796528197617633926164254913649353392","price":"0.02","size":"8819.25","side":"BUY","hash":"6d2301a68a3304379611cb692a888dc3ee90432a","best_bid":"0.03","best_ask":"0.04"},{"asset_id":"40652734036737240317526188612064032143639112324786051284480877037991580442979","price":"0.98","size":"8819.25","side":"SELL","hash":"c5720397d971da5ebdda447c67f1df0ab17f07dc","best_bid":"0.96","best_ask":"0.97"}],"timestamp":"1770839723604","event_type":"price_change","_sub_state":"active","_subscription_id":1,"_active_subscription_id":1},"parse_warnings":[],"out_of_order":false}
{"run_id":"29526913bab7446286864a321c124486","channel":"market","event_type":"price_change","market":"0x8032d8355d335c6ccbfc2508d99fbc87eb13f437bd275c93ee56fd1558e517ff","asset_id":null,"source":"market_ws:sub:active:1","t_event_ms":1770839723608,"t_recv_wall_ms":1770839723516,"t_recv_wall_iso":"2026-02-11T19:55:23.516Z","t_recv_mono_ns":618588857205958,"raw":{"market":"0x8032d8355d335c6ccbfc2508d99fbc87eb13f437bd275c93ee56fd1558e517ff","price_changes":[{"asset_id":"40652734036737240317526188612064032143639112324786051284480877037991580442979","price":"0.96","size":"4051.17","side":"BUY","hash":"67eb7cf4f0ff90e4a49814b5f1a6c6e3162dbb74","best_bid":"0.96","best_ask":"0.97"},{"asset_id":"20773614133833886322101538939702011175545796528197617633926164254913649353392","price":"0.04","size":"4051.17","side":"SELL","hash":"c50df66c90ccea22cef41173ebcd24c928e90b63","best_bid":"0.03","best_ask":"0.04"}],"timestamp":"1770839723608","event_type":"price_change","_sub_state":"active","_subscription_id":1,"_active_subscription_id":1},"parse_warnings":[],"out_of_order":false}
{"run_id":"29526913bab7446286864a321c124486","channel":"market","event_type":"last_trade_price","market":"0x8032d8355d335c6ccbfc2508d99fbc87eb13f437bd275c93ee56fd1558e517ff","asset_id":"40652734036737240317526188612064032143639112324786051284480877037991580442979","source":"market_ws:sub:unknown","t_event_ms":1770839723609,"t_recv_wall_ms":1770839723516,"t_recv_wall_iso":"2026-02-11T19:55:23.516Z","t_recv_mono_ns":618588857640833,"raw":{"market":"0x8032d8355d335c6ccbfc2508d99fbc87eb13f437bd275c93ee56fd1558e517ff","asset_id":"40652734036737240317526188612064032143639112324786051284480877037991580442979","price":"0.97","size":"9","fee_rate_bps":"1000","side":"BUY","timestamp":"1770839723609","event_type":"last_trade_price","transaction_hash":"0xbe9430d07615e8719ceaeb55aaccf43736974f0fb0518b0d61ed8b529dbd1ed1","_sub_state":"unknown","_subscription_id":null,"_active_subscription_id":1},"parse_warnings":["unknown_message_schema"],"out_of_order":false}
{"run_id":"29526913bab7446286864a321c124486","channel":"market","event_type":"price_change","market":"0x8032d8355d335c6ccbfc2508d99fbc87eb13f437bd275c93ee56fd1558e517ff","asset_id":null,"source":"market_ws:sub:active:1","t_event_ms":1770839723612,"t_recv_wall_ms":1770839723517,"t_recv_wall_iso":"2026-02-11T19:55:23.517Z","t_recv_mono_ns":618588857808666,"raw":{"market":"0x8032d8355d335c6ccbfc2508d99fbc87eb13f437bd275c93ee56fd1558e517ff","price_changes":[{"asset_id":"40652734036737240317526188612064032143639112324786051284480877037991580442979","price":"0.96","size":"4021.17","side":"BUY","hash":"28642cc991f9da73c75db73c4c518060b8b42e22","best_bid":"0.96","best_ask":"0.97"},{"asset_id":"20773614133833886322101538939702011175545796528197617633926164254913649353392","price":"0.04","size":"4021.17","side":"SELL","hash":"86d9aa9dd2b94d5c97b1c7437c96923c64aaab32","best_bid":"0.03","best_ask":"0.04"}],"timestamp":"1770839723612","event_type":"price_change","_sub_state":"active","_subscription_id":1,"_active_subscription_id":1},"parse_warnings":[],"out_of_order":false}
{"run_id":"29526913bab7446286864a321c124486","channel":"market","event_type":"price_change","market":"0x8032d8355d335c6ccbfc2508d99fbc87eb13f437bd275c93ee56fd1558e517ff","asset_id":null,"source":"market_ws:sub:active:1","t_event_ms":1770839723613,"t_recv_wall_ms":1770839723533,"t_recv_wall_iso":"2026-02-11T19:55:23.533Z","t_recv_mono_ns":618588874025583,"raw":{"market":"0x8032d8355d335c6ccbfc2508d99fbc87eb13f437bd275c93ee56fd1558e517ff","price_changes":[{"asset_id":"40652734036737240317526188612064032143639112324786051284480877037991580442979","price":"0.96","size":"3961.17","side":"BUY","hash":"a08ea36ce08f99b40fc4113d8b2c5d667227f7db","best_bid":"0.96","best_ask":"0.97"},{"asset_id":"20773614133833886322101538939702011175545796528197617633926164254913649353392","price":"0.04","size":"3961.17","side":"SELL","hash":"968d5059523108b4fe9ecd8a601f3b163a0806bc","best_bid":"0.03","best_ask":"0.04"}],"timestamp":"1770839723613","event_type":"price_change","_sub_state":"active","_subscription_id":1,"_active_subscription_id":1},"parse_warnings":[],"out_of_order":false}
{"run_id":"29526913bab7446286864a321c124486","channel":"market","event_type":"price_change","market":"0x8032d8355d335c6ccbfc2508d99fbc87eb13f437bd275c93ee56fd1558e517ff","asset_id":null,"source":"market_ws:sub:active:1","t_event_ms":1770839723614,"t_recv_wall_ms":1770839723533,"t_recv_wall_iso":"2026-02-11T19:55:23.533Z","t_recv_mono_ns":618588874545875,"raw":{"market":"0x8032d8355d335c6ccbfc2508d99fbc87eb13f437bd275c93ee56fd1558e517ff","price_changes":[{"asset_id":"40652734036737240317526188612064032143639112324786051284480877037991580442979","price":"0.96","size":"3931.17","side":"BUY","hash":"159fa9e19d0ea3c3cff586d88b8f3e1cf467d320","best_bid":"0.96","best_ask":"0.97"},{"asset_id":"20773614133833886322101538939702011175545796528197617633926164254913649353392","price":"0.04","size":"3931.17","side":"SELL","hash":"17b0221dd230b105028833116ac7db2edb06017f","best_bid":"0.03","best_ask":"0.04"}],"timestamp":"1770839723614","event_type":"price_change","_sub_state":"active","_subscription_id":1,"_active_subscription_id":1},"parse_warnings":[],"out_of_order":false}
{"run_id":"29526913bab7446286864a321c124486","channel":"market","event_type":"price_change","market":"0x8032d8355d335c6ccbfc2508d99fbc87eb13f437bd275c93ee56fd1558e517ff","asset_id":null,"source":"market_ws:sub:active:1","t_event_ms":1770839723616,"t_recv_wall_ms":1770839723533,"t_recv_wall_iso":"2026-02-11T19:55:23.533Z","t_recv_mono_ns":618588874720916,"raw":{"market":"0x8032d8355d335c6ccbfc2508d99fbc87eb13f437bd275c93ee56fd1558e517ff","price_changes":[{"asset_id":"20773614133833886322101538939702011175545796528197617633926164254913649353392","price":"0.01","size":"30884.91","side":"BUY","hash":"b58d2674546f4f662c788dfbfd820d2583e3bcfb","best_bid":"0.03","best_ask":"0.04"},{"asset_id":"40652734036737240317526188612064032143639112324786051284480877037991580442979","price":"0.99","size":"30884.91","side":"SELL","hash":"a1599aabbbb500eecdec8ce34e1bb739b66aff6c","best_bid":"0.96","best_ask":"0.97"}],"timestamp":"1770839723616","event_type":"price_change","_sub_state":"active","_subscription_id":1,"_active_subscription_id":1},"parse_warnings":[],"out_of_order":false}
{"run_id":"29526913bab7446286864a321c124486","channel":"market","event_type":"price_change","market":"0x8032d8355d335c6ccbfc2508d99fbc87eb13f437bd275c93ee56fd1558e517ff","asset_id":null,"source":"market_ws:sub:active:1","t_event_ms":1770839723619,"t_recv_wall_ms":1770839723534,"t_recv_wall_iso":"2026-02-11T19:55:23.534Z","t_recv_mono_ns":618588874859666,"raw":{"market":"0x8032d8355d335c6ccbfc2508d99fbc87eb13f437bd275c93ee56fd1558e517ff","price_changes":[{"asset_id":"40652734036737240317526188612064032143639112324786051284480877037991580442979","price":"0.96","size":"3871.17","side":"BUY","hash":"667a013eed609918917a285d732969d0ea1a493d","best_bid":"0.96","best_ask":"0.97"},{"asset_id":"20773614133833886322101538939702011175545796528197617633926164254913649353392","price":"0.04","size":"3871.17","side":"SELL","hash":"017502649713fe462aefc6912a3b698a3e58a538","best_bid":"0.03","best_ask":"0.04"}],"timestamp":"1770839723619","event_type":"price_change","_sub_state":"active","_subscription_id":1,"_active_subscription_id":1},"parse_warnings":[],"out_of_order":false}
{"run_id":"29526913bab7446286864a321c124486","channel":"market","event_type":"price_change","market":"0x8032d8355d335c6ccbfc2508d99fbc87eb13f437bd275c93ee56fd1558e517ff","asset_id":null,"source":"market_ws:sub:active:1","t_event_ms":1770839723643,"t_recv_wall_ms":1770839723561,"t_recv_wall_iso":"2026-02-11T19:55:23.561Z","t_recv_mono_ns":618588902675791,"raw":{"market":"0x8032d8355d335c6ccbfc2508d99fbc87eb13f437bd275c93ee56fd1558e517ff","price_changes":[{"asset_id":"40652734036737240317526188612064032143639112324786051284480877037991580442979","price":"0.96","size":"3854.17","side":"BUY","hash":"3450838377eb3598cdba6414931c07082a09cd2f","best_bid":"0.96","best_ask":"0.97"},{"asset_id":"20773614133833886322101538939702011175545796528197617633926164254913649353392","price":"0.04","size":"3854.17","side":"SELL","hash":"5eefee3738236c68e85ba3b322231258ce15d6e4","best_bid":"0.03","best_ask":"0.04"}],"timestamp":"1770839723643","event_type":"price_change","_sub_state":"active","_subscription_id":1,"_active_subscription_id":1},"parse_warnings":[],"out_of_order":false}
{"run_id":"29526913bab7446286864a321c124486","channel":"market","event_type":"price_change","market":"0x8032d8355d335c6ccbfc2508d99fbc87eb13f437bd275c93ee56fd1558e517ff","asset_id":null,"source":"market_ws:sub:active:1","t_event_ms":1770839723665,"t_recv_wall_ms":1770839723586,"t_recv_wall_iso":"2026-02-11T19:55:23.586Z","t_recv_mono_ns":618588927244750,"raw":{"market":"0x8032d8355d335c6ccbfc2508d99fbc87eb13f437bd275c93ee56fd1558e517ff","price_changes":[{"asset_id":"40652734036737240317526188612064032143639112324786051284480877037991580442979","price":"0.83","size":"958.39","side":"BUY","hash":"905b5f06984ea9f609cd661662c1afdaf23948f0","best_bid":"0.96","best_ask":"0.97"},{"asset_id":"20773614133833886322101538939702011175545796528197617633926164254913649353392","price":"0.17","size":"958.39","side":"SELL","hash":"7b886765a29c56204c0f48409d0734d599ed5b95","best_bid":"0.03","best_ask":"0.04"}],"timestamp":"1770839723665","event_type":"price_change","_sub_state":"active","_subscription_id":1,"_active_subscription_id":1},"parse_warnings":[],"out_of_order":false}
{"run_id":"29526913bab7446286864a321c124486","channel":"market","event_type":"price_change","market":"0x8032d8355d335c6ccbfc2508d99fbc87eb13f437bd275c93ee56fd1558e517ff","asset_id":null,"source":"market_ws:sub:active:1","t_event_ms":1770839723699,"t_recv_wall_ms":1770839723611,"t_recv_wall_iso":"2026-02-11T19:55:23.611Z","t_recv_mono_ns":618588952579583,"raw":{"market":"0x8032d8355d335c6ccbfc2508d99fbc87eb13f437bd275c93ee56fd1558e517ff","price_changes":[{"asset_id":"20773614133833886322101538939702011175545796528197617633926164254913649353392","price":"0.01","size":"30854.91","side":"BUY","hash":"75fd4aae9a3f03f87020f6ef64043b67ad0d9a25","best_bid":"0.03","best_ask":"0.04"},{"asset_id":"40652734036737240317526188612064032143639112324786051284480877037991580442979","price":"0.99","size":"30854.91","side":"SELL","hash":"98f44dc800bc898eda3f07874e4a465b09cdde6a","best_bid":"0.96","best_ask":"0.97"}],"timestamp":"1770839723699","event_type":"price_change","_sub_state":"active","_subscription_id":1,"_active_subscription_id":1},"parse_warnings":[],"out_of_order":false}
{"run_id":"29526913bab7446286864a321c124486","channel":"market","event_type":"price_change","market":"0x8032d8355d335c6ccbfc2508d99fbc87eb13f437bd275c93ee56fd1558e517ff","asset_id":null,"source":"market_ws:sub:active:1","t_event_ms":1770839723701,"t_recv_wall_ms":1770839723612,"t_recv_wall_iso":"2026-02-11T19:55:23.612Z","t_recv_mono_ns":618588952893666,"raw":{"market":"0x8032d8355d335c6ccbfc2508d99fbc87eb13f437bd275c93ee56fd1558e517ff","price_changes":[{"asset_id":"40652734036737240317526188612064032143639112324786051284480877037991580442979","price":"0.95","size":"3199.45","side":"BUY","hash":"48e5198848df66e2f2e5338e1f1f452f532cb7c4","best_bid":"0.96","best_ask":"0.97"},{"asset_id":"20773614133833886322101538939702011175545796528197617633926164254913649353392","price":"0.05","size":"3199.45","side":"SELL","hash":"5b13d04fa5740f27b495fc46b6b7fb4651a2e0c4","best_bid":"0.03","best_ask":"0.04"}],"timestamp":"1770839723701","event_type":"price_change","_sub_state":"active","_subscription_id":1,"_active_subscription_id":1},"parse_warnings":[],"out_of_order":false}
{"run_id":"29526913bab7446286864a321c124486","channel":"market","event_type":"price_change","market":"0x8032d8355d335c6ccbfc2508d99fbc87eb13f437bd275c93ee56fd1558e517ff","asset_id":null,"source":"market_ws:sub:active:1","t_event_ms":1770839723703,"t_recv_wall_ms":1770839723612,"t_recv_wall_iso":"2026-02-11T19:55:23.612Z","t_recv_mono_ns":618588953019541,"raw":{"market":"0x8032d8355d335c6ccbfc2508d99fbc87eb13f437bd275c93ee56fd1558e517ff","price_changes":[{"asset_id":"40652734036737240317526188612064032143639112324786051284480877037991580442979","price":"0.95","size":"3229.45","side":"BUY","hash":"2411bdfbd0e2bb15e77ae38781e85559e3d11801","best_bid":"0.96","best_ask":"0.97"},{"asset_id":"20773614133833886322101538939702011175545796528197617633926164254913649353392","price":"0.05","size":"3229.45","side":"SELL","hash":"1511906f93076887e4e163ef11a1ee20a01ceb43","best_bid":"0.03","best_ask":"0.04"}],"timestamp":"1770839723703","event_type":"price_change","_sub_state":"active","_subscription_id":1,"_active_subscription_id":1},"parse_warnings":[],"out_of_order":false}
{"run_id":"29526913bab7446286864a321c124486","channel":"market","event_type":"price_change","market":"0x8032d8355d335c6ccbfc2508d99fbc87eb13f437bd275c93ee56fd1558e517ff","asset_id":null,"source":"market_ws:sub:active:1","t_event_ms":1770839723706,"t_recv_wall_ms":1770839723615,"t_recv_wall_iso":"2026-02-11T19:55:23.615Z","t_recv_mono_ns":618588956081791,"raw":{"market":"0x8032d8355d335c6ccbfc2508d99fbc87eb13f437bd275c93ee56fd1558e517ff","price_changes":[{"asset_id":"40652734036737240317526188612064032143639112324786051284480877037991580442979","price":"0.95","size":"3259.45","side":"BUY","hash":"40de526d475ab678d77923803fca53a18884d137","best_bid":"0.96","best_ask":"0.97"},{"asset_id":"20773614133833886322101538939702011175545796528197617633926164254913649353392","price":"0.05","size":"3259.45","side":"SELL","hash":"5921241e32007daf141c302807d1e821366acdf9","best_bid":"0.03","best_ask":"0.04"}],"timestamp":"1770839723706","event_type":"price_change","_sub_state":"active","_subscription_id":1,"_active_subscription_id":1},"parse_warnings":[],"out_of_order":false}
{"run_id":"29526913bab7446286864a321c124486","channel":"market","event_type":"price_change","market":"0x8032d8355d335c6ccbfc2508d99fbc87eb13f437bd275c93ee56fd1558e517ff","asset_id":null,"source":"market_ws:sub:active:1","t_event_ms":1770839723710,"t_recv_wall_ms":1770839723616,"t_recv_wall_iso":"2026-02-11T19:55:23.616Z","t_recv_mono_ns":618588957037750,"raw":{"market":"0x8032d8355d335c6ccbfc2508d99fbc87eb13f437bd275c93ee56fd1558e517ff","price_changes":[{"asset_id":"40652734036737240317526188612064032143639112324786051284480877037991580442979","price":"0.95","size":"3289.45","side":"BUY","hash":"9f411cf815b00b6b3aba33a7d4f53e1a22a66084","best_bid":"0.96","best_ask":"0.97"},{"asset_id":"20773614133833886322101538939702011175545796528197617633926164254913649353392","price":"0.05","size":"3289.45","side":"SELL","hash":"1dde0ba7ef00fb8d6c42c08d3dfbffb871910eba","best_bid":"0.03","best_ask":"0.04"}],"timestamp":"1770839723710","event_type":"price_change","_sub_state":"active","_subscription_id":1,"_active_subscription_id":1},"parse_warnings":[],"out_of_order":false}
{"run_id":"29526913bab7446286864a321c124486","channel":"market","event_type":"price_change","market":"0x8032d8355d335c6ccbfc2508d99fbc87eb13f437bd275c93ee56fd1558e517ff","asset_id":null,"source":"market_ws:sub:active:1","t_event_ms":1770839723712,"t_recv_wall_ms":1770839723616,"t_recv_wall_iso":"2026-02-11T19:55:23.616Z","t_recv_mono_ns":618588957193958,"raw":{"market":"0x8032d8355d335c6ccbfc2508d99fbc87eb13f437bd275c93ee56fd1558e517ff","price_changes":[{"asset_id":"40652734036737240317526188612064032143639112324786051284480877037991580442979","price":"0.98","size":"8824.25","side":"SELL","hash":"b5684b82a711b817cb997d020ef198066a0bfad6","best_bid":"0.96","best_ask":"0.97"},{"asset_id":"20773614133833886322101538939702011175545796528197617633926164254913649353392","price":"0.02","size":"8824.25","side":"BUY","hash":"d1968a9d26077a72b68829872e28ae7e6e00801f","best_bid":"0.03","best_ask":"0.04"}],"timestamp":"1770839723712","event_type":"price_change","_sub_state":"active","_subscription_id":1,"_active_subscription_id":1},"parse_warnings":[],"out_of_order":false}
{"run_id":"29526913bab7446286864a321c124486","channel":"market","event_type":"price_change","market":"0x8032d8355d335c6ccbfc2508d99fbc87eb13f437bd275c93ee56fd1558e517ff","asset_id":null,"source":"market_ws:sub:active:1","t_event_ms":1770839723752,"t_recv_wall_ms":1770839723659,"t_recv_wall_iso":"2026-02-11T19:55:23.659Z","t_recv_mono_ns":618588999912958,"raw":{"market":"0x8032d8355d335c6ccbfc2508d99fbc87eb13f437bd275c93ee56fd1558e517ff","price_changes":[{"asset_id":"20773614133833886322101538939702011175545796528197617633926164254913649353392","price":"0.03","size":"42.68","side":"BUY","hash":"6bd096534b942a6f204f16be99bdcabf9405122f","best_bid":"0.03","best_ask":"0.04"},{"asset_id":"40652734036737240317526188612064032143639112324786051284480877037991580442979","price":"0.97","size":"42.68","side":"SELL","hash":"121c0021b5efc9735cf309d3675f891fa6207cb5","best_bid":"0.96","best_ask":"0.97"}],"timestamp":"1770839723752","event_type":"price_change","_sub_state":"active","_subscription_id":1,"_active_subscription_id":1},"parse_warnings":[],"out_of_order":false}
{"run_id":"29526913bab7446286864a321c124486","channel":"market","event_type":"book","market":"0x8032d8355d335c6ccbfc2508d99fbc87eb13f437bd275c93ee56fd1558e517ff","asset_id":"20773614133833886322101538939702011175545796528197617633926164254913649353392","source":"market_ws:sub:active:1","t_event_ms":1770839723752,"t_recv_wall_ms":1770839723659,"t_recv_wall_iso":"2026-02-11T19:55:23.659Z","t_recv_mono_ns":618589000272166,"raw":{"market":"0x8032d8355d335c6ccbfc2508d99fbc87eb13f437bd275c93ee56fd1558e517ff","asset_id":"20773614133833886322101538939702011175545796528197617633926164254913649353392","bids":[{"price":"0.01","size":"30854.91"},{"price":"0.02","size":"8824.25"},{"price":"0.03","size":"42.68"}],"asks":[{"price":"0.99","size":"30822.26"},{"price":"0.98","size":"12559.04"},{"price":"0.97","size":"7433.03"},{"price":"0.96","size":"5453.8"},{"price":"0.95","size":"6815.8"},{"price":"0.94","size":"5105"},{"price":"0.93","size":"5421.38"},{"price":"0.92","size":"5139.4"},{"price":"0.91","size":"5225.8"},{"price":"0.9","size":"5102.8"},{"price":"0.89","size":"120.6"},{"price":"0.88","size":"63.6"},{"price":"0.87","size":"63"},{"price":"0.86","size":"61.6"},{"price":"0.85","size":"107.39"},{"price":"0.84","size":"69.39"},{"price":"0.83","size":"58.39"},{"price":"0.82","size":"66.71"},{"price":"0.81","size":"56.8"},{"price":"0.8","size":"92.14"},{"price":"0.79","size":"60.8"},{"price":"0.78","size":"55.2"},{"price":"0.77","size":"64.48"},{"price":"0.76","size":"54.2"},{"price":"0.75","size":"375.8"},{"price":"0.74","size":"68.6"},{"price":"0.73","size":"53.2"},{"price":"0.72","size":"63.26"},{"price":"0.71","size":"52.6"},{"price":"0.7","size":"402.4"},{"price":"0.69","size":"72.2"},{"price":"0.68","size":"87.88"},{"price":"0.67","size":"188.46"},{"price":"0.66","size":"123.6"},{"price":"0.65","size":"317.03"},{"price":"0.64","size":"582.36"},{"price":"0.63","size":"559.2"},{"price":"0.62","size":"559"},{"price":"0.61","size":"594"},{"price":"0.6","size":"2915.41"},{"price":"0.59","size":"576.8"},{"price":"0.58","size":"575.5"},{"price":"0.57","size":"558.6"},{"price":"0.56","size":"572.68"},{"price":"0.55","size":"566.4"},{"price":"0.54","size":"561.94"},{"price":"0.53","size":"631.57"},{"price":"0.52","size":"611.4"},{"price":"0.51","size":"705.2"},{"price":"0.5","size":"1011.55"},{"price":"0.49","size":"692.4"},{"price":"0.48","size":"628.4"},{"price":"0.47","size":"633.4"},{"price":"0.46","size":"711.65"},{"price":"0.45","size":"866.59"},{"price":"0.44","size":"905.69"},{"price":"0.43","size":"641.6"},{"price":"0.42","size":"645.58"},{"price":"0.41","size":"564"},{"price":"0.4","size":"20642.9"},{"price":"0.39","size":"650.23"},{"price":"0.38","size":"593"},{"price":"0.37","size":"755.73"},{"price":"0.36","size":"558"},{"price":"0.35","size":"1144.32"},{"price":"0.34","size":"649.59"},{"price":"0.33","size":"624.8"},{"price":"0.32","size":"574"},{"price":"0.31","size":"594.2"},{"price":"0.3","size":"735.66"},{"price":"0.29","size":"924.6"},{"price":"0.28","size":"356.8"},{"price":"0.27","size":"869.2"},{"price":"0.26","size":"967.6"},{"price":"0.25","size":"1673.8"},{"price":"0.24","size":"869.2"},{"price":"0.23","size":"864.6"},{"price":"0.22","size":"870.2"},{"price":"0.21","size":"871.6"},{"price":"0.2","size":"987.2"},{"price":"0.19","size":"876.8"},{"price":"0.18","size":"1091.55"},{"price":"0.17","size":"958.39"},{"price":"0.16","size":"1119.39"},{"price":"0.15","size":"1149.13"},{"price":"0.14","size":"962.6"},{"price":"0.13","size":"1041.8"},{"price":"0.12","size":"1060.55"},{"price":"0.11","size":"1124.49"},{"price":"0.1","size":"1191.79"},{"price":"0.09","size":"589.6"},{"price":"0.08","size":"3424.35"},{"price":"0.07","size":"3340.43"},{"price":"0.06","size":"3220.34"},{"price":"0.05","size":"3289.45"},{"price":"0.04","size":"3854.17"}],"hash":"6bd096534b942a6f204f16be99bdcabf9405122f","timestamp":"1770839723752","event_type":"book","_sub_state":"active","_subscription_id":1,"_active_subscription_id":1},"parse_warnings":[],"out_of_order":false}
{"run_id":"29526913bab7446286864a321c124486","channel":"market","event_type":"book","market":"0x8032d8355d335c6ccbfc2508d99fbc87eb13f437bd275c93ee56fd1558e517ff","asset_id":"40652734036737240317526188612064032143639112324786051284480877037991580442979","source":"market_ws:sub:active:1","t_event_ms":1770839723752,"t_recv_wall_ms":1770839723660,"t_recv_wall_iso":"2026-02-11T19:55:23.660Z","t_recv_mono_ns":618589000814541,"raw":{"market":"0x8032d8355d335c6ccbfc2508d99fbc87eb13f437bd275c93ee56fd1558e517ff","asset_id":"40652734036737240317526188612064032143639112324786051284480877037991580442979","bids":[{"price":"0.01","size":"30822.26"},{"price":"0.02","size":"12559.04"},{"price":"0.03","size":"7433.03"},{"price":"0.04","size":"5453.8"},{"price":"0.05","size":"6815.8"},{"price":"0.06","size":"5105"},{"price":"0.07","size":"5421.38"},{"price":"0.08","size":"5139.4"},{"price":"0.09","size":"5225.8"},{"price":"0.1","size":"5102.8"},{"price":"0.11","size":"120.6"},{"price":"0.12","size":"63.6"},{"price":"0.13","size":"63"},{"price":"0.14","size":"61.6"},{"price":"0.15","size":"107.39"},{"price":"0.16","size":"69.39"},{"price":"0.17","size":"58.39"},{"price":"0.18","size":"66.71"},{"price":"0.19","size":"56.8"},{"price":"0.2","size":"92.14"},{"price":"0.21","size":"60.8"},{"price":"0.22","size":"55.2"},{"price":"0.23","size":"64.48"},{"price":"0.24","size":"54.2"},{"price":"0.25","size":"375.8"},{"price":"0.26","size":"68.6"},{"price":"0.27","size":"53.2"},{"price":"0.28","size":"63.26"},{"price":"0.29","size":"52.6"},{"price":"0.3","size":"402.4"},{"price":"0.31","size":"72.2"},{"price":"0.32","size":"87.88"},{"price":"0.33","size":"188.46"},{"price":"0.34","size":"123.6"},{"price":"0.35","size":"317.03"},{"price":"0.36","size":"582.36"},{"price":"0.37","size":"559.2"},{"price":"0.38","size":"559"},{"price":"0.39","size":"594"},{"price":"0.4","size":"2915.41"},{"price":"0.41","size":"576.8"},{"price":"0.42","size":"575.5"},{"price":"0.43","size":"558.6"},{"price":"0.44","size":"572.68"},{"price":"0.45","size":"566.4"},{"price":"0.46","size":"561.94"},{"price":"0.47","size":"631.57"},{"price":"0.48","size":"611.4"},{"price":"0.49","size":"705.2"},{"price":"0.5","size":"1011.55"},{"price":"0.51","size":"692.4"},{"price":"0.52","size":"628.4"},{"price":"0.53","size":"633.4"},{"price":"0.54","size":"711.65"},{"price":"0.55","size":"866.59"},{"price":"0.56","size":"905.69"},{"price":"0.57","size":"641.6"},{"price":"0.58","size":"645.58"},{"price":"0.59","size":"564"},{"price":"0.6","size":"20642.9"},{"price":"0.61","size":"650.23"},{"price":"0.62","size":"593"},{"price":"0.63","size":"755.73"},{"price":"0.64","size":"558"},{"price":"0.65","size":"1144.32"},{"price":"0.66","size":"649.59"},{"price":"0.67","size":"624.8"},{"price":"0.68","size":"574"},{"price":"0.69","size":"594.2"},{"price":"0.7","size":"735.66"},{"price":"0.71","size":"924.6"},{"price":"0.72","size":"356.8"},{"price":"0.73","size":"869.2"},{"price":"0.74","size":"967.6"},{"price":"0.75","size":"1673.8"},{"price":"0.76","size":"869.2"},{"price":"0.77","size":"864.6"},{"price":"0.78","size":"870.2"},{"price":"0.79","size":"871.6"},{"price":"0.8","size":"987.2"},{"price":"0.81","size":"876.8"},{"price":"0.82","size":"1091.55"},{"price":"0.83","size":"958.39"},{"price":"0.84","size":"1119.39"},{"price":"0.85","size":"1149.13"},{"price":"0.86","size":"962.6"},{"price":"0.87","size":"1041.8"},{"price":"0.88","size":"1060.55"},{"price":"0.89","size":"1124.49"},{"price":"0.9","size":"1191.79"},{"price":"0.91","size":"589.6"},{"price":"0.92","size":"3424.35"},{"price":"0.93","size":"3340.43"},{"price":"0.94","size":"3220.34"},{"price":"0.95","size":"3289.45"},{"price":"0.96","size":"3854.17"}],"asks":[{"price":"0.99","size":"30854.91"},{"price":"0.98","size":"8824.25"},{"price":"0.97","size":"42.68"}],"hash":"121c0021b5efc9735cf309d3675f891fa6207cb5","timestamp":"1770839723752","event_type":"book","_sub_state":"active","_subscription_id":1,"_active_subscription_id":1},"parse_warnings":[],"out_of_order":false}
{"run_id":"29526913bab7446286864a321c124486","channel":"market","event_type":"price_change","market":"0x8032d8355d335c6ccbfc2508d99fbc87eb13f437bd275c93ee56fd1558e517ff","asset_id":null,"source":"market_ws:sub:active:1","t_event_ms":1770839723757,"t_recv_wall_ms":1770839723664,"t_recv_wall_iso":"2026-02-11T19:55:23.664Z","t_recv_mono_ns":618589005088958,"raw":{"market":"0x8032d8355d335c6ccbfc2508d99fbc87eb13f437bd275c93ee56fd1558e517ff","price_changes":[{"asset_id":"40652734036737240317526188612064032143639112324786051284480877037991580442979","price":"0.94","size":"3215.34","side":"BUY","hash":"792aa3facd657ad1b19c368f0dcef38080e53225","best_bid":"0.96","best_ask":"0.97"},{"asset_id":"20773614133833886322101538939702011175545796528197617633926164254913649353392","price":"0.06","size":"3215.34","side":"SELL","hash":"36b0332de015a066ba3258b96e7d0f512279452e","best_bid":"0.03","best_ask":"0.04"}],"timestamp":"1770839723757","event_type":"price_change","_sub_state":"active","_subscription_id":1,"_active_subscription_id":1},"parse_warnings":[],"out_of_order":false}
{"run_id":"29526913bab7446286864a321c124486","channel":"market","event_type":"price_change","market":"0x8032d8355d335c6ccbfc2508d99fbc87eb13f437bd275c93ee56fd1558e517ff","asset_id":null,"source":"market_ws:sub:active:1","t_event_ms":1770839723770,"t_recv_wall_ms":1770839723696,"t_recv_wall_iso":"2026-02-11T19:55:23.696Z","t_recv_mono_ns":618589036885166,"raw":{"market":"0x8032d8355d335c6ccbfc2508d99fbc87eb13f437bd275c93ee56fd1558e517ff","price_changes":[{"asset_id":"40652734036737240317526188612064032143639112324786051284480877037991580442979","price":"0.97","size":"34.68","side":"SELL","hash":"a4aa9ddf10c6fc9eccfb44cf93490cfc60a35d7b","best_bid":"0.96","best_ask":"0.97"},{"asset_id":"20773614133833886322101538939702011175545796528197617633926164254913649353392","price":"0.03","size":"34.68","side":"BUY","hash":"7453fbb773b3d54ec3e27d300acbbb649365a97c","best_bid":"0.03","best_ask":"0.04"}],"timestamp":"1770839723770","event_type":"price_change","_sub_state":"active","_subscription_id":1,"_active_subscription_id":1},"parse_warnings":[],"out_of_order":false}
{"run_id":"29526913bab7446286864a321c124486","channel":"market","event_type":"price_change","market":"0x8032d8355d335c6ccbfc2508d99fbc87eb13f437bd275c93ee56fd1558e517ff","asset_id":null,"source":"market_ws:sub:active:1","t_event_ms":1770839723770,"t_recv_wall_ms":1770839723696,"t_recv_wall_iso":"2026-02-11T19:55:23.696Z","t_recv_mono_ns":618589037274083,"raw":{"market":"0x8032d8355d335c6ccbfc2508d99fbc87eb13f437bd275c93ee56fd1558e517ff","price_changes":[{"asset_id":"20773614133833886322101538939702011175545796528197617633926164254913649353392","price":"0.03","size":"34.68","side":"BUY","hash":"7453fbb773b3d54ec3e27d300acbbb649365a97c","best_bid":"0.03","best_ask":"0.04"},{"asset_id":"40652734036737240317526188612064032143639112324786051284480877037991580442979","price":"0.97","size":"34.68","side":"SELL","hash":"a4aa9ddf10c6fc9eccfb44cf93490cfc60a35d7b","best_bid":"0.96","best_ask":"0.97"}],"timestamp":"1770839723770","event_type":"price_change","_sub_state":"active","_subscription_id":1,"_active_subscription_id":1},"parse_warnings":[],"out_of_order":false}
{"run_id":"29526913bab7446286864a321c124486","channel":"market","event_type":"book","market":"0x8032d8355d335c6ccbfc2508d99fbc87eb13f437bd275c93ee56fd1558e517ff","asset_id":"20773614133833886322101538939702011175545796528197617633926164254913649353392","source":"market_ws:sub:active:1","t_event_ms":1770839723770,"t_recv_wall_ms":1770839723696,"t_recv_wall_iso":"2026-02-11T19:55:23.696Z","t_recv_mono_ns":618589037423041,"raw":{"market":"0x8032d8355d335c6ccbfc2508d99fbc87eb13f437bd275c93ee56fd1558e517ff","asset_id":"20773614133833886322101538939702011175545796528197617633926164254913649353392","bids":[{"price":"0.01","size":"30854.91"},{"price":"0.02","size":"8824.25"},{"price":"0.03","size":"34.68"}],"asks":[{"price":"0.99","size":"30822.26"},{"price":"0.98","size":"12559.04"},{"price":"0.97","size":"7433.03"},{"price":"0.96","size":"5453.8"},{"price":"0.95","size":"6815.8"},{"price":"0.94","size":"5105"},{"price":"0.93","size":"5421.38"},{"price":"0.92","size":"5139.4"},{"price":"0.91","size":"5225.8"},{"price":"0.9","size":"5102.8"},{"price":"0.89","size":"120.6"},{"price":"0.88","size":"63.6"},{"price":"0.87","size":"63"},{"price":"0.86","size":"61.6"},{"price":"0.85","size":"107.39"},{"price":"0.84","size":"69.39"},{"price":"0.83","size":"58.39"},{"price":"0.82","size":"66.71"},{"price":"0.81","size":"56.8"},{"price":"0.8","size":"92.14"},{"price":"0.79","size":"60.8"},{"price":"0.78","size":"55.2"},{"price":"0.77","size":"64.48"},{"price":"0.76","size":"54.2"},{"price":"0.75","size":"375.8"},{"price":"0.74","size":"68.6"},{"price":"0.73","size":"53.2"},{"price":"0.72","size":"63.26"},{"price":"0.71","size":"52.6"},{"price":"0.7","size":"402.4"},{"price":"0.69","size":"72.2"},{"price":"0.68","size":"87.88"},{"price":"0.67","size":"188.46"},{"price":"0.66","size":"123.6"},{"price":"0.65","size":"317.03"},{"price":"0.64","size":"582.36"},{"price":"0.63","size":"559.2"},{"price":"0.62","size":"559"},{"price":"0.61","size":"594"},{"price":"0.6","size":"2915.41"},{"price":"0.59","size":"576.8"},{"price":"0.58","size":"575.5"},{"price":"0.57","size":"558.6"},{"price":"0.56","size":"572.68"},{"price":"0.55","size":"566.4"},{"price":"0.54","size":"561.94"},{"price":"0.53","size":"631.57"},{"price":"0.52","size":"611.4"},{"price":"0.51","size":"705.2"},{"price":"0.5","size":"1011.55"},{"price":"0.49","size":"692.4"},{"price":"0.48","size":"628.4"},{"price":"0.47","size":"633.4"},{"price":"0.46","size":"711.65"},{"price":"0.45","size":"866.59"},{"price":"0.44","size":"905.69"},{"price":"0.43","size":"641.6"},{"price":"0.42","size":"645.58"},{"price":"0.41","size":"564"},{"price":"0.4","size":"20642.9"},{"price":"0.39","size":"650.23"},{"price":"0.38","size":"593"},{"price":"0.37","size":"755.73"},{"price":"0.36","size":"558"},{"price":"0.35","size":"1144.32"},{"price":"0.34","size":"649.59"},{"price":"0.33","size":"624.8"},{"price":"0.32","size":"574"},{"price":"0.31","size":"594.2"},{"price":"0.3","size":"735.66"},{"price":"0.29","size":"924.6"},{"price":"0.28","size":"356.8"},{"price":"0.27","size":"869.2"},{"price":"0.26","size":"967.6"},{"price":"0.25","size":"1673.8"},{"price":"0.24","size":"869.2"},{"price":"0.23","size":"864.6"},{"price":"0.22","size":"870.2"},{"price":"0.21","size":"871.6"},{"price":"0.2","size":"987.2"},{"price":"0.19","size":"876.8"},{"price":"0.18","size":"1091.55"},{"price":"0.17","size":"958.39"},{"price":"0.16","size":"1119.39"},{"price":"0.15","size":"1149.13"},{"price":"0.14","size":"962.6"},{"price":"0.13","size":"1041.8"},{"price":"0.12","size":"1060.55"},{"price":"0.11","size":"1124.49"},{"price":"0.1","size":"1191.79"},{"price":"0.09","size":"589.6"},{"price":"0.08","size":"3424.35"},{"price":"0.07","size":"3340.43"},{"price":"0.06","size":"3215.34"},{"price":"0.05","size":"3289.45"},{"price":"0.04","size":"3854.17"}],"hash":"7453fbb773b3d54ec3e27d300acbbb649365a97c","timestamp":"1770839723770","event_type":"book","_sub_state":"active","_subscription_id":1,"_active_subscription_id":1},"parse_warnings":[],"out_of_order":false}
{"run_id":"29526913bab7446286864a321c124486","channel":"market","event_type":"book","market":"0x8032d8355d335c6ccbfc2508d99fbc87eb13f437bd275c93ee56fd1558e517ff","asset_id":"40652734036737240317526188612064032143639112324786051284480877037991580442979","source":"market_ws:sub:active:1","t_event_ms":1770839723770,"t_recv_wall_ms":1770839723697,"t_recv_wall_iso":"2026-02-11T19:55:23.697Z","t_recv_mono_ns":618589037817375,"raw":{"market":"0x8032d8355d335c6ccbfc2508d99fbc87eb13f437bd275c93ee56fd1558e517ff","asset_id":"40652734036737240317526188612064032143639112324786051284480877037991580442979","bids":[{"price":"0.01","size":"30822.26"},{"price":"0.02","size":"12559.04"},{"price":"0.03","size":"7433.03"},{"price":"0.04","size":"5453.8"},{"price":"0.05","size":"6815.8"},{"price":"0.06","size":"5105"},{"price":"0.07","size":"5421.38"},{"price":"0.08","size":"5139.4"},{"price":"0.09","size":"5225.8"},{"price":"0.1","size":"5102.8"},{"price":"0.11","size":"120.6"},{"price":"0.12","size":"63.6"},{"price":"0.13","size":"63"},{"price":"0.14","size":"61.6"},{"price":"0.15","size":"107.39"},{"price":"0.16","size":"69.39"},{"price":"0.17","size":"58.39"},{"price":"0.18","size":"66.71"},{"price":"0.19","size":"56.8"},{"price":"0.2","size":"92.14"},{"price":"0.21","size":"60.8"},{"price":"0.22","size":"55.2"},{"price":"0.23","size":"64.48"},{"price":"0.24","size":"54.2"},{"price":"0.25","size":"375.8"},{"price":"0.26","size":"68.6"},{"price":"0.27","size":"53.2"},{"price":"0.28","size":"63.26"},{"price":"0.29","size":"52.6"},{"price":"0.3","size":"402.4"},{"price":"0.31","size":"72.2"},{"price":"0.32","size":"87.88"},{"price":"0.33","size":"188.46"},{"price":"0.34","size":"123.6"},{"price":"0.35","size":"317.03"},{"price":"0.36","size":"582.36"},{"price":"0.37","size":"559.2"},{"price":"0.38","size":"559"},{"price":"0.39","size":"594"},{"price":"0.4","size":"2915.41"},{"price":"0.41","size":"576.8"},{"price":"0.42","size":"575.5"},{"price":"0.43","size":"558.6"},{"price":"0.44","size":"572.68"},{"price":"0.45","size":"566.4"},{"price":"0.46","size":"561.94"},{"price":"0.47","size":"631.57"},{"price":"0.48","size":"611.4"},{"price":"0.49","size":"705.2"},{"price":"0.5","size":"1011.55"},{"price":"0.51","size":"692.4"},{"price":"0.52","size":"628.4"},{"price":"0.53","size":"633.4"},{"price":"0.54","size":"711.65"},{"price":"0.55","size":"866.59"},{"price":"0.56","size":"905.69"},{"price":"0.57","size":"641.6"},{"price":"0.58","size":"645.58"},{"price":"0.59","size":"564"},{"price":"0.6","size":"20642.9"},{"price":"0.61","size":"650.23"},{"price":"0.62","size":"593"},{"price":"0.63","size":"755.73"},{"price":"0.64","size":"558"},{"price":"0.65","size":"1144.32"},{"price":"0.66","size":"649.59"},{"price":"0.67","size":"624.8"},{"price":"0.68","size":"574"},{"price":"0.69","size":"594.2"},{"price":"0.7","size":"735.66"},{"price":"0.71","size":"924.6"},{"price":"0.72","size":"356.8"},{"price":"0.73","size":"869.2"},{"price":"0.74","size":"967.6"},{"price":"0.75","size":"1673.8"},{"price":"0.76","size":"869.2"},{"price":"0.77","size":"864.6"},{"price":"0.78","size":"870.2"},{"price":"0.79","size":"871.6"},{"price":"0.8","size":"987.2"},{"price":"0.81","size":"876.8"},{"price":"0.82","size":"1091.55"},{"price":"0.83","size":"958.39"},{"price":"0.84","size":"1119.39"},{"price":"0.85","size":"1149.13"},{"price":"0.86","size":"962.6"},{"price":"0.87","size":"1041.8"},{"price":"0.88","size":"1060.55"},{"price":"0.89","size":"1124.49"},{"price":"0.9","size":"1191.79"},{"price":"0.91","size":"589.6"},{"price":"0.92","size":"3424.35"},{"price":"0.93","size":"3340.43"},{"price":"0.94","size":"3215.34"},{"price":"0.95","size":"3289.45"},{"price":"0.96","size":"3854.17"}],"asks":[{"price":"0.99","size":"30854.91"},{"price":"0.98","size":"8824.25"},{"price":"0.97","size":"34.68"}],"hash":"a4aa9ddf10c6fc9eccfb44cf93490cfc60a35d7b","timestamp":"1770839723770","event_type":"book","_sub_state":"active","_subscription_id":1,"_active_subscription_id":1},"parse_warnings":[],"out_of_order":false}
{"run_id":"29526913bab7446286864a321c124486","channel":"market","event_type":"price_change","market":"0x8032d8355d335c6ccbfc2508d99fbc87eb13f437bd275c93ee56fd1558e517ff","asset_id":null,"source":"market_ws:sub:active:1","t_event_ms":1770839723772,"t_recv_wall_ms":1770839723697,"t_recv_wall_iso":"2026-02-11T19:55:23.697Z","t_recv_mono_ns":618589038129583,"raw":{"market":"0x8032d8355d335c6ccbfc2508d99fbc87eb13f437bd275c93ee56fd1558e517ff","price_changes":[{"asset_id":"40652734036737240317526188612064032143639112324786051284480877037991580442979","price":"0.83","size":"963.39","side":"BUY","hash":"f2051e8608df991161a5a126a8fc0e9de581d5da","best_bid":"0.96","best_ask":"0.97"},{"asset_id":"20773614133833886322101538939702011175545796528197617633926164254913649353392","price":"0.17","size":"963.39","side":"SELL","hash":"0739ccef952481cc7796692adfd0f020c2fab9c7","best_bid":"0.03","best_ask":"0.04"}],"timestamp":"1770839723772","event_type":"price_change","_sub_state":"active","_subscription_id":1,"_active_subscription_id":1},"parse_warnings":[],"out_of_order":false}
{"run_id":"29526913bab7446286864a321c124486","channel":"market","event_type":"last_trade_price","market":"0x8032d8355d335c6ccbfc2508d99fbc87eb13f437bd275c93ee56fd1558e517ff","asset_id":"20773614133833886322101538939702011175545796528197617633926164254913649353392","source":"market_ws:sub:unknown","t_event_ms":1770839723780,"t_recv_wall_ms":1770839723709,"t_recv_wall_iso":"2026-02-11T19:55:23.709Z","t_recv_mono_ns":618589050301708,"raw":{"market":"0x8032d8355d335c6ccbfc2508d99fbc87eb13f437bd275c93ee56fd1558e517ff","asset_id":"20773614133833886322101538939702011175545796528197617633926164254913649353392","price":"0.03","size":"6","fee_rate_bps":"1000","side":"SELL","timestamp":"1770839723780","event_type":"last_trade_price","transaction_hash":"0x3e87025bfb9a0506a8b4a90c47bb9ad22753683c2a424a537276c02a218cccb9","_sub_state":"unknown","_subscription_id":null,"_active_subscription_id":1},"parse_warnings":["unknown_message_schema"],"out_of_order":false}
{"run_id":"29526913bab7446286864a321c124486","channel":"market","event_type":"price_change","market":"0x8032d8355d335c6ccbfc2508d99fbc87eb13f437bd275c93ee56fd1558e517ff","asset_id":null,"source":"market_ws:sub:active:1","t_event_ms":1770839723800,"t_recv_wall_ms":1770839723709,"t_recv_wall_iso":"2026-02-11T19:55:23.709Z","t_recv_mono_ns":618589050492041,"raw":{"market":"0x8032d8355d335c6ccbfc2508d99fbc87eb13f437bd275c93ee56fd1558e517ff","price_changes":[{"asset_id":"40652734036737240317526188612064032143639112324786051284480877037991580442979","price":"0.96","size":"3824.17","side":"BUY","hash":"d8b2e5a8f8ed769d11a26fc04e29ece9ab950bb6","best_bid":"0.96","best_ask":"0.97"},{"asset_id":"20773614133833886322101538939702011175545796528197617633926164254913649353392","price":"0.04","size":"3824.17","side":"SELL","hash":"be74a8d78d5d461bb98bcadae7087be5f75b3a00","best_bid":"0.03","best_ask":"0.04"}],"timestamp":"1770839723800","event_type":"price_change","_sub_state":"active","_subscription_id":1,"_active_subscription_id":1},"parse_warnings":[],"out_of_order":false}
{"run_id":"29526913bab7446286864a321c124486","channel":"market","event_type":"price_change","market":"0x8032d8355d335c6ccbfc2508d99fbc87eb13f437bd275c93ee56fd1558e517ff","asset_id":null,"source":"market_ws:sub:active:1","t_event_ms":1770839723801,"t_recv_wall_ms":1770839723709,"t_recv_wall_iso":"2026-02-11T19:55:23.709Z","t_recv_mono_ns":618589050629208,"raw":{"market":"0x8032d8355d335c6ccbfc2508d99fbc87eb13f437bd275c93ee56fd1558e517ff","price_changes":[{"asset_id":"20773614133833886322101538939702011175545796528197617633926164254913649353392","price":"0.01","size":"30824.91","side":"BUY","hash":"40bbc3ee0bfa7b5bb641e396206882f66b1ff0a9","best_bid":"0.03","best_ask":"0.04"},{"asset_id":"40652734036737240317526188612064032143639112324786051284480877037991580442979","price":"0.99","size":"30824.91","side":"SELL","hash":"18e40b3ac5547619bcd6660d8f063a18860ece7d","best_bid":"0.96","best_ask":"0.97"}],"timestamp":"1770839723801","event_type":"price_change","_sub_state":"active","_subscription_id":1,"_active_subscription_id":1},"parse_warnings":[],"out_of_order":false}
{"run_id":"29526913bab7446286864a321c124486","channel":"market","event_type":"price_change","market":"0x8032d8355d335c6ccbfc2508d99fbc87eb13f437bd275c93ee56fd1558e517ff","asset_id":null,"source":"market_ws:sub:active:1","t_event_ms":1770839723803,"t_recv_wall_ms":1770839723709,"t_recv_wall_iso":"2026-02-11T19:55:23.709Z","t_recv_mono_ns":618589050724875,"raw":{"market":"0x8032d8355d335c6ccbfc2508d99fbc87eb13f437bd275c93ee56fd1558e517ff","price_changes":[{"asset_id":"20773614133833886322101538939702011175545796528197617633926164254913649353392","price":"0.02","size":"8854.25","side":"BUY","hash":"34414e4d9d140a0036ed1cbcd45af4cd34904775","best_bid":"0.03","best_ask":"0.04"},{"asset_id":"40652734036737240317526188612064032143639112324786051284480877037991580442979","price":"0.98","size":"8854.25","side":"SELL","hash":"bab267ec62ebb8308f3fb88ccd367e08afa001ec","best_bid":"0.96","best_ask":"0.97"}],"timestamp":"1770839723803","event_type":"price_change","_sub_state":"active","_subscription_id":1,"_active_subscription_id":1},"parse_warnings":[],"out_of_order":false}
{"run_id":"29526913bab7446286864a321c124486","channel":"market","event_type":"last_trade_price","market":"0x8032d8355d335c6ccbfc2508d99fbc87eb13f437bd275c93ee56fd1558e517ff","asset_id":"40652734036737240317526188612064032143639112324786051284480877037991580442979","source":"market_ws:sub:unknown","t_event_ms":1770839723802,"t_recv_wall_ms":1770839723710,"t_recv_wall_iso":"2026-02-11T19:55:23.710Z","t_recv_mono_ns":618589050811458,"raw":{"market":"0x8032d8355d335c6ccbfc2508d99fbc87eb13f437bd275c93ee56fd1558e517ff","asset_id":"40652734036737240317526188612064032143639112324786051284480877037991580442979","price":"0.97","size":"8","fee_rate_bps":"1000","side":"BUY","timestamp":"1770839723802","event_type":"last_trade_price","transaction_hash":"0xb177ebda6cc6fd88f38ec9bdf6fe4d5f0585db8be6c9d1d1ec628a0d77553a88","_sub_state":"unknown","_subscription_id":null,"_active_subscription_id":1},"parse_warnings":["unknown_message_schema"],"out_of_order":false}
{"run_id":"29526913bab7446286864a321c124486","channel":"market","event_type":"price_change","market":"0x8032d8355d335c6ccbfc2508d99fbc87eb13f437bd275c93ee56fd1558e517ff","asset_id":null,"source":"market_ws:sub:active:1","t_event_ms":1770839723809,"t_recv_wall_ms":1770839723727,"t_recv_wall_iso":"2026-02-11T19:55:23.727Z","t_recv_mono_ns":618589068643208,"raw":{"market":"0x8032d8355d335c6ccbfc2508d99fbc87eb13f437bd275c93ee56fd1558e517ff","price_changes":[{"asset_id":"40652734036737240317526188612064032143639112324786051284480877037991580442979","price":"0.94","size":"3220.34","side":"BUY","hash":"507f3d7605a06c6c45c0ee6714b77f7da3312589","best_bid":"0.96","best_ask":"0.97"},{"asset_id":"20773614133833886322101538939702011175545796528197617633926164254913649353392","price":"0.06","size":"3220.34","side":"SELL","hash":"0e085abad28b67e4034b1c083c7675900d47ab1a","best_bid":"0.03","best_ask":"0.04"}],"timestamp":"1770839723809","event_type":"price_change","_sub_state":"active","_subscription_id":1,"_active_subscription_id":1},"parse_warnings":[],"out_of_order":false}
{"run_id":"29526913bab7446286864a321c124486","channel":"market","event_type":"price_change","market":"0x8032d8355d335c6ccbfc2508d99fbc87eb13f437bd275c93ee56fd1558e517ff","asset_id":null,"source":"market_ws:sub:active:1","t_event_ms":1770839723812,"t_recv_wall_ms":1770839723728,"t_recv_wall_iso":"2026-02-11T19:55:23.728Z","t_recv_mono_ns":618589069118875,"raw":{"market":"0x8032d8355d335c6ccbfc2508d99fbc87eb13f437bd275c93ee56fd1558e517ff","price_changes":[{"asset_id":"40652734036737240317526188612064032143639112324786051284480877037991580442979","price":"0.92","size":"3404.35","side":"BUY","hash":"857d0b47bba3e6e41575a22a7eecf89c8936560c","best_bid":"0.96","best_ask":"0.97"},{"asset_id":"20773614133833886322101538939702011175545796528197617633926164254913649353392","price":"0.08","size":"3404.35","side":"SELL","hash":"24b25b2441cab520a57a2933a3bfbdde5b2b2d59","best_bid":"0.03","best_ask":"0.04"}],"timestamp":"1770839723812","event_type":"price_change","_sub_state":"active","_subscription_id":1,"_active_subscription_id":1},"parse_warnings":[],"out_of_order":false}
{"run_id":"29526913bab7446286864a321c124486","channel":"market","event_type":"price_change","market":"0x8032d8355d335c6ccbfc2508d99fbc87eb13f437bd275c93ee56fd1558e517ff","asset_id":null,"source":"market_ws:sub:active:1","t_event_ms":1770839723828,"t_recv_wall_ms":1770839723738,"t_recv_wall_iso":"2026-02-11T19:55:23.738Z","t_recv_mono_ns":618589078961041,"raw":{"market":"0x8032d8355d335c6ccbfc2508d99fbc87eb13f437bd275c93ee56fd1558e517ff","price_changes":[{"asset_id":"40652734036737240317526188612064032143639112324786051284480877037991580442979","price":"0.97","size":"465.32","side":"BUY","hash":"b5a2448c005ecabb294a5a63aa919396c887ef17","best_bid":"0.97","best_ask":"0.98"},{"asset_id":"20773614133833886322101538939702011175545796528197617633926164254913649353392","price":"0.03","size":"465.32","side":"SELL","hash":"41928e3bdcc54a6881edea9a80311223d8c15ddf","best_bid":"0.02","best_ask":"0.03"}],"timestamp":"1770839723828","event_type":"price_change","_sub_state":"active","_subscription_id":1,"_active_subscription_id":1},"parse_warnings":[],"out_of_order":false}
{"run_id":"29526913bab7446286864a321c124486","channel":"market","event_type":"price_change","market":"0x8032d8355d335c6ccbfc2508d99fbc87eb13f437bd275c93ee56fd1558e517ff","asset_id":null,"source":"market_ws:sub:active:1","t_event_ms":1770839723828,"t_recv_wall_ms":1770839723738,"t_recv_wall_iso":"2026-02-11T19:55:23.738Z","t_recv_mono_ns":618589079222833,"raw":{"market":"0x8032d8355d335c6ccbfc2508d99fbc87eb13f437bd275c93ee56fd1558e517ff","price_changes":[{"asset_id":"20773614133833886322101538939702011175545796528197617633926164254913649353392","price":"0.03","size":"0","side":"BUY","hash":"41928e3bdcc54a6881edea9a80311223d8c15ddf","best_bid":"0.02","best_ask":"0.03"},{"asset_id":"40652734036737240317526188612064032143639112324786051284480877037991580442979","price":"0.97","size":"0","side":"SELL","hash":"b5a2448c005ecabb294a5a63aa919396c887ef17","best_bid":"0.97","best_ask":"0.98"}],"timestamp":"1770839723828","event_type":"price_change","_sub_state":"active","_subscription_id":1,"_active_subscription_id":1},"parse_warnings":[],"out_of_order":false}
{"run_id":"29526913bab7446286864a321c124486","channel":"market","event_type":"book","market":"0x8032d8355d335c6ccbfc2508d99fbc87eb13f437bd275c93ee56fd1558e517ff","asset_id":"20773614133833886322101538939702011175545796528197617633926164254913649353392","source":"market_ws:sub:active:1","t_event_ms":1770839723828,"t_recv_wall_ms":1770839723738,"t_recv_wall_iso":"2026-02-11T19:55:23.738Z","t_recv_mono_ns":618589079328875,"raw":{"market":"0x8032d8355d335c6ccbfc2508d99fbc87eb13f437bd275c93ee56fd1558e517ff","asset_id":"20773614133833886322101538939702011175545796528197617633926164254913649353392","bids":[{"price":"0.01","size":"30824.91"},{"price":"0.02","size":"8854.25"}],"asks":[{"price":"0.99","size":"30822.26"},{"price":"0.98","size":"12559.04"},{"price":"0.97","size":"7433.03"},{"price":"0.96","size":"5453.8"},{"price":"0.95","size":"6815.8"},{"price":"0.94","size":"5105"},{"price":"0.93","size":"5421.38"},{"price":"0.92","size":"5139.4"},{"price":"0.91","size":"5225.8"},{"price":"0.9","size":"5102.8"},{"price":"0.89","size":"120.6"},{"price":"0.88","size":"63.6"},{"price":"0.87","size":"63"},{"price":"0.86","size":"61.6"},{"price":"0.85","size":"107.39"},{"price":"0.84","size":"69.39"},{"price":"0.83","size":"58.39"},{"price":"0.82","size":"66.71"},{"price":"0.81","size":"56.8"},{"price":"0.8","size":"92.14"},{"price":"0.79","size":"60.8"},{"price":"0.78","size":"55.2"},{"price":"0.77","size":"64.48"},{"price":"0.76","size":"54.2"},{"price":"0.75","size":"375.8"},{"price":"0.74","size":"68.6"},{"price":"0.73","size":"53.2"},{"price":"0.72","size":"63.26"},{"price":"0.71","size":"52.6"},{"price":"0.7","size":"402.4"},{"price":"0.69","size":"72.2"},{"price":"0.68","size":"87.88"},{"price":"0.67","size":"188.46"},{"price":"0.66","size":"123.6"},{"price":"0.65","size":"317.03"},{"price":"0.64","size":"582.36"},{"price":"0.63","size":"559.2"},{"price":"0.62","size":"559"},{"price":"0.61","size":"594"},{"price":"0.6","size":"2915.41"},{"price":"0.59","size":"576.8"},{"price":"0.58","size":"575.5"},{"price":"0.57","size":"558.6"},{"price":"0.56","size":"572.68"},{"price":"0.55","size":"566.4"},{"price":"0.54","size":"561.94"},{"price":"0.53","size":"631.57"},{"price":"0.52","size":"611.4"},{"price":"0.51","size":"705.2"},{"price":"0.5","size":"1011.55"},{"price":"0.49","size":"692.4"},{"price":"0.48","size":"628.4"},{"price":"0.47","size":"633.4"},{"price":"0.46","size":"711.65"},{"price":"0.45","size":"866.59"},{"price":"0.44","size":"905.69"},{"price":"0.43","size":"641.6"},{"price":"0.42","size":"645.58"},{"price":"0.41","size":"564"},{"price":"0.4","size":"20642.9"},{"price":"0.39","size":"650.23"},{"price":"0.38","size":"593"},{"price":"0.37","size":"755.73"},{"price":"0.36","size":"558"},{"price":"0.35","size":"1144.32"},{"price":"0.34","size":"649.59"},{"price":"0.33","size":"624.8"},{"price":"0.32","size":"574"},{"price":"0.31","size":"594.2"},{"price":"0.3","size":"735.66"},{"price":"0.29","size":"924.6"},{"price":"0.28","size":"356.8"},{"price":"0.27","size":"869.2"},{"price":"0.26","size":"967.6"},{"price":"0.25","size":"1673.8"},{"price":"0.24","size":"869.2"},{"price":"0.23","size":"864.6"},{"price":"0.22","size":"870.2"},{"price":"0.21","size":"871.6"},{"price":"0.2","size":"987.2"},{"price":"0.19","size":"876.8"},{"price":"0.18","size":"1091.55"},{"price":"0.17","size":"963.39"},{"price":"0.16","size":"1119.39"},{"price":"0.15","size":"1149.13"},{"price":"0.14","size":"962.6"},{"price":"0.13","size":"1041.8"},{"price":"0.12","size":"1060.55"},{"price":"0.11","size":"1124.49"},{"price":"0.1","size":"1191.79"},{"price":"0.09","size":"589.6"},{"price":"0.08","size":"3404.35"},{"price":"0.07","size":"3340.43"},{"price":"0.06","size":"3220.34"},{"price":"0.05","size":"3289.45"},{"price":"0.04","size":"3824.17"},{"price":"0.03","size":"465.32"}],"hash":"41928e3bdcc54a6881edea9a80311223d8c15ddf","timestamp":"1770839723828","event_type":"book","_sub_state":"active","_subscription_id":1,"_active_subscription_id":1},"parse_warnings":[],"out_of_order":false}
{"run_id":"29526913bab7446286864a321c124486","channel":"market","event_type":"book","market":"0x8032d8355d335c6ccbfc2508d99fbc87eb13f437bd275c93ee56fd1558e517ff","asset_id":"40652734036737240317526188612064032143639112324786051284480877037991580442979","source":"market_ws:sub:active:1","t_event_ms":1770839723828,"t_recv_wall_ms":1770839723738,"t_recv_wall_iso":"2026-02-11T19:55:23.738Z","t_recv_mono_ns":618589079737166,"raw":{"market":"0x8032d8355d335c6ccbfc2508d99fbc87eb13f437bd275c93ee56fd1558e517ff","asset_id":"40652734036737240317526188612064032143639112324786051284480877037991580442979","bids":[{"price":"0.01","size":"30822.26"},{"price":"0.02","size":"12559.04"},{"price":"0.03","size":"7433.03"},{"price":"0.04","size":"5453.8"},{"price":"0.05","size":"6815.8"},{"price":"0.06","size":"5105"},{"price":"0.07","size":"5421.38"},{"price":"0.08","size":"5139.4"},{"price":"0.09","size":"5225.8"},{"price":"0.1","size":"5102.8"},{"price":"0.11","size":"120.6"},{"price":"0.12","size":"63.6"},{"price":"0.13","size":"63"},{"price":"0.14","size":"61.6"},{"price":"0.15","size":"107.39"},{"price":"0.16","size":"69.39"},{"price":"0.17","size":"58.39"},{"price":"0.18","size":"66.71"},{"price":"0.19","size":"56.8"},{"price":"0.2","size":"92.14"},{"price":"0.21","size":"60.8"},{"price":"0.22","size":"55.2"},{"price":"0.23","size":"64.48"},{"price":"0.24","size":"54.2"},{"price":"0.25","size":"375.8"},{"price":"0.26","size":"68.6"},{"price":"0.27","size":"53.2"},{"price":"0.28","size":"63.26"},{"price":"0.29","size":"52.6"},{"price":"0.3","size":"402.4"},{"price":"0.31","size":"72.2"},{"price":"0.32","size":"87.88"},{"price":"0.33","size":"188.46"},{"price":"0.34","size":"123.6"},{"price":"0.35","size":"317.03"},{"price":"0.36","size":"582.36"},{"price":"0.37","size":"559.2"},{"price":"0.38","size":"559"},{"price":"0.39","size":"594"},{"price":"0.4","size":"2915.41"},{"price":"0.41","size":"576.8"},{"price":"0.42","size":"575.5"},{"price":"0.43","size":"558.6"},{"price":"0.44","size":"572.68"},{"price":"0.45","size":"566.4"},{"price":"0.46","size":"561.94"},{"price":"0.47","size":"631.57"},{"price":"0.48","size":"611.4"},{"price":"0.49","size":"705.2"},{"price":"0.5","size":"1011.55"},{"price":"0.51","size":"692.4"},{"price":"0.52","size":"628.4"},{"price":"0.53","size":"633.4"},{"price":"0.54","size":"711.65"},{"price":"0.55","size":"866.59"},{"price":"0.56","size":"905.69"},{"price":"0.57","size":"641.6"},{"price":"0.58","size":"645.58"},{"price":"0.59","size":"564"},{"price":"0.6","size":"20642.9"},{"price":"0.61","size":"650.23"},{"price":"0.62","size":"593"},{"price":"0.63","size":"755.73"},{"price":"0.64","size":"558"},{"price":"0.65","size":"1144.32"},{"price":"0.66","size":"649.59"},{"price":"0.67","size":"624.8"},{"price":"0.68","size":"574"},{"price":"0.69","size":"594.2"},{"price":"0.7","size":"735.66"},{"price":"0.71","size":"924.6"},{"price":"0.72","size":"356.8"},{"price":"0.73","size":"869.2"},{"price":"0.74","size":"967.6"},{"price":"0.75","size":"1673.8"},{"price":"0.76","size":"869.2"},{"price":"0.77","size":"864.6"},{"price":"0.78","size":"870.2"},{"price":"0.79","size":"871.6"},{"price":"0.8","size":"987.2"},{"price":"0.81","size":"876.8"},{"price":"0.82","size":"1091.55"},{"price":"0.83","size":"963.39"},{"price":"0.84","size":"1119.39"},{"price":"0.85","size":"1149.13"},{"price":"0.86","size":"962.6"},{"price":"0.87","size":"1041.8"},{"price":"0.88","size":"1060.55"},{"price":"0.89","size":"1124.49"},{"price":"0.9","size":"1191.79"},{"price":"0.91","size":"589.6"},{"price":"0.92","size":"3404.35"},{"price":"0.93","size":"3340.43"},{"price":"0.94","size":"3220.34"},{"price":"0.95","size":"3289.45"},{"price":"0.96","size":"3824.17"},{"price":"0.97","size":"465.32"}],"asks":[{"price":"0.99","size":"30824.91"},{"price":"0.98","size":"8854.25"}],"hash":"b5a2448c005ecabb294a5a63aa919396c887ef17","timestamp":"1770839723828","event_type":"book","_sub_state":"active","_subscription_id":1,"_active_subscription_id":1},"parse_warnings":[],"out_of_order":false}
{"run_id":"29526913bab7446286864a321c124486","channel":"market","event_type":"price_change","market":"0x8032d8355d335c6ccbfc2508d99fbc87eb13f437bd275c93ee56fd1558e517ff","asset_id":null,"source":"market_ws:sub:active:1","t_event_ms":1770839723837,"t_recv_wall_ms":1770839723741,"t_recv_wall_iso":"2026-02-11T19:55:23.741Z","t_recv_mono_ns":618589082728375,"raw":{"market":"0x8032d8355d335c6ccbfc2508d99fbc87eb13f437bd275c93ee56fd1558e517ff","price_changes":[{"asset_id":"20773614133833886322101538939702011175545796528197617633926164254913649353392","price":"0.02","size":"8884.25","side":"BUY","hash":"c5a88304c8e5b61609f8b3294fdb449c147c6429","best_bid":"0.02","best_ask":"0.03"},{"asset_id":"40652734036737240317526188612064032143639112324786051284480877037991580442979","price":"0.98","size":"8884.25","side":"SELL","hash":"58c9f8a86bc5067589a248cae822349db4922b1b","best_bid":"0.97","best_ask":"0.98"}],"timestamp":"1770839723837","event_type":"price_change","_sub_state":"active","_subscription_id":1,"_active_subscription_id":1},"parse_warnings":[],"out_of_order":false}
{"run_id":"29526913bab7446286864a321c124486","channel":"market","event_type":"price_change","market":"0x8032d8355d335c6ccbfc2508d99fbc87eb13f437bd275c93ee56fd1558e517ff","asset_id":null,"source":"market_ws:sub:active:1","t_event_ms":1770839723838,"t_recv_wall_ms":1770839723743,"t_recv_wall_iso":"2026-02-11T19:55:23.743Z","t_recv_mono_ns":618589084069208,"raw":{"market":"0x8032d8355d335c6ccbfc2508d99fbc87eb13f437bd275c93ee56fd1558e517ff","price_changes":[{"asset_id":"40652734036737240317526188612064032143639112324786051284480877037991580442979","price":"0.95","size":"3319.45","side":"BUY","hash":"7613dbcf6627d6387604fab30a71251777b5432e","best_bid":"0.97","best_ask":"0.98"},{"asset_id":"20773614133833886322101538939702011175545796528197617633926164254913649353392","price":"0.05","size":"3319.45","side":"SELL","hash":"5f0118269420d248d6d261c54cd085a54b041a58","best_bid":"0.02","best_ask":"0.03"}],"timestamp":"1770839723838","event_type":"price_change","_sub_state":"active","_subscription_id":1,"_active_subscription_id":1},"parse_warnings":[],"out_of_order":false}
{"run_id":"29526913bab7446286864a321c124486","channel":"market","event_type":"price_change","market":"0x8032d8355d335c6ccbfc2508d99fbc87eb13f437bd275c93ee56fd1558e517ff","asset_id":null,"source":"market_ws:sub:active:1","t_event_ms":1770839723851,"t_recv_wall_ms":1770839723758,"t_recv_wall_iso":"2026-02-11T19:55:23.758Z","t_recv_mono_ns":618589099210250,"raw":{"market":"0x8032d8355d335c6ccbfc2508d99fbc87eb13f437bd275c93ee56fd1558e517ff","price_changes":[{"asset_id":"40652734036737240317526188612064032143639112324786051284480877037991580442979","price":"0.92","size":"3424.35","side":"BUY","hash":"9b64fc46377617c4fe5f91fb01c95bfaeb6f8d1c","best_bid":"0.97","best_ask":"0.98"},{"asset_id":"20773614133833886322101538939702011175545796528197617633926164254913649353392","price":"0.08","size":"3424.35","side":"SELL","hash":"431a8dbdb29bea11653dde19f5ed12048e745da5","best_bid":"0.02","best_ask":"0.03"}],"timestamp":"1770839723851","event_type":"price_change","_sub_state":"active","_subscription_id":1,"_active_subscription_id":1},"parse_warnings":[],"out_of_order":false}
{"run_id":"29526913bab7446286864a321c124486","channel":"market","event_type":"price_change","market":"0x8032d8355d335c6ccbfc2508d99fbc87eb13f437bd275c93ee56fd1558e517ff","asset_id":null,"source":"market_ws:sub:active:1","t_event_ms":1770839723854,"t_recv_wall_ms":1770839723765,"t_recv_wall_iso":"2026-02-11T19:55:23.765Z","t_recv_mono_ns":618589106452416,"raw":{"market":"0x8032d8355d335c6ccbfc2508d99fbc87eb13f437bd275c93ee56fd1558e517ff","price_changes":[{"asset_id":"40652734036737240317526188612064032143639112324786051284480877037991580442979","price":"0.96","size":"3764.17","side":"BUY","hash":"b257b0d6eb4b5fc05b38fee95782b5eae0696518","best_bid":"0.97","best_ask":"0.98"},{"asset_id":"20773614133833886322101538939702011175545796528197617633926164254913649353392","price":"0.04","size":"3764.17","side":"SELL","hash":"33fd75a1acd7d429a0dd5869e5ccfb3c85500aaf","best_bid":"0.02","best_ask":"0.03"}],"timestamp":"1770839723854","event_type":"price_change","_sub_state":"active","_subscription_id":1,"_active_subscription_id":1},"parse_warnings":[],"out_of_order":false}
{"run_id":"29526913bab7446286864a321c124486","channel":"market","event_type":"price_change","market":"0x8032d8355d335c6ccbfc2508d99fbc87eb13f437bd275c93ee56fd1558e517ff","asset_id":null,"source":"market_ws:sub:active:1","t_event_ms":1770839723856,"t_recv_wall_ms":1770839723765,"t_recv_wall_iso":"2026-02-11T19:55:23.765Z","t_recv_mono_ns":618589106674583,"raw":{"market":"0x8032d8355d335c6ccbfc2508d99fbc87eb13f437bd275c93ee56fd1558e517ff","price_changes":[{"asset_id":"40652734036737240317526188612064032143639112324786051284480877037991580442979","price":"0.95","size":"3253.45","side":"BUY","hash":"13c6c11e780c663f9c6b061a41c3ea57ca1643da","best_bid":"0.97","best_ask":"0.98"},{"asset_id":"20773614133833886322101538939702011175545796528197617633926164254913649353392","price":"0.05","size":"3253.45","side":"SELL","hash":"3d9966d51eb8c1fae0699593813d6d1fa85e35d7","best_bid":"0.02","best_ask":"0.03"}],"timestamp":"1770839723856","event_type":"price_change","_sub_state":"active","_subscription_id":1,"_active_subscription_id":1},"parse_warnings":[],"out_of_order":false}
{"run_id":"29526913bab7446286864a321c124486","channel":"market","event_type":"last_trade_price","market":"0x8032d8355d335c6ccbfc2508d99fbc87eb13f437bd275c93ee56fd1558e517ff","asset_id":"40652734036737240317526188612064032143639112324786051284480877037991580442979","source":"market_ws:sub:unknown","t_event_ms":1770839723857,"t_recv_wall_ms":1770839723766,"t_recv_wall_iso":"2026-02-11T19:55:23.766Z","t_recv_mono_ns":618589106784458,"raw":{"market":"0x8032d8355d335c6ccbfc2508d99fbc87eb13f437bd275c93ee56fd1558e517ff","asset_id":"40652734036737240317526188612064032143639112324786051284480877037991580442979","price":"0.97","size":"34.68","fee_rate_bps":"1000","side":"BUY","timestamp":"1770839723857","event_type":"last_trade_price","transaction_hash":"0xd1141ac88469702c692fb6242505fde390beba6db5a47a5caec4865d630b8fb2","_sub_state":"unknown","_subscription_id":null,"_active_subscription_id":1},"parse_warnings":["unknown_message_schema"],"out_of_order":false}
{"run_id":"29526913bab7446286864a321c124486","channel":"market","event_type":"price_change","market":"0x8032d8355d335c6ccbfc2508d99fbc87eb13f437bd275c93ee56fd1558e517ff","asset_id":null,"source":"market_ws:sub:active:1","t_event_ms":1770839723858,"t_recv_wall_ms":1770839723766,"t_recv_wall_iso":"2026-02-11T19:55:23.766Z","t_recv_mono_ns":618589106876041,"raw":{"market":"0x8032d8355d335c6ccbfc2508d99fbc87eb13f437bd275c93ee56fd1558e517ff","price_changes":[{"asset_id":"20773614133833886322101538939702011175545796528197617633926164254913649353392","price":"0.02","size":"8868.72","side":"BUY","hash":"d0e72b3c98ee0604048f2757b5afab6731dd982d","best_bid":"0.02","best_ask":"0.03"},{"asset_id":"40652734036737240317526188612064032143639112324786051284480877037991580442979","price":"0.98","size":"8868.72","side":"SELL","hash":"54b4bcac4e36b363c05a1a6d8baa8bd00b8d5165","best_bid":"0.97","best_ask":"0.98"}],"timestamp":"1770839723858","event_type":"price_change","_sub_state":"active","_subscription_id":1,"_active_subscription_id":1},"parse_warnings":[],"out_of_order":false}
{"run_id":"29526913bab7446286864a321c124486","channel":"market","event_type":"price_change","market":"0x8032d8355d335c6ccbfc2508d99fbc87eb13f437bd275c93ee56fd1558e517ff","asset_id":null,"source":"market_ws:sub:active:1","t_event_ms":1770839723858,"t_recv_wall_ms":1770839723766,"t_recv_wall_iso":"2026-02-11T19:55:23.766Z","t_recv_mono_ns":618589106965958,"raw":{"market":"0x8032d8355d335c6ccbfc2508d99fbc87eb13f437bd275c93ee56fd1558e517ff","price_changes":[{"asset_id":"40652734036737240317526188612064032143639112324786051284480877037991580442979","price":"0.95","size":"3319.45","side":"BUY","hash":"4629a93ead4769e0d277a40eaa12b1b93f6969a2","best_bid":"0.97","best_ask":"0.98"},{"asset_id":"20773614133833886322101538939702011175545796528197617633926164254913649353392","price":"0.05","size":"3319.45","side":"SELL","hash":"3fdc3e7f53ef27715b61d5522a3a358e2ecaae59","best_bid":"0.02","best_ask":"0.03"}],"timestamp":"1770839723858","event_type":"price_change","_sub_state":"active","_subscription_id":1,"_active_subscription_id":1},"parse_warnings":[],"out_of_order":false}
{"run_id":"29526913bab7446286864a321c124486","channel":"market","event_type":"price_change","market":"0x8032d8355d335c6ccbfc2508d99fbc87eb13f437bd275c93ee56fd1558e517ff","asset_id":null,"source":"market_ws:sub:active:1","t_event_ms":1770839723860,"t_recv_wall_ms":1770839723776,"t_recv_wall_iso":"2026-02-11T19:55:23.776Z","t_recv_mono_ns":618589117268500,"raw":{"market":"0x8032d8355d335c6ccbfc2508d99fbc87eb13f437bd275c93ee56fd1558e517ff","price_changes":[{"asset_id":"40652734036737240317526188612064032143639112324786051284480877037991580442979","price":"0.96","size":"3824.17","side":"BUY","hash":"8bf1676eb1acabf4ba2484b7c372e48662a103bb","best_bid":"0.97","best_ask":"0.98"},{"asset_id":"20773614133833886322101538939702011175545796528197617633926164254913649353392","price":"0.04","size":"3824.17","side":"SELL","hash":"592e931e139203ff07fbdd4f3483edea6e794c7d","best_bid":"0.02","best_ask":"0.03"}],"timestamp":"1770839723860","event_type":"price_change","_sub_state":"active","_subscription_id":1,"_active_subscription_id":1},"parse_warnings":[],"out_of_order":false}
{"run_id":"29526913bab7446286864a321c124486","channel":"market","event_type":"price_change","market":"0x8032d8355d335c6ccbfc2508d99fbc87eb13f437bd275c93ee56fd1558e517ff","asset_id":null,"source":"market_ws:sub:active:1","t_event_ms":1770839723865,"t_recv_wall_ms":1770839723776,"t_recv_wall_iso":"2026-02-11T19:55:23.776Z","t_recv_mono_ns":618589117541041,"raw":{"market":"0x8032d8355d335c6ccbfc2508d99fbc87eb13f437bd275c93ee56fd1558e517ff","price_changes":[{"asset_id":"40652734036737240317526188612064032143639112324786051284480877037991580442979","price":"0.97","size":"510.32","side":"BUY","hash":"ed387fb1164ba2d3ac157fa3eb67d20bc346d6b3","best_bid":"0.97","best_ask":"0.98"},{"asset_id":"20773614133833886322101538939702011175545796528197617633926164254913649353392","price":"0.03","size":"510.32","side":"SELL","hash":"e64eb665aa73e93b64dc24205dd0fa752a27b6e7","best_bid":"0.02","best_ask":"0.03"}],"timestamp":"1770839723865","event_type":"price_change","_sub_state":"active","_subscription_id":1,"_active_subscription_id":1},"parse_warnings":[],"out_of_order":false}
{"run_id":"29526913bab7446286864a321c124486","channel":"market","event_type":"price_change","market":"0x8032d8355d335c6ccbfc2508d99fbc87eb13f437bd275c93ee56fd1558e517ff","asset_id":null,"source":"market_ws:sub:active:1","t_event_ms":1770839723867,"t_recv_wall_ms":1770839723776,"t_recv_wall_iso":"2026-02-11T19:55:23.776Z","t_recv_mono_ns":618589117663708,"raw":{"market":"0x8032d8355d335c6ccbfc2508d99fbc87eb13f437bd275c93ee56fd1558e517ff","price_changes":[{"asset_id":"40652734036737240317526188612064032143639112324786051284480877037991580442979","price":"0.95","size":"3314.45","side":"BUY","hash":"80647b46d68d8cbfadd87334bfba9843a24c42ac","best_bid":"0.97","best_ask":"0.98"},{"asset_id":"20773614133833886322101538939702011175545796528197617633926164254913649353392","price":"0.05","size":"3314.45","side":"SELL","hash":"83d483f9e0bd85b566068a318c3cdd8816d8d643","best_bid":"0.02","best_ask":"0.03"}],"timestamp":"1770839723867","event_type":"price_change","_sub_state":"active","_subscription_id":1,"_active_subscription_id":1},"parse_warnings":[],"out_of_order":false}
{"run_id":"29526913bab7446286864a321c124486","channel":"market","event_type":"price_change","market":"0x8032d8355d335c6ccbfc2508d99fbc87eb13f437bd275c93ee56fd1558e517ff","asset_id":null,"source":"market_ws:sub:active:1","t_event_ms":1770839723872,"t_recv_wall_ms":1770839723787,"t_recv_wall_iso":"2026-02-11T19:55:23.787Z","t_recv_mono_ns":618589128159041,"raw":{"market":"0x8032d8355d335c6ccbfc2508d99fbc87eb13f437bd275c93ee56fd1558e517ff","price_changes":[{"asset_id":"40652734036737240317526188612064032143639112324786051284480877037991580442979","price":"0.83","size":"958.39","side":"BUY","hash":"d02e9a4fe13a89217ba2523e9b7c83ae36f3a9d9","best_bid":"0.97","best_ask":"0.98"},{"asset_id":"20773614133833886322101538939702011175545796528197617633926164254913649353392","price":"0.17","size":"958.39","side":"SELL","hash":"a5752d7c581eeda99c65636b6cb34e4387906ec5","best_bid":"0.02","best_ask":"0.03"}],"timestamp":"1770839723872","event_type":"price_change","_sub_state":"active","_subscription_id":1,"_active_subscription_id":1},"parse_warnings":[],"out_of_order":false}
{"run_id":"29526913bab7446286864a321c124486","channel":"market","event_type":"price_change","market":"0x8032d8355d335c6ccbfc2508d99fbc87eb13f437bd275c93ee56fd1558e517ff","asset_id":null,"source":"market_ws:sub:active:1","t_event_ms":1770839723876,"t_recv_wall_ms":1770839723787,"t_recv_wall_iso":"2026-02-11T19:55:23.787Z","t_recv_mono_ns":618589128383666,"raw":{"market":"0x8032d8355d335c6ccbfc2508d99fbc87eb13f437bd275c93ee56fd1558e517ff","price_changes":[{"asset_id":"40652734036737240317526188612064032143639112324786051284480877037991580442979","price":"0.96","size":"3804.17","side":"BUY","hash":"24daa19f9a40b33df9a0b5499867b220facef9c3","best_bid":"0.97","best_ask":"0.98"},{"asset_id":"20773614133833886322101538939702011175545796528197617633926164254913649353392","price":"0.04","size":"3804.17","side":"SELL","hash":"68575572ac8747f01d84f6ab9d2d36ab68cd03a9","best_bid":"0.02","best_ask":"0.03"}],"timestamp":"1770839723876","event_type":"price_change","_sub_state":"active","_subscription_id":1,"_active_subscription_id":1},"parse_warnings":[],"out_of_order":false}
{"run_id":"29526913bab7446286864a321c124486","channel":"market","event_type":"price_change","market":"0x8032d8355d335c6ccbfc2508d99fbc87eb13f437bd275c93ee56fd1558e517ff","asset_id":null,"source":"market_ws:sub:active:1","t_event_ms":1770839723880,"t_recv_wall_ms":1770839723787,"t_recv_wall_iso":"2026-02-11T19:55:23.787Z","t_recv_mono_ns":618589128514791,"raw":{"market":"0x8032d8355d335c6ccbfc2508d99fbc87eb13f437bd275c93ee56fd1558e517ff","price_changes":[{"asset_id":"40652734036737240317526188612064032143639112324786051284480877037991580442979","price":"0.92","size":"3404.35","side":"BUY","hash":"326fe5db39af351c27179a4644b103d47eccba06","best_bid":"0.97","best_ask":"0.98"},{"asset_id":"20773614133833886322101538939702011175545796528197617633926164254913649353392","price":"0.08","size":"3404.35","side":"SELL","hash":"f521b8432fd4195e356ec1fbde44113e91e2bf7d","best_bid":"0.02","best_ask":"0.03"}],"timestamp":"1770839723880","event_type":"price_change","_sub_state":"active","_subscription_id":1,"_active_subscription_id":1},"parse_warnings":[],"out_of_order":false}
{"run_id":"29526913bab7446286864a321c124486","channel":"market","event_type":"price_change","market":"0x8032d8355d335c6ccbfc2508d99fbc87eb13f437bd275c93ee56fd1558e517ff","asset_id":null,"source":"market_ws:sub:active:1","t_event_ms":1770839723883,"t_recv_wall_ms":1770839723787,"t_recv_wall_iso":"2026-02-11T19:55:23.787Z","t_recv_mono_ns":618589128628083,"raw":{"market":"0x8032d8355d335c6ccbfc2508d99fbc87eb13f437bd275c93ee56fd1558e517ff","price_changes":[{"asset_id":"20773614133833886322101538939702011175545796528197617633926164254913649353392","price":"0.04","size":"3791.17","side":"SELL","hash":"8c556dfe564fd6f5996bbe0916baf7f8d90303cf","best_bid":"0.02","best_ask":"0.03"},{"asset_id":"40652734036737240317526188612064032143639112324786051284480877037991580442979","price":"0.96","size":"3791.17","side":"BUY","hash":"e808ea11d886c172ba92b05a61824c53484cc65e","best_bid":"0.97","best_ask":"0.98"}],"timestamp":"1770839723883","event_type":"price_change","_sub_state":"active","_subscription_id":1,"_active_subscription_id":1},"parse_warnings":[],"out_of_order":false}
{"run_id":"29526913bab7446286864a321c124486","channel":"market","event_type":"price_change","market":"0x8032d8355d335c6ccbfc2508d99fbc87eb13f437bd275c93ee56fd1558e517ff","asset_id":null,"source":"market_ws:sub:active:1","t_event_ms":1770839723897,"t_recv_wall_ms":1770839723959,"t_recv_wall_iso":"2026-02-11T19:55:23.959Z","t_recv_mono_ns":618589299870875,"raw":{"market":"0x8032d8355d335c6ccbfc2508d99fbc87eb13f437bd275c93ee56fd1558e517ff","price_changes":[{"asset_id":"40652734036737240317526188612064032143639112324786051284480877037991580442979","price":"0.96","size":"3776.17","side":"BUY","hash":"343494ebee59a704ad2550ff6f2f38800dd7e880","best_bid":"0.97","best_ask":"0.98"},{"asset_id":"20773614133833886322101538939702011175545796528197617633926164254913649353392","price":"0.04","size":"3776.17","side":"SELL","hash":"07b184cc93063afdbf421104b4097fc73d462a05","best_bid":"0.02","best_ask":"0.03"}],"timestamp":"1770839723897","event_type":"price_change","_sub_state":"active","_subscription_id":1,"_active_subscription_id":1},"parse_warnings":[],"out_of_order":false}
{"run_id":"29526913bab7446286864a321c124486","channel":"market","event_type":"price_change","market":"0x8032d8355d335c6ccbfc2508d99fbc87eb13f437bd275c93ee56fd1558e517ff","asset_id":null,"source":"market_ws:sub:active:1","t_event_ms":1770839723906,"t_recv_wall_ms":1770839723959,"t_recv_wall_iso":"2026-02-11T19:55:23.959Z","t_recv_mono_ns":618589300265041,"raw":{"market":"0x8032d8355d335c6ccbfc2508d99fbc87eb13f437bd275c93ee56fd1558e517ff","price_changes":[{"asset_id":"40652734036737240317526188612064032143639112324786051284480877037991580442979","price":"0.95","size":"3284.45","side":"BUY","hash":"75b62ba8172d88785a6bd1108ae9459db1da2056","best_bid":"0.97","best_ask":"0.98"},{"asset_id":"20773614133833886322101538939702011175545796528197617633926164254913649353392","price":"0.05","size":"3284.45","side":"SELL","hash":"33d663312328645955f6a7d5e9b14bdaedc0a589","best_bid":"0.02","best_ask":"0.03"}],"timestamp":"1770839723906","event_type":"price_change","_sub_state":"active","_subscription_id":1,"_active_subscription_id":1},"parse_warnings":[],"out_of_order":false}
{"run_id":"29526913bab7446286864a321c124486","channel":"market","event_type":"price_change","market":"0x8032d8355d335c6ccbfc2508d99fbc87eb13f437bd275c93ee56fd1558e517ff","asset_id":null,"source":"market_ws:sub:active:1","t_event_ms":1770839723908,"t_recv_wall_ms":1770839723959,"t_recv_wall_iso":"2026-02-11T19:55:23.959Z","t_recv_mono_ns":618589300430458,"raw":{"market":"0x8032d8355d335c6ccbfc2508d99fbc87eb13f437bd275c93ee56fd1558e517ff","price_changes":[{"asset_id":"40652734036737240317526188612064032143639112324786051284480877037991580442979","price":"0.96","size":"3761.17","side":"BUY","hash":"bb019d6c4a70e8ef0c6634882d296a5bca17700a","best_bid":"0.97","best_ask":"0.98"},{"asset_id":"20773614133833886322101538939702011175545796528197617633926164254913649353392","price":"0.04","size":"3761.17","side":"SELL","hash":"35fb60a59ca30c2a70f4de58c86ff507f1b2bf25","best_bid":"0.02","best_ask":"0.03"}],"timestamp":"1770839723908","event_type":"price_change","_sub_state":"active","_subscription_id":1,"_active_subscription_id":1},"parse_warnings":[],"out_of_order":false}
{"run_id":"29526913bab7446286864a321c124486","channel":"market","event_type":"price_change","market":"0x8032d8355d335c6ccbfc2508d99fbc87eb13f437bd275c93ee56fd1558e517ff","asset_id":null,"source":"market_ws:sub:active:1","t_event_ms":1770839723911,"t_recv_wall_ms":1770839723959,"t_recv_wall_iso":"2026-02-11T19:55:23.959Z","t_recv_mono_ns":618589300537583,"raw":{"market":"0x8032d8355d335c6ccbfc2508d99fbc87eb13f437bd275c93ee56fd1558e517ff","price_changes":[{"asset_id":"40652734036737240317526188612064032143639112324786051284480877037991580442979","price":"0.95","size":"3254.45","side":"BUY","hash":"996554fab804d54c2ec70b19542fbe0c9de38ad1","best_bid":"0.97","best_ask":"0.98"},{"asset_id":"20773614133833886322101538939702011175545796528197617633926164254913649353392","price":"0.05","size":"3254.45","side":"SELL","hash":"2a830cd38c61e1ac0a58b43c9d6cd39dccc65129","best_bid":"0.02","best_ask":"0.03"}],"timestamp":"1770839723911","event_type":"price_change","_sub_state":"active","_subscription_id":1,"_active_subscription_id":1},"parse_warnings":[],"out_of_order":false}
{"run_id":"29526913bab7446286864a321c124486","channel":"market","event_type":"price_change","market":"0x8032d8355d335c6ccbfc2508d99fbc87eb13f437bd275c93ee56fd1558e517ff","asset_id":null,"source":"market_ws:sub:active:1","t_event_ms":1770839723914,"t_recv_wall_ms":1770839723959,"t_recv_wall_iso":"2026-02-11T19:55:23.959Z","t_recv_mono_ns":618589300632750,"raw":{"market":"0x8032d8355d335c6ccbfc2508d99fbc87eb13f437bd275c93ee56fd1558e517ff","price_changes":[{"asset_id":"40652734036737240317526188612064032143639112324786051284480877037991580442979","price":"0.96","size":"3748.17","side":"BUY","hash":"4ceec2fdc3a653258f0878f48051a6d6c5b79e64","best_bid":"0.97","best_ask":"0.98"},{"asset_id":"20773614133833886322101538939702011175545796528197617633926164254913649353392","price":"0.04","size":"3748.17","side":"SELL","hash":"43a97b8cac2b88e262b36189ccf74c465bf28f1f","best_bid":"0.02","best_ask":"0.03"}],"timestamp":"1770839723914","event_type":"price_change","_sub_state":"active","_subscription_id":1,"_active_subscription_id":1},"parse_warnings":[],"out_of_order":false}
{"run_id":"29526913bab7446286864a321c124486","channel":"market","event_type":"price_change","market":"0x8032d8355d335c6ccbfc2508d99fbc87eb13f437bd275c93ee56fd1558e517ff","asset_id":null,"source":"market_ws:sub:active:1","t_event_ms":1770839723917,"t_recv_wall_ms":1770839723959,"t_recv_wall_iso":"2026-02-11T19:55:23.959Z","t_recv_mono_ns":618589300727000,"raw":{"market":"0x8032d8355d335c6ccbfc2508d99fbc87eb13f437bd275c93ee56fd1558e517ff","price_changes":[{"asset_id":"20773614133833886322101538939702011175545796528197617633926164254913649353392","price":"0.02","size":"8873.72","side":"BUY","hash":"17b481b6b697d7afeb84353ee71245cd6344ae45","best_bid":"0.02","best_ask":"0.03"},{"asset_id":"40652734036737240317526188612064032143639112324786051284480877037991580442979","price":"0.98","size":"8873.72","side":"SELL","hash":"3d4c3bfaab7e3e9aec2552230ed266cd6b560414","best_bid":"0.97","best_ask":"0.98"}],"timestamp":"1770839723917","event_type":"price_change","_sub_state":"active","_subscription_id":1,"_active_subscription_id":1},"parse_warnings":[],"out_of_order":false}
{"run_id":"29526913bab7446286864a321c124486","channel":"market","event_type":"price_change","market":"0x8032d8355d335c6ccbfc2508d99fbc87eb13f437bd275c93ee56fd1558e517ff","asset_id":null,"source":"market_ws:sub:active:1","t_event_ms":1770839723924,"t_recv_wall_ms":1770839723960,"t_recv_wall_iso":"2026-02-11T19:55:23.960Z","t_recv_mono_ns":618589300811750,"raw":{"market":"0x8032d8355d335c6ccbfc2508d99fbc87eb13f437bd275c93ee56fd1558e517ff","price_changes":[{"asset_id":"40652734036737240317526188612064032143639112324786051284480877037991580442979","price":"0.97","size":"530.32","side":"BUY","hash":"46abc701b853ea70247640e5ed2282869415ce3f","best_bid":"0.97","best_ask":"0.98"},{"asset_id":"20773614133833886322101538939702011175545796528197617633926164254913649353392","price":"0.03","size":"530.32","side":"SELL","hash":"9c60e8898230a93d5f4cc7cf5206abcb90a69b04","best_bid":"0.02","best_ask":"0.03"}],"timestamp":"1770839723924","event_type":"price_change","_sub_state":"active","_subscription_id":1,"_active_subscription_id":1},"parse_warnings":[],"out_of_order":false}
{"run_id":"29526913bab7446286864a321c124486","channel":"market","event_type":"price_change","market":"0x8032d8355d335c6ccbfc2508d99fbc87eb13f437bd275c93ee56fd1558e517ff","asset_id":null,"source":"market_ws:sub:active:1","t_event_ms":1770839723927,"t_recv_wall_ms":1770839723960,"t_recv_wall_iso":"2026-02-11T19:55:23.960Z","t_recv_mono_ns":618589300893583,"raw":{"market":"0x8032d8355d335c6ccbfc2508d99fbc87eb13f437bd275c93ee56fd1558e517ff","price_changes":[{"asset_id":"40652734036737240317526188612064032143639112324786051284480877037991580442979","price":"0.96","size":"3753.17","side":"BUY","hash":"929c43ee3996fbf588e5e190acb16a2156973016","best_bid":"0.97","best_ask":"0.98"},{"asset_id":"20773614133833886322101538939702011175545796528197617633926164254913649353392","price":"0.04","size":"3753.17","side":"SELL","hash":"4d6ab7516e0e9b5166466ac7d7953491dcb158ab","best_bid":"0.02","best_ask":"0.03"}],"timestamp":"1770839723927","event_type":"price_change","_sub_state":"active","_subscription_id":1,"_active_subscription_id":1},"parse_warnings":[],"out_of_order":false}
{"run_id":"29526913bab7446286864a321c124486","channel":"market","event_type":"price_change","market":"0x8032d8355d335c6ccbfc2508d99fbc87eb13f437bd275c93ee56fd1558e517ff","asset_id":null,"source":"market_ws:sub:active:1","t_event_ms":1770839723928,"t_recv_wall_ms":1770839723960,"t_recv_wall_iso":"2026-02-11T19:55:23.960Z","t_recv_mono_ns":618589300983291,"raw":{"market":"0x8032d8355d335c6ccbfc2508d99fbc87eb13f437bd275c93ee56fd1558e517ff","price_changes":[{"asset_id":"40652734036737240317526188612064032143639112324786051284480877037991580442979","price":"0.97","size":"536.32","side":"BUY","hash":"980b21f08525fc0c3506e03693dad56d29aa8fe5","best_bid":"0.97","best_ask":"0.98"},{"asset_id":"20773614133833886322101538939702011175545796528197617633926164254913649353392","price":"0.03","size":"536.32","side":"SELL","hash":"4a2c89dbedc0ba513e943adfb0645f21d9f5a3d1","best_bid":"0.02","best_ask":"0.03"}],"timestamp":"1770839723928","event_type":"price_change","_sub_state":"active","_subscription_id":1,"_active_subscription_id":1},"parse_warnings":[],"out_of_order":false}
{"run_id":"29526913bab7446286864a321c124486","channel":"market","event_type":"price_change","market":"0x8032d8355d335c6ccbfc2508d99fbc87eb13f437bd275c93ee56fd1558e517ff","asset_id":null,"source":"market_ws:sub:active:1","t_event_ms":1770839723937,"t_recv_wall_ms":1770839723960,"t_recv_wall_iso":"2026-02-11T19:55:23.960Z","t_recv_mono_ns":618589301061541,"raw":{"market":"0x8032d8355d335c6ccbfc2508d99fbc87eb13f437bd275c93ee56fd1558e517ff","price_changes":[{"asset_id":"40652734036737240317526188612064032143639112324786051284480877037991580442979","price":"0.96","size":"3738.17","side":"BUY","hash":"5c2d3e89ed559da82e5c16811cd6d64493288725","best_bid":"0.97","best_ask":"0.98"},{"asset_id":"20773614133833886322101538939702011175545796528197617633926164254913649353392","price":"0.04","size":"3738.17","side":"SELL","hash":"30cae17aa523394e2d6204244e4aede33cd2f49a","best_bid":"0.02","best_ask":"0.03"}],"timestamp":"1770839723937","event_type":"price_change","_sub_state":"active","_subscription_id":1,"_active_subscription_id":1},"parse_warnings":[],"out_of_order":false}
{"run_id":"29526913bab7446286864a321c124486","channel":"market","event_type":"price_change","market":"0x8032d8355d335c6ccbfc2508d99fbc87eb13f437bd275c93ee56fd1558e517ff","asset_id":null,"source":"market_ws:sub:active:1","t_event_ms":1770839723944,"t_recv_wall_ms":1770839723960,"t_recv_wall_iso":"2026-02-11T19:55:23.960Z","t_recv_mono_ns":618589301136791,"raw":{"market":"0x8032d8355d335c6ccbfc2508d99fbc87eb13f437bd275c93ee56fd1558e517ff","price_changes":[{"asset_id":"40652734036737240317526188612064032143639112324786051284480877037991580442979","price":"0.92","size":"3384.35","side":"BUY","hash":"b5ab393a0596966a9f3772c38f59e9a91a61de18","best_bid":"0.97","best_ask":"0.98"},{"asset_id":"20773614133833886322101538939702011175545796528197617633926164254913649353392","price":"0.08","size":"3384.35","side":"SELL","hash":"28b03aa533efd287d432b0536b7462d040d497df","best_bid":"0.02","best_ask":"0.03"}],"timestamp":"1770839723944","event_type":"price_change","_sub_state":"active","_subscription_id":1,"_active_subscription_id":1},"parse_warnings":[],"out_of_order":false}
{"run_id":"29526913bab7446286864a321c124486","channel":"market","event_type":"price_change","market":"0x8032d8355d335c6ccbfc2508d99fbc87eb13f437bd275c93ee56fd1558e517ff","asset_id":null,"source":"market_ws:sub:active:1","t_event_ms":1770839723946,"t_recv_wall_ms":1770839723960,"t_recv_wall_iso":"2026-02-11T19:55:23.960Z","t_recv_mono_ns":618589301221291,"raw":{"market":"0x8032d8355d335c6ccbfc2508d99fbc87eb13f437bd275c93ee56fd1558e517ff","price_changes":[{"asset_id":"20773614133833886322101538939702011175545796528197617633926164254913649353392","price":"0.03","size":"549.32","side":"SELL","hash":"51469743c64ff11ac73d08eeb77a6068829a10b8","best_bid":"0.02","best_ask":"0.03"},{"asset_id":"40652734036737240317526188612064032143639112324786051284480877037991580442979","price":"0.97","size":"549.32","side":"BUY","hash":"5733da0876612f992d6a021f364aaf70f3c411f1","best_bid":"0.97","best_ask":"0.98"}],"timestamp":"1770839723946","event_type":"price_change","_sub_state":"active","_subscription_id":1,"_active_subscription_id":1},"parse_warnings":[],"out_of_order":false}
{"run_id":"29526913bab7446286864a321c124486","channel":"market","event_type":"price_change","market":"0x8032d8355d335c6ccbfc2508d99fbc87eb13f437bd275c93ee56fd1558e517ff","asset_id":null,"source":"market_ws:sub:active:1","t_event_ms":1770839723962,"t_recv_wall_ms":1770839723960,"t_recv_wall_iso":"2026-02-11T19:55:23.960Z","t_recv_mono_ns":618589301296375,"raw":{"market":"0x8032d8355d335c6ccbfc2508d99fbc87eb13f437bd275c93ee56fd1558e517ff","price_changes":[{"asset_id":"40652734036737240317526188612064032143639112324786051284480877037991580442979","price":"0.97","size":"564.32","side":"BUY","hash":"88c513d9efada2e8642db47a1ee9003f819d87e3","best_bid":"0.97","best_ask":"0.98"},{"asset_id":"20773614133833886322101538939702011175545796528197617633926164254913649353392","price":"0.03","size":"564.32","side":"SELL","hash":"78c85b0d46fe96ea76cbafbad4d79eada8eb2093","best_bid":"0.02","best_ask":"0.03"}],"timestamp":"1770839723962","event_type":"price_change","_sub_state":"active","_subscription_id":1,"_active_subscription_id":1},"parse_warnings":[],"out_of_order":false}
{"run_id":"29526913bab7446286864a321c124486","channel":"market","event_type":"price_change","market":"0x8032d8355d335c6ccbfc2508d99fbc87eb13f437bd275c93ee56fd1558e517ff","asset_id":null,"source":"market_ws:sub:active:1","t_event_ms":1770839723964,"t_recv_wall_ms":1770839723960,"t_recv_wall_iso":"2026-02-11T19:55:23.960Z","t_recv_mono_ns":618589301371208,"raw":{"market":"0x8032d8355d335c6ccbfc2508d99fbc87eb13f437bd275c93ee56fd1558e517ff","price_changes":[{"asset_id":"40652734036737240317526188612064032143639112324786051284480877037991580442979","price":"0.95","size":"3224.45","side":"BUY","hash":"cb5447636ce353e2f15899f812080b1f89150c42","best_bid":"0.97","best_ask":"0.98"},{"asset_id":"20773614133833886322101538939702011175545796528197617633926164254913649353392","price":"0.05","size":"3224.45","side":"SELL","hash":"309a4fb19551a2cd8c121839d7f82aaf44f23e3c","best_bid":"0.02","best_ask":"0.03"}],"timestamp":"1770839723964","event_type":"price_change","_sub_state":"active","_subscription_id":1,"_active_subscription_id":1},"parse_warnings":[],"out_of_order":false}
{"run_id":"29526913bab7446286864a321c124486","channel":"market","event_type":"price_change","market":"0x8032d8355d335c6ccbfc2508d99fbc87eb13f437bd275c93ee56fd1558e517ff","asset_id":null,"source":"market_ws:sub:active:1","t_event_ms":1770839723966,"t_recv_wall_ms":1770839723960,"t_recv_wall_iso":"2026-02-11T19:55:23.960Z","t_recv_mono_ns":618589301444375,"raw":{"market":"0x8032d8355d335c6ccbfc2508d99fbc87eb13f437bd275c93ee56fd1558e517ff","price_changes":[{"asset_id":"40652734036737240317526188612064032143639112324786051284480877037991580442979","price":"0.97","size":"569.48","side":"BUY","hash":"22ec4358d4f3ea80a5140adf17b601d0a324f259","best_bid":"0.97","best_ask":"0.98"},{"asset_id":"20773614133833886322101538939702011175545796528197617633926164254913649353392","price":"0.03","size":"569.48","side":"SELL","hash":"cd98c3ec19d955bf913f93b66c39ff09e51e04f9","best_bid":"0.02","best_ask":"0.03"}],"timestamp":"1770839723966","event_type":"price_change","_sub_state":"active","_subscription_id":1,"_active_subscription_id":1},"parse_warnings":[],"out_of_order":false}
{"run_id":"29526913bab7446286864a321c124486","channel":"market","event_type":"price_change","market":"0x8032d8355d335c6ccbfc2508d99fbc87eb13f437bd275c93ee56fd1558e517ff","asset_id":null,"source":"market_ws:sub:active:1","t_event_ms":1770839723967,"t_recv_wall_ms":1770839723960,"t_recv_wall_iso":"2026-02-11T19:55:23.960Z","t_recv_mono_ns":618589301518750,"raw":{"market":"0x8032d8355d335c6ccbfc2508d99fbc87eb13f437bd275c93ee56fd1558e517ff","price_changes":[{"asset_id":"40652734036737240317526188612064032143639112324786051284480877037991580442979","price":"0.97","size":"584.48","side":"BUY","hash":"2255ed7720073ef14626a8a40557d37e4459a6bc","best_bid":"0.97","best_ask":"0.98"},{"asset_id":"20773614133833886322101538939702011175545796528197617633926164254913649353392","price":"0.03","size":"584.48","side":"SELL","hash":"a54de20d94c5a9defbb80bf037f6365b603bb85f","best_bid":"0.02","best_ask":"0.03"}],"timestamp":"1770839723967","event_type":"price_change","_sub_state":"active","_subscription_id":1,"_active_subscription_id":1},"parse_warnings":[],"out_of_order":false}
{"run_id":"29526913bab7446286864a321c124486","channel":"market","event_type":"price_change","market":"0x8032d8355d335c6ccbfc2508d99fbc87eb13f437bd275c93ee56fd1558e517ff","asset_id":null,"source":"market_ws:sub:active:1","t_event_ms":1770839723972,"t_recv_wall_ms":1770839723960,"t_recv_wall_iso":"2026-02-11T19:55:23.960Z","t_recv_mono_ns":618589301593958,"raw":{"market":"0x8032d8355d335c6ccbfc2508d99fbc87eb13f437bd275c93ee56fd1558e517ff","price_changes":[{"asset_id":"40652734036737240317526188612064032143639112324786051284480877037991580442979","price":"0.83","size":"963.39","side":"BUY","hash":"88dd1a54393bc894d1eb965f6faf708da4b2112e","best_bid":"0.97","best_ask":"0.98"},{"asset_id":"20773614133833886322101538939702011175545796528197617633926164254913649353392","price":"0.17","size":"963.39","side":"SELL","hash":"7fb275312431287b9660cbc7cb6ab1c8b83d1f2c","best_bid":"0.02","best_ask":"0.03"}],"timestamp":"1770839723972","event_type":"price_change","_sub_state":"active","_subscription_id":1,"_active_subscription_id":1},"parse_warnings":[],"out_of_order":false}
{"run_id":"29526913bab7446286864a321c124486","channel":"market","event_type":"price_change","market":"0x8032d8355d335c6ccbfc2508d99fbc87eb13f437bd275c93ee56fd1558e517ff","asset_id":null,"source":"market_ws:sub:active:1","t_event_ms":1770839723982,"t_recv_wall_ms":1770839723960,"t_recv_wall_iso":"2026-02-11T19:55:23.960Z","t_recv_mono_ns":618589301680833,"raw":{"market":"0x8032d8355d335c6ccbfc2508d99fbc87eb13f437bd275c93ee56fd1558e517ff","price_changes":[{"asset_id":"40652734036737240317526188612064032143639112324786051284480877037991580442979","price":"0.93","size":"3360.43","side":"BUY","hash":"ebe2de6660f4d922a503e029aa563c6a1ad98d5c","best_bid":"0.97","best_ask":"0.98"},{"asset_id":"20773614133833886322101538939702011175545796528197617633926164254913649353392","price":"0.07","size":"3360.43","side":"SELL","hash":"f05d045f05d5ff667135836bc81184fda3ff0509","best_bid":"0.02","best_ask":"0.03"}],"timestamp":"1770839723982","event_type":"price_change","_sub_state":"active","_subscription_id":1,"_active_subscription_id":1},"parse_warnings":[],"out_of_order":false}
{"run_id":"29526913bab7446286864a321c124486","channel":"market","event_type":"price_change","market":"0x8032d8355d335c6ccbfc2508d99fbc87eb13f437bd275c93ee56fd1558e517ff","asset_id":null,"source":"market_ws:sub:active:1","t_event_ms":1770839724008,"t_recv_wall_ms":1770839723961,"t_recv_wall_iso":"2026-02-11T19:55:23.961Z","t_recv_mono_ns":618589301767208,"raw":{"market":"0x8032d8355d335c6ccbfc2508d99fbc87eb13f437bd275c93ee56fd1558e517ff","price_changes":[{"asset_id":"40652734036737240317526188612064032143639112324786051284480877037991580442979","price":"0.97","size":"597.48","side":"BUY","hash":"d72eef9b3957ee770cce60862be05098be88c7ce","best_bid":"0.97","best_ask":"0.98"},{"asset_id":"20773614133833886322101538939702011175545796528197617633926164254913649353392","price":"0.03","size":"597.48","side":"SELL","hash":"edaaef015e7e242b4e727bacecd11d08814ff1cb","best_bid":"0.02","best_ask":"0.03"}],"timestamp":"1770839724008","event_type":"price_change","_sub_state":"active","_subscription_id":1,"_active_subscription_id":1},"parse_warnings":[],"out_of_order":false}
{"run_id":"29526913bab7446286864a321c124486","channel":"market","event_type":"price_change","market":"0x8032d8355d335c6ccbfc2508d99fbc87eb13f437bd275c93ee56fd1558e517ff","asset_id":null,"source":"market_ws:sub:active:1","t_event_ms":1770839724034,"t_recv_wall_ms":1770839723961,"t_recv_wall_iso":"2026-02-11T19:55:23.961Z","t_recv_mono_ns":618589301894041,"raw":{"market":"0x8032d8355d335c6ccbfc2508d99fbc87eb13f437bd275c93ee56fd1558e517ff","price_changes":[{"asset_id":"40652734036737240317526188612064032143639112324786051284480877037991580442979","price":"0.94","size":"3215.34","side":"BUY","hash":"e777641d0d6a3762d6fd5a02b34ac754f4e6c600","best_bid":"0.97","best_ask":"0.98"},{"asset_id":"20773614133833886322101538939702011175545796528197617633926164254913649353392","price":"0.06","size":"3215.34","side":"SELL","hash":"a690da7ce0035303f8fb31f0738e87c584f83844","best_bid":"0.02","best_ask":"0.03"}],"timestamp":"1770839724034","event_type":"price_change","_sub_state":"active","_subscription_id":1,"_active_subscription_id":1},"parse_warnings":[],"out_of_order":false}
{"run_id":"29526913bab7446286864a321c124486","channel":"market","event_type":"price_change","market":"0x8032d8355d335c6ccbfc2508d99fbc87eb13f437bd275c93ee56fd1558e517ff","asset_id":null,"source":"market_ws:sub:active:1","t_event_ms":1770839724044,"t_recv_wall_ms":1770839723961,"t_recv_wall_iso":"2026-02-11T19:55:23.961Z","t_recv_mono_ns":618589301976333,"raw":{"market":"0x8032d8355d335c6ccbfc2508d99fbc87eb13f437bd275c93ee56fd1558e517ff","price_changes":[{"asset_id":"20773614133833886322101538939702011175545796528197617633926164254913649353392","price":"0.02","size":"8843.72","side":"BUY","hash":"a4ac953edb765c00f05592860bfa3e76106b1dbd","best_bid":"0.02","best_ask":"0.03"},{"asset_id":"40652734036737240317526188612064032143639112324786051284480877037991580442979","price":"0.98","size":"8843.72","side":"SELL","hash":"b272807b25795071841cee8bc860bac8ceee2827","best_bid":"0.97","best_ask":"0.98"}],"timestamp":"1770839724044","event_type":"price_change","_sub_state":"active","_subscription_id":1,"_active_subscription_id":1},"parse_warnings":[],"out_of_order":false}
{"run_id":"29526913bab7446286864a321c124486","channel":"market","event_type":"price_change","market":"0x8032d8355d335c6ccbfc2508d99fbc87eb13f437bd275c93ee56fd1558e517ff","asset_id":null,"source":"market_ws:sub:active:1","t_event_ms":1770839724046,"t_recv_wall_ms":1770839723961,"t_recv_wall_iso":"2026-02-11T19:55:23.961Z","t_recv_mono_ns":618589302140333,"raw":{"market":"0x8032d8355d335c6ccbfc2508d99fbc87eb13f437bd275c93ee56fd1558e517ff","price_changes":[{"asset_id":"40652734036737240317526188612064032143639112324786051284480877037991580442979","price":"0.95","size":"3194.45","side":"BUY","hash":"71794e43b370ea20be0ebbd6f0698cdca8328c8f","best_bid":"0.97","best_ask":"0.98"},{"asset_id":"20773614133833886322101538939702011175545796528197617633926164254913649353392","price":"0.05","size":"3194.45","side":"SELL","hash":"592b45254f92d14ecfb0f13b2a6c98ff58a5fbef","best_bid":"0.02","best_ask":"0.03"}],"timestamp":"1770839724046","event_type":"price_change","_sub_state":"active","_subscription_id":1,"_active_subscription_id":1},"parse_warnings":[],"out_of_order":false}
{"run_id":"29526913bab7446286864a321c124486","channel":"market","event_type":"price_change","market":"0x8032d8355d335c6ccbfc2508d99fbc87eb13f437bd275c93ee56fd1558e517ff","asset_id":null,"source":"market_ws:sub:active:1","t_event_ms":1770839724048,"t_recv_wall_ms":1770839723969,"t_recv_wall_iso":"2026-02-11T19:55:23.969Z","t_recv_mono_ns":618589310667125,"raw":{"market":"0x8032d8355d335c6ccbfc2508d99fbc87eb13f437bd275c93ee56fd1558e517ff","price_changes":[{"asset_id":"20773614133833886322101538939702011175545796528197617633926164254913649353392","price":"0.02","size":"8813.72","side":"BUY","hash":"dcde617329171a4d950dce940fdd07e302189572","best_bid":"0.02","best_ask":"0.03"},{"asset_id":"40652734036737240317526188612064032143639112324786051284480877037991580442979","price":"0.98","size":"8813.72","side":"SELL","hash":"d5e6e0bd8ccc651adcb74cfa548b36d010db106f","best_bid":"0.97","best_ask":"0.98"}],"timestamp":"1770839724048","event_type":"price_change","_sub_state":"active","_subscription_id":1,"_active_subscription_id":1},"parse_warnings":[],"out_of_order":false}
{"run_id":"29526913bab7446286864a321c124486","channel":"market","event_type":"price_change","market":"0x8032d8355d335c6ccbfc2508d99fbc87eb13f437bd275c93ee56fd1558e517ff","asset_id":null,"source":"market_ws:sub:active:1","t_event_ms":1770839724050,"t_recv_wall_ms":1770839723970,"t_recv_wall_iso":"2026-02-11T19:55:23.970Z","t_recv_mono_ns":618589310959250,"raw":{"market":"0x8032d8355d335c6ccbfc2508d99fbc87eb13f437bd275c93ee56fd1558e517ff","price_changes":[{"asset_id":"40652734036737240317526188612064032143639112324786051284480877037991580442979","price":"0.96","size":"3768.17","side":"BUY","hash":"3199bb16ee2c03487771dde12bf5641c2f4e5d16","best_bid":"0.97","best_ask":"0.98"},{"asset_id":"20773614133833886322101538939702011175545796528197617633926164254913649353392","price":"0.04","size":"3768.17","side":"SELL","hash":"89b97a6ca5e4d4f9e6d090be10a5e9c9cbd6a81f","best_bid":"0.02","best_ask":"0.03"}],"timestamp":"1770839724050","event_type":"price_change","_sub_state":"active","_subscription_id":1,"_active_subscription_id":1},"parse_warnings":[],"out_of_order":false}
{"run_id":"29526913bab7446286864a321c124486","channel":"market","event_type":"price_change","market":"0x8032d8355d335c6ccbfc2508d99fbc87eb13f437bd275c93ee56fd1558e517ff","asset_id":null,"source":"market_ws:sub:active:1","t_event_ms":1770839724052,"t_recv_wall_ms":1770839723970,"t_recv_wall_iso":"2026-02-11T19:55:23.970Z","t_recv_mono_ns":618589311098416,"raw":{"market":"0x8032d8355d335c6ccbfc2508d99fbc87eb13f437bd275c93ee56fd1558e517ff","price_changes":[{"asset_id":"40652734036737240317526188612064032143639112324786051284480877037991580442979","price":"0.95","size":"3164.45","side":"BUY","hash":"143713f7dc223de959284f5ae720c4d649d61998","best_bid":"0.97","best_ask":"0.98"},{"asset_id":"20773614133833886322101538939702011175545796528197617633926164254913649353392","price":"0.05","size":"3164.45","side":"SELL","hash":"b6e642ae6e90a4173401458f2cac542a8931d04f","best_bid":"0.02","best_ask":"0.03"}],"timestamp":"1770839724052","event_type":"price_change","_sub_state":"active","_subscription_id":1,"_active_subscription_id":1},"parse_warnings":[],"out_of_order":false}
{"run_id":"29526913bab7446286864a321c124486","channel":"market","event_type":"price_change","market":"0x8032d8355d335c6ccbfc2508d99fbc87eb13f437bd275c93ee56fd1558e517ff","asset_id":null,"source":"market_ws:sub:active:1","t_event_ms":1770839724053,"t_recv_wall_ms":1770839723970,"t_recv_wall_iso":"2026-02-11T19:55:23.970Z","t_recv_mono_ns":618589311210375,"raw":{"market":"0x8032d8355d335c6ccbfc2508d99fbc87eb13f437bd275c93ee56fd1558e517ff","price_changes":[{"asset_id":"40652734036737240317526188612064032143639112324786051284480877037991580442979","price":"0.96","size":"3718.17","side":"BUY","hash":"2816b8e168247381eac49b01d3821abb58460a6c","best_bid":"0.97","best_ask":"0.98"},{"asset_id":"20773614133833886322101538939702011175545796528197617633926164254913649353392","price":"0.04","size":"3718.17","side":"SELL","hash":"65d398e044ecfabfac52d1acde1230b2fe9956da","best_bid":"0.02","best_ask":"0.03"}],"timestamp":"1770839724053","event_type":"price_change","_sub_state":"active","_subscription_id":1,"_active_subscription_id":1},"parse_warnings":[],"out_of_order":false}
{"run_id":"29526913bab7446286864a321c124486","channel":"market","event_type":"price_change","market":"0x8032d8355d335c6ccbfc2508d99fbc87eb13f437bd275c93ee56fd1558e517ff","asset_id":null,"source":"market_ws:sub:active:1","t_event_ms":1770839724055,"t_recv_wall_ms":1770839723970,"t_recv_wall_iso":"2026-02-11T19:55:23.970Z","t_recv_mono_ns":618589311317958,"raw":{"market":"0x8032d8355d335c6ccbfc2508d99fbc87eb13f437bd275c93ee56fd1558e517ff","price_changes":[{"asset_id":"40652734036737240317526188612064032143639112324786051284480877037991580442979","price":"0.96","size":"3748.17","side":"BUY","hash":"5aac16993d38d3515110b13c93bc32f9862a578e","best_bid":"0.97","best_ask":"0.98"},{"asset_id":"20773614133833886322101538939702011175545796528197617633926164254913649353392","price":"0.04","size":"3748.17","side":"SELL","hash":"51901b152a300bbee9b85a5296ef8f1c6a99e7be","best_bid":"0.02","best_ask":"0.03"}],"timestamp":"1770839724055","event_type":"price_change","_sub_state":"active","_subscription_id":1,"_active_subscription_id":1},"parse_warnings":[],"out_of_order":false}
{"run_id":"29526913bab7446286864a321c124486","channel":"market","event_type":"price_change","market":"0x8032d8355d335c6ccbfc2508d99fbc87eb13f437bd275c93ee56fd1558e517ff","asset_id":null,"source":"market_ws:sub:active:1","t_event_ms":1770839724072,"t_recv_wall_ms":1770839723976,"t_recv_wall_iso":"2026-02-11T19:55:23.976Z","t_recv_mono_ns":618589317065583,"raw":{"market":"0x8032d8355d335c6ccbfc2508d99fbc87eb13f437bd275c93ee56fd1558e517ff","price_changes":[{"asset_id":"40652734036737240317526188612064032143639112324786051284480877037991580442979","price":"0.83","size":"958.39","side":"BUY","hash":"8809f1bbe0107bf9f4f73e879bdafc3a017db585","best_bid":"0.97","best_ask":"0.98"},{"asset_id":"20773614133833886322101538939702011175545796528197617633926164254913649353392","price":"0.17","size":"958.39","side":"SELL","hash":"753905e963b89170d268e692ddb9b5af98268e33","best_bid":"0.02","best_ask":"0.03"}],"timestamp":"1770839724072","event_type":"price_change","_sub_state":"active","_subscription_id":1,"_active_subscription_id":1},"parse_warnings":[],"out_of_order":false}
{"run_id":"29526913bab7446286864a321c124486","channel":"market","event_type":"price_change","market":"0x8032d8355d335c6ccbfc2508d99fbc87eb13f437bd275c93ee56fd1558e517ff","asset_id":null,"source":"market_ws:sub:active:1","t_event_ms":1770839724075,"t_recv_wall_ms":1770839723978,"t_recv_wall_iso":"2026-02-11T19:55:23.978Z","t_recv_mono_ns":618589319193958,"raw":{"market":"0x8032d8355d335c6ccbfc2508d99fbc87eb13f437bd275c93ee56fd1558e517ff","price_changes":[{"asset_id":"20773614133833886322101538939702011175545796528197617633926164254913649353392","price":"0.01","size":"30854.91","side":"BUY","hash":"3deb3ebb4c830ad382c4041471a352e801bf330a","best_bid":"0.02","best_ask":"0.03"},{"asset_id":"40652734036737240317526188612064032143639112324786051284480877037991580442979","price":"0.99","size":"30854.91","side":"SELL","hash":"64f1853e86bd61838fdcec195623e31410a0476e","best_bid":"0.97","best_ask":"0.98"}],"timestamp":"1770839724075","event_type":"price_change","_sub_state":"active","_subscription_id":1,"_active_subscription_id":1},"parse_warnings":[],"out_of_order":false}
{"run_id":"29526913bab7446286864a321c124486","channel":"market","event_type":"price_change","market":"0x8032d8355d335c6ccbfc2508d99fbc87eb13f437bd275c93ee56fd1558e517ff","asset_id":null,"source":"market_ws:sub:active:1","t_event_ms":1770839724079,"t_recv_wall_ms":1770839723982,"t_recv_wall_iso":"2026-02-11T19:55:23.982Z","t_recv_mono_ns":618589323411583,"raw":{"market":"0x8032d8355d335c6ccbfc2508d99fbc87eb13f437bd275c93ee56fd1558e517ff","price_changes":[{"asset_id":"20773614133833886322101538939702011175545796528197617633926164254913649353392","price":"0.01","size":"30884.91","side":"BUY","hash":"7b67aae0365096ae05951f96429e08d16fe0be0f","best_bid":"0.02","best_ask":"0.03"},{"asset_id":"40652734036737240317526188612064032143639112324786051284480877037991580442979","price":"0.99","size":"30884.91","side":"SELL","hash":"ad795b1d388a0fe4103816434bb41f050adfa52e","best_bid":"0.97","best_ask":"0.98"}],"timestamp":"1770839724079","event_type":"price_change","_sub_state":"active","_subscription_id":1,"_active_subscription_id":1},"parse_warnings":[],"out_of_order":false}
{"run_id":"29526913bab7446286864a321c124486","channel":"market","event_type":"price_change","market":"0x8032d8355d335c6ccbfc2508d99fbc87eb13f437bd275c93ee56fd1558e517ff","asset_id":null,"source":"market_ws:sub:active:1","t_event_ms":1770839724085,"t_recv_wall_ms":1770839724002,"t_recv_wall_iso":"2026-02-11T19:55:24.002Z","t_recv_mono_ns":618589343115125,"raw":{"market":"0x8032d8355d335c6ccbfc2508d99fbc87eb13f437bd275c93ee56fd1558e517ff","price_changes":[{"asset_id":"40652734036737240317526188612064032143639112324786051284480877037991580442979","price":"0.97","size":"612.48","side":"BUY","hash":"f18115e542daa482863b36ecd1625e4391aefe29","best_bid":"0.97","best_ask":"0.98"},{"asset_id":"20773614133833886322101538939702011175545796528197617633926164254913649353392","price":"0.03","size":"612.48","side":"SELL","hash":"4dae2c268b2370381241275d319a2918ac801262","best_bid":"0.02","best_ask":"0.03"}],"timestamp":"1770839724085","event_type":"price_change","_sub_state":"active","_subscription_id":1,"_active_subscription_id":1},"parse_warnings":[],"out_of_order":false}
{"run_id":"29526913bab7446286864a321c124486","channel":"market","event_type":"price_change","market":"0x8032d8355d335c6ccbfc2508d99fbc87eb13f437bd275c93ee56fd1558e517ff","asset_id":null,"source":"market_ws:sub:active:1","t_event_ms":1770839724087,"t_recv_wall_ms":1770839724002,"t_recv_wall_iso":"2026-02-11T19:55:24.002Z","t_recv_mono_ns":618589343503291,"raw":{"market":"0x8032d8355d335c6ccbfc2508d99fbc87eb13f437bd275c93ee56fd1558e517ff","price_changes":[{"asset_id":"40652734036737240317526188612064032143639112324786051284480877037991580442979","price":"0.97","size":"622.48","side":"BUY","hash":"c955cc12edcbc46e09c19ee3d80894decbff8b04","best_bid":"0.97","best_ask":"0.98"},{"asset_id":"20773614133833886322101538939702011175545796528197617633926164254913649353392","price":"0.03","size":"622.48","side":"SELL","hash":"95faaac14c24aafe3d8536b2a365c83000adbe22","best_bid":"0.02","best_ask":"0.03"}],"timestamp":"1770839724087","event_type":"price_change","_sub_state":"active","_subscription_id":1,"_active_subscription_id":1},"parse_warnings":[],"out_of_order":false}
{"run_id":"29526913bab7446286864a321c124486","channel":"market","event_type":"price_change","market":"0x8032d8355d335c6ccbfc2508d99fbc87eb13f437bd275c93ee56fd1558e517ff","asset_id":null,"source":"market_ws:sub:active:1","t_event_ms":1770839724093,"t_recv_wall_ms":1770839724003,"t_recv_wall_iso":"2026-02-11T19:55:24.003Z","t_recv_mono_ns":618589343745291,"raw":{"market":"0x8032d8355d335c6ccbfc2508d99fbc87eb13f437bd275c93ee56fd1558e517ff","price_changes":[{"asset_id":"40652734036737240317526188612064032143639112324786051284480877037991580442979","price":"0.94","size":"3220.34","side":"BUY","hash":"7ae5c7d6b4439c5c8542df5ecf749bca675b027f","best_bid":"0.97","best_ask":"0.98"},{"asset_id":"20773614133833886322101538939702011175545796528197617633926164254913649353392","price":"0.06","size":"3220.34","side":"SELL","hash":"cf58239d1626e800f1332c0f4a74604321467ad3","best_bid":"0.02","best_ask":"0.03"}],"timestamp":"1770839724093","event_type":"price_change","_sub_state":"active","_subscription_id":1,"_active_subscription_id":1},"parse_warnings":[],"out_of_order":false}
{"run_id":"29526913bab7446286864a321c124486","channel":"market","event_type":"price_change","market":"0x8032d8355d335c6ccbfc2508d99fbc87eb13f437bd275c93ee56fd1558e517ff","asset_id":null,"source":"market_ws:sub:active:1","t_event_ms":1770839724128,"t_recv_wall_ms":1770839724053,"t_recv_wall_iso":"2026-02-11T19:55:24.053Z","t_recv_mono_ns":618589394067250,"raw":{"market":"0x8032d8355d335c6ccbfc2508d99fbc87eb13f437bd275c93ee56fd1558e517ff","price_changes":[{"asset_id":"40652734036737240317526188612064032143639112324786051284480877037991580442979","price":"0.9","size":"1291.79","side":"BUY","hash":"000822817fe0e4259371ca7f3b92649d0c4ea0e0","best_bid":"0.97","best_ask":"0.98"},{"asset_id":"20773614133833886322101538939702011175545796528197617633926164254913649353392","price":"0.1","size":"1291.79","side":"SELL","hash":"7deeb9437671c4bac0aa202c2ee1f0035f902a65","best_bid":"0.02","best_ask":"0.03"}],"timestamp":"1770839724128","event_type":"price_change","_sub_state":"active","_subscription_id":1,"_active_subscription_id":1},"parse_warnings":[],"out_of_order":false}
{"run_id":"29526913bab7446286864a321c124486","channel":"market","event_type":"price_change","market":"0x8032d8355d335c6ccbfc2508d99fbc87eb13f437bd275c93ee56fd1558e517ff","asset_id":null,"source":"market_ws:sub:active:1","t_event_ms":1770839724145,"t_recv_wall_ms":1770839724092,"t_recv_wall_iso":"2026-02-11T19:55:24.092Z","t_recv_mono_ns":618589433412250,"raw":{"market":"0x8032d8355d335c6ccbfc2508d99fbc87eb13f437bd275c93ee56fd1558e517ff","price_changes":[{"asset_id":"20773614133833886322101538939702011175545796528197617633926164254913649353392","price":"0.03","size":"632.82","side":"SELL","hash":"665e3331effc19ed7e75d19a0a51ca863c0952c8","best_bid":"0.02","best_ask":"0.03"},{"asset_id":"40652734036737240317526188612064032143639112324786051284480877037991580442979","price":"0.97","size":"632.82","side":"BUY","hash":"6549784841377d27bb924f564de6a2e6dd5d34cd","best_bid":"0.97","best_ask":"0.98"}],"timestamp":"1770839724145","event_type":"price_change","_sub_state":"active","_subscription_id":1,"_active_subscription_id":1},"parse_warnings":[],"out_of_order":false}
{"run_id":"29526913bab7446286864a321c124486","channel":"market","event_type":"price_change","market":"0x8032d8355d335c6ccbfc2508d99fbc87eb13f437bd275c93ee56fd1558e517ff","asset_id":null,"source":"market_ws:sub:active:1","t_event_ms":1770839724176,"t_recv_wall_ms":1770839724092,"t_recv_wall_iso":"2026-02-11T19:55:24.092Z","t_recv_mono_ns":618589433719791,"raw":{"market":"0x8032d8355d335c6ccbfc2508d99fbc87eb13f437bd275c93ee56fd1558e517ff","price_changes":[{"asset_id":"40652734036737240317526188612064032143639112324786051284480877037991580442979","price":"0.96","size":"3743.17","side":"BUY","hash":"81d443bb062fc585ace1f5668b78b841c7420351","best_bid":"0.97","best_ask":"0.98"},{"asset_id":"20773614133833886322101538939702011175545796528197617633926164254913649353392","price":"0.04","size":"3743.17","side":"SELL","hash":"a2113c4cbd249d690dad5f189787894347736ffc","best_bid":"0.02","best_ask":"0.03"}],"timestamp":"1770839724176","event_type":"price_change","_sub_state":"active","_subscription_id":1,"_active_subscription_id":1},"parse_warnings":[],"out_of_order":false}
{"run_id":"29526913bab7446286864a321c124486","channel":"market","event_type":"price_change","market":"0x8032d8355d335c6ccbfc2508d99fbc87eb13f437bd275c93ee56fd1558e517ff","asset_id":null,"source":"market_ws:sub:active:1","t_event_ms":1770839724183,"t_recv_wall_ms":1770839724093,"t_recv_wall_iso":"2026-02-11T19:55:24.093Z","t_recv_mono_ns":618589433877375,"raw":{"market":"0x8032d8355d335c6ccbfc2508d99fbc87eb13f437bd275c93ee56fd1558e517ff","price_changes":[{"asset_id":"40652734036737240317526188612064032143639112324786051284480877037991580442979","price":"0.83","size":"963.39","side":"BUY","hash":"8ded9261876dff32600207d836a55e1c69d2b3f3","best_bid":"0.97","best_ask":"0.98"},{"asset_id":"20773614133833886322101538939702011175545796528197617633926164254913649353392","price":"0.17","size":"963.39","side":"SELL","hash":"d58e0845fbcc19cc8a5f6438ce78373c24d25a51","best_bid":"0.02","best_ask":"0.03"}],"timestamp":"1770839724183","event_type":"price_change","_sub_state":"active","_subscription_id":1,"_active_subscription_id":1},"parse_warnings":[],"out_of_order":false}
{"run_id":"29526913bab7446286864a321c124486","channel":"market","event_type":"price_change","market":"0x8032d8355d335c6ccbfc2508d99fbc87eb13f437bd275c93ee56fd1558e517ff","asset_id":null,"source":"market_ws:sub:active:1","t_event_ms":1770839724187,"t_recv_wall_ms":1770839724093,"t_recv_wall_iso":"2026-02-11T19:55:24.093Z","t_recv_mono_ns":618589433972125,"raw":{"market":"0x8032d8355d335c6ccbfc2508d99fbc87eb13f437bd275c93ee56fd1558e517ff","price_changes":[{"asset_id":"20773614133833886322101538939702011175545796528197617633926164254913649353392","price":"0.02","size":"8758.72","side":"BUY","hash":"dde3bf123bc8f99136db4fb395e2212538d4697d","best_bid":"0.02","best_ask":"0.03"},{"asset_id":"40652734036737240317526188612064032143639112324786051284480877037991580442979","price":"0.98","size":"8758.72","side":"SELL","hash":"d5f8792f67fd512dcc82035beb278ee9a55686aa","best_bid":"0.97","best_ask":"0.98"}],"timestamp":"1770839724187","event_type":"price_change","_sub_state":"active","_subscription_id":1,"_active_subscription_id":1},"parse_warnings":[],"out_of_order":false}
{"run_id":"29526913bab7446286864a321c124486","channel":"market","event_type":"price_change","market":"0x8032d8355d335c6ccbfc2508d99fbc87eb13f437bd275c93ee56fd1558e517ff","asset_id":null,"source":"market_ws:sub:active:1","t_event_ms":1770839724188,"t_recv_wall_ms":1770839724100,"t_recv_wall_iso":"2026-02-11T19:55:24.100Z","t_recv_mono_ns":618589441734083,"raw":{"market":"0x8032d8355d335c6ccbfc2508d99fbc87eb13f437bd275c93ee56fd1558e517ff","price_changes":[{"asset_id":"40652734036737240317526188612064032143639112324786051284480877037991580442979","price":"0.96","size":"3773.17","side":"BUY","hash":"8487c9f9b6879c9f0e9498b0b522c21f45c19478","best_bid":"0.97","best_ask":"0.98"},{"asset_id":"20773614133833886322101538939702011175545796528197617633926164254913649353392","price":"0.04","size":"3773.17","side":"SELL","hash":"574646dfc05d4e279db305dbd90a60f1094d2ffd","best_bid":"0.02","best_ask":"0.03"}],"timestamp":"1770839724188","event_type":"price_change","_sub_state":"active","_subscription_id":1,"_active_subscription_id":1},"parse_warnings":[],"out_of_order":false}
{"run_id":"29526913bab7446286864a321c124486","channel":"market","event_type":"price_change","market":"0x8032d8355d335c6ccbfc2508d99fbc87eb13f437bd275c93ee56fd1558e517ff","asset_id":null,"source":"market_ws:sub:active:1","t_event_ms":1770839724191,"t_recv_wall_ms":1770839724101,"t_recv_wall_iso":"2026-02-11T19:55:24.101Z","t_recv_mono_ns":618589442029416,"raw":{"market":"0x8032d8355d335c6ccbfc2508d99fbc87eb13f437bd275c93ee56fd1558e517ff","price_changes":[{"asset_id":"40652734036737240317526188612064032143639112324786051284480877037991580442979","price":"0.96","size":"3803.17","side":"BUY","hash":"75388329a442b85625ad1ae7f7b9d483af24d313","best_bid":"0.97","best_ask":"0.98"},{"asset_id":"20773614133833886322101538939702011175545796528197617633926164254913649353392","price":"0.04","size":"3803.17","side":"SELL","hash":"375a92a91e282b1c3d13590e19ff6dfddfc73e0f","best_bid":"0.02","best_ask":"0.03"}],"timestamp":"1770839724191","event_type":"price_change","_sub_state":"active","_subscription_id":1,"_active_subscription_id":1},"parse_warnings":[],"out_of_order":false}
{"run_id":"29526913bab7446286864a321c124486","channel":"market","event_type":"price_change","market":"0x8032d8355d335c6ccbfc2508d99fbc87eb13f437bd275c93ee56fd1558e517ff","asset_id":null,"source":"market_ws:sub:active:1","t_event_ms":1770839724193,"t_recv_wall_ms":1770839724101,"t_recv_wall_iso":"2026-02-11T19:55:24.101Z","t_recv_mono_ns":618589442166291,"raw":{"market":"0x8032d8355d335c6ccbfc2508d99fbc87eb13f437bd275c93ee56fd1558e517ff","price_changes":[{"asset_id":"40652734036737240317526188612064032143639112324786051284480877037991580442979","price":"0.96","size":"3798.17","side":"BUY","hash":"a83cbc9f85a1b6199046d7f0bff0e3a496544190","best_bid":"0.97","best_ask":"0.98"},{"asset_id":"20773614133833886322101538939702011175545796528197617633926164254913649353392","price":"0.04","size":"3798.17","side":"SELL","hash":"5c9e358581570b63a48475e6f7ba14fb2ea272b5","best_bid":"0.02","best_ask":"0.03"}],"timestamp":"1770839724193","event_type":"price_change","_sub_state":"active","_subscription_id":1,"_active_subscription_id":1},"parse_warnings":[],"out_of_order":false}
{"run_id":"29526913bab7446286864a321c124486","channel":"market","event_type":"price_change","market":"0x8032d8355d335c6ccbfc2508d99fbc87eb13f437bd275c93ee56fd1558e517ff","asset_id":null,"source":"market_ws:sub:active:1","t_event_ms":1770839724196,"t_recv_wall_ms":1770839724102,"t_recv_wall_iso":"2026-02-11T19:55:24.102Z","t_recv_mono_ns":618589443362500,"raw":{"market":"0x8032d8355d335c6ccbfc2508d99fbc87eb13f437bd275c93ee56fd1558e517ff","price_changes":[{"asset_id":"40652734036737240317526188612064032143639112324786051284480877037991580442979","price":"0.96","size":"3828.17","side":"BUY","hash":"a9ff329ae0e472d4e71978ab1012999a8d1cf3bf","best_bid":"0.97","best_ask":"0.98"},{"asset_id":"20773614133833886322101538939702011175545796528197617633926164254913649353392","price":"0.04","size":"3828.17","side":"SELL","hash":"727b5eb9af7174e532f11590bd7d50fccd099645","best_bid":"0.02","best_ask":"0.03"}],"timestamp":"1770839724196","event_type":"price_change","_sub_state":"active","_subscription_id":1,"_active_subscription_id":1},"parse_warnings":[],"out_of_order":false}
{"run_id":"29526913bab7446286864a321c124486","channel":"market","event_type":"price_change","market":"0x8032d8355d335c6ccbfc2508d99fbc87eb13f437bd275c93ee56fd1558e517ff","asset_id":null,"source":"market_ws:sub:active:1","t_event_ms":1770839724204,"t_recv_wall_ms":1770839724115,"t_recv_wall_iso":"2026-02-11T19:55:24.115Z","t_recv_mono_ns":618589456511916,"raw":{"market":"0x8032d8355d335c6ccbfc2508d99fbc87eb13f437bd275c93ee56fd1558e517ff","price_changes":[{"asset_id":"20773614133833886322101538939702011175545796528197617633926164254913649353392","price":"0.01","size":"30864.91","side":"BUY","hash":"c7c0c48f907a1a5f488259d77ebf3cdd03c1bbba","best_bid":"0.02","best_ask":"0.03"},{"asset_id":"40652734036737240317526188612064032143639112324786051284480877037991580442979","price":"0.99","size":"30864.91","side":"SELL","hash":"613aeb28e18d54b9b81375bd95eada179eaaed79","best_bid":"0.97","best_ask":"0.98"}],"timestamp":"1770839724204","event_type":"price_change","_sub_state":"active","_subscription_id":1,"_active_subscription_id":1},"parse_warnings":[],"out_of_order":false}
{"run_id":"29526913bab7446286864a321c124486","channel":"market","event_type":"price_change","market":"0x8032d8355d335c6ccbfc2508d99fbc87eb13f437bd275c93ee56fd1558e517ff","asset_id":null,"source":"market_ws:sub:active:1","t_event_ms":1770839724266,"t_recv_wall_ms":1770839724180,"t_recv_wall_iso":"2026-02-11T19:55:24.180Z","t_recv_mono_ns":618589521341666,"raw":{"market":"0x8032d8355d335c6ccbfc2508d99fbc87eb13f437bd275c93ee56fd1558e517ff","price_changes":[{"asset_id":"20773614133833886322101538939702011175545796528197617633926164254913649353392","price":"0.02","size":"8755.68","side":"BUY","hash":"6afbee0a4ee0d286a82fdb63410a20c60ad7a69f","best_bid":"0.02","best_ask":"0.03"},{"asset_id":"40652734036737240317526188612064032143639112324786051284480877037991580442979","price":"0.98","size":"8755.68","side":"SELL","hash":"1dfe2b87841231c8f9e3c656da5d1e768f8c51bf","best_bid":"0.97","best_ask":"0.98"}],"timestamp":"1770839724266","event_type":"price_change","_sub_state":"active","_subscription_id":1,"_active_subscription_id":1},"parse_warnings":[],"out_of_order":false}
{"run_id":"29526913bab7446286864a321c124486","channel":"market","event_type":"book","market":"0x8032d8355d335c6ccbfc2508d99fbc87eb13f437bd275c93ee56fd1558e517ff","asset_id":"20773614133833886322101538939702011175545796528197617633926164254913649353392","source":"market_ws:sub:active:1","t_event_ms":1770839724266,"t_recv_wall_ms":1770839724180,"t_recv_wall_iso":"2026-02-11T19:55:24.180Z","t_recv_mono_ns":618589521708041,"raw":{"market":"0x8032d8355d335c6ccbfc2508d99fbc87eb13f437bd275c93ee56fd1558e517ff","asset_id":"20773614133833886322101538939702011175545796528197617633926164254913649353392","bids":[{"price":"0.01","size":"30864.91"},{"price":"0.02","size":"8755.68"}],"asks":[{"price":"0.99","size":"30822.26"},{"price":"0.98","size":"12559.04"},{"price":"0.97","size":"7433.03"},{"price":"0.96","size":"5453.8"},{"price":"0.95","size":"6815.8"},{"price":"0.94","size":"5105"},{"price":"0.93","size":"5421.38"},{"price":"0.92","size":"5139.4"},{"price":"0.91","size":"5225.8"},{"price":"0.9","size":"5102.8"},{"price":"0.89","size":"120.6"},{"price":"0.88","size":"63.6"},{"price":"0.87","size":"63"},{"price":"0.86","size":"61.6"},{"price":"0.85","size":"107.39"},{"price":"0.84","size":"69.39"},{"price":"0.83","size":"58.39"},{"price":"0.82","size":"66.71"},{"price":"0.81","size":"56.8"},{"price":"0.8","size":"92.14"},{"price":"0.79","size":"60.8"},{"price":"0.78","size":"55.2"},{"price":"0.77","size":"64.48"},{"price":"0.76","size":"54.2"},{"price":"0.75","size":"375.8"},{"price":"0.74","size":"68.6"},{"price":"0.73","size":"53.2"},{"price":"0.72","size":"63.26"},{"price":"0.71","size":"52.6"},{"price":"0.7","size":"402.4"},{"price":"0.69","size":"72.2"},{"price":"0.68","size":"87.88"},{"price":"0.67","size":"188.46"},{"price":"0.66","size":"123.6"},{"price":"0.65","size":"317.03"},{"price":"0.64","size":"582.36"},{"price":"0.63","size":"559.2"},{"price":"0.62","size":"559"},{"price":"0.61","size":"594"},{"price":"0.6","size":"2915.41"},{"price":"0.59","size":"576.8"},{"price":"0.58","size":"575.5"},{"price":"0.57","size":"558.6"},{"price":"0.56","size":"572.68"},{"price":"0.55","size":"566.4"},{"price":"0.54","size":"561.94"},{"price":"0.53","size":"631.57"},{"price":"0.52","size":"611.4"},{"price":"0.51","size":"705.2"},{"price":"0.5","size":"1011.55"},{"price":"0.49","size":"692.4"},{"price":"0.48","size":"628.4"},{"price":"0.47","size":"633.4"},{"price":"0.46","size":"711.65"},{"price":"0.45","size":"866.59"},{"price":"0.44","size":"905.69"},{"price":"0.43","size":"641.6"},{"price":"0.42","size":"645.58"},{"price":"0.41","size":"564"},{"price":"0.4","size":"20642.9"},{"price":"0.39","size":"650.23"},{"price":"0.38","size":"593"},{"price":"0.37","size":"755.73"},{"price":"0.36","size":"558"},{"price":"0.35","size":"1144.32"},{"price":"0.34","size":"649.59"},{"price":"0.33","size":"624.8"},{"price":"0.32","size":"574"},{"price":"0.31","size":"594.2"},{"price":"0.3","size":"735.66"},{"price":"0.29","size":"924.6"},{"price":"0.28","size":"356.8"},{"price":"0.27","size":"869.2"},{"price":"0.26","size":"967.6"},{"price":"0.25","size":"1673.8"},{"price":"0.24","size":"869.2"},{"price":"0.23","size":"864.6"},{"price":"0.22","size":"870.2"},{"price":"0.21","size":"871.6"},{"price":"0.2","size":"987.2"},{"price":"0.19","size":"876.8"},{"price":"0.18","size":"1091.55"},{"price":"0.17","size":"963.39"},{"price":"0.16","size":"1119.39"},{"price":"0.15","size":"1149.13"},{"price":"0.14","size":"962.6"},{"price":"0.13","size":"1041.8"},{"price":"0.12","size":"1060.55"},{"price":"0.11","size":"1124.49"},{"price":"0.1","size":"1291.79"},{"price":"0.09","size":"589.6"},{"price":"0.08","size":"3384.35"},{"price":"0.07","size":"3360.43"},{"price":"0.06","size":"3220.34"},{"price":"0.05","size":"3164.45"},{"price":"0.04","size":"3828.17"},{"price":"0.03","size":"632.82"}],"hash":"6afbee0a4ee0d286a82fdb63410a20c60ad7a69f","timestamp":"1770839724266","event_type":"book","_sub_state":"active","_subscription_id":1,"_active_subscription_id":1},"parse_warnings":[],"out_of_order":false}
{"run_id":"29526913bab7446286864a321c124486","channel":"market","event_type":"book","market":"0x8032d8355d335c6ccbfc2508d99fbc87eb13f437bd275c93ee56fd1558e517ff","asset_id":"40652734036737240317526188612064032143639112324786051284480877037991580442979","source":"market_ws:sub:active:1","t_event_ms":1770839724266,"t_recv_wall_ms":1770839724181,"t_recv_wall_iso":"2026-02-11T19:55:24.181Z","t_recv_mono_ns":618589522718416,"raw":{"market":"0x8032d8355d335c6ccbfc2508d99fbc87eb13f437bd275c93ee56fd1558e517ff","asset_id":"40652734036737240317526188612064032143639112324786051284480877037991580442979","bids":[{"price":"0.01","size":"30822.26"},{"price":"0.02","size":"12559.04"},{"price":"0.03","size":"7433.03"},{"price":"0.04","size":"5453.8"},{"price":"0.05","size":"6815.8"},{"price":"0.06","size":"5105"},{"price":"0.07","size":"5421.38"},{"price":"0.08","size":"5139.4"},{"price":"0.09","size":"5225.8"},{"price":"0.1","size":"5102.8"},{"price":"0.11","size":"120.6"},{"price":"0.12","size":"63.6"},{"price":"0.13","size":"63"},{"price":"0.14","size":"61.6"},{"price":"0.15","size":"107.39"},{"price":"0.16","size":"69.39"},{"price":"0.17","size":"58.39"},{"price":"0.18","size":"66.71"},{"price":"0.19","size":"56.8"},{"price":"0.2","size":"92.14"},{"price":"0.21","size":"60.8"},{"price":"0.22","size":"55.2"},{"price":"0.23","size":"64.48"},{"price":"0.24","size":"54.2"},{"price":"0.25","size":"375.8"},{"price":"0.26","size":"68.6"},{"price":"0.27","size":"53.2"},{"price":"0.28","size":"63.26"},{"price":"0.29","size":"52.6"},{"price":"0.3","size":"402.4"},{"price":"0.31","size":"72.2"},{"price":"0.32","size":"87.88"},{"price":"0.33","size":"188.46"},{"price":"0.34","size":"123.6"},{"price":"0.35","size":"317.03"},{"price":"0.36","size":"582.36"},{"price":"0.37","size":"559.2"},{"price":"0.38","size":"559"},{"price":"0.39","size":"594"},{"price":"0.4","size":"2915.41"},{"price":"0.41","size":"576.8"},{"price":"0.42","size":"575.5"},{"price":"0.43","size":"558.6"},{"price":"0.44","size":"572.68"},{"price":"0.45","size":"566.4"},{"price":"0.46","size":"561.94"},{"price":"0.47","size":"631.57"},{"price":"0.48","size":"611.4"},{"price":"0.49","size":"705.2"},{"price":"0.5","size":"1011.55"},{"price":"0.51","size":"692.4"},{"price":"0.52","size":"628.4"},{"price":"0.53","size":"633.4"},{"price":"0.54","size":"711.65"},{"price":"0.55","size":"866.59"},{"price":"0.56","size":"905.69"},{"price":"0.57","size":"641.6"},{"price":"0.58","size":"645.58"},{"price":"0.59","size":"564"},{"price":"0.6","size":"20642.9"},{"price":"0.61","size":"650.23"},{"price":"0.62","size":"593"},{"price":"0.63","size":"755.73"},{"price":"0.64","size":"558"},{"price":"0.65","size":"1144.32"},{"price":"0.66","size":"649.59"},{"price":"0.67","size":"624.8"},{"price":"0.68","size":"574"},{"price":"0.69","size":"594.2"},{"price":"0.7","size":"735.66"},{"price":"0.71","size":"924.6"},{"price":"0.72","size":"356.8"},{"price":"0.73","size":"869.2"},{"price":"0.74","size":"967.6"},{"price":"0.75","size":"1673.8"},{"price":"0.76","size":"869.2"},{"price":"0.77","size":"864.6"},{"price":"0.78","size":"870.2"},{"price":"0.79","size":"871.6"},{"price":"0.8","size":"987.2"},{"price":"0.81","size":"876.8"},{"price":"0.82","size":"1091.55"},{"price":"0.83","size":"963.39"},{"price":"0.84","size":"1119.39"},{"price":"0.85","size":"1149.13"},{"price":"0.86","size":"962.6"},{"price":"0.87","size":"1041.8"},{"price":"0.88","size":"1060.55"},{"price":"0.89","size":"1124.49"},{"price":"0.9","size":"1291.79"},{"price":"0.91","size":"589.6"},{"price":"0.92","size":"3384.35"},{"price":"0.93","size":"3360.43"},{"price":"0.94","size":"3220.34"},{"price":"0.95","size":"3164.45"},{"price":"0.96","size":"3828.17"},{"price":"0.97","size":"632.82"}],"asks":[{"price":"0.99","size":"30864.91"},{"price":"0.98","size":"8755.68"}],"hash":"1dfe2b87841231c8f9e3c656da5d1e768f8c51bf","timestamp":"1770839724266","event_type":"book","_sub_state":"active","_subscription_id":1,"_active_subscription_id":1},"parse_warnings":[],"out_of_order":false}
{"run_id":"29526913bab7446286864a321c124486","channel":"market","event_type":"price_change","market":"0x8032d8355d335c6ccbfc2508d99fbc87eb13f437bd275c93ee56fd1558e517ff","asset_id":null,"source":"market_ws:sub:active:1","t_event_ms":1770839724271,"t_recv_wall_ms":1770839724182,"t_recv_wall_iso":"2026-02-11T19:55:24.182Z","t_recv_mono_ns":618589523509208,"raw":{"market":"0x8032d8355d335c6ccbfc2508d99fbc87eb13f437bd275c93ee56fd1558e517ff","price_changes":[{"asset_id":"40652734036737240317526188612064032143639112324786051284480877037991580442979","price":"0.96","size":"3843.17","side":"BUY","hash":"0ee3a8acbf605d3bdb037c880cd177a0d570c109","best_bid":"0.97","best_ask":"0.98"},{"asset_id":"20773614133833886322101538939702011175545796528197617633926164254913649353392","price":"0.04","size":"3843.17","side":"SELL","hash":"bab5edb583b1edca903ffe54a7e8da80e96ec945","best_bid":"0.02","best_ask":"0.03"}],"timestamp":"1770839724271","event_type":"price_change","_sub_state":"active","_subscription_id":1,"_active_subscription_id":1},"parse_warnings":[],"out_of_order":false}
{"run_id":"29526913bab7446286864a321c124486","channel":"market","event_type":"price_change","market":"0x8032d8355d335c6ccbfc2508d99fbc87eb13f437bd275c93ee56fd1558e517ff","asset_id":null,"source":"market_ws:sub:active:1","t_event_ms":1770839724275,"t_recv_wall_ms":1770839724183,"t_recv_wall_iso":"2026-02-11T19:55:24.183Z","t_recv_mono_ns":618589523815750,"raw":{"market":"0x8032d8355d335c6ccbfc2508d99fbc87eb13f437bd275c93ee56fd1558e517ff","price_changes":[{"asset_id":"40652734036737240317526188612064032143639112324786051284480877037991580442979","price":"0.97","size":"637.82","side":"BUY","hash":"d8e8bae240fe1e46f39c3ee2efad63b20386f880","best_bid":"0.97","best_ask":"0.98"},{"asset_id":"20773614133833886322101538939702011175545796528197617633926164254913649353392","price":"0.03","size":"637.82","side":"SELL","hash":"a0fa6179db96bff0305de1f05adf791b88c5e23d","best_bid":"0.02","best_ask":"0.03"}],"timestamp":"1770839724275","event_type":"price_change","_sub_state":"active","_subscription_id":1,"_active_subscription_id":1},"parse_warnings":[],"out_of_order":false}
{"run_id":"29526913bab7446286864a321c124486","channel":"market","event_type":"price_change","market":"0x8032d8355d335c6ccbfc2508d99fbc87eb13f437bd275c93ee56fd1558e517ff","asset_id":null,"source":"market_ws:sub:active:1","t_event_ms":1770839724278,"t_recv_wall_ms":1770839724183,"t_recv_wall_iso":"2026-02-11T19:55:24.183Z","t_recv_mono_ns":618589524420041,"raw":{"market":"0x8032d8355d335c6ccbfc2508d99fbc87eb13f437bd275c93ee56fd1558e517ff","price_changes":[{"asset_id":"40652734036737240317526188612064032143639112324786051284480877037991580442979","price":"0.71","size":"624.6","side":"BUY","hash":"8bb45144b4a200c9a09b5e8ade130e46ae726742","best_bid":"0.97","best_ask":"0.98"},{"asset_id":"20773614133833886322101538939702011175545796528197617633926164254913649353392","price":"0.29","size":"624.6","side":"SELL","hash":"5dfe86a4417087be60380ef7f56942f908b897fd","best_bid":"0.02","best_ask":"0.03"}],"timestamp":"1770839724278","event_type":"price_change","_sub_state":"active","_subscription_id":1,"_active_subscription_id":1},"parse_warnings":[],"out_of_order":false}
{"run_id":"29526913bab7446286864a321c124486","channel":"market","event_type":"price_change","market":"0x8032d8355d335c6ccbfc2508d99fbc87eb13f437bd275c93ee56fd1558e517ff","asset_id":null,"source":"market_ws:sub:active:1","t_event_ms":1770839724285,"t_recv_wall_ms":1770839724192,"t_recv_wall_iso":"2026-02-11T19:55:24.192Z","t_recv_mono_ns":618589533723375,"raw":{"market":"0x8032d8355d335c6ccbfc2508d99fbc87eb13f437bd275c93ee56fd1558e517ff","price_changes":[{"asset_id":"40652734036737240317526188612064032143639112324786051284480877037991580442979","price":"0.83","size":"958.39","side":"BUY","hash":"c7094ae93584edbb7d5e65b22e195c7245730f25","best_bid":"0.97","best_ask":"0.98"},{"asset_id":"20773614133833886322101538939702011175545796528197617633926164254913649353392","price":"0.17","size":"958.39","side":"SELL","hash":"e5744373f6dfda2bb154f4f5a702d400adb8cf89","best_bid":"0.02","best_ask":"0.03"}],"timestamp":"1770839724285","event_type":"price_change","_sub_state":"active","_subscription_id":1,"_active_subscription_id":1},"parse_warnings":[],"out_of_order":false}
{"run_id":"29526913bab7446286864a321c124486","channel":"market","event_type":"last_trade_price","market":"0x8032d8355d335c6ccbfc2508d99fbc87eb13f437bd275c93ee56fd1558e517ff","asset_id":"40652734036737240317526188612064032143639112324786051284480877037991580442979","source":"market_ws:sub:unknown","t_event_ms":1770839724298,"t_recv_wall_ms":1770839724202,"t_recv_wall_iso":"2026-02-11T19:55:24.202Z","t_recv_mono_ns":618589543694000,"raw":{"market":"0x8032d8355d335c6ccbfc2508d99fbc87eb13f437bd275c93ee56fd1558e517ff","asset_id":"40652734036737240317526188612064032143639112324786051284480877037991580442979","price":"0.98","size":"3.04","fee_rate_bps":"1000","side":"BUY","timestamp":"1770839724298","event_type":"last_trade_price","transaction_hash":"0xf0856fc9531f18849809c693c2afe239c1f21680fc6370defd0474528b119427","_sub_state":"unknown","_subscription_id":null,"_active_subscription_id":1},"parse_warnings":["unknown_message_schema"],"out_of_order":false}
{"run_id":"29526913bab7446286864a321c124486","channel":"market","event_type":"price_change","market":"0x8032d8355d335c6ccbfc2508d99fbc87eb13f437bd275c93ee56fd1558e517ff","asset_id":null,"source":"market_ws:sub:active:1","t_event_ms":1770839724314,"t_recv_wall_ms":1770839724220,"t_recv_wall_iso":"2026-02-11T19:55:24.220Z","t_recv_mono_ns":618589560973291,"raw":{"market":"0x8032d8355d335c6ccbfc2508d99fbc87eb13f437bd275c93ee56fd1558e517ff","price_changes":[{"asset_id":"40652734036737240317526188612064032143639112324786051284480877037991580442979","price":"0.97","size":"642.82","side":"BUY","hash":"ef74638d0081595aab475beaabcae3d66eba512a","best_bid":"0.97","best_ask":"0.98"},{"asset_id":"20773614133833886322101538939702011175545796528197617633926164254913649353392","price":"0.03","size":"642.82","side":"SELL","hash":"d46c90f413f7ba3ed08798c777a191d24d8cef39","best_bid":"0.02","best_ask":"0.03"}],"timestamp":"1770839724314","event_type":"price_change","_sub_state":"active","_subscription_id":1,"_active_subscription_id":1},"parse_warnings":[],"out_of_order":false}
{"run_id":"29526913bab7446286864a321c124486","channel":"market","event_type":"price_change","market":"0x8032d8355d335c6ccbfc2508d99fbc87eb13f437bd275c93ee56fd1558e517ff","asset_id":null,"source":"market_ws:sub:active:1","t_event_ms":1770839724324,"t_recv_wall_ms":1770839724235,"t_recv_wall_iso":"2026-02-11T19:55:24.235Z","t_recv_mono_ns":618589575931458,"raw":{"market":"0x8032d8355d335c6ccbfc2508d99fbc87eb13f437bd275c93ee56fd1558e517ff","price_changes":[{"asset_id":"40652734036737240317526188612064032143639112324786051284480877037991580442979","price":"0.94","size":"3215.34","side":"BUY","hash":"ff5160b5ec576b3b51fbb85fed3e3706579413b2","best_bid":"0.97","best_ask":"0.98"},{"asset_id":"20773614133833886322101538939702011175545796528197617633926164254913649353392","price":"0.06","size":"3215.34","side":"SELL","hash":"2d70f8c2024aed2d31ded66b6d26aaf709ca920b","best_bid":"0.02","best_ask":"0.03"}],"timestamp":"1770839724324","event_type":"price_change","_sub_state":"active","_subscription_id":1,"_active_subscription_id":1},"parse_warnings":[],"out_of_order":false}
{"run_id":"29526913bab7446286864a321c124486","channel":"market","event_type":"price_change","market":"0x8032d8355d335c6ccbfc2508d99fbc87eb13f437bd275c93ee56fd1558e517ff","asset_id":null,"source":"market_ws:sub:active:1","t_event_ms":1770839724351,"t_recv_wall_ms":1770839724255,"t_recv_wall_iso":"2026-02-11T19:55:24.255Z","t_recv_mono_ns":618589596392250,"raw":{"market":"0x8032d8355d335c6ccbfc2508d99fbc87eb13f437bd275c93ee56fd1558e517ff","price_changes":[{"asset_id":"20773614133833886322101538939702011175545796528197617633926164254913649353392","price":"0.02","size":"8851.68","side":"BUY","hash":"3a084e5ea2b5a76f1350126b2748415b0ad076ac","best_bid":"0.02","best_ask":"0.03"},{"asset_id":"40652734036737240317526188612064032143639112324786051284480877037991580442979","price":"0.98","size":"8851.68","side":"SELL","hash":"b15cbdd88a307a0d74fe5f8dc63ba19ac72f0e80","best_bid":"0.97","best_ask":"0.98"}],"timestamp":"1770839724351","event_type":"price_change","_sub_state":"active","_subscription_id":1,"_active_subscription_id":1},"parse_warnings":[],"out_of_order":false}
{"run_id":"29526913bab7446286864a321c124486","channel":"market","event_type":"price_change","market":"0x8032d8355d335c6ccbfc2508d99fbc87eb13f437bd275c93ee56fd1558e517ff","asset_id":null,"source":"market_ws:sub:active:1","t_event_ms":1770839724353,"t_recv_wall_ms":1770839724259,"t_recv_wall_iso":"2026-02-11T19:55:24.259Z","t_recv_mono_ns":618589600471541,"raw":{"market":"0x8032d8355d335c6ccbfc2508d99fbc87eb13f437bd275c93ee56fd1558e517ff","price_changes":[{"asset_id":"40652734036737240317526188612064032143639112324786051284480877037991580442979","price":"0.95","size":"3230.45","side":"BUY","hash":"28c72ea87a11bf0c76ad84fa5f59f89b8d5df7e5","best_bid":"0.97","best_ask":"0.98"},{"asset_id":"20773614133833886322101538939702011175545796528197617633926164254913649353392","price":"0.05","size":"3230.45","side":"SELL","hash":"aad79328c5cc11f39ae1b669003929b8ab0da7f3","best_bid":"0.02","best_ask":"0.03"}],"timestamp":"1770839724353","event_type":"price_change","_sub_state":"active","_subscription_id":1,"_active_subscription_id":1},"parse_warnings":[],"out_of_order":false}
{"run_id":"29526913bab7446286864a321c124486","channel":"market","event_type":"price_change","market":"0x8032d8355d335c6ccbfc2508d99fbc87eb13f437bd275c93ee56fd1558e517ff","asset_id":null,"source":"market_ws:sub:active:1","t_event_ms":1770839724356,"t_recv_wall_ms":1770839724268,"t_recv_wall_iso":"2026-02-11T19:55:24.268Z","t_recv_mono_ns":618589608784041,"raw":{"market":"0x8032d8355d335c6ccbfc2508d99fbc87eb13f437bd275c93ee56fd1558e517ff","price_changes":[{"asset_id":"40652734036737240317526188612064032143639112324786051284480877037991580442979","price":"0.96","size":"3777.17","side":"BUY","hash":"61fc8640509789e077daf2ff689b68ba0a77d35c","best_bid":"0.97","best_ask":"0.98"},{"asset_id":"20773614133833886322101538939702011175545796528197617633926164254913649353392","price":"0.04","size":"3777.17","side":"SELL","hash":"ccec39001bfbc855cd99ba4328616023eef31bf8","best_bid":"0.02","best_ask":"0.03"}],"timestamp":"1770839724356","event_type":"price_change","_sub_state":"active","_subscription_id":1,"_active_subscription_id":1},"parse_warnings":[],"out_of_order":false}
{"run_id":"29526913bab7446286864a321c124486","channel":"market","event_type":"price_change","market":"0x8032d8355d335c6ccbfc2508d99fbc87eb13f437bd275c93ee56fd1558e517ff","asset_id":null,"source":"market_ws:sub:active:1","t_event_ms":1770839724359,"t_recv_wall_ms":1770839724268,"t_recv_wall_iso":"2026-02-11T19:55:24.268Z","t_recv_mono_ns":618589609076583,"raw":{"market":"0x8032d8355d335c6ccbfc2508d99fbc87eb13f437bd275c93ee56fd1558e517ff","price_changes":[{"asset_id":"20773614133833886322101538939702011175545796528197617633926164254913649353392","price":"0.02","size":"8791.68","side":"BUY","hash":"68195e36c0b799df7ff6734576b8d324ded72432","best_bid":"0.02","best_ask":"0.03"},{"asset_id":"40652734036737240317526188612064032143639112324786051284480877037991580442979","price":"0.98","size":"8791.68","side":"SELL","hash":"46728f04edb99a61a7dd7e0232f23f1d52a29ff0","best_bid":"0.97","best_ask":"0.98"}],"timestamp":"1770839724359","event_type":"price_change","_sub_state":"active","_subscription_id":1,"_active_subscription_id":1},"parse_warnings":[],"out_of_order":false}
{"run_id":"29526913bab7446286864a321c124486","channel":"market","event_type":"price_change","market":"0x8032d8355d335c6ccbfc2508d99fbc87eb13f437bd275c93ee56fd1558e517ff","asset_id":null,"source":"market_ws:sub:active:1","t_event_ms":1770839724360,"t_recv_wall_ms":1770839724268,"t_recv_wall_iso":"2026-02-11T19:55:24.268Z","t_recv_mono_ns":618589609185416,"raw":{"market":"0x8032d8355d335c6ccbfc2508d99fbc87eb13f437bd275c93ee56fd1558e517ff","price_changes":[{"asset_id":"20773614133833886322101538939702011175545796528197617633926164254913649353392","price":"0.01","size":"30924.91","side":"BUY","hash":"da634057ef5e5d91f0bd0efc09de2f444e5c810a","best_bid":"0.02","best_ask":"0.03"},{"asset_id":"40652734036737240317526188612064032143639112324786051284480877037991580442979","price":"0.99","size":"30924.91","side":"SELL","hash":"aac6bab95bca06c43591ae2b740c11eb476dd730","best_bid":"0.97","best_ask":"0.98"}],"timestamp":"1770839724360","event_type":"price_change","_sub_state":"active","_subscription_id":1,"_active_subscription_id":1},"parse_warnings":[],"out_of_order":false}
{"run_id":"29526913bab7446286864a321c124486","channel":"market","event_type":"price_change","market":"0x8032d8355d335c6ccbfc2508d99fbc87eb13f437bd275c93ee56fd1558e517ff","asset_id":null,"source":"market_ws:sub:active:1","t_event_ms":1770839724361,"t_recv_wall_ms":1770839724268,"t_recv_wall_iso":"2026-02-11T19:55:24.268Z","t_recv_mono_ns":618589609282708,"raw":{"market":"0x8032d8355d335c6ccbfc2508d99fbc87eb13f437bd275c93ee56fd1558e517ff","price_changes":[{"asset_id":"40652734036737240317526188612064032143639112324786051284480877037991580442979","price":"0.96","size":"3762.17","side":"BUY","hash":"957390b4f332827417b34a4fa3344b9cdcbfa8d6","best_bid":"0.97","best_ask":"0.98"},{"asset_id":"20773614133833886322101538939702011175545796528197617633926164254913649353392","price":"0.04","size":"3762.17","side":"SELL","hash":"457d6c8552e3301950ee6d861c1ce0b729b7dd68","best_bid":"0.02","best_ask":"0.03"}],"timestamp":"1770839724361","event_type":"price_change","_sub_state":"active","_subscription_id":1,"_active_subscription_id":1},"parse_warnings":[],"out_of_order":false}
{"run_id":"29526913bab7446286864a321c124486","channel":"market","event_type":"price_change","market":"0x8032d8355d335c6ccbfc2508d99fbc87eb13f437bd275c93ee56fd1558e517ff","asset_id":null,"source":"market_ws:sub:active:1","t_event_ms":1770839724364,"t_recv_wall_ms":1770839724269,"t_recv_wall_iso":"2026-02-11T19:55:24.269Z","t_recv_mono_ns":618589610110916,"raw":{"market":"0x8032d8355d335c6ccbfc2508d99fbc87eb13f437bd275c93ee56fd1558e517ff","price_changes":[{"asset_id":"40652734036737240317526188612064032143639112324786051284480877037991580442979","price":"0.96","size":"3822.17","side":"BUY","hash":"9c37d320d698b76b3ad0de72c899a37eb99e611d","best_bid":"0.97","best_ask":"0.98"},{"asset_id":"20773614133833886322101538939702011175545796528197617633926164254913649353392","price":"0.04","size":"3822.17","side":"SELL","hash":"328a3dedbab4c576d6e3591495bffbe79adb0068","best_bid":"0.02","best_ask":"0.03"}],"timestamp":"1770839724364","event_type":"price_change","_sub_state":"active","_subscription_id":1,"_active_subscription_id":1},"parse_warnings":[],"out_of_order":false}
{"run_id":"29526913bab7446286864a321c124486","channel":"market","event_type":"price_change","market":"0x8032d8355d335c6ccbfc2508d99fbc87eb13f437bd275c93ee56fd1558e517ff","asset_id":null,"source":"market_ws:sub:active:1","t_event_ms":1770839724367,"t_recv_wall_ms":1770839724271,"t_recv_wall_iso":"2026-02-11T19:55:24.271Z","t_recv_mono_ns":618589612411208,"raw":{"market":"0x8032d8355d335c6ccbfc2508d99fbc87eb13f437bd275c93ee56fd1558e517ff","price_changes":[{"asset_id":"40652734036737240317526188612064032143639112324786051284480877037991580442979","price":"0.95","size":"3170.45","side":"BUY","hash":"ae594fed37bd9de4ab7e5f941a17daf047450c75","best_bid":"0.97","best_ask":"0.98"},{"asset_id":"20773614133833886322101538939702011175545796528197617633926164254913649353392","price":"0.05","size":"3170.45","side":"SELL","hash":"6c0c5c2b149bdec9d94762ec63509334ecb38942","best_bid":"0.02","best_ask":"0.03"}],"timestamp":"1770839724367","event_type":"price_change","_sub_state":"active","_subscription_id":1,"_active_subscription_id":1},"parse_warnings":[],"out_of_order":false}
{"run_id":"29526913bab7446286864a321c124486","channel":"market","event_type":"price_change","market":"0x8032d8355d335c6ccbfc2508d99fbc87eb13f437bd275c93ee56fd1558e517ff","asset_id":null,"source":"market_ws:sub:active:1","t_event_ms":1770839724376,"t_recv_wall_ms":1770839724282,"t_recv_wall_iso":"2026-02-11T19:55:24.282Z","t_recv_mono_ns":618589623016333,"raw":{"market":"0x8032d8355d335c6ccbfc2508d99fbc87eb13f437bd275c93ee56fd1558e517ff","price_changes":[{"asset_id":"40652734036737240317526188612064032143639112324786051284480877037991580442979","price":"0.95","size":"3175.45","side":"BUY","hash":"d6d3ec896650bce515c1e1196171a7431c1f33e5","best_bid":"0.97","best_ask":"0.98"},{"asset_id":"20773614133833886322101538939702011175545796528197617633926164254913649353392","price":"0.05","size":"3175.45","side":"SELL","hash":"5d0ac2c4c77727d78f3225854662915152908c3e","best_bid":"0.02","best_ask":"0.03"}],"timestamp":"1770839724376","event_type":"price_change","_sub_state":"active","_subscription_id":1,"_active_subscription_id":1},"parse_warnings":[],"out_of_order":false}
{"run_id":"29526913bab7446286864a321c124486","channel":"market","event_type":"price_change","market":"0x8032d8355d335c6ccbfc2508d99fbc87eb13f437bd275c93ee56fd1558e517ff","asset_id":null,"source":"market_ws:sub:active:1","t_event_ms":1770839724385,"t_recv_wall_ms":1770839724291,"t_recv_wall_iso":"2026-02-11T19:55:24.291Z","t_recv_mono_ns":618589631844916,"raw":{"market":"0x8032d8355d335c6ccbfc2508d99fbc87eb13f437bd275c93ee56fd1558e517ff","price_changes":[{"asset_id":"40652734036737240317526188612064032143639112324786051284480877037991580442979","price":"0.8","size":"1007.2","side":"BUY","hash":"15bb902cc2d0f6fe19e7f9904659da3b72b80d0e","best_bid":"0.97","best_ask":"0.98"},{"asset_id":"20773614133833886322101538939702011175545796528197617633926164254913649353392","price":"0.2","size":"1007.2","side":"SELL","hash":"dcbf1e56d91d8dc618e3f88298535488c111fa94","best_bid":"0.02","best_ask":"0.03"}],"timestamp":"1770839724385","event_type":"price_change","_sub_state":"active","_subscription_id":1,"_active_subscription_id":1},"parse_warnings":[],"out_of_order":false}
{"run_id":"29526913bab7446286864a321c124486","channel":"market","event_type":"price_change","market":"0x8032d8355d335c6ccbfc2508d99fbc87eb13f437bd275c93ee56fd1558e517ff","asset_id":null,"source":"market_ws:sub:active:1","t_event_ms":1770839724388,"t_recv_wall_ms":1770839724292,"t_recv_wall_iso":"2026-02-11T19:55:24.292Z","t_recv_mono_ns":618589633607000,"raw":{"market":"0x8032d8355d335c6ccbfc2508d99fbc87eb13f437bd275c93ee56fd1558e517ff","price_changes":[{"asset_id":"20773614133833886322101538939702011175545796528197617633926164254913649353392","price":"0.01","size":"30894.91","side":"BUY","hash":"aaa2166963d46ab8b1381cf17a6d74d9cc61c289","best_bid":"0.02","best_ask":"0.03"},{"asset_id":"40652734036737240317526188612064032143639112324786051284480877037991580442979","price":"0.99","size":"30894.91","side":"SELL","hash":"a2e5bbde8f6a461f5681b4409846248af5a18a55","best_bid":"0.97","best_ask":"0.98"}],"timestamp":"1770839724388","event_type":"price_change","_sub_state":"active","_subscription_id":1,"_active_subscription_id":1},"parse_warnings":[],"out_of_order":false}
{"run_id":"29526913bab7446286864a321c124486","channel":"market","event_type":"price_change","market":"0x8032d8355d335c6ccbfc2508d99fbc87eb13f437bd275c93ee56fd1558e517ff","asset_id":null,"source":"market_ws:sub:active:1","t_event_ms":1770839724392,"t_recv_wall_ms":1770839724297,"t_recv_wall_iso":"2026-02-11T19:55:24.297Z","t_recv_mono_ns":618589637904833,"raw":{"market":"0x8032d8355d335c6ccbfc2508d99fbc87eb13f437bd275c93ee56fd1558e517ff","price_changes":[{"asset_id":"20773614133833886322101538939702011175545796528197617633926164254913649353392","price":"0.01","size":"30924.91","side":"BUY","hash":"adefb8bd2cab24affedda5ab475cfbd013dca92b","best_bid":"0.02","best_ask":"0.03"},{"asset_id":"40652734036737240317526188612064032143639112324786051284480877037991580442979","price":"0.99","size":"30924.91","side":"SELL","hash":"81097756efbfa4c7a37501228afd771cd11a6f3d","best_bid":"0.97","best_ask":"0.98"}],"timestamp":"1770839724392","event_type":"price_change","_sub_state":"active","_subscription_id":1,"_active_subscription_id":1},"parse_warnings":[],"out_of_order":false}
{"run_id":"29526913bab7446286864a321c124486","channel":"market","event_type":"price_change","market":"0x8032d8355d335c6ccbfc2508d99fbc87eb13f437bd275c93ee56fd1558e517ff","asset_id":null,"source":"market_ws:sub:active:1","t_event_ms":1770839724394,"t_recv_wall_ms":1770839724309,"t_recv_wall_iso":"2026-02-11T19:55:24.309Z","t_recv_mono_ns":618589649763625,"raw":{"market":"0x8032d8355d335c6ccbfc2508d99fbc87eb13f437bd275c93ee56fd1558e517ff","price_changes":[{"asset_id":"40652734036737240317526188612064032143639112324786051284480877037991580442979","price":"0.82","size":"1096.55","side":"BUY","hash":"232ec9416e8baf51c088d6a893d6b3a98794047e","best_bid":"0.97","best_ask":"0.98"},{"asset_id":"20773614133833886322101538939702011175545796528197617633926164254913649353392","price":"0.18","size":"1096.55","side":"SELL","hash":"4ef442183db3c0ae2102d0f0f34feea002aa3cd4","best_bid":"0.02","best_ask":"0.03"}],"timestamp":"1770839724394","event_type":"price_change","_sub_state":"active","_subscription_id":1,"_active_subscription_id":1},"parse_warnings":[],"out_of_order":false}
{"run_id":"29526913bab7446286864a321c124486","channel":"market","event_type":"price_change","market":"0x8032d8355d335c6ccbfc2508d99fbc87eb13f437bd275c93ee56fd1558e517ff","asset_id":null,"source":"market_ws:sub:active:1","t_event_ms":1770839724399,"t_recv_wall_ms":1770839724309,"t_recv_wall_iso":"2026-02-11T19:55:24.309Z","t_recv_mono_ns":618589650166291,"raw":{"market":"0x8032d8355d335c6ccbfc2508d99fbc87eb13f437bd275c93ee56fd1558e517ff","price_changes":[{"asset_id":"20773614133833886322101538939702011175545796528197617633926164254913649353392","price":"0.02","size":"8846.68","side":"BUY","hash":"e111acda444f779a36e310926296253c939dca2b","best_bid":"0.02","best_ask":"0.03"},{"asset_id":"40652734036737240317526188612064032143639112324786051284480877037991580442979","price":"0.98","size":"8846.68","side":"SELL","hash":"b4c45e164ce6b4b5b0625152c5f3b99f817ba6d9","best_bid":"0.97","best_ask":"0.98"}],"timestamp":"1770839724399","event_type":"price_change","_sub_state":"active","_subscription_id":1,"_active_subscription_id":1},"parse_warnings":[],"out_of_order":false}
{"run_id":"29526913bab7446286864a321c124486","channel":"market","event_type":"price_change","market":"0x8032d8355d335c6ccbfc2508d99fbc87eb13f437bd275c93ee56fd1558e517ff","asset_id":null,"source":"market_ws:sub:active:1","t_event_ms":1770839724405,"t_recv_wall_ms":1770839724316,"t_recv_wall_iso":"2026-02-11T19:55:24.316Z","t_recv_mono_ns":618589656800500,"raw":{"market":"0x8032d8355d335c6ccbfc2508d99fbc87eb13f437bd275c93ee56fd1558e517ff","price_changes":[{"asset_id":"40652734036737240317526188612064032143639112324786051284480877037991580442979","price":"0.96","size":"3837.17","side":"BUY","hash":"77bb9a7a653528acba3a704bcadd2225f9d86f2b","best_bid":"0.97","best_ask":"0.98"},{"asset_id":"20773614133833886322101538939702011175545796528197617633926164254913649353392","price":"0.04","size":"3837.17","side":"SELL","hash":"38bab79a78780917698451b3ab19262f5571fa45","best_bid":"0.02","best_ask":"0.03"}],"timestamp":"1770839724405","event_type":"price_change","_sub_state":"active","_subscription_id":1,"_active_subscription_id":1},"parse_warnings":[],"out_of_order":false}
{"run_id":"29526913bab7446286864a321c124486","channel":"market","event_type":"price_change","market":"0x8032d8355d335c6ccbfc2508d99fbc87eb13f437bd275c93ee56fd1558e517ff","asset_id":null,"source":"market_ws:sub:active:1","t_event_ms":1770839724410,"t_recv_wall_ms":1770839724316,"t_recv_wall_iso":"2026-02-11T19:55:24.316Z","t_recv_mono_ns":618589657160041,"raw":{"market":"0x8032d8355d335c6ccbfc2508d99fbc87eb13f437bd275c93ee56fd1558e517ff","price_changes":[{"asset_id":"40652734036737240317526188612064032143639112324786051284480877037991580442979","price":"0.94","size":"3135.34","side":"BUY","hash":"9cf1c553fffdf86f5600028eaa1bf5b97599a903","best_bid":"0.97","best_ask":"0.98"},{"asset_id":"20773614133833886322101538939702011175545796528197617633926164254913649353392","price":"0.06","size":"3135.34","side":"SELL","hash":"e475968fcf2b1412948e99c54624d5a86f6ddb11","best_bid":"0.02","best_ask":"0.03"}],"timestamp":"1770839724410","event_type":"price_change","_sub_state":"active","_subscription_id":1,"_active_subscription_id":1},"parse_warnings":[],"out_of_order":false}
{"run_id":"29526913bab7446286864a321c124486","channel":"market","event_type":"price_change","market":"0x8032d8355d335c6ccbfc2508d99fbc87eb13f437bd275c93ee56fd1558e517ff","asset_id":null,"source":"market_ws:sub:active:1","t_event_ms":1770839724425,"t_recv_wall_ms":1770839724336,"t_recv_wall_iso":"2026-02-11T19:55:24.336Z","t_recv_mono_ns":618589677471791,"raw":{"market":"0x8032d8355d335c6ccbfc2508d99fbc87eb13f437bd275c93ee56fd1558e517ff","price_changes":[{"asset_id":"20773614133833886322101538939702011175545796528197617633926164254913649353392","price":"0.02","size":"8791.68","side":"BUY","hash":"b76afa8b661a64e92ea8122c42f04f958eae98d4","best_bid":"0.02","best_ask":"0.03"},{"asset_id":"40652734036737240317526188612064032143639112324786051284480877037991580442979","price":"0.98","size":"8791.68","side":"SELL","hash":"de86968846c45cc2dee7f79b682352dfb89c6720","best_bid":"0.97","best_ask":"0.98"}],"timestamp":"1770839724425","event_type":"price_change","_sub_state":"active","_subscription_id":1,"_active_subscription_id":1},"parse_warnings":[],"out_of_order":false}
{"run_id":"29526913bab7446286864a321c124486","channel":"market","event_type":"price_change","market":"0x8032d8355d335c6ccbfc2508d99fbc87eb13f437bd275c93ee56fd1558e517ff","asset_id":null,"source":"market_ws:sub:active:1","t_event_ms":1770839724428,"t_recv_wall_ms":1770839724337,"t_recv_wall_iso":"2026-02-11T19:55:24.337Z","t_recv_mono_ns":618589677913666,"raw":{"market":"0x8032d8355d335c6ccbfc2508d99fbc87eb13f437bd275c93ee56fd1558e517ff","price_changes":[{"asset_id":"40652734036737240317526188612064032143639112324786051284480877037991580442979","price":"0.91","size":"669.6","side":"BUY","hash":"13726ef2162271af5180d67b33ea8f3478197f4e","best_bid":"0.97","best_ask":"0.98"},{"asset_id":"20773614133833886322101538939702011175545796528197617633926164254913649353392","price":"0.09","size":"669.6","side":"SELL","hash":"80aadf9c65aa2b72b114a4962827b5623099e8e4","best_bid":"0.02","best_ask":"0.03"}],"timestamp":"1770839724428","event_type":"price_change","_sub_state":"active","_subscription_id":1,"_active_subscription_id":1},"parse_warnings":[],"out_of_order":false}
{"run_id":"29526913bab7446286864a321c124486","channel":"market","event_type":"price_change","market":"0x8032d8355d335c6ccbfc2508d99fbc87eb13f437bd275c93ee56fd1558e517ff","asset_id":null,"source":"market_ws:sub:active:1","t_event_ms":1770839724432,"t_recv_wall_ms":1770839724337,"t_recv_wall_iso":"2026-02-11T19:55:24.337Z","t_recv_mono_ns":618589678179833,"raw":{"market":"0x8032d8355d335c6ccbfc2508d99fbc87eb13f437bd275c93ee56fd1558e517ff","price_changes":[{"asset_id":"20773614133833886322101538939702011175545796528197617633926164254913649353392","price":"0.02","size":"8821.68","side":"BUY","hash":"3d3177cfca7b74d544fff8e348e9b9fe048ebccd","best_bid":"0.02","best_ask":"0.03"},{"asset_id":"40652734036737240317526188612064032143639112324786051284480877037991580442979","price":"0.98","size":"8821.68","side":"SELL","hash":"d30bf20d27d656f37225722c99f8fe716905f608","best_bid":"0.97","best_ask":"0.98"}],"timestamp":"1770839724432","event_type":"price_change","_sub_state":"active","_subscription_id":1,"_active_subscription_id":1},"parse_warnings":[],"out_of_order":false}
{"run_id":"29526913bab7446286864a321c124486","channel":"market","event_type":"price_change","market":"0x8032d8355d335c6ccbfc2508d99fbc87eb13f437bd275c93ee56fd1558e517ff","asset_id":null,"source":"market_ws:sub:active:1","t_event_ms":1770839724434,"t_recv_wall_ms":1770839724345,"t_recv_wall_iso":"2026-02-11T19:55:24.345Z","t_recv_mono_ns":618589686585791,"raw":{"market":"0x8032d8355d335c6ccbfc2508d99fbc87eb13f437bd275c93ee56fd1558e517ff","price_changes":[{"asset_id":"40652734036737240317526188612064032143639112324786051284480877037991580442979","price":"0.96","size":"3822.17","side":"BUY","hash":"ac0c259ea0e00c83cc6f06c57c70152127b38532","best_bid":"0.97","best_ask":"0.98"},{"asset_id":"20773614133833886322101538939702011175545796528197617633926164254913649353392","price":"0.04","size":"3822.17","side":"SELL","hash":"e651914bc9106fa02b001c67a5d56e002975958c","best_bid":"0.02","best_ask":"0.03"}],"timestamp":"1770839724434","event_type":"price_change","_sub_state":"active","_subscription_id":1,"_active_subscription_id":1},"parse_warnings":[],"out_of_order":false}
{"run_id":"29526913bab7446286864a321c124486","channel":"market","event_type":"price_change","market":"0x8032d8355d335c6ccbfc2508d99fbc87eb13f437bd275c93ee56fd1558e517ff","asset_id":null,"source":"market_ws:sub:active:1","t_event_ms":1770839724437,"t_recv_wall_ms":1770839724346,"t_recv_wall_iso":"2026-02-11T19:55:24.346Z","t_recv_mono_ns":618589686852166,"raw":{"market":"0x8032d8355d335c6ccbfc2508d99fbc87eb13f437bd275c93ee56fd1558e517ff","price_changes":[{"asset_id":"40652734036737240317526188612064032143639112324786051284480877037991580442979","price":"0.96","size":"3792.17","side":"BUY","hash":"2b48bff4b5c50871f8c5589105c977e1d4825283","best_bid":"0.97","best_ask":"0.98"},{"asset_id":"20773614133833886322101538939702011175545796528197617633926164254913649353392","price":"0.04","size":"3792.17","side":"SELL","hash":"37348e8794836ec8330525e70c3be568de79557c","best_bid":"0.02","best_ask":"0.03"}],"timestamp":"1770839724437","event_type":"price_change","_sub_state":"active","_subscription_id":1,"_active_subscription_id":1},"parse_warnings":[],"out_of_order":false}
{"run_id":"29526913bab7446286864a321c124486","channel":"market","event_type":"price_change","market":"0x8032d8355d335c6ccbfc2508d99fbc87eb13f437bd275c93ee56fd1558e517ff","asset_id":null,"source":"market_ws:sub:active:1","t_event_ms":1770839724440,"t_recv_wall_ms":1770839724346,"t_recv_wall_iso":"2026-02-11T19:55:24.346Z","t_recv_mono_ns":618589687016125,"raw":{"market":"0x8032d8355d335c6ccbfc2508d99fbc87eb13f437bd275c93ee56fd1558e517ff","price_changes":[{"asset_id":"40652734036737240317526188612064032143639112324786051284480877037991580442979","price":"0.8","size":"987.2","side":"BUY","hash":"ef53895fb8ababffa9fcb6f51d408e35416f916f","best_bid":"0.97","best_ask":"0.98"},{"asset_id":"20773614133833886322101538939702011175545796528197617633926164254913649353392","price":"0.2","size":"987.2","side":"SELL","hash":"1605f7941a6f9a56210af212ca3a69e692aa0663","best_bid":"0.02","best_ask":"0.03"}],"timestamp":"1770839724440","event_type":"price_change","_sub_state":"active","_subscription_id":1,"_active_subscription_id":1},"parse_warnings":[],"out_of_order":false}
{"run_id":"29526913bab7446286864a321c124486","channel":"market","event_type":"price_change","market":"0x8032d8355d335c6ccbfc2508d99fbc87eb13f437bd275c93ee56fd1558e517ff","asset_id":null,"source":"market_ws:sub:active:1","t_event_ms":1770839724458,"t_recv_wall_ms":1770839724371,"t_recv_wall_iso":"2026-02-11T19:55:24.371Z","t_recv_mono_ns":618589712698458,"raw":{"market":"0x8032d8355d335c6ccbfc2508d99fbc87eb13f437bd275c93ee56fd1558e517ff","price_changes":[{"asset_id":"40652734036737240317526188612064032143639112324786051284480877037991580442979","price":"0.97","size":"641.4","side":"BUY","hash":"c2d84d120c667c466e6cede93b3e8e5c3bcd1d9e","best_bid":"0.97","best_ask":"0.98"},{"asset_id":"20773614133833886322101538939702011175545796528197617633926164254913649353392","price":"0.03","size":"641.4","side":"SELL","hash":"5e0fe4ddc0d4d6b65db4471e188cb758db4e8bb2","best_bid":"0.02","best_ask":"0.03"}],"timestamp":"1770839724458","event_type":"price_change","_sub_state":"active","_subscription_id":1,"_active_subscription_id":1},"parse_warnings":[],"out_of_order":false}
