{"run_id":"29526913bab7446286864a321c124486","channel":"market","event_type":"book","market":"0x8032d8355d335c6ccbfc2508d99fbc87eb13f437bd275c93ee56fd1558e517ff","asset_id":"20773614133833886322101538939702011175545796528197617633926164254913649353392","source":"market_ws:sub:active:1","t_event_ms":1770839720779,"t_recv_wall_ms":1770839720746,"t_recv_wall_iso":"2026-02-11T19:55:20.746Z","t_recv_mono_ns":618586087648791,"raw":{"market":"0x8032d8355d335c6ccbfc2508d99fbc87eb13f437bd275c93ee56fd1558e517ff","asset_id":"20773614133833886322101538939702011175545796528197617633926164254913649353392","timestamp":"1770839720779","hash":"3ff5cae99a008ddf19ee5aeb93f4109e3de08772","bids":[{"price":"0.01","size":"30769.91"},{"price":"0.02","size":"10777.23"},{"price":"0.03","size":"330.52"}],"asks":[{"price":"0.99","size":"30822.26"},{"price":"0.98","size":"12559.04"},{"price":"0.97","size":"7433.03"},{"price":"0.96","size":"5453.8"},{"price":"0.95","size":"6815.8"},{"price":"0.94","size":"5105"},{"price":"0.93","size":"5421.38"},{"price":"0.92","size":"5139.4"},{"price":"0.91","size":"5225.8"},{"price":"0.9","size":"5102.8"},{"price":"0.89","size":"120.6"},{"price":"0.88","size":"63.6"},{"price":"0.87","size":"63"},{"price":"0.86","size":"61.6"},{"price":"0.85","size":"107.39"},{"price":"0.84","size":"69.39"},{"price":"0.83","size":"58.39"},{"price":"0.82","size":"66.71"},{"price":"0.81","size":"56.8"},{"price":"0.8","size":"92.14"},{"price":"0.79","size":"60.8"},{"price":"0.78","size":"55.2"},{"price":"0.77","size":"64.48"},{"price":"0.76","size":"54.2"},{"price":"0.75","size":"375.8"},{"price":"0.74","size":"68.6"},{"price":"0.73","size":"53.2"},{"price":"0.72","size":"63.26"},{"price":"0.71","size":"52.6"},{"price":"0.7","size":"402.4"},{"price":"0.69","size":"72.2"},{"price":"0.68","size":"87.88"},{"price":"0.67","size":"188.46"},{"price":"0.66","size":"123.6"},{"price":"0.65","size":"317.03"},{"price":"0.64","size":"582.36"},{"price":"0.63","size":"559.2"},{"price":"0.62","size":"559"},{"price":"0.61","size":"594"},{"price":"0.6","size":"2915.41"},{"price":"0.59","size":"576.8"},{"price":"0.58","size":"575.5"},{"price":"0.57","size":"558.6"},{"price":"0.56","size":"572.68"},{"price":"0.55","size":"566.4"},{"price":"0.54","size":"561.94"},{"price":"0.53","size":"631.57"},{"price":"0.52","size":"611.4"},{"price":"0.51","size":"705.2"},{"price":"0.5","size":"1011.55"},{"price":"0.49","size":"692.4"},{"price":"0.48","size":"628.4"},{"price":"0.47","size":"633.4"},{"price":"0.46","size":"711.65"},{"price":"0.45","size":"866.59"},{"price":"0.44","size":"905.69"},{"price":"0.43","size":"641.6"},{"price":"0.42","size":"645.58"},{"price":"0.41","size":"564"},{"price":"0.4","size":"20642.9"},{"price":"0.39","size":"650.23"},{"price":"0.38","size":"593"},{"price":"0.37","size":"755.73"},{"price":"0.36","size":"558"},{"price":"0.35","size":"1144.32"},{"price":"0.34","size":"649.59"},{"price":"0.33","size":"624.8"},{"price":"0.32","size":"574"},{"price":"0.31","size":"594.2"},{"price":"0.3","size":"735.66"},{"price":"0.29","size":"918.6"},{"price":"0.28","size":"356.8"},{"price":"0.27","size":"869.2"},{"price":"0.26","size":"967.6"},{"price":"0.25","size":"1673.8"},{"price":"0.24","size":"869.2"},{"price":"0.23","size":"884.6"},{"price":"0.22","size":"870.2"},{"price":"0.21","size":"871.6"},{"price":"0.2","size":"987.2"},{"price":"0.19","size":"876.8"},{"price":"0.18","size":"1091.55"},{"price":"0.17","size":"958.39"},{"price":"0.16","size":"1119.39"},{"price":"0.15","size":"1164.13"},{"price":"0.14","size":"962.6"},{"price":"0.13","size":"1046.8"},{"price":"0.12","size":"1055.55"},{"price":"0.11","size":"1124.49"},{"price":"0.1","size":"664.79"},{"price":"0.09","size":"889.6"},{"price":"0.08","size":"3429.35"},{"price":"0.07","size":"3335.43"},{"price":"0.06","size":"3186.34"},{"price":"0.05","size":"3310.45"},{"price":"0.04","size":"3681.97"}],"event_type":"book","last_trade_price":"0.030","_sub_state":"active","_subscription_id":1,"_active_subscription_id":1},"parse_warnings":[],"out_of_order":false}
{"run_id":"29526913bab7446286864a321c124486","channel":"market","event_type":"book","market":"0x8032d8355d335c6ccbfc2508d99fbc87eb13f437bd275c93ee56fd1558e517ff","asset_id":"40652734036737240317526188612064032143639112324786051284480877037991580442979","source":"market_ws:sub:active:1","t_event_ms":1770839720779,"t_recv_wall_ms":1770839720746,"t_recv_wall_iso":"2026-02-11T19:55:20.746Z","t_recv_mono_ns":618586087648791,"raw":{"market":"0x8032d8355d335c6ccbfc2508d99fbc87eb13f437bd275c93ee56fd1558e517ff","asset_id":"40652734036737240317526188612064032143639112324786051284480877037991580442979","timestamp":"1770839720779","hash":"f8f6309fe2855f50df15e8b04f7a8e346c31eb88","bids":[{"price":"0.01","size":"30822.26"},{"price":"0.02","size":"12559.04"},{"price":"0.03","size":"7433.03"},{"price":"0.04","size":"5453.8"},{"price":"0.05","size":"6815.8"},{"price":"0.06","size":"5105"},{"price":"0.07","size":"5421.38"},{"price":"0.08","size":"5139.4"},{"price":"0.09","size":"5225.8"},{"price":"0.1","size":"5102.8"},{"price":"0.11","size":"120.6"},{"price":"0.12","size":"63.6"},{"price":"0.13","size":"63"},{"price":"0.14","size":"61.6"},{"price":"0.15","size":"107.39"},{"price":"0.16","size":"69.39"},{"price":"0.17","size":"58.39"},{"price":"0.18","size":"66.71"},{"price":"0.19","size":"56.8"},{"price":"0.2","size":"92.14"},{"price":"0.21","size":"60.8"},{"price":"0.22","size":"55.2"},{"price":"0.23","size":"64.48"},{"price":"0.24","size":"54.2"},{"price":"0.25","size":"375.8"},{"price":"0.26","size":"68.6"},{"price":"0.27","size":"53.2"},{"price":"0.28","size":"63.26"},{"price":"0.29","size":"52.6"},{"price":"0.3","size":"402.4"},{"price":"0.31","size":"72.2"},{"price":"0.32","size":"87.88"},{"price":"0.33","size":"188.46"},{"price":"0.34","size":"123.6"},{"price":"0.35","size":"317.03"},{"price":"0.36","size":"582.36"},{"price":"0.37","size":"559.2"},{"price":"0.38","size":"559"},{"price":"0.39","size":"594"},{"price":"0.4","size":"2915.41"},{"price":"0.41","size":"576.8"},{"price":"0.42","size":"575.5"},{"price":"0.43","size":"558.6"},{"price":"0.44","size":"572.68"},{"price":"0.45","size":"566.4"},{"price":"0.46","size":"561.94"},{"price":"0.47","size":"631.57"},{"price":"0.48","size":"611.4"},{"price":"0.49","size":"705.2"},{"price":"0.5","size":"1011.55"},{"price":"0.51","size":"692.4"},{"price":"0.52","size":"628.4"},{"price":"0.53","size":"633.4"},{"price":"0.54","size":"711.65"},{"price":"0.55","size":"866.59"},{"price":"0.56","size":"905.69"},{"price":"0.57","size":"641.6"},{"price":"0.58","size":"645.58"},{"price":"0.59","size":"564"},{"price":"0.6","size":"20642.9"},{"price":"0.61","size":"650.23"},{"price":"0.62","size":"593"},{"price":"0.63","size":"755.73"},{"price":"0.64","size":"558"},{"price":"0.65","size":"1144.32"},{"price":"0.66","size":"649.59"},{"price":"0.67","size":"624.8"},{"price":"0.68","size":"574"},{"price":"0.69","size":"594.2"},{"price":"0.7","size":"735.66"},{"price":"0.71","size":"918.6"},{"price":"0.72","size":"356.8"},{"price":"0.73","size":"869.2"},{"price":"0.74","size":"967.6"},{"price":"0.75","size":"1673.8"},{"price":"0.76","size":"869.2"},{"price":"0.77","size":"884.6"},{"price":"0.78","size":"870.2"},{"price":"0.79","size":"871.6"},{"price":"0.8","size":"987.2"},{"price":"0.81","size":"876.8"},{"price":"0.82","size":"1091.55"},{"price":"0.83","size":"958.39"},{"price":"0.84","size":"1119.39"},{"price":"0.85","size":"1164.13"},{"price":"0.86","size":"962.6"},{"price":"0.87","size":"1046.8"},{"price":"0.88","size":"1055.55"},{"price":"0.89","size":"1124.49"},{"price":"0.9","size":"664.79"},{"price":"0.91","size":"889.6"},{"price":"0.92","size":"3429.35"},{"price":"0.93","size":"3335.43"},{"price":"0.94","size":"3186.34"},{"price":"0.95","size":"3310.45"},{"price":"0.96","size":"3681.97"}],"asks":[{"price":"0.99","size":"30769.91"},{"price":"0.98","size":"10777.23"},{"price":"0.97","size":"330.52"}],"event_type":"book","last_trade_price":"0.030","_sub_state":"active","_subscription_id":1,"_active_subscription_id":1},"parse_warnings":[],"out_of_order":false}
{"run_id":"29526913bab7446286864a321c124486","channel":"market","event_type":"price_change","market":"0x8032d8355d335c6ccbfc2508d99fbc87eb13f437bd275c93ee56fd1558e517ff","asset_id":null,"source":"market_ws:sub:active:1","t_event_ms":1770839720840,"t_recv_wall_ms":1770839720749,"t_recv_wall_iso":"2026-02-11T19:55:20.749Z","t_recv_mono_ns":618586090638041,"raw":{"market":"0x8032d8355d335c6ccbfc2508d99fbc87eb13f437bd275c93ee56fd1558e517ff","price_changes":[{"asset_id":"40652734036737240317526188612064032143639112324786051284480877037991580442979","price":"0.97","size":"324.52","side":"SELL","hash":"83b48c1dea777b390a0f7406b175dc29eb2d4cbf","best_bid":"0.96","best_ask":"0.97"},{"asset_id":"20773614133833886322101538939702011175545796528197617633926164254913649353392","price":"0.03","size":"324.52","side":"BUY","hash":"c9c4ecf40a73bbd1e4ffe8ed2e042d8ab4d02864","best_bid":"0.03","best_ask":"0.04"}],"timestamp":"1770839720840","event_type":"price_change","_sub_state":"active","_subscription_id":1,"_active_subscription_id":1},"parse_warnings":[],"out_of_order":false}
{"run_id":"29526913bab7446286864a321c124486","channel":"market","event_type":"book","market":"0x8032d8355d335c6ccbfc2508d99fbc87eb13f437bd275c93ee56fd1558e517ff","asset_id":"20773614133833886322101538939702011175545796528197617633926164254913649353392","source":"market_ws:sub:active:1","t_event_ms":1770839720840,"t_recv_wall_ms":1770839720750,"t_recv_wall_iso":"2026-02-11T19:55:20.750Z","t_recv_mono_ns":618586090940208,"raw":{"market":"0x8032d8355d335c6ccbfc2508d99fbc87eb13f437bd275c93ee56fd1558e517ff","asset_id":"20773614133833886322101538939702011175545796528197617633926164254913649353392","bids":[{"price":"0.01","size":"30769.91"},{"price":"0.02","size":"10777.23"},{"price":"0.03","size":"324.52"}],"asks":[{"price":"0.99","size":"30822.26"},{"price":"0.98","size":"12559.04"},{"price":"0.97","size":"7433.03"},{"price":"0.96","size":"5453.8"},{"price":"0.95","size":"6815.8"},{"price":"0.94","size":"5105"},{"price":"0.93","size":"5421.38"},{"price":"0.92","size":"5139.4"},{"price":"0.91","size":"5225.8"},{"price":"0.9","size":"5102.8"},{"price":"0.89","size":"120.6"},{"price":"0.88","size":"63.6"},{"price":"0.87","size":"63"},{"price":"0.86","size":"61.6"},{"price":"0.85","size":"107.39"},{"price":"0.84","size":"69.39"},{"price":"0.83","size":"58.39"},{"price":"0.82","size":"66.71"},{"price":"0.81","size":"56.8"},{"price":"0.8","size":"92.14"},{"price":"0.79","size":"60.8"},{"price":"0.78","size":"55.2"},{"price":"0.77","size":"64.48"},{"price":"0.76","size":"54.2"},{"price":"0.75","size":"375.8"},{"price":"0.74","size":"68.6"},{"price":"0.73","size":"53.2"},{"price":"0.72","size":"63.26"},{"price":"0.71","size":"52.6"},{"price":"0.7","size":"402.4"},{"price":"0.69","size":"72.2"},{"price":"0.68","size":"87.88"},{"price":"0.67","size":"188.46"},{"price":"0.66","size":"123.6"},{"price":"0.65","size":"317.03"},{"price":"0.64","size":"582.36"},{"price":"0.63","size":"559.2"},{"price":"0.62","size":"559"},{"price":"0.61","size":"594"},{"price":"0.6","size":"2915.41"},{"price":"0.59","size":"576.8"},{"price":"0.58","size":"575.5"},{"price":"0.57","size":"558.6"},{"price":"0.56","size":"572.68"},{"price":"0.55","size":"566.4"},{"price":"0.54","size":"561.94"},{"price":"0.53","size":"631.57"},{"price":"0.52","size":"611.4"},{"price":"0.51","size":"705.2"},{"price":"0.5","size":"1011.55"},{"price":"0.49","size":"692.4"},{"price":"0.48","size":"628.4"},{"price":"0.47","size":"633.4"},{"price":"0.46","size":"711.65"},{"price":"0.45","size":"866.59"},{"price":"0.44","size":"905.69"},{"price":"0.43","size":"641.6"},{"price":"0.42","size":"645.58"},{"price":"0.41","size":"564"},{"price":"0.4","size":"20642.9"},{"price":"0.39","size":"650.23"},{"price":"0.38","size":"593"},{"price":"0.37","size":"755.73"},{"price":"0.36","size":"558"},{"price":"0.35","size":"1144.32"},{"price":"0.34","size":"649.59"},{"price":"0.33","size":"624.8"},{"price":"0.32","size":"574"},{"price":"0.31","size":"594.2"},{"price":"0.3","size":"735.66"},{"price":"0.29","size":"918.6"},{"price":"0.28","size":"356.8"},{"price":"0.27","size":"869.2"},{"price":"0.26","size":"967.6"},{"price":"0.25","size":"1673.8"},{"price":"0.24","size":"869.2"},{"price":"0.23","size":"884.6"},{"price":"0.22","size":"870.2"},{"price":"0.21","size":"871.6"},{"price":"0.2","size":"987.2"},{"price":"0.19","size":"876.8"},{"price":"0.18","size":"1091.55"},{"price":"0.17","size":"958.39"},{"price":"0.16","size":"1119.39"},{"price":"0.15","size":"1164.13"},{"price":"0.14","size":"962.6"},{"price":"0.13","size":"1046.8"},{"price":"0.12","size":"1055.55"},{"price":"0.11","size":"1124.49"},{"price":"0.1","size":"664.79"},{"price":"0.09","size":"889.6"},{"price":"0.08","size":"3429.35"},{"price":"0.07","size":"3335.43"},{"price":"0.06","size":"3186.34"},{"price":"0.05","size":"3310.45"},{"price":"0.04","size":"3681.97"}],"hash":"c9c4ecf40a73bbd1e4ffe8ed2e042d8ab4d02864","timestamp":"1770839720840","event_type":"book","_sub_state":"active","_subscription_id":1,"_active_subscription_id":1},"parse_warnings":[],"out_of_order":false}
{"run_id":"29526913bab7446286864a321c124486","channel":"market","event_type":"book","market":"0x8032d8355d335c6ccbfc2508d99fbc87eb13f437bd275c93ee56fd1558e517ff","asset_id":"40652734036737240317526188612064032143639112324786051284480877037991580442979","source":"market_ws:sub:active:1","t_event_ms":1770839720840,"t_recv_wall_ms":1770839720838,"t_recv_wall_iso":"2026-02-11T19:55:20.838Z","t_recv_mono_ns":618586179059875,"raw":{"market":"0x8032d8355d335c6ccbfc2508d99fbc87eb13f437bd275c93ee56fd1558e517ff","asset_id":"40652734036737240317526188612064032143639112324786051284480877037991580442979","bids":[{"price":"0.01","size":"30822.26"},{"price":"0.02","size":"12559.04"},{"price":"0.03","size":"7433.03"},{"price":"0.04","size":"5453.8"},{"price":"0.05","size":"6815.8"},{"price":"0.06","size":"5105"},{"price":"0.07","size":"5421.38"},{"price":"0.08","size":"5139.4"},{"price":"0.09","size":"5225.8"},{"price":"0.1","size":"5102.8"},{"price":"0.11","size":"120.6"},{"price":"0.12","size":"63.6"},{"price":"0.13","size":"63"},{"price":"0.14","size":"61.6"},{"price":"0.15","size":"107.39"},{"price":"0.16","size":"69.39"},{"price":"0.17","size":"58.39"},{"price":"0.18","size":"66.71"},{"price":"0.19","size":"56.8"},{"price":"0.2","size":"92.14"},{"price":"0.21","size":"60.8"},{"price":"0.22","size":"55.2"},{"price":"0.23","size":"64.48"},{"price":"0.24","size":"54.2"},{"price":"0.25","size":"375.8"},{"price":"0.26","size":"68.6"},{"price":"0.27","size":"53.2"},{"price":"0.28","size":"63.26"},{"price":"0.29","size":"52.6"},{"price":"0.3","size":"402.4"},{"price":"0.31","size":"72.2"},{"price":"0.32","size":"87.88"},{"price":"0.33","size":"188.46"},{"price":"0.34","size":"123.6"},{"price":"0.35","size":"317.03"},{"price":"0.36","size":"582.36"},{"price":"0.37","size":"559.2"},{"price":"0.38","size":"559"},{"price":"0.39","size":"594"},{"price":"0.4","size":"2915.41"},{"price":"0.41","size":"576.8"},{"price":"0.42","size":"575.5"},{"price":"0.43","size":"558.6"},{"price":"0.44","size":"572.68"},{"price":"0.45","size":"566.4"},{"price":"0.46","size":"561.94"},{"price":"0.47","size":"631.57"},{"price":"0.48","size":"611.4"},{"price":"0.49","size":"705.2"},{"price":"0.5","size":"1011.55"},{"price":"0.51","size":"692.4"},{"price":"0.52","size":"628.4"},{"price":"0.53","size":"633.4"},{"price":"0.54","size":"711.65"},{"price":"0.55","size":"866.59"},{"price":"0.56","size":"905.69"},{"price":"0.57","size":"641.6"},{"price":"0.58","size":"645.58"},{"price":"0.59","size":"564"},{"price":"0.6","size":"20642.9"},{"price":"0.61","size":"650.23"},{"price":"0.62","size":"593"},{"price":"0.63","size":"755.73"},{"price":"0.64","size":"558"},{"price":"0.65","size":"1144.32"},{"price":"0.66","size":"649.59"},{"price":"0.67","size":"624.8"},{"price":"0.68","size":"574"},{"price":"0.69","size":"594.2"},{"price":"0.7","size":"735.66"},{"price":"0.71","size":"918.6"},{"price":"0.72","size":"356.8"},{"price":"0.73","size":"869.2"},{"price":"0.74","size":"967.6"},{"price":"0.75","size":"1673.8"},{"price":"0.76","size":"869.2"},{"price":"0.77","size":"884.6"},{"price":"0.78","size":"870.2"},{"price":"0.79","size":"871.6"},{"price":"0.8","size":"987.2"},{"price":"0.81","size":"876.8"},{"price":"0.82","size":"1091.55"},{"price":"0.83","size":"958.39"},{"price":"0.84","size":"1119.39"},{"price":"0.85","size":"1164.13"},{"price":"0.86","size":"962.6"},{"price":"0.87","size":"1046.8"},{"price":"0.88","size":"1055.55"},{"price":"0.89","size":"1124.49"},{"price":"0.9","size":"664.79"},{"price":"0.91","size":"889.6"},{"price":"0.92","size":"3429.35"},{"price":"0.93","size":"3335.43"},{"price":"0.94","size":"3186.34"},{"price":"0.95","size":"3310.45"},{"price":"0.96","size":"3681.97"}],"asks":[{"price":"0.99","size":"30769.91"},{"price":"0.98","size":"10777.23"},{"price":"0.97","size":"324.52"}],"hash":"83b48c1dea777b390a0f7406b175dc29eb2d4cbf","timestamp":"1770839720840","event_type":"book","_sub_state":"active","_subscription_id":1,"_active_subscription_id":1},"parse_warnings":[],"out_of_order":false}
{"run_id":"29526913bab7446286864a321c124486","channel":"market","event_type":"price_change","market":"0x8032d8355d335c6ccbfc2508d99fbc87eb13f437bd275c93ee56fd1558e517ff","asset_id":null,"source":"market_ws:sub:active:1","t_event_ms":1770839720842,"t_recv_wall_ms":1770839720839,"t_recv_wall_iso":"2026-02-11T19:55:20.839Z","t_recv_mono_ns":618586180413375,"raw":{"market":"0x8032d8355d335c6ccbfc2508d99fbc87eb13f437bd275c93ee56fd1558e517ff","price_changes":[{"asset_id":"40652734036737240317526188612064032143639112324786051284480877037991580442979","price":"0.96","size":"3687.97","side":"BUY","hash":"cb1b867062eb32db3578106e1cc08e7d34422088","best_bid":"0.96","best_ask":"0.97"},{"asset_id":"20773614133833886322101538939702011175545796528197617633926164254913649353392","price":"0.04","size":"3687.97","side":"SELL","hash":"7cffd55f963453cabfd50a90e2d62c463ce7be3b","best_bid":"0.03","best_ask":"0.04"}],"timestamp":"1770839720842","event_type":"price_change","_sub_state":"active","_subscription_id":1,"_active_subscription_id":1},"parse_warnings":[],"out_of_order":false}
{"run_id":"29526913bab7446286864a321c124486","channel":"market","event_type":"price_change","market":"0x8032d8355d335c6ccbfc2508d99fbc87eb13f437bd275c93ee56fd1558e517ff","asset_id":null,"source":"market_ws:sub:active:1","t_event_ms":1770839720852,"t_recv_wall_ms":1770839720839,"t_recv_wall_iso":"2026-02-11T19:55:20.839Z","t_recv_mono_ns":618586180744208,"raw":{"market":"0x8032d8355d335c6ccbfc2508d99fbc87eb13f437bd275c93ee56fd1558e517ff","price_changes":[{"asset_id":"40652734036737240317526188612064032143639112324786051284480877037991580442979","price":"0.82","size":"1096.55","side":"BUY","hash":"de3faeb5701885655ced744a1e7a58dc8f0accd8","best_bid":"0.96","best_ask":"0.97"},{"asset_id":"20773614133833886322101538939702011175545796528197617633926164254913649353392","price":"0.18","size":"1096.55","side":"SELL","hash":"9b5033a32335a0da72d3594127a299d142f273a3","best_bid":"0.03","best_ask":"0.04"}],"timestamp":"1770839720852","event_type":"price_change","_sub_state":"active","_subscription_id":1,"_active_subscription_id":1},"parse_warnings":[],"out_of_order":false}
{"run_id":"29526913bab7446286864a321c124486","channel":"market","event_type":"last_trade_price","market":"0x8032d8355d335c6ccbfc2508d99fbc87eb13f437bd275c93ee56fd1558e517ff","asset_id":"40652734036737240317526188612064032143639112324786051284480877037991580442979","source":"market_ws:sub:unknown","t_event_ms":1770839720869,"t_recv_wall_ms":1770839720840,"t_recv_wall_iso":"2026-02-11T19:55:20.840Z","t_recv_mono_ns":618586180995708,"raw":{"market":"0x8032d8355d335c6ccbfc2508d99fbc87eb13f437bd275c93ee56fd1558e517ff","asset_id":"40652734036737240317526188612064032143639112324786051284480877037991580442979","price":"0.97","size":"6","fee_rate_bps":"1000","side":"BUY","timestamp":"1770839720869","event_type":"last_trade_price","transaction_hash":"0x06096398993d03178f8fda960ac38e8c0da3dceeb6f3f3ad45e26637be738b67","_sub_state":"unknown","_subscription_id":null,"_active_subscription_id":1},"parse_warnings":["unknown_message_schema"],"out_of_order":false}
{"run_id":"29526913bab7446286864a321c124486","channel":"market","event_type":"price_change","market":"0x8032d8355d335c6ccbfc2508d99fbc87eb13f437bd275c93ee56fd1558e517ff","asset_id":null,"source":"market_ws:sub:active:1","t_event_ms":1770839720882,"t_recv_wall_ms":1770839720840,"t_recv_wall_iso":"2026-02-11T19:55:20.840Z","t_recv_mono_ns":618586181224833,"raw":{"market":"0x8032d8355d335c6ccbfc2508d99fbc87eb13f437bd275c93ee56fd1558e517ff","price_changes":[{"asset_id":"40652734036737240317526188612064032143639112324786051284480877037991580442979","price":"0.94","size":"3181.34","side":"BUY","hash":"9753e79b18aa4cbb306bf6587a7291c101c7f2e1","best_bid":"0.96","best_ask":"0.97"},{"asset_id":"20773614133833886322101538939702011175545796528197617633926164254913649353392","price":"0.06","size":"3181.34","side":"SELL","hash":"929e8d39d9b32384d44197be5c80231661dfdaa8","best_bid":"0.03","best_ask":"0.04"}],"timestamp":"1770839720882","event_type":"price_change","_sub_state":"active","_subscription_id":1,"_active_subscription_id":1},"parse_warnings":[],"out_of_order":false}
{"run_id":"29526913bab7446286864a321c124486","channel":"market","event_type":"price_change","market":"0x8032d8355d335c6ccbfc2508d99fbc87eb13f437bd275c93ee56fd1558e517ff","asset_id":null,"source":"market_ws:sub:active:1","t_event_ms":1770839720936,"t_recv_wall_ms":1770839720843,"t_recv_wall_iso":"2026-02-11T19:55:20.843Z","t_recv_mono_ns":618586184142750,"raw":{"market":"0x8032d8355d335c6ccbfc2508d99fbc87eb13f437bd275c93ee56fd1558e517ff","price_changes":[{"asset_id":"40652734036737240317526188612064032143639112324786051284480877037991580442979","price":"0.94","size":"3186.34","side":"BUY","hash":"0395e022d52bd090056129dd62e60dbbabeb236f","best_bid":"0.96","best_ask":"0.97"},{"asset_id":"20773614133833886322101538939702011175545796528197617633926164254913649353392","price":"0.06","size":"3186.34","side":"SELL","hash":"3548fd931b600518f327658cd85d4086406c3fac","best_bid":"0.03","best_ask":"0.04"}],"timestamp":"1770839720936","event_type":"price_change","_sub_state":"active","_subscription_id":1,"_active_subscription_id":1},"parse_warnings":[],"out_of_order":false}
{"run_id":"29526913bab7446286864a321c124486","channel":"market","event_type":"price_change","market":"0x8032d8355d335c6ccbfc2508d99fbc87eb13f437bd275c93ee56fd1558e517ff","asset_id":null,"source":"market_ws:sub:active:1","t_event_ms":1770839720950,"t_recv_wall_ms":1770839720856,"t_recv_wall_iso":"2026-02-11T19:55:20.856Z","t_recv_mono_ns":618586196998833,"raw":{"market":"0x8032d8355d335c6ccbfc2508d99fbc87eb13f437bd275c93ee56fd1558e517ff","price_changes":[{"asset_id":"40652734036737240317526188612064032143639112324786051284480877037991580442979","price":"0.82","size":"1091.55","side":"BUY","hash":"9b3a6d559f427a5741323d7fffad43b57be608a6","best_bid":"0.96","best_ask":"0.97"},{"asset_id":"20773614133833886322101538939702011175545796528197617633926164254913649353392","price":"0.18","size":"1091.55","side":"SELL","hash":"74de0bf3e512e6a14e8b1ac21699b8687b5e635a","best_bid":"0.03","best_ask":"0.04"}],"timestamp":"1770839720950","event_type":"price_change","_sub_state":"active","_subscription_id":1,"_active_subscription_id":1},"parse_warnings":[],"out_of_order":false}
{"run_id":"29526913bab7446286864a321c124486","channel":"market","event_type":"price_change","market":"0x8032d8355d335c6ccbfc2508d99fbc87eb13f437bd275c93ee56fd1558e517ff","asset_id":null,"source":"market_ws:sub:active:1","t_event_ms":1770839720954,"t_recv_wall_ms":1770839720863,"t_recv_wall_iso":"2026-02-11T19:55:20.863Z","t_recv_mono_ns":618586203866541,"raw":{"market":"0x8032d8355d335c6ccbfc2508d99fbc87eb13f437bd275c93ee56fd1558e517ff","price_changes":[{"asset_id":"40652734036737240317526188612064032143639112324786051284480877037991580442979","price":"0.96","size":"3669.97","side":"BUY","hash":"65634218e58ae16b92b37903cdc73227923c2eb2","best_bid":"0.96","best_ask":"0.97"},{"asset_id":"20773614133833886322101538939702011175545796528197617633926164254913649353392","price":"0.04","size":"3669.97","side":"SELL","hash":"5da2627fb5d790e7d206d68f6f3ed2101ae1c64b","best_bid":"0.03","best_ask":"0.04"}],"timestamp":"1770839720954","event_type":"price_change","_sub_state":"active","_subscription_id":1,"_active_subscription_id":1},"parse_warnings":[],"out_of_order":false}
{"run_id":"29526913bab7446286864a321c124486","channel":"market","event_type":"price_change","market":"0x8032d8355d335c6ccbfc2508d99fbc87eb13f437bd275c93ee56fd1558e517ff","asset_id":null,"source":"market_ws:sub:active:1","t_event_ms":1770839720965,"t_recv_wall_ms":1770839720869,"t_recv_wall_iso":"2026-02-11T19:55:20.869Z","t_recv_mono_ns":618586210369875,"raw":{"market":"0x8032d8355d335c6ccbfc2508d99fbc87eb13f437bd275c93ee56fd1558e517ff","price_changes":[{"asset_id":"20773614133833886322101538939702011175545796528197617633926164254913649353392","price":"0.02","size":"10747.23","side":"BUY","hash":"781eec2127a3ebd7aa63eaf49b82b28e169138cc","best_bid":"0.03","best_ask":"0.04"},{"asset_id":"40652734036737240317526188612064032143639112324786051284480877037991580442979","price":"0.98","size":"10747.23","side":"SELL","hash":"ac4f39003774ede0afb33b1c5197c686d5e8d97e","best_bid":"0.96","best_ask":"0.97"}],"timestamp":"1770839720965","event_type":"price_change","_sub_state":"active","_subscription_id":1,"_active_subscription_id":1},"parse_warnings":[],"out_of_order":false}
{"run_id":"29526913bab7446286864a321c124486","channel":"market","event_type":"price_change","market":"0x8032d8355d335c6ccbfc2508d99fbc87eb13f437bd275c93ee56fd1558e517ff","asset_id":null,"source":"market_ws:sub:active:1","t_event_ms":1770839721010,"t_recv_wall_ms":1770839720917,"t_recv_wall_iso":"2026-02-11T19:55:20.917Z","t_recv_mono_ns":618586258375125,"raw":{"market":"0x8032d8355d335c6ccbfc2508d99fbc87eb13f437bd275c93ee56fd1558e517ff","price_changes":[{"asset_id":"40652734036737240317526188612064032143639112324786051284480877037991580442979","price":"0.97","size":"319.46","side":"SELL","hash":"4652fa750cb695453248c998ebd5e47c433e5c7c","best_bid":"0.96","best_ask":"0.97"},{"asset_id":"20773614133833886322101538939702011175545796528197617633926164254913649353392","price":"0.03","size":"319.46","side":"BUY","hash":"1186a7928026e52c1b7d51154537a40f26ceb25f","best_bid":"0.03","best_ask":"0.04"}],"timestamp":"1770839721010","event_type":"price_change","_sub_state":"active","_subscription_id":1,"_active_subscription_id":1},"parse_warnings":[],"out_of_order":false}
{"run_id":"29526913bab7446286864a321c124486","channel":"market","event_type":"book","market":"0x8032d8355d335c6ccbfc2508d99fbc87eb13f437bd275c93ee56fd1558e517ff","asset_id":"20773614133833886322101538939702011175545796528197617633926164254913649353392","source":"market_ws:sub:active:1","t_event_ms":1770839721010,"t_recv_wall_ms":1770839720918,"t_recv_wall_iso":"2026-02-11T19:55:20.918Z","t_recv_mono_ns":618586259203083,"raw":{"market":"0x8032d8355d335c6ccbfc2508d99fbc87eb13f437bd275c93ee56fd1558e517ff","asset_id":"20773614133833886322101538939702011175545796528197617633926164254913649353392","bids":[{"price":"0.01","size":"30769.91"},{"price":"0.02","size":"10747.23"},{"price":"0.03","size":"319.46"}],"asks":[{"price":"0.99","size":"30822.26"},{"price":"0.98","size":"12559.04"},{"price":"0.97","size":"7433.03"},{"price":"0.96","size":"5453.8"},{"price":"0.95","size":"6815.8"},{"price":"0.94","size":"5105"},{"price":"0.93","size":"5421.38"},{"price":"0.92","size":"5139.4"},{"price":"0.91","size":"5225.8"},{"price":"0.9","size":"5102.8"},{"price":"0.89","size":"120.6"},{"price":"0.88","size":"63.6"},{"price":"0.87","size":"63"},{"price":"0.86","size":"61.6"},{"price":"0.85","size":"107.39"},{"price":"0.84","size":"69.39"},{"price":"0.83","size":"58.39"},{"price":"0.82","size":"66.71"},{"price":"0.81","size":"56.8"},{"price":"0.8","size":"92.14"},{"price":"0.79","size":"60.8"},{"price":"0.78","size":"55.2"},{"price":"0.77","size":"64.48"},{"price":"0.76","size":"54.2"},{"price":"0.75","size":"375.8"},{"price":"0.74","size":"68.6"},{"price":"0.73","size":"53.2"},{"price":"0.72","size":"63.26"},{"price":"0.71","size":"52.6"},{"price":"0.7","size":"402.4"},{"price":"0.69","size":"72.2"},{"price":"0.68","size":"87.88"},{"price":"0.67","size":"188.46"},{"price":"0.66","size":"123.6"},{"price":"0.65","size":"317.03"},{"price":"0.64","size":"582.36"},{"price":"0.63","size":"559.2"},{"price":"0.62","size":"559"},{"price":"0.61","size":"594"},{"price":"0.6","size":"2915.41"},{"price":"0.59","size":"576.8"},{"price":"0.58","size":"575.5"},{"price":"0.57","size":"558.6"},{"price":"0.56","size":"572.68"},{"price":"0.55","size":"566.4"},{"price":"0.54","size":"561.94"},{"price":"0.53","size":"631.57"},{"price":"0.52","size":"611.4"},{"price":"0.51","size":"705.2"},{"price":"0.5","size":"1011.55"},{"price":"0.49","size":"692.4"},{"price":"0.48","size":"628.4"},{"price":"0.47","size":"633.4"},{"price":"0.46","size":"711.65"},{"price":"0.45","size":"866.59"},{"price":"0.44","size":"905.69"},{"price":"0.43","size":"641.6"},{"price":"0.42","size":"645.58"},{"price":"0.41","size":"564"},{"price":"0.4","size":"20642.9"},{"price":"0.39","size":"650.23"},{"price":"0.38","size":"593"},{"price":"0.37","size":"755.73"},{"price":"0.36","size":"558"},{"price":"0.35","size":"1144.32"},{"price":"0.34","size":"649.59"},{"price":"0.33","size":"624.8"},{"price":"0.32","size":"574"},{"price":"0.31","size":"594.2"},{"price":"0.3","size":"735.66"},{"price":"0.29","size":"918.6"},{"price":"0.28","size":"356.8"},{"price":"0.27","size":"869.2"},{"price":"0.26","size":"967.6"},{"price":"0.25","size":"1673.8"},{"price":"0.24","size":"869.2"},{"price":"0.23","size":"884.6"},{"price":"0.22","size":"870.2"},{"price":"0.21","size":"871.6"},{"price":"0.2","size":"987.2"},{"price":"0.19","size":"876.8"},{"price":"0.18","size":"1091.55"},{"price":"0.17","size":"958.39"},{"price":"0.16","size":"1119.39"},{"price":"0.15","size":"1164.13"},{"price":"0.14","size":"962.6"},{"price":"0.13","size":"1046.8"},{"price":"0.12","size":"1055.55"},{"price":"0.11","size":"1124.49"},{"price":"0.1","size":"664.79"},{"price":"0.09","size":"889.6"},{"price":"0.08","size":"3429.35"},{"price":"0.07","size":"3335.43"},{"price":"0.06","size":"3186.34"},{"price":"0.05","size":"3310.45"},{"price":"0.04","size":"3669.97"}],"hash":"1186a7928026e52c1b7d51154537a40f26ceb25f","timestamp":"1770839721010","event_type":"book","_sub_state":"active","_subscription_id":1,"_active_subscription_id":1},"parse_warnings":[],"out_of_order":false}
{"run_id":"29526913bab7446286864a321c124486","channel":"market","event_type":"book","market":"0x8032d8355d335c6ccbfc2508d99fbc87eb13f437bd275c93ee56fd1558e517ff","asset_id":"40652734036737240317526188612064032143639112324786051284480877037991580442979","source":"market_ws:sub:active:1","t_event_ms":1770839721010,"t_recv_wall_ms":1770839720919,"t_recv_wall_iso":"2026-02-11T19:55:20.919Z","t_recv_mono_ns":618586260261291,"raw":{"market":"0x8032d8355d335c6ccbfc2508d99fbc87eb13f437bd275c93ee56fd1558e517ff","asset_id":"40652734036737240317526188612064032143639112324786051284480877037991580442979","bids":[{"price":"0.01","size":"30822.26"},{"price":"0.02","size":"12559.04"},{"price":"0.03","size":"7433.03"},{"price":"0.04","size":"5453.8"},{"price":"0.05","size":"6815.8"},{"price":"0.06","size":"5105"},{"price":"0.07","size":"5421.38"},{"price":"0.08","size":"5139.4"},{"price":"0.09","size":"5225.8"},{"price":"0.1","size":"5102.8"},{"price":"0.11","size":"120.6"},{"price":"0.12","size":"63.6"},{"price":"0.13","size":"63"},{"price":"0.14","size":"61.6"},{"price":"0.15","size":"107.39"},{"price":"0.16","size":"69.39"},{"price":"0.17","size":"58.39"},{"price":"0.18","size":"66.71"},{"price":"0.19","size":"56.8"},{"price":"0.2","size":"92.14"},{"price":"0.21","size":"60.8"},{"price":"0.22","size":"55.2"},{"price":"0.23","size":"64.48"},{"price":"0.24","size":"54.2"},{"price":"0.25","size":"375.8"},{"price":"0.26","size":"68.6"},{"price":"0.27","size":"53.2"},{"price":"0.28","size":"63.26"},{"price":"0.29","size":"52.6"},{"price":"0.3","size":"402.4"},{"price":"0.31","size":"72.2"},{"price":"0.32","size":"87.88"},{"price":"0.33","size":"188.46"},{"price":"0.34","size":"123.6"},{"price":"0.35","size":"317.03"},{"price":"0.36","size":"582.36"},{"price":"0.37","size":"559.2"},{"price":"0.38","size":"559"},{"price":"0.39","size":"594"},{"price":"0.4","size":"2915.41"},{"price":"0.41","size":"576.8"},{"price":"0.42","size":"575.5"},{"price":"0.43","size":"558.6"},{"price":"0.44","size":"572.68"},{"price":"0.45","size":"566.4"},{"price":"0.46","size":"561.94"},{"price":"0.47","size":"631.57"},{"price":"0.48","size":"611.4"},{"price":"0.49","size":"705.2"},{"price":"0.5","size":"1011.55"},{"price":"0.51","size":"692.4"},{"price":"0.52","size":"628.4"},{"price":"0.53","size":"633.4"},{"price":"0.54","size":"711.65"},{"price":"0.55","size":"866.59"},{"price":"0.56","size":"905.69"},{"price":"0.57","size":"641.6"},{"price":"0.58","size":"645.58"},{"price":"0.59","size":"564"},{"price":"0.6","size":"20642.9"},{"price":"0.61","size":"650.23"},{"price":"0.62","size":"593"},{"price":"0.63","size":"755.73"},{"price":"0.64","size":"558"},{"price":"0.65","size":"1144.32"},{"price":"0.66","size":"649.59"},{"price":"0.67","size":"624.8"},{"price":"0.68","size":"574"},{"price":"0.69","size":"594.2"},{"price":"0.7","size":"735.66"},{"price":"0.71","size":"918.6"},{"price":"0.72","size":"356.8"},{"price":"0.73","size":"869.2"},{"price":"0.74","size":"967.6"},{"price":"0.75","size":"1673.8"},{"price":"0.76","size":"869.2"},{"price":"0.77","size":"884.6"},{"price":"0.78","size":"870.2"},{"price":"0.79","size":"871.6"},{"price":"0.8","size":"987.2"},{"price":"0.81","size":"876.8"},{"price":"0.82","size":"1091.55"},{"price":"0.83","size":"958.39"},{"price":"0.84","size":"1119.39"},{"price":"0.85","size":"1164.13"},{"price":"0.86","size":"962.6"},{"price":"0.87","size":"1046.8"},{"price":"0.88","size":"1055.55"},{"price":"0.89","size":"1124.49"},{"price":"0.9","size":"664.79"},{"price":"0.91","size":"889.6"},{"price":"0.92","size":"3429.35"},{"price":"0.93","size":"3335.43"},{"price":"0.94","size":"3186.34"},{"price":"0.95","size":"3310.45"},{"price":"0.96","size":"3669.97"}],"asks":[{"price":"0.99","size":"30769.91"},{"price":"0.98","size":"10747.23"},{"price":"0.97","size":"319.46"}],"hash":"4652fa750cb695453248c998ebd5e47c433e5c7c","timestamp":"1770839721010","event_type":"book","_sub_state":"active","_subscription_id":1,"_active_subscription_id":1},"parse_warnings":[],"out_of_order":false}
{"run_id":"29526913bab7446286864a321c124486","channel":"market","event_type":"price_change","market":"0x8032d8355d335c6ccbfc2508d99fbc87eb13f437bd275c93ee56fd1558e517ff","asset_id":null,"source":"market_ws:sub:active:1","t_event_ms":1770839721013,"t_recv_wall_ms":1770839720920,"t_recv_wall_iso":"2026-02-11T19:55:20.920Z","t_recv_mono_ns":618586260957875,"raw":{"market":"0x8032d8355d335c6ccbfc2508d99fbc87eb13f437bd275c93ee56fd1558e517ff","price_changes":[{"asset_id":"20773614133833886322101538939702011175545796528197617633926164254913649353392","price":"0.01","size":"30789.91","side":"BUY","hash":"fc2b90065a01a66f9b98bc3aa5d1f6d20db54d3e","best_bid":"0.03","best_ask":"0.04"},{"asset_id":"40652734036737240317526188612064032143639112324786051284480877037991580442979","price":"0.99","size":"30789.91","side":"SELL","hash":"3c863c8c4a2e417285cb07a724b99f2e2e09a46f","best_bid":"0.96","best_ask":"0.97"}],"timestamp":"1770839721013","event_type":"price_change","_sub_state":"active","_subscription_id":1,"_active_subscription_id":1},"parse_warnings":[],"out_of_order":false}
{"run_id":"29526913bab7446286864a321c124486","channel":"market","event_type":"last_trade_price","market":"0x8032d8355d335c6ccbfc2508d99fbc87eb13f437bd275c93ee56fd1558e517ff","asset_id":"40652734036737240317526188612064032143639112324786051284480877037991580442979","source":"market_ws:sub:unknown","t_event_ms":1770839721039,"t_recv_wall_ms":1770839720960,"t_recv_wall_iso":"2026-02-11T19:55:20.960Z","t_recv_mono_ns":618586300815875,"raw":{"market":"0x8032d8355d335c6ccbfc2508d99fbc87eb13f437bd275c93ee56fd1558e517ff","asset_id":"40652734036737240317526188612064032143639112324786051284480877037991580442979","price":"0.97","size":"5.051545","fee_rate_bps":"1000","side":"BUY","timestamp":"1770839721039","event_type":"last_trade_price","transaction_hash":"0xd7b3bff42aa8c1f3ce965da618bc23d99cad375a92c9e53bc0d9d1708a36701e","_sub_state":"unknown","_subscription_id":null,"_active_subscription_id":1},"parse_warnings":["unknown_message_schema"],"out_of_order":false}
{"run_id":"29526913bab7446286864a321c124486","channel":"market","event_type":"price_change","market":"0x8032d8355d335c6ccbfc2508d99fbc87eb13f437bd275c93ee56fd1558e517ff","asset_id":null,"source":"market_ws:sub:active:1","t_event_ms":1770839721056,"t_recv_wall_ms":1770839720962,"t_recv_wall_iso":"2026-02-11T19:55:20.962Z","t_recv_mono_ns":618586303210250,"raw":{"market":"0x8032d8355d335c6ccbfc2508d99fbc87eb13f437bd275c93ee56fd1558e517ff","price_changes":[{"asset_id":"40652734036737240317526188612064032143639112324786051284480877037991580442979","price":"0.92","size":"3399.35","side":"BUY","hash":"889d9f2baed46065eb487e67d09724d62d07fb5c","best_bid":"0.96","best_ask":"0.97"},{"asset_id":"20773614133833886322101538939702011175545796528197617633926164254913649353392","price":"0.08","size":"3399.35","side":"SELL","hash":"954fbc5d4c30eddfdc4eaff4a9488700279c70f5","best_bid":"0.03","best_ask":"0.04"}],"timestamp":"1770839721056","event_type":"price_change","_sub_state":"active","_subscription_id":1,"_active_subscription_id":1},"parse_warnings":[],"out_of_order":false}
{"run_id":"29526913bab7446286864a321c124486","channel":"market","event_type":"price_change","market":"0x8032d8355d335c6ccbfc2508d99fbc87eb13f437bd275c93ee56fd1558e517ff","asset_id":null,"source":"market_ws:sub:active:1","t_event_ms":1770839721058,"t_recv_wall_ms":1770839720962,"t_recv_wall_iso":"2026-02-11T19:55:20.962Z","t_recv_mono_ns":618586303689750,"raw":{"market":"0x8032d8355d335c6ccbfc2508d99fbc87eb13f437bd275c93ee56fd1558e517ff","price_changes":[{"asset_id":"40652734036737240317526188612064032143639112324786051284480877037991580442979","price":"0.82","size":"1096.55","side":"BUY","hash":"1d6339cb0cf13e41bee1298fe792d65ce657e449","best_bid":"0.96","best_ask":"0.97"},{"asset_id":"20773614133833886322101538939702011175545796528197617633926164254913649353392","price":"0.18","size":"1096.55","side":"SELL","hash":"71cd10beb0a879de6c3aded1143c98ae6033ff14","best_bid":"0.03","best_ask":"0.04"}],"timestamp":"1770839721058","event_type":"price_change","_sub_state":"active","_subscription_id":1,"_active_subscription_id":1},"parse_warnings":[],"out_of_order":false}
{"run_id":"29526913bab7446286864a321c124486","channel":"market","event_type":"price_change","market":"0x8032d8355d335c6ccbfc2508d99fbc87eb13f437bd275c93ee56fd1558e517ff","asset_id":null,"source":"market_ws:sub:active:1","t_event_ms":1770839721059,"t_recv_wall_ms":1770839720964,"t_recv_wall_iso":"2026-02-11T19:55:20.964Z","t_recv_mono_ns":618586305498833,"raw":{"market":"0x8032d8355d335c6ccbfc2508d99fbc87eb13f437bd275c93ee56fd1558e517ff","price_changes":[{"asset_id":"20773614133833886322101538939702011175545796528197617633926164254913649353392","price":"0.05","size":"3304.45","side":"SELL","hash":"3325915c52b5476c3896bc04ba20829fd7b97241","best_bid":"0.03","best_ask":"0.04"},{"asset_id":"40652734036737240317526188612064032143639112324786051284480877037991580442979","price":"0.95","size":"3304.45","side":"BUY","hash":"9daadae6876305f704f19d2f6d25d9c8c6135297","best_bid":"0.96","best_ask":"0.97"}],"timestamp":"1770839721059","event_type":"price_change","_sub_state":"active","_subscription_id":1,"_active_subscription_id":1},"parse_warnings":[],"out_of_order":false}
{"run_id":"29526913bab7446286864a321c124486","channel":"market","event_type":"price_change","market":"0x8032d8355d335c6ccbfc2508d99fbc87eb13f437bd275c93ee56fd1558e517ff","asset_id":null,"source":"market_ws:sub:active:1","t_event_ms":1770839721071,"t_recv_wall_ms":1770839720977,"t_recv_wall_iso":"2026-02-11T19:55:20.977Z","t_recv_mono_ns":618586318660166,"raw":{"market":"0x8032d8355d335c6ccbfc2508d99fbc87eb13f437bd275c93ee56fd1558e517ff","price_changes":[{"asset_id":"40652734036737240317526188612064032143639112324786051284480877037991580442979","price":"0.96","size":"3689.97","side":"BUY","hash":"2ab0b7431bc99fa2ced119ca11966e187fd314b7","best_bid":"0.96","best_ask":"0.97"},{"asset_id":"20773614133833886322101538939702011175545796528197617633926164254913649353392","price":"0.04","size":"3689.97","side":"SELL","hash":"7f0ab8370809e39cc135d9ffcc5c02234ffb8254","best_bid":"0.03","best_ask":"0.04"}],"timestamp":"1770839721071","event_type":"price_change","_sub_state":"active","_subscription_id":1,"_active_subscription_id":1},"parse_warnings":[],"out_of_order":false}
{"run_id":"29526913bab7446286864a321c124486","channel":"market","event_type":"price_change","market":"0x8032d8355d335c6ccbfc2508d99fbc87eb13f437bd275c93ee56fd1558e517ff","asset_id":null,"source":"market_ws:sub:active:1","t_event_ms":1770839721088,"t_recv_wall_ms":1770839720993,"t_recv_wall_iso":"2026-02-11T19:55:20.993Z","t_recv_mono_ns":618586334145500,"raw":{"market":"0x8032d8355d335c6ccbfc2508d99fbc87eb13f437bd275c93ee56fd1558e517ff","price_changes":[{"asset_id":"40652734036737240317526188612064032143639112324786051284480877037991580442979","price":"0.96","size":"3699.97","side":"BUY","hash":"a1876033cb52899ce6dc68dcb65f2881586e1044","best_bid":"0.96","best_ask":"0.97"},{"asset_id":"20773614133833886322101538939702011175545796528197617633926164254913649353392","price":"0.04","size":"3699.97","side":"SELL","hash":"f6b9a4b5e8f06138780b5865f912260c343c6c49","best_bid":"0.03","best_ask":"0.04"}],"timestamp":"1770839721088","event_type":"price_change","_sub_state":"active","_subscription_id":1,"_active_subscription_id":1},"parse_warnings":[],"out_of_order":false}
{"run_id":"29526913bab7446286864a321c124486","channel":"market","event_type":"price_change","market":"0x8032d8355d335c6ccbfc2508d99fbc87eb13f437bd275c93ee56fd1558e517ff","asset_id":null,"source":"market_ws:sub:active:1","t_event_ms":1770839721108,"t_recv_wall_ms":1770839721014,"t_recv_wall_iso":"2026-02-11T19:55:21.014Z","t_recv_mono_ns":618586355012500,"raw":{"market":"0x8032d8355d335c6ccbfc2508d99fbc87eb13f437bd275c93ee56fd1558e517ff","price_changes":[{"asset_id":"40652734036737240317526188612064032143639112324786051284480877037991580442979","price":"0.92","size":"3419.35","side":"BUY","hash":"f23d0073c9db1cb14bb919edbb3aaa865863a4ab","best_bid":"0.96","best_ask":"0.97"},{"asset_id":"20773614133833886322101538939702011175545796528197617633926164254913649353392","price":"0.08","size":"3419.35","side":"SELL","hash":"7dbc31253a4407e30539850ab4eb47dc2efe8d8c","best_bid":"0.03","best_ask":"0.04"}],"timestamp":"1770839721108","event_type":"price_change","_sub_state":"active","_subscription_id":1,"_active_subscription_id":1},"parse_warnings":[],"out_of_order":false}
{"run_id":"29526913bab7446286864a321c124486","channel":"market","event_type":"price_change","market":"0x8032d8355d335c6ccbfc2508d99fbc87eb13f437bd275c93ee56fd1558e517ff","asset_id":null,"source":"market_ws:sub:active:1","t_event_ms":1770839721155,"t_recv_wall_ms":1770839721067,"t_recv_wall_iso":"2026-02-11T19:55:21.067Z","t_recv_mono_ns":618586408220625,"raw":{"market":"0x8032d8355d335c6ccbfc2508d99fbc87eb13f437bd275c93ee56fd1558e517ff","price_changes":[{"asset_id":"40652734036737240317526188612064032143639112324786051284480877037991580442979","price":"0.82","size":"1091.55","side":"BUY","hash":"3794f394bbd2ef68ec733efa0ee4c3d531cd3244","best_bid":"0.96","best_ask":"0.97"},{"asset_id":"20773614133833886322101538939702011175545796528197617633926164254913649353392","price":"0.18","size":"1091.55","side":"SELL","hash":"3ca98bba4a1abfbf6555dccf45089b4a6a1f54b2","best_bid":"0.03","best_ask":"0.04"}],"timestamp":"1770839721155","event_type":"price_change","_sub_state":"active","_subscription_id":1,"_active_subscription_id":1},"parse_warnings":[],"out_of_order":false}
{"run_id":"29526913bab7446286864a321c124486","channel":"market","event_type":"price_change","market":"0x8032d8355d335c6ccbfc2508d99fbc87eb13f437bd275c93ee56fd1558e517ff","asset_id":null,"source":"market_ws:sub:active:1","t_event_ms":1770839721160,"t_recv_wall_ms":1770839721067,"t_recv_wall_iso":"2026-02-11T19:55:21.067Z","t_recv_mono_ns":618586408740000,"raw":{"market":"0x8032d8355d335c6ccbfc2508d99fbc87eb13f437bd275c93ee56fd1558e517ff","price_changes":[{"asset_id":"40652734036737240317526188612064032143639112324786051284480877037991580442979","price":"0.94","size":"3181.34","side":"BUY","hash":"100f23347917fc8b97579035b84204057317e10c","best_bid":"0.96","best_ask":"0.97"},{"asset_id":"20773614133833886322101538939702011175545796528197617633926164254913649353392","price":"0.06","size":"3181.34","side":"SELL","hash":"d418205e9bc592230d12796c9ff9ea5f8ece0c69","best_bid":"0.03","best_ask":"0.04"}],"timestamp":"1770839721160","event_type":"price_change","_sub_state":"active","_subscription_id":1,"_active_subscription_id":1},"parse_warnings":[],"out_of_order":false}
{"run_id":"29526913bab7446286864a321c124486","channel":"market","event_type":"price_change","market":"0x8032d8355d335c6ccbfc2508d99fbc87eb13f437bd275c93ee56fd1558e517ff","asset_id":null,"source":"market_ws:sub:active:1","t_event_ms":1770839721218,"t_recv_wall_ms":1770839721123,"t_recv_wall_iso":"2026-02-11T19:55:21.123Z","t_recv_mono_ns":618586463756208,"raw":{"market":"0x8032d8355d335c6ccbfc2508d99fbc87eb13f437bd275c93ee56fd1558e517ff","price_changes":[{"asset_id":"40652734036737240317526188612064032143639112324786051284480877037991580442979","price":"0.94","size":"3186.34","side":"BUY","hash":"720585f05b358cef0caf6b64f3e1a08bd88aa589","best_bid":"0.96","best_ask":"0.97"},{"asset_id":"20773614133833886322101538939702011175545796528197617633926164254913649353392","price":"0.06","size":"3186.34","side":"SELL","hash":"37826a30d48a06dc425fce5a501272f0b154bda9","best_bid":"0.03","best_ask":"0.04"}],"timestamp":"1770839721218","event_type":"price_change","_sub_state":"active","_subscription_id":1,"_active_subscription_id":1},"parse_warnings":[],"out_of_order":false}
{"run_id":"29526913bab7446286864a321c124486","channel":"market","event_type":"price_change","market":"0x8032d8355d335c6ccbfc2508d99fbc87eb13f437bd275c93ee56fd1558e517ff","asset_id":null,"source":"market_ws:sub:active:1","t_event_ms":1770839721260,"t_recv_wall_ms":1770839721166,"t_recv_wall_iso":"2026-02-11T19:55:21.166Z","t_recv_mono_ns":618586507559958,"raw":{"market":"0x8032d8355d335c6ccbfc2508d99fbc87eb13f437bd275c93ee56fd1558e517ff","price_changes":[{"asset_id":"40652734036737240317526188612064032143639112324786051284480877037991580442979","price":"0.82","size":"1096.55","side":"BUY","hash":"ff54bd51751fd5e1adde3f01efacb42187aa30f6","best_bid":"0.96","best_ask":"0.97"},{"asset_id":"20773614133833886322101538939702011175545796528197617633926164254913649353392","price":"0.18","size":"1096.55","side":"SELL","hash":"a2e05009ca22c1161a0ed4621fcc8591671eed36","best_bid":"0.03","best_ask":"0.04"}],"timestamp":"1770839721260","event_type":"price_change","_sub_state":"active","_subscription_id":1,"_active_subscription_id":1},"parse_warnings":[],"out_of_order":false}
{"run_id":"29526913bab7446286864a321c124486","channel":"market","event_type":"price_change","market":"0x8032d8355d335c6ccbfc2508d99fbc87eb13f437bd275c93ee56fd1558e517ff","asset_id":null,"source":"market_ws:sub:active:1","t_event_ms":1770839721293,"t_recv_wall_ms":1770839721208,"t_recv_wall_iso":"2026-02-11T19:55:21.208Z","t_recv_mono_ns":618586548842666,"raw":{"market":"0x8032d8355d335c6ccbfc2508d99fbc87eb13f437bd275c93ee56fd1558e517ff","price_changes":[{"asset_id":"40652734036737240317526188612064032143639112324786051284480877037991580442979","price":"0.96","size":"3704.97","side":"BUY","hash":"ce9490043be43790367a684fc132cc0ee15d2eec","best_bid":"0.96","best_ask":"0.97"},{"asset_id":"20773614133833886322101538939702011175545796528197617633926164254913649353392","price":"0.04","size":"3704.97","side":"SELL","hash":"5234425b62d2155a9c05e8753210957e2a8ee366","best_bid":"0.03","best_ask":"0.04"}],"timestamp":"1770839721293","event_type":"price_change","_sub_state":"active","_subscription_id":1,"_active_subscription_id":1},"parse_warnings":[],"out_of_order":false}
{"run_id":"29526913bab7446286864a321c124486","channel":"market","event_type":"price_change","market":"0x8032d8355d335c6ccbfc2508d99fbc87eb13f437bd275c93ee56fd1558e517ff","asset_id":null,"source":"market_ws:sub:active:1","t_event_ms":1770839721336,"t_recv_wall_ms":1770839721241,"t_recv_wall_iso":"2026-02-11T19:55:21.241Z","t_recv_mono_ns":618586581868583,"raw":{"market":"0x8032d8355d335c6ccbfc2508d99fbc87eb13f437bd275c93ee56fd1558e517ff","price_changes":[{"asset_id":"20773614133833886322101538939702011175545796528197617633926164254913649353392","price":"0.04","size":"3710.97","side":"SELL","hash":"cb3548f45e111224a7720c6610e630b49270a4cc","best_bid":"0.03","best_ask":"0.04"},{"asset_id":"40652734036737240317526188612064032143639112324786051284480877037991580442979","price":"0.96","size":"3710.97","side":"BUY","hash":"6f1eea562487140bc6ded6db2cb47e5b24764dfc","best_bid":"0.96","best_ask":"0.97"}],"timestamp":"1770839721336","event_type":"price_change","_sub_state":"active","_subscription_id":1,"_active_subscription_id":1},"parse_warnings":[],"out_of_order":false}
{"run_id":"29526913bab7446286864a321c124486","channel":"market","event_type":"price_change","market":"0x8032d8355d335c6ccbfc2508d99fbc87eb13f437bd275c93ee56fd1558e517ff","asset_id":null,"source":"market_ws:sub:active:1","t_event_ms":1770839721371,"t_recv_wall_ms":1770839721278,"t_recv_wall_iso":"2026-02-11T19:55:21.278Z","t_recv_mono_ns":618586619525625,"raw":{"market":"0x8032d8355d335c6ccbfc2508d99fbc87eb13f437bd275c93ee56fd1558e517ff","price_changes":[{"asset_id":"40652734036737240317526188612064032143639112324786051284480877037991580442979","price":"0.82","size":"1091.55","side":"BUY","hash":"fa722cd20b193be19483605610a191991ae7e980","best_bid":"0.96","best_ask":"0.97"},{"asset_id":"20773614133833886322101538939702011175545796528197617633926164254913649353392","price":"0.18","size":"1091.55","side":"SELL","hash":"74087d04e6e5133eba6754b0293dbc11b056c4b2","best_bid":"0.03","best_ask":"0.04"}],"timestamp":"1770839721371","event_type":"price_change","_sub_state":"active","_subscription_id":1,"_active_subscription_id":1},"parse_warnings":[],"out_of_order":false}
{"run_id":"29526913bab7446286864a321c124486","channel":"market","event_type":"price_change","market":"0x8032d8355d335c6ccbfc2508d99fbc87eb13f437bd275c93ee56fd1558e517ff","asset_id":null,"source":"market_ws:sub:active:1","t_event_ms":1770839721447,"t_recv_wall_ms":1770839721364,"t_recv_wall_iso":"2026-02-11T19:55:21.364Z","t_recv_mono_ns":618586704762000,"raw":{"market":"0x8032d8355d335c6ccbfc2508d99fbc87eb13f437bd275c93ee56fd1558e517ff","price_changes":[{"asset_id":"40652734036737240317526188612064032143639112324786051284480877037991580442979","price":"0.94","size":"3181.34","side":"BUY","hash":"91f9588cf98d06163b406bde07c1c9aad32bc50f","best_bid":"0.96","best_ask":"0.97"},{"asset_id":"20773614133833886322101538939702011175545796528197617633926164254913649353392","price":"0.06","size":"3181.34","side":"SELL","hash":"d825d1ed5fc61607bb6fc6bbd2da8c232de618f7","best_bid":"0.03","best_ask":"0.04"}],"timestamp":"1770839721447","event_type":"price_change","_sub_state":"active","_subscription_id":1,"_active_subscription_id":1},"parse_warnings":[],"out_of_order":false}
{"run_id":"29526913bab7446286864a321c124486","channel":"market","event_type":"price_change","market":"0x8032d8355d335c6ccbfc2508d99fbc87eb13f437bd275c93ee56fd1558e517ff","asset_id":null,"source":"market_ws:sub:active:1","t_event_ms":1770839721471,"t_recv_wall_ms":1770839721382,"t_recv_wall_iso":"2026-02-11T19:55:21.382Z","t_recv_mono_ns":618586723592833,"raw":{"market":"0x8032d8355d335c6ccbfc2508d99fbc87eb13f437bd275c93ee56fd1558e517ff","price_changes":[{"asset_id":"40652734036737240317526188612064032143639112324786051284480877037991580442979","price":"0.82","size":"1096.55","side":"BUY","hash":"944356f7dcb7f0d6387c228ef7c0f3961d46e7c3","best_bid":"0.96","best_ask":"0.97"},{"asset_id":"20773614133833886322101538939702011175545796528197617633926164254913649353392","price":"0.18","size":"1096.55","side":"SELL","hash":"e807cdb40fdac6712de22494a09ecc7bbfb30001","best_bid":"0.03","best_ask":"0.04"}],"timestamp":"1770839721471","event_type":"price_change","_sub_state":"active","_subscription_id":1,"_active_subscription_id":1},"parse_warnings":[],"out_of_order":false}
{"run_id":"29526913bab7446286864a321c124486","channel":"market","event_type":"price_change","market":"0x8032d8355d335c6ccbfc2508d99fbc87eb13f437bd275c93ee56fd1558e517ff","asset_id":null,"source":"market_ws:sub:active:1","t_event_ms":1770839721500,"t_recv_wall_ms":1770839721408,"t_recv_wall_iso":"2026-02-11T19:55:21.408Z","t_recv_mono_ns":618586749353458,"raw":{"market":"0x8032d8355d335c6ccbfc2508d99fbc87eb13f437bd275c93ee56fd1558e517ff","price_changes":[{"asset_id":"40652734036737240317526188612064032143639112324786051284480877037991580442979","price":"0.94","size":"3186.34","side":"BUY","hash":"242831ccf4cda28818ddde46966f08058253ad64","best_bid":"0.96","best_ask":"0.97"},{"asset_id":"20773614133833886322101538939702011175545796528197617633926164254913649353392","price":"0.06","size":"3186.34","side":"SELL","hash":"934a428aba3487fc180e5182568b679ad0e59b9e","best_bid":"0.03","best_ask":"0.04"}],"timestamp":"1770839721500","event_type":"price_change","_sub_state":"active","_subscription_id":1,"_active_subscription_id":1},"parse_warnings":[],"out_of_order":false}
{"run_id":"29526913bab7446286864a321c124486","channel":"market","event_type":"price_change","market":"0x8032d8355d335c6ccbfc2508d99fbc87eb13f437bd275c93ee56fd1558e517ff","asset_id":null,"source":"market_ws:sub:active:1","t_event_ms":1770839721516,"t_recv_wall_ms":1770839721434,"t_recv_wall_iso":"2026-02-11T19:55:21.434Z","t_recv_mono_ns":618586775560416,"raw":{"market":"0x8032d8355d335c6ccbfc2508d99fbc87eb13f437bd275c93ee56fd1558e517ff","price_changes":[{"asset_id":"40652734036737240317526188612064032143639112324786051284480877037991580442979","price":"0.9","size":"659.79","side":"BUY","hash":"e62283947687dd4186760a2f93161ac6b5c92ffe","best_bid":"0.96","best_ask":"0.97"},{"asset_id":"20773614133833886322101538939702011175545796528197617633926164254913649353392","price":"0.1","size":"659.79","side":"SELL","hash":"e4d90b268d94d55aa1a4b985404f4bfae2318160","best_bid":"0.03","best_ask":"0.04"}],"timestamp":"1770839721516","event_type":"price_change","_sub_state":"active","_subscription_id":1,"_active_subscription_id":1},"parse_warnings":[],"out_of_order":false}
{"run_id":"29526913bab7446286864a321c124486","channel":"market","event_type":"price_change","market":"0x8032d8355d335c6ccbfc2508d99fbc87eb13f437bd275c93ee56fd1558e517ff","asset_id":null,"source":"market_ws:sub:active:1","t_event_ms":1770839721571,"t_recv_wall_ms":1770839721483,"t_recv_wall_iso":"2026-02-11T19:55:21.483Z","t_recv_mono_ns":618586824235500,"raw":{"market":"0x8032d8355d335c6ccbfc2508d99fbc87eb13f437bd275c93ee56fd1558e517ff","price_changes":[{"asset_id":"40652734036737240317526188612064032143639112324786051284480877037991580442979","price":"0.82","size":"1091.55","side":"BUY","hash":"09e21910075778dda34f7a8e663ca41f5cbc6b47","best_bid":"0.96","best_ask":"0.97"},{"asset_id":"20773614133833886322101538939702011175545796528197617633926164254913649353392","price":"0.18","size":"1091.55","side":"SELL","hash":"58990122d73338680f3a560ce7e425b08aca448e","best_bid":"0.03","best_ask":"0.04"}],"timestamp":"1770839721571","event_type":"price_change","_sub_state":"active","_subscription_id":1,"_active_subscription_id":1},"parse_warnings":[],"out_of_order":false}
{"run_id":"29526913bab7446286864a321c124486","channel":"market","event_type":"price_change","market":"0x8032d8355d335c6ccbfc2508d99fbc87eb13f437bd275c93ee56fd1558e517ff","asset_id":null,"source":"market_ws:sub:active:1","t_event_ms":1770839721674,"t_recv_wall_ms":1770839721583,"t_recv_wall_iso":"2026-02-11T19:55:21.583Z","t_recv_mono_ns":618586923813750,"raw":{"market":"0x8032d8355d335c6ccbfc2508d99fbc87eb13f437bd275c93ee56fd1558e517ff","price_changes":[{"asset_id":"40652734036737240317526188612064032143639112324786051284480877037991580442979","price":"0.82","size":"1096.55","side":"BUY","hash":"c8579dccf799a03af676473f393db7dc3225cd0d","best_bid":"0.96","best_ask":"0.97"},{"asset_id":"20773614133833886322101538939702011175545796528197617633926164254913649353392","price":"0.18","size":"1096.55","side":"SELL","hash":"2a2f05fb2d757b0b70b6a33f824447ea229f55df","best_bid":"0.03","best_ask":"0.04"}],"timestamp":"1770839721674","event_type":"price_change","_sub_state":"active","_subscription_id":1,"_active_subscription_id":1},"parse_warnings":[],"out_of_order":false}
{"run_id":"29526913bab7446286864a321c124486","channel":"market","event_type":"price_change","market":"0x8032d8355d335c6ccbfc2508d99fbc87eb13f437bd275c93ee56fd1558e517ff","asset_id":null,"source":"market_ws:sub:active:1","t_event_ms":1770839721752,"t_recv_wall_ms":1770839721662,"t_recv_wall_iso":"2026-02-11T19:55:21.662Z","t_recv_mono_ns":618587003365125,"raw":{"market":"0x8032d8355d335c6ccbfc2508d99fbc87eb13f437bd275c93ee56fd1558e517ff","price_changes":[{"asset_id":"40652734036737240317526188612064032143639112324786051284480877037991580442979","price":"0.97","size":"315.37","side":"SELL","hash":"486a3383858e1ea927582f987b8ed84a5ee6153c","best_bid":"0.96","best_ask":"0.97"},{"asset_id":"20773614133833886322101538939702011175545796528197617633926164254913649353392","price":"0.03","size":"315.37","side":"BUY","hash":"41a0e334faa7f8dcded9b41b57f8d61896c93eb9","best_bid":"0.03","best_ask":"0.04"}],"timestamp":"1770839721752","event_type":"price_change","_sub_state":"active","_subscription_id":1,"_active_subscription_id":1},"parse_warnings":[],"out_of_order":false}
{"run_id":"29526913bab7446286864a321c124486","channel":"market","event_type":"book","market":"0x8032d8355d335c6ccbfc2508d99fbc87eb13f437bd275c93ee56fd1558e517ff","asset_id":"20773614133833886322101538939702011175545796528197617633926164254913649353392","source":"market_ws:sub:active:1","t_event_ms":1770839721752,"t_recv_wall_ms":1770839721663,"t_recv_wall_iso":"2026-02-11T19:55:21.663Z","t_recv_mono_ns":618587004098541,"raw":{"market":"0x8032d8355d335c6ccbfc2508d99fbc87eb13f437bd275c93ee56fd1558e517ff","asset_id":"20773614133833886322101538939702011175545796528197617633926164254913649353392","bids":[{"price":"0.01","size":"30789.91"},{"price":"0.02","size":"10747.23"},{"price":"0.03","size":"315.37"}],"asks":[{"price":"0.99","size":"30822.26"},{"price":"0.98","size":"12559.04"},{"price":"0.97","size":"7433.03"},{"price":"0.96","size":"5453.8"},{"price":"0.95","size":"6815.8"},{"price":"0.94","size":"5105"},{"price":"0.93","size":"5421.38"},{"price":"0.92","size":"5139.4"},{"price":"0.91","size":"5225.8"},{"price":"0.9","size":"5102.8"},{"price":"0.89","size":"120.6"},{"price":"0.88","size":"63.6"},{"price":"0.87","size":"63"},{"price":"0.86","size":"61.6"},{"price":"0.85","size":"107.39"},{"price":"0.84","size":"69.39"},{"price":"0.83","size":"58.39"},{"price":"0.82","size":"66.71"},{"price":"0.81","size":"56.8"},{"price":"0.8","size":"92.14"},{"price":"0.79","size":"60.8"},{"price":"0.78","size":"55.2"},{"price":"0.77","size":"64.48"},{"price":"0.76","size":"54.2"},{"price":"0.75","size":"375.8"},{"price":"0.74","size":"68.6"},{"price":"0.73","size":"53.2"},{"price":"0.72","size":"63.26"},{"price":"0.71","size":"52.6"},{"price":"0.7","size":"402.4"},{"price":"0.69","size":"72.2"},{"price":"0.68","size":"87.88"},{"price":"0.67","size":"188.46"},{"price":"0.66","size":"123.6"},{"price":"0.65","size":"317.03"},{"price":"0.64","size":"582.36"},{"price":"0.63","size":"559.2"},{"price":"0.62","size":"559"},{"price":"0.61","size":"594"},{"price":"0.6","size":"2915.41"},{"price":"0.59","size":"576.8"},{"price":"0.58","size":"575.5"},{"price":"0.57","size":"558.6"},{"price":"0.56","size":"572.68"},{"price":"0.55","size":"566.4"},{"price":"0.54","size":"561.94"},{"price":"0.53","size":"631.57"},{"price":"0.52","size":"611.4"},{"price":"0.51","size":"705.2"},{"price":"0.5","size":"1011.55"},{"price":"0.49","size":"692.4"},{"price":"0.48","size":"628.4"},{"price":"0.47","size":"633.4"},{"price":"0.46","size":"711.65"},{"price":"0.45","size":"866.59"},{"price":"0.44","size":"905.69"},{"price":"0.43","size":"641.6"},{"price":"0.42","size":"645.58"},{"price":"0.41","size":"564"},{"price":"0.4","size":"20642.9"},{"price":"0.39","size":"650.23"},{"price":"0.38","size":"593"},{"price":"0.37","size":"755.73"},{"price":"0.36","size":"558"},{"price":"0.35","size":"1144.32"},{"price":"0.34","size":"649.59"},{"price":"0.33","size":"624.8"},{"price":"0.32","size":"574"},{"price":"0.31","size":"594.2"},{"price":"0.3","size":"735.66"},{"price":"0.29","size":"918.6"},{"price":"0.28","size":"356.8"},{"price":"0.27","size":"869.2"},{"price":"0.26","size":"967.6"},{"price":"0.25","size":"1673.8"},{"price":"0.24","size":"869.2"},{"price":"0.23","size":"884.6"},{"price":"0.22","size":"870.2"},{"price":"0.21","size":"871.6"},{"price":"0.2","size":"987.2"},{"price":"0.19","size":"876.8"},{"price":"0.18","size":"1096.55"},{"price":"0.17","size":"958.39"},{"price":"0.16","size":"1119.39"},{"price":"0.15","size":"1164.13"},{"price":"0.14","size":"962.6"},{"price":"0.13","size":"1046.8"},{"price":"0.12","size":"1055.55"},{"price":"0.11","size":"1124.49"},{"price":"0.1","size":"659.79"},{"price":"0.09","size":"889.6"},{"price":"0.08","size":"3419.35"},{"price":"0.07","size":"3335.43"},{"price":"0.06","size":"3186.34"},{"price":"0.05","size":"3304.45"},{"price":"0.04","size":"3710.97"}],"hash":"41a0e334faa7f8dcded9b41b57f8d61896c93eb9","timestamp":"1770839721752","event_type":"book","_sub_state":"active","_subscription_id":1,"_active_subscription_id":1},"parse_warnings":[],"out_of_order":false}
{"run_id":"29526913bab7446286864a321c124486","channel":"market","event_type":"book","market":"0x8032d8355d335c6ccbfc2508d99fbc87eb13f437bd275c93ee56fd1558e517ff","asset_id":"40652734036737240317526188612064032143639112324786051284480877037991580442979","source":"market_ws:sub:active:1","t_event_ms":1770839721752,"t_recv_wall_ms":1770839721664,"t_recv_wall_iso":"2026-02-11T19:55:21.664Z","t_recv_mono_ns":618587005284125,"raw":{"market":"0x8032d8355d335c6ccbfc2508d99fbc87eb13f437bd275c93ee56fd1558e517ff","asset_id":"40652734036737240317526188612064032143639112324786051284480877037991580442979","bids":[{"price":"0.01","size":"30822.26"},{"price":"0.02","size":"12559.04"},{"price":"0.03","size":"7433.03"},{"price":"0.04","size":"5453.8"},{"price":"0.05","size":"6815.8"},{"price":"0.06","size":"5105"},{"price":"0.07","size":"5421.38"},{"price":"0.08","size":"5139.4"},{"price":"0.09","size":"5225.8"},{"price":"0.1","size":"5102.8"},{"price":"0.11","size":"120.6"},{"price":"0.12","size":"63.6"},{"price":"0.13","size":"63"},{"price":"0.14","size":"61.6"},{"price":"0.15","size":"107.39"},{"price":"0.16","size":"69.39"},{"price":"0.17","size":"58.39"},{"price":"0.18","size":"66.71"},{"price":"0.19","size":"56.8"},{"price":"0.2","size":"92.14"},{"price":"0.21","size":"60.8"},{"price":"0.22","size":"55.2"},{"price":"0.23","size":"64.48"},{"price":"0.24","size":"54.2"},{"price":"0.25","size":"375.8"},{"price":"0.26","size":"68.6"},{"price":"0.27","size":"53.2"},{"price":"0.28","size":"63.26"},{"price":"0.29","size":"52.6"},{"price":"0.3","size":"402.4"},{"price":"0.31","size":"72.2"},{"price":"0.32","size":"87.88"},{"price":"0.33","size":"188.46"},{"price":"0.34","size":"123.6"},{"price":"0.35","size":"317.03"},{"price":"0.36","size":"582.36"},{"price":"0.37","size":"559.2"},{"price":"0.38","size":"559"},{"price":"0.39","size":"594"},{"price":"0.4","size":"2915.41"},{"price":"0.41","size":"576.8"},{"price":"0.42","size":"575.5"},{"price":"0.43","size":"558.6"},{"price":"0.44","size":"572.68"},{"price":"0.45","size":"566.4"},{"price":"0.46","size":"561.94"},{"price":"0.47","size":"631.57"},{"price":"0.48","size":"611.4"},{"price":"0.49","size":"705.2"},{"price":"0.5","size":"1011.55"},{"price":"0.51","size":"692.4"},{"price":"0.52","size":"628.4"},{"price":"0.53","size":"633.4"},{"price":"0.54","size":"711.65"},{"price":"0.55","size":"866.59"},{"price":"0.56","size":"905.69"},{"price":"0.57","size":"641.6"},{"price":"0.58","size":"645.58"},{"price":"0.59","size":"564"},{"price":"0.6","size":"20642.9"},{"price":"0.61","size":"650.23"},{"price":"0.62","size":"593"},{"price":"0.63","size":"755.73"},{"price":"0.64","size":"558"},{"price":"0.65","size":"1144.32"},{"price":"0.66","size":"649.59"},{"price":"0.67","size":"624.8"},{"price":"0.68","size":"574"},{"price":"0.69","size":"594.2"},{"price":"0.7","size":"735.66"},{"price":"0.71","size":"918.6"},{"price":"0.72","size":"356.8"},{"price":"0.73","size":"869.2"},{"price":"0.74","size":"967.6"},{"price":"0.75","size":"1673.8"},{"price":"0.76","size":"869.2"},{"price":"0.77","size":"884.6"},{"price":"0.78","size":"870.2"},{"price":"0.79","size":"871.6"},{"price":"0.8","size":"987.2"},{"price":"0.81","size":"876.8"},{"price":"0.82","size":"1096.55"},{"price":"0.83","size":"958.39"},{"price":"0.84","size":"1119.39"},{"price":"0.85","size":"1164.13"},{"price":"0.86","size":"962.6"},{"price":"0.87","size":"1046.8"},{"price":"0.88","size":"1055.55"},{"price":"0.89","size":"1124.49"},{"price":"0.9","size":"659.79"},{"price":"0.91","size":"889.6"},{"price":"0.92","size":"3419.35"},{"price":"0.93","size":"3335.43"},{"price":"0.94","size":"3186.34"},{"price":"0.95","size":"3304.45"},{"price":"0.96","size":"3710.97"}],"asks":[{"price":"0.99","size":"30789.91"},{"price":"0.98","size":"10747.23"},{"price":"0.97","size":"315.37"}],"hash":"486a3383858e1ea927582f987b8ed84a5ee6153c","timestamp":"1770839721752","event_type":"book","_sub_state":"active","_subscription_id":1,"_active_subscription_id":1},"parse_warnings":[],"out_of_order":false}
{"run_id":"29526913bab7446286864a321c124486","channel":"market","event_type":"price_change","market":"0x8032d8355d335c6ccbfc2508d99fbc87eb13f437bd275c93ee56fd1558e517ff","asset_id":null,"source":"market_ws:sub:active:1","t_event_ms":1770839721754,"t_recv_wall_ms":1770839721665,"t_recv_wall_iso":"2026-02-11T19:55:21.665Z","t_recv_mono_ns":618587006069583,"raw":{"market":"0x8032d8355d335c6ccbfc2508d99fbc87eb13f437bd275c93ee56fd1558e517ff","price_changes":[{"asset_id":"40652734036737240317526188612064032143639112324786051284480877037991580442979","price":"0.94","size":"3181.34","side":"BUY","hash":"ecd4eed740d6c3f92af7892ea59da34f28d4cb4a","best_bid":"0.96","best_ask":"0.97"},{"asset_id":"20773614133833886322101538939702011175545796528197617633926164254913649353392","price":"0.06","size":"3181.34","side":"SELL","hash":"2cb2467f85fc5aeff81dce4c5293bfc321cbc9ba","best_bid":"0.03","best_ask":"0.04"}],"timestamp":"1770839721754","event_type":"price_change","_sub_state":"active","_subscription_id":1,"_active_subscription_id":1},"parse_warnings":[],"out_of_order":false}
{"run_id":"29526913bab7446286864a321c124486","channel":"market","event_type":"last_trade_price","market":"0x8032d8355d335c6ccbfc2508d99fbc87eb13f437bd275c93ee56fd1558e517ff","asset_id":"40652734036737240317526188612064032143639112324786051284480877037991580442979","source":"market_ws:sub:unknown","t_event_ms":1770839721783,"t_recv_wall_ms":1770839721689,"t_recv_wall_iso":"2026-02-11T19:55:21.689Z","t_recv_mono_ns":618587030288041,"raw":{"market":"0x8032d8355d335c6ccbfc2508d99fbc87eb13f437bd275c93ee56fd1558e517ff","asset_id":"40652734036737240317526188612064032143639112324786051284480877037991580442979","price":"0.97","size":"4.082473","fee_rate_bps":"1000","side":"BUY","timestamp":"1770839721783","event_type":"last_trade_price","transaction_hash":"0x5e82113c6f067ae13efa336e57466165c55d11661fc1e9a5ae9f7e82589392d7","_sub_state":"unknown","_subscription_id":null,"_active_subscription_id":1},"parse_warnings":["unknown_message_schema"],"out_of_order":false}
{"run_id":"29526913bab7446286864a321c124486","channel":"market","event_type":"price_change","market":"0x8032d8355d335c6ccbfc2508d99fbc87eb13f437bd275c93ee56fd1558e517ff","asset_id":null,"source":"market_ws:sub:active:1","t_event_ms":1770839721784,"t_recv_wall_ms":1770839721689,"t_recv_wall_iso":"2026-02-11T19:55:21.689Z","t_recv_mono_ns":618587030729583,"raw":{"market":"0x8032d8355d335c6ccbfc2508d99fbc87eb13f437bd275c93ee56fd1558e517ff","price_changes":[{"asset_id":"40652734036737240317526188612064032143639112324786051284480877037991580442979","price":"0.82","size":"1091.55","side":"BUY","hash":"fbb5696a9cb160b357a4201471883ae5b3517945","best_bid":"0.96","best_ask":"0.97"},{"asset_id":"20773614133833886322101538939702011175545796528197617633926164254913649353392","price":"0.18","size":"1091.55","side":"SELL","hash":"79626b0e161f628639fe79a9dc288af9acdd889d","best_bid":"0.03","best_ask":"0.04"}],"timestamp":"1770839721784","event_type":"price_change","_sub_state":"active","_subscription_id":1,"_active_subscription_id":1},"parse_warnings":[],"out_of_order":false}
{"run_id":"29526913bab7446286864a321c124486","channel":"market","event_type":"price_change","market":"0x8032d8355d335c6ccbfc2508d99fbc87eb13f437bd275c93ee56fd1558e517ff","asset_id":null,"source":"market_ws:sub:active:1","t_event_ms":1770839721787,"t_recv_wall_ms":1770839721701,"t_recv_wall_iso":"2026-02-11T19:55:21.701Z","t_recv_mono_ns":618587042022500,"raw":{"market":"0x8032d8355d335c6ccbfc2508d99fbc87eb13f437bd275c93ee56fd1558e517ff","price_changes":[{"asset_id":"40652734036737240317526188612064032143639112324786051284480877037991580442979","price":"0.98","size":"10752.23","side":"SELL","hash":"e65de9ca53a3b2447ab00665b7a01a7f07704deb","best_bid":"0.96","best_ask":"0.97"},{"asset_id":"20773614133833886322101538939702011175545796528197617633926164254913649353392","price":"0.02","size":"10752.23","side":"BUY","hash":"40c3d201140b26b8ca4be50cbe5d6bcccd74d09e","best_bid":"0.03","best_ask":"0.04"}],"timestamp":"1770839721787","event_type":"price_change","_sub_state":"active","_subscription_id":1,"_active_subscription_id":1},"parse_warnings":[],"out_of_order":false}
{"run_id":"29526913bab7446286864a321c124486","channel":"market","event_type":"price_change","market":"0x8032d8355d335c6ccbfc2508d99fbc87eb13f437bd275c93ee56fd1558e517ff","asset_id":null,"source":"market_ws:sub:active:1","t_event_ms":1770839721808,"t_recv_wall_ms":1770839721719,"t_recv_wall_iso":"2026-02-11T19:55:21.719Z","t_recv_mono_ns":618587060679500,"raw":{"market":"0x8032d8355d335c6ccbfc2508d99fbc87eb13f437bd275c93ee56fd1558e517ff","price_changes":[{"asset_id":"20773614133833886322101538939702011175545796528197617633926164254913649353392","price":"0.03","size":"321.37","side":"BUY","hash":"7b2864afe616c367132a2dd685a4879bb1cc6deb","best_bid":"0.03","best_ask":"0.04"},{"asset_id":"40652734036737240317526188612064032143639112324786051284480877037991580442979","price":"0.97","size":"321.37","side":"SELL","hash":"b61c1e5b24a5b5aa1b3826f96af08d3a5663d020","best_bid":"0.96","best_ask":"0.97"}],"timestamp":"1770839721808","event_type":"price_change","_sub_state":"active","_subscription_id":1,"_active_subscription_id":1},"parse_warnings":[],"out_of_order":false}
{"run_id":"29526913bab7446286864a321c124486","channel":"market","event_type":"price_change","market":"0x8032d8355d335c6ccbfc2508d99fbc87eb13f437bd275c93ee56fd1558e517ff","asset_id":null,"source":"market_ws:sub:active:1","t_event_ms":1770839721809,"t_recv_wall_ms":1770839721720,"t_recv_wall_iso":"2026-02-11T19:55:21.720Z","t_recv_mono_ns":618587061197625,"raw":{"market":"0x8032d8355d335c6ccbfc2508d99fbc87eb13f437bd275c93ee56fd1558e517ff","price_changes":[{"asset_id":"40652734036737240317526188612064032143639112324786051284480877037991580442979","price":"0.94","size":"3187.34","side":"BUY","hash":"dc2dd53f0b212457a6c28bdc292658406ecbb9d3","best_bid":"0.96","best_ask":"0.97"},{"asset_id":"20773614133833886322101538939702011175545796528197617633926164254913649353392","price":"0.06","size":"3187.34","side":"SELL","hash":"e7c4d98bc82b2760800c332bab0687934679503e","best_bid":"0.03","best_ask":"0.04"}],"timestamp":"1770839721809","event_type":"price_change","_sub_state":"active","_subscription_id":1,"_active_subscription_id":1},"parse_warnings":[],"out_of_order":false}
{"run_id":"29526913bab7446286864a321c124486","channel":"market","event_type":"price_change","market":"0x8032d8355d335c6ccbfc2508d99fbc87eb13f437bd275c93ee56fd1558e517ff","asset_id":null,"source":"market_ws:sub:active:1","t_event_ms":1770839721811,"t_recv_wall_ms":1770839721720,"t_recv_wall_iso":"2026-02-11T19:55:21.720Z","t_recv_mono_ns":618587061405583,"raw":{"market":"0x8032d8355d335c6ccbfc2508d99fbc87eb13f437bd275c93ee56fd1558e517ff","price_changes":[{"asset_id":"40652734036737240317526188612064032143639112324786051284480877037991580442979","price":"0.94","size":"3192.34","side":"BUY","hash":"2d390cbc4bd93061edc089573ef0b43372e3c053","best_bid":"0.96","best_ask":"0.97"},{"asset_id":"20773614133833886322101538939702011175545796528197617633926164254913649353392","price":"0.06","size":"3192.34","side":"SELL","hash":"870a23ab40c196e4b0a51f649ea15cbdfbf48e7f","best_bid":"0.03","best_ask":"0.04"}],"timestamp":"1770839721811","event_type":"price_change","_sub_state":"active","_subscription_id":1,"_active_subscription_id":1},"parse_warnings":[],"out_of_order":false}
{"run_id":"29526913bab7446286864a321c124486","channel":"market","event_type":"price_change","market":"0x8032d8355d335c6ccbfc2508d99fbc87eb13f437bd275c93ee56fd1558e517ff","asset_id":null,"source":"market_ws:sub:active:1","t_event_ms":1770839721823,"t_recv_wall_ms":1770839721728,"t_recv_wall_iso":"2026-02-11T19:55:21.728Z","t_recv_mono_ns":618587069467958,"raw":{"market":"0x8032d8355d335c6ccbfc2508d99fbc87eb13f437bd275c93ee56fd1558e517ff","price_changes":[{"asset_id":"40652734036737240317526188612064032143639112324786051284480877037991580442979","price":"0.95","size":"3364.45","side":"BUY","hash":"b1b6856f8b29e260a59d1bb3579d866fd7c18175","best_bid":"0.96","best_ask":"0.97"},{"asset_id":"20773614133833886322101538939702011175545796528197617633926164254913649353392","price":"0.05","size":"3364.45","side":"SELL","hash":"7f71a5b2bc252fc7cbf7cc0b2123c1872c5b9d2c","best_bid":"0.03","best_ask":"0.04"}],"timestamp":"1770839721823","event_type":"price_change","_sub_state":"active","_subscription_id":1,"_active_subscription_id":1},"parse_warnings":[],"out_of_order":false}
{"run_id":"29526913bab7446286864a321c124486","channel":"market","event_type":"price_change","market":"0x8032d8355d335c6ccbfc2508d99fbc87eb13f437bd275c93ee56fd1558e517ff","asset_id":null,"source":"market_ws:sub:active:1","t_event_ms":1770839721824,"t_recv_wall_ms":1770839721729,"t_recv_wall_iso":"2026-02-11T19:55:21.729Z","t_recv_mono_ns":618587069926583,"raw":{"market":"0x8032d8355d335c6ccbfc2508d99fbc87eb13f437bd275c93ee56fd1558e517ff","price_changes":[{"asset_id":"40652734036737240317526188612064032143639112324786051284480877037991580442979","price":"0.96","size":"3650.97","side":"BUY","hash":"1dbf4e3729a8d4880e1206fc3c0012da7dbdf1e2","best_bid":"0.96","best_ask":"0.97"},{"asset_id":"20773614133833886322101538939702011175545796528197617633926164254913649353392","price":"0.04","size":"3650.97","side":"SELL","hash":"6ba36337b4e0a7d01551bdf243dc61de955fc680","best_bid":"0.03","best_ask":"0.04"}],"timestamp":"1770839721824","event_type":"price_change","_sub_state":"active","_subscription_id":1,"_active_subscription_id":1},"parse_warnings":[],"out_of_order":false}
{"run_id":"29526913bab7446286864a321c124486","channel":"market","event_type":"price_change","market":"0x8032d8355d335c6ccbfc2508d99fbc87eb13f437bd275c93ee56fd1558e517ff","asset_id":null,"source":"market_ws:sub:active:1","t_event_ms":1770839721887,"t_recv_wall_ms":1770839721798,"t_recv_wall_iso":"2026-02-11T19:55:21.798Z","t_recv_mono_ns":618587139137041,"raw":{"market":"0x8032d8355d335c6ccbfc2508d99fbc87eb13f437bd275c93ee56fd1558e517ff","price_changes":[{"asset_id":"40652734036737240317526188612064032143639112324786051284480877037991580442979","price":"0.82","size":"1096.55","side":"BUY","hash":"77301c5dda3dbbfe2dda5f4ef62e9d17c2a7318c","best_bid":"0.96","best_ask":"0.97"},{"asset_id":"20773614133833886322101538939702011175545796528197617633926164254913649353392","price":"0.18","size":"1096.55","side":"SELL","hash":"c1381e9c7a7a18a02ad082f7d6f8e26731e3226b","best_bid":"0.03","best_ask":"0.04"}],"timestamp":"1770839721887","event_type":"price_change","_sub_state":"active","_subscription_id":1,"_active_subscription_id":1},"parse_warnings":[],"out_of_order":false}
{"run_id":"29526913bab7446286864a321c124486","channel":"market","event_type":"price_change","market":"0x8032d8355d335c6ccbfc2508d99fbc87eb13f437bd275c93ee56fd1558e517ff","asset_id":null,"source":"market_ws:sub:active:1","t_event_ms":1770839721919,"t_recv_wall_ms":1770839721824,"t_recv_wall_iso":"2026-02-11T19:55:21.824Z","t_recv_mono_ns":618587165709916,"raw":{"market":"0x8032d8355d335c6ccbfc2508d99fbc87eb13f437bd275c93ee56fd1558e517ff","price_changes":[{"asset_id":"40652734036737240317526188612064032143639112324786051284480877037991580442979","price":"0.95","size":"3304.45","side":"BUY","hash":"f7bbd2fbcb233ec4fca54df272d911a147d5eac1","best_bid":"0.96","best_ask":"0.97"},{"asset_id":"20773614133833886322101538939702011175545796528197617633926164254913649353392","price":"0.05","size":"3304.45","side":"SELL","hash":"975fe657b1992acedd8e30a867d8e8a4dcb056eb","best_bid":"0.03","best_ask":"0.04"}],"timestamp":"1770839721919","event_type":"price_change","_sub_state":"active","_subscription_id":1,"_active_subscription_id":1},"parse_warnings":[],"out_of_order":false}
{"run_id":"29526913bab7446286864a321c124486","channel":"market","event_type":"price_change","market":"0x8032d8355d335c6ccbfc2508d99fbc87eb13f437bd275c93ee56fd1558e517ff","asset_id":null,"source":"market_ws:sub:active:1","t_event_ms":1770839721921,"t_recv_wall_ms":1770839721825,"t_recv_wall_iso":"2026-02-11T19:55:21.825Z","t_recv_mono_ns":618587166551958,"raw":{"market":"0x8032d8355d335c6ccbfc2508d99fbc87eb13f437bd275c93ee56fd1558e517ff","price_changes":[{"asset_id":"40652734036737240317526188612064032143639112324786051284480877037991580442979","price":"0.96","size":"3710.97","side":"BUY","hash":"67cdd2b8cb4345dc18fc4106969000631d214d54","best_bid":"0.96","best_ask":"0.97"},{"asset_id":"20773614133833886322101538939702011175545796528197617633926164254913649353392","price":"0.04","size":"3710.97","side":"SELL","hash":"3aedabcc3d17f532de232200a477022b58b7a1b4","best_bid":"0.03","best_ask":"0.04"}],"timestamp":"1770839721921","event_type":"price_change","_sub_state":"active","_subscription_id":1,"_active_subscription_id":1},"parse_warnings":[],"out_of_order":false}
{"run_id":"29526913bab7446286864a321c124486","channel":"market","event_type":"price_change","market":"0x8032d8355d335c6ccbfc2508d99fbc87eb13f437bd275c93ee56fd1558e517ff","asset_id":null,"source":"market_ws:sub:active:1","t_event_ms":1770839721985,"t_recv_wall_ms":1770839721893,"t_recv_wall_iso":"2026-02-11T19:55:21.893Z","t_recv_mono_ns":618587234679250,"raw":{"market":"0x8032d8355d335c6ccbfc2508d99fbc87eb13f437bd275c93ee56fd1558e517ff","price_changes":[{"asset_id":"40652734036737240317526188612064032143639112324786051284480877037991580442979","price":"0.82","size":"1091.55","side":"BUY","hash":"29f4628e3b30294fd90c8f03f7228c88c7c42334","best_bid":"0.96","best_ask":"0.97"},{"asset_id":"20773614133833886322101538939702011175545796528197617633926164254913649353392","price":"0.18","size":"1091.55","side":"SELL","hash":"8c10652f82da847eb1d670ade17409f129b57cca","best_bid":"0.03","best_ask":"0.04"}],"timestamp":"1770839721985","event_type":"price_change","_sub_state":"active","_subscription_id":1,"_active_subscription_id":1},"parse_warnings":[],"out_of_order":false}
{"run_id":"29526913bab7446286864a321c124486","channel":"market","event_type":"price_change","market":"0x8032d8355d335c6ccbfc2508d99fbc87eb13f437bd275c93ee56fd1558e517ff","asset_id":null,"source":"market_ws:sub:active:1","t_event_ms":1770839722035,"t_recv_wall_ms":1770839721941,"t_recv_wall_iso":"2026-02-11T19:55:21.941Z","t_recv_mono_ns":618587281928583,"raw":{"market":"0x8032d8355d335c6ccbfc2508d99fbc87eb13f437bd275c93ee56fd1558e517ff","price_changes":[{"asset_id":"40652734036737240317526188612064032143639112324786051284480877037991580442979","price":"0.94","size":"3187.34","side":"BUY","hash":"6a4fd1ebda4242512c9a7fe0bf12aa61b2910a38","best_bid":"0.96","best_ask":"0.97"},{"asset_id":"20773614133833886322101538939702011175545796528197617633926164254913649353392","price":"0.06","size":"3187.34","side":"SELL","hash":"8f57630a4d4cc68f357e82e18aa89edde3a280ae","best_bid":"0.03","best_ask":"0.04"}],"timestamp":"1770839722035","event_type":"price_change","_sub_state":"active","_subscription_id":1,"_active_subscription_id":1},"parse_warnings":[],"out_of_order":false}
{"run_id":"29526913bab7446286864a321c124486","channel":"market","event_type":"price_change","market":"0x8032d8355d335c6ccbfc2508d99fbc87eb13f437bd275c93ee56fd1558e517ff","asset_id":null,"source":"market_ws:sub:active:1","t_event_ms":1770839722044,"t_recv_wall_ms":1770839721958,"t_recv_wall_iso":"2026-02-11T19:55:21.958Z","t_recv_mono_ns":618587298784166,"raw":{"market":"0x8032d8355d335c6ccbfc2508d99fbc87eb13f437bd275c93ee56fd1558e517ff","price_changes":[{"asset_id":"20773614133833886322101538939702011175545796528197617633926164254913649353392","price":"0.03","size":"276.82","side":"BUY","hash":"c98a2dafa4add83e1581e4dc3548ac6032dd8701","best_bid":"0.03","best_ask":"0.04"},{"asset_id":"40652734036737240317526188612064032143639112324786051284480877037991580442979","price":"0.97","size":"276.82","side":"SELL","hash":"99644bd1fd216b8d24e4daba8399d5d68d856297","best_bid":"0.96","best_ask":"0.97"}],"timestamp":"1770839722044","event_type":"price_change","_sub_state":"active","_subscription_id":1,"_active_subscription_id":1},"parse_warnings":[],"out_of_order":false}
{"run_id":"29526913bab7446286864a321c124486","channel":"market","event_type":"price_change","market":"0x8032d8355d335c6ccbfc2508d99fbc87eb13f437bd275c93ee56fd1558e517ff","asset_id":null,"source":"market_ws:sub:active:1","t_event_ms":1770839722044,"t_recv_wall_ms":1770839721958,"t_recv_wall_iso":"2026-02-11T19:55:21.958Z","t_recv_mono_ns":618587299391375,"raw":{"market":"0x8032d8355d335c6ccbfc2508d99fbc87eb13f437bd275c93ee56fd1558e517ff","price_changes":[{"asset_id":"40652734036737240317526188612064032143639112324786051284480877037991580442979","price":"0.97","size":"276.82","side":"SELL","hash":"99644bd1fd216b8d24e4daba8399d5d68d856297","best_bid":"0.96","best_ask":"0.97"},{"asset_id":"20773614133833886322101538939702011175545796528197617633926164254913649353392","price":"0.03","size":"276.82","side":"BUY","hash":"c98a2dafa4add83e1581e4dc3548ac6032dd8701","best_bid":"0.03","best_ask":"0.04"}],"timestamp":"1770839722044","event_type":"price_change","_sub_state":"active","_subscription_id":1,"_active_subscription_id":1},"parse_warnings":[],"out_of_order":false}
{"run_id":"29526913bab7446286864a321c124486","channel":"market","event_type":"book","market":"0x8032d8355d335c6ccbfc2508d99fbc87eb13f437bd275c93ee56fd1558e517ff","asset_id":"20773614133833886322101538939702011175545796528197617633926164254913649353392","source":"market_ws:sub:active:1","t_event_ms":1770839722044,"t_recv_wall_ms":1770839721958,"t_recv_wall_iso":"2026-02-11T19:55:21.958Z","t_recv_mono_ns":618587299698833,"raw":{"market":"0x8032d8355d335c6ccbfc2508d99fbc87eb13f437bd275c93ee56fd1558e517ff","asset_id":"20773614133833886322101538939702011175545796528197617633926164254913649353392","bids":[{"price":"0.01","size":"30789.91"},{"price":"0.02","size":"10752.23"},{"price":"0.03","size":"276.82"}],"asks":[{"price":"0.99","size":"30822.26"},{"price":"0.98","size":"12559.04"},{"price":"0.97","size":"7433.03"},{"price":"0.96","size":"5453.8"},{"price":"0.95","size":"6815.8"},{"price":"0.94","size":"5105"},{"price":"0.93","size":"5421.38"},{"price":"0.92","size":"5139.4"},{"price":"0.91","size":"5225.8"},{"price":"0.9","size":"5102.8"},{"price":"0.89","size":"120.6"},{"price":"0.88","size":"63.6"},{"price":"0.87","size":"63"},{"price":"0.86","size":"61.6"},{"price":"0.85","size":"107.39"},{"price":"0.84","size":"69.39"},{"price":"0.83","size":"58.39"},{"price":"0.82","size":"66.71"},{"price":"0.81","size":"56.8"},{"price":"0.8","size":"92.14"},{"price":"0.79","size":"60.8"},{"price":"0.78","size":"55.2"},{"price":"0.77","size":"64.48"},{"price":"0.76","size":"54.2"},{"price":"0.75","size":"375.8"},{"price":"0.74","size":"68.6"},{"price":"0.73","size":"53.2"},{"price":"0.72","size":"63.26"},{"price":"0.71","size":"52.6"},{"price":"0.7","size":"402.4"},{"price":"0.69","size":"72.2"},{"price":"0.68","size":"87.88"},{"price":"0.67","size":"188.46"},{"price":"0.66","size":"123.6"},{"price":"0.65","size":"317.03"},{"price":"0.64","size":"582.36"},{"price":"0.63","size":"559.2"},{"price":"0.62","size":"559"},{"price":"0.61","size":"594"},{"price":"0.6","size":"2915.41"},{"price":"0.59","size":"576.8"},{"price":"0.58","size":"575.5"},{"price":"0.57","size":"558.6"},{"price":"0.56","size":"572.68"},{"price":"0.55","size":"566.4"},{"price":"0.54","size":"561.94"},{"price":"0.53","size":"631.57"},{"price":"0.52","size":"611.4"},{"price":"0.51","size":"705.2"},{"price":"0.5","size":"1011.55"},{"price":"0.49","size":"692.4"},{"price":"0.48","size":"628.4"},{"price":"0.47","size":"633.4"},{"price":"0.46","size":"711.65"},{"price":"0.45","size":"866.59"},{"price":"0.44","size":"905.69"},{"price":"0.43","size":"641.6"},{"price":"0.42","size":"645.58"},{"price":"0.41","size":"564"},{"price":"0.4","size":"20642.9"},{"price":"0.39","size":"650.23"},{"price":"0.38","size":"593"},{"price":"0.37","size":"755.73"},{"price":"0.36","size":"558"},{"price":"0.35","size":"1144.32"},{"price":"0.34","size":"649.59"},{"price":"0.33","size":"624.8"},{"price":"0.32","size":"574"},{"price":"0.31","size":"594.2"},{"price":"0.3","size":"735.66"},{"price":"0.29","size":"918.6"},{"price":"0.28","size":"356.8"},{"price":"0.27","size":"869.2"},{"price":"0.26","size":"967.6"},{"price":"0.25","size":"1673.8"},{"price":"0.24","size":"869.2"},{"price":"0.23","size":"884.6"},{"price":"0.22","size":"870.2"},{"price":"0.21","size":"871.6"},{"price":"0.2","size":"987.2"},{"price":"0.19","size":"876.8"},{"price":"0.18","size":"1091.55"},{"price":"0.17","size":"958.39"},{"price":"0.16","size":"1119.39"},{"price":"0.15","size":"1164.13"},{"price":"0.14","size":"962.6"},{"price":"0.13","size":"1046.8"},{"price":"0.12","size":"1055.55"},{"price":"0.11","size":"1124.49"},{"price":"0.1","size":"659.79"},{"price":"0.09","size":"889.6"},{"price":"0.08","size":"3419.35"},{"price":"0.07","size":"3335.43"},{"price":"0.06","size":"3187.34"},{"price":"0.05","size":"3304.45"},{"price":"0.04","size":"3710.97"}],"hash":"c98a2dafa4add83e1581e4dc3548ac6032dd8701","timestamp":"1770839722044","event_type":"book","_sub_state":"active","_subscription_id":1,"_active_subscription_id":1},"parse_warnings":[],"out_of_order":false}
{"run_id":"29526913bab7446286864a321c124486","channel":"market","event_type":"book","market":"0x8032d8355d335c6ccbfc2508d99fbc87eb13f437bd275c93ee56fd1558e517ff","asset_id":"40652734036737240317526188612064032143639112324786051284480877037991580442979","source":"market_ws:sub:active:1","t_event_ms":1770839722044,"t_recv_wall_ms":1770839721959,"t_recv_wall_iso":"2026-02-11T19:55:21.959Z","t_recv_mono_ns":618587300607583,"raw":{"market":"0x8032d8355d335c6ccbfc2508d99fbc87eb13f437bd275c93ee56fd1558e517ff","asset_id":"40652734036737240317526188612064032143639112324786051284480877037991580442979","bids":[{"price":"0.01","size":"30822.26"},{"price":"0.02","size":"12559.04"},{"price":"0.03","size":"7433.03"},{"price":"0.04","size":"5453.8"},{"price":"0.05","size":"6815.8"},{"price":"0.06","size":"5105"},{"price":"0.07","size":"5421.38"},{"price":"0.08","size":"5139.4"},{"price":"0.09","size":"5225.8"},{"price":"0.1","size":"5102.8"},{"price":"0.11","size":"120.6"},{"price":"0.12","size":"63.6"},{"price":"0.13","size":"63"},{"price":"0.14","size":"61.6"},{"price":"0.15","size":"107.39"},{"price":"0.16","size":"69.39"},{"price":"0.17","size":"58.39"},{"price":"0.18","size":"66.71"},{"price":"0.19","size":"56.8"},{"price":"0.2","size":"92.14"},{"price":"0.21","size":"60.8"},{"price":"0.22","size":"55.2"},{"price":"0.23","size":"64.48"},{"price":"0.24","size":"54.2"},{"price":"0.25","size":"375.8"},{"price":"0.26","size":"68.6"},{"price":"0.27","size":"53.2"},{"price":"0.28","size":"63.26"},{"price":"0.29","size":"52.6"},{"price":"0.3","size":"402.4"},{"price":"0.31","size":"72.2"},{"price":"0.32","size":"87.88"},{"price":"0.33","size":"188.46"},{"price":"0.34","size":"123.6"},{"price":"0.35","size":"317.03"},{"price":"0.36","size":"582.36"},{"price":"0.37","size":"559.2"},{"price":"0.38","size":"559"},{"price":"0.39","size":"594"},{"price":"0.4","size":"2915.41"},{"price":"0.41","size":"576.8"},{"price":"0.42","size":"575.5"},{"price":"0.43","size":"558.6"},{"price":"0.44","size":"572.68"},{"price":"0.45","size":"566.4"},{"price":"0.46","size":"561.94"},{"price":"0.47","size":"631.57"},{"price":"0.48","size":"611.4"},{"price":"0.49","size":"705.2"},{"price":"0.5","size":"1011.55"},{"price":"0.51","size":"692.4"},{"price":"0.52","size":"628.4"},{"price":"0.53","size":"633.4"},{"price":"0.54","size":"711.65"},{"price":"0.55","size":"866.59"},{"price":"0.56","size":"905.69"},{"price":"0.57","size":"641.6"},{"price":"0.58","size":"645.58"},{"price":"0.59","size":"564"},{"price":"0.6","size":"20642.9"},{"price":"0.61","size":"650.23"},{"price":"0.62","size":"593"},{"price":"0.63","size":"755.73"},{"price":"0.64","size":"558"},{"price":"0.65","size":"1144.32"},{"price":"0.66","size":"649.59"},{"price":"0.67","size":"624.8"},{"price":"0.68","size":"574"},{"price":"0.69","size":"594.2"},{"price":"0.7","size":"735.66"},{"price":"0.71","size":"918.6"},{"price":"0.72","size":"356.8"},{"price":"0.73","size":"869.2"},{"price":"0.74","size":"967.6"},{"price":"0.75","size":"1673.8"},{"price":"0.76","size":"869.2"},{"price":"0.77","size":"884.6"},{"price":"0.78","size":"870.2"},{"price":"0.79","size":"871.6"},{"price":"0.8","size":"987.2"},{"price":"0.81","size":"876.8"},{"price":"0.82","size":"1091.55"},{"price":"0.83","size":"958.39"},{"price":"0.84","size":"1119.39"},{"price":"0.85","size":"1164.13"},{"price":"0.86","size":"962.6"},{"price":"0.87","size":"1046.8"},{"price":"0.88","size":"1055.55"},{"price":"0.89","size":"1124.49"},{"price":"0.9","size":"659.79"},{"price":"0.91","size":"889.6"},{"price":"0.92","size":"3419.35"},{"price":"0.93","size":"3335.43"},{"price":"0.94","size":"3187.34"},{"price":"0.95","size":"3304.45"},{"price":"0.96","size":"3710.97"}],"asks":[{"price":"0.99","size":"30789.91"},{"price":"0.98","size":"10752.23"},{"price":"0.97","size":"276.82"}],"hash":"99644bd1fd216b8d24e4daba8399d5d68d856297","timestamp":"1770839722044","event_type":"book","_sub_state":"active","_subscription_id":1,"_active_subscription_id":1},"parse_warnings":[],"out_of_order":false}
{"run_id":"29526913bab7446286864a321c124486","channel":"market","event_type":"last_trade_price","market":"0x8032d8355d335c6ccbfc2508d99fbc87eb13f437bd275c93ee56fd1558e517ff","asset_id":"40652734036737240317526188612064032143639112324786051284480877037991580442979","source":"market_ws:sub:unknown","t_event_ms":1770839722075,"t_recv_wall_ms":1770839721990,"t_recv_wall_iso":"2026-02-11T19:55:21.990Z","t_recv_mono_ns":618587330865625,"raw":{"market":"0x8032d8355d335c6ccbfc2508d99fbc87eb13f437bd275c93ee56fd1558e517ff","asset_id":"40652734036737240317526188612064032143639112324786051284480877037991580442979","price":"0.97","size":"44.55","fee_rate_bps":"1000","side":"BUY","timestamp":"1770839722075","event_type":"last_trade_price","transaction_hash":"0x8b64b1bd69ebde4b64b52a2ed4e356b2e401fec867155b3d2ddce3e92d93319e","_sub_state":"unknown","_subscription_id":null,"_active_subscription_id":1},"parse_warnings":["unknown_message_schema"],"out_of_order":false}
{"run_id":"29526913bab7446286864a321c124486","channel":"market","event_type":"price_change","market":"0x8032d8355d335c6ccbfc2508d99fbc87eb13f437bd275c93ee56fd1558e517ff","asset_id":null,"source":"market_ws:sub:active:1","t_event_ms":1770839722088,"t_recv_wall_ms":1770839721994,"t_recv_wall_iso":"2026-02-11T19:55:21.994Z","t_recv_mono_ns":618587335577750,"raw":{"market":"0x8032d8355d335c6ccbfc2508d99fbc87eb13f437bd275c93ee56fd1558e517ff","price_changes":[{"asset_id":"40652734036737240317526188612064032143639112324786051284480877037991580442979","price":"0.82","size":"1096.55","side":"BUY","hash":"bfb1fc05b05ce2043b21f6173f06b4202c4580a0","best_bid":"0.96","best_ask":"0.97"},{"asset_id":"20773614133833886322101538939702011175545796528197617633926164254913649353392","price":"0.18","size":"1096.55","side":"SELL","hash":"869e2a52924db04ceadeb5bcc4c41f8f8ba71a0c","best_bid":"0.03","best_ask":"0.04"}],"timestamp":"1770839722088","event_type":"price_change","_sub_state":"active","_subscription_id":1,"_active_subscription_id":1},"parse_warnings":[],"out_of_order":false}
{"run_id":"29526913bab7446286864a321c124486","channel":"market","event_type":"price_change","market":"0x8032d8355d335c6ccbfc2508d99fbc87eb13f437bd275c93ee56fd1558e517ff","asset_id":null,"source":"market_ws:sub:active:1","t_event_ms":1770839722094,"t_recv_wall_ms":1770839721999,"t_recv_wall_iso":"2026-02-11T19:55:21.999Z","t_recv_mono_ns":618587340515958,"raw":{"market":"0x8032d8355d335c6ccbfc2508d99fbc87eb13f437bd275c93ee56fd1558e517ff","price_changes":[{"asset_id":"40652734036737240317526188612064032143639112324786051284480877037991580442979","price":"0.94","size":"3192.34","side":"BUY","hash":"83185f87367f11f064228ac93a033426144202ee","best_bid":"0.96","best_ask":"0.97"},{"asset_id":"20773614133833886322101538939702011175545796528197617633926164254913649353392","price":"0.06","size":"3192.34","side":"SELL","hash":"1c292c81cc7b8a8bbe9ee532d36ebe4a7e105f31","best_bid":"0.03","best_ask":"0.04"}],"timestamp":"1770839722094","event_type":"price_change","_sub_state":"active","_subscription_id":1,"_active_subscription_id":1},"parse_warnings":[],"out_of_order":false}
{"run_id":"29526913bab7446286864a321c124486","channel":"market","event_type":"price_change","market":"0x8032d8355d335c6ccbfc2508d99fbc87eb13f437bd275c93ee56fd1558e517ff","asset_id":null,"source":"market_ws:sub:active:1","t_event_ms":1770839722189,"t_recv_wall_ms":1770839722099,"t_recv_wall_iso":"2026-02-11T19:55:22.099Z","t_recv_mono_ns":618587440085666,"raw":{"market":"0x8032d8355d335c6ccbfc2508d99fbc87eb13f437bd275c93ee56fd1558e517ff","price_changes":[{"asset_id":"40652734036737240317526188612064032143639112324786051284480877037991580442979","price":"0.82","size":"1091.55","side":"BUY","hash":"0523d69cac244d6a5f745182728e03963bff9c1b","best_bid":"0.96","best_ask":"0.97"},{"asset_id":"20773614133833886322101538939702011175545796528197617633926164254913649353392","price":"0.18","size":"1091.55","side":"SELL","hash":"fae94a3ae7ee53960d50b2194b99a033285948c8","best_bid":"0.03","best_ask":"0.04"}],"timestamp":"1770839722189","event_type":"price_change","_sub_state":"active","_subscription_id":1,"_active_subscription_id":1},"parse_warnings":[],"out_of_order":false}
{"run_id":"29526913bab7446286864a321c124486","channel":"market","event_type":"price_change","market":"0x8032d8355d335c6ccbfc2508d99fbc87eb13f437bd275c93ee56fd1558e517ff","asset_id":null,"source":"market_ws:sub:active:1","t_event_ms":1770839722254,"t_recv_wall_ms":1770839722165,"t_recv_wall_iso":"2026-02-11T19:55:22.165Z","t_recv_mono_ns":618587506189375,"raw":{"market":"0x8032d8355d335c6ccbfc2508d99fbc87eb13f437bd275c93ee56fd1558e517ff","price_changes":[{"asset_id":"40652734036737240317526188612064032143639112324786051284480877037991580442979","price":"0.94","size":"3197.34","side":"BUY","hash":"1ae01e6ba5fd793924efcf0cdcee44d38cf05aff","best_bid":"0.96","best_ask":"0.97"},{"asset_id":"20773614133833886322101538939702011175545796528197617633926164254913649353392","price":"0.06","size":"3197.34","side":"SELL","hash":"9da3f8d1507d4061d61fd7a398a2810eeeb7fd41","best_bid":"0.03","best_ask":"0.04"}],"timestamp":"1770839722254","event_type":"price_change","_sub_state":"active","_subscription_id":1,"_active_subscription_id":1},"parse_warnings":[],"out_of_order":false}
{"run_id":"29526913bab7446286864a321c124486","channel":"market","event_type":"price_change","market":"0x8032d8355d335c6ccbfc2508d99fbc87eb13f437bd275c93ee56fd1558e517ff","asset_id":null,"source":"market_ws:sub:active:1","t_event_ms":1770839722272,"t_recv_wall_ms":1770839722188,"t_recv_wall_iso":"2026-02-11T19:55:22.188Z","t_recv_mono_ns":618587529203416,"raw":{"market":"0x8032d8355d335c6ccbfc2508d99fbc87eb13f437bd275c93ee56fd1558e517ff","price_changes":[{"asset_id":"20773614133833886322101538939702011175545796528197617633926164254913649353392","price":"0.02","size":"10757.23","side":"BUY","hash":"bc48d9312367a76afbb0652ab1e51b03054184e1","best_bid":"0.03","best_ask":"0.04"},{"asset_id":"40652734036737240317526188612064032143639112324786051284480877037991580442979","price":"0.98","size":"10757.23","side":"SELL","hash":"0d62919758bf2a4fcb8ed22fec929f767064d89e","best_bid":"0.96","best_ask":"0.97"}],"timestamp":"1770839722272","event_type":"price_change","_sub_state":"active","_subscription_id":1,"_active_subscription_id":1},"parse_warnings":[],"out_of_order":false}
{"run_id":"29526913bab7446286864a321c124486","channel":"market","event_type":"price_change","market":"0x8032d8355d335c6ccbfc2508d99fbc87eb13f437bd275c93ee56fd1558e517ff","asset_id":null,"source":"market_ws:sub:active:1","t_event_ms":1770839722323,"t_recv_wall_ms":1770839722234,"t_recv_wall_iso":"2026-02-11T19:55:22.234Z","t_recv_mono_ns":618587575185875,"raw":{"market":"0x8032d8355d335c6ccbfc2508d99fbc87eb13f437bd275c93ee56fd1558e517ff","price_changes":[{"asset_id":"40652734036737240317526188612064032143639112324786051284480877037991580442979","price":"0.97","size":"235.58","side":"SELL","hash":"9815fd80c56ac9653c76b9a7996e9b0ee9b21570","best_bid":"0.96","best_ask":"0.97"},{"asset_id":"20773614133833886322101538939702011175545796528197617633926164254913649353392","price":"0.03","size":"235.58","side":"BUY","hash":"fd1fd44f1e64042b1e0165501a5efc09a9c8307a","best_bid":"0.03","best_ask":"0.04"}],"timestamp":"1770839722323","event_type":"price_change","_sub_state":"active","_subscription_id":1,"_active_subscription_id":1},"parse_warnings":[],"out_of_order":false}
{"run_id":"29526913bab7446286864a321c124486","channel":"market","event_type":"price_change","market":"0x8032d8355d335c6ccbfc2508d99fbc87eb13f437bd275c93ee56fd1558e517ff","asset_id":null,"source":"market_ws:sub:active:1","t_event_ms":1770839722323,"t_recv_wall_ms":1770839722234,"t_recv_wall_iso":"2026-02-11T19:55:22.234Z","t_recv_mono_ns":618587575641333,"raw":{"market":"0x8032d8355d335c6ccbfc2508d99fbc87eb13f437bd275c93ee56fd1558e517ff","price_changes":[{"asset_id":"20773614133833886322101538939702011175545796528197617633926164254913649353392","price":"0.03","size":"235.58","side":"BUY","hash":"fd1fd44f1e64042b1e0165501a5efc09a9c8307a","best_bid":"0.03","best_ask":"0.04"},{"asset_id":"40652734036737240317526188612064032143639112324786051284480877037991580442979","price":"0.97","size":"235.58","side":"SELL","hash":"9815fd80c56ac9653c76b9a7996e9b0ee9b21570","best_bid":"0.96","best_ask":"0.97"}],"timestamp":"1770839722323","event_type":"price_change","_sub_state":"active","_subscription_id":1,"_active_subscription_id":1},"parse_warnings":[],"out_of_order":false}
{"run_id":"29526913bab7446286864a321c124486","channel":"market","event_type":"book","market":"0x8032d8355d335c6ccbfc2508d99fbc87eb13f437bd275c93ee56fd1558e517ff","asset_id":"20773614133833886322101538939702011175545796528197617633926164254913649353392","source":"market_ws:sub:active:1","t_event_ms":1770839722323,"t_recv_wall_ms":1770839722235,"t_recv_wall_iso":"2026-02-11T19:55:22.235Z","t_recv_mono_ns":618587575815000,"raw":{"market":"0x8032d8355d335c6ccbfc2508d99fbc87eb13f437bd275c93ee56fd1558e517ff","asset_id":"20773614133833886322101538939702011175545796528197617633926164254913649353392","bids":[{"price":"0.01","size":"30789.91"},{"price":"0.02","size":"10757.23"},{"price":"0.03","size":"235.58"}],"asks":[{"price":"0.99","size":"30822.26"},{"price":"0.98","size":"12559.04"},{"price":"0.97","size":"7433.03"},{"price":"0.96","size":"5453.8"},{"price":"0.95","size":"6815.8"},{"price":"0.94","size":"5105"},{"price":"0.93","size":"5421.38"},{"price":"0.92","size":"5139.4"},{"price":"0.91","size":"5225.8"},{"price":"0.9","size":"5102.8"},{"price":"0.89","size":"120.6"},{"price":"0.88","size":"63.6"},{"price":"0.87","size":"63"},{"price":"0.86","size":"61.6"},{"price":"0.85","size":"107.39"},{"price":"0.84","size":"69.39"},{"price":"0.83","size":"58.39"},{"price":"0.82","size":"66.71"},{"price":"0.81","size":"56.8"},{"price":"0.8","size":"92.14"},{"price":"0.79","size":"60.8"},{"price":"0.78","size":"55.2"},{"price":"0.77","size":"64.48"},{"price":"0.76","size":"54.2"},{"price":"0.75","size":"375.8"},{"price":"0.74","size":"68.6"},{"price":"0.73","size":"53.2"},{"price":"0.72","size":"63.26"},{"price":"0.71","size":"52.6"},{"price":"0.7","size":"402.4"},{"price":"0.69","size":"72.2"},{"price":"0.68","size":"87.88"},{"price":"0.67","size":"188.46"},{"price":"0.66","size":"123.6"},{"price":"0.65","size":"317.03"},{"price":"0.64","size":"582.36"},{"price":"0.63","size":"559.2"},{"price":"0.62","size":"559"},{"price":"0.61","size":"594"},{"price":"0.6","size":"2915.41"},{"price":"0.59","size":"576.8"},{"price":"0.58","size":"575.5"},{"price":"0.57","size":"558.6"},{"price":"0.56","size":"572.68"},{"price":"0.55","size":"566.4"},{"price":"0.54","size":"561.94"},{"price":"0.53","size":"631.57"},{"price":"0.52","size":"611.4"},{"price":"0.51","size":"705.2"},{"price":"0.5","size":"1011.55"},{"price":"0.49","size":"692.4"},{"price":"0.48","size":"628.4"},{"price":"0.47","size":"633.4"},{"price":"0.46","size":"711.65"},{"price":"0.45","size":"866.59"},{"price":"0.44","size":"905.69"},{"price":"0.43","size":"641.6"},{"price":"0.42","size":"645.58"},{"price":"0.41","size":"564"},{"price":"0.4","size":"20642.9"},{"price":"0.39","size":"650.23"},{"price":"0.38","size":"593"},{"price":"0.37","size":"755.73"},{"price":"0.36","size":"558"},{"price":"0.35","size":"1144.32"},{"price":"0.34","size":"649.59"},{"price":"0.33","size":"624.8"},{"price":"0.32","size":"574"},{"price":"0.31","size":"594.2"},{"price":"0.3","size":"735.66"},{"price":"0.29","size":"918.6"},{"price":"0.28","size":"356.8"},{"price":"0.27","size":"869.2"},{"price":"0.26","size":"967.6"},{"price":"0.25","size":"1673.8"},{"price":"0.24","size":"869.2"},{"price":"0.23","size":"884.6"},{"price":"0.22","size":"870.2"},{"price":"0.21","size":"871.6"},{"price":"0.2","size":"987.2"},{"price":"0.19","size":"876.8"},{"price":"0.18","size":"1091.55"},{"price":"0.17","size":"958.39"},{"price":"0.16","size":"1119.39"},{"price":"0.15","size":"1164.13"},{"price":"0.14","size":"962.6"},{"price":"0.13","size":"1046.8"},{"price":"0.12","size":"1055.55"},{"price":"0.11","size":"1124.49"},{"price":"0.1","size":"659.79"},{"price":"0.09","size":"889.6"},{"price":"0.08","size":"3419.35"},{"price":"0.07","size":"3335.43"},{"price":"0.06","size":"3197.34"},{"price":"0.05","size":"3304.45"},{"price":"0.04","size":"3710.97"}],"hash":"fd1fd44f1e64042b1e0165501a5efc09a9c8307a","timestamp":"1770839722323","event_type":"book","_sub_state":"active","_subscription_id":1,"_active_subscription_id":1},"parse_warnings":[],"out_of_order":false}
{"run_id":"29526913bab7446286864a321c124486","channel":"market","event_type":"book","market":"0x8032d8355d335c6ccbfc2508d99fbc87eb13f437bd275c93ee56fd1558e517ff","asset_id":"40652734036737240317526188612064032143639112324786051284480877037991580442979","source":"market_ws:sub:active:1","t_event_ms":1770839722323,"t_recv_wall_ms":1770839722235,"t_recv_wall_iso":"2026-02-11T19:55:22.235Z","t_recv_mono_ns":618587576602333,"raw":{"market":"0x8032d8355d335c6ccbfc2508d99fbc87eb13f437bd275c93ee56fd1558e517ff","asset_id":"40652734036737240317526188612064032143639112324786051284480877037991580442979","bids":[{"price":"0.01","size":"30822.26"},{"price":"0.02","size":"12559.04"},{"price":"0.03","size":"7433.03"},{"price":"0.04","size":"5453.8"},{"price":"0.05","size":"6815.8"},{"price":"0.06","size":"5105"},{"price":"0.07","size":"5421.38"},{"price":"0.08","size":"5139.4"},{"price":"0.09","size":"5225.8"},{"price":"0.1","size":"5102.8"},{"price":"0.11","size":"120.6"},{"price":"0.12","size":"63.6"},{"price":"0.13","size":"63"},{"price":"0.14","size":"61.6"},{"price":"0.15","size":"107.39"},{"price":"0.16","size":"69.39"},{"price":"0.17","size":"58.39"},{"price":"0.18","size":"66.71"},{"price":"0.19","size":"56.8"},{"price":"0.2","size":"92.14"},{"price":"0.21","size":"60.8"},{"price":"0.22","size":"55.2"},{"price":"0.23","size":"64.48"},{"price":"0.24","size":"54.2"},{"price":"0.25","size":"375.8"},{"price":"0.26","size":"68.6"},{"price":"0.27","size":"53.2"},{"price":"0.28","size":"63.26"},{"price":"0.29","size":"52.6"},{"price":"0.3","size":"402.4"},{"price":"0.31","size":"72.2"},{"price":"0.32","size":"87.88"},{"price":"0.33","size":"188.46"},{"price":"0.34","size":"123.6"},{"price":"0.35","size":"317.03"},{"price":"0.36","size":"582.36"},{"price":"0.37","size":"559.2"},{"price":"0.38","size":"559"},{"price":"0.39","size":"594"},{"price":"0.4","size":"2915.41"},{"price":"0.41","size":"576.8"},{"price":"0.42","size":"575.5"},{"price":"0.43","size":"558.6"},{"price":"0.44","size":"572.68"},{"price":"0.45","size":"566.4"},{"price":"0.46","size":"561.94"},{"price":"0.47","size":"631.57"},{"price":"0.48","size":"611.4"},{"price":"0.49","size":"705.2"},{"price":"0.5","size":"1011.55"},{"price":"0.51","size":"692.4"},{"price":"0.52","size":"628.4"},{"price":"0.53","size":"633.4"},{"price":"0.54","size":"711.65"},{"price":"0.55","size":"866.59"},{"price":"0.56","size":"905.69"},{"price":"0.57","size":"641.6"},{"price":"0.58","size":"645.58"},{"price":"0.59","size":"564"},{"price":"0.6","size":"20642.9"},{"price":"0.61","size":"650.23"},{"price":"0.62","size":"593"},{"price":"0.63","size":"755.73"},{"price":"0.64","size":"558"},{"price":"0.65","size":"1144.32"},{"price":"0.66","size":"649.59"},{"price":"0.67","size":"624.8"},{"price":"0.68","size":"574"},{"price":"0.69","size":"594.2"},{"price":"0.7","size":"735.66"},{"price":"0.71","size":"918.6"},{"price":"0.72","size":"356.8"},{"price":"0.73","size":"869.2"},{"price":"0.74","size":"967.6"},{"price":"0.75","size":"1673.8"},{"price":"0.76","size":"869.2"},{"price":"0.77","size":"884.6"},{"price":"0.78","size":"870.2"},{"price":"0.79","size":"871.6"},{"price":"0.8","size":"987.2"},{"price":"0.81","size":"876.8"},{"price":"0.82","size":"1091.55"},{"price":"0.83","size":"958.39"},{"price":"0.84","size":"1119.39"},{"price":"0.85","size":"1164.13"},{"price":"0.86","size":"962.6"},{"price":"0.87","size":"1046.8"},{"price":"0.88","size":"1055.55"},{"price":"0.89","size":"1124.49"},{"price":"0.9","size":"659.79"},{"price":"0.91","size":"889.6"},{"price":"0.92","size":"3419.35"},{"price":"0.93","size":"3335.43"},{"price":"0.94","size":"3197.34"},{"price":"0.95","size":"3304.45"},{"price":"0.96","size":"3710.97"}],"asks":[{"price":"0.99","size":"30789.91"},{"price":"0.98","size":"10757.23"},{"price":"0.97","size":"235.58"}],"hash":"9815fd80c56ac9653c76b9a7996e9b0ee9b21570","timestamp":"1770839722323","event_type":"book","_sub_state":"active","_subscription_id":1,"_active_subscription_id":1},"parse_warnings":[],"out_of_order":false}
{"run_id":"29526913bab7446286864a321c124486","channel":"market","event_type":"price_change","market":"0x8032d8355d335c6ccbfc2508d99fbc87eb13f437bd275c93ee56fd1558e517ff","asset_id":null,"source":"market_ws:sub:active:1","t_event_ms":1770839722325,"t_recv_wall_ms":1770839722236,"t_recv_wall_iso":"2026-02-11T19:55:22.236Z","t_recv_mono_ns":618587577396583,"raw":{"market":"0x8032d8355d335c6ccbfc2508d99fbc87eb13f437bd275c93ee56fd1558e517ff","price_changes":[{"asset_id":"40652734036737240317526188612064032143639112324786051284480877037991580442979","price":"0.77","size":"864.6","side":"BUY","hash":"7301d318194ace6aa82068ea8fce6ba29aea72b5","best_bid":"0.96","best_ask":"0.97"},{"asset_id":"20773614133833886322101538939702011175545796528197617633926164254913649353392","price":"0.23","size":"864.6","side":"SELL","hash":"51de62423ad22f750db4d32da56914a4f2536561","best_bid":"0.03","best_ask":"0.04"}],"timestamp":"1770839722325","event_type":"price_change","_sub_state":"active","_subscription_id":1,"_active_subscription_id":1},"parse_warnings":[],"out_of_order":false}
{"run_id":"29526913bab7446286864a321c124486","channel":"market","event_type":"price_change","market":"0x8032d8355d335c6ccbfc2508d99fbc87eb13f437bd275c93ee56fd1558e517ff","asset_id":null,"source":"market_ws:sub:active:1","t_event_ms":1770839722327,"t_recv_wall_ms":1770839722236,"t_recv_wall_iso":"2026-02-11T19:55:22.236Z","t_recv_mono_ns":618587577611666,"raw":{"market":"0x8032d8355d335c6ccbfc2508d99fbc87eb13f437bd275c93ee56fd1558e517ff","price_changes":[{"asset_id":"40652734036737240317526188612064032143639112324786051284480877037991580442979","price":"0.94","size":"3192.34","side":"BUY","hash":"dd37cec64e5597e9192cf257ca621ccc4f523219","best_bid":"0.96","best_ask":"0.97"},{"asset_id":"20773614133833886322101538939702011175545796528197617633926164254913649353392","price":"0.06","size":"3192.34","side":"SELL","hash":"4f608cd5fd37d3f2d60d68f3c2e9a3cb0736933c","best_bid":"0.03","best_ask":"0.04"}],"timestamp":"1770839722327","event_type":"price_change","_sub_state":"active","_subscription_id":1,"_active_subscription_id":1},"parse_warnings":[],"out_of_order":false}
{"run_id":"29526913bab7446286864a321c124486","channel":"market","event_type":"price_change","market":"0x8032d8355d335c6ccbfc2508d99fbc87eb13f437bd275c93ee56fd1558e517ff","asset_id":null,"source":"market_ws:sub:active:1","t_event_ms":1770839722340,"t_recv_wall_ms":1770839722250,"t_recv_wall_iso":"2026-02-11T19:55:22.250Z","t_recv_mono_ns":618587591415000,"raw":{"market":"0x8032d8355d335c6ccbfc2508d99fbc87eb13f437bd275c93ee56fd1558e517ff","price_changes":[{"asset_id":"40652734036737240317526188612064032143639112324786051284480877037991580442979","price":"0.82","size":"1096.55","side":"BUY","hash":"817bf135cc7fc414a5de438f40af532b23ef225f","best_bid":"0.96","best_ask":"0.97"},{"asset_id":"20773614133833886322101538939702011175545796528197617633926164254913649353392","price":"0.18","size":"1096.55","side":"SELL","hash":"a4751cf457ea82bfc05263d8ebcda6e997187fcf","best_bid":"0.03","best_ask":"0.04"}],"timestamp":"1770839722340","event_type":"price_change","_sub_state":"active","_subscription_id":1,"_active_subscription_id":1},"parse_warnings":[],"out_of_order":false}
{"run_id":"29526913bab7446286864a321c124486","channel":"market","event_type":"last_trade_price","market":"0x8032d8355d335c6ccbfc2508d99fbc87eb13f437bd275c93ee56fd1558e517ff","asset_id":"40652734036737240317526188612064032143639112324786051284480877037991580442979","source":"market_ws:sub:unknown","t_event_ms":1770839722354,"t_recv_wall_ms":1770839722269,"t_recv_wall_iso":"2026-02-11T19:55:22.269Z","t_recv_mono_ns":618587610108833,"raw":{"market":"0x8032d8355d335c6ccbfc2508d99fbc87eb13f437bd275c93ee56fd1558e517ff","asset_id":"40652734036737240317526188612064032143639112324786051284480877037991580442979","price":"0.97","size":"41.237112","fee_rate_bps":"1000","side":"BUY","timestamp":"1770839722354","event_type":"last_trade_price","transaction_hash":"0x11a02fac3c1a120162fbc6bf6f2a68f4f9bd46246fa7dcbb3d7166866691efd6","_sub_state":"unknown","_subscription_id":null,"_active_subscription_id":1},"parse_warnings":["unknown_message_schema"],"out_of_order":false}
{"run_id":"29526913bab7446286864a321c124486","channel":"market","event_type":"price_change","market":"0x8032d8355d335c6ccbfc2508d99fbc87eb13f437bd275c93ee56fd1558e517ff","asset_id":null,"source":"market_ws:sub:active:1","t_event_ms":1770839722390,"t_recv_wall_ms":1770839722303,"t_recv_wall_iso":"2026-02-11T19:55:22.303Z","t_recv_mono_ns":618587644670250,"raw":{"market":"0x8032d8355d335c6ccbfc2508d99fbc87eb13f437bd275c93ee56fd1558e517ff","price_changes":[{"asset_id":"40652734036737240317526188612064032143639112324786051284480877037991580442979","price":"0.94","size":"3197.34","side":"BUY","hash":"371c151480aff117d92c0f4186752667628ed6cc","best_bid":"0.96","best_ask":"0.97"},{"asset_id":"20773614133833886322101538939702011175545796528197617633926164254913649353392","price":"0.06","size":"3197.34","side":"SELL","hash":"95937d372712d1d879c0921510a101466033350f","best_bid":"0.03","best_ask":"0.04"}],"timestamp":"1770839722390","event_type":"price_change","_sub_state":"active","_subscription_id":1,"_active_subscription_id":1},"parse_warnings":[],"out_of_order":false}
{"run_id":"29526913bab7446286864a321c124486","channel":"market","event_type":"price_change","market":"0x8032d8355d335c6ccbfc2508d99fbc87eb13f437bd275c93ee56fd1558e517ff","asset_id":null,"source":"market_ws:sub:active:1","t_event_ms":1770839722391,"t_recv_wall_ms":1770839722304,"t_recv_wall_iso":"2026-02-11T19:55:22.304Z","t_recv_mono_ns":618587645256333,"raw":{"market":"0x8032d8355d335c6ccbfc2508d99fbc87eb13f437bd275c93ee56fd1558e517ff","price_changes":[{"asset_id":"40652734036737240317526188612064032143639112324786051284480877037991580442979","price":"0.97","size":"234.36","side":"SELL","hash":"e895e547786843881dd75d6ab45ee32f22ab2698","best_bid":"0.96","best_ask":"0.97"},{"asset_id":"20773614133833886322101538939702011175545796528197617633926164254913649353392","price":"0.03","size":"234.36","side":"BUY","hash":"4faf76afe1ccb1f9f158b86b78a566dfd6ca7bf3","best_bid":"0.03","best_ask":"0.04"}],"timestamp":"1770839722391","event_type":"price_change","_sub_state":"active","_subscription_id":1,"_active_subscription_id":1},"parse_warnings":[],"out_of_order":false}
{"run_id":"29526913bab7446286864a321c124486","channel":"market","event_type":"price_change","market":"0x8032d8355d335c6ccbfc2508d99fbc87eb13f437bd275c93ee56fd1558e517ff","asset_id":null,"source":"market_ws:sub:active:1","t_event_ms":1770839722392,"t_recv_wall_ms":1770839722304,"t_recv_wall_iso":"2026-02-11T19:55:22.304Z","t_recv_mono_ns":618587645648125,"raw":{"market":"0x8032d8355d335c6ccbfc2508d99fbc87eb13f437bd275c93ee56fd1558e517ff","price_changes":[{"asset_id":"40652734036737240317526188612064032143639112324786051284480877037991580442979","price":"0.94","size":"3162.34","side":"BUY","hash":"3e4ab73e537e631d30c6cf21bcd9cba37c388e39","best_bid":"0.96","best_ask":"0.97"},{"asset_id":"20773614133833886322101538939702011175545796528197617633926164254913649353392","price":"0.06","size":"3162.34","side":"SELL","hash":"7069bd085fa7e28fcce57069d1b33f6e3927a500","best_bid":"0.03","best_ask":"0.04"}],"timestamp":"1770839722392","event_type":"price_change","_sub_state":"active","_subscription_id":1,"_active_subscription_id":1},"parse_warnings":[],"out_of_order":false}
{"run_id":"29526913bab7446286864a321c124486","channel":"market","event_type":"price_change","market":"0x8032d8355d335c6ccbfc2508d99fbc87eb13f437bd275c93ee56fd1558e517ff","asset_id":null,"source":"market_ws:sub:active:1","t_event_ms":1770839722401,"t_recv_wall_ms":1770839722308,"t_recv_wall_iso":"2026-02-11T19:55:22.308Z","t_recv_mono_ns":618587648928666,"raw":{"market":"0x8032d8355d335c6ccbfc2508d99fbc87eb13f437bd275c93ee56fd1558e517ff","price_changes":[{"asset_id":"40652734036737240317526188612064032143639112324786051284480877037991580442979","price":"0.91","size":"879.6","side":"BUY","hash":"ad38da48fde9be8cac9d2d74c5b195a5772abcca","best_bid":"0.96","best_ask":"0.97"},{"asset_id":"20773614133833886322101538939702011175545796528197617633926164254913649353392","price":"0.09","size":"879.6","side":"SELL","hash":"27a63dd53b15a41601e9fbad95c2cb7c5d0d50bc","best_bid":"0.03","best_ask":"0.04"}],"timestamp":"1770839722401","event_type":"price_change","_sub_state":"active","_subscription_id":1,"_active_subscription_id":1},"parse_warnings":[],"out_of_order":false}
{"run_id":"29526913bab7446286864a321c124486","channel":"market","event_type":"price_change","market":"0x8032d8355d335c6ccbfc2508d99fbc87eb13f437bd275c93ee56fd1558e517ff","asset_id":null,"source":"market_ws:sub:active:1","t_event_ms":1770839722405,"t_recv_wall_ms":1770839722311,"t_recv_wall_iso":"2026-02-11T19:55:22.311Z","t_recv_mono_ns":618587652538125,"raw":{"market":"0x8032d8355d335c6ccbfc2508d99fbc87eb13f437bd275c93ee56fd1558e517ff","price_changes":[{"asset_id":"40652734036737240317526188612064032143639112324786051284480877037991580442979","price":"0.96","size":"3650.97","side":"BUY","hash":"5d04d90b257955e03de05ff77942a8277aabb062","best_bid":"0.96","best_ask":"0.97"},{"asset_id":"20773614133833886322101538939702011175545796528197617633926164254913649353392","price":"0.04","size":"3650.97","side":"SELL","hash":"e251a8ee72ccbdc231ef8eb47b273005a8abb259","best_bid":"0.03","best_ask":"0.04"}],"timestamp":"1770839722405","event_type":"price_change","_sub_state":"active","_subscription_id":1,"_active_subscription_id":1},"parse_warnings":[],"out_of_order":false}
{"run_id":"29526913bab7446286864a321c124486","channel":"market","event_type":"price_change","market":"0x8032d8355d335c6ccbfc2508d99fbc87eb13f437bd275c93ee56fd1558e517ff","asset_id":null,"source":"market_ws:sub:active:1","t_event_ms":1770839722409,"t_recv_wall_ms":1770839722314,"t_recv_wall_iso":"2026-02-11T19:55:22.314Z","t_recv_mono_ns":618587655173958,"raw":{"market":"0x8032d8355d335c6ccbfc2508d99fbc87eb13f437bd275c93ee56fd1558e517ff","price_changes":[{"asset_id":"40652734036737240317526188612064032143639112324786051284480877037991580442979","price":"0.95","size":"3364.45","side":"BUY","hash":"2f809b95c83ba79ee8d32cdf3b823b8921198650","best_bid":"0.96","best_ask":"0.97"},{"asset_id":"20773614133833886322101538939702011175545796528197617633926164254913649353392","price":"0.05","size":"3364.45","side":"SELL","hash":"437512eddca4a49fb697ef610ac28dd15b7dc42d","best_bid":"0.03","best_ask":"0.04"}],"timestamp":"1770839722409","event_type":"price_change","_sub_state":"active","_subscription_id":1,"_active_subscription_id":1},"parse_warnings":[],"out_of_order":false}
{"run_id":"29526913bab7446286864a321c124486","channel":"market","event_type":"price_change","market":"0x8032d8355d335c6ccbfc2508d99fbc87eb13f437bd275c93ee56fd1558e517ff","asset_id":null,"source":"market_ws:sub:active:1","t_event_ms":1770839722427,"t_recv_wall_ms":1770839722338,"t_recv_wall_iso":"2026-02-11T19:55:22.338Z","t_recv_mono_ns":618587679100250,"raw":{"market":"0x8032d8355d335c6ccbfc2508d99fbc87eb13f437bd275c93ee56fd1558e517ff","price_changes":[{"asset_id":"40652734036737240317526188612064032143639112324786051284480877037991580442979","price":"0.77","size":"884.6","side":"BUY","hash":"57a8b5fd4ed7c4f7ab90901b6de34b2810eff520","best_bid":"0.96","best_ask":"0.97"},{"asset_id":"20773614133833886322101538939702011175545796528197617633926164254913649353392","price":"0.23","size":"884.6","side":"SELL","hash":"146ce7d043f0c9e7c1dc6f97ca359f3c380aef26","best_bid":"0.03","best_ask":"0.04"}],"timestamp":"1770839722427","event_type":"price_change","_sub_state":"active","_subscription_id":1,"_active_subscription_id":1},"parse_warnings":[],"out_of_order":false}
{"run_id":"29526913bab7446286864a321c124486","channel":"market","event_type":"price_change","market":"0x8032d8355d335c6ccbfc2508d99fbc87eb13f437bd275c93ee56fd1558e517ff","asset_id":null,"source":"market_ws:sub:active:1","t_event_ms":1770839722435,"t_recv_wall_ms":1770839722346,"t_recv_wall_iso":"2026-02-11T19:55:22.346Z","t_recv_mono_ns":618587686982666,"raw":{"market":"0x8032d8355d335c6ccbfc2508d99fbc87eb13f437bd275c93ee56fd1558e517ff","price_changes":[{"asset_id":"40652734036737240317526188612064032143639112324786051284480877037991580442979","price":"0.98","size":"10792.23","side":"SELL","hash":"8ad14b609f5b27824126f3f7437634c1b614619a","best_bid":"0.96","best_ask":"0.97"},{"asset_id":"20773614133833886322101538939702011175545796528197617633926164254913649353392","price":"0.02","size":"10792.23","side":"BUY","hash":"222a180f5979eda3db49c2e169f0aa64d2371732","best_bid":"0.03","best_ask":"0.04"}],"timestamp":"1770839722435","event_type":"price_change","_sub_state":"active","_subscription_id":1,"_active_subscription_id":1},"parse_warnings":[],"out_of_order":false}
{"run_id":"29526913bab7446286864a321c124486","channel":"market","event_type":"price_change","market":"0x8032d8355d335c6ccbfc2508d99fbc87eb13f437bd275c93ee56fd1558e517ff","asset_id":null,"source":"market_ws:sub:active:1","t_event_ms":1770839722436,"t_recv_wall_ms":1770839722346,"t_recv_wall_iso":"2026-02-11T19:55:22.346Z","t_recv_mono_ns":618587687308458,"raw":{"market":"0x8032d8355d335c6ccbfc2508d99fbc87eb13f437bd275c93ee56fd1558e517ff","price_changes":[{"asset_id":"40652734036737240317526188612064032143639112324786051284480877037991580442979","price":"0.95","size":"3399.45","side":"BUY","hash":"aa5963568c95da9b1bb5f2dc778e8e841ac8cb8e","best_bid":"0.96","best_ask":"0.97"},{"asset_id":"20773614133833886322101538939702011175545796528197617633926164254913649353392","price":"0.05","size":"3399.45","side":"SELL","hash":"530b757d7daeea0008ed1acd625db1bdefa0d094","best_bid":"0.03","best_ask":"0.04"}],"timestamp":"1770839722436","event_type":"price_change","_sub_state":"active","_subscription_id":1,"_active_subscription_id":1},"parse_warnings":[],"out_of_order":false}
{"run_id":"29526913bab7446286864a321c124486","channel":"market","event_type":"price_change","market":"0x8032d8355d335c6ccbfc2508d99fbc87eb13f437bd275c93ee56fd1558e517ff","asset_id":null,"source":"market_ws:sub:active:1","t_event_ms":1770839722440,"t_recv_wall_ms":1770839722346,"t_recv_wall_iso":"2026-02-11T19:55:22.346Z","t_recv_mono_ns":618587687472000,"raw":{"market":"0x8032d8355d335c6ccbfc2508d99fbc87eb13f437bd275c93ee56fd1558e517ff","price_changes":[{"asset_id":"40652734036737240317526188612064032143639112324786051284480877037991580442979","price":"0.82","size":"1091.55","side":"BUY","hash":"9a54b892adad8875bc397d7bd2bbe5e081700389","best_bid":"0.96","best_ask":"0.97"},{"asset_id":"20773614133833886322101538939702011175545796528197617633926164254913649353392","price":"0.18","size":"1091.55","side":"SELL","hash":"e1f340948517629444497782efa9e717a9b07d6e","best_bid":"0.03","best_ask":"0.04"}],"timestamp":"1770839722440","event_type":"price_change","_sub_state":"active","_subscription_id":1,"_active_subscription_id":1},"parse_warnings":[],"out_of_order":false}
{"run_id":"29526913bab7446286864a321c124486","channel":"market","event_type":"price_change","market":"0x8032d8355d335c6ccbfc2508d99fbc87eb13f437bd275c93ee56fd1558e517ff","asset_id":null,"source":"market_ws:sub:active:1","t_event_ms":1770839722503,"t_recv_wall_ms":1770839722414,"t_recv_wall_iso":"2026-02-11T19:55:22.414Z","t_recv_mono_ns":618587755739416,"raw":{"market":"0x8032d8355d335c6ccbfc2508d99fbc87eb13f437bd275c93ee56fd1558e517ff","price_changes":[{"asset_id":"20773614133833886322101538939702011175545796528197617633926164254913649353392","price":"0.06","size":"3127.34","side":"SELL","hash":"9503ae90f598d761ed723070c5326ba50c12542f","best_bid":"0.03","best_ask":"0.04"},{"asset_id":"40652734036737240317526188612064032143639112324786051284480877037991580442979","price":"0.94","size":"3127.34","side":"BUY","hash":"607ba9047413b7b8f75d6687d0bfdb0b7a63ff8f","best_bid":"0.96","best_ask":"0.97"}],"timestamp":"1770839722503","event_type":"price_change","_sub_state":"active","_subscription_id":1,"_active_subscription_id":1},"parse_warnings":[],"out_of_order":false}
{"run_id":"29526913bab7446286864a321c124486","channel":"market","event_type":"price_change","market":"0x8032d8355d335c6ccbfc2508d99fbc87eb13f437bd275c93ee56fd1558e517ff","asset_id":null,"source":"market_ws:sub:active:1","t_event_ms":1770839722507,"t_recv_wall_ms":1770839722415,"t_recv_wall_iso":"2026-02-11T19:55:22.415Z","t_recv_mono_ns":618587756357125,"raw":{"market":"0x8032d8355d335c6ccbfc2508d99fbc87eb13f437bd275c93ee56fd1558e517ff","price_changes":[{"asset_id":"20773614133833886322101538939702011175545796528197617633926164254913649353392","price":"0.02","size":"10772.23","side":"BUY","hash":"b2839f45d2afb4a64a14ec1803bb755920f7d137","best_bid":"0.03","best_ask":"0.04"},{"asset_id":"40652734036737240317526188612064032143639112324786051284480877037991580442979","price":"0.98","size":"10772.23","side":"SELL","hash":"e588840d42cb1142dfe7b18cb0e52ae65c9ebb9d","best_bid":"0.96","best_ask":"0.97"}],"timestamp":"1770839722507","event_type":"price_change","_sub_state":"active","_subscription_id":1,"_active_subscription_id":1},"parse_warnings":[],"out_of_order":false}
{"run_id":"29526913bab7446286864a321c124486","channel":"market","event_type":"price_change","market":"0x8032d8355d335c6ccbfc2508d99fbc87eb13f437bd275c93ee56fd1558e517ff","asset_id":null,"source":"market_ws:sub:active:1","t_event_ms":1770839722517,"t_recv_wall_ms":1770839722426,"t_recv_wall_iso":"2026-02-11T19:55:22.426Z","t_recv_mono_ns":618587766829916,"raw":{"market":"0x8032d8355d335c6ccbfc2508d99fbc87eb13f437bd275c93ee56fd1558e517ff","price_changes":[{"asset_id":"20773614133833886322101538939702011175545796528197617633926164254913649353392","price":"0.02","size":"10767.23","side":"BUY","hash":"194aa0b17b58e9fc8bc324c34eed8af2f3a64ab4","best_bid":"0.03","best_ask":"0.04"},{"asset_id":"40652734036737240317526188612064032143639112324786051284480877037991580442979","price":"0.98","size":"10767.23","side":"SELL","hash":"9e8c22eb572a529c1bbea376183490a6b72a0a9f","best_bid":"0.96","best_ask":"0.97"}],"timestamp":"1770839722517","event_type":"price_change","_sub_state":"active","_subscription_id":1,"_active_subscription_id":1},"parse_warnings":[],"out_of_order":false}
{"run_id":"29526913bab7446286864a321c124486","channel":"market","event_type":"price_change","market":"0x8032d8355d335c6ccbfc2508d99fbc87eb13f437bd275c93ee56fd1558e517ff","asset_id":null,"source":"market_ws:sub:active:1","t_event_ms":1770839722520,"t_recv_wall_ms":1770839722427,"t_recv_wall_iso":"2026-02-11T19:55:22.427Z","t_recv_mono_ns":618587768207041,"raw":{"market":"0x8032d8355d335c6ccbfc2508d99fbc87eb13f437bd275c93ee56fd1558e517ff","price_changes":[{"asset_id":"40652734036737240317526188612064032143639112324786051284480877037991580442979","price":"0.94","size":"3122.34","side":"BUY","hash":"2edf3ca97f15623eeabae45c7e1c110fc5e922fc","best_bid":"0.96","best_ask":"0.97"},{"asset_id":"20773614133833886322101538939702011175545796528197617633926164254913649353392","price":"0.06","size":"3122.34","side":"SELL","hash":"da82ffcba2ca1b774d0a68bf9e7e85c478dcc505","best_bid":"0.03","best_ask":"0.04"}],"timestamp":"1770839722520","event_type":"price_change","_sub_state":"active","_subscription_id":1,"_active_subscription_id":1},"parse_warnings":[],"out_of_order":false}
{"run_id":"29526913bab7446286864a321c124486","channel":"market","event_type":"price_change","market":"0x8032d8355d335c6ccbfc2508d99fbc87eb13f437bd275c93ee56fd1558e517ff","asset_id":null,"source":"market_ws:sub:active:1","t_event_ms":1770839722526,"t_recv_wall_ms":1770839722435,"t_recv_wall_iso":"2026-02-11T19:55:22.435Z","t_recv_mono_ns":618587776193375,"raw":{"market":"0x8032d8355d335c6ccbfc2508d99fbc87eb13f437bd275c93ee56fd1558e517ff","price_changes":[{"asset_id":"40652734036737240317526188612064032143639112324786051284480877037991580442979","price":"0.85","size":"1149.13","side":"BUY","hash":"de28e74029556cf0741a2d94e5d5c2b4b88c63c2","best_bid":"0.96","best_ask":"0.97"},{"asset_id":"20773614133833886322101538939702011175545796528197617633926164254913649353392","price":"0.15","size":"1149.13","side":"SELL","hash":"e8e6285ce0b086611cc22407e9b3bacca0ed9a2e","best_bid":"0.03","best_ask":"0.04"}],"timestamp":"1770839722526","event_type":"price_change","_sub_state":"active","_subscription_id":1,"_active_subscription_id":1},"parse_warnings":[],"out_of_order":false}
{"run_id":"29526913bab7446286864a321c124486","channel":"market","event_type":"price_change","market":"0x8032d8355d335c6ccbfc2508d99fbc87eb13f437bd275c93ee56fd1558e517ff","asset_id":null,"source":"market_ws:sub:active:1","t_event_ms":1770839722537,"t_recv_wall_ms":1770839722446,"t_recv_wall_iso":"2026-02-11T19:55:22.446Z","t_recv_mono_ns":618587786747750,"raw":{"market":"0x8032d8355d335c6ccbfc2508d99fbc87eb13f437bd275c93ee56fd1558e517ff","price_changes":[{"asset_id":"40652734036737240317526188612064032143639112324786051284480877037991580442979","price":"0.93","size":"3340.43","side":"BUY","hash":"a33862432765581f1b21992e5feea1c6e58e362c","best_bid":"0.96","best_ask":"0.97"},{"asset_id":"20773614133833886322101538939702011175545796528197617633926164254913649353392","price":"0.07","size":"3340.43","side":"SELL","hash":"20030d485c29bcef69c27b68c91b2537ab36a002","best_bid":"0.03","best_ask":"0.04"}],"timestamp":"1770839722537","event_type":"price_change","_sub_state":"active","_subscription_id":1,"_active_subscription_id":1},"parse_warnings":[],"out_of_order":false}
{"run_id":"29526913bab7446286864a321c124486","channel":"market","event_type":"price_change","market":"0x8032d8355d335c6ccbfc2508d99fbc87eb13f437bd275c93ee56fd1558e517ff","asset_id":null,"source":"market_ws:sub:active:1","t_event_ms":1770839722538,"t_recv_wall_ms":1770839722446,"t_recv_wall_iso":"2026-02-11T19:55:22.446Z","t_recv_mono_ns":618587787122666,"raw":{"market":"0x8032d8355d335c6ccbfc2508d99fbc87eb13f437bd275c93ee56fd1558e517ff","price_changes":[{"asset_id":"40652734036737240317526188612064032143639112324786051284480877037991580442979","price":"0.96","size":"3655.97","side":"BUY","hash":"12da254bed32ba5efd09e3f27b1f28398b7784bc","best_bid":"0.96","best_ask":"0.97"},{"asset_id":"20773614133833886322101538939702011175545796528197617633926164254913649353392","price":"0.04","size":"3655.97","side":"SELL","hash":"d84480fae59cdfc35faa01e68b185f8a763c2842","best_bid":"0.03","best_ask":"0.04"}],"timestamp":"1770839722538","event_type":"price_change","_sub_state":"active","_subscription_id":1,"_active_subscription_id":1},"parse_warnings":[],"out_of_order":false}
{"run_id":"29526913bab7446286864a321c124486","channel":"market","event_type":"price_change","market":"0x8032d8355d335c6ccbfc2508d99fbc87eb13f437bd275c93ee56fd1558e517ff","asset_id":null,"source":"market_ws:sub:active:1","t_event_ms":1770839722540,"t_recv_wall_ms":1770839722446,"t_recv_wall_iso":"2026-02-11T19:55:22.446Z","t_recv_mono_ns":618587787531166,"raw":{"market":"0x8032d8355d335c6ccbfc2508d99fbc87eb13f437bd275c93ee56fd1558e517ff","price_changes":[{"asset_id":"20773614133833886322101538939702011175545796528197617633926164254913649353392","price":"0.05","size":"3434.45","side":"SELL","hash":"555cebe8ad785d59e078eaf5a59c2865f28b8026","best_bid":"0.03","best_ask":"0.04"},{"asset_id":"40652734036737240317526188612064032143639112324786051284480877037991580442979","price":"0.95","size":"3434.45","side":"BUY","hash":"9ba08d3f8cc9516775c5e189fb119f21198ec004","best_bid":"0.96","best_ask":"0.97"}],"timestamp":"1770839722540","event_type":"price_change","_sub_state":"active","_subscription_id":1,"_active_subscription_id":1},"parse_warnings":[],"out_of_order":false}
{"run_id":"29526913bab7446286864a321c124486","channel":"market","event_type":"price_change","market":"0x8032d8355d335c6ccbfc2508d99fbc87eb13f437bd275c93ee56fd1558e517ff","asset_id":null,"source":"market_ws:sub:active:1","t_event_ms":1770839722549,"t_recv_wall_ms":1770839722457,"t_recv_wall_iso":"2026-02-11T19:55:22.457Z","t_recv_mono_ns":618587798142708,"raw":{"market":"0x8032d8355d335c6ccbfc2508d99fbc87eb13f437bd275c93ee56fd1558e517ff","price_changes":[{"asset_id":"40652734036737240317526188612064032143639112324786051284480877037991580442979","price":"0.96","size":"3650.95","side":"BUY","hash":"cfd6149046b5177ea0a5d2b0c46471fb8780a78d","best_bid":"0.96","best_ask":"0.97"},{"asset_id":"20773614133833886322101538939702011175545796528197617633926164254913649353392","price":"0.04","size":"3650.95","side":"SELL","hash":"dcb97c46427d133a0cc0cc5e8e298d97cdf7a718","best_bid":"0.03","best_ask":"0.04"}],"timestamp":"1770839722549","event_type":"price_change","_sub_state":"active","_subscription_id":1,"_active_subscription_id":1},"parse_warnings":[],"out_of_order":false}
{"run_id":"29526913bab7446286864a321c124486","channel":"market","event_type":"book","market":"0x8032d8355d335c6ccbfc2508d99fbc87eb13f437bd275c93ee56fd1558e517ff","asset_id":"20773614133833886322101538939702011175545796528197617633926164254913649353392","source":"market_ws:sub:active:1","t_event_ms":1770839722549,"t_recv_wall_ms":1770839722457,"t_recv_wall_iso":"2026-02-11T19:55:22.457Z","t_recv_mono_ns":618587798530083,"raw":{"market":"0x8032d8355d335c6ccbfc2508d99fbc87eb13f437bd275c93ee56fd1558e517ff","asset_id":"20773614133833886322101538939702011175545796528197617633926164254913649353392","bids":[{"price":"0.01","size":"30789.91"},{"price":"0.02","size":"10767.23"},{"price":"0.03","size":"234.36"}],"asks":[{"price":"0.99","size":"30822.26"},{"price":"0.98","size":"12559.04"},{"price":"0.97","size":"7433.03"},{"price":"0.96","size":"5453.8"},{"price":"0.95","size":"6815.8"},{"price":"0.94","size":"5105"},{"price":"0.93","size":"5421.38"},{"price":"0.92","size":"5139.4"},{"price":"0.91","size":"5225.8"},{"price":"0.9","size":"5102.8"},{"price":"0.89","size":"120.6"},{"price":"0.88","size":"63.6"},{"price":"0.87","size":"63"},{"price":"0.86","size":"61.6"},{"price":"0.85","size":"107.39"},{"price":"0.84","size":"69.39"},{"price":"0.83","size":"58.39"},{"price":"0.82","size":"66.71"},{"price":"0.81","size":"56.8"},{"price":"0.8","size":"92.14"},{"price":"0.79","size":"60.8"},{"price":"0.78","size":"55.2"},{"price":"0.77","size":"64.48"},{"price":"0.76","size":"54.2"},{"price":"0.75","size":"375.8"},{"price":"0.74","size":"68.6"},{"price":"0.73","size":"53.2"},{"price":"0.72","size":"63.26"},{"price":"0.71","size":"52.6"},{"price":"0.7","size":"402.4"},{"price":"0.69","size":"72.2"},{"price":"0.68","size":"87.88"},{"price":"0.67","size":"188.46"},{"price":"0.66","size":"123.6"},{"price":"0.65","size":"317.03"},{"price":"0.64","size":"582.36"},{"price":"0.63","size":"559.2"},{"price":"0.62","size":"559"},{"price":"0.61","size":"594"},{"price":"0.6","size":"2915.41"},{"price":"0.59","size":"576.8"},{"price":"0.58","size":"575.5"},{"price":"0.57","size":"558.6"},{"price":"0.56","size":"572.68"},{"price":"0.55","size":"566.4"},{"price":"0.54","size":"561.94"},{"price":"0.53","size":"631.57"},{"price":"0.52","size":"611.4"},{"price":"0.51","size":"705.2"},{"price":"0.5","size":"1011.55"},{"price":"0.49","size":"692.4"},{"price":"0.48","size":"628.4"},{"price":"0.47","size":"633.4"},{"price":"0.46","size":"711.65"},{"price":"0.45","size":"866.59"},{"price":"0.44","size":"905.69"},{"price":"0.43","size":"641.6"},{"price":"0.42","size":"645.58"},{"price":"0.41","size":"564"},{"price":"0.4","size":"20642.9"},{"price":"0.39","size":"650.23"},{"price":"0.38","size":"593"},{"price":"0.37","size":"755.73"},{"price":"0.36","size":"558"},{"price":"0.35","size":"1144.32"},{"price":"0.34","size":"649.59"},{"price":"0.33","size":"624.8"},{"price":"0.32","size":"574"},{"price":"0.31","size":"594.2"},{"price":"0.3","size":"735.66"},{"price":"0.29","size":"918.6"},{"price":"0.28","size":"356.8"},{"price":"0.27","size":"869.2"},{"price":"0.26","size":"967.6"},{"price":"0.25","size":"1673.8"},{"price":"0.24","size":"869.2"},{"price":"0.23","size":"884.6"},{"price":"0.22","size":"870.2"},{"price":"0.21","size":"871.6"},{"price":"0.2","size":"987.2"},{"price":"0.19","size":"876.8"},{"price":"0.18","size":"1091.55"},{"price":"0.17","size":"958.39"},{"price":"0.16","size":"1119.39"},{"price":"0.15","size":"1149.13"},{"price":"0.14","size":"962.6"},{"price":"0.13","size":"1046.8"},{"price":"0.12","size":"1055.55"},{"price":"0.11","size":"1124.49"},{"price":"0.1","size":"659.79"},{"price":"0.09","size":"879.6"},{"price":"0.08","size":"3419.35"},{"price":"0.07","size":"3340.43"},{"price":"0.06","size":"3122.34"},{"price":"0.05","size":"3434.45"},{"price":"0.04","size":"3650.95"}],"hash":"dcb97c46427d133a0cc0cc5e8e298d97cdf7a718","timestamp":"1770839722549","event_type":"book","_sub_state":"active","_subscription_id":1,"_active_subscription_id":1},"parse_warnings":[],"out_of_order":false}
{"run_id":"29526913bab7446286864a321c124486","channel":"market","event_type":"book","market":"0x8032d8355d335c6ccbfc2508d99fbc87eb13f437bd275c93ee56fd1558e517ff","asset_id":"40652734036737240317526188612064032143639112324786051284480877037991580442979","source":"market_ws:sub:active:1","t_event_ms":1770839722549,"t_recv_wall_ms":1770839722458,"t_recv_wall_iso":"2026-02-11T19:55:22.458Z","t_recv_mono_ns":618587799519875,"raw":{"market":"0x8032d8355d335c6ccbfc2508d99fbc87eb13f437bd275c93ee56fd1558e517ff","asset_id":"40652734036737240317526188612064032143639112324786051284480877037991580442979","bids":[{"price":"0.01","size":"30822.26"},{"price":"0.02","size":"12559.04"},{"price":"0.03","size":"7433.03"},{"price":"0.04","size":"5453.8"},{"price":"0.05","size":"6815.8"},{"price":"0.06","size":"5105"},{"price":"0.07","size":"5421.38"},{"price":"0.08","size":"5139.4"},{"price":"0.09","size":"5225.8"},{"price":"0.1","size":"5102.8"},{"price":"0.11","size":"120.6"},{"price":"0.12","size":"63.6"},{"price":"0.13","size":"63"},{"price":"0.14","size":"61.6"},{"price":"0.15","size":"107.39"},{"price":"0.16","size":"69.39"},{"price":"0.17","size":"58.39"},{"price":"0.18","size":"66.71"},{"price":"0.19","size":"56.8"},{"price":"0.2","size":"92.14"},{"price":"0.21","size":"60.8"},{"price":"0.22","size":"55.2"},{"price":"0.23","size":"64.48"},{"price":"0.24","size":"54.2"},{"price":"0.25","size":"375.8"},{"price":"0.26","size":"68.6"},{"price":"0.27","size":"53.2"},{"price":"0.28","size":"63.26"},{"price":"0.29","size":"52.6"},{"price":"0.3","size":"402.4"},{"price":"0.31","size":"72.2"},{"price":"0.32","size":"87.88"},{"price":"0.33","size":"188.46"},{"price":"0.34","size":"123.6"},{"price":"0.35","size":"317.03"},{"price":"0.36","size":"582.36"},{"price":"0.37","size":"559.2"},{"price":"0.38","size":"559"},{"price":"0.39","size":"594"},{"price":"0.4","size":"2915.41"},{"price":"0.41","size":"576.8"},{"price":"0.42","size":"575.5"},{"price":"0.43","size":"558.6"},{"price":"0.44","size":"572.68"},{"price":"0.45","size":"566.4"},{"price":"0.46","size":"561.94"},{"price":"0.47","size":"631.57"},{"price":"0.48","size":"611.4"},{"price":"0.49","size":"705.2"},{"price":"0.5","size":"1011.55"},{"price":"0.51","size":"692.4"},{"price":"0.52","size":"628.4"},{"price":"0.53","size":"633.4"},{"price":"0.54","size":"711.65"},{"price":"0.55","size":"866.59"},{"price":"0.56","size":"905.69"},{"price":"0.57","size":"641.6"},{"price":"0.58","size":"645.58"},{"price":"0.59","size":"564"},{"price":"0.6","size":"20642.9"},{"price":"0.61","size":"650.23"},{"price":"0.62","size":"593"},{"price":"0.63","size":"755.73"},{"price":"0.64","size":"558"},{"price":"0.65","size":"1144.32"},{"price":"0.66","size":"649.59"},{"price":"0.67","size":"624.8"},{"price":"0.68","size":"574"},{"price":"0.69","size":"594.2"},{"price":"0.7","size":"735.66"},{"price":"0.71","size":"918.6"},{"price":"0.72","size":"356.8"},{"price":"0.73","size":"869.2"},{"price":"0.74","size":"967.6"},{"price":"0.75","size":"1673.8"},{"price":"0.76","size":"869.2"},{"price":"0.77","size":"884.6"},{"price":"0.78","size":"870.2"},{"price":"0.79","size":"871.6"},{"price":"0.8","size":"987.2"},{"price":"0.81","size":"876.8"},{"price":"0.82","size":"1091.55"},{"price":"0.83","size":"958.39"},{"price":"0.84","size":"1119.39"},{"price":"0.85","size":"1149.13"},{"price":"0.86","size":"962.6"},{"price":"0.87","size":"1046.8"},{"price":"0.88","size":"1055.55"},{"price":"0.89","size":"1124.49"},{"price":"0.9","size":"659.79"},{"price":"0.91","size":"879.6"},{"price":"0.92","size":"3419.35"},{"price":"0.93","size":"3340.43"},{"price":"0.94","size":"3122.34"},{"price":"0.95","size":"3434.45"},{"price":"0.96","size":"3650.95"}],"asks":[{"price":"0.99","size":"30789.91"},{"price":"0.98","size":"10767.23"},{"price":"0.97","size":"234.36"}],"hash":"cfd6149046b5177ea0a5d2b0c46471fb8780a78d","timestamp":"1770839722549","event_type":"book","_sub_state":"active","_subscription_id":1,"_active_subscription_id":1},"parse_warnings":[],"out_of_order":false}
{"run_id":"29526913bab7446286864a321c124486","channel":"market","event_type":"price_change","market":"0x8032d8355d335c6ccbfc2508d99fbc87eb13f437bd275c93ee56fd1558e517ff","asset_id":null,"source":"market_ws:sub:active:1","t_event_ms":1770839722551,"t_recv_wall_ms":1770839722460,"t_recv_wall_iso":"2026-02-11T19:55:22.460Z","t_recv_mono_ns":618587800884458,"raw":{"market":"0x8032d8355d335c6ccbfc2508d99fbc87eb13f437bd275c93ee56fd1558e517ff","price_changes":[{"asset_id":"40652734036737240317526188612064032143639112324786051284480877037991580442979","price":"0.96","size":"3655.95","side":"BUY","hash":"9141ed913bf9178cb62b24ec435fd5120b06f2fa","best_bid":"0.96","best_ask":"0.97"},{"asset_id":"20773614133833886322101538939702011175545796528197617633926164254913649353392","price":"0.04","size":"3655.95","side":"SELL","hash":"cd49fe282ead90bc4836df3aaa8420c0a35e7332","best_bid":"0.03","best_ask":"0.04"}],"timestamp":"1770839722551","event_type":"price_change","_sub_state":"active","_subscription_id":1,"_active_subscription_id":1},"parse_warnings":[],"out_of_order":false}
{"run_id":"29526913bab7446286864a321c124486","channel":"market","event_type":"price_change","market":"0x8032d8355d335c6ccbfc2508d99fbc87eb13f437bd275c93ee56fd1558e517ff","asset_id":null,"source":"market_ws:sub:active:1","t_event_ms":1770839722553,"t_recv_wall_ms":1770839722460,"t_recv_wall_iso":"2026-02-11T19:55:22.460Z","t_recv_mono_ns":618587801248041,"raw":{"market":"0x8032d8355d335c6ccbfc2508d99fbc87eb13f437bd275c93ee56fd1558e517ff","price_changes":[{"asset_id":"40652734036737240317526188612064032143639112324786051284480877037991580442979","price":"0.82","size":"1096.55","side":"BUY","hash":"1ebc4633b9909520a9a5f4c12f62b1a1fa8c37d4","best_bid":"0.96","best_ask":"0.97"},{"asset_id":"20773614133833886322101538939702011175545796528197617633926164254913649353392","price":"0.18","size":"1096.55","side":"SELL","hash":"9e035ed14b800d4fdb919bdc3c1cd19ee634e28c","best_bid":"0.03","best_ask":"0.04"}],"timestamp":"1770839722553","event_type":"price_change","_sub_state":"active","_subscription_id":1,"_active_subscription_id":1},"parse_warnings":[],"out_of_order":false}
{"run_id":"29526913bab7446286864a321c124486","channel":"market","event_type":"price_change","market":"0x8032d8355d335c6ccbfc2508d99fbc87eb13f437bd275c93ee56fd1558e517ff","asset_id":null,"source":"market_ws:sub:active:1","t_event_ms":1770839722554,"t_recv_wall_ms":1770839722461,"t_recv_wall_iso":"2026-02-11T19:55:22.461Z","t_recv_mono_ns":618587802459875,"raw":{"market":"0x8032d8355d335c6ccbfc2508d99fbc87eb13f437bd275c93ee56fd1558e517ff","price_changes":[{"asset_id":"40652734036737240317526188612064032143639112324786051284480877037991580442979","price":"0.77","size":"864.6","side":"BUY","hash":"a04d40c4439194e60c2d483a19b00971f4133238","best_bid":"0.96","best_ask":"0.97"},{"asset_id":"20773614133833886322101538939702011175545796528197617633926164254913649353392","price":"0.23","size":"864.6","side":"SELL","hash":"1715c615cc02dfb8787dd8724a05dddee7ee2694","best_bid":"0.03","best_ask":"0.04"}],"timestamp":"1770839722554","event_type":"price_change","_sub_state":"active","_subscription_id":1,"_active_subscription_id":1},"parse_warnings":[],"out_of_order":false}
{"run_id":"29526913bab7446286864a321c124486","channel":"market","event_type":"price_change","market":"0x8032d8355d335c6ccbfc2508d99fbc87eb13f437bd275c93ee56fd1558e517ff","asset_id":null,"source":"market_ws:sub:active:1","t_event_ms":1770839722556,"t_recv_wall_ms":1770839722461,"t_recv_wall_iso":"2026-02-11T19:55:22.461Z","t_recv_mono_ns":618587802726041,"raw":{"market":"0x8032d8355d335c6ccbfc2508d99fbc87eb13f437bd275c93ee56fd1558e517ff","price_changes":[{"asset_id":"20773614133833886322101538939702011175545796528197617633926164254913649353392","price":"0.02","size":"8767.23","side":"BUY","hash":"931969e63638e88b42cdb235e95677d5f52d449b","best_bid":"0.03","best_ask":"0.04"},{"asset_id":"40652734036737240317526188612064032143639112324786051284480877037991580442979","price":"0.98","size":"8767.23","side":"SELL","hash":"99ac37381b695b9a2a4953ced5ddac456b39c2f9","best_bid":"0.96","best_ask":"0.97"}],"timestamp":"1770839722556","event_type":"price_change","_sub_state":"active","_subscription_id":1,"_active_subscription_id":1},"parse_warnings":[],"out_of_order":false}
{"run_id":"29526913bab7446286864a321c124486","channel":"market","event_type":"price_change","market":"0x8032d8355d335c6ccbfc2508d99fbc87eb13f437bd275c93ee56fd1558e517ff","asset_id":null,"source":"market_ws:sub:active:1","t_event_ms":1770839722557,"t_recv_wall_ms":1770839722462,"t_recv_wall_iso":"2026-02-11T19:55:22.462Z","t_recv_mono_ns":618587802872750,"raw":{"market":"0x8032d8355d335c6ccbfc2508d99fbc87eb13f437bd275c93ee56fd1558e517ff","price_changes":[{"asset_id":"40652734036737240317526188612064032143639112324786051284480877037991580442979","price":"0.9","size":"1191.79","side":"BUY","hash":"c267addebdf254a673ca75ba9bcca35424c943ca","best_bid":"0.96","best_ask":"0.97"},{"asset_id":"20773614133833886322101538939702011175545796528197617633926164254913649353392","price":"0.1","size":"1191.79","side":"SELL","hash":"520ee5a3c6360c75a35eb15ff5e3f2522a6f1204","best_bid":"0.03","best_ask":"0.04"}],"timestamp":"1770839722557","event_type":"price_change","_sub_state":"active","_subscription_id":1,"_active_subscription_id":1},"parse_warnings":[],"out_of_order":false}
{"run_id":"29526913bab7446286864a321c124486","channel":"market","event_type":"price_change","market":"0x8032d8355d335c6ccbfc2508d99fbc87eb13f437bd275c93ee56fd1558e517ff","asset_id":null,"source":"market_ws:sub:active:1","t_event_ms":1770839722561,"t_recv_wall_ms":1770839722466,"t_recv_wall_iso":"2026-02-11T19:55:22.466Z","t_recv_mono_ns":618587806770583,"raw":{"market":"0x8032d8355d335c6ccbfc2508d99fbc87eb13f437bd275c93ee56fd1558e517ff","price_changes":[{"asset_id":"40652734036737240317526188612064032143639112324786051284480877037991580442979","price":"0.98","size":"8762.23","side":"SELL","hash":"d3264a5f69368277b034842e75fcb8cba43c5dff","best_bid":"0.96","best_ask":"0.97"},{"asset_id":"20773614133833886322101538939702011175545796528197617633926164254913649353392","price":"0.02","size":"8762.23","side":"BUY","hash":"eac92a5bfa7511573bcc1d2c5715387274f815ec","best_bid":"0.03","best_ask":"0.04"}],"timestamp":"1770839722561","event_type":"price_change","_sub_state":"active","_subscription_id":1,"_active_subscription_id":1},"parse_warnings":[],"out_of_order":false}
{"run_id":"29526913bab7446286864a321c124486","channel":"market","event_type":"price_change","market":"0x8032d8355d335c6ccbfc2508d99fbc87eb13f437bd275c93ee56fd1558e517ff","asset_id":null,"source":"market_ws:sub:active:1","t_event_ms":1770839722562,"t_recv_wall_ms":1770839722466,"t_recv_wall_iso":"2026-02-11T19:55:22.466Z","t_recv_mono_ns":618587806963250,"raw":{"market":"0x8032d8355d335c6ccbfc2508d99fbc87eb13f437bd275c93ee56fd1558e517ff","price_changes":[{"asset_id":"20773614133833886322101538939702011175545796528197617633926164254913649353392","price":"0.03","size":"239.36","side":"BUY","hash":"ca581e262b76ddbf188f459bb8539f6dd4b5a721","best_bid":"0.03","best_ask":"0.04"},{"asset_id":"40652734036737240317526188612064032143639112324786051284480877037991580442979","price":"0.97","size":"239.36","side":"SELL","hash":"36f350e286886efcb327cdccb1fc8012684cd289","best_bid":"0.96","best_ask":"0.97"}],"timestamp":"1770839722562","event_type":"price_change","_sub_state":"active","_subscription_id":1,"_active_subscription_id":1},"parse_warnings":[],"out_of_order":false}
{"run_id":"29526913bab7446286864a321c124486","channel":"market","event_type":"price_change","market":"0x8032d8355d335c6ccbfc2508d99fbc87eb13f437bd275c93ee56fd1558e517ff","asset_id":null,"source":"market_ws:sub:active:1","t_event_ms":1770839722576,"t_recv_wall_ms":1770839722487,"t_recv_wall_iso":"2026-02-11T19:55:22.487Z","t_recv_mono_ns":618587828121125,"raw":{"market":"0x8032d8355d335c6ccbfc2508d99fbc87eb13f437bd275c93ee56fd1558e517ff","price_changes":[{"asset_id":"40652734036737240317526188612064032143639112324786051284480877037991580442979","price":"0.91","size":"799.6","side":"BUY","hash":"19c5f486020e86024908d51ad1eb4451ff00e50c","best_bid":"0.96","best_ask":"0.97"},{"asset_id":"20773614133833886322101538939702011175545796528197617633926164254913649353392","price":"0.09","size":"799.6","side":"SELL","hash":"faba422fee31d24c08da67e50e8733974da91fbc","best_bid":"0.03","best_ask":"0.04"}],"timestamp":"1770839722576","event_type":"price_change","_sub_state":"active","_subscription_id":1,"_active_subscription_id":1},"parse_warnings":[],"out_of_order":false}
{"run_id":"29526913bab7446286864a321c124486","channel":"market","event_type":"price_change","market":"0x8032d8355d335c6ccbfc2508d99fbc87eb13f437bd275c93ee56fd1558e517ff","asset_id":null,"source":"market_ws:sub:active:1","t_event_ms":1770839722579,"t_recv_wall_ms":1770839722487,"t_recv_wall_iso":"2026-02-11T19:55:22.487Z","t_recv_mono_ns":618587828360958,"raw":{"market":"0x8032d8355d335c6ccbfc2508d99fbc87eb13f437bd275c93ee56fd1558e517ff","price_changes":[{"asset_id":"40652734036737240317526188612064032143639112324786051284480877037991580442979","price":"0.94","size":"3202.34","side":"BUY","hash":"67d714e35ef86a97c17396750fb8dd7e2d6df9b0","best_bid":"0.96","best_ask":"0.97"},{"asset_id":"20773614133833886322101538939702011175545796528197617633926164254913649353392","price":"0.06","size":"3202.34","side":"SELL","hash":"01f92ff61fbaf1f78359c98982051afa57c16bce","best_bid":"0.03","best_ask":"0.04"}],"timestamp":"1770839722579","event_type":"price_change","_sub_state":"active","_subscription_id":1,"_active_subscription_id":1},"parse_warnings":[],"out_of_order":false}
{"run_id":"29526913bab7446286864a321c124486","channel":"market","event_type":"last_trade_price","market":"0x8032d8355d335c6ccbfc2508d99fbc87eb13f437bd275c93ee56fd1558e517ff","asset_id":"40652734036737240317526188612064032143639112324786051284480877037991580442979","source":"market_ws:sub:unknown","t_event_ms":1770839722580,"t_recv_wall_ms":1770839722487,"t_recv_wall_iso":"2026-02-11T19:55:22.487Z","t_recv_mono_ns":618587828516666,"raw":{"market":"0x8032d8355d335c6ccbfc2508d99fbc87eb13f437bd275c93ee56fd1558e517ff","asset_id":"40652734036737240317526188612064032143639112324786051284480877037991580442979","price":"0.96","size":"5.02","fee_rate_bps":"1000","side":"SELL","timestamp":"1770839722580","event_type":"last_trade_price","transaction_hash":"0x57d8cef12ecd74c19c0ec14354c3424be134bd7a16858be9e40a88616f461cee","_sub_state":"unknown","_subscription_id":null,"_active_subscription_id":1},"parse_warnings":["unknown_message_schema"],"out_of_order":false}
{"run_id":"29526913bab7446286864a321c124486","channel":"market","event_type":"price_change","market":"0x8032d8355d335c6ccbfc2508d99fbc87eb13f437bd275c93ee56fd1558e517ff","asset_id":null,"source":"market_ws:sub:active:1","t_event_ms":1770839722582,"t_recv_wall_ms":1770839722492,"t_recv_wall_iso":"2026-02-11T19:55:22.492Z","t_recv_mono_ns":618587833495541,"raw":{"market":"0x8032d8355d335c6ccbfc2508d99fbc87eb13f437bd275c93ee56fd1558e517ff","price_changes":[{"asset_id":"40652734036737240317526188612064032143639112324786051284480877037991580442979","price":"0.95","size":"3439.45","side":"BUY","hash":"cb7eed5327c373e87cae27b436530832b61fef45","best_bid":"0.96","best_ask":"0.97"},{"asset_id":"20773614133833886322101538939702011175545796528197617633926164254913649353392","price":"0.05","size":"3439.45","side":"SELL","hash":"ac1aea5b9da3f3a2563cfc415f3d652ee1f38c07","best_bid":"0.03","best_ask":"0.04"}],"timestamp":"1770839722582","event_type":"price_change","_sub_state":"active","_subscription_id":1,"_active_subscription_id":1},"parse_warnings":[],"out_of_order":false}
{"run_id":"29526913bab7446286864a321c124486","channel":"market","event_type":"price_change","market":"0x8032d8355d335c6ccbfc2508d99fbc87eb13f437bd275c93ee56fd1558e517ff","asset_id":null,"source":"market_ws:sub:active:1","t_event_ms":1770839722585,"t_recv_wall_ms":1770839722493,"t_recv_wall_iso":"2026-02-11T19:55:22.493Z","t_recv_mono_ns":618587833749833,"raw":{"market":"0x8032d8355d335c6ccbfc2508d99fbc87eb13f437bd275c93ee56fd1558e517ff","price_changes":[{"asset_id":"20773614133833886322101538939702011175545796528197617633926164254913649353392","price":"0.02","size":"8732.23","side":"BUY","hash":"c087070e0f1f3e3ad22ada4d4c9e4cf1d0997724","best_bid":"0.03","best_ask":"0.04"},{"asset_id":"40652734036737240317526188612064032143639112324786051284480877037991580442979","price":"0.98","size":"8732.23","side":"SELL","hash":"5edcd25bf64c9613c1a59204bd3e2889dea98fd0","best_bid":"0.96","best_ask":"0.97"}],"timestamp":"1770839722585","event_type":"price_change","_sub_state":"active","_subscription_id":1,"_active_subscription_id":1},"parse_warnings":[],"out_of_order":false}
{"run_id":"29526913bab7446286864a321c124486","channel":"market","event_type":"price_change","market":"0x8032d8355d335c6ccbfc2508d99fbc87eb13f437bd275c93ee56fd1558e517ff","asset_id":null,"source":"market_ws:sub:active:1","t_event_ms":1770839722588,"t_recv_wall_ms":1770839722496,"t_recv_wall_iso":"2026-02-11T19:55:22.496Z","t_recv_mono_ns":618587837715708,"raw":{"market":"0x8032d8355d335c6ccbfc2508d99fbc87eb13f437bd275c93ee56fd1558e517ff","price_changes":[{"asset_id":"40652734036737240317526188612064032143639112324786051284480877037991580442979","price":"0.95","size":"3409.45","side":"BUY","hash":"7e8644c7a383b670babcd0e63626b739dbd8c513","best_bid":"0.96","best_ask":"0.97"},{"asset_id":"20773614133833886322101538939702011175545796528197617633926164254913649353392","price":"0.05","size":"3409.45","side":"SELL","hash":"7812cd63baec9c37b7a7de246a48fc0c9f0b3b2b","best_bid":"0.03","best_ask":"0.04"}],"timestamp":"1770839722588","event_type":"price_change","_sub_state":"active","_subscription_id":1,"_active_subscription_id":1},"parse_warnings":[],"out_of_order":false}
{"run_id":"29526913bab7446286864a321c124486","channel":"market","event_type":"price_change","market":"0x8032d8355d335c6ccbfc2508d99fbc87eb13f437bd275c93ee56fd1558e517ff","asset_id":null,"source":"market_ws:sub:active:1","t_event_ms":1770839722590,"t_recv_wall_ms":1770839722497,"t_recv_wall_iso":"2026-02-11T19:55:22.497Z","t_recv_mono_ns":618587837973041,"raw":{"market":"0x8032d8355d335c6ccbfc2508d99fbc87eb13f437bd275c93ee56fd1558e517ff","price_changes":[{"asset_id":"20773614133833886322101538939702011175545796528197617633926164254913649353392","price":"0.01","size":"30759.91","side":"BUY","hash":"44bf91c2a4fed3a4e315758314088b2ffb47ecdb","best_bid":"0.03","best_ask":"0.04"},{"asset_id":"40652734036737240317526188612064032143639112324786051284480877037991580442979","price":"0.99","size":"30759.91","side":"SELL","hash":"805af8624b5e8e5bdd019a5dc26d20c65e60f83a","best_bid":"0.96","best_ask":"0.97"}],"timestamp":"1770839722590","event_type":"price_change","_sub_state":"active","_subscription_id":1,"_active_subscription_id":1},"parse_warnings":[],"out_of_order":false}
{"run_id":"29526913bab7446286864a321c124486","channel":"market","event_type":"price_change","market":"0x8032d8355d335c6ccbfc2508d99fbc87eb13f437bd275c93ee56fd1558e517ff","asset_id":null,"source":"market_ws:sub:active:1","t_event_ms":1770839722594,"t_recv_wall_ms":1770839722500,"t_recv_wall_iso":"2026-02-11T19:55:22.500Z","t_recv_mono_ns":618587840850583,"raw":{"market":"0x8032d8355d335c6ccbfc2508d99fbc87eb13f437bd275c93ee56fd1558e517ff","price_changes":[{"asset_id":"20773614133833886322101538939702011175545796528197617633926164254913649353392","price":"0.02","size":"8702.23","side":"BUY","hash":"dc65dea20b33185e71c6e5168e2c0b88428831fa","best_bid":"0.03","best_ask":"0.04"},{"asset_id":"40652734036737240317526188612064032143639112324786051284480877037991580442979","price":"0.98","size":"8702.23","side":"SELL","hash":"22c4e0297d81cb3fef79489fe7ebefb8938ad8ec","best_bid":"0.96","best_ask":"0.97"}],"timestamp":"1770839722594","event_type":"price_change","_sub_state":"active","_subscription_id":1,"_active_subscription_id":1},"parse_warnings":[],"out_of_order":false}
{"run_id":"29526913bab7446286864a321c124486","channel":"market","event_type":"price_change","market":"0x8032d8355d335c6ccbfc2508d99fbc87eb13f437bd275c93ee56fd1558e517ff","asset_id":null,"source":"market_ws:sub:active:1","t_event_ms":1770839722597,"t_recv_wall_ms":1770839722503,"t_recv_wall_iso":"2026-02-11T19:55:22.503Z","t_recv_mono_ns":618587844513958,"raw":{"market":"0x8032d8355d335c6ccbfc2508d99fbc87eb13f437bd275c93ee56fd1558e517ff","price_changes":[{"asset_id":"40652734036737240317526188612064032143639112324786051284480877037991580442979","price":"0.91","size":"679.6","side":"BUY","hash":"f91b43385fa7ead6716caab7b6cd8d0c43555ac3","best_bid":"0.96","best_ask":"0.97"},{"asset_id":"20773614133833886322101538939702011175545796528197617633926164254913649353392","price":"0.09","size":"679.6","side":"SELL","hash":"4c65bdce4d1a892c0b61e5ba4fe6face49b8ea3f","best_bid":"0.03","best_ask":"0.04"}],"timestamp":"1770839722597","event_type":"price_change","_sub_state":"active","_subscription_id":1,"_active_subscription_id":1},"parse_warnings":[],"out_of_order":false}
{"run_id":"29526913bab7446286864a321c124486","channel":"market","event_type":"price_change","market":"0x8032d8355d335c6ccbfc2508d99fbc87eb13f437bd275c93ee56fd1558e517ff","asset_id":null,"source":"market_ws:sub:active:1","t_event_ms":1770839722600,"t_recv_wall_ms":1770839722506,"t_recv_wall_iso":"2026-02-11T19:55:22.506Z","t_recv_mono_ns":618587847122916,"raw":{"market":"0x8032d8355d335c6ccbfc2508d99fbc87eb13f437bd275c93ee56fd1558e517ff","price_changes":[{"asset_id":"40652734036737240317526188612064032143639112324786051284480877037991580442979","price":"0.94","size":"3322.34","side":"BUY","hash":"43a18190fd16b4e5d3f5d0c359d89516d998c5ee","best_bid":"0.96","best_ask":"0.97"},{"asset_id":"20773614133833886322101538939702011175545796528197617633926164254913649353392","price":"0.06","size":"3322.34","side":"SELL","hash":"265d2b987f7dea2bdbb882ad0d06c5353771a80c","best_bid":"0.03","best_ask":"0.04"}],"timestamp":"1770839722600","event_type":"price_change","_sub_state":"active","_subscription_id":1,"_active_subscription_id":1},"parse_warnings":[],"out_of_order":false}
{"run_id":"29526913bab7446286864a321c124486","channel":"market","event_type":"price_change","market":"0x8032d8355d335c6ccbfc2508d99fbc87eb13f437bd275c93ee56fd1558e517ff","asset_id":null,"source":"market_ws:sub:active:1","t_event_ms":1770839722606,"t_recv_wall_ms":1770839722514,"t_recv_wall_iso":"2026-02-11T19:55:22.514Z","t_recv_mono_ns":618587855061791,"raw":{"market":"0x8032d8355d335c6ccbfc2508d99fbc87eb13f437bd275c93ee56fd1558e517ff","price_changes":[{"asset_id":"40652734036737240317526188612064032143639112324786051284480877037991580442979","price":"0.87","size":"1041.8","side":"BUY","hash":"62a574dc5353587d676f1800595e4c285b2e64c2","best_bid":"0.96","best_ask":"0.97"},{"asset_id":"20773614133833886322101538939702011175545796528197617633926164254913649353392","price":"0.13","size":"1041.8","side":"SELL","hash":"c32d3d6c8f83c503fa50b42a5a850316509ea6c5","best_bid":"0.03","best_ask":"0.04"}],"timestamp":"1770839722606","event_type":"price_change","_sub_state":"active","_subscription_id":1,"_active_subscription_id":1},"parse_warnings":[],"out_of_order":false}
{"run_id":"29526913bab7446286864a321c124486","channel":"market","event_type":"price_change","market":"0x8032d8355d335c6ccbfc2508d99fbc87eb13f437bd275c93ee56fd1558e517ff","asset_id":null,"source":"market_ws:sub:active:1","t_event_ms":1770839722609,"t_recv_wall_ms":1770839722517,"t_recv_wall_iso":"2026-02-11T19:55:22.517Z","t_recv_mono_ns":618587858165833,"raw":{"market":"0x8032d8355d335c6ccbfc2508d99fbc87eb13f437bd275c93ee56fd1558e517ff","price_changes":[{"asset_id":"40652734036737240317526188612064032143639112324786051284480877037991580442979","price":"0.95","size":"3379.45","side":"BUY","hash":"567b365d14e954977f99da73a866060cbbe74fe9","best_bid":"0.96","best_ask":"0.97"},{"asset_id":"20773614133833886322101538939702011175545796528197617633926164254913649353392","price":"0.05","size":"3379.45","side":"SELL","hash":"520f9b493cb5b94ba56dd096c652912144b66f0c","best_bid":"0.03","best_ask":"0.04"}],"timestamp":"1770839722609","event_type":"price_change","_sub_state":"active","_subscription_id":1,"_active_subscription_id":1},"parse_warnings":[],"out_of_order":false}
{"run_id":"29526913bab7446286864a321c124486","channel":"market","event_type":"price_change","market":"0x8032d8355d335c6ccbfc2508d99fbc87eb13f437bd275c93ee56fd1558e517ff","asset_id":null,"source":"market_ws:sub:active:1","t_event_ms":1770839722614,"t_recv_wall_ms":1770839722523,"t_recv_wall_iso":"2026-02-11T19:55:22.523Z","t_recv_mono_ns":618587864719791,"raw":{"market":"0x8032d8355d335c6ccbfc2508d99fbc87eb13f437bd275c93ee56fd1558e517ff","price_changes":[{"asset_id":"40652734036737240317526188612064032143639112324786051284480877037991580442979","price":"0.94","size":"3317.34","side":"BUY","hash":"3314abf9bc45315a97bbc18e8b33e75c8ee7db58","best_bid":"0.96","best_ask":"0.97"},{"asset_id":"20773614133833886322101538939702011175545796528197617633926164254913649353392","price":"0.06","size":"3317.34","side":"SELL","hash":"b50f3a634e8d7b451a903be1d8d681b743df600e","best_bid":"0.03","best_ask":"0.04"}],"timestamp":"1770839722614","event_type":"price_change","_sub_state":"active","_subscription_id":1,"_active_subscription_id":1},"parse_warnings":[],"out_of_order":false}
{"run_id":"29526913bab7446286864a321c124486","channel":"market","event_type":"price_change","market":"0x8032d8355d335c6ccbfc2508d99fbc87eb13f437bd275c93ee56fd1558e517ff","asset_id":null,"source":"market_ws:sub:active:1","t_event_ms":1770839722616,"t_recv_wall_ms":1770839722524,"t_recv_wall_iso":"2026-02-11T19:55:22.524Z","t_recv_mono_ns":618587865127791,"raw":{"market":"0x8032d8355d335c6ccbfc2508d99fbc87eb13f437bd275c93ee56fd1558e517ff","price_changes":[{"asset_id":"40652734036737240317526188612064032143639112324786051284480877037991580442979","price":"0.96","size":"3650.95","side":"BUY","hash":"2b87fcf5aa66ff5f55805182205498e480a63ce6","best_bid":"0.96","best_ask":"0.97"},{"asset_id":"20773614133833886322101538939702011175545796528197617633926164254913649353392","price":"0.04","size":"3650.95","side":"SELL","hash":"4be8309a899c20d963d1bd7a87cc28d164cfb573","best_bid":"0.03","best_ask":"0.04"}],"timestamp":"1770839722616","event_type":"price_change","_sub_state":"active","_subscription_id":1,"_active_subscription_id":1},"parse_warnings":[],"out_of_order":false}
{"run_id":"29526913bab7446286864a321c124486","channel":"market","event_type":"price_change","market":"0x8032d8355d335c6ccbfc2508d99fbc87eb13f437bd275c93ee56fd1558e517ff","asset_id":null,"source":"market_ws:sub:active:1","t_event_ms":1770839722617,"t_recv_wall_ms":1770839722524,"t_recv_wall_iso":"2026-02-11T19:55:22.524Z","t_recv_mono_ns":618587865389750,"raw":{"market":"0x8032d8355d335c6ccbfc2508d99fbc87eb13f437bd275c93ee56fd1558e517ff","price_changes":[{"asset_id":"20773614133833886322101538939702011175545796528197617633926164254913649353392","price":"0.01","size":"30789.91","side":"BUY","hash":"6105277cdaf642a577116bf9a2b37bfae0bcc9b2","best_bid":"0.03","best_ask":"0.04"},{"asset_id":"40652734036737240317526188612064032143639112324786051284480877037991580442979","price":"0.99","size":"30789.91","side":"SELL","hash":"4e8aef2721a1456c1046aed40c4bad30c013d985","best_bid":"0.96","best_ask":"0.97"}],"timestamp":"1770839722617","event_type":"price_change","_sub_state":"active","_subscription_id":1,"_active_subscription_id":1},"parse_warnings":[],"out_of_order":false}
{"run_id":"29526913bab7446286864a321c124486","channel":"market","event_type":"price_change","market":"0x8032d8355d335c6ccbfc2508d99fbc87eb13f437bd275c93ee56fd1558e517ff","asset_id":null,"source":"market_ws:sub:active:1","t_event_ms":1770839722619,"t_recv_wall_ms":1770839722533,"t_recv_wall_iso":"2026-02-11T19:55:22.533Z","t_recv_mono_ns":618587874047250,"raw":{"market":"0x8032d8355d335c6ccbfc2508d99fbc87eb13f437bd275c93ee56fd1558e517ff","price_changes":[{"asset_id":"40652734036737240317526188612064032143639112324786051284480877037991580442979","price":"0.78","size":"890.2","side":"BUY","hash":"b6781c8918ee8d361bdfc0899bb024f7ef5f0ab5","best_bid":"0.96","best_ask":"0.97"},{"asset_id":"20773614133833886322101538939702011175545796528197617633926164254913649353392","price":"0.22","size":"890.2","side":"SELL","hash":"10cb0c57607117cfbf189ea29a7a285e31fcc530","best_bid":"0.03","best_ask":"0.04"}],"timestamp":"1770839722619","event_type":"price_change","_sub_state":"active","_subscription_id":1,"_active_subscription_id":1},"parse_warnings":[],"out_of_order":false}
{"run_id":"29526913bab7446286864a321c124486","channel":"market","event_type":"price_change","market":"0x8032d8355d335c6ccbfc2508d99fbc87eb13f437bd275c93ee56fd1558e517ff","asset_id":null,"source":"market_ws:sub:active:1","t_event_ms":1770839722623,"t_recv_wall_ms":1770839722533,"t_recv_wall_iso":"2026-02-11T19:55:22.533Z","t_recv_mono_ns":618587874471833,"raw":{"market":"0x8032d8355d335c6ccbfc2508d99fbc87eb13f437bd275c93ee56fd1558e517ff","price_changes":[{"asset_id":"40652734036737240317526188612064032143639112324786051284480877037991580442979","price":"0.96","size":"3680.95","side":"BUY","hash":"e3523f68cfb0f592b796f7f9e510bb5b6754276e","best_bid":"0.96","best_ask":"0.97"},{"asset_id":"20773614133833886322101538939702011175545796528197617633926164254913649353392","price":"0.04","size":"3680.95","side":"SELL","hash":"740aa51cf5875d507bc52605bafdb1a2d7491f06","best_bid":"0.03","best_ask":"0.04"}],"timestamp":"1770839722623","event_type":"price_change","_sub_state":"active","_subscription_id":1,"_active_subscription_id":1},"parse_warnings":[],"out_of_order":false}
{"run_id":"29526913bab7446286864a321c124486","channel":"market","event_type":"price_change","market":"0x8032d8355d335c6ccbfc2508d99fbc87eb13f437bd275c93ee56fd1558e517ff","asset_id":null,"source":"market_ws:sub:active:1","t_event_ms":1770839722624,"t_recv_wall_ms":1770839722533,"t_recv_wall_iso":"2026-02-11T19:55:22.533Z","t_recv_mono_ns":618587874667666,"raw":{"market":"0x8032d8355d335c6ccbfc2508d99fbc87eb13f437bd275c93ee56fd1558e517ff","price_changes":[{"asset_id":"20773614133833886322101538939702011175545796528197617633926164254913649353392","price":"0.01","size":"30819.91","side":"BUY","hash":"ac0d801585a8526c523d6b8df0db608cc5c8803c","best_bid":"0.03","best_ask":"0.04"},{"asset_id":"40652734036737240317526188612064032143639112324786051284480877037991580442979","price":"0.99","size":"30819.91","side":"SELL","hash":"f08d74989cdc8417b568e3214a3e17be2b1ca24b","best_bid":"0.96","best_ask":"0.97"}],"timestamp":"1770839722624","event_type":"price_change","_sub_state":"active","_subscription_id":1,"_active_subscription_id":1},"parse_warnings":[],"out_of_order":false}
{"run_id":"29526913bab7446286864a321c124486","channel":"market","event_type":"price_change","market":"0x8032d8355d335c6ccbfc2508d99fbc87eb13f437bd275c93ee56fd1558e517ff","asset_id":null,"source":"market_ws:sub:active:1","t_event_ms":1770839722628,"t_recv_wall_ms":1770839722541,"t_recv_wall_iso":"2026-02-11T19:55:22.541Z","t_recv_mono_ns":618587881747583,"raw":{"market":"0x8032d8355d335c6ccbfc2508d99fbc87eb13f437bd275c93ee56fd1558e517ff","price_changes":[{"asset_id":"40652734036737240317526188612064032143639112324786051284480877037991580442979","price":"0.94","size":"3311.34","side":"BUY","hash":"b11b3f4264a5fd27b7a410e2928c30643ad796bc","best_bid":"0.96","best_ask":"0.97"},{"asset_id":"20773614133833886322101538939702011175545796528197617633926164254913649353392","price":"0.06","size":"3311.34","side":"SELL","hash":"b6c287f0f1c9ebe543dbd6d5033294db14a9170c","best_bid":"0.03","best_ask":"0.04"}],"timestamp":"1770839722628","event_type":"price_change","_sub_state":"active","_subscription_id":1,"_active_subscription_id":1},"parse_warnings":[],"out_of_order":false}
{"run_id":"29526913bab7446286864a321c124486","channel":"market","event_type":"price_change","market":"0x8032d8355d335c6ccbfc2508d99fbc87eb13f437bd275c93ee56fd1558e517ff","asset_id":null,"source":"market_ws:sub:active:1","t_event_ms":1770839722630,"t_recv_wall_ms":1770839722541,"t_recv_wall_iso":"2026-02-11T19:55:22.541Z","t_recv_mono_ns":618587882294166,"raw":{"market":"0x8032d8355d335c6ccbfc2508d99fbc87eb13f437bd275c93ee56fd1558e517ff","price_changes":[{"asset_id":"20773614133833886322101538939702011175545796528197617633926164254913649353392","price":"0.03","size":"233.36","side":"BUY","hash":"ac0c9a19a90bf1ec23cada6d5b7ea150cfc249e9","best_bid":"0.03","best_ask":"0.04"},{"asset_id":"40652734036737240317526188612064032143639112324786051284480877037991580442979","price":"0.97","size":"233.36","side":"SELL","hash":"89ceb7cab816a87e8921b6867f8ce0f4d12c93df","best_bid":"0.96","best_ask":"0.97"}],"timestamp":"1770839722630","event_type":"price_change","_sub_state":"active","_subscription_id":1,"_active_subscription_id":1},"parse_warnings":[],"out_of_order":false}
{"run_id":"29526913bab7446286864a321c124486","channel":"market","event_type":"price_change","market":"0x8032d8355d335c6ccbfc2508d99fbc87eb13f437bd275c93ee56fd1558e517ff","asset_id":null,"source":"market_ws:sub:active:1","t_event_ms":1770839722635,"t_recv_wall_ms":1770839722549,"t_recv_wall_iso":"2026-02-11T19:55:22.549Z","t_recv_mono_ns":618587890353916,"raw":{"market":"0x8032d8355d335c6ccbfc2508d99fbc87eb13f437bd275c93ee56fd1558e517ff","price_changes":[{"asset_id":"40652734036737240317526188612064032143639112324786051284480877037991580442979","price":"0.88","size":"1060.55","side":"BUY","hash":"b408805f28ac0f45317179e8a6adf0184ac7b81b","best_bid":"0.96","best_ask":"0.97"},{"asset_id":"20773614133833886322101538939702011175545796528197617633926164254913649353392","price":"0.12","size":"1060.55","side":"SELL","hash":"94fc77b18921e083a0c21f4657cb51fdb061c6a0","best_bid":"0.03","best_ask":"0.04"}],"timestamp":"1770839722635","event_type":"price_change","_sub_state":"active","_subscription_id":1,"_active_subscription_id":1},"parse_warnings":[],"out_of_order":false}
{"run_id":"29526913bab7446286864a321c124486","channel":"market","event_type":"price_change","market":"0x8032d8355d335c6ccbfc2508d99fbc87eb13f437bd275c93ee56fd1558e517ff","asset_id":null,"source":"market_ws:sub:active:1","t_event_ms":1770839722644,"t_recv_wall_ms":1770839722550,"t_recv_wall_iso":"2026-02-11T19:55:22.550Z","t_recv_mono_ns":618587890905208,"raw":{"market":"0x8032d8355d335c6ccbfc2508d99fbc87eb13f437bd275c93ee56fd1558e517ff","price_changes":[{"asset_id":"40652734036737240317526188612064032143639112324786051284480877037991580442979","price":"0.82","size":"1091.55","side":"BUY","hash":"2998dd0e22240c869c65fa124fd4d4543a41999d","best_bid":"0.96","best_ask":"0.97"},{"asset_id":"20773614133833886322101538939702011175545796528197617633926164254913649353392","price":"0.18","size":"1091.55","side":"SELL","hash":"e6ed4ad56f7cbcafd05ebbacd29fdcb3bba4eaf7","best_bid":"0.03","best_ask":"0.04"}],"timestamp":"1770839722644","event_type":"price_change","_sub_state":"active","_subscription_id":1,"_active_subscription_id":1},"parse_warnings":[],"out_of_order":false}
{"run_id":"29526913bab7446286864a321c124486","channel":"market","event_type":"price_change","market":"0x8032d8355d335c6ccbfc2508d99fbc87eb13f437bd275c93ee56fd1558e517ff","asset_id":null,"source":"market_ws:sub:active:1","t_event_ms":1770839722657,"t_recv_wall_ms":1770839722562,"t_recv_wall_iso":"2026-02-11T19:55:22.562Z","t_recv_mono_ns":618587903585333,"raw":{"market":"0x8032d8355d335c6ccbfc2508d99fbc87eb13f437bd275c93ee56fd1558e517ff","price_changes":[{"asset_id":"40652734036737240317526188612064032143639112324786051284480877037991580442979","price":"0.96","size":"3710.95","side":"BUY","hash":"ff4836cdc743ee2e9b657ecf68473ec7f692d24b","best_bid":"0.96","best_ask":"0.97"},{"asset_id":"20773614133833886322101538939702011175545796528197617633926164254913649353392","price":"0.04","size":"3710.95","side":"SELL","hash":"878953560cba6199d48f72245d6db8f185ef8e4f","best_bid":"0.03","best_ask":"0.04"}],"timestamp":"1770839722657","event_type":"price_change","_sub_state":"active","_subscription_id":1,"_active_subscription_id":1},"parse_warnings":[],"out_of_order":false}
{"run_id":"29526913bab7446286864a321c124486","channel":"market","event_type":"price_change","market":"0x8032d8355d335c6ccbfc2508d99fbc87eb13f437bd275c93ee56fd1558e517ff","asset_id":null,"source":"market_ws:sub:active:1","t_event_ms":1770839722659,"t_recv_wall_ms":1770839722566,"t_recv_wall_iso":"2026-02-11T19:55:22.566Z","t_recv_mono_ns":618587907085458,"raw":{"market":"0x8032d8355d335c6ccbfc2508d99fbc87eb13f437bd275c93ee56fd1558e517ff","price_changes":[{"asset_id":"40652734036737240317526188612064032143639112324786051284480877037991580442979","price":"0.95","size":"3349.45","side":"BUY","hash":"03ab8f529cb978f7727f5d828fe33b7ea71402d4","best_bid":"0.96","best_ask":"0.97"},{"asset_id":"20773614133833886322101538939702011175545796528197617633926164254913649353392","price":"0.05","size":"3349.45","side":"SELL","hash":"bb131a2460ce300cfb7c7634ebdd470cf67a5732","best_bid":"0.03","best_ask":"0.04"}],"timestamp":"1770839722659","event_type":"price_change","_sub_state":"active","_subscription_id":1,"_active_subscription_id":1},"parse_warnings":[],"out_of_order":false}
{"run_id":"29526913bab7446286864a321c124486","channel":"market","event_type":"price_change","market":"0x8032d8355d335c6ccbfc2508d99fbc87eb13f437bd275c93ee56fd1558e517ff","asset_id":null,"source":"market_ws:sub:active:1","t_event_ms":1770839722661,"t_recv_wall_ms":1770839722574,"t_recv_wall_iso":"2026-02-11T19:55:22.574Z","t_recv_mono_ns":618587915427208,"raw":{"market":"0x8032d8355d335c6ccbfc2508d99fbc87eb13f437bd275c93ee56fd1558e517ff","price_changes":[{"asset_id":"40652734036737240317526188612064032143639112324786051284480877037991580442979","price":"0.78","size":"870.2","side":"BUY","hash":"635f5d3d2ee47db197adeb682eb5d6bf1fcb9639","best_bid":"0.96","best_ask":"0.97"},{"asset_id":"20773614133833886322101538939702011175545796528197617633926164254913649353392","price":"0.22","size":"870.2","side":"SELL","hash":"cf973fd7237627c0d7ea943d371a3b22403f515e","best_bid":"0.03","best_ask":"0.04"}],"timestamp":"1770839722661","event_type":"price_change","_sub_state":"active","_subscription_id":1,"_active_subscription_id":1},"parse_warnings":[],"out_of_order":false}
{"run_id":"29526913bab7446286864a321c124486","channel":"market","event_type":"price_change","market":"0x8032d8355d335c6ccbfc2508d99fbc87eb13f437bd275c93ee56fd1558e517ff","asset_id":null,"source":"market_ws:sub:active:1","t_event_ms":1770839722670,"t_recv_wall_ms":1770839722579,"t_recv_wall_iso":"2026-02-11T19:55:22.579Z","t_recv_mono_ns":618587920450625,"raw":{"market":"0x8032d8355d335c6ccbfc2508d99fbc87eb13f437bd275c93ee56fd1558e517ff","price_changes":[{"asset_id":"20773614133833886322101538939702011175545796528197617633926164254913649353392","price":"0.03","size":"203.36","side":"BUY","hash":"db9951739a826d611870af608b3cfd8edba62f7c","best_bid":"0.03","best_ask":"0.04"},{"asset_id":"40652734036737240317526188612064032143639112324786051284480877037991580442979","price":"0.97","size":"203.36","side":"SELL","hash":"7b18b80cb53ac1e4a05c64c598c2f2b5928c00fe","best_bid":"0.96","best_ask":"0.97"}],"timestamp":"1770839722670","event_type":"price_change","_sub_state":"active","_subscription_id":1,"_active_subscription_id":1},"parse_warnings":[],"out_of_order":false}
{"run_id":"29526913bab7446286864a321c124486","channel":"market","event_type":"price_change","market":"0x8032d8355d335c6ccbfc2508d99fbc87eb13f437bd275c93ee56fd1558e517ff","asset_id":null,"source":"market_ws:sub:active:1","t_event_ms":1770839722675,"t_recv_wall_ms":1770839722587,"t_recv_wall_iso":"2026-02-11T19:55:22.587Z","t_recv_mono_ns":618587928262458,"raw":{"market":"0x8032d8355d335c6ccbfc2508d99fbc87eb13f437bd275c93ee56fd1558e517ff","price_changes":[{"asset_id":"40652734036737240317526188612064032143639112324786051284480877037991580442979","price":"0.96","size":"3770.95","side":"BUY","hash":"f4e44db08f6b88a22a29d2192bd8daa7584d5737","best_bid":"0.96","best_ask":"0.97"},{"asset_id":"20773614133833886322101538939702011175545796528197617633926164254913649353392","price":"0.04","size":"3770.95","side":"SELL","hash":"e496fe9cb6151cc151bf031f113836e2f4354a1a","best_bid":"0.03","best_ask":"0.04"}],"timestamp":"1770839722675","event_type":"price_change","_sub_state":"active","_subscription_id":1,"_active_subscription_id":1},"parse_warnings":[],"out_of_order":false}
{"run_id":"29526913bab7446286864a321c124486","channel":"market","event_type":"price_change","market":"0x8032d8355d335c6ccbfc2508d99fbc87eb13f437bd275c93ee56fd1558e517ff","asset_id":null,"source":"market_ws:sub:active:1","t_event_ms":1770839722682,"t_recv_wall_ms":1770839722587,"t_recv_wall_iso":"2026-02-11T19:55:22.587Z","t_recv_mono_ns":618587928604250,"raw":{"market":"0x8032d8355d335c6ccbfc2508d99fbc87eb13f437bd275c93ee56fd1558e517ff","price_changes":[{"asset_id":"40652734036737240317526188612064032143639112324786051284480877037991580442979","price":"0.95","size":"3319.45","side":"BUY","hash":"ecddcc867eeb60ed82dd6d641a676d714f511221","best_bid":"0.96","best_ask":"0.97"},{"asset_id":"20773614133833886322101538939702011175545796528197617633926164254913649353392","price":"0.05","size":"3319.45","side":"SELL","hash":"1fc052562ef9d6e19533736050086ff9b0162057","best_bid":"0.03","best_ask":"0.04"}],"timestamp":"1770839722682","event_type":"price_change","_sub_state":"active","_subscription_id":1,"_active_subscription_id":1},"parse_warnings":[],"out_of_order":false}
{"run_id":"29526913bab7446286864a321c124486","channel":"market","event_type":"price_change","market":"0x8032d8355d335c6ccbfc2508d99fbc87eb13f437bd275c93ee56fd1558e517ff","asset_id":null,"source":"market_ws:sub:active:1","t_event_ms":1770839722686,"t_recv_wall_ms":1770839722592,"t_recv_wall_iso":"2026-02-11T19:55:22.592Z","t_recv_mono_ns":618587933651916,"raw":{"market":"0x8032d8355d335c6ccbfc2508d99fbc87eb13f437bd275c93ee56fd1558e517ff","price_changes":[{"asset_id":"20773614133833886322101538939702011175545796528197617633926164254913649353392","price":"0.01","size":"30799.91","side":"BUY","hash":"4dd813e650c4cf88a127a836bf3d529b6ddcfa46","best_bid":"0.03","best_ask":"0.04"},{"asset_id":"40652734036737240317526188612064032143639112324786051284480877037991580442979","price":"0.99","size":"30799.91","side":"SELL","hash":"99871ee6b4b4904990cbcd6ef743008134ada0bd","best_bid":"0.96","best_ask":"0.97"}],"timestamp":"1770839722686","event_type":"price_change","_sub_state":"active","_subscription_id":1,"_active_subscription_id":1},"parse_warnings":[],"out_of_order":false}
{"run_id":"29526913bab7446286864a321c124486","channel":"market","event_type":"price_change","market":"0x8032d8355d335c6ccbfc2508d99fbc87eb13f437bd275c93ee56fd1558e517ff","asset_id":null,"source":"market_ws:sub:active:1","t_event_ms":1770839722687,"t_recv_wall_ms":1770839722604,"t_recv_wall_iso":"2026-02-11T19:55:22.604Z","t_recv_mono_ns":618587945336833,"raw":{"market":"0x8032d8355d335c6ccbfc2508d99fbc87eb13f437bd275c93ee56fd1558e517ff","price_changes":[{"asset_id":"40652734036737240317526188612064032143639112324786051284480877037991580442979","price":"0.95","size":"3289.45","side":"BUY","hash":"41b828f92a957aed50b8e060aac55e24f326b16d","best_bid":"0.96","best_ask":"0.97"},{"asset_id":"20773614133833886322101538939702011175545796528197617633926164254913649353392","price":"0.05","size":"3289.45","side":"SELL","hash":"79b73104cbd99d927db7ed2c2770f548a6eb4988","best_bid":"0.03","best_ask":"0.04"}],"timestamp":"1770839722687","event_type":"price_change","_sub_state":"active","_subscription_id":1,"_active_subscription_id":1},"parse_warnings":[],"out_of_order":false}
{"run_id":"29526913bab7446286864a321c124486","channel":"market","event_type":"price_change","market":"0x8032d8355d335c6ccbfc2508d99fbc87eb13f437bd275c93ee56fd1558e517ff","asset_id":null,"source":"market_ws:sub:active:1","t_event_ms":1770839722689,"t_recv_wall_ms":1770839722605,"t_recv_wall_iso":"2026-02-11T19:55:22.605Z","t_recv_mono_ns":618587945954250,"raw":{"market":"0x8032d8355d335c6ccbfc2508d99fbc87eb13f437bd275c93ee56fd1558e517ff","price_changes":[{"asset_id":"40652734036737240317526188612064032143639112324786051284480877037991580442979","price":"0.88","size":"1105.55","side":"BUY","hash":"08e70965bfd09be1594fbd6d41398453e41e469c","best_bid":"0.96","best_ask":"0.97"},{"asset_id":"20773614133833886322101538939702011175545796528197617633926164254913649353392","price":"0.12","size":"1105.55","side":"SELL","hash":"7606187790ef0311af2a5a8d6c49cbf13776b58e","best_bid":"0.03","best_ask":"0.04"}],"timestamp":"1770839722689","event_type":"price_change","_sub_state":"active","_subscription_id":1,"_active_subscription_id":1},"parse_warnings":[],"out_of_order":false}
{"run_id":"29526913bab7446286864a321c124486","channel":"market","event_type":"price_change","market":"0x8032d8355d335c6ccbfc2508d99fbc87eb13f437bd275c93ee56fd1558e517ff","asset_id":null,"source":"market_ws:sub:active:1","t_event_ms":1770839722691,"t_recv_wall_ms":1770839722605,"t_recv_wall_iso":"2026-02-11T19:55:22.605Z","t_recv_mono_ns":618587946184333,"raw":{"market":"0x8032d8355d335c6ccbfc2508d99fbc87eb13f437bd275c93ee56fd1558e517ff","price_changes":[{"asset_id":"40652734036737240317526188612064032143639112324786051284480877037991580442979","price":"0.94","size":"3316.34","side":"BUY","hash":"721f88ef55808da2ca627d28793a7b2d896f1e90","best_bid":"0.96","best_ask":"0.97"},{"asset_id":"20773614133833886322101538939702011175545796528197617633926164254913649353392","price":"0.06","size":"3316.34","side":"SELL","hash":"2a27767c7ab90d05e0c57245e958b031bb2df5f4","best_bid":"0.03","best_ask":"0.04"}],"timestamp":"1770839722691","event_type":"price_change","_sub_state":"active","_subscription_id":1,"_active_subscription_id":1},"parse_warnings":[],"out_of_order":false}
{"run_id":"29526913bab7446286864a321c124486","channel":"market","event_type":"price_change","market":"0x8032d8355d335c6ccbfc2508d99fbc87eb13f437bd275c93ee56fd1558e517ff","asset_id":null,"source":"market_ws:sub:active:1","t_event_ms":1770839722692,"t_recv_wall_ms":1770839722605,"t_recv_wall_iso":"2026-02-11T19:55:22.605Z","t_recv_mono_ns":618587946346416,"raw":{"market":"0x8032d8355d335c6ccbfc2508d99fbc87eb13f437bd275c93ee56fd1558e517ff","price_changes":[{"asset_id":"20773614133833886322101538939702011175545796528197617633926164254913649353392","price":"0.02","size":"8672.23","side":"BUY","hash":"406daabf2e0af1a9c8668cce717674969e20b671","best_bid":"0.03","best_ask":"0.04"},{"asset_id":"40652734036737240317526188612064032143639112324786051284480877037991580442979","price":"0.98","size":"8672.23","side":"SELL","hash":"4999d8d716075f37c3076270a6be3d79798dada5","best_bid":"0.96","best_ask":"0.97"}],"timestamp":"1770839722692","event_type":"price_change","_sub_state":"active","_subscription_id":1,"_active_subscription_id":1},"parse_warnings":[],"out_of_order":false}
{"run_id":"29526913bab7446286864a321c124486","channel":"market","event_type":"price_change","market":"0x8032d8355d335c6ccbfc2508d99fbc87eb13f437bd275c93ee56fd1558e517ff","asset_id":null,"source":"market_ws:sub:active:1","t_event_ms":1770839722692,"t_recv_wall_ms":1770839722605,"t_recv_wall_iso":"2026-02-11T19:55:22.605Z","t_recv_mono_ns":618587946484750,"raw":{"market":"0x8032d8355d335c6ccbfc2508d99fbc87eb13f437bd275c93ee56fd1558e517ff","price_changes":[{"asset_id":"40652734036737240317526188612064032143639112324786051284480877037991580442979","price":"0.95","size":"3259.45","side":"BUY","hash":"6dbba921e3f4db953b131b7e90e48244d70eea83","best_bid":"0.96","best_ask":"0.97"},{"asset_id":"20773614133833886322101538939702011175545796528197617633926164254913649353392","price":"0.05","size":"3259.45","side":"SELL","hash":"9d8847e65abd14f7d4667e67c7417a46867aaeeb","best_bid":"0.03","best_ask":"0.04"}],"timestamp":"1770839722692","event_type":"price_change","_sub_state":"active","_subscription_id":1,"_active_subscription_id":1},"parse_warnings":[],"out_of_order":false}
{"run_id":"29526913bab7446286864a321c124486","channel":"market","event_type":"price_change","market":"0x8032d8355d335c6ccbfc2508d99fbc87eb13f437bd275c93ee56fd1558e517ff","asset_id":null,"source":"market_ws:sub:active:1","t_event_ms":1770839722694,"t_recv_wall_ms":1770839722605,"t_recv_wall_iso":"2026-02-11T19:55:22.605Z","t_recv_mono_ns":618587946613166,"raw":{"market":"0x8032d8355d335c6ccbfc2508d99fbc87eb13f437bd275c93ee56fd1558e517ff","price_changes":[{"asset_id":"40652734036737240317526188612064032143639112324786051284480877037991580442979","price":"0.87","size":"995.8","side":"BUY","hash":"4053ebfb9ec78b1503981d9bb1d2c0fdb882a5a6","best_bid":"0.96","best_ask":"0.97"},{"asset_id":"20773614133833886322101538939702011175545796528197617633926164254913649353392","price":"0.13","size":"995.8","side":"SELL","hash":"d790a03a2823d38dadf019b324ac5e29c6b117d5","best_bid":"0.03","best_ask":"0.04"}],"timestamp":"1770839722694","event_type":"price_change","_sub_state":"active","_subscription_id":1,"_active_subscription_id":1},"parse_warnings":[],"out_of_order":false}
{"run_id":"29526913bab7446286864a321c124486","channel":"market","event_type":"price_change","market":"0x8032d8355d335c6ccbfc2508d99fbc87eb13f437bd275c93ee56fd1558e517ff","asset_id":null,"source":"market_ws:sub:active:1","t_event_ms":1770839722695,"t_recv_wall_ms":1770839722606,"t_recv_wall_iso":"2026-02-11T19:55:22.606Z","t_recv_mono_ns":618587946749833,"raw":{"market":"0x8032d8355d335c6ccbfc2508d99fbc87eb13f437bd275c93ee56fd1558e517ff","price_changes":[{"asset_id":"40652734036737240317526188612064032143639112324786051284480877037991580442979","price":"0.95","size":"3229.45","side":"BUY","hash":"02d8d71bb2b8419ce937bf869c933175c8327ce5","best_bid":"0.96","best_ask":"0.97"},{"asset_id":"20773614133833886322101538939702011175545796528197617633926164254913649353392","price":"0.05","size":"3229.45","side":"SELL","hash":"633613eaa35264fa09db95b4df3a9045d0457946","best_bid":"0.03","best_ask":"0.04"}],"timestamp":"1770839722695","event_type":"price_change","_sub_state":"active","_subscription_id":1,"_active_subscription_id":1},"parse_warnings":[],"out_of_order":false}
{"run_id":"29526913bab7446286864a321c124486","channel":"market","event_type":"price_change","market":"0x8032d8355d335c6ccbfc2508d99fbc87eb13f437bd275c93ee56fd1558e517ff","asset_id":null,"source":"market_ws:sub:active:1","t_event_ms":1770839722697,"t_recv_wall_ms":1770839722606,"t_recv_wall_iso":"2026-02-11T19:55:22.606Z","t_recv_mono_ns":618587946867250,"raw":{"market":"0x8032d8355d335c6ccbfc2508d99fbc87eb13f437bd275c93ee56fd1558e517ff","price_changes":[{"asset_id":"40652734036737240317526188612064032143639112324786051284480877037991580442979","price":"0.95","size":"3199.45","side":"BUY","hash":"51afe10a09cfaf28a1e316d8ddecbae6b4984f34","best_bid":"0.96","best_ask":"0.97"},{"asset_id":"20773614133833886322101538939702011175545796528197617633926164254913649353392","price":"0.05","size":"3199.45","side":"SELL","hash":"3c5ab9c394d185ceacd531404a61f527038b46d0","best_bid":"0.03","best_ask":"0.04"}],"timestamp":"1770839722697","event_type":"price_change","_sub_state":"active","_subscription_id":1,"_active_subscription_id":1},"parse_warnings":[],"out_of_order":false}
{"run_id":"29526913bab7446286864a321c124486","channel":"market","event_type":"price_change","market":"0x8032d8355d335c6ccbfc2508d99fbc87eb13f437bd275c93ee56fd1558e517ff","asset_id":null,"source":"market_ws:sub:active:1","t_event_ms":1770839722698,"t_recv_wall_ms":1770839722606,"t_recv_wall_iso":"2026-02-11T19:55:22.606Z","t_recv_mono_ns":618587947293916,"raw":{"market":"0x8032d8355d335c6ccbfc2508d99fbc87eb13f437bd275c93ee56fd1558e517ff","price_changes":[{"asset_id":"40652734036737240317526188612064032143639112324786051284480877037991580442979","price":"0.96","size":"3800.95","side":"BUY","hash":"ea5361d7d5456c613222fd9d4ca5123a27ed05b1","best_bid":"0.96","best_ask":"0.97"},{"asset_id":"20773614133833886322101538939702011175545796528197617633926164254913649353392","price":"0.04","size":"3800.95","side":"SELL","hash":"569a0d586489a8bcc70ce922add5ec89ad1b362e","best_bid":"0.03","best_ask":"0.04"}],"timestamp":"1770839722698","event_type":"price_change","_sub_state":"active","_subscription_id":1,"_active_subscription_id":1},"parse_warnings":[],"out_of_order":false}
{"run_id":"29526913bab7446286864a321c124486","channel":"market","event_type":"price_change","market":"0x8032d8355d335c6ccbfc2508d99fbc87eb13f437bd275c93ee56fd1558e517ff","asset_id":null,"source":"market_ws:sub:active:1","t_event_ms":1770839722703,"t_recv_wall_ms":1770839722610,"t_recv_wall_iso":"2026-02-11T19:55:22.610Z","t_recv_mono_ns":618587951672375,"raw":{"market":"0x8032d8355d335c6ccbfc2508d99fbc87eb13f437bd275c93ee56fd1558e517ff","price_changes":[{"asset_id":"40652734036737240317526188612064032143639112324786051284480877037991580442979","price":"0.96","size":"3740.95","side":"BUY","hash":"1ff9665478f4623eb7a22c49df956ce911878efd","best_bid":"0.96","best_ask":"0.97"},{"asset_id":"20773614133833886322101538939702011175545796528197617633926164254913649353392","price":"0.04","size":"3740.95","side":"SELL","hash":"c41fb0d5ea7171dfa05263adefc3f4caf258b3ac","best_bid":"0.03","best_ask":"0.04"}],"timestamp":"1770839722703","event_type":"price_change","_sub_state":"active","_subscription_id":1,"_active_subscription_id":1},"parse_warnings":[],"out_of_order":false}
{"run_id":"29526913bab7446286864a321c124486","channel":"market","event_type":"price_change","market":"0x8032d8355d335c6ccbfc2508d99fbc87eb13f437bd275c93ee56fd1558e517ff","asset_id":null,"source":"market_ws:sub:active:1","t_event_ms":1770839722705,"t_recv_wall_ms":1770839722613,"t_recv_wall_iso":"2026-02-11T19:55:22.613Z","t_recv_mono_ns":618587954651958,"raw":{"market":"0x8032d8355d335c6ccbfc2508d99fbc87eb13f437bd275c93ee56fd1558e517ff","price_changes":[{"asset_id":"40652734036737240317526188612064032143639112324786051284480877037991580442979","price":"0.96","size":"3800.95","side":"BUY","hash":"39d3c9c774ddc90bad8994987ab5fc4c7307e559","best_bid":"0.96","best_ask":"0.97"},{"asset_id":"20773614133833886322101538939702011175545796528197617633926164254913649353392","price":"0.04","size":"3800.95","side":"SELL","hash":"5b1288403a6a819bcd4e6128ba9c62dc1563044f","best_bid":"0.03","best_ask":"0.04"}],"timestamp":"1770839722705","event_type":"price_change","_sub_state":"active","_subscription_id":1,"_active_subscription_id":1},"parse_warnings":[],"out_of_order":false}
{"run_id":"29526913bab7446286864a321c124486","channel":"market","event_type":"price_change","market":"0x8032d8355d335c6ccbfc2508d99fbc87eb13f437bd275c93ee56fd1558e517ff","asset_id":null,"source":"market_ws:sub:active:1","t_event_ms":1770839722706,"t_recv_wall_ms":1770839722614,"t_recv_wall_iso":"2026-02-11T19:55:22.614Z","t_recv_mono_ns":618587955062000,"raw":{"market":"0x8032d8355d335c6ccbfc2508d99fbc87eb13f437bd275c93ee56fd1558e517ff","price_changes":[{"asset_id":"20773614133833886322101538939702011175545796528197617633926164254913649353392","price":"0.02","size":"8702.23","side":"BUY","hash":"a2750ba4a7058bab5e935523f4d65fe4bffccc1c","best_bid":"0.03","best_ask":"0.04"},{"asset_id":"40652734036737240317526188612064032143639112324786051284480877037991580442979","price":"0.98","size":"8702.23","side":"SELL","hash":"59c9cdece69807756da9cabfdf6fec4384d4e639","best_bid":"0.96","best_ask":"0.97"}],"timestamp":"1770839722706","event_type":"price_change","_sub_state":"active","_subscription_id":1,"_active_subscription_id":1},"parse_warnings":[],"out_of_order":false}
{"run_id":"29526913bab7446286864a321c124486","channel":"market","event_type":"price_change","market":"0x8032d8355d335c6ccbfc2508d99fbc87eb13f437bd275c93ee56fd1558e517ff","asset_id":null,"source":"market_ws:sub:active:1","t_event_ms":1770839722707,"t_recv_wall_ms":1770839722616,"t_recv_wall_iso":"2026-02-11T19:55:22.616Z","t_recv_mono_ns":618587957522416,"raw":{"market":"0x8032d8355d335c6ccbfc2508d99fbc87eb13f437bd275c93ee56fd1558e517ff","price_changes":[{"asset_id":"40652734036737240317526188612064032143639112324786051284480877037991580442979","price":"0.91","size":"594.6","side":"BUY","hash":"70416c26a8aa2f034a9e65cc48706e2d7e517d1d","best_bid":"0.96","best_ask":"0.97"},{"asset_id":"20773614133833886322101538939702011175545796528197617633926164254913649353392","price":"0.09","size":"594.6","side":"SELL","hash":"c85ad6da3846e3c853e491131c95397a8b1c0a87","best_bid":"0.03","best_ask":"0.04"}],"timestamp":"1770839722707","event_type":"price_change","_sub_state":"active","_subscription_id":1,"_active_subscription_id":1},"parse_warnings":[],"out_of_order":false}
{"run_id":"29526913bab7446286864a321c124486","channel":"market","event_type":"price_change","market":"0x8032d8355d335c6ccbfc2508d99fbc87eb13f437bd275c93ee56fd1558e517ff","asset_id":null,"source":"market_ws:sub:active:1","t_event_ms":1770839722718,"t_recv_wall_ms":1770839722641,"t_recv_wall_iso":"2026-02-11T19:55:22.641Z","t_recv_mono_ns":618587981946041,"raw":{"market":"0x8032d8355d335c6ccbfc2508d99fbc87eb13f437bd275c93ee56fd1558e517ff","price_changes":[{"asset_id":"40652734036737240317526188612064032143639112324786051284480877037991580442979","price":"0.96","size":"3830.95","side":"BUY","hash":"fdca3eccddbc53f6fe1ecee89f896c35da55449e","best_bid":"0.96","best_ask":"0.97"},{"asset_id":"20773614133833886322101538939702011175545796528197617633926164254913649353392","price":"0.04","size":"3830.95","side":"SELL","hash":"fe6fe4a608a1cf34ec49601227f050e28f2b52c8","best_bid":"0.03","best_ask":"0.04"}],"timestamp":"1770839722718","event_type":"price_change","_sub_state":"active","_subscription_id":1,"_active_subscription_id":1},"parse_warnings":[],"out_of_order":false}
{"run_id":"29526913bab7446286864a321c124486","channel":"market","event_type":"price_change","market":"0x8032d8355d335c6ccbfc2508d99fbc87eb13f437bd275c93ee56fd1558e517ff","asset_id":null,"source":"market_ws:sub:active:1","t_event_ms":1770839722723,"t_recv_wall_ms":1770839722641,"t_recv_wall_iso":"2026-02-11T19:55:22.641Z","t_recv_mono_ns":618587982141041,"raw":{"market":"0x8032d8355d335c6ccbfc2508d99fbc87eb13f437bd275c93ee56fd1558e517ff","price_changes":[{"asset_id":"40652734036737240317526188612064032143639112324786051284480877037991580442979","price":"0.92","size":"3399.35","side":"BUY","hash":"525b5b30ce7dede69bc77f3e3b448e90b3b8baf6","best_bid":"0.96","best_ask":"0.97"},{"asset_id":"20773614133833886322101538939702011175545796528197617633926164254913649353392","price":"0.08","size":"3399.35","side":"SELL","hash":"8683696f5dbd5a79484a5a0e842f1ad3bdde4ad5","best_bid":"0.03","best_ask":"0.04"}],"timestamp":"1770839722723","event_type":"price_change","_sub_state":"active","_subscription_id":1,"_active_subscription_id":1},"parse_warnings":[],"out_of_order":false}
{"run_id":"29526913bab7446286864a321c124486","channel":"market","event_type":"price_change","market":"0x8032d8355d335c6ccbfc2508d99fbc87eb13f437bd275c93ee56fd1558e517ff","asset_id":null,"source":"market_ws:sub:active:1","t_event_ms":1770839722731,"t_recv_wall_ms":1770839722641,"t_recv_wall_iso":"2026-02-11T19:55:22.641Z","t_recv_mono_ns":618587982241208,"raw":{"market":"0x8032d8355d335c6ccbfc2508d99fbc87eb13f437bd275c93ee56fd1558e517ff","price_changes":[{"asset_id":"40652734036737240317526188612064032143639112324786051284480877037991580442979","price":"0.96","size":"3770.95","side":"BUY","hash":"d9a59b159b59cb15e12a88777a5f3da253580b46","best_bid":"0.96","best_ask":"0.97"},{"asset_id":"20773614133833886322101538939702011175545796528197617633926164254913649353392","price":"0.04","size":"3770.95","side":"SELL","hash":"4bd688c0dd91aba43b63d35c63b2719c44e30167","best_bid":"0.03","best_ask":"0.04"}],"timestamp":"1770839722731","event_type":"price_change","_sub_state":"active","_subscription_id":1,"_active_subscription_id":1},"parse_warnings":[],"out_of_order":false}
{"run_id":"29526913bab7446286864a321c124486","channel":"market","event_type":"price_change","market":"0x8032d8355d335c6ccbfc2508d99fbc87eb13f437bd275c93ee56fd1558e517ff","asset_id":null,"source":"market_ws:sub:active:1","t_event_ms":1770839722733,"t_recv_wall_ms":1770839722641,"t_recv_wall_iso":"2026-02-11T19:55:22.641Z","t_recv_mono_ns":618587982324500,"raw":{"market":"0x8032d8355d335c6ccbfc2508d99fbc87eb13f437bd275c93ee56fd1558e517ff","price_changes":[{"asset_id":"40652734036737240317526188612064032143639112324786051284480877037991580442979","price":"0.96","size":"3830.95","side":"BUY","hash":"b1b4aa85a22d9a7976844d04a89a09120f0bfac8","best_bid":"0.96","best_ask":"0.97"},{"asset_id":"20773614133833886322101538939702011175545796528197617633926164254913649353392","price":"0.04","size":"3830.95","side":"SELL","hash":"34f647c42964d5364e5a04d9402803981f301e04","best_bid":"0.03","best_ask":"0.04"}],"timestamp":"1770839722733","event_type":"price_change","_sub_state":"active","_subscription_id":1,"_active_subscription_id":1},"parse_warnings":[],"out_of_order":false}
{"run_id":"29526913bab7446286864a321c124486","channel":"market","event_type":"price_change","market":"0x8032d8355d335c6ccbfc2508d99fbc87eb13f437bd275c93ee56fd1558e517ff","asset_id":null,"source":"market_ws:sub:active:1","t_event_ms":1770839722755,"t_recv_wall_ms":1770839722665,"t_recv_wall_iso":"2026-02-11T19:55:22.665Z","t_recv_mono_ns":618588005926583,"raw":{"market":"0x8032d8355d335c6ccbfc2508d99fbc87eb13f437bd275c93ee56fd1558e517ff","price_changes":[{"asset_id":"40652734036737240317526188612064032143639112324786051284480877037991580442979","price":"0.83","size":"963.39","side":"BUY","hash":"bb710f9a1416b54fc186647326c697dace1cbe2c","best_bid":"0.96","best_ask":"0.97"},{"asset_id":"20773614133833886322101538939702011175545796528197617633926164254913649353392","price":"0.17","size":"963.39","side":"SELL","hash":"8eb72dcb797c89599fbd0f731e677392bbbf379b","best_bid":"0.03","best_ask":"0.04"}],"timestamp":"1770839722755","event_type":"price_change","_sub_state":"active","_subscription_id":1,"_active_subscription_id":1},"parse_warnings":[],"out_of_order":false}
