{"run_id":"29526913bab7446286864a321c124486","channel":"market","event_type":"book","market":"0x8032d8355d335c6ccbfc2508d99fbc87eb13f437bd275c93ee56fd1558e517ff","asset_id":"20773614133833886322101538939702011175545796528197617633926164254913649353392","source":"market_ws:sub:active:1","t_event_ms":1770839724458,"t_recv_wall_ms":1770839724372,"t_recv_wall_iso":"2026-02-11T19:55:24.372Z","t_recv_mono_ns":618589712996041,"raw":{"market":"0x8032d8355d335c6ccbfc2508d99fbc87eb13f437bd275c93ee56fd1558e517ff","asset_id":"20773614133833886322101538939702011175545796528197617633926164254913649353392","bids":[{"price":"0.01","size":"30924.91"},{"price":"0.02","size":"8821.68"}],"asks":[{"price":"0.99","size":"30822.26"},{"price":"0.98","size":"12559.04"},{"price":"0.97","size":"7433.03"},{"price":"0.96","size":"5453.8"},{"price":"0.95","size":"6815.8"},{"price":"0.94","size":"5105"},{"price":"0.93","size":"5421.38"},{"price":"0.92","size":"5139.4"},{"price":"0.91","size":"5225.8"},{"price":"0.9","size":"5102.8"},{"price":"0.89","size":"120.6"},{"price":"0.88","size":"63.6"},{"price":"0.87","size":"63"},{"price":"0.86","size":"61.6"},{"price":"0.85","size":"107.39"},{"price":"0.84","size":"69.39"},{"price":"0.83","size":"58.39"},{"price":"0.82","size":"66.71"},{"price":"0.81","size":"56.8"},{"price":"0.8","size":"92.14"},{"price":"0.79","size":"60.8"},{"price":"0.78","size":"55.2"},{"price":"0.77","size":"64.48"},{"price":"0.76","size":"54.2"},{"price":"0.75","size":"375.8"},{"price":"0.74","size":"68.6"},{"price":"0.73","size":"53.2"},{"price":"0.72","size":"63.26"},{"price":"0.71","size":"52.6"},{"price":"0.7","size":"402.4"},{"price":"0.69","size":"72.2"},{"price":"0.68","size":"87.88"},{"price":"0.67","size":"188.46"},{"price":"0.66","size":"123.6"},{"price":"0.65","size":"317.03"},{"price":"0.64","size":"582.36"},{"price":"0.63","size":"559.2"},{"price":"0.62","size":"559"},{"price":"0.61","size":"594"},{"price":"0.6","size":"2915.41"},{"price":"0.59","size":"576.8"},{"price":"0.58","size":"575.5"},{"price":"0.57","size":"558.6"},{"price":"0.56","size":"572.68"},{"price":"0.55","size":"566.4"},{"price":"0.54","size":"561.94"},{"price":"0.53","size":"631.57"},{"price":"0.52","size":"611.4"},{"price":"0.51","size":"705.2"},{"price":"0.5","size":"1011.55"},{"price":"0.49","size":"692.4"},{"price":"0.48","size":"628.4"},{"price":"0.47","size":"633.4"},{"price":"0.46","size":"711.65"},{"price":"0.45","size":"866.59"},{"price":"0.44","size":"905.69"},{"price":"0.43","size":"641.6"},{"price":"0.42","size":"645.58"},{"price":"0.41","size":"564"},{"price":"0.4","size":"20642.9"},{"price":"0.39","size":"650.23"},{"price":"0.38","size":"593"},{"price":"0.37","size":"755.73"},{"price":"0.36","size":"558"},{"price":"0.35","size":"1144.32"},{"price":"0.34","size":"649.59"},{"price":"0.33","size":"624.8"},{"price":"0.32","size":"574"},{"price":"0.31","size":"594.2"},{"price":"0.3","size":"735.66"},{"price":"0.29","size":"624.6"},{"price":"0.28","size":"356.8"},{"price":"0.27","size":"869.2"},{"price":"0.26","size":"967.6"},{"price":"0.25","size":"1673.8"},{"price":"0.24","size":"869.2"},{"price":"0.23","size":"864.6"},{"price":"0.22","size":"870.2"},{"price":"0.21","size":"871.6"},{"price":"0.2","size":"987.2"},{"price":"0.19","size":"876.8"},{"price":"0.18","size":"1096.55"},{"price":"0.17","size":"958.39"},{"price":"0.16","size":"1119.39"},{"price":"0.15","size":"1149.13"},{"price":"0.14","size":"962.6"},{"price":"0.13","size":"1041.8"},{"price":"0.12","size":"1060.55"},{"price":"0.11","size":"1124.49"},{"price":"0.1","size":"1291.79"},{"price":"0.09","size":"669.6"},{"price":"0.08","size":"3384.35"},{"price":"0.07","size":"3360.43"},{"price":"0.06","size":"3135.34"},{"price":"0.05","size":"3175.45"},{"price":"0.04","size":"3792.17"},{"price":"0.03","size":"641.4"}],"hash":"5e0fe4ddc0d4d6b65db4471e188cb758db4e8bb2","timestamp":"1770839724458","event_type":"book","_sub_state":"active","_subscription_id":1,"_active_subscription_id":1},"parse_warnings":[],"out_of_order":false}
{"run_id":"29526913bab7446286864a321c124486","channel":"market","event_type":"book","market":"0x8032d8355d335c6ccbfc2508d99fbc87eb13f437bd275c93ee56fd1558e517ff","asset_id":"40652734036737240317526188612064032143639112324786051284480877037991580442979","source":"market_ws:sub:active:1","t_event_ms":1770839724458,"t_recv_wall_ms":1770839724373,"t_recv_wall_iso":"2026-02-11T19:55:24.373Z","t_recv_mono_ns":618589713821708,"raw":{"market":"0x8032d8355d335c6ccbfc2508d99fbc87eb13f437bd275c93ee56fd1558e517ff","asset_id":"40652734036737240317526188612064032143639112324786051284480877037991580442979","bids":[{"price":"0.01","size":"30822.26"},{"price":"0.02","size":"12559.04"},{"price":"0.03","size":"7433.03"},{"price":"0.04","size":"5453.8"},{"price":"0.05","size":"6815.8"},{"price":"0.06","size":"5105"},{"price":"0.07","size":"5421.38"},{"price":"0.08","size":"5139.4"},{"price":"0.09","size":"5225.8"},{"price":"0.1","size":"5102.8"},{"price":"0.11","size":"120.6"},{"price":"0.12","size":"63.6"},{"price":"0.13","size":"63"},{"price":"0.14","size":"61.6"},{"price":"0.15","size":"107.39"},{"price":"0.16","size":"69.39"},{"price":"0.17","size":"58.39"},{"price":"0.18","size":"66.71"},{"price":"0.19","size":"56.8"},{"price":"0.2","size":"92.14"},{"price":"0.21","size":"60.8"},{"price":"0.22","size":"55.2"},{"price":"0.23","size":"64.48"},{"price":"0.24","size":"54.2"},{"price":"0.25","size":"375.8"},{"price":"0.26","size":"68.6"},{"price":"0.27","size":"53.2"},{"price":"0.28","size":"63.26"},{"price":"0.29","size":"52.6"},{"price":"0.3","size":"402.4"},{"price":"0.31","size":"72.2"},{"price":"0.32","size":"87.88"},{"price":"0.33","size":"188.46"},{"price":"0.34","size":"123.6"},{"price":"0.35","size":"317.03"},{"price":"0.36","size":"582.36"},{"price":"0.37","size":"559.2"},{"price":"0.38","size":"559"},{"price":"0.39","size":"594"},{"price":"0.4","size":"2915.41"},{"price":"0.41","size":"576.8"},{"price":"0.42","size":"575.5"},{"price":"0.43","size":"558.6"},{"price":"0.44","size":"572.68"},{"price":"0.45","size":"566.4"},{"price":"0.46","size":"561.94"},{"price":"0.47","size":"631.57"},{"price":"0.48","size":"611.4"},{"price":"0.49","size":"705.2"},{"price":"0.5","size":"1011.55"},{"price":"0.51","size":"692.4"},{"price":"0.52","size":"628.4"},{"price":"0.53","size":"633.4"},{"price":"0.54","size":"711.65"},{"price":"0.55","size":"866.59"},{"price":"0.56","size":"905.69"},{"price":"0.57","size":"641.6"},{"price":"0.58","size":"645.58"},{"price":"0.59","size":"564"},{"price":"0.6","size":"20642.9"},{"price":"0.61","size":"650.23"},{"price":"0.62","size":"593"},{"price":"0.63","size":"755.73"},{"price":"0.64","size":"558"},{"price":"0.65","size":"1144.32"},{"price":"0.66","size":"649.59"},{"price":"0.67","size":"624.8"},{"price":"0.68","size":"574"},{"price":"0.69","size":"594.2"},{"price":"0.7","size":"735.66"},{"price":"0.71","size":"624.6"},{"price":"0.72","size":"356.8"},{"price":"0.73","size":"869.2"},{"price":"0.74","size":"967.6"},{"price":"0.75","size":"1673.8"},{"price":"0.76","size":"869.2"},{"price":"0.77","size":"864.6"},{"price":"0.78","size":"870.2"},{"price":"0.79","size":"871.6"},{"price":"0.8","size":"987.2"},{"price":"0.81","size":"876.8"},{"price":"0.82","size":"1096.55"},{"price":"0.83","size":"958.39"},{"price":"0.84","size":"1119.39"},{"price":"0.85","size":"1149.13"},{"price":"0.86","size":"962.6"},{"price":"0.87","size":"1041.8"},{"price":"0.88","size":"1060.55"},{"price":"0.89","size":"1124.49"},{"price":"0.9","size":"1291.79"},{"price":"0.91","size":"669.6"},{"price":"0.92","size":"3384.35"},{"price":"0.93","size":"3360.43"},{"price":"0.94","size":"3135.34"},{"price":"0.95","size":"3175.45"},{"price":"0.96","size":"3792.17"},{"price":"0.97","size":"641.4"}],"asks":[{"price":"0.99","size":"30924.91"},{"price":"0.98","size":"8821.68"}],"hash":"c2d84d120c667c466e6cede93b3e8e5c3bcd1d9e","timestamp":"1770839724458","event_type":"book","_sub_state":"active","_subscription_id":1,"_active_subscription_id":1},"parse_warnings":[],"out_of_order":false}
{"run_id":"29526913bab7446286864a321c124486","channel":"market","event_type":"price_change","market":"0x8032d8355d335c6ccbfc2508d99fbc87eb13f437bd275c93ee56fd1558e517ff","asset_id":null,"source":"market_ws:sub:active:1","t_event_ms":1770839724477,"t_recv_wall_ms":1770839724381,"t_recv_wall_iso":"2026-02-11T19:55:24.381Z","t_recv_mono_ns":618589722043000,"raw":{"market":"0x8032d8355d335c6ccbfc2508d99fbc87eb13f437bd275c93ee56fd1558e517ff","price_changes":[{"asset_id":"20773614133833886322101538939702011175545796528197617633926164254913649353392","price":"0.02","size":"8876.68","side":"BUY","hash":"03ee3870b9953dd9e8f31a2897cb6bad23bc76ad","best_bid":"0.02","best_ask":"0.03"},{"asset_id":"40652734036737240317526188612064032143639112324786051284480877037991580442979","price":"0.98","size":"8876.68","side":"SELL","hash":"a4db9dd3012831f5e670423d24fc3e7383247776","best_bid":"0.97","best_ask":"0.98"}],"timestamp":"1770839724477","event_type":"price_change","_sub_state":"active","_subscription_id":1,"_active_subscription_id":1},"parse_warnings":[],"out_of_order":false}
{"run_id":"29526913bab7446286864a321c124486","channel":"market","event_type":"price_change","market":"0x8032d8355d335c6ccbfc2508d99fbc87eb13f437bd275c93ee56fd1558e517ff","asset_id":null,"source":"market_ws:sub:active:1","t_event_ms":1770839724480,"t_recv_wall_ms":1770839724386,"t_recv_wall_iso":"2026-02-11T19:55:24.386Z","t_recv_mono_ns":618589727402750,"raw":{"market":"0x8032d8355d335c6ccbfc2508d99fbc87eb13f437bd275c93ee56fd1558e517ff","price_changes":[{"asset_id":"40652734036737240317526188612064032143639112324786051284480877037991580442979","price":"0.96","size":"3732.17","side":"BUY","hash":"56842dcd60847194d18c6ead402d108020c54cec","best_bid":"0.97","best_ask":"0.98"},{"asset_id":"20773614133833886322101538939702011175545796528197617633926164254913649353392","price":"0.04","size":"3732.17","side":"SELL","hash":"c5d73219941aed6eafbb1b7d31922867ebc71062","best_bid":"0.02","best_ask":"0.03"}],"timestamp":"1770839724480","event_type":"price_change","_sub_state":"active","_subscription_id":1,"_active_subscription_id":1},"parse_warnings":[],"out_of_order":false}
{"run_id":"29526913bab7446286864a321c124486","channel":"market","event_type":"price_change","market":"0x8032d8355d335c6ccbfc2508d99fbc87eb13f437bd275c93ee56fd1558e517ff","asset_id":null,"source":"market_ws:sub:active:1","t_event_ms":1770839724483,"t_recv_wall_ms":1770839724389,"t_recv_wall_iso":"2026-02-11T19:55:24.389Z","t_recv_mono_ns":618589730490208,"raw":{"market":"0x8032d8355d335c6ccbfc2508d99fbc87eb13f437bd275c93ee56fd1558e517ff","price_changes":[{"asset_id":"40652734036737240317526188612064032143639112324786051284480877037991580442979","price":"0.95","size":"3109.45","side":"BUY","hash":"70d7ce0cac76ceaf54508ad9b84c26ab46c075b8","best_bid":"0.97","best_ask":"0.98"},{"asset_id":"20773614133833886322101538939702011175545796528197617633926164254913649353392","price":"0.05","size":"3109.45","side":"SELL","hash":"203e8417cc896cae54286f2987ff396e985015cb","best_bid":"0.02","best_ask":"0.03"}],"timestamp":"1770839724483","event_type":"price_change","_sub_state":"active","_subscription_id":1,"_active_subscription_id":1},"parse_warnings":[],"out_of_order":false}
{"run_id":"29526913bab7446286864a321c124486","channel":"market","event_type":"price_change","market":"0x8032d8355d335c6ccbfc2508d99fbc87eb13f437bd275c93ee56fd1558e517ff","asset_id":null,"source":"market_ws:sub:active:1","t_event_ms":1770839724487,"t_recv_wall_ms":1770839724394,"t_recv_wall_iso":"2026-02-11T19:55:24.394Z","t_recv_mono_ns":618589734787333,"raw":{"market":"0x8032d8355d335c6ccbfc2508d99fbc87eb13f437bd275c93ee56fd1558e517ff","price_changes":[{"asset_id":"40652734036737240317526188612064032143639112324786051284480877037991580442979","price":"0.95","size":"3169.45","side":"BUY","hash":"a6bb6612f8b2c2dd0d251e40724cb16f7422b42a","best_bid":"0.97","best_ask":"0.98"},{"asset_id":"20773614133833886322101538939702011175545796528197617633926164254913649353392","price":"0.05","size":"3169.45","side":"SELL","hash":"fe0ff59804547fed40d4e07192c1de716515104f","best_bid":"0.02","best_ask":"0.03"}],"timestamp":"1770839724487","event_type":"price_change","_sub_state":"active","_subscription_id":1,"_active_subscription_id":1},"parse_warnings":[],"out_of_order":false}
{"run_id":"29526913bab7446286864a321c124486","channel":"market","event_type":"last_trade_price","market":"0x8032d8355d335c6ccbfc2508d99fbc87eb13f437bd275c93ee56fd1558e517ff","asset_id":"40652734036737240317526188612064032143639112324786051284480877037991580442979","source":"market_ws:sub:unknown","t_event_ms":1770839724489,"t_recv_wall_ms":1770839724394,"t_recv_wall_iso":"2026-02-11T19:55:24.394Z","t_recv_mono_ns":618589735235041,"raw":{"market":"0x8032d8355d335c6ccbfc2508d99fbc87eb13f437bd275c93ee56fd1558e517ff","asset_id":"40652734036737240317526188612064032143639112324786051284480877037991580442979","price":"0.97","size":"1.42","fee_rate_bps":"1000","side":"SELL","timestamp":"1770839724489","event_type":"last_trade_price","transaction_hash":"0x4e94d5b4fbd70908e1dc7968ea90bc7a729ec82c40e417048f61b32dec8e5543","_sub_state":"unknown","_subscription_id":null,"_active_subscription_id":1},"parse_warnings":["unknown_message_schema"],"out_of_order":false}
{"run_id":"29526913bab7446286864a321c124486","channel":"market","event_type":"price_change","market":"0x8032d8355d335c6ccbfc2508d99fbc87eb13f437bd275c93ee56fd1558e517ff","asset_id":null,"source":"market_ws:sub:active:1","t_event_ms":1770839724490,"t_recv_wall_ms":1770839724395,"t_recv_wall_iso":"2026-02-11T19:55:24.395Z","t_recv_mono_ns":618589736531958,"raw":{"market":"0x8032d8355d335c6ccbfc2508d99fbc87eb13f437bd275c93ee56fd1558e517ff","price_changes":[{"asset_id":"20773614133833886322101538939702011175545796528197617633926164254913649353392","price":"0.01","size":"30864.91","side":"BUY","hash":"3e67378e9fc9432acdb125adcf873ebf5ebbbb49","best_bid":"0.02","best_ask":"0.03"},{"asset_id":"40652734036737240317526188612064032143639112324786051284480877037991580442979","price":"0.99","size":"30864.91","side":"SELL","hash":"c8e89f9db55130cc8ef9552652f76d4b2228fa37","best_bid":"0.97","best_ask":"0.98"}],"timestamp":"1770839724490","event_type":"price_change","_sub_state":"active","_subscription_id":1,"_active_subscription_id":1},"parse_warnings":[],"out_of_order":false}
{"run_id":"29526913bab7446286864a321c124486","channel":"market","event_type":"price_change","market":"0x8032d8355d335c6ccbfc2508d99fbc87eb13f437bd275c93ee56fd1558e517ff","asset_id":null,"source":"market_ws:sub:active:1","t_event_ms":1770839724491,"t_recv_wall_ms":1770839724403,"t_recv_wall_iso":"2026-02-11T19:55:24.403Z","t_recv_mono_ns":618589744529500,"raw":{"market":"0x8032d8355d335c6ccbfc2508d99fbc87eb13f437bd275c93ee56fd1558e517ff","price_changes":[{"asset_id":"40652734036737240317526188612064032143639112324786051284480877037991580442979","price":"0.96","size":"3798.17","side":"BUY","hash":"4ee43c7ff4d24db10d0088b199bb1965d1655288","best_bid":"0.97","best_ask":"0.98"},{"asset_id":"20773614133833886322101538939702011175545796528197617633926164254913649353392","price":"0.04","size":"3798.17","side":"SELL","hash":"2d25f32b463e3072fafd7ccb3e6e1c6e825cab4d","best_bid":"0.02","best_ask":"0.03"}],"timestamp":"1770839724491","event_type":"price_change","_sub_state":"active","_subscription_id":1,"_active_subscription_id":1},"parse_warnings":[],"out_of_order":false}
{"run_id":"29526913bab7446286864a321c124486","channel":"market","event_type":"price_change","market":"0x8032d8355d335c6ccbfc2508d99fbc87eb13f437bd275c93ee56fd1558e517ff","asset_id":null,"source":"market_ws:sub:active:1","t_event_ms":1770839724495,"t_recv_wall_ms":1770839724404,"t_recv_wall_iso":"2026-02-11T19:55:24.404Z","t_recv_mono_ns":618589745045166,"raw":{"market":"0x8032d8355d335c6ccbfc2508d99fbc87eb13f437bd275c93ee56fd1558e517ff","price_changes":[{"asset_id":"20773614133833886322101538939702011175545796528197617633926164254913649353392","price":"0.02","size":"8936.68","side":"BUY","hash":"c8d5e564c88769947e73707999ff1e4d6de1cf89","best_bid":"0.02","best_ask":"0.03"},{"asset_id":"40652734036737240317526188612064032143639112324786051284480877037991580442979","price":"0.98","size":"8936.68","side":"SELL","hash":"4209d2c596fe92a62249b92b781e7a863c59a8ed","best_bid":"0.97","best_ask":"0.98"}],"timestamp":"1770839724495","event_type":"price_change","_sub_state":"active","_subscription_id":1,"_active_subscription_id":1},"parse_warnings":[],"out_of_order":false}
{"run_id":"29526913bab7446286864a321c124486","channel":"market","event_type":"price_change","market":"0x8032d8355d335c6ccbfc2508d99fbc87eb13f437bd275c93ee56fd1558e517ff","asset_id":null,"source":"market_ws:sub:active:1","t_event_ms":1770839724496,"t_recv_wall_ms":1770839724404,"t_recv_wall_iso":"2026-02-11T19:55:24.404Z","t_recv_mono_ns":618589745202041,"raw":{"market":"0x8032d8355d335c6ccbfc2508d99fbc87eb13f437bd275c93ee56fd1558e517ff","price_changes":[{"asset_id":"40652734036737240317526188612064032143639112324786051284480877037991580442979","price":"0.82","size":"1091.55","side":"BUY","hash":"34a8b2f1a636839c80f5bd50f84e371c13b665a5","best_bid":"0.97","best_ask":"0.98"},{"asset_id":"20773614133833886322101538939702011175545796528197617633926164254913649353392","price":"0.18","size":"1091.55","side":"SELL","hash":"d064f2c2c07b75deb5f6134ad0f3019e9b44ee25","best_bid":"0.02","best_ask":"0.03"}],"timestamp":"1770839724496","event_type":"price_change","_sub_state":"active","_subscription_id":1,"_active_subscription_id":1},"parse_warnings":[],"out_of_order":false}
{"run_id":"29526913bab7446286864a321c124486","channel":"market","event_type":"price_change","market":"0x8032d8355d335c6ccbfc2508d99fbc87eb13f437bd275c93ee56fd1558e517ff","asset_id":null,"source":"market_ws:sub:active:1","t_event_ms":1770839724502,"t_recv_wall_ms":1770839724411,"t_recv_wall_iso":"2026-02-11T19:55:24.411Z","t_recv_mono_ns":618589752012125,"raw":{"market":"0x8032d8355d335c6ccbfc2508d99fbc87eb13f437bd275c93ee56fd1558e517ff","price_changes":[{"asset_id":"20773614133833886322101538939702011175545796528197617633926164254913649353392","price":"0.02","size":"8986.68","side":"BUY","hash":"c249bd7564f8b912a67a7365cc5339688c408a14","best_bid":"0.02","best_ask":"0.03"},{"asset_id":"40652734036737240317526188612064032143639112324786051284480877037991580442979","price":"0.98","size":"8986.68","side":"SELL","hash":"f7b33efd79a0df4f1bc5b1e23bc26bbd5164e591","best_bid":"0.97","best_ask":"0.98"}],"timestamp":"1770839724502","event_type":"price_change","_sub_state":"active","_subscription_id":1,"_active_subscription_id":1},"parse_warnings":[],"out_of_order":false}
{"run_id":"29526913bab7446286864a321c124486","channel":"market","event_type":"price_change","market":"0x8032d8355d335c6ccbfc2508d99fbc87eb13f437bd275c93ee56fd1558e517ff","asset_id":null,"source":"market_ws:sub:active:1","t_event_ms":1770839724529,"t_recv_wall_ms":1770839724438,"t_recv_wall_iso":"2026-02-11T19:55:24.438Z","t_recv_mono_ns":618589779584166,"raw":{"market":"0x8032d8355d335c6ccbfc2508d99fbc87eb13f437bd275c93ee56fd1558e517ff","price_changes":[{"asset_id":"40652734036737240317526188612064032143639112324786051284480877037991580442979","price":"0.9","size":"1306.79","side":"BUY","hash":"f9a9c6d9b00200876776a996546abf991b99d6be","best_bid":"0.97","best_ask":"0.98"},{"asset_id":"20773614133833886322101538939702011175545796528197617633926164254913649353392","price":"0.1","size":"1306.79","side":"SELL","hash":"ffe9c486dd345baf48b7d84322481b81339f088e","best_bid":"0.02","best_ask":"0.03"}],"timestamp":"1770839724529","event_type":"price_change","_sub_state":"active","_subscription_id":1,"_active_subscription_id":1},"parse_warnings":[],"out_of_order":false}
{"run_id":"29526913bab7446286864a321c124486","channel":"market","event_type":"price_change","market":"0x8032d8355d335c6ccbfc2508d99fbc87eb13f437bd275c93ee56fd1558e517ff","asset_id":null,"source":"market_ws:sub:active:1","t_event_ms":1770839724556,"t_recv_wall_ms":1770839724461,"t_recv_wall_iso":"2026-02-11T19:55:24.461Z","t_recv_mono_ns":618589802095291,"raw":{"market":"0x8032d8355d335c6ccbfc2508d99fbc87eb13f437bd275c93ee56fd1558e517ff","price_changes":[{"asset_id":"40652734036737240317526188612064032143639112324786051284480877037991580442979","price":"0.96","size":"3768.17","side":"BUY","hash":"aa747297b83179f89a32c01f812e8b8047c99809","best_bid":"0.97","best_ask":"0.98"},{"asset_id":"20773614133833886322101538939702011175545796528197617633926164254913649353392","price":"0.04","size":"3768.17","side":"SELL","hash":"7500ab436e0a67b3161510a3e087e98dbfb51962","best_bid":"0.02","best_ask":"0.03"}],"timestamp":"1770839724556","event_type":"price_change","_sub_state":"active","_subscription_id":1,"_active_subscription_id":1},"parse_warnings":[],"out_of_order":false}
{"run_id":"29526913bab7446286864a321c124486","channel":"market","event_type":"price_change","market":"0x8032d8355d335c6ccbfc2508d99fbc87eb13f437bd275c93ee56fd1558e517ff","asset_id":null,"source":"market_ws:sub:active:1","t_event_ms":1770839724558,"t_recv_wall_ms":1770839724462,"t_recv_wall_iso":"2026-02-11T19:55:24.462Z","t_recv_mono_ns":618589802879708,"raw":{"market":"0x8032d8355d335c6ccbfc2508d99fbc87eb13f437bd275c93ee56fd1558e517ff","price_changes":[{"asset_id":"20773614133833886322101538939702011175545796528197617633926164254913649353392","price":"0.01","size":"30834.91","side":"BUY","hash":"8044c7ba923caceb49e468ff6cad03df39aa6612","best_bid":"0.02","best_ask":"0.03"},{"asset_id":"40652734036737240317526188612064032143639112324786051284480877037991580442979","price":"0.99","size":"30834.91","side":"SELL","hash":"a36a7bcaa54218c602192d15e8fe208e8ebe8d22","best_bid":"0.97","best_ask":"0.98"}],"timestamp":"1770839724558","event_type":"price_change","_sub_state":"active","_subscription_id":1,"_active_subscription_id":1},"parse_warnings":[],"out_of_order":false}
{"run_id":"29526913bab7446286864a321c124486","channel":"market","event_type":"price_change","market":"0x8032d8355d335c6ccbfc2508d99fbc87eb13f437bd275c93ee56fd1558e517ff","asset_id":null,"source":"market_ws:sub:active:1","t_event_ms":1770839724559,"t_recv_wall_ms":1770839724464,"t_recv_wall_iso":"2026-02-11T19:55:24.464Z","t_recv_mono_ns":618589804823208,"raw":{"market":"0x8032d8355d335c6ccbfc2508d99fbc87eb13f437bd275c93ee56fd1558e517ff","price_changes":[{"asset_id":"40652734036737240317526188612064032143639112324786051284480877037991580442979","price":"0.96","size":"3738.17","side":"BUY","hash":"1ad1e0a8425622f704c05f1dc0af22ab3613e097","best_bid":"0.97","best_ask":"0.98"},{"asset_id":"20773614133833886322101538939702011175545796528197617633926164254913649353392","price":"0.04","size":"3738.17","side":"SELL","hash":"a92443dc6bafd67d37536161d1497ab966a87216","best_bid":"0.02","best_ask":"0.03"}],"timestamp":"1770839724559","event_type":"price_change","_sub_state":"active","_subscription_id":1,"_active_subscription_id":1},"parse_warnings":[],"out_of_order":false}
{"run_id":"29526913bab7446286864a321c124486","channel":"market","event_type":"price_change","market":"0x8032d8355d335c6ccbfc2508d99fbc87eb13f437bd275c93ee56fd1558e517ff","asset_id":null,"source":"market_ws:sub:active:1","t_event_ms":1770839724562,"t_recv_wall_ms":1770839724470,"t_recv_wall_iso":"2026-02-11T19:55:24.470Z","t_recv_mono_ns":618589811231333,"raw":{"market":"0x8032d8355d335c6ccbfc2508d99fbc87eb13f437bd275c93ee56fd1558e517ff","price_changes":[{"asset_id":"40652734036737240317526188612064032143639112324786051284480877037991580442979","price":"0.79","size":"891.6","side":"BUY","hash":"0dc28b51be18050f210f3e7f69baf5f93d5427ff","best_bid":"0.97","best_ask":"0.98"},{"asset_id":"20773614133833886322101538939702011175545796528197617633926164254913649353392","price":"0.21","size":"891.6","side":"SELL","hash":"67985cf0e50a1f4a922d0777acd219e9e1f009a8","best_bid":"0.02","best_ask":"0.03"}],"timestamp":"1770839724562","event_type":"price_change","_sub_state":"active","_subscription_id":1,"_active_subscription_id":1},"parse_warnings":[],"out_of_order":false}
{"run_id":"29526913bab7446286864a321c124486","channel":"market","event_type":"price_change","market":"0x8032d8355d335c6ccbfc2508d99fbc87eb13f437bd275c93ee56fd1558e517ff","asset_id":null,"source":"market_ws:sub:active:1","t_event_ms":1770839724568,"t_recv_wall_ms":1770839724471,"t_recv_wall_iso":"2026-02-11T19:55:24.471Z","t_recv_mono_ns":618589812549041,"raw":{"market":"0x8032d8355d335c6ccbfc2508d99fbc87eb13f437bd275c93ee56fd1558e517ff","price_changes":[{"asset_id":"20773614133833886322101538939702011175545796528197617633926164254913649353392","price":"0.01","size":"30804.91","side":"BUY","hash":"d4d8e995d1519cb58522936a66b874f890b0240f","best_bid":"0.02","best_ask":"0.03"},{"asset_id":"40652734036737240317526188612064032143639112324786051284480877037991580442979","price":"0.99","size":"30804.91","side":"SELL","hash":"b109654f563b072369dccd4b12be042b28e9abd5","best_bid":"0.97","best_ask":"0.98"}],"timestamp":"1770839724568","event_type":"price_change","_sub_state":"active","_subscription_id":1,"_active_subscription_id":1},"parse_warnings":[],"out_of_order":false}
{"run_id":"29526913bab7446286864a321c124486","channel":"market","event_type":"price_change","market":"0x8032d8355d335c6ccbfc2508d99fbc87eb13f437bd275c93ee56fd1558e517ff","asset_id":null,"source":"market_ws:sub:active:1","t_event_ms":1770839724573,"t_recv_wall_ms":1770839724478,"t_recv_wall_iso":"2026-02-11T19:55:24.478Z","t_recv_mono_ns":618589818921916,"raw":{"market":"0x8032d8355d335c6ccbfc2508d99fbc87eb13f437bd275c93ee56fd1558e517ff","price_changes":[{"asset_id":"20773614133833886322101538939702011175545796528197617633926164254913649353392","price":"0.02","size":"8956.68","side":"BUY","hash":"3ee6514120813143e00fa99bc7648fd58587b64a","best_bid":"0.02","best_ask":"0.03"},{"asset_id":"40652734036737240317526188612064032143639112324786051284480877037991580442979","price":"0.98","size":"8956.68","side":"SELL","hash":"3938617815cb923886afabe6bce5a73b08d21a0f","best_bid":"0.97","best_ask":"0.98"}],"timestamp":"1770839724573","event_type":"price_change","_sub_state":"active","_subscription_id":1,"_active_subscription_id":1},"parse_warnings":[],"out_of_order":false}
{"run_id":"29526913bab7446286864a321c124486","channel":"market","event_type":"price_change","market":"0x8032d8355d335c6ccbfc2508d99fbc87eb13f437bd275c93ee56fd1558e517ff","asset_id":null,"source":"market_ws:sub:active:1","t_event_ms":1770839724574,"t_recv_wall_ms":1770839724488,"t_recv_wall_iso":"2026-02-11T19:55:24.488Z","t_recv_mono_ns":618589829559041,"raw":{"market":"0x8032d8355d335c6ccbfc2508d99fbc87eb13f437bd275c93ee56fd1558e517ff","price_changes":[{"asset_id":"40652734036737240317526188612064032143639112324786051284480877037991580442979","price":"0.96","size":"3708.17","side":"BUY","hash":"4264a2b695374f3bd55a36d46241b90ed0f68400","best_bid":"0.97","best_ask":"0.98"},{"asset_id":"20773614133833886322101538939702011175545796528197617633926164254913649353392","price":"0.04","size":"3708.17","side":"SELL","hash":"34056f6ae0fb358263299b42a9e30fd48367558c","best_bid":"0.02","best_ask":"0.03"}],"timestamp":"1770839724574","event_type":"price_change","_sub_state":"active","_subscription_id":1,"_active_subscription_id":1},"parse_warnings":[],"out_of_order":false}
{"run_id":"29526913bab7446286864a321c124486","channel":"market","event_type":"price_change","market":"0x8032d8355d335c6ccbfc2508d99fbc87eb13f437bd275c93ee56fd1558e517ff","asset_id":null,"source":"market_ws:sub:active:1","t_event_ms":1770839724587,"t_recv_wall_ms":1770839724509,"t_recv_wall_iso":"2026-02-11T19:55:24.509Z","t_recv_mono_ns":618589849990166,"raw":{"market":"0x8032d8355d335c6ccbfc2508d99fbc87eb13f437bd275c93ee56fd1558e517ff","price_changes":[{"asset_id":"20773614133833886322101538939702011175545796528197617633926164254913649353392","price":"0.02","size":"8986.68","side":"BUY","hash":"ebe0dd5a852944b8dae5dea35a35c4c5674e383b","best_bid":"0.02","best_ask":"0.03"},{"asset_id":"40652734036737240317526188612064032143639112324786051284480877037991580442979","price":"0.98","size":"8986.68","side":"SELL","hash":"8a108cdf45137335eb74a76e0682827bcb844bb1","best_bid":"0.97","best_ask":"0.98"}],"timestamp":"1770839724587","event_type":"price_change","_sub_state":"active","_subscription_id":1,"_active_subscription_id":1},"parse_warnings":[],"out_of_order":false}
{"run_id":"29526913bab7446286864a321c124486","channel":"market","event_type":"price_change","market":"0x8032d8355d335c6ccbfc2508d99fbc87eb13f437bd275c93ee56fd1558e517ff","asset_id":null,"source":"market_ws:sub:active:1","t_event_ms":1770839724591,"t_recv_wall_ms":1770839724509,"t_recv_wall_iso":"2026-02-11T19:55:24.509Z","t_recv_mono_ns":618589850484333,"raw":{"market":"0x8032d8355d335c6ccbfc2508d99fbc87eb13f437bd275c93ee56fd1558e517ff","price_changes":[{"asset_id":"40652734036737240317526188612064032143639112324786051284480877037991580442979","price":"0.95","size":"3199.45","side":"BUY","hash":"c4b890b673f4da9629c8dda273981d602737b2b2","best_bid":"0.97","best_ask":"0.98"},{"asset_id":"20773614133833886322101538939702011175545796528197617633926164254913649353392","price":"0.05","size":"3199.45","side":"SELL","hash":"00370ac130ea9663b9cbea850179a5d1df439e4c","best_bid":"0.02","best_ask":"0.03"}],"timestamp":"1770839724591","event_type":"price_change","_sub_state":"active","_subscription_id":1,"_active_subscription_id":1},"parse_warnings":[],"out_of_order":false}
{"run_id":"29526913bab7446286864a321c124486","channel":"market","event_type":"price_change","market":"0x8032d8355d335c6ccbfc2508d99fbc87eb13f437bd275c93ee56fd1558e517ff","asset_id":null,"source":"market_ws:sub:active:1","t_event_ms":1770839724597,"t_recv_wall_ms":1770839724509,"t_recv_wall_iso":"2026-02-11T19:55:24.509Z","t_recv_mono_ns":618589850661458,"raw":{"market":"0x8032d8355d335c6ccbfc2508d99fbc87eb13f437bd275c93ee56fd1558e517ff","price_changes":[{"asset_id":"40652734036737240317526188612064032143639112324786051284480877037991580442979","price":"0.95","size":"3229.45","side":"BUY","hash":"09a4a9696add0d19a0b7091c5a44d13eb99767ec","best_bid":"0.97","best_ask":"0.98"},{"asset_id":"20773614133833886322101538939702011175545796528197617633926164254913649353392","price":"0.05","size":"3229.45","side":"SELL","hash":"7d9a589409143044a66d42625cd34adf0bb027e3","best_bid":"0.02","best_ask":"0.03"}],"timestamp":"1770839724597","event_type":"price_change","_sub_state":"active","_subscription_id":1,"_active_subscription_id":1},"parse_warnings":[],"out_of_order":false}
{"run_id":"29526913bab7446286864a321c124486","channel":"market","event_type":"price_change","market":"0x8032d8355d335c6ccbfc2508d99fbc87eb13f437bd275c93ee56fd1558e517ff","asset_id":null,"source":"market_ws:sub:active:1","t_event_ms":1770839724601,"t_recv_wall_ms":1770839724510,"t_recv_wall_iso":"2026-02-11T19:55:24.510Z","t_recv_mono_ns":618589851659750,"raw":{"market":"0x8032d8355d335c6ccbfc2508d99fbc87eb13f437bd275c93ee56fd1558e517ff","price_changes":[{"asset_id":"40652734036737240317526188612064032143639112324786051284480877037991580442979","price":"0.82","size":"1096.55","side":"BUY","hash":"6c8d4951007fee84a29b044cee2dcf4726bddf9f","best_bid":"0.97","best_ask":"0.98"},{"asset_id":"20773614133833886322101538939702011175545796528197617633926164254913649353392","price":"0.18","size":"1096.55","side":"SELL","hash":"b35b9a6421472707586ce7afceb864b07cf5be31","best_bid":"0.02","best_ask":"0.03"}],"timestamp":"1770839724601","event_type":"price_change","_sub_state":"active","_subscription_id":1,"_active_subscription_id":1},"parse_warnings":[],"out_of_order":false}
{"run_id":"29526913bab7446286864a321c124486","channel":"market","event_type":"price_change","market":"0x8032d8355d335c6ccbfc2508d99fbc87eb13f437bd275c93ee56fd1558e517ff","asset_id":null,"source":"market_ws:sub:active:1","t_event_ms":1770839724603,"t_recv_wall_ms":1770839724511,"t_recv_wall_iso":"2026-02-11T19:55:24.511Z","t_recv_mono_ns":618589851887625,"raw":{"market":"0x8032d8355d335c6ccbfc2508d99fbc87eb13f437bd275c93ee56fd1558e517ff","price_changes":[{"asset_id":"40652734036737240317526188612064032143639112324786051284480877037991580442979","price":"0.95","size":"3224.45","side":"BUY","hash":"3e5461a767b2fd3f807682ebee379aa5bc2ca86d","best_bid":"0.97","best_ask":"0.98"},{"asset_id":"20773614133833886322101538939702011175545796528197617633926164254913649353392","price":"0.05","size":"3224.45","side":"SELL","hash":"92d61a9f3a533d9377fd48de203500c99fd656c4","best_bid":"0.02","best_ask":"0.03"}],"timestamp":"1770839724603","event_type":"price_change","_sub_state":"active","_subscription_id":1,"_active_subscription_id":1},"parse_warnings":[],"out_of_order":false}
{"run_id":"29526913bab7446286864a321c124486","channel":"market","event_type":"price_change","market":"0x8032d8355d335c6ccbfc2508d99fbc87eb13f437bd275c93ee56fd1558e517ff","asset_id":null,"source":"market_ws:sub:active:1","t_event_ms":1770839724606,"t_recv_wall_ms":1770839724511,"t_recv_wall_iso":"2026-02-11T19:55:24.511Z","t_recv_mono_ns":618589852006500,"raw":{"market":"0x8032d8355d335c6ccbfc2508d99fbc87eb13f437bd275c93ee56fd1558e517ff","price_changes":[{"asset_id":"40652734036737240317526188612064032143639112324786051284480877037991580442979","price":"0.96","size":"3678.17","side":"BUY","hash":"3483a9edca5db248d115c58117c37bfe8e07bb8f","best_bid":"0.97","best_ask":"0.98"},{"asset_id":"20773614133833886322101538939702011175545796528197617633926164254913649353392","price":"0.04","size":"3678.17","side":"SELL","hash":"08fbe28b4ca5bc16dd5924c264368a07b36e815d","best_bid":"0.02","best_ask":"0.03"}],"timestamp":"1770839724606","event_type":"price_change","_sub_state":"active","_subscription_id":1,"_active_subscription_id":1},"parse_warnings":[],"out_of_order":false}
{"run_id":"29526913bab7446286864a321c124486","channel":"market","event_type":"price_change","market":"0x8032d8355d335c6ccbfc2508d99fbc87eb13f437bd275c93ee56fd1558e517ff","asset_id":null,"source":"market_ws:sub:active:1","t_event_ms":1770839724609,"t_recv_wall_ms":1770839724512,"t_recv_wall_iso":"2026-02-11T19:55:24.512Z","t_recv_mono_ns":618589853649125,"raw":{"market":"0x8032d8355d335c6ccbfc2508d99fbc87eb13f437bd275c93ee56fd1558e517ff","price_changes":[{"asset_id":"20773614133833886322101538939702011175545796528197617633926164254913649353392","price":"0.02","size":"9016.68","side":"BUY","hash":"2a58fde62de44147ac81dfdd49d026f67d3f667f","best_bid":"0.02","best_ask":"0.03"},{"asset_id":"40652734036737240317526188612064032143639112324786051284480877037991580442979","price":"0.98","size":"9016.68","side":"SELL","hash":"3cc14acc2058f840937af8fb26171742e306de9e","best_bid":"0.97","best_ask":"0.98"}],"timestamp":"1770839724609","event_type":"price_change","_sub_state":"active","_subscription_id":1,"_active_subscription_id":1},"parse_warnings":[],"out_of_order":false}
{"run_id":"29526913bab7446286864a321c124486","channel":"market","event_type":"price_change","market":"0x8032d8355d335c6ccbfc2508d99fbc87eb13f437bd275c93ee56fd1558e517ff","asset_id":null,"source":"market_ws:sub:active:1","t_event_ms":1770839724610,"t_recv_wall_ms":1770839724515,"t_recv_wall_iso":"2026-02-11T19:55:24.515Z","t_recv_mono_ns":618589855794333,"raw":{"market":"0x8032d8355d335c6ccbfc2508d99fbc87eb13f437bd275c93ee56fd1558e517ff","price_changes":[{"asset_id":"40652734036737240317526188612064032143639112324786051284480877037991580442979","price":"0.95","size":"3254.45","side":"BUY","hash":"e233e0cedc5279422e393cca3fe1b85d1af87c72","best_bid":"0.97","best_ask":"0.98"},{"asset_id":"20773614133833886322101538939702011175545796528197617633926164254913649353392","price":"0.05","size":"3254.45","side":"SELL","hash":"fb8e1eb1f56e829937e8917f00a134687c13fc64","best_bid":"0.02","best_ask":"0.03"}],"timestamp":"1770839724610","event_type":"price_change","_sub_state":"active","_subscription_id":1,"_active_subscription_id":1},"parse_warnings":[],"out_of_order":false}
{"run_id":"29526913bab7446286864a321c124486","channel":"market","event_type":"price_change","market":"0x8032d8355d335c6ccbfc2508d99fbc87eb13f437bd275c93ee56fd1558e517ff","asset_id":null,"source":"market_ws:sub:active:1","t_event_ms":1770839724613,"t_recv_wall_ms":1770839724517,"t_recv_wall_iso":"2026-02-11T19:55:24.517Z","t_recv_mono_ns":618589857914666,"raw":{"market":"0x8032d8355d335c6ccbfc2508d99fbc87eb13f437bd275c93ee56fd1558e517ff","price_changes":[{"asset_id":"20773614133833886322101538939702011175545796528197617633926164254913649353392","price":"0.02","size":"9046.68","side":"BUY","hash":"eca1ae919398eae4904095f473cfbf947261a1be","best_bid":"0.02","best_ask":"0.03"},{"asset_id":"40652734036737240317526188612064032143639112324786051284480877037991580442979","price":"0.98","size":"9046.68","side":"SELL","hash":"0bfb79539037e965b095fd89b936df624c2e9bf8","best_bid":"0.97","best_ask":"0.98"}],"timestamp":"1770839724613","event_type":"price_change","_sub_state":"active","_subscription_id":1,"_active_subscription_id":1},"parse_warnings":[],"out_of_order":false}
{"run_id":"29526913bab7446286864a321c124486","channel":"market","event_type":"price_change","market":"0x8032d8355d335c6ccbfc2508d99fbc87eb13f437bd275c93ee56fd1558e517ff","asset_id":null,"source":"market_ws:sub:active:1","t_event_ms":1770839724619,"t_recv_wall_ms":1770839724524,"t_recv_wall_iso":"2026-02-11T19:55:24.524Z","t_recv_mono_ns":618589865734375,"raw":{"market":"0x8032d8355d335c6ccbfc2508d99fbc87eb13f437bd275c93ee56fd1558e517ff","price_changes":[{"asset_id":"40652734036737240317526188612064032143639112324786051284480877037991580442979","price":"0.95","size":"3194.45","side":"BUY","hash":"5dae1569b630ed9d887105115f9ba2f6131f9a7a","best_bid":"0.97","best_ask":"0.98"},{"asset_id":"20773614133833886322101538939702011175545796528197617633926164254913649353392","price":"0.05","size":"3194.45","side":"SELL","hash":"919217c6dee17af6164177d759aaf8018fee5bf1","best_bid":"0.02","best_ask":"0.03"}],"timestamp":"1770839724619","event_type":"price_change","_sub_state":"active","_subscription_id":1,"_active_subscription_id":1},"parse_warnings":[],"out_of_order":false}
{"run_id":"29526913bab7446286864a321c124486","channel":"market","event_type":"price_change","market":"0x8032d8355d335c6ccbfc2508d99fbc87eb13f437bd275c93ee56fd1558e517ff","asset_id":null,"source":"market_ws:sub:active:1","t_event_ms":1770839724621,"t_recv_wall_ms":1770839724525,"t_recv_wall_iso":"2026-02-11T19:55:24.525Z","t_recv_mono_ns":618589866450416,"raw":{"market":"0x8032d8355d335c6ccbfc2508d99fbc87eb13f437bd275c93ee56fd1558e517ff","price_changes":[{"asset_id":"20773614133833886322101538939702011175545796528197617633926164254913649353392","price":"0.02","size":"8986.68","side":"BUY","hash":"34e3094baaeff8d2282c40375ff108248145bbdb","best_bid":"0.02","best_ask":"0.03"},{"asset_id":"40652734036737240317526188612064032143639112324786051284480877037991580442979","price":"0.98","size":"8986.68","side":"SELL","hash":"af7db8cf7fec2dc7b20f87fa9e72966d841aa448","best_bid":"0.97","best_ask":"0.98"}],"timestamp":"1770839724621","event_type":"price_change","_sub_state":"active","_subscription_id":1,"_active_subscription_id":1},"parse_warnings":[],"out_of_order":false}
{"run_id":"29526913bab7446286864a321c124486","channel":"market","event_type":"price_change","market":"0x8032d8355d335c6ccbfc2508d99fbc87eb13f437bd275c93ee56fd1558e517ff","asset_id":null,"source":"market_ws:sub:active:1","t_event_ms":1770839724623,"t_recv_wall_ms":1770839724526,"t_recv_wall_iso":"2026-02-11T19:55:24.526Z","t_recv_mono_ns":618589867289875,"raw":{"market":"0x8032d8355d335c6ccbfc2508d99fbc87eb13f437bd275c93ee56fd1558e517ff","price_changes":[{"asset_id":"20773614133833886322101538939702011175545796528197617633926164254913649353392","price":"0.01","size":"30864.91","side":"BUY","hash":"d3fe0ee25c9a9daee228d49dbee8889c628ae08f","best_bid":"0.02","best_ask":"0.03"},{"asset_id":"40652734036737240317526188612064032143639112324786051284480877037991580442979","price":"0.99","size":"30864.91","side":"SELL","hash":"8af65d21f58cfedebdf437ae8bf8ae313e38567a","best_bid":"0.97","best_ask":"0.98"}],"timestamp":"1770839724623","event_type":"price_change","_sub_state":"active","_subscription_id":1,"_active_subscription_id":1},"parse_warnings":[],"out_of_order":false}
{"run_id":"29526913bab7446286864a321c124486","channel":"market","event_type":"price_change","market":"0x8032d8355d335c6ccbfc2508d99fbc87eb13f437bd275c93ee56fd1558e517ff","asset_id":null,"source":"market_ws:sub:active:1","t_event_ms":1770839724624,"t_recv_wall_ms":1770839724528,"t_recv_wall_iso":"2026-02-11T19:55:24.528Z","t_recv_mono_ns":618589869456125,"raw":{"market":"0x8032d8355d335c6ccbfc2508d99fbc87eb13f437bd275c93ee56fd1558e517ff","price_changes":[{"asset_id":"40652734036737240317526188612064032143639112324786051284480877037991580442979","price":"0.96","size":"3738.17","side":"BUY","hash":"33f075e8369dfcf7e6b5a50ff1a0c3ce6f2261f1","best_bid":"0.97","best_ask":"0.98"},{"asset_id":"20773614133833886322101538939702011175545796528197617633926164254913649353392","price":"0.04","size":"3738.17","side":"SELL","hash":"eb03f5c1726a471feb2b3069be4f94d0cf84a504","best_bid":"0.02","best_ask":"0.03"}],"timestamp":"1770839724624","event_type":"price_change","_sub_state":"active","_subscription_id":1,"_active_subscription_id":1},"parse_warnings":[],"out_of_order":false}
{"run_id":"29526913bab7446286864a321c124486","channel":"market","event_type":"price_change","market":"0x8032d8355d335c6ccbfc2508d99fbc87eb13f437bd275c93ee56fd1558e517ff","asset_id":null,"source":"market_ws:sub:active:1","t_event_ms":1770839724662,"t_recv_wall_ms":1770839724579,"t_recv_wall_iso":"2026-02-11T19:55:24.579Z","t_recv_mono_ns":618589920096375,"raw":{"market":"0x8032d8355d335c6ccbfc2508d99fbc87eb13f437bd275c93ee56fd1558e517ff","price_changes":[{"asset_id":"20773614133833886322101538939702011175545796528197617633926164254913649353392","price":"0.02","size":"8977.49","side":"BUY","hash":"d3daa08ce841a06d4cabe626e7f8d950a93937ac","best_bid":"0.02","best_ask":"0.03"},{"asset_id":"40652734036737240317526188612064032143639112324786051284480877037991580442979","price":"0.98","size":"8977.49","side":"SELL","hash":"812a690e21b2948f30f0b3f4bbcf37b5c903c240","best_bid":"0.97","best_ask":"0.98"}],"timestamp":"1770839724662","event_type":"price_change","_sub_state":"active","_subscription_id":1,"_active_subscription_id":1},"parse_warnings":[],"out_of_order":false}
{"run_id":"29526913bab7446286864a321c124486","channel":"market","event_type":"book","market":"0x8032d8355d335c6ccbfc2508d99fbc87eb13f437bd275c93ee56fd1558e517ff","asset_id":"20773614133833886322101538939702011175545796528197617633926164254913649353392","source":"market_ws:sub:active:1","t_event_ms":1770839724662,"t_recv_wall_ms":1770839724579,"t_recv_wall_iso":"2026-02-11T19:55:24.579Z","t_recv_mono_ns":618589920538000,"raw":{"market":"0x8032d8355d335c6ccbfc2508d99fbc87eb13f437bd275c93ee56fd1558e517ff","asset_id":"20773614133833886322101538939702011175545796528197617633926164254913649353392","bids":[{"price":"0.01","size":"30864.91"},{"price":"0.02","size":"8977.49"}],"asks":[{"price":"0.99","size":"30822.26"},{"price":"0.98","size":"12559.04"},{"price":"0.97","size":"7433.03"},{"price":"0.96","size":"5453.8"},{"price":"0.95","size":"6815.8"},{"price":"0.94","size":"5105"},{"price":"0.93","size":"5421.38"},{"price":"0.92","size":"5139.4"},{"price":"0.91","size":"5225.8"},{"price":"0.9","size":"5102.8"},{"price":"0.89","size":"120.6"},{"price":"0.88","size":"63.6"},{"price":"0.87","size":"63"},{"price":"0.86","size":"61.6"},{"price":"0.85","size":"107.39"},{"price":"0.84","size":"69.39"},{"price":"0.83","size":"58.39"},{"price":"0.82","size":"66.71"},{"price":"0.81","size":"56.8"},{"price":"0.8","size":"92.14"},{"price":"0.79","size":"60.8"},{"price":"0.78","size":"55.2"},{"price":"0.77","size":"64.48"},{"price":"0.76","size":"54.2"},{"price":"0.75","size":"375.8"},{"price":"0.74","size":"68.6"},{"price":"0.73","size":"53.2"},{"price":"0.72","size":"63.26"},{"price":"0.71","size":"52.6"},{"price":"0.7","size":"402.4"},{"price":"0.69","size":"72.2"},{"price":"0.68","size":"87.88"},{"price":"0.67","size":"188.46"},{"price":"0.66","size":"123.6"},{"price":"0.65","size":"317.03"},{"price":"0.64","size":"582.36"},{"price":"0.63","size":"559.2"},{"price":"0.62","size":"559"},{"price":"0.61","size":"594"},{"price":"0.6","size":"2915.41"},{"price":"0.59","size":"576.8"},{"price":"0.58","size":"575.5"},{"price":"0.57","size":"558.6"},{"price":"0.56","size":"572.68"},{"price":"0.55","size":"566.4"},{"price":"0.54","size":"561.94"},{"price":"0.53","size":"631.57"},{"price":"0.52","size":"611.4"},{"price":"0.51","size":"705.2"},{"price":"0.5","size":"1011.55"},{"price":"0.49","size":"692.4"},{"price":"0.48","size":"628.4"},{"price":"0.47","size":"633.4"},{"price":"0.46","size":"711.65"},{"price":"0.45","size":"866.59"},{"price":"0.44","size":"905.69"},{"price":"0.43","size":"641.6"},{"price":"0.42","size":"645.58"},{"price":"0.41","size":"564"},{"price":"0.4","size":"20642.9"},{"price":"0.39","size":"650.23"},{"price":"0.38","size":"593"},{"price":"0.37","size":"755.73"},{"price":"0.36","size":"558"},{"price":"0.35","size":"1144.32"},{"price":"0.34","size":"649.59"},{"price":"0.33","size":"624.8"},{"price":"0.32","size":"574"},{"price":"0.31","size":"594.2"},{"price":"0.3","size":"735.66"},{"price":"0.29","size":"624.6"},{"price":"0.28","size":"356.8"},{"price":"0.27","size":"869.2"},{"price":"0.26","size":"967.6"},{"price":"0.25","size":"1673.8"},{"price":"0.24","size":"869.2"},{"price":"0.23","size":"864.6"},{"price":"0.22","size":"870.2"},{"price":"0.21","size":"891.6"},{"price":"0.2","size":"987.2"},{"price":"0.19","size":"876.8"},{"price":"0.18","size":"1096.55"},{"price":"0.17","size":"958.39"},{"price":"0.16","size":"1119.39"},{"price":"0.15","size":"1149.13"},{"price":"0.14","size":"962.6"},{"price":"0.13","size":"1041.8"},{"price":"0.12","size":"1060.55"},{"price":"0.11","size":"1124.49"},{"price":"0.1","size":"1306.79"},{"price":"0.09","size":"669.6"},{"price":"0.08","size":"3384.35"},{"price":"0.07","size":"3360.43"},{"price":"0.06","size":"3135.34"},{"price":"0.05","size":"3194.45"},{"price":"0.04","size":"3738.17"},{"price":"0.03","size":"641.4"}],"hash":"d3daa08ce841a06d4cabe626e7f8d950a93937ac","timestamp":"1770839724662","event_type":"book","_sub_state":"active","_subscription_id":1,"_active_subscription_id":1},"parse_warnings":[],"out_of_order":false}
{"run_id":"29526913bab7446286864a321c124486","channel":"market","event_type":"book","market":"0x8032d8355d335c6ccbfc2508d99fbc87eb13f437bd275c93ee56fd1558e517ff","asset_id":"40652734036737240317526188612064032143639112324786051284480877037991580442979","source":"market_ws:sub:active:1","t_event_ms":1770839724662,"t_recv_wall_ms":1770839724582,"t_recv_wall_iso":"2026-02-11T19:55:24.582Z","t_recv_mono_ns":618589922995208,"raw":{"market":"0x8032d8355d335c6ccbfc2508d99fbc87eb13f437bd275c93ee56fd1558e517ff","asset_id":"40652734036737240317526188612064032143639112324786051284480877037991580442979","bids":[{"price":"0.01","size":"30822.26"},{"price":"0.02","size":"12559.04"},{"price":"0.03","size":"7433.03"},{"price":"0.04","size":"5453.8"},{"price":"0.05","size":"6815.8"},{"price":"0.06","size":"5105"},{"price":"0.07","size":"5421.38"},{"price":"0.08","size":"5139.4"},{"price":"0.09","size":"5225.8"},{"price":"0.1","size":"5102.8"},{"price":"0.11","size":"120.6"},{"price":"0.12","size":"63.6"},{"price":"0.13","size":"63"},{"price":"0.14","size":"61.6"},{"price":"0.15","size":"107.39"},{"price":"0.16","size":"69.39"},{"price":"0.17","size":"58.39"},{"price":"0.18","size":"66.71"},{"price":"0.19","size":"56.8"},{"price":"0.2","size":"92.14"},{"price":"0.21","size":"60.8"},{"price":"0.22","size":"55.2"},{"price":"0.23","size":"64.48"},{"price":"0.24","size":"54.2"},{"price":"0.25","size":"375.8"},{"price":"0.26","size":"68.6"},{"price":"0.27","size":"53.2"},{"price":"0.28","size":"63.26"},{"price":"0.29","size":"52.6"},{"price":"0.3","size":"402.4"},{"price":"0.31","size":"72.2"},{"price":"0.32","size":"87.88"},{"price":"0.33","size":"188.46"},{"price":"0.34","size":"123.6"},{"price":"0.35","size":"317.03"},{"price":"0.36","size":"582.36"},{"price":"0.37","size":"559.2"},{"price":"0.38","size":"559"},{"price":"0.39","size":"594"},{"price":"0.4","size":"2915.41"},{"price":"0.41","size":"576.8"},{"price":"0.42","size":"575.5"},{"price":"0.43","size":"558.6"},{"price":"0.44","size":"572.68"},{"price":"0.45","size":"566.4"},{"price":"0.46","size":"561.94"},{"price":"0.47","size":"631.57"},{"price":"0.48","size":"611.4"},{"price":"0.49","size":"705.2"},{"price":"0.5","size":"1011.55"},{"price":"0.51","size":"692.4"},{"price":"0.52","size":"628.4"},{"price":"0.53","size":"633.4"},{"price":"0.54","size":"711.65"},{"price":"0.55","size":"866.59"},{"price":"0.56","size":"905.69"},{"price":"0.57","size":"641.6"},{"price":"0.58","size":"645.58"},{"price":"0.59","size":"564"},{"price":"0.6","size":"20642.9"},{"price":"0.61","size":"650.23"},{"price":"0.62","size":"593"},{"price":"0.63","size":"755.73"},{"price":"0.64","size":"558"},{"price":"0.65","size":"1144.32"},{"price":"0.66","size":"649.59"},{"price":"0.67","size":"624.8"},{"price":"0.68","size":"574"},{"price":"0.69","size":"594.2"},{"price":"0.7","size":"735.66"},{"price":"0.71","size":"624.6"},{"price":"0.72","size":"356.8"},{"price":"0.73","size":"869.2"},{"price":"0.74","size":"967.6"},{"price":"0.75","size":"1673.8"},{"price":"0.76","size":"869.2"},{"price":"0.77","size":"864.6"},{"price":"0.78","size":"870.2"},{"price":"0.79","size":"891.6"},{"price":"0.8","size":"987.2"},{"price":"0.81","size":"876.8"},{"price":"0.82","size":"1096.55"},{"price":"0.83","size":"958.39"},{"price":"0.84","size":"1119.39"},{"price":"0.85","size":"1149.13"},{"price":"0.86","size":"962.6"},{"price":"0.87","size":"1041.8"},{"price":"0.88","size":"1060.55"},{"price":"0.89","size":"1124.49"},{"price":"0.9","size":"1306.79"},{"price":"0.91","size":"669.6"},{"price":"0.92","size":"3384.35"},{"price":"0.93","size":"3360.43"},{"price":"0.94","size":"3135.34"},{"price":"0.95","size":"3194.45"},{"price":"0.96","size":"3738.17"},{"price":"0.97","size":"641.4"}],"asks":[{"price":"0.99","size":"30864.91"},{"price":"0.98","size":"8977.49"}],"hash":"812a690e21b2948f30f0b3f4bbcf37b5c903c240","timestamp":"1770839724662","event_type":"book","_sub_state":"active","_subscription_id":1,"_active_subscription_id":1},"parse_warnings":[],"out_of_order":false}
{"run_id":"29526913bab7446286864a321c124486","channel":"market","event_type":"price_change","market":"0x8032d8355d335c6ccbfc2508d99fbc87eb13f437bd275c93ee56fd1558e517ff","asset_id":null,"source":"market_ws:sub:active:1","t_event_ms":1770839724666,"t_recv_wall_ms":1770839724582,"t_recv_wall_iso":"2026-02-11T19:55:24.582Z","t_recv_mono_ns":618589923522250,"raw":{"market":"0x8032d8355d335c6ccbfc2508d99fbc87eb13f437bd275c93ee56fd1558e517ff","price_changes":[{"asset_id":"40652734036737240317526188612064032143639112324786051284480877037991580442979","price":"0.95","size":"3224.45","side":"BUY","hash":"6d23859d171a290e5b6e90e1e4aca7a5eb1b712c","best_bid":"0.97","best_ask":"0.98"},{"asset_id":"20773614133833886322101538939702011175545796528197617633926164254913649353392","price":"0.05","size":"3224.45","side":"SELL","hash":"5abd77f06c77a7d74a8720ab1d669656c9f2212b","best_bid":"0.02","best_ask":"0.03"}],"timestamp":"1770839724666","event_type":"price_change","_sub_state":"active","_subscription_id":1,"_active_subscription_id":1},"parse_warnings":[],"out_of_order":false}
{"run_id":"29526913bab7446286864a321c124486","channel":"market","event_type":"price_change","market":"0x8032d8355d335c6ccbfc2508d99fbc87eb13f437bd275c93ee56fd1558e517ff","asset_id":null,"source":"market_ws:sub:active:1","t_event_ms":1770839724670,"t_recv_wall_ms":1770839724582,"t_recv_wall_iso":"2026-02-11T19:55:24.582Z","t_recv_mono_ns":618589923645041,"raw":{"market":"0x8032d8355d335c6ccbfc2508d99fbc87eb13f437bd275c93ee56fd1558e517ff","price_changes":[{"asset_id":"40652734036737240317526188612064032143639112324786051284480877037991580442979","price":"0.94","size":"3140.34","side":"BUY","hash":"af8e3675ed91ab877ca40cd77a7269ee4fe5b24e","best_bid":"0.97","best_ask":"0.98"},{"asset_id":"20773614133833886322101538939702011175545796528197617633926164254913649353392","price":"0.06","size":"3140.34","side":"SELL","hash":"2a4958891222feca99321b723919c63521d6eafe","best_bid":"0.02","best_ask":"0.03"}],"timestamp":"1770839724670","event_type":"price_change","_sub_state":"active","_subscription_id":1,"_active_subscription_id":1},"parse_warnings":[],"out_of_order":false}
{"run_id":"29526913bab7446286864a321c124486","channel":"market","event_type":"last_trade_price","market":"0x8032d8355d335c6ccbfc2508d99fbc87eb13f437bd275c93ee56fd1558e517ff","asset_id":"40652734036737240317526188612064032143639112324786051284480877037991580442979","source":"market_ws:sub:unknown","t_event_ms":1770839724697,"t_recv_wall_ms":1770839724625,"t_recv_wall_iso":"2026-02-11T19:55:24.625Z","t_recv_mono_ns":618589966230250,"raw":{"market":"0x8032d8355d335c6ccbfc2508d99fbc87eb13f437bd275c93ee56fd1558e517ff","asset_id":"40652734036737240317526188612064032143639112324786051284480877037991580442979","price":"0.98","size":"9.19","fee_rate_bps":"1000","side":"BUY","timestamp":"1770839724697","event_type":"last_trade_price","transaction_hash":"0x956b56efa75d386f5ccef79fb32c09303831addc8bea7a1b4cfbd9479341e14a","_sub_state":"unknown","_subscription_id":null,"_active_subscription_id":1},"parse_warnings":["unknown_message_schema"],"out_of_order":false}
{"run_id":"29526913bab7446286864a321c124486","channel":"market","event_type":"price_change","market":"0x8032d8355d335c6ccbfc2508d99fbc87eb13f437bd275c93ee56fd1558e517ff","asset_id":null,"source":"market_ws:sub:active:1","t_event_ms":1770839724698,"t_recv_wall_ms":1770839724626,"t_recv_wall_iso":"2026-02-11T19:55:24.626Z","t_recv_mono_ns":618589966807000,"raw":{"market":"0x8032d8355d335c6ccbfc2508d99fbc87eb13f437bd275c93ee56fd1558e517ff","price_changes":[{"asset_id":"20773614133833886322101538939702011175545796528197617633926164254913649353392","price":"0.02","size":"8973.4","side":"BUY","hash":"d197050b57dc576e12e0f967a6746626d99b609f","best_bid":"0.02","best_ask":"0.03"},{"asset_id":"40652734036737240317526188612064032143639112324786051284480877037991580442979","price":"0.98","size":"8973.4","side":"SELL","hash":"0105f9b3a7828163704b82a67f9cee2b26a92e87","best_bid":"0.97","best_ask":"0.98"}],"timestamp":"1770839724698","event_type":"price_change","_sub_state":"active","_subscription_id":1,"_active_subscription_id":1},"parse_warnings":[],"out_of_order":false}
{"run_id":"29526913bab7446286864a321c124486","channel":"market","event_type":"book","market":"0x8032d8355d335c6ccbfc2508d99fbc87eb13f437bd275c93ee56fd1558e517ff","asset_id":"20773614133833886322101538939702011175545796528197617633926164254913649353392","source":"market_ws:sub:active:1","t_event_ms":1770839724698,"t_recv_wall_ms":1770839724626,"t_recv_wall_iso":"2026-02-11T19:55:24.626Z","t_recv_mono_ns":618589967174416,"raw":{"market":"0x8032d8355d335c6ccbfc2508d99fbc87eb13f437bd275c93ee56fd1558e517ff","asset_id":"20773614133833886322101538939702011175545796528197617633926164254913649353392","bids":[{"price":"0.01","size":"30864.91"},{"price":"0.02","size":"8973.4"}],"asks":[{"price":"0.99","size":"30822.26"},{"price":"0.98","size":"12559.04"},{"price":"0.97","size":"7433.03"},{"price":"0.96","size":"5453.8"},{"price":"0.95","size":"6815.8"},{"price":"0.94","size":"5105"},{"price":"0.93","size":"5421.38"},{"price":"0.92","size":"5139.4"},{"price":"0.91","size":"5225.8"},{"price":"0.9","size":"5102.8"},{"price":"0.89","size":"120.6"},{"price":"0.88","size":"63.6"},{"price":"0.87","size":"63"},{"price":"0.86","size":"61.6"},{"price":"0.85","size":"107.39"},{"price":"0.84","size":"69.39"},{"price":"0.83","size":"58.39"},{"price":"0.82","size":"66.71"},{"price":"0.81","size":"56.8"},{"price":"0.8","size":"92.14"},{"price":"0.79","size":"60.8"},{"price":"0.78","size":"55.2"},{"price":"0.77","size":"64.48"},{"price":"0.76","size":"54.2"},{"price":"0.75","size":"375.8"},{"price":"0.74","size":"68.6"},{"price":"0.73","size":"53.2"},{"price":"0.72","size":"63.26"},{"price":"0.71","size":"52.6"},{"price":"0.7","size":"402.4"},{"price":"0.69","size":"72.2"},{"price":"0.68","size":"87.88"},{"price":"0.67","size":"188.46"},{"price":"0.66","size":"123.6"},{"price":"0.65","size":"317.03"},{"price":"0.64","size":"582.36"},{"price":"0.63","size":"559.2"},{"price":"0.62","size":"559"},{"price":"0.61","size":"594"},{"price":"0.6","size":"2915.41"},{"price":"0.59","size":"576.8"},{"price":"0.58","size":"575.5"},{"price":"0.57","size":"558.6"},{"price":"0.56","size":"572.68"},{"price":"0.55","size":"566.4"},{"price":"0.54","size":"561.94"},{"price":"0.53","size":"631.57"},{"price":"0.52","size":"611.4"},{"price":"0.51","size":"705.2"},{"price":"0.5","size":"1011.55"},{"price":"0.49","size":"692.4"},{"price":"0.48","size":"628.4"},{"price":"0.47","size":"633.4"},{"price":"0.46","size":"711.65"},{"price":"0.45","size":"866.59"},{"price":"0.44","size":"905.69"},{"price":"0.43","size":"641.6"},{"price":"0.42","size":"645.58"},{"price":"0.41","size":"564"},{"price":"0.4","size":"20642.9"},{"price":"0.39","size":"650.23"},{"price":"0.38","size":"593"},{"price":"0.37","size":"755.73"},{"price":"0.36","size":"558"},{"price":"0.35","size":"1144.32"},{"price":"0.34","size":"649.59"},{"price":"0.33","size":"624.8"},{"price":"0.32","size":"574"},{"price":"0.31","size":"594.2"},{"price":"0.3","size":"735.66"},{"price":"0.29","size":"624.6"},{"price":"0.28","size":"356.8"},{"price":"0.27","size":"869.2"},{"price":"0.26","size":"967.6"},{"price":"0.25","size":"1673.8"},{"price":"0.24","size":"869.2"},{"price":"0.23","size":"864.6"},{"price":"0.22","size":"870.2"},{"price":"0.21","size":"891.6"},{"price":"0.2","size":"987.2"},{"price":"0.19","size":"876.8"},{"price":"0.18","size":"1096.55"},{"price":"0.17","size":"958.39"},{"price":"0.16","size":"1119.39"},{"price":"0.15","size":"1149.13"},{"price":"0.14","size":"962.6"},{"price":"0.13","size":"1041.8"},{"price":"0.12","size":"1060.55"},{"price":"0.11","size":"1124.49"},{"price":"0.1","size":"1306.79"},{"price":"0.09","size":"669.6"},{"price":"0.08","size":"3384.35"},{"price":"0.07","size":"3360.43"},{"price":"0.06","size":"3140.34"},{"price":"0.05","size":"3224.45"},{"price":"0.04","size":"3738.17"},{"price":"0.03","size":"641.4"}],"hash":"d197050b57dc576e12e0f967a6746626d99b609f","timestamp":"1770839724698","event_type":"book","_sub_state":"active","_subscription_id":1,"_active_subscription_id":1},"parse_warnings":[],"out_of_order":false}
{"run_id":"29526913bab7446286864a321c124486","channel":"market","event_type":"book","market":"0x8032d8355d335c6ccbfc2508d99fbc87eb13f437bd275c93ee56fd1558e517ff","asset_id":"40652734036737240317526188612064032143639112324786051284480877037991580442979","source":"market_ws:sub:active:1","t_event_ms":1770839724698,"t_recv_wall_ms":1770839724627,"t_recv_wall_iso":"2026-02-11T19:55:24.627Z","t_recv_mono_ns":618589967996416,"raw":{"market":"0x8032d8355d335c6ccbfc2508d99fbc87eb13f437bd275c93ee56fd1558e517ff","asset_id":"40652734036737240317526188612064032143639112324786051284480877037991580442979","bids":[{"price":"0.01","size":"30822.26"},{"price":"0.02","size":"12559.04"},{"price":"0.03","size":"7433.03"},{"price":"0.04","size":"5453.8"},{"price":"0.05","size":"6815.8"},{"price":"0.06","size":"5105"},{"price":"0.07","size":"5421.38"},{"price":"0.08","size":"5139.4"},{"price":"0.09","size":"5225.8"},{"price":"0.1","size":"5102.8"},{"price":"0.11","size":"120.6"},{"price":"0.12","size":"63.6"},{"price":"0.13","size":"63"},{"price":"0.14","size":"61.6"},{"price":"0.15","size":"107.39"},{"price":"0.16","size":"69.39"},{"price":"0.17","size":"58.39"},{"price":"0.18","size":"66.71"},{"price":"0.19","size":"56.8"},{"price":"0.2","size":"92.14"},{"price":"0.21","size":"60.8"},{"price":"0.22","size":"55.2"},{"price":"0.23","size":"64.48"},{"price":"0.24","size":"54.2"},{"price":"0.25","size":"375.8"},{"price":"0.26","size":"68.6"},{"price":"0.27","size":"53.2"},{"price":"0.28","size":"63.26"},{"price":"0.29","size":"52.6"},{"price":"0.3","size":"402.4"},{"price":"0.31","size":"72.2"},{"price":"0.32","size":"87.88"},{"price":"0.33","size":"188.46"},{"price":"0.34","size":"123.6"},{"price":"0.35","size":"317.03"},{"price":"0.36","size":"582.36"},{"price":"0.37","size":"559.2"},{"price":"0.38","size":"559"},{"price":"0.39","size":"594"},{"price":"0.4","size":"2915.41"},{"price":"0.41","size":"576.8"},{"price":"0.42","size":"575.5"},{"price":"0.43","size":"558.6"},{"price":"0.44","size":"572.68"},{"price":"0.45","size":"566.4"},{"price":"0.46","size":"561.94"},{"price":"0.47","size":"631.57"},{"price":"0.48","size":"611.4"},{"price":"0.49","size":"705.2"},{"price":"0.5","size":"1011.55"},{"price":"0.51","size":"692.4"},{"price":"0.52","size":"628.4"},{"price":"0.53","size":"633.4"},{"price":"0.54","size":"711.65"},{"price":"0.55","size":"866.59"},{"price":"0.56","size":"905.69"},{"price":"0.57","size":"641.6"},{"price":"0.58","size":"645.58"},{"price":"0.59","size":"564"},{"price":"0.6","size":"20642.9"},{"price":"0.61","size":"650.23"},{"price":"0.62","size":"593"},{"price":"0.63","size":"755.73"},{"price":"0.64","size":"558"},{"price":"0.65","size":"1144.32"},{"price":"0.66","size":"649.59"},{"price":"0.67","size":"624.8"},{"price":"0.68","size":"574"},{"price":"0.69","size":"594.2"},{"price":"0.7","size":"735.66"},{"price":"0.71","size":"624.6"},{"price":"0.72","size":"356.8"},{"price":"0.73","size":"869.2"},{"price":"0.74","size":"967.6"},{"price":"0.75","size":"1673.8"},{"price":"0.76","size":"869.2"},{"price":"0.77","size":"864.6"},{"price":"0.78","size":"870.2"},{"price":"0.79","size":"891.6"},{"price":"0.8","size":"987.2"},{"price":"0.81","size":"876.8"},{"price":"0.82","size":"1096.55"},{"price":"0.83","size":"958.39"},{"price":"0.84","size":"1119.39"},{"price":"0.85","size":"1149.13"},{"price":"0.86","size":"962.6"},{"price":"0.87","size":"1041.8"},{"price":"0.88","size":"1060.55"},{"price":"0.89","size":"1124.49"},{"price":"0.9","size":"1306.79"},{"price":"0.91","size":"669.6"},{"price":"0.92","size":"3384.35"},{"price":"0.93","size":"3360.43"},{"price":"0.94","size":"3140.34"},{"price":"0.95","size":"3224.45"},{"price":"0.96","size":"3738.17"},{"price":"0.97","size":"641.4"}],"asks":[{"price":"0.99","size":"30864.91"},{"price":"0.98","size":"8973.4"}],"hash":"0105f9b3a7828163704b82a67f9cee2b26a92e87","timestamp":"1770839724698","event_type":"book","_sub_state":"active","_subscription_id":1,"_active_subscription_id":1},"parse_warnings":[],"out_of_order":false}
{"run_id":"29526913bab7446286864a321c124486","channel":"market","event_type":"price_change","market":"0x8032d8355d335c6ccbfc2508d99fbc87eb13f437bd275c93ee56fd1558e517ff","asset_id":null,"source":"market_ws:sub:active:1","t_event_ms":1770839724703,"t_recv_wall_ms":1770839724627,"t_recv_wall_iso":"2026-02-11T19:55:24.627Z","t_recv_mono_ns":618589968507291,"raw":{"market":"0x8032d8355d335c6ccbfc2508d99fbc87eb13f437bd275c93ee56fd1558e517ff","price_changes":[{"asset_id":"40652734036737240317526188612064032143639112324786051284480877037991580442979","price":"0.95","size":"3254.45","side":"BUY","hash":"7e06d2fdf79d35876d268783a039a0a012c69562","best_bid":"0.97","best_ask":"0.98"},{"asset_id":"20773614133833886322101538939702011175545796528197617633926164254913649353392","price":"0.05","size":"3254.45","side":"SELL","hash":"7534dd0ff4d309b223adbf88dd4b725125b83080","best_bid":"0.02","best_ask":"0.03"}],"timestamp":"1770839724703","event_type":"price_change","_sub_state":"active","_subscription_id":1,"_active_subscription_id":1},"parse_warnings":[],"out_of_order":false}
{"run_id":"29526913bab7446286864a321c124486","channel":"market","event_type":"price_change","market":"0x8032d8355d335c6ccbfc2508d99fbc87eb13f437bd275c93ee56fd1558e517ff","asset_id":null,"source":"market_ws:sub:active:1","t_event_ms":1770839724706,"t_recv_wall_ms":1770839724627,"t_recv_wall_iso":"2026-02-11T19:55:24.627Z","t_recv_mono_ns":618589968648333,"raw":{"market":"0x8032d8355d335c6ccbfc2508d99fbc87eb13f437bd275c93ee56fd1558e517ff","price_changes":[{"asset_id":"40652734036737240317526188612064032143639112324786051284480877037991580442979","price":"0.82","size":"1091.55","side":"BUY","hash":"dedb94fd7950e82eeec760210a85890543214784","best_bid":"0.97","best_ask":"0.98"},{"asset_id":"20773614133833886322101538939702011175545796528197617633926164254913649353392","price":"0.18","size":"1091.55","side":"SELL","hash":"cc54107237f55dbfa60a3e4106df7eef1b862f23","best_bid":"0.02","best_ask":"0.03"}],"timestamp":"1770839724706","event_type":"price_change","_sub_state":"active","_subscription_id":1,"_active_subscription_id":1},"parse_warnings":[],"out_of_order":false}
{"run_id":"29526913bab7446286864a321c124486","channel":"market","event_type":"price_change","market":"0x8032d8355d335c6ccbfc2508d99fbc87eb13f437bd275c93ee56fd1558e517ff","asset_id":null,"source":"market_ws:sub:active:1","t_event_ms":1770839724709,"t_recv_wall_ms":1770839724628,"t_recv_wall_iso":"2026-02-11T19:55:24.628Z","t_recv_mono_ns":618589968795125,"raw":{"market":"0x8032d8355d335c6ccbfc2508d99fbc87eb13f437bd275c93ee56fd1558e517ff","price_changes":[{"asset_id":"40652734036737240317526188612064032143639112324786051284480877037991580442979","price":"0.91","size":"754.6","side":"BUY","hash":"330b4de8993182c0a19a1302dd39042e211cc19d","best_bid":"0.97","best_ask":"0.98"},{"asset_id":"20773614133833886322101538939702011175545796528197617633926164254913649353392","price":"0.09","size":"754.6","side":"SELL","hash":"4702da7145e573a2643b7a95aeb0d1100c8244a3","best_bid":"0.02","best_ask":"0.03"}],"timestamp":"1770839724709","event_type":"price_change","_sub_state":"active","_subscription_id":1,"_active_subscription_id":1},"parse_warnings":[],"out_of_order":false}
{"run_id":"29526913bab7446286864a321c124486","channel":"market","event_type":"price_change","market":"0x8032d8355d335c6ccbfc2508d99fbc87eb13f437bd275c93ee56fd1558e517ff","asset_id":null,"source":"market_ws:sub:active:1","t_event_ms":1770839724725,"t_recv_wall_ms":1770839724647,"t_recv_wall_iso":"2026-02-11T19:55:24.647Z","t_recv_mono_ns":618589987799791,"raw":{"market":"0x8032d8355d335c6ccbfc2508d99fbc87eb13f437bd275c93ee56fd1558e517ff","price_changes":[{"asset_id":"20773614133833886322101538939702011175545796528197617633926164254913649353392","price":"0.02","size":"8966.25","side":"BUY","hash":"d14993e795ae2e9234c3abc17512802df414b5e5","best_bid":"0.02","best_ask":"0.03"},{"asset_id":"40652734036737240317526188612064032143639112324786051284480877037991580442979","price":"0.98","size":"8966.25","side":"SELL","hash":"d7006feea020784abfdc24bf52a45804393001e8","best_bid":"0.97","best_ask":"0.98"}],"timestamp":"1770839724725","event_type":"price_change","_sub_state":"active","_subscription_id":1,"_active_subscription_id":1},"parse_warnings":[],"out_of_order":false}
{"run_id":"29526913bab7446286864a321c124486","channel":"market","event_type":"last_trade_price","market":"0x8032d8355d335c6ccbfc2508d99fbc87eb13f437bd275c93ee56fd1558e517ff","asset_id":"40652734036737240317526188612064032143639112324786051284480877037991580442979","source":"market_ws:sub:unknown","t_event_ms":1770839724729,"t_recv_wall_ms":1770839724647,"t_recv_wall_iso":"2026-02-11T19:55:24.647Z","t_recv_mono_ns":618589988239458,"raw":{"market":"0x8032d8355d335c6ccbfc2508d99fbc87eb13f437bd275c93ee56fd1558e517ff","asset_id":"40652734036737240317526188612064032143639112324786051284480877037991580442979","price":"0.98","size":"4.09","fee_rate_bps":"1000","side":"BUY","timestamp":"1770839724729","event_type":"last_trade_price","transaction_hash":"0x4733927ab859570458114b01dbd70b82a1bd71d54344f9a5b9534470e865f3c2","_sub_state":"unknown","_subscription_id":null,"_active_subscription_id":1},"parse_warnings":["unknown_message_schema"],"out_of_order":false}
{"run_id":"29526913bab7446286864a321c124486","channel":"market","event_type":"book","market":"0x8032d8355d335c6ccbfc2508d99fbc87eb13f437bd275c93ee56fd1558e517ff","asset_id":"20773614133833886322101538939702011175545796528197617633926164254913649353392","source":"market_ws:sub:active:1","t_event_ms":1770839724725,"t_recv_wall_ms":1770839724647,"t_recv_wall_iso":"2026-02-11T19:55:24.647Z","t_recv_mono_ns":618589988477333,"raw":{"market":"0x8032d8355d335c6ccbfc2508d99fbc87eb13f437bd275c93ee56fd1558e517ff","asset_id":"20773614133833886322101538939702011175545796528197617633926164254913649353392","bids":[{"price":"0.01","size":"30864.91"},{"price":"0.02","size":"8966.25"}],"asks":[{"price":"0.99","size":"30822.26"},{"price":"0.98","size":"12559.04"},{"price":"0.97","size":"7433.03"},{"price":"0.96","size":"5453.8"},{"price":"0.95","size":"6815.8"},{"price":"0.94","size":"5105"},{"price":"0.93","size":"5421.38"},{"price":"0.92","size":"5139.4"},{"price":"0.91","size":"5225.8"},{"price":"0.9","size":"5102.8"},{"price":"0.89","size":"120.6"},{"price":"0.88","size":"63.6"},{"price":"0.87","size":"63"},{"price":"0.86","size":"61.6"},{"price":"0.85","size":"107.39"},{"price":"0.84","size":"69.39"},{"price":"0.83","size":"58.39"},{"price":"0.82","size":"66.71"},{"price":"0.81","size":"56.8"},{"price":"0.8","size":"92.14"},{"price":"0.79","size":"60.8"},{"price":"0.78","size":"55.2"},{"price":"0.77","size":"64.48"},{"price":"0.76","size":"54.2"},{"price":"0.75","size":"375.8"},{"price":"0.74","size":"68.6"},{"price":"0.73","size":"53.2"},{"price":"0.72","size":"63.26"},{"price":"0.71","size":"52.6"},{"price":"0.7","size":"402.4"},{"price":"0.69","size":"72.2"},{"price":"0.68","size":"87.88"},{"price":"0.67","size":"188.46"},{"price":"0.66","size":"123.6"},{"price":"0.65","size":"317.03"},{"price":"0.64","size":"582.36"},{"price":"0.63","size":"559.2"},{"price":"0.62","size":"559"},{"price":"0.61","size":"594"},{"price":"0.6","size":"2915.41"},{"price":"0.59","size":"576.8"},{"price":"0.58","size":"575.5"},{"price":"0.57","size":"558.6"},{"price":"0.56","size":"572.68"},{"price":"0.55","size":"566.4"},{"price":"0.54","size":"561.94"},{"price":"0.53","size":"631.57"},{"price":"0.52","size":"611.4"},{"price":"0.51","size":"705.2"},{"price":"0.5","size":"1011.55"},{"price":"0.49","size":"692.4"},{"price":"0.48","size":"628.4"},{"price":"0.47","size":"633.4"},{"price":"0.46","size":"711.65"},{"price":"0.45","size":"866.59"},{"price":"0.44","size":"905.69"},{"price":"0.43","size":"641.6"},{"price":"0.42","size":"645.58"},{"price":"0.41","size":"564"},{"price":"0.4","size":"20642.9"},{"price":"0.39","size":"650.23"},{"price":"0.38","size":"593"},{"price":"0.37","size":"755.73"},{"price":"0.36","size":"558"},{"price":"0.35","size":"1144.32"},{"price":"0.34","size":"649.59"},{"price":"0.33","size":"624.8"},{"price":"0.32","size":"574"},{"price":"0.31","size":"594.2"},{"price":"0.3","size":"735.66"},{"price":"0.29","size":"624.6"},{"price":"0.28","size":"356.8"},{"price":"0.27","size":"869.2"},{"price":"0.26","size":"967.6"},{"price":"0.25","size":"1673.8"},{"price":"0.24","size":"869.2"},{"price":"0.23","size":"864.6"},{"price":"0.22","size":"870.2"},{"price":"0.21","size":"891.6"},{"price":"0.2","size":"987.2"},{"price":"0.19","size":"876.8"},{"price":"0.18","size":"1091.55"},{"price":"0.17","size":"958.39"},{"price":"0.16","size":"1119.39"},{"price":"0.15","size":"1149.13"},{"price":"0.14","size":"962.6"},{"price":"0.13","size":"1041.8"},{"price":"0.12","size":"1060.55"},{"price":"0.11","size":"1124.49"},{"price":"0.1","size":"1306.79"},{"price":"0.09","size":"754.6"},{"price":"0.08","size":"3384.35"},{"price":"0.07","size":"3360.43"},{"price":"0.06","size":"3140.34"},{"price":"0.05","size":"3254.45"},{"price":"0.04","size":"3738.17"},{"price":"0.03","size":"641.4"}],"hash":"d14993e795ae2e9234c3abc17512802df414b5e5","timestamp":"1770839724725","event_type":"book","_sub_state":"active","_subscription_id":1,"_active_subscription_id":1},"parse_warnings":[],"out_of_order":false}
{"run_id":"29526913bab7446286864a321c124486","channel":"market","event_type":"book","market":"0x8032d8355d335c6ccbfc2508d99fbc87eb13f437bd275c93ee56fd1558e517ff","asset_id":"40652734036737240317526188612064032143639112324786051284480877037991580442979","source":"market_ws:sub:active:1","t_event_ms":1770839724725,"t_recv_wall_ms":1770839724648,"t_recv_wall_iso":"2026-02-11T19:55:24.648Z","t_recv_mono_ns":618589989323750,"raw":{"market":"0x8032d8355d335c6ccbfc2508d99fbc87eb13f437bd275c93ee56fd1558e517ff","asset_id":"40652734036737240317526188612064032143639112324786051284480877037991580442979","bids":[{"price":"0.01","size":"30822.26"},{"price":"0.02","size":"12559.04"},{"price":"0.03","size":"7433.03"},{"price":"0.04","size":"5453.8"},{"price":"0.05","size":"6815.8"},{"price":"0.06","size":"5105"},{"price":"0.07","size":"5421.38"},{"price":"0.08","size":"5139.4"},{"price":"0.09","size":"5225.8"},{"price":"0.1","size":"5102.8"},{"price":"0.11","size":"120.6"},{"price":"0.12","size":"63.6"},{"price":"0.13","size":"63"},{"price":"0.14","size":"61.6"},{"price":"0.15","size":"107.39"},{"price":"0.16","size":"69.39"},{"price":"0.17","size":"58.39"},{"price":"0.18","size":"66.71"},{"price":"0.19","size":"56.8"},{"price":"0.2","size":"92.14"},{"price":"0.21","size":"60.8"},{"price":"0.22","size":"55.2"},{"price":"0.23","size":"64.48"},{"price":"0.24","size":"54.2"},{"price":"0.25","size":"375.8"},{"price":"0.26","size":"68.6"},{"price":"0.27","size":"53.2"},{"price":"0.28","size":"63.26"},{"price":"0.29","size":"52.6"},{"price":"0.3","size":"402.4"},{"price":"0.31","size":"72.2"},{"price":"0.32","size":"87.88"},{"price":"0.33","size":"188.46"},{"price":"0.34","size":"123.6"},{"price":"0.35","size":"317.03"},{"price":"0.36","size":"582.36"},{"price":"0.37","size":"559.2"},{"price":"0.38","size":"559"},{"price":"0.39","size":"594"},{"price":"0.4","size":"2915.41"},{"price":"0.41","size":"576.8"},{"price":"0.42","size":"575.5"},{"price":"0.43","size":"558.6"},{"price":"0.44","size":"572.68"},{"price":"0.45","size":"566.4"},{"price":"0.46","size":"561.94"},{"price":"0.47","size":"631.57"},{"price":"0.48","size":"611.4"},{"price":"0.49","size":"705.2"},{"price":"0.5","size":"1011.55"},{"price":"0.51","size":"692.4"},{"price":"0.52","size":"628.4"},{"price":"0.53","size":"633.4"},{"price":"0.54","size":"711.65"},{"price":"0.55","size":"866.59"},{"price":"0.56","size":"905.69"},{"price":"0.57","size":"641.6"},{"price":"0.58","size":"645.58"},{"price":"0.59","size":"564"},{"price":"0.6","size":"20642.9"},{"price":"0.61","size":"650.23"},{"price":"0.62","size":"593"},{"price":"0.63","size":"755.73"},{"price":"0.64","size":"558"},{"price":"0.65","size":"1144.32"},{"price":"0.66","size":"649.59"},{"price":"0.67","size":"624.8"},{"price":"0.68","size":"574"},{"price":"0.69","size":"594.2"},{"price":"0.7","size":"735.66"},{"price":"0.71","size":"624.6"},{"price":"0.72","size":"356.8"},{"price":"0.73","size":"869.2"},{"price":"0.74","size":"967.6"},{"price":"0.75","size":"1673.8"},{"price":"0.76","size":"869.2"},{"price":"0.77","size":"864.6"},{"price":"0.78","size":"870.2"},{"price":"0.79","size":"891.6"},{"price":"0.8","size":"987.2"},{"price":"0.81","size":"876.8"},{"price":"0.82","size":"1091.55"},{"price":"0.83","size":"958.39"},{"price":"0.84","size":"1119.39"},{"price":"0.85","size":"1149.13"},{"price":"0.86","size":"962.6"},{"price":"0.87","size":"1041.8"},{"price":"0.88","size":"1060.55"},{"price":"0.89","size":"1124.49"},{"price":"0.9","size":"1306.79"},{"price":"0.91","size":"754.6"},{"price":"0.92","size":"3384.35"},{"price":"0.93","size":"3360.43"},{"price":"0.94","size":"3140.34"},{"price":"0.95","size":"3254.45"},{"price":"0.96","size":"3738.17"},{"price":"0.97","size":"641.4"}],"asks":[{"price":"0.99","size":"30864.91"},{"price":"0.98","size":"8966.25"}],"hash":"d7006feea020784abfdc24bf52a45804393001e8","timestamp":"1770839724725","event_type":"book","_sub_state":"active","_subscription_id":1,"_active_subscription_id":1},"parse_warnings":[],"out_of_order":false}
{"run_id":"29526913bab7446286864a321c124486","channel":"market","event_type":"price_change","market":"0x8032d8355d335c6ccbfc2508d99fbc87eb13f437bd275c93ee56fd1558e517ff","asset_id":null,"source":"market_ws:sub:active:1","t_event_ms":1770839724739,"t_recv_wall_ms":1770839724649,"t_recv_wall_iso":"2026-02-11T19:55:24.649Z","t_recv_mono_ns":618589989859875,"raw":{"market":"0x8032d8355d335c6ccbfc2508d99fbc87eb13f437bd275c93ee56fd1558e517ff","price_changes":[{"asset_id":"40652734036737240317526188612064032143639112324786051284480877037991580442979","price":"0.99","size":"30859.91","side":"SELL","hash":"b193b514d5369c88e55593e451433a0983bfd15a","best_bid":"0.97","best_ask":"0.98"},{"asset_id":"20773614133833886322101538939702011175545796528197617633926164254913649353392","price":"0.01","size":"30859.91","side":"BUY","hash":"9b8954f5ce862b3e5c8f15e77c162544781ae63d","best_bid":"0.02","best_ask":"0.03"}],"timestamp":"1770839724739","event_type":"price_change","_sub_state":"active","_subscription_id":1,"_active_subscription_id":1},"parse_warnings":[],"out_of_order":false}
{"run_id":"29526913bab7446286864a321c124486","channel":"market","event_type":"price_change","market":"0x8032d8355d335c6ccbfc2508d99fbc87eb13f437bd275c93ee56fd1558e517ff","asset_id":null,"source":"market_ws:sub:active:1","t_event_ms":1770839724742,"t_recv_wall_ms":1770839724649,"t_recv_wall_iso":"2026-02-11T19:55:24.649Z","t_recv_mono_ns":618589990123333,"raw":{"market":"0x8032d8355d335c6ccbfc2508d99fbc87eb13f437bd275c93ee56fd1558e517ff","price_changes":[{"asset_id":"40652734036737240317526188612064032143639112324786051284480877037991580442979","price":"0.92","size":"3379.35","side":"BUY","hash":"c785b20866f4083f68366145130deafd103ba8b5","best_bid":"0.97","best_ask":"0.98"},{"asset_id":"20773614133833886322101538939702011175545796528197617633926164254913649353392","price":"0.08","size":"3379.35","side":"SELL","hash":"0ffef9aff96dcddbdc8be350e8e0152aca2a93f5","best_bid":"0.02","best_ask":"0.03"}],"timestamp":"1770839724742","event_type":"price_change","_sub_state":"active","_subscription_id":1,"_active_subscription_id":1},"parse_warnings":[],"out_of_order":false}
{"run_id":"29526913bab7446286864a321c124486","channel":"market","event_type":"last_trade_price","market":"0x8032d8355d335c6ccbfc2508d99fbc87eb13f437bd275c93ee56fd1558e517ff","asset_id":"40652734036737240317526188612064032143639112324786051284480877037991580442979","source":"market_ws:sub:unknown","t_event_ms":1770839724756,"t_recv_wall_ms":1770839724660,"t_recv_wall_iso":"2026-02-11T19:55:24.660Z","t_recv_mono_ns":618590001371166,"raw":{"market":"0x8032d8355d335c6ccbfc2508d99fbc87eb13f437bd275c93ee56fd1558e517ff","asset_id":"40652734036737240317526188612064032143639112324786051284480877037991580442979","price":"0.98","size":"7.15","fee_rate_bps":"1000","side":"BUY","timestamp":"1770839724756","event_type":"last_trade_price","transaction_hash":"0x7fe971bbb7c30c7210d84e912898e1f2bdb6d4ee8c1a79b81845ca243ffc42f7","_sub_state":"unknown","_subscription_id":null,"_active_subscription_id":1},"parse_warnings":["unknown_message_schema"],"out_of_order":false}
{"run_id":"29526913bab7446286864a321c124486","channel":"market","event_type":"price_change","market":"0x8032d8355d335c6ccbfc2508d99fbc87eb13f437bd275c93ee56fd1558e517ff","asset_id":null,"source":"market_ws:sub:active:1","t_event_ms":1770839724761,"t_recv_wall_ms":1770839724673,"t_recv_wall_iso":"2026-02-11T19:55:24.673Z","t_recv_mono_ns":618590014155458,"raw":{"market":"0x8032d8355d335c6ccbfc2508d99fbc87eb13f437bd275c93ee56fd1558e517ff","price_changes":[{"asset_id":"20773614133833886322101538939702011175545796528197617633926164254913649353392","price":"0.02","size":"8956.04","side":"BUY","hash":"6ccff18cc37a5ff8eb9dda2c9331e74a438c6bcb","best_bid":"0.02","best_ask":"0.03"},{"asset_id":"40652734036737240317526188612064032143639112324786051284480877037991580442979","price":"0.98","size":"8956.04","side":"SELL","hash":"449eaf6d1c4275d3d187ea1ebce2b6c608529606","best_bid":"0.97","best_ask":"0.98"}],"timestamp":"1770839724761","event_type":"price_change","_sub_state":"active","_subscription_id":1,"_active_subscription_id":1},"parse_warnings":[],"out_of_order":false}
{"run_id":"29526913bab7446286864a321c124486","channel":"market","event_type":"book","market":"0x8032d8355d335c6ccbfc2508d99fbc87eb13f437bd275c93ee56fd1558e517ff","asset_id":"20773614133833886322101538939702011175545796528197617633926164254913649353392","source":"market_ws:sub:active:1","t_event_ms":1770839724761,"t_recv_wall_ms":1770839724673,"t_recv_wall_iso":"2026-02-11T19:55:24.673Z","t_recv_mono_ns":618590014445625,"raw":{"market":"0x8032d8355d335c6ccbfc2508d99fbc87eb13f437bd275c93ee56fd1558e517ff","asset_id":"20773614133833886322101538939702011175545796528197617633926164254913649353392","bids":[{"price":"0.01","size":"30859.91"},{"price":"0.02","size":"8956.04"}],"asks":[{"price":"0.99","size":"30822.26"},{"price":"0.98","size":"12559.04"},{"price":"0.97","size":"7433.03"},{"price":"0.96","size":"5453.8"},{"price":"0.95","size":"6815.8"},{"price":"0.94","size":"5105"},{"price":"0.93","size":"5421.38"},{"price":"0.92","size":"5139.4"},{"price":"0.91","size":"5225.8"},{"price":"0.9","size":"5102.8"},{"price":"0.89","size":"120.6"},{"price":"0.88","size":"63.6"},{"price":"0.87","size":"63"},{"price":"0.86","size":"61.6"},{"price":"0.85","size":"107.39"},{"price":"0.84","size":"69.39"},{"price":"0.83","size":"58.39"},{"price":"0.82","size":"66.71"},{"price":"0.81","size":"56.8"},{"price":"0.8","size":"92.14"},{"price":"0.79","size":"60.8"},{"price":"0.78","size":"55.2"},{"price":"0.77","size":"64.48"},{"price":"0.76","size":"54.2"},{"price":"0.75","size":"375.8"},{"price":"0.74","size":"68.6"},{"price":"0.73","size":"53.2"},{"price":"0.72","size":"63.26"},{"price":"0.71","size":"52.6"},{"price":"0.7","size":"402.4"},{"price":"0.69","size":"72.2"},{"price":"0.68","size":"87.88"},{"price":"0.67","size":"188.46"},{"price":"0.66","size":"123.6"},{"price":"0.65","size":"317.03"},{"price":"0.64","size":"582.36"},{"price":"0.63","size":"559.2"},{"price":"0.62","size":"559"},{"price":"0.61","size":"594"},{"price":"0.6","size":"2915.41"},{"price":"0.59","size":"576.8"},{"price":"0.58","size":"575.5"},{"price":"0.57","size":"558.6"},{"price":"0.56","size":"572.68"},{"price":"0.55","size":"566.4"},{"price":"0.54","size":"561.94"},{"price":"0.53","size":"631.57"},{"price":"0.52","size":"611.4"},{"price":"0.51","size":"705.2"},{"price":"0.5","size":"1011.55"},{"price":"0.49","size":"692.4"},{"price":"0.48","size":"628.4"},{"price":"0.47","size":"633.4"},{"price":"0.46","size":"711.65"},{"price":"0.45","size":"866.59"},{"price":"0.44","size":"905.69"},{"price":"0.43","size":"641.6"},{"price":"0.42","size":"645.58"},{"price":"0.41","size":"564"},{"price":"0.4","size":"20642.9"},{"price":"0.39","size":"650.23"},{"price":"0.38","size":"593"},{"price":"0.37","size":"755.73"},{"price":"0.36","size":"558"},{"price":"0.35","size":"1144.32"},{"price":"0.34","size":"649.59"},{"price":"0.33","size":"624.8"},{"price":"0.32","size":"574"},{"price":"0.31","size":"594.2"},{"price":"0.3","size":"735.66"},{"price":"0.29","size":"624.6"},{"price":"0.28","size":"356.8"},{"price":"0.27","size":"869.2"},{"price":"0.26","size":"967.6"},{"price":"0.25","size":"1673.8"},{"price":"0.24","size":"869.2"},{"price":"0.23","size":"864.6"},{"price":"0.22","size":"870.2"},{"price":"0.21","size":"891.6"},{"price":"0.2","size":"987.2"},{"price":"0.19","size":"876.8"},{"price":"0.18","size":"1091.55"},{"price":"0.17","size":"958.39"},{"price":"0.16","size":"1119.39"},{"price":"0.15","size":"1149.13"},{"price":"0.14","size":"962.6"},{"price":"0.13","size":"1041.8"},{"price":"0.12","size":"1060.55"},{"price":"0.11","size":"1124.49"},{"price":"0.1","size":"1306.79"},{"price":"0.09","size":"754.6"},{"price":"0.08","size":"3379.35"},{"price":"0.07","size":"3360.43"},{"price":"0.06","size":"3140.34"},{"price":"0.05","size":"3254.45"},{"price":"0.04","size":"3738.17"},{"price":"0.03","size":"641.4"}],"hash":"6ccff18cc37a5ff8eb9dda2c9331e74a438c6bcb","timestamp":"1770839724761","event_type":"book","_sub_state":"active","_subscription_id":1,"_active_subscription_id":1},"parse_warnings":[],"out_of_order":false}
{"run_id":"29526913bab7446286864a321c124486","channel":"market","event_type":"book","market":"0x8032d8355d335c6ccbfc2508d99fbc87eb13f437bd275c93ee56fd1558e517ff","asset_id":"40652734036737240317526188612064032143639112324786051284480877037991580442979","source":"market_ws:sub:active:1","t_event_ms":1770839724761,"t_recv_wall_ms":1770839724674,"t_recv_wall_iso":"2026-02-11T19:55:24.674Z","t_recv_mono_ns":618590014899750,"raw":{"market":"0x8032d8355d335c6ccbfc2508d99fbc87eb13f437bd275c93ee56fd1558e517ff","asset_id":"40652734036737240317526188612064032143639112324786051284480877037991580442979","bids":[{"price":"0.01","size":"30822.26"},{"price":"0.02","size":"12559.04"},{"price":"0.03","size":"7433.03"},{"price":"0.04","size":"5453.8"},{"price":"0.05","size":"6815.8"},{"price":"0.06","size":"5105"},{"price":"0.07","size":"5421.38"},{"price":"0.08","size":"5139.4"},{"price":"0.09","size":"5225.8"},{"price":"0.1","size":"5102.8"},{"price":"0.11","size":"120.6"},{"price":"0.12","size":"63.6"},{"price":"0.13","size":"63"},{"price":"0.14","size":"61.6"},{"price":"0.15","size":"107.39"},{"price":"0.16","size":"69.39"},{"price":"0.17","size":"58.39"},{"price":"0.18","size":"66.71"},{"price":"0.19","size":"56.8"},{"price":"0.2","size":"92.14"},{"price":"0.21","size":"60.8"},{"price":"0.22","size":"55.2"},{"price":"0.23","size":"64.48"},{"price":"0.24","size":"54.2"},{"price":"0.25","size":"375.8"},{"price":"0.26","size":"68.6"},{"price":"0.27","size":"53.2"},{"price":"0.28","size":"63.26"},{"price":"0.29","size":"52.6"},{"price":"0.3","size":"402.4"},{"price":"0.31","size":"72.2"},{"price":"0.32","size":"87.88"},{"price":"0.33","size":"188.46"},{"price":"0.34","size":"123.6"},{"price":"0.35","size":"317.03"},{"price":"0.36","size":"582.36"},{"price":"0.37","size":"559.2"},{"price":"0.38","size":"559"},{"price":"0.39","size":"594"},{"price":"0.4","size":"2915.41"},{"price":"0.41","size":"576.8"},{"price":"0.42","size":"575.5"},{"price":"0.43","size":"558.6"},{"price":"0.44","size":"572.68"},{"price":"0.45","size":"566.4"},{"price":"0.46","size":"561.94"},{"price":"0.47","size":"631.57"},{"price":"0.48","size":"611.4"},{"price":"0.49","size":"705.2"},{"price":"0.5","size":"1011.55"},{"price":"0.51","size":"692.4"},{"price":"0.52","size":"628.4"},{"price":"0.53","size":"633.4"},{"price":"0.54","size":"711.65"},{"price":"0.55","size":"866.59"},{"price":"0.56","size":"905.69"},{"price":"0.57","size":"641.6"},{"price":"0.58","size":"645.58"},{"price":"0.59","size":"564"},{"price":"0.6","size":"20642.9"},{"price":"0.61","size":"650.23"},{"price":"0.62","size":"593"},{"price":"0.63","size":"755.73"},{"price":"0.64","size":"558"},{"price":"0.65","size":"1144.32"},{"price":"0.66","size":"649.59"},{"price":"0.67","size":"624.8"},{"price":"0.68","size":"574"},{"price":"0.69","size":"594.2"},{"price":"0.7","size":"735.66"},{"price":"0.71","size":"624.6"},{"price":"0.72","size":"356.8"},{"price":"0.73","size":"869.2"},{"price":"0.74","size":"967.6"},{"price":"0.75","size":"1673.8"},{"price":"0.76","size":"869.2"},{"price":"0.77","size":"864.6"},{"price":"0.78","size":"870.2"},{"price":"0.79","size":"891.6"},{"price":"0.8","size":"987.2"},{"price":"0.81","size":"876.8"},{"price":"0.82","size":"1091.55"},{"price":"0.83","size":"958.39"},{"price":"0.84","size":"1119.39"},{"price":"0.85","size":"1149.13"},{"price":"0.86","size":"962.6"},{"price":"0.87","size":"1041.8"},{"price":"0.88","size":"1060.55"},{"price":"0.89","size":"1124.49"},{"price":"0.9","size":"1306.79"},{"price":"0.91","size":"754.6"},{"price":"0.92","size":"3379.35"},{"price":"0.93","size":"3360.43"},{"price":"0.94","size":"3140.34"},{"price":"0.95","size":"3254.45"},{"price":"0.96","size":"3738.17"},{"price":"0.97","size":"641.4"}],"asks":[{"price":"0.99","size":"30859.91"},{"price":"0.98","size":"8956.04"}],"hash":"449eaf6d1c4275d3d187ea1ebce2b6c608529606","timestamp":"1770839724761","event_type":"book","_sub_state":"active","_subscription_id":1,"_active_subscription_id":1},"parse_warnings":[],"out_of_order":false}
{"run_id":"29526913bab7446286864a321c124486","channel":"market","event_type":"price_change","market":"0x8032d8355d335c6ccbfc2508d99fbc87eb13f437bd275c93ee56fd1558e517ff","asset_id":null,"source":"market_ws:sub:active:1","t_event_ms":1770839724780,"t_recv_wall_ms":1770839724698,"t_recv_wall_iso":"2026-02-11T19:55:24.698Z","t_recv_mono_ns":618590038862916,"raw":{"market":"0x8032d8355d335c6ccbfc2508d99fbc87eb13f437bd275c93ee56fd1558e517ff","price_changes":[{"asset_id":"20773614133833886322101538939702011175545796528197617633926164254913649353392","price":"0.02","size":"8949.91","side":"BUY","hash":"0208b1f97183537ecf85f501a8b605d5212a04fe","best_bid":"0.02","best_ask":"0.03"},{"asset_id":"40652734036737240317526188612064032143639112324786051284480877037991580442979","price":"0.98","size":"8949.91","side":"SELL","hash":"d8ae179c3486740236bc2c9286e1679c246c7200","best_bid":"0.97","best_ask":"0.98"}],"timestamp":"1770839724780","event_type":"price_change","_sub_state":"active","_subscription_id":1,"_active_subscription_id":1},"parse_warnings":[],"out_of_order":false}
{"run_id":"29526913bab7446286864a321c124486","channel":"market","event_type":"book","market":"0x8032d8355d335c6ccbfc2508d99fbc87eb13f437bd275c93ee56fd1558e517ff","asset_id":"20773614133833886322101538939702011175545796528197617633926164254913649353392","source":"market_ws:sub:active:1","t_event_ms":1770839724780,"t_recv_wall_ms":1770839724698,"t_recv_wall_iso":"2026-02-11T19:55:24.698Z","t_recv_mono_ns":618590039372625,"raw":{"market":"0x8032d8355d335c6ccbfc2508d99fbc87eb13f437bd275c93ee56fd1558e517ff","asset_id":"20773614133833886322101538939702011175545796528197617633926164254913649353392","bids":[{"price":"0.01","size":"30859.91"},{"price":"0.02","size":"8949.91"}],"asks":[{"price":"0.99","size":"30822.26"},{"price":"0.98","size":"12559.04"},{"price":"0.97","size":"7433.03"},{"price":"0.96","size":"5453.8"},{"price":"0.95","size":"6815.8"},{"price":"0.94","size":"5105"},{"price":"0.93","size":"5421.38"},{"price":"0.92","size":"5139.4"},{"price":"0.91","size":"5225.8"},{"price":"0.9","size":"5102.8"},{"price":"0.89","size":"120.6"},{"price":"0.88","size":"63.6"},{"price":"0.87","size":"63"},{"price":"0.86","size":"61.6"},{"price":"0.85","size":"107.39"},{"price":"0.84","size":"69.39"},{"price":"0.83","size":"58.39"},{"price":"0.82","size":"66.71"},{"price":"0.81","size":"56.8"},{"price":"0.8","size":"92.14"},{"price":"0.79","size":"60.8"},{"price":"0.78","size":"55.2"},{"price":"0.77","size":"64.48"},{"price":"0.76","size":"54.2"},{"price":"0.75","size":"375.8"},{"price":"0.74","size":"68.6"},{"price":"0.73","size":"53.2"},{"price":"0.72","size":"63.26"},{"price":"0.71","size":"52.6"},{"price":"0.7","size":"402.4"},{"price":"0.69","size":"72.2"},{"price":"0.68","size":"87.88"},{"price":"0.67","size":"188.46"},{"price":"0.66","size":"123.6"},{"price":"0.65","size":"317.03"},{"price":"0.64","size":"582.36"},{"price":"0.63","size":"559.2"},{"price":"0.62","size":"559"},{"price":"0.61","size":"594"},{"price":"0.6","size":"2915.41"},{"price":"0.59","size":"576.8"},{"price":"0.58","size":"575.5"},{"price":"0.57","size":"558.6"},{"price":"0.56","size":"572.68"},{"price":"0.55","size":"566.4"},{"price":"0.54","size":"561.94"},{"price":"0.53","size":"631.57"},{"price":"0.52","size":"611.4"},{"price":"0.51","size":"705.2"},{"price":"0.5","size":"1011.55"},{"price":"0.49","size":"692.4"},{"price":"0.48","size":"628.4"},{"price":"0.47","size":"633.4"},{"price":"0.46","size":"711.65"},{"price":"0.45","size":"866.59"},{"price":"0.44","size":"905.69"},{"price":"0.43","size":"641.6"},{"price":"0.42","size":"645.58"},{"price":"0.41","size":"564"},{"price":"0.4","size":"20642.9"},{"price":"0.39","size":"650.23"},{"price":"0.38","size":"593"},{"price":"0.37","size":"755.73"},{"price":"0.36","size":"558"},{"price":"0.35","size":"1144.32"},{"price":"0.34","size":"649.59"},{"price":"0.33","size":"624.8"},{"price":"0.32","size":"574"},{"price":"0.31","size":"594.2"},{"price":"0.3","size":"735.66"},{"price":"0.29","size":"624.6"},{"price":"0.28","size":"356.8"},{"price":"0.27","size":"869.2"},{"price":"0.26","size":"967.6"},{"price":"0.25","size":"1673.8"},{"price":"0.24","size":"869.2"},{"price":"0.23","size":"864.6"},{"price":"0.22","size":"870.2"},{"price":"0.21","size":"891.6"},{"price":"0.2","size":"987.2"},{"price":"0.19","size":"876.8"},{"price":"0.18","size":"1091.55"},{"price":"0.17","size":"958.39"},{"price":"0.16","size":"1119.39"},{"price":"0.15","size":"1149.13"},{"price":"0.14","size":"962.6"},{"price":"0.13","size":"1041.8"},{"price":"0.12","size":"1060.55"},{"price":"0.11","size":"1124.49"},{"price":"0.1","size":"1306.79"},{"price":"0.09","size":"754.6"},{"price":"0.08","size":"3379.35"},{"price":"0.07","size":"3360.43"},{"price":"0.06","size":"3140.34"},{"price":"0.05","size":"3254.45"},{"price":"0.04","size":"3738.17"},{"price":"0.03","size":"641.4"}],"hash":"0208b1f97183537ecf85f501a8b605d5212a04fe","timestamp":"1770839724780","event_type":"book","_sub_state":"active","_subscription_id":1,"_active_subscription_id":1},"parse_warnings":[],"out_of_order":false}
{"run_id":"29526913bab7446286864a321c124486","channel":"market","event_type":"book","market":"0x8032d8355d335c6ccbfc2508d99fbc87eb13f437bd275c93ee56fd1558e517ff","asset_id":"40652734036737240317526188612064032143639112324786051284480877037991580442979","source":"market_ws:sub:active:1","t_event_ms":1770839724780,"t_recv_wall_ms":1770839724699,"t_recv_wall_iso":"2026-02-11T19:55:24.699Z","t_recv_mono_ns":618590039907000,"raw":{"market":"0x8032d8355d335c6ccbfc2508d99fbc87eb13f437bd275c93ee56fd1558e517ff","asset_id":"40652734036737240317526188612064032143639112324786051284480877037991580442979","bids":[{"price":"0.01","size":"30822.26"},{"price":"0.02","size":"12559.04"},{"price":"0.03","size":"7433.03"},{"price":"0.04","size":"5453.8"},{"price":"0.05","size":"6815.8"},{"price":"0.06","size":"5105"},{"price":"0.07","size":"5421.38"},{"price":"0.08","size":"5139.4"},{"price":"0.09","size":"5225.8"},{"price":"0.1","size":"5102.8"},{"price":"0.11","size":"120.6"},{"price":"0.12","size":"63.6"},{"price":"0.13","size":"63"},{"price":"0.14","size":"61.6"},{"price":"0.15","size":"107.39"},{"price":"0.16","size":"69.39"},{"price":"0.17","size":"58.39"},{"price":"0.18","size":"66.71"},{"price":"0.19","size":"56.8"},{"price":"0.2","size":"92.14"},{"price":"0.21","size":"60.8"},{"price":"0.22","size":"55.2"},{"price":"0.23","size":"64.48"},{"price":"0.24","size":"54.2"},{"price":"0.25","size":"375.8"},{"price":"0.26","size":"68.6"},{"price":"0.27","size":"53.2"},{"price":"0.28","size":"63.26"},{"price":"0.29","size":"52.6"},{"price":"0.3","size":"402.4"},{"price":"0.31","size":"72.2"},{"price":"0.32","size":"87.88"},{"price":"0.33","size":"188.46"},{"price":"0.34","size":"123.6"},{"price":"0.35","size":"317.03"},{"price":"0.36","size":"582.36"},{"price":"0.37","size":"559.2"},{"price":"0.38","size":"559"},{"price":"0.39","size":"594"},{"price":"0.4","size":"2915.41"},{"price":"0.41","size":"576.8"},{"price":"0.42","size":"575.5"},{"price":"0.43","size":"558.6"},{"price":"0.44","size":"572.68"},{"price":"0.45","size":"566.4"},{"price":"0.46","size":"561.94"},{"price":"0.47","size":"631.57"},{"price":"0.48","size":"611.4"},{"price":"0.49","size":"705.2"},{"price":"0.5","size":"1011.55"},{"price":"0.51","size":"692.4"},{"price":"0.52","size":"628.4"},{"price":"0.53","size":"633.4"},{"price":"0.54","size":"711.65"},{"price":"0.55","size":"866.59"},{"price":"0.56","size":"905.69"},{"price":"0.57","size":"641.6"},{"price":"0.58","size":"645.58"},{"price":"0.59","size":"564"},{"price":"0.6","size":"20642.9"},{"price":"0.61","size":"650.23"},{"price":"0.62","size":"593"},{"price":"0.63","size":"755.73"},{"price":"0.64","size":"558"},{"price":"0.65","size":"1144.32"},{"price":"0.66","size":"649.59"},{"price":"0.67","size":"624.8"},{"price":"0.68","size":"574"},{"price":"0.69","size":"594.2"},{"price":"0.7","size":"735.66"},{"price":"0.71","size":"624.6"},{"price":"0.72","size":"356.8"},{"price":"0.73","size":"869.2"},{"price":"0.74","size":"967.6"},{"price":"0.75","size":"1673.8"},{"price":"0.76","size":"869.2"},{"price":"0.77","size":"864.6"},{"price":"0.78","size":"870.2"},{"price":"0.79","size":"891.6"},{"price":"0.8","size":"987.2"},{"price":"0.81","size":"876.8"},{"price":"0.82","size":"1091.55"},{"price":"0.83","size":"958.39"},{"price":"0.84","size":"1119.39"},{"price":"0.85","size":"1149.13"},{"price":"0.86","size":"962.6"},{"price":"0.87","size":"1041.8"},{"price":"0.88","size":"1060.55"},{"price":"0.89","size":"1124.49"},{"price":"0.9","size":"1306.79"},{"price":"0.91","size":"754.6"},{"price":"0.92","size":"3379.35"},{"price":"0.93","size":"3360.43"},{"price":"0.94","size":"3140.34"},{"price":"0.95","size":"3254.45"},{"price":"0.96","size":"3738.17"},{"price":"0.97","size":"641.4"}],"asks":[{"price":"0.99","size":"30859.91"},{"price":"0.98","size":"8949.91"}],"hash":"d8ae179c3486740236bc2c9286e1679c246c7200","timestamp":"1770839724780","event_type":"book","_sub_state":"active","_subscription_id":1,"_active_subscription_id":1},"parse_warnings":[],"out_of_order":false}
{"run_id":"29526913bab7446286864a321c124486","channel":"market","event_type":"price_change","market":"0x8032d8355d335c6ccbfc2508d99fbc87eb13f437bd275c93ee56fd1558e517ff","asset_id":null,"source":"market_ws:sub:active:1","t_event_ms":1770839724784,"t_recv_wall_ms":1770839724699,"t_recv_wall_iso":"2026-02-11T19:55:24.699Z","t_recv_mono_ns":618590040273333,"raw":{"market":"0x8032d8355d335c6ccbfc2508d99fbc87eb13f437bd275c93ee56fd1558e517ff","price_changes":[{"asset_id":"20773614133833886322101538939702011175545796528197617633926164254913649353392","price":"0.02","size":"9009.91","side":"BUY","hash":"9741765229fadaf584dcda34eb859b988e83dfa6","best_bid":"0.02","best_ask":"0.03"},{"asset_id":"40652734036737240317526188612064032143639112324786051284480877037991580442979","price":"0.98","size":"9009.91","side":"SELL","hash":"f84a04bfc461a715c0269e7ef2af5496160830be","best_bid":"0.97","best_ask":"0.98"}],"timestamp":"1770839724784","event_type":"price_change","_sub_state":"active","_subscription_id":1,"_active_subscription_id":1},"parse_warnings":[],"out_of_order":false}
{"run_id":"29526913bab7446286864a321c124486","channel":"market","event_type":"price_change","market":"0x8032d8355d335c6ccbfc2508d99fbc87eb13f437bd275c93ee56fd1558e517ff","asset_id":null,"source":"market_ws:sub:active:1","t_event_ms":1770839724784,"t_recv_wall_ms":1770839724699,"t_recv_wall_iso":"2026-02-11T19:55:24.699Z","t_recv_mono_ns":618590040373375,"raw":{"market":"0x8032d8355d335c6ccbfc2508d99fbc87eb13f437bd275c93ee56fd1558e517ff","price_changes":[{"asset_id":"40652734036737240317526188612064032143639112324786051284480877037991580442979","price":"0.96","size":"3678.17","side":"BUY","hash":"01d5a2a0d7cf72533d234c6f384278a520385366","best_bid":"0.97","best_ask":"0.98"},{"asset_id":"20773614133833886322101538939702011175545796528197617633926164254913649353392","price":"0.04","size":"3678.17","side":"SELL","hash":"b450976595e641d79a2a04d9b4a4bc1fffe98cd2","best_bid":"0.02","best_ask":"0.03"}],"timestamp":"1770839724784","event_type":"price_change","_sub_state":"active","_subscription_id":1,"_active_subscription_id":1},"parse_warnings":[],"out_of_order":false}
{"run_id":"29526913bab7446286864a321c124486","channel":"market","event_type":"price_change","market":"0x8032d8355d335c6ccbfc2508d99fbc87eb13f437bd275c93ee56fd1558e517ff","asset_id":null,"source":"market_ws:sub:active:1","t_event_ms":1770839724787,"t_recv_wall_ms":1770839724699,"t_recv_wall_iso":"2026-02-11T19:55:24.699Z","t_recv_mono_ns":618590040469250,"raw":{"market":"0x8032d8355d335c6ccbfc2508d99fbc87eb13f437bd275c93ee56fd1558e517ff","price_changes":[{"asset_id":"40652734036737240317526188612064032143639112324786051284480877037991580442979","price":"0.91","size":"759.6","side":"BUY","hash":"bc31c4df5f10bac2116e34e00e7094b2e9840b9c","best_bid":"0.97","best_ask":"0.98"},{"asset_id":"20773614133833886322101538939702011175545796528197617633926164254913649353392","price":"0.09","size":"759.6","side":"SELL","hash":"73617eba4d773429077f5a17ad213ffcca782abc","best_bid":"0.02","best_ask":"0.03"}],"timestamp":"1770839724787","event_type":"price_change","_sub_state":"active","_subscription_id":1,"_active_subscription_id":1},"parse_warnings":[],"out_of_order":false}
{"run_id":"29526913bab7446286864a321c124486","channel":"market","event_type":"price_change","market":"0x8032d8355d335c6ccbfc2508d99fbc87eb13f437bd275c93ee56fd1558e517ff","asset_id":null,"source":"market_ws:sub:active:1","t_event_ms":1770839724789,"t_recv_wall_ms":1770839724699,"t_recv_wall_iso":"2026-02-11T19:55:24.699Z","t_recv_mono_ns":618590040557333,"raw":{"market":"0x8032d8355d335c6ccbfc2508d99fbc87eb13f437bd275c93ee56fd1558e517ff","price_changes":[{"asset_id":"20773614133833886322101538939702011175545796528197617633926164254913649353392","price":"0.01","size":"30799.91","side":"BUY","hash":"6b8a13f0847f7ef8943670d5eca6c10276dd08a7","best_bid":"0.02","best_ask":"0.03"},{"asset_id":"40652734036737240317526188612064032143639112324786051284480877037991580442979","price":"0.99","size":"30799.91","side":"SELL","hash":"a094e90d97b4616d4de2292b12b39fd8d7e703c2","best_bid":"0.97","best_ask":"0.98"}],"timestamp":"1770839724789","event_type":"price_change","_sub_state":"active","_subscription_id":1,"_active_subscription_id":1},"parse_warnings":[],"out_of_order":false}
{"run_id":"29526913bab7446286864a321c124486","channel":"market","event_type":"price_change","market":"0x8032d8355d335c6ccbfc2508d99fbc87eb13f437bd275c93ee56fd1558e517ff","asset_id":null,"source":"market_ws:sub:active:1","t_event_ms":1770839724790,"t_recv_wall_ms":1770839724699,"t_recv_wall_iso":"2026-02-11T19:55:24.699Z","t_recv_mono_ns":618590040649875,"raw":{"market":"0x8032d8355d335c6ccbfc2508d99fbc87eb13f437bd275c93ee56fd1558e517ff","price_changes":[{"asset_id":"40652734036737240317526188612064032143639112324786051284480877037991580442979","price":"0.98","size":"9014.91","side":"SELL","hash":"f4dcdcfda741837198ebd38abd2e4b19e2ee4278","best_bid":"0.97","best_ask":"0.98"},{"asset_id":"20773614133833886322101538939702011175545796528197617633926164254913649353392","price":"0.02","size":"9014.91","side":"BUY","hash":"b5a95039a6dacec85f9739aa1a9bd6ded3354898","best_bid":"0.02","best_ask":"0.03"}],"timestamp":"1770839724790","event_type":"price_change","_sub_state":"active","_subscription_id":1,"_active_subscription_id":1},"parse_warnings":[],"out_of_order":false}
{"run_id":"29526913bab7446286864a321c124486","channel":"market","event_type":"price_change","market":"0x8032d8355d335c6ccbfc2508d99fbc87eb13f437bd275c93ee56fd1558e517ff","asset_id":null,"source":"market_ws:sub:active:1","t_event_ms":1770839724792,"t_recv_wall_ms":1770839724710,"t_recv_wall_iso":"2026-02-11T19:55:24.710Z","t_recv_mono_ns":618590050937666,"raw":{"market":"0x8032d8355d335c6ccbfc2508d99fbc87eb13f437bd275c93ee56fd1558e517ff","price_changes":[{"asset_id":"40652734036737240317526188612064032143639112324786051284480877037991580442979","price":"0.95","size":"3314.45","side":"BUY","hash":"8314a86144c107861ce4e4cac30429314c188b94","best_bid":"0.97","best_ask":"0.98"},{"asset_id":"20773614133833886322101538939702011175545796528197617633926164254913649353392","price":"0.05","size":"3314.45","side":"SELL","hash":"a3fb8a9806fd0ab2e2cf689b360b2c818dc9ceb1","best_bid":"0.02","best_ask":"0.03"}],"timestamp":"1770839724792","event_type":"price_change","_sub_state":"active","_subscription_id":1,"_active_subscription_id":1},"parse_warnings":[],"out_of_order":false}
{"run_id":"29526913bab7446286864a321c124486","channel":"market","event_type":"last_trade_price","market":"0x8032d8355d335c6ccbfc2508d99fbc87eb13f437bd275c93ee56fd1558e517ff","asset_id":"40652734036737240317526188612064032143639112324786051284480877037991580442979","source":"market_ws:sub:unknown","t_event_ms":1770839724795,"t_recv_wall_ms":1770839724710,"t_recv_wall_iso":"2026-02-11T19:55:24.710Z","t_recv_mono_ns":618590051198541,"raw":{"market":"0x8032d8355d335c6ccbfc2508d99fbc87eb13f437bd275c93ee56fd1558e517ff","asset_id":"40652734036737240317526188612064032143639112324786051284480877037991580442979","price":"0.98","size":"10.21","fee_rate_bps":"1000","side":"BUY","timestamp":"1770839724795","event_type":"last_trade_price","transaction_hash":"0x68fd5cc7b85bba74f4634324ea482be501d60442fc2439a93d0e663fda3e556a","_sub_state":"unknown","_subscription_id":null,"_active_subscription_id":1},"parse_warnings":["unknown_message_schema"],"out_of_order":false}
{"run_id":"29526913bab7446286864a321c124486","channel":"market","event_type":"last_trade_price","market":"0x8032d8355d335c6ccbfc2508d99fbc87eb13f437bd275c93ee56fd1558e517ff","asset_id":"40652734036737240317526188612064032143639112324786051284480877037991580442979","source":"market_ws:sub:unknown","t_event_ms":1770839724810,"t_recv_wall_ms":1770839724717,"t_recv_wall_iso":"2026-02-11T19:55:24.717Z","t_recv_mono_ns":618590058253208,"raw":{"market":"0x8032d8355d335c6ccbfc2508d99fbc87eb13f437bd275c93ee56fd1558e517ff","asset_id":"40652734036737240317526188612064032143639112324786051284480877037991580442979","price":"0.98","size":"6.13","fee_rate_bps":"1000","side":"BUY","timestamp":"1770839724810","event_type":"last_trade_price","transaction_hash":"0x456bee4525460dd8d4cee1e48d9a5cc79cb069a18644ea4a7b51b91e280d56f2","_sub_state":"unknown","_subscription_id":null,"_active_subscription_id":1},"parse_warnings":["unknown_message_schema"],"out_of_order":false}
{"run_id":"29526913bab7446286864a321c124486","channel":"market","event_type":"price_change","market":"0x8032d8355d335c6ccbfc2508d99fbc87eb13f437bd275c93ee56fd1558e517ff","asset_id":null,"source":"market_ws:sub:active:1","t_event_ms":1770839724808,"t_recv_wall_ms":1770839724717,"t_recv_wall_iso":"2026-02-11T19:55:24.717Z","t_recv_mono_ns":618590058471750,"raw":{"market":"0x8032d8355d335c6ccbfc2508d99fbc87eb13f437bd275c93ee56fd1558e517ff","price_changes":[{"asset_id":"20773614133833886322101538939702011175545796528197617633926164254913649353392","price":"0.02","size":"9010.82","side":"BUY","hash":"8d9c9ab42331116875523aaf811dbeafdfa6bd25","best_bid":"0.02","best_ask":"0.03"},{"asset_id":"40652734036737240317526188612064032143639112324786051284480877037991580442979","price":"0.98","size":"9010.82","side":"SELL","hash":"629def7201a9b3e0b5593385761b93cdcefd73ce","best_bid":"0.97","best_ask":"0.98"}],"timestamp":"1770839724808","event_type":"price_change","_sub_state":"active","_subscription_id":1,"_active_subscription_id":1},"parse_warnings":[],"out_of_order":false}
{"run_id":"29526913bab7446286864a321c124486","channel":"market","event_type":"book","market":"0x8032d8355d335c6ccbfc2508d99fbc87eb13f437bd275c93ee56fd1558e517ff","asset_id":"20773614133833886322101538939702011175545796528197617633926164254913649353392","source":"market_ws:sub:active:1","t_event_ms":1770839724808,"t_recv_wall_ms":1770839724727,"t_recv_wall_iso":"2026-02-11T19:55:24.727Z","t_recv_mono_ns":618590068561250,"raw":{"market":"0x8032d8355d335c6ccbfc2508d99fbc87eb13f437bd275c93ee56fd1558e517ff","asset_id":"20773614133833886322101538939702011175545796528197617633926164254913649353392","bids":[{"price":"0.01","size":"30799.91"},{"price":"0.02","size":"9010.82"}],"asks":[{"price":"0.99","size":"30822.26"},{"price":"0.98","size":"12559.04"},{"price":"0.97","size":"7433.03"},{"price":"0.96","size":"5453.8"},{"price":"0.95","size":"6815.8"},{"price":"0.94","size":"5105"},{"price":"0.93","size":"5421.38"},{"price":"0.92","size":"5139.4"},{"price":"0.91","size":"5225.8"},{"price":"0.9","size":"5102.8"},{"price":"0.89","size":"120.6"},{"price":"0.88","size":"63.6"},{"price":"0.87","size":"63"},{"price":"0.86","size":"61.6"},{"price":"0.85","size":"107.39"},{"price":"0.84","size":"69.39"},{"price":"0.83","size":"58.39"},{"price":"0.82","size":"66.71"},{"price":"0.81","size":"56.8"},{"price":"0.8","size":"92.14"},{"price":"0.79","size":"60.8"},{"price":"0.78","size":"55.2"},{"price":"0.77","size":"64.48"},{"price":"0.76","size":"54.2"},{"price":"0.75","size":"375.8"},{"price":"0.74","size":"68.6"},{"price":"0.73","size":"53.2"},{"price":"0.72","size":"63.26"},{"price":"0.71","size":"52.6"},{"price":"0.7","size":"402.4"},{"price":"0.69","size":"72.2"},{"price":"0.68","size":"87.88"},{"price":"0.67","size":"188.46"},{"price":"0.66","size":"123.6"},{"price":"0.65","size":"317.03"},{"price":"0.64","size":"582.36"},{"price":"0.63","size":"559.2"},{"price":"0.62","size":"559"},{"price":"0.61","size":"594"},{"price":"0.6","size":"2915.41"},{"price":"0.59","size":"576.8"},{"price":"0.58","size":"575.5"},{"price":"0.57","size":"558.6"},{"price":"0.56","size":"572.68"},{"price":"0.55","size":"566.4"},{"price":"0.54","size":"561.94"},{"price":"0.53","size":"631.57"},{"price":"0.52","size":"611.4"},{"price":"0.51","size":"705.2"},{"price":"0.5","size":"1011.55"},{"price":"0.49","size":"692.4"},{"price":"0.48","size":"628.4"},{"price":"0.47","size":"633.4"},{"price":"0.46","size":"711.65"},{"price":"0.45","size":"866.59"},{"price":"0.44","size":"905.69"},{"price":"0.43","size":"641.6"},{"price":"0.42","size":"645.58"},{"price":"0.41","size":"564"},{"price":"0.4","size":"20642.9"},{"price":"0.39","size":"650.23"},{"price":"0.38","size":"593"},{"price":"0.37","size":"755.73"},{"price":"0.36","size":"558"},{"price":"0.35","size":"1144.32"},{"price":"0.34","size":"649.59"},{"price":"0.33","size":"624.8"},{"price":"0.32","size":"574"},{"price":"0.31","size":"594.2"},{"price":"0.3","size":"735.66"},{"price":"0.29","size":"624.6"},{"price":"0.28","size":"356.8"},{"price":"0.27","size":"869.2"},{"price":"0.26","size":"967.6"},{"price":"0.25","size":"1673.8"},{"price":"0.24","size":"869.2"},{"price":"0.23","size":"864.6"},{"price":"0.22","size":"870.2"},{"price":"0.21","size":"891.6"},{"price":"0.2","size":"987.2"},{"price":"0.19","size":"876.8"},{"price":"0.18","size":"1091.55"},{"price":"0.17","size":"958.39"},{"price":"0.16","size":"1119.39"},{"price":"0.15","size":"1149.13"},{"price":"0.14","size":"962.6"},{"price":"0.13","size":"1041.8"},{"price":"0.12","size":"1060.55"},{"price":"0.11","size":"1124.49"},{"price":"0.1","size":"1306.79"},{"price":"0.09","size":"759.6"},{"price":"0.08","size":"3379.35"},{"price":"0.07","size":"3360.43"},{"price":"0.06","size":"3140.34"},{"price":"0.05","size":"3314.45"},{"price":"0.04","size":"3678.17"},{"price":"0.03","size":"641.4"}],"hash":"8d9c9ab42331116875523aaf811dbeafdfa6bd25","timestamp":"1770839724808","event_type":"book","_sub_state":"active","_subscription_id":1,"_active_subscription_id":1},"parse_warnings":[],"out_of_order":false}
{"run_id":"29526913bab7446286864a321c124486","channel":"market","event_type":"book","market":"0x8032d8355d335c6ccbfc2508d99fbc87eb13f437bd275c93ee56fd1558e517ff","asset_id":"40652734036737240317526188612064032143639112324786051284480877037991580442979","source":"market_ws:sub:active:1","t_event_ms":1770839724808,"t_recv_wall_ms":1770839724728,"t_recv_wall_iso":"2026-02-11T19:55:24.728Z","t_recv_mono_ns":618590069552125,"raw":{"market":"0x8032d8355d335c6ccbfc2508d99fbc87eb13f437bd275c93ee56fd1558e517ff","asset_id":"40652734036737240317526188612064032143639112324786051284480877037991580442979","bids":[{"price":"0.01","size":"30822.26"},{"price":"0.02","size":"12559.04"},{"price":"0.03","size":"7433.03"},{"price":"0.04","size":"5453.8"},{"price":"0.05","size":"6815.8"},{"price":"0.06","size":"5105"},{"price":"0.07","size":"5421.38"},{"price":"0.08","size":"5139.4"},{"price":"0.09","size":"5225.8"},{"price":"0.1","size":"5102.8"},{"price":"0.11","size":"120.6"},{"price":"0.12","size":"63.6"},{"price":"0.13","size":"63"},{"price":"0.14","size":"61.6"},{"price":"0.15","size":"107.39"},{"price":"0.16","size":"69.39"},{"price":"0.17","size":"58.39"},{"price":"0.18","size":"66.71"},{"price":"0.19","size":"56.8"},{"price":"0.2","size":"92.14"},{"price":"0.21","size":"60.8"},{"price":"0.22","size":"55.2"},{"price":"0.23","size":"64.48"},{"price":"0.24","size":"54.2"},{"price":"0.25","size":"375.8"},{"price":"0.26","size":"68.6"},{"price":"0.27","size":"53.2"},{"price":"0.28","size":"63.26"},{"price":"0.29","size":"52.6"},{"price":"0.3","size":"402.4"},{"price":"0.31","size":"72.2"},{"price":"0.32","size":"87.88"},{"price":"0.33","size":"188.46"},{"price":"0.34","size":"123.6"},{"price":"0.35","size":"317.03"},{"price":"0.36","size":"582.36"},{"price":"0.37","size":"559.2"},{"price":"0.38","size":"559"},{"price":"0.39","size":"594"},{"price":"0.4","size":"2915.41"},{"price":"0.41","size":"576.8"},{"price":"0.42","size":"575.5"},{"price":"0.43","size":"558.6"},{"price":"0.44","size":"572.68"},{"price":"0.45","size":"566.4"},{"price":"0.46","size":"561.94"},{"price":"0.47","size":"631.57"},{"price":"0.48","size":"611.4"},{"price":"0.49","size":"705.2"},{"price":"0.5","size":"1011.55"},{"price":"0.51","size":"692.4"},{"price":"0.52","size":"628.4"},{"price":"0.53","size":"633.4"},{"price":"0.54","size":"711.65"},{"price":"0.55","size":"866.59"},{"price":"0.56","size":"905.69"},{"price":"0.57","size":"641.6"},{"price":"0.58","size":"645.58"},{"price":"0.59","size":"564"},{"price":"0.6","size":"20642.9"},{"price":"0.61","size":"650.23"},{"price":"0.62","size":"593"},{"price":"0.63","size":"755.73"},{"price":"0.64","size":"558"},{"price":"0.65","size":"1144.32"},{"price":"0.66","size":"649.59"},{"price":"0.67","size":"624.8"},{"price":"0.68","size":"574"},{"price":"0.69","size":"594.2"},{"price":"0.7","size":"735.66"},{"price":"0.71","size":"624.6"},{"price":"0.72","size":"356.8"},{"price":"0.73","size":"869.2"},{"price":"0.74","size":"967.6"},{"price":"0.75","size":"1673.8"},{"price":"0.76","size":"869.2"},{"price":"0.77","size":"864.6"},{"price":"0.78","size":"870.2"},{"price":"0.79","size":"891.6"},{"price":"0.8","size":"987.2"},{"price":"0.81","size":"876.8"},{"price":"0.82","size":"1091.55"},{"price":"0.83","size":"958.39"},{"price":"0.84","size":"1119.39"},{"price":"0.85","size":"1149.13"},{"price":"0.86","size":"962.6"},{"price":"0.87","size":"1041.8"},{"price":"0.88","size":"1060.55"},{"price":"0.89","size":"1124.49"},{"price":"0.9","size":"1306.79"},{"price":"0.91","size":"759.6"},{"price":"0.92","size":"3379.35"},{"price":"0.93","size":"3360.43"},{"price":"0.94","size":"3140.34"},{"price":"0.95","size":"3314.45"},{"price":"0.96","size":"3678.17"},{"price":"0.97","size":"641.4"}],"asks":[{"price":"0.99","size":"30799.91"},{"price":"0.98","size":"9010.82"}],"hash":"629def7201a9b3e0b5593385761b93cdcefd73ce","timestamp":"1770839724808","event_type":"book","_sub_state":"active","_subscription_id":1,"_active_subscription_id":1},"parse_warnings":[],"out_of_order":false}
{"run_id":"29526913bab7446286864a321c124486","channel":"market","event_type":"price_change","market":"0x8032d8355d335c6ccbfc2508d99fbc87eb13f437bd275c93ee56fd1558e517ff","asset_id":null,"source":"market_ws:sub:active:1","t_event_ms":1770839724826,"t_recv_wall_ms":1770839724737,"t_recv_wall_iso":"2026-02-11T19:55:24.737Z","t_recv_mono_ns":618590078174166,"raw":{"market":"0x8032d8355d335c6ccbfc2508d99fbc87eb13f437bd275c93ee56fd1558e517ff","price_changes":[{"asset_id":"20773614133833886322101538939702011175545796528197617633926164254913649353392","price":"0.02","size":"9006.73","side":"BUY","hash":"7f204298602bef27eb0a3b1868b72468385c82c4","best_bid":"0.02","best_ask":"0.03"},{"asset_id":"40652734036737240317526188612064032143639112324786051284480877037991580442979","price":"0.98","size":"9006.73","side":"SELL","hash":"676b97d0a62c04bca11e2d1ece96a0ebe76036f9","best_bid":"0.97","best_ask":"0.98"}],"timestamp":"1770839724826","event_type":"price_change","_sub_state":"active","_subscription_id":1,"_active_subscription_id":1},"parse_warnings":[],"out_of_order":false}
{"run_id":"29526913bab7446286864a321c124486","channel":"market","event_type":"book","market":"0x8032d8355d335c6ccbfc2508d99fbc87eb13f437bd275c93ee56fd1558e517ff","asset_id":"20773614133833886322101538939702011175545796528197617633926164254913649353392","source":"market_ws:sub:active:1","t_event_ms":1770839724826,"t_recv_wall_ms":1770839724737,"t_recv_wall_iso":"2026-02-11T19:55:24.737Z","t_recv_mono_ns":618590078478166,"raw":{"market":"0x8032d8355d335c6ccbfc2508d99fbc87eb13f437bd275c93ee56fd1558e517ff","asset_id":"20773614133833886322101538939702011175545796528197617633926164254913649353392","bids":[{"price":"0.01","size":"30799.91"},{"price":"0.02","size":"9006.73"}],"asks":[{"price":"0.99","size":"30822.26"},{"price":"0.98","size":"12559.04"},{"price":"0.97","size":"7433.03"},{"price":"0.96","size":"5453.8"},{"price":"0.95","size":"6815.8"},{"price":"0.94","size":"5105"},{"price":"0.93","size":"5421.38"},{"price":"0.92","size":"5139.4"},{"price":"0.91","size":"5225.8"},{"price":"0.9","size":"5102.8"},{"price":"0.89","size":"120.6"},{"price":"0.88","size":"63.6"},{"price":"0.87","size":"63"},{"price":"0.86","size":"61.6"},{"price":"0.85","size":"107.39"},{"price":"0.84","size":"69.39"},{"price":"0.83","size":"58.39"},{"price":"0.82","size":"66.71"},{"price":"0.81","size":"56.8"},{"price":"0.8","size":"92.14"},{"price":"0.79","size":"60.8"},{"price":"0.78","size":"55.2"},{"price":"0.77","size":"64.48"},{"price":"0.76","size":"54.2"},{"price":"0.75","size":"375.8"},{"price":"0.74","size":"68.6"},{"price":"0.73","size":"53.2"},{"price":"0.72","size":"63.26"},{"price":"0.71","size":"52.6"},{"price":"0.7","size":"402.4"},{"price":"0.69","size":"72.2"},{"price":"0.68","size":"87.88"},{"price":"0.67","size":"188.46"},{"price":"0.66","size":"123.6"},{"price":"0.65","size":"317.03"},{"price":"0.64","size":"582.36"},{"price":"0.63","size":"559.2"},{"price":"0.62","size":"559"},{"price":"0.61","size":"594"},{"price":"0.6","size":"2915.41"},{"price":"0.59","size":"576.8"},{"price":"0.58","size":"575.5"},{"price":"0.57","size":"558.6"},{"price":"0.56","size":"572.68"},{"price":"0.55","size":"566.4"},{"price":"0.54","size":"561.94"},{"price":"0.53","size":"631.57"},{"price":"0.52","size":"611.4"},{"price":"0.51","size":"705.2"},{"price":"0.5","size":"1011.55"},{"price":"0.49","size":"692.4"},{"price":"0.48","size":"628.4"},{"price":"0.47","size":"633.4"},{"price":"0.46","size":"711.65"},{"price":"0.45","size":"866.59"},{"price":"0.44","size":"905.69"},{"price":"0.43","size":"641.6"},{"price":"0.42","size":"645.58"},{"price":"0.41","size":"564"},{"price":"0.4","size":"20642.9"},{"price":"0.39","size":"650.23"},{"price":"0.38","size":"593"},{"price":"0.37","size":"755.73"},{"price":"0.36","size":"558"},{"price":"0.35","size":"1144.32"},{"price":"0.34","size":"649.59"},{"price":"0.33","size":"624.8"},{"price":"0.32","size":"574"},{"price":"0.31","size":"594.2"},{"price":"0.3","size":"735.66"},{"price":"0.29","size":"624.6"},{"price":"0.28","size":"356.8"},{"price":"0.27","size":"869.2"},{"price":"0.26","size":"967.6"},{"price":"0.25","size":"1673.8"},{"price":"0.24","size":"869.2"},{"price":"0.23","size":"864.6"},{"price":"0.22","size":"870.2"},{"price":"0.21","size":"891.6"},{"price":"0.2","size":"987.2"},{"price":"0.19","size":"876.8"},{"price":"0.18","size":"1091.55"},{"price":"0.17","size":"958.39"},{"price":"0.16","size":"1119.39"},{"price":"0.15","size":"1149.13"},{"price":"0.14","size":"962.6"},{"price":"0.13","size":"1041.8"},{"price":"0.12","size":"1060.55"},{"price":"0.11","size":"1124.49"},{"price":"0.1","size":"1306.79"},{"price":"0.09","size":"759.6"},{"price":"0.08","size":"3379.35"},{"price":"0.07","size":"3360.43"},{"price":"0.06","size":"3140.34"},{"price":"0.05","size":"3314.45"},{"price":"0.04","size":"3678.17"},{"price":"0.03","size":"641.4"}],"hash":"7f204298602bef27eb0a3b1868b72468385c82c4","timestamp":"1770839724826","event_type":"book","_sub_state":"active","_subscription_id":1,"_active_subscription_id":1},"parse_warnings":[],"out_of_order":false}
{"run_id":"29526913bab7446286864a321c124486","channel":"market","event_type":"book","market":"0x8032d8355d335c6ccbfc2508d99fbc87eb13f437bd275c93ee56fd1558e517ff","asset_id":"40652734036737240317526188612064032143639112324786051284480877037991580442979","source":"market_ws:sub:active:1","t_event_ms":1770839724826,"t_recv_wall_ms":1770839724738,"t_recv_wall_iso":"2026-02-11T19:55:24.738Z","t_recv_mono_ns":618590078999375,"raw":{"market":"0x8032d8355d335c6ccbfc2508d99fbc87eb13f437bd275c93ee56fd1558e517ff","asset_id":"40652734036737240317526188612064032143639112324786051284480877037991580442979","bids":[{"price":"0.01","size":"30822.26"},{"price":"0.02","size":"12559.04"},{"price":"0.03","size":"7433.03"},{"price":"0.04","size":"5453.8"},{"price":"0.05","size":"6815.8"},{"price":"0.06","size":"5105"},{"price":"0.07","size":"5421.38"},{"price":"0.08","size":"5139.4"},{"price":"0.09","size":"5225.8"},{"price":"0.1","size":"5102.8"},{"price":"0.11","size":"120.6"},{"price":"0.12","size":"63.6"},{"price":"0.13","size":"63"},{"price":"0.14","size":"61.6"},{"price":"0.15","size":"107.39"},{"price":"0.16","size":"69.39"},{"price":"0.17","size":"58.39"},{"price":"0.18","size":"66.71"},{"price":"0.19","size":"56.8"},{"price":"0.2","size":"92.14"},{"price":"0.21","size":"60.8"},{"price":"0.22","size":"55.2"},{"price":"0.23","size":"64.48"},{"price":"0.24","size":"54.2"},{"price":"0.25","size":"375.8"},{"price":"0.26","size":"68.6"},{"price":"0.27","size":"53.2"},{"price":"0.28","size":"63.26"},{"price":"0.29","size":"52.6"},{"price":"0.3","size":"402.4"},{"price":"0.31","size":"72.2"},{"price":"0.32","size":"87.88"},{"price":"0.33","size":"188.46"},{"price":"0.34","size":"123.6"},{"price":"0.35","size":"317.03"},{"price":"0.36","size":"582.36"},{"price":"0.37","size":"559.2"},{"price":"0.38","size":"559"},{"price":"0.39","size":"594"},{"price":"0.4","size":"2915.41"},{"price":"0.41","size":"576.8"},{"price":"0.42","size":"575.5"},{"price":"0.43","size":"558.6"},{"price":"0.44","size":"572.68"},{"price":"0.45","size":"566.4"},{"price":"0.46","size":"561.94"},{"price":"0.47","size":"631.57"},{"price":"0.48","size":"611.4"},{"price":"0.49","size":"705.2"},{"price":"0.5","size":"1011.55"},{"price":"0.51","size":"692.4"},{"price":"0.52","size":"628.4"},{"price":"0.53","size":"633.4"},{"price":"0.54","size":"711.65"},{"price":"0.55","size":"866.59"},{"price":"0.56","size":"905.69"},{"price":"0.57","size":"641.6"},{"price":"0.58","size":"645.58"},{"price":"0.59","size":"564"},{"price":"0.6","size":"20642.9"},{"price":"0.61","size":"650.23"},{"price":"0.62","size":"593"},{"price":"0.63","size":"755.73"},{"price":"0.64","size":"558"},{"price":"0.65","size":"1144.32"},{"price":"0.66","size":"649.59"},{"price":"0.67","size":"624.8"},{"price":"0.68","size":"574"},{"price":"0.69","size":"594.2"},{"price":"0.7","size":"735.66"},{"price":"0.71","size":"624.6"},{"price":"0.72","size":"356.8"},{"price":"0.73","size":"869.2"},{"price":"0.74","size":"967.6"},{"price":"0.75","size":"1673.8"},{"price":"0.76","size":"869.2"},{"price":"0.77","size":"864.6"},{"price":"0.78","size":"870.2"},{"price":"0.79","size":"891.6"},{"price":"0.8","size":"987.2"},{"price":"0.81","size":"876.8"},{"price":"0.82","size":"1091.55"},{"price":"0.83","size":"958.39"},{"price":"0.84","size":"1119.39"},{"price":"0.85","size":"1149.13"},{"price":"0.86","size":"962.6"},{"price":"0.87","size":"1041.8"},{"price":"0.88","size":"1060.55"},{"price":"0.89","size":"1124.49"},{"price":"0.9","size":"1306.79"},{"price":"0.91","size":"759.6"},{"price":"0.92","size":"3379.35"},{"price":"0.93","size":"3360.43"},{"price":"0.94","size":"3140.34"},{"price":"0.95","size":"3314.45"},{"price":"0.96","size":"3678.17"},{"price":"0.97","size":"641.4"}],"asks":[{"price":"0.99","size":"30799.91"},{"price":"0.98","size":"9006.73"}],"hash":"676b97d0a62c04bca11e2d1ece96a0ebe76036f9","timestamp":"1770839724826","event_type":"book","_sub_state":"active","_subscription_id":1,"_active_subscription_id":1},"parse_warnings":[],"out_of_order":false}
{"run_id":"29526913bab7446286864a321c124486","channel":"market","event_type":"price_change","market":"0x8032d8355d335c6ccbfc2508d99fbc87eb13f437bd275c93ee56fd1558e517ff","asset_id":null,"source":"market_ws:sub:active:1","t_event_ms":1770839724830,"t_recv_wall_ms":1770839724738,"t_recv_wall_iso":"2026-02-11T19:55:24.738Z","t_recv_mono_ns":618590079452416,"raw":{"market":"0x8032d8355d335c6ccbfc2508d99fbc87eb13f437bd275c93ee56fd1558e517ff","price_changes":[{"asset_id":"40652734036737240317526188612064032143639112324786051284480877037991580442979","price":"0.82","size":"1096.55","side":"BUY","hash":"f858ab8fe2bf7661d431114a59790c8c0e070d55","best_bid":"0.97","best_ask":"0.98"},{"asset_id":"20773614133833886322101538939702011175545796528197617633926164254913649353392","price":"0.18","size":"1096.55","side":"SELL","hash":"8734da22421ffea4459c9f972697972201c79b33","best_bid":"0.02","best_ask":"0.03"}],"timestamp":"1770839724830","event_type":"price_change","_sub_state":"active","_subscription_id":1,"_active_subscription_id":1},"parse_warnings":[],"out_of_order":false}
{"run_id":"29526913bab7446286864a321c124486","channel":"market","event_type":"last_trade_price","market":"0x8032d8355d335c6ccbfc2508d99fbc87eb13f437bd275c93ee56fd1558e517ff","asset_id":"40652734036737240317526188612064032143639112324786051284480877037991580442979","source":"market_ws:sub:unknown","t_event_ms":1770839724840,"t_recv_wall_ms":1770839724753,"t_recv_wall_iso":"2026-02-11T19:55:24.753Z","t_recv_mono_ns":618590093860250,"raw":{"market":"0x8032d8355d335c6ccbfc2508d99fbc87eb13f437bd275c93ee56fd1558e517ff","asset_id":"40652734036737240317526188612064032143639112324786051284480877037991580442979","price":"0.98","size":"4.09","fee_rate_bps":"1000","side":"BUY","timestamp":"1770839724840","event_type":"last_trade_price","transaction_hash":"0x555a8594c19603564c013751bf1d5c0a4cc8609e3aa699db5a321fe251d454ff","_sub_state":"unknown","_subscription_id":null,"_active_subscription_id":1},"parse_warnings":["unknown_message_schema"],"out_of_order":false}
{"run_id":"29526913bab7446286864a321c124486","channel":"market","event_type":"price_change","market":"0x8032d8355d335c6ccbfc2508d99fbc87eb13f437bd275c93ee56fd1558e517ff","asset_id":null,"source":"market_ws:sub:active:1","t_event_ms":1770839724848,"t_recv_wall_ms":1770839724759,"t_recv_wall_iso":"2026-02-11T19:55:24.759Z","t_recv_mono_ns":618590099962208,"raw":{"market":"0x8032d8355d335c6ccbfc2508d99fbc87eb13f437bd275c93ee56fd1558e517ff","price_changes":[{"asset_id":"20773614133833886322101538939702011175545796528197617633926164254913649353392","price":"0.02","size":"8996.52","side":"BUY","hash":"6161751622ac0003182015072f6c603c12c3e781","best_bid":"0.02","best_ask":"0.03"},{"asset_id":"40652734036737240317526188612064032143639112324786051284480877037991580442979","price":"0.98","size":"8996.52","side":"SELL","hash":"d7d03fe12385bcae855620985fa373fb70469d36","best_bid":"0.97","best_ask":"0.98"}],"timestamp":"1770839724848","event_type":"price_change","_sub_state":"active","_subscription_id":1,"_active_subscription_id":1},"parse_warnings":[],"out_of_order":false}
{"run_id":"29526913bab7446286864a321c124486","channel":"market","event_type":"book","market":"0x8032d8355d335c6ccbfc2508d99fbc87eb13f437bd275c93ee56fd1558e517ff","asset_id":"20773614133833886322101538939702011175545796528197617633926164254913649353392","source":"market_ws:sub:active:1","t_event_ms":1770839724848,"t_recv_wall_ms":1770839724759,"t_recv_wall_iso":"2026-02-11T19:55:24.759Z","t_recv_mono_ns":618590100323375,"raw":{"market":"0x8032d8355d335c6ccbfc2508d99fbc87eb13f437bd275c93ee56fd1558e517ff","asset_id":"20773614133833886322101538939702011175545796528197617633926164254913649353392","bids":[{"price":"0.01","size":"30799.91"},{"price":"0.02","size":"8996.52"}],"asks":[{"price":"0.99","size":"30822.26"},{"price":"0.98","size":"12559.04"},{"price":"0.97","size":"7433.03"},{"price":"0.96","size":"5453.8"},{"price":"0.95","size":"6815.8"},{"price":"0.94","size":"5105"},{"price":"0.93","size":"5421.38"},{"price":"0.92","size":"5139.4"},{"price":"0.91","size":"5225.8"},{"price":"0.9","size":"5102.8"},{"price":"0.89","size":"120.6"},{"price":"0.88","size":"63.6"},{"price":"0.87","size":"63"},{"price":"0.86","size":"61.6"},{"price":"0.85","size":"107.39"},{"price":"0.84","size":"69.39"},{"price":"0.83","size":"58.39"},{"price":"0.82","size":"66.71"},{"price":"0.81","size":"56.8"},{"price":"0.8","size":"92.14"},{"price":"0.79","size":"60.8"},{"price":"0.78","size":"55.2"},{"price":"0.77","size":"64.48"},{"price":"0.76","size":"54.2"},{"price":"0.75","size":"375.8"},{"price":"0.74","size":"68.6"},{"price":"0.73","size":"53.2"},{"price":"0.72","size":"63.26"},{"price":"0.71","size":"52.6"},{"price":"0.7","size":"402.4"},{"price":"0.69","size":"72.2"},{"price":"0.68","size":"87.88"},{"price":"0.67","size":"188.46"},{"price":"0.66","size":"123.6"},{"price":"0.65","size":"317.03"},{"price":"0.64","size":"582.36"},{"price":"0.63","size":"559.2"},{"price":"0.62","size":"559"},{"price":"0.61","size":"594"},{"price":"0.6","size":"2915.41"},{"price":"0.59","size":"576.8"},{"price":"0.58","size":"575.5"},{"price":"0.57","size":"558.6"},{"price":"0.56","size":"572.68"},{"price":"0.55","size":"566.4"},{"price":"0.54","size":"561.94"},{"price":"0.53","size":"631.57"},{"price":"0.52","size":"611.4"},{"price":"0.51","size":"705.2"},{"price":"0.5","size":"1011.55"},{"price":"0.49","size":"692.4"},{"price":"0.48","size":"628.4"},{"price":"0.47","size":"633.4"},{"price":"0.46","size":"711.65"},{"price":"0.45","size":"866.59"},{"price":"0.44","size":"905.69"},{"price":"0.43","size":"641.6"},{"price":"0.42","size":"645.58"},{"price":"0.41","size":"564"},{"price":"0.4","size":"20642.9"},{"price":"0.39","size":"650.23"},{"price":"0.38","size":"593"},{"price":"0.37","size":"755.73"},{"price":"0.36","size":"558"},{"price":"0.35","size":"1144.32"},{"price":"0.34","size":"649.59"},{"price":"0.33","size":"624.8"},{"price":"0.32","size":"574"},{"price":"0.31","size":"594.2"},{"price":"0.3","size":"735.66"},{"price":"0.29","size":"624.6"},{"price":"0.28","size":"356.8"},{"price":"0.27","size":"869.2"},{"price":"0.26","size":"967.6"},{"price":"0.25","size":"1673.8"},{"price":"0.24","size":"869.2"},{"price":"0.23","size":"864.6"},{"price":"0.22","size":"870.2"},{"price":"0.21","size":"891.6"},{"price":"0.2","size":"987.2"},{"price":"0.19","size":"876.8"},{"price":"0.18","size":"1096.55"},{"price":"0.17","size":"958.39"},{"price":"0.16","size":"1119.39"},{"price":"0.15","size":"1149.13"},{"price":"0.14","size":"962.6"},{"price":"0.13","size":"1041.8"},{"price":"0.12","size":"1060.55"},{"price":"0.11","size":"1124.49"},{"price":"0.1","size":"1306.79"},{"price":"0.09","size":"759.6"},{"price":"0.08","size":"3379.35"},{"price":"0.07","size":"3360.43"},{"price":"0.06","size":"3140.34"},{"price":"0.05","size":"3314.45"},{"price":"0.04","size":"3678.17"},{"price":"0.03","size":"641.4"}],"hash":"6161751622ac0003182015072f6c603c12c3e781","timestamp":"1770839724848","event_type":"book","_sub_state":"active","_subscription_id":1,"_active_subscription_id":1},"parse_warnings":[],"out_of_order":false}
{"run_id":"29526913bab7446286864a321c124486","channel":"market","event_type":"book","market":"0x8032d8355d335c6ccbfc2508d99fbc87eb13f437bd275c93ee56fd1558e517ff","asset_id":"40652734036737240317526188612064032143639112324786051284480877037991580442979","source":"market_ws:sub:active:1","t_event_ms":1770839724848,"t_recv_wall_ms":1770839724760,"t_recv_wall_iso":"2026-02-11T19:55:24.760Z","t_recv_mono_ns":618590100969208,"raw":{"market":"0x8032d8355d335c6ccbfc2508d99fbc87eb13f437bd275c93ee56fd1558e517ff","asset_id":"40652734036737240317526188612064032143639112324786051284480877037991580442979","bids":[{"price":"0.01","size":"30822.26"},{"price":"0.02","size":"12559.04"},{"price":"0.03","size":"7433.03"},{"price":"0.04","size":"5453.8"},{"price":"0.05","size":"6815.8"},{"price":"0.06","size":"5105"},{"price":"0.07","size":"5421.38"},{"price":"0.08","size":"5139.4"},{"price":"0.09","size":"5225.8"},{"price":"0.1","size":"5102.8"},{"price":"0.11","size":"120.6"},{"price":"0.12","size":"63.6"},{"price":"0.13","size":"63"},{"price":"0.14","size":"61.6"},{"price":"0.15","size":"107.39"},{"price":"0.16","size":"69.39"},{"price":"0.17","size":"58.39"},{"price":"0.18","size":"66.71"},{"price":"0.19","size":"56.8"},{"price":"0.2","size":"92.14"},{"price":"0.21","size":"60.8"},{"price":"0.22","size":"55.2"},{"price":"0.23","size":"64.48"},{"price":"0.24","size":"54.2"},{"price":"0.25","size":"375.8"},{"price":"0.26","size":"68.6"},{"price":"0.27","size":"53.2"},{"price":"0.28","size":"63.26"},{"price":"0.29","size":"52.6"},{"price":"0.3","size":"402.4"},{"price":"0.31","size":"72.2"},{"price":"0.32","size":"87.88"},{"price":"0.33","size":"188.46"},{"price":"0.34","size":"123.6"},{"price":"0.35","size":"317.03"},{"price":"0.36","size":"582.36"},{"price":"0.37","size":"559.2"},{"price":"0.38","size":"559"},{"price":"0.39","size":"594"},{"price":"0.4","size":"2915.41"},{"price":"0.41","size":"576.8"},{"price":"0.42","size":"575.5"},{"price":"0.43","size":"558.6"},{"price":"0.44","size":"572.68"},{"price":"0.45","size":"566.4"},{"price":"0.46","size":"561.94"},{"price":"0.47","size":"631.57"},{"price":"0.48","size":"611.4"},{"price":"0.49","size":"705.2"},{"price":"0.5","size":"1011.55"},{"price":"0.51","size":"692.4"},{"price":"0.52","size":"628.4"},{"price":"0.53","size":"633.4"},{"price":"0.54","size":"711.65"},{"price":"0.55","size":"866.59"},{"price":"0.56","size":"905.69"},{"price":"0.57","size":"641.6"},{"price":"0.58","size":"645.58"},{"price":"0.59","size":"564"},{"price":"0.6","size":"20642.9"},{"price":"0.61","size":"650.23"},{"price":"0.62","size":"593"},{"price":"0.63","size":"755.73"},{"price":"0.64","size":"558"},{"price":"0.65","size":"1144.32"},{"price":"0.66","size":"649.59"},{"price":"0.67","size":"624.8"},{"price":"0.68","size":"574"},{"price":"0.69","size":"594.2"},{"price":"0.7","size":"735.66"},{"price":"0.71","size":"624.6"},{"price":"0.72","size":"356.8"},{"price":"0.73","size":"869.2"},{"price":"0.74","size":"967.6"},{"price":"0.75","size":"1673.8"},{"price":"0.76","size":"869.2"},{"price":"0.77","size":"864.6"},{"price":"0.78","size":"870.2"},{"price":"0.79","size":"891.6"},{"price":"0.8","size":"987.2"},{"price":"0.81","size":"876.8"},{"price":"0.82","size":"1096.55"},{"price":"0.83","size":"958.39"},{"price":"0.84","size":"1119.39"},{"price":"0.85","size":"1149.13"},{"price":"0.86","size":"962.6"},{"price":"0.87","size":"1041.8"},{"price":"0.88","size":"1060.55"},{"price":"0.89","size":"1124.49"},{"price":"0.9","size":"1306.79"},{"price":"0.91","size":"759.6"},{"price":"0.92","size":"3379.35"},{"price":"0.93","size":"3360.43"},{"price":"0.94","size":"3140.34"},{"price":"0.95","size":"3314.45"},{"price":"0.96","size":"3678.17"},{"price":"0.97","size":"641.4"}],"asks":[{"price":"0.99","size":"30799.91"},{"price":"0.98","size":"8996.52"}],"hash":"d7d03fe12385bcae855620985fa373fb70469d36","timestamp":"1770839724848","event_type":"book","_sub_state":"active","_subscription_id":1,"_active_subscription_id":1},"parse_warnings":[],"out_of_order":false}
{"run_id":"29526913bab7446286864a321c124486","channel":"market","event_type":"last_trade_price","market":"0x8032d8355d335c6ccbfc2508d99fbc87eb13f437bd275c93ee56fd1558e517ff","asset_id":"40652734036737240317526188612064032143639112324786051284480877037991580442979","source":"market_ws:sub:unknown","t_event_ms":1770839724864,"t_recv_wall_ms":1770839724768,"t_recv_wall_iso":"2026-02-11T19:55:24.768Z","t_recv_mono_ns":618590108835333,"raw":{"market":"0x8032d8355d335c6ccbfc2508d99fbc87eb13f437bd275c93ee56fd1558e517ff","asset_id":"40652734036737240317526188612064032143639112324786051284480877037991580442979","price":"0.98","size":"4.09","fee_rate_bps":"1000","side":"BUY","timestamp":"1770839724864","event_type":"last_trade_price","transaction_hash":"0x48b4bc74bc75537fef1c4ae2534b228fce6aa2fddf969943978611ace6163a98","_sub_state":"unknown","_subscription_id":null,"_active_subscription_id":1},"parse_warnings":["unknown_message_schema"],"out_of_order":false}
{"run_id":"29526913bab7446286864a321c124486","channel":"market","event_type":"price_change","market":"0x8032d8355d335c6ccbfc2508d99fbc87eb13f437bd275c93ee56fd1558e517ff","asset_id":null,"source":"market_ws:sub:active:1","t_event_ms":1770839724868,"t_recv_wall_ms":1770839724780,"t_recv_wall_iso":"2026-02-11T19:55:24.780Z","t_recv_mono_ns":618590121478333,"raw":{"market":"0x8032d8355d335c6ccbfc2508d99fbc87eb13f437bd275c93ee56fd1558e517ff","price_changes":[{"asset_id":"20773614133833886322101538939702011175545796528197617633926164254913649353392","price":"0.02","size":"8987.33","side":"BUY","hash":"1f4a770263516b4973e94afde727e8c7cce0c74f","best_bid":"0.02","best_ask":"0.03"},{"asset_id":"40652734036737240317526188612064032143639112324786051284480877037991580442979","price":"0.98","size":"8987.33","side":"SELL","hash":"f4e0b4c398683ba57f4d1b9c8ee7b811e067800f","best_bid":"0.97","best_ask":"0.98"}],"timestamp":"1770839724868","event_type":"price_change","_sub_state":"active","_subscription_id":1,"_active_subscription_id":1},"parse_warnings":[],"out_of_order":false}
{"run_id":"29526913bab7446286864a321c124486","channel":"market","event_type":"book","market":"0x8032d8355d335c6ccbfc2508d99fbc87eb13f437bd275c93ee56fd1558e517ff","asset_id":"20773614133833886322101538939702011175545796528197617633926164254913649353392","source":"market_ws:sub:active:1","t_event_ms":1770839724868,"t_recv_wall_ms":1770839724781,"t_recv_wall_iso":"2026-02-11T19:55:24.781Z","t_recv_mono_ns":618590121981250,"raw":{"market":"0x8032d8355d335c6ccbfc2508d99fbc87eb13f437bd275c93ee56fd1558e517ff","asset_id":"20773614133833886322101538939702011175545796528197617633926164254913649353392","bids":[{"price":"0.01","size":"30799.91"},{"price":"0.02","size":"8987.33"}],"asks":[{"price":"0.99","size":"30822.26"},{"price":"0.98","size":"12559.04"},{"price":"0.97","size":"7433.03"},{"price":"0.96","size":"5453.8"},{"price":"0.95","size":"6815.8"},{"price":"0.94","size":"5105"},{"price":"0.93","size":"5421.38"},{"price":"0.92","size":"5139.4"},{"price":"0.91","size":"5225.8"},{"price":"0.9","size":"5102.8"},{"price":"0.89","size":"120.6"},{"price":"0.88","size":"63.6"},{"price":"0.87","size":"63"},{"price":"0.86","size":"61.6"},{"price":"0.85","size":"107.39"},{"price":"0.84","size":"69.39"},{"price":"0.83","size":"58.39"},{"price":"0.82","size":"66.71"},{"price":"0.81","size":"56.8"},{"price":"0.8","size":"92.14"},{"price":"0.79","size":"60.8"},{"price":"0.78","size":"55.2"},{"price":"0.77","size":"64.48"},{"price":"0.76","size":"54.2"},{"price":"0.75","size":"375.8"},{"price":"0.74","size":"68.6"},{"price":"0.73","size":"53.2"},{"price":"0.72","size":"63.26"},{"price":"0.71","size":"52.6"},{"price":"0.7","size":"402.4"},{"price":"0.69","size":"72.2"},{"price":"0.68","size":"87.88"},{"price":"0.67","size":"188.46"},{"price":"0.66","size":"123.6"},{"price":"0.65","size":"317.03"},{"price":"0.64","size":"582.36"},{"price":"0.63","size":"559.2"},{"price":"0.62","size":"559"},{"price":"0.61","size":"594"},{"price":"0.6","size":"2915.41"},{"price":"0.59","size":"576.8"},{"price":"0.58","size":"575.5"},{"price":"0.57","size":"558.6"},{"price":"0.56","size":"572.68"},{"price":"0.55","size":"566.4"},{"price":"0.54","size":"561.94"},{"price":"0.53","size":"631.57"},{"price":"0.52","size":"611.4"},{"price":"0.51","size":"705.2"},{"price":"0.5","size":"1011.55"},{"price":"0.49","size":"692.4"},{"price":"0.48","size":"628.4"},{"price":"0.47","size":"633.4"},{"price":"0.46","size":"711.65"},{"price":"0.45","size":"866.59"},{"price":"0.44","size":"905.69"},{"price":"0.43","size":"641.6"},{"price":"0.42","size":"645.58"},{"price":"0.41","size":"564"},{"price":"0.4","size":"20642.9"},{"price":"0.39","size":"650.23"},{"price":"0.38","size":"593"},{"price":"0.37","size":"755.73"},{"price":"0.36","size":"558"},{"price":"0.35","size":"1144.32"},{"price":"0.34","size":"649.59"},{"price":"0.33","size":"624.8"},{"price":"0.32","size":"574"},{"price":"0.31","size":"594.2"},{"price":"0.3","size":"735.66"},{"price":"0.29","size":"624.6"},{"price":"0.28","size":"356.8"},{"price":"0.27","size":"869.2"},{"price":"0.26","size":"967.6"},{"price":"0.25","size":"1673.8"},{"price":"0.24","size":"869.2"},{"price":"0.23","size":"864.6"},{"price":"0.22","size":"870.2"},{"price":"0.21","size":"891.6"},{"price":"0.2","size":"987.2"},{"price":"0.19","size":"876.8"},{"price":"0.18","size":"1096.55"},{"price":"0.17","size":"958.39"},{"price":"0.16","size":"1119.39"},{"price":"0.15","size":"1149.13"},{"price":"0.14","size":"962.6"},{"price":"0.13","size":"1041.8"},{"price":"0.12","size":"1060.55"},{"price":"0.11","size":"1124.49"},{"price":"0.1","size":"1306.79"},{"price":"0.09","size":"759.6"},{"price":"0.08","size":"3379.35"},{"price":"0.07","size":"3360.43"},{"price":"0.06","size":"3140.34"},{"price":"0.05","size":"3314.45"},{"price":"0.04","size":"3678.17"},{"price":"0.03","size":"641.4"}],"hash":"1f4a770263516b4973e94afde727e8c7cce0c74f","timestamp":"1770839724868","event_type":"book","_sub_state":"active","_subscription_id":1,"_active_subscription_id":1},"parse_warnings":[],"out_of_order":false}
{"run_id":"29526913bab7446286864a321c124486","channel":"market","event_type":"book","market":"0x8032d8355d335c6ccbfc2508d99fbc87eb13f437bd275c93ee56fd1558e517ff","asset_id":"40652734036737240317526188612064032143639112324786051284480877037991580442979","source":"market_ws:sub:active:1","t_event_ms":1770839724868,"t_recv_wall_ms":1770839724782,"t_recv_wall_iso":"2026-02-11T19:55:24.782Z","t_recv_mono_ns":618590123141208,"raw":{"market":"0x8032d8355d335c6ccbfc2508d99fbc87eb13f437bd275c93ee56fd1558e517ff","asset_id":"40652734036737240317526188612064032143639112324786051284480877037991580442979","bids":[{"price":"0.01","size":"30822.26"},{"price":"0.02","size":"12559.04"},{"price":"0.03","size":"7433.03"},{"price":"0.04","size":"5453.8"},{"price":"0.05","size":"6815.8"},{"price":"0.06","size":"5105"},{"price":"0.07","size":"5421.38"},{"price":"0.08","size":"5139.4"},{"price":"0.09","size":"5225.8"},{"price":"0.1","size":"5102.8"},{"price":"0.11","size":"120.6"},{"price":"0.12","size":"63.6"},{"price":"0.13","size":"63"},{"price":"0.14","size":"61.6"},{"price":"0.15","size":"107.39"},{"price":"0.16","size":"69.39"},{"price":"0.17","size":"58.39"},{"price":"0.18","size":"66.71"},{"price":"0.19","size":"56.8"},{"price":"0.2","size":"92.14"},{"price":"0.21","size":"60.8"},{"price":"0.22","size":"55.2"},{"price":"0.23","size":"64.48"},{"price":"0.24","size":"54.2"},{"price":"0.25","size":"375.8"},{"price":"0.26","size":"68.6"},{"price":"0.27","size":"53.2"},{"price":"0.28","size":"63.26"},{"price":"0.29","size":"52.6"},{"price":"0.3","size":"402.4"},{"price":"0.31","size":"72.2"},{"price":"0.32","size":"87.88"},{"price":"0.33","size":"188.46"},{"price":"0.34","size":"123.6"},{"price":"0.35","size":"317.03"},{"price":"0.36","size":"582.36"},{"price":"0.37","size":"559.2"},{"price":"0.38","size":"559"},{"price":"0.39","size":"594"},{"price":"0.4","size":"2915.41"},{"price":"0.41","size":"576.8"},{"price":"0.42","size":"575.5"},{"price":"0.43","size":"558.6"},{"price":"0.44","size":"572.68"},{"price":"0.45","size":"566.4"},{"price":"0.46","size":"561.94"},{"price":"0.47","size":"631.57"},{"price":"0.48","size":"611.4"},{"price":"0.49","size":"705.2"},{"price":"0.5","size":"1011.55"},{"price":"0.51","size":"692.4"},{"price":"0.52","size":"628.4"},{"price":"0.53","size":"633.4"},{"price":"0.54","size":"711.65"},{"price":"0.55","size":"866.59"},{"price":"0.56","size":"905.69"},{"price":"0.57","size":"641.6"},{"price":"0.58","size":"645.58"},{"price":"0.59","size":"564"},{"price":"0.6","size":"20642.9"},{"price":"0.61","size":"650.23"},{"price":"0.62","size":"593"},{"price":"0.63","size":"755.73"},{"price":"0.64","size":"558"},{"price":"0.65","size":"1144.32"},{"price":"0.66","size":"649.59"},{"price":"0.67","size":"624.8"},{"price":"0.68","size":"574"},{"price":"0.69","size":"594.2"},{"price":"0.7","size":"735.66"},{"price":"0.71","size":"624.6"},{"price":"0.72","size":"356.8"},{"price":"0.73","size":"869.2"},{"price":"0.74","size":"967.6"},{"price":"0.75","size":"1673.8"},{"price":"0.76","size":"869.2"},{"price":"0.77","size":"864.6"},{"price":"0.78","size":"870.2"},{"price":"0.79","size":"891.6"},{"price":"0.8","size":"987.2"},{"price":"0.81","size":"876.8"},{"price":"0.82","size":"1096.55"},{"price":"0.83","size":"958.39"},{"price":"0.84","size":"1119.39"},{"price":"0.85","size":"1149.13"},{"price":"0.86","size":"962.6"},{"price":"0.87","size":"1041.8"},{"price":"0.88","size":"1060.55"},{"price":"0.89","size":"1124.49"},{"price":"0.9","size":"1306.79"},{"price":"0.91","size":"759.6"},{"price":"0.92","size":"3379.35"},{"price":"0.93","size":"3360.43"},{"price":"0.94","size":"3140.34"},{"price":"0.95","size":"3314.45"},{"price":"0.96","size":"3678.17"},{"price":"0.97","size":"641.4"}],"asks":[{"price":"0.99","size":"30799.91"},{"price":"0.98","size":"8987.33"}],"hash":"f4e0b4c398683ba57f4d1b9c8ee7b811e067800f","timestamp":"1770839724868","event_type":"book","_sub_state":"active","_subscription_id":1,"_active_subscription_id":1},"parse_warnings":[],"out_of_order":false}
{"run_id":"29526913bab7446286864a321c124486","channel":"market","event_type":"last_trade_price","market":"0x8032d8355d335c6ccbfc2508d99fbc87eb13f437bd275c93ee56fd1558e517ff","asset_id":"40652734036737240317526188612064032143639112324786051284480877037991580442979","source":"market_ws:sub:unknown","t_event_ms":1770839724883,"t_recv_wall_ms":1770839724797,"t_recv_wall_iso":"2026-02-11T19:55:24.797Z","t_recv_mono_ns":618590138243916,"raw":{"market":"0x8032d8355d335c6ccbfc2508d99fbc87eb13f437bd275c93ee56fd1558e517ff","asset_id":"40652734036737240317526188612064032143639112324786051284480877037991580442979","price":"0.98","size":"10.21","fee_rate_bps":"1000","side":"BUY","timestamp":"1770839724883","event_type":"last_trade_price","transaction_hash":"0x021aad283f28e476c4325e242e278cbab3d4ceb8f6c59c6bc079159cb0fa28f1","_sub_state":"unknown","_subscription_id":null,"_active_subscription_id":1},"parse_warnings":["unknown_message_schema"],"out_of_order":false}
{"run_id":"29526913bab7446286864a321c124486","channel":"market","event_type":"last_trade_price","market":"0x8032d8355d335c6ccbfc2508d99fbc87eb13f437bd275c93ee56fd1558e517ff","asset_id":"40652734036737240317526188612064032143639112324786051284480877037991580442979","source":"market_ws:sub:unknown","t_event_ms":1770839724900,"t_recv_wall_ms":1770839724804,"t_recv_wall_iso":"2026-02-11T19:55:24.804Z","t_recv_mono_ns":618590145687250,"raw":{"market":"0x8032d8355d335c6ccbfc2508d99fbc87eb13f437bd275c93ee56fd1558e517ff","asset_id":"40652734036737240317526188612064032143639112324786051284480877037991580442979","price":"0.98","size":"9.19","fee_rate_bps":"1000","side":"BUY","timestamp":"1770839724900","event_type":"last_trade_price","transaction_hash":"0x2a571e884dc4144e9f2fab65e32fc5a3299bc7a527db60fe7e95ce09c4f355df","_sub_state":"unknown","_subscription_id":null,"_active_subscription_id":1},"parse_warnings":["unknown_message_schema"],"out_of_order":false}
{"run_id":"29526913bab7446286864a321c124486","channel":"market","event_type":"price_change","market":"0x8032d8355d335c6ccbfc2508d99fbc87eb13f437bd275c93ee56fd1558e517ff","asset_id":null,"source":"market_ws:sub:active:1","t_event_ms":1770839724910,"t_recv_wall_ms":1770839724844,"t_recv_wall_iso":"2026-02-11T19:55:24.844Z","t_recv_mono_ns":618590185201000,"raw":{"market":"0x8032d8355d335c6ccbfc2508d99fbc87eb13f437bd275c93ee56fd1558e517ff","price_changes":[{"asset_id":"20773614133833886322101538939702011175545796528197617633926164254913649353392","price":"0.02","size":"8979.57","side":"BUY","hash":"5e91f195859289c7bcd2685942bf676cac570f6b","best_bid":"0.02","best_ask":"0.03"},{"asset_id":"40652734036737240317526188612064032143639112324786051284480877037991580442979","price":"0.98","size":"8979.57","side":"SELL","hash":"725dba1d1b4f0a5b05f31a978222cead0b3155b2","best_bid":"0.97","best_ask":"0.98"}],"timestamp":"1770839724910","event_type":"price_change","_sub_state":"active","_subscription_id":1,"_active_subscription_id":1},"parse_warnings":[],"out_of_order":false}
{"run_id":"29526913bab7446286864a321c124486","channel":"market","event_type":"book","market":"0x8032d8355d335c6ccbfc2508d99fbc87eb13f437bd275c93ee56fd1558e517ff","asset_id":"20773614133833886322101538939702011175545796528197617633926164254913649353392","source":"market_ws:sub:active:1","t_event_ms":1770839724910,"t_recv_wall_ms":1770839724844,"t_recv_wall_iso":"2026-02-11T19:55:24.844Z","t_recv_mono_ns":618590185618208,"raw":{"market":"0x8032d8355d335c6ccbfc2508d99fbc87eb13f437bd275c93ee56fd1558e517ff","asset_id":"20773614133833886322101538939702011175545796528197617633926164254913649353392","bids":[{"price":"0.01","size":"30799.91"},{"price":"0.02","size":"8979.57"}],"asks":[{"price":"0.99","size":"30822.26"},{"price":"0.98","size":"12559.04"},{"price":"0.97","size":"7433.03"},{"price":"0.96","size":"5453.8"},{"price":"0.95","size":"6815.8"},{"price":"0.94","size":"5105"},{"price":"0.93","size":"5421.38"},{"price":"0.92","size":"5139.4"},{"price":"0.91","size":"5225.8"},{"price":"0.9","size":"5102.8"},{"price":"0.89","size":"120.6"},{"price":"0.88","size":"63.6"},{"price":"0.87","size":"63"},{"price":"0.86","size":"61.6"},{"price":"0.85","size":"107.39"},{"price":"0.84","size":"69.39"},{"price":"0.83","size":"58.39"},{"price":"0.82","size":"66.71"},{"price":"0.81","size":"56.8"},{"price":"0.8","size":"92.14"},{"price":"0.79","size":"60.8"},{"price":"0.78","size":"55.2"},{"price":"0.77","size":"64.48"},{"price":"0.76","size":"54.2"},{"price":"0.75","size":"375.8"},{"price":"0.74","size":"68.6"},{"price":"0.73","size":"53.2"},{"price":"0.72","size":"63.26"},{"price":"0.71","size":"52.6"},{"price":"0.7","size":"402.4"},{"price":"0.69","size":"72.2"},{"price":"0.68","size":"87.88"},{"price":"0.67","size":"188.46"},{"price":"0.66","size":"123.6"},{"price":"0.65","size":"317.03"},{"price":"0.64","size":"582.36"},{"price":"0.63","size":"559.2"},{"price":"0.62","size":"559"},{"price":"0.61","size":"594"},{"price":"0.6","size":"2915.41"},{"price":"0.59","size":"576.8"},{"price":"0.58","size":"575.5"},{"price":"0.57","size":"558.6"},{"price":"0.56","size":"572.68"},{"price":"0.55","size":"566.4"},{"price":"0.54","size":"561.94"},{"price":"0.53","size":"631.57"},{"price":"0.52","size":"611.4"},{"price":"0.51","size":"705.2"},{"price":"0.5","size":"1011.55"},{"price":"0.49","size":"692.4"},{"price":"0.48","size":"628.4"},{"price":"0.47","size":"633.4"},{"price":"0.46","size":"711.65"},{"price":"0.45","size":"866.59"},{"price":"0.44","size":"905.69"},{"price":"0.43","size":"641.6"},{"price":"0.42","size":"645.58"},{"price":"0.41","size":"564"},{"price":"0.4","size":"20642.9"},{"price":"0.39","size":"650.23"},{"price":"0.38","size":"593"},{"price":"0.37","size":"755.73"},{"price":"0.36","size":"558"},{"price":"0.35","size":"1144.32"},{"price":"0.34","size":"649.59"},{"price":"0.33","size":"624.8"},{"price":"0.32","size":"574"},{"price":"0.31","size":"594.2"},{"price":"0.3","size":"735.66"},{"price":"0.29","size":"624.6"},{"price":"0.28","size":"356.8"},{"price":"0.27","size":"869.2"},{"price":"0.26","size":"967.6"},{"price":"0.25","size":"1673.8"},{"price":"0.24","size":"869.2"},{"price":"0.23","size":"864.6"},{"price":"0.22","size":"870.2"},{"price":"0.21","size":"891.6"},{"price":"0.2","size":"987.2"},{"price":"0.19","size":"876.8"},{"price":"0.18","size":"1096.55"},{"price":"0.17","size":"958.39"},{"price":"0.16","size":"1119.39"},{"price":"0.15","size":"1149.13"},{"price":"0.14","size":"962.6"},{"price":"0.13","size":"1041.8"},{"price":"0.12","size":"1060.55"},{"price":"0.11","size":"1124.49"},{"price":"0.1","size":"1306.79"},{"price":"0.09","size":"759.6"},{"price":"0.08","size":"3379.35"},{"price":"0.07","size":"3360.43"},{"price":"0.06","size":"3140.34"},{"price":"0.05","size":"3314.45"},{"price":"0.04","size":"3678.17"},{"price":"0.03","size":"641.4"}],"hash":"5e91f195859289c7bcd2685942bf676cac570f6b","timestamp":"1770839724910","event_type":"book","_sub_state":"active","_subscription_id":1,"_active_subscription_id":1},"parse_warnings":[],"out_of_order":false}
{"run_id":"29526913bab7446286864a321c124486","channel":"market","event_type":"book","market":"0x8032d8355d335c6ccbfc2508d99fbc87eb13f437bd275c93ee56fd1558e517ff","asset_id":"40652734036737240317526188612064032143639112324786051284480877037991580442979","source":"market_ws:sub:active:1","t_event_ms":1770839724910,"t_recv_wall_ms":1770839724845,"t_recv_wall_iso":"2026-02-11T19:55:24.845Z","t_recv_mono_ns":618590186235041,"raw":{"market":"0x8032d8355d335c6ccbfc2508d99fbc87eb13f437bd275c93ee56fd1558e517ff","asset_id":"40652734036737240317526188612064032143639112324786051284480877037991580442979","bids":[{"price":"0.01","size":"30822.26"},{"price":"0.02","size":"12559.04"},{"price":"0.03","size":"7433.03"},{"price":"0.04","size":"5453.8"},{"price":"0.05","size":"6815.8"},{"price":"0.06","size":"5105"},{"price":"0.07","size":"5421.38"},{"price":"0.08","size":"5139.4"},{"price":"0.09","size":"5225.8"},{"price":"0.1","size":"5102.8"},{"price":"0.11","size":"120.6"},{"price":"0.12","size":"63.6"},{"price":"0.13","size":"63"},{"price":"0.14","size":"61.6"},{"price":"0.15","size":"107.39"},{"price":"0.16","size":"69.39"},{"price":"0.17","size":"58.39"},{"price":"0.18","size":"66.71"},{"price":"0.19","size":"56.8"},{"price":"0.2","size":"92.14"},{"price":"0.21","size":"60.8"},{"price":"0.22","size":"55.2"},{"price":"0.23","size":"64.48"},{"price":"0.24","size":"54.2"},{"price":"0.25","size":"375.8"},{"price":"0.26","size":"68.6"},{"price":"0.27","size":"53.2"},{"price":"0.28","size":"63.26"},{"price":"0.29","size":"52.6"},{"price":"0.3","size":"402.4"},{"price":"0.31","size":"72.2"},{"price":"0.32","size":"87.88"},{"price":"0.33","size":"188.46"},{"price":"0.34","size":"123.6"},{"price":"0.35","size":"317.03"},{"price":"0.36","size":"582.36"},{"price":"0.37","size":"559.2"},{"price":"0.38","size":"559"},{"price":"0.39","size":"594"},{"price":"0.4","size":"2915.41"},{"price":"0.41","size":"576.8"},{"price":"0.42","size":"575.5"},{"price":"0.43","size":"558.6"},{"price":"0.44","size":"572.68"},{"price":"0.45","size":"566.4"},{"price":"0.46","size":"561.94"},{"price":"0.47","size":"631.57"},{"price":"0.48","size":"611.4"},{"price":"0.49","size":"705.2"},{"price":"0.5","size":"1011.55"},{"price":"0.51","size":"692.4"},{"price":"0.52","size":"628.4"},{"price":"0.53","size":"633.4"},{"price":"0.54","size":"711.65"},{"price":"0.55","size":"866.59"},{"price":"0.56","size":"905.69"},{"price":"0.57","size":"641.6"},{"price":"0.58","size":"645.58"},{"price":"0.59","size":"564"},{"price":"0.6","size":"20642.9"},{"price":"0.61","size":"650.23"},{"price":"0.62","size":"593"},{"price":"0.63","size":"755.73"},{"price":"0.64","size":"558"},{"price":"0.65","size":"1144.32"},{"price":"0.66","size":"649.59"},{"price":"0.67","size":"624.8"},{"price":"0.68","size":"574"},{"price":"0.69","size":"594.2"},{"price":"0.7","size":"735.66"},{"price":"0.71","size":"624.6"},{"price":"0.72","size":"356.8"},{"price":"0.73","size":"869.2"},{"price":"0.74","size":"967.6"},{"price":"0.75","size":"1673.8"},{"price":"0.76","size":"869.2"},{"price":"0.77","size":"864.6"},{"price":"0.78","size":"870.2"},{"price":"0.79","size":"891.6"},{"price":"0.8","size":"987.2"},{"price":"0.81","size":"876.8"},{"price":"0.82","size":"1096.55"},{"price":"0.83","size":"958.39"},{"price":"0.84","size":"1119.39"},{"price":"0.85","size":"1149.13"},{"price":"0.86","size":"962.6"},{"price":"0.87","size":"1041.8"},{"price":"0.88","size":"1060.55"},{"price":"0.89","size":"1124.49"},{"price":"0.9","size":"1306.79"},{"price":"0.91","size":"759.6"},{"price":"0.92","size":"3379.35"},{"price":"0.93","size":"3360.43"},{"price":"0.94","size":"3140.34"},{"price":"0.95","size":"3314.45"},{"price":"0.96","size":"3678.17"},{"price":"0.97","size":"641.4"}],"asks":[{"price":"0.99","size":"30799.91"},{"price":"0.98","size":"8979.57"}],"hash":"725dba1d1b4f0a5b05f31a978222cead0b3155b2","timestamp":"1770839724910","event_type":"book","_sub_state":"active","_subscription_id":1,"_active_subscription_id":1},"parse_warnings":[],"out_of_order":false}
{"run_id":"29526913bab7446286864a321c124486","channel":"market","event_type":"price_change","market":"0x8032d8355d335c6ccbfc2508d99fbc87eb13f437bd275c93ee56fd1558e517ff","asset_id":null,"source":"market_ws:sub:active:1","t_event_ms":1770839724928,"t_recv_wall_ms":1770839724845,"t_recv_wall_iso":"2026-02-11T19:55:24.845Z","t_recv_mono_ns":618590186701958,"raw":{"market":"0x8032d8355d335c6ccbfc2508d99fbc87eb13f437bd275c93ee56fd1558e517ff","price_changes":[{"asset_id":"20773614133833886322101538939702011175545796528197617633926164254913649353392","price":"0.02","size":"8970.38","side":"BUY","hash":"ee1a1c49b382f1f1dfd948fa2bea8281a9169e17","best_bid":"0.02","best_ask":"0.03"},{"asset_id":"40652734036737240317526188612064032143639112324786051284480877037991580442979","price":"0.98","size":"8970.38","side":"SELL","hash":"5d516ce0a0ca12366cc75ba0d62dc68ed1aacc5c","best_bid":"0.97","best_ask":"0.98"}],"timestamp":"1770839724928","event_type":"price_change","_sub_state":"active","_subscription_id":1,"_active_subscription_id":1},"parse_warnings":[],"out_of_order":false}
{"run_id":"29526913bab7446286864a321c124486","channel":"market","event_type":"book","market":"0x8032d8355d335c6ccbfc2508d99fbc87eb13f437bd275c93ee56fd1558e517ff","asset_id":"20773614133833886322101538939702011175545796528197617633926164254913649353392","source":"market_ws:sub:active:1","t_event_ms":1770839724928,"t_recv_wall_ms":1770839724846,"t_recv_wall_iso":"2026-02-11T19:55:24.846Z","t_recv_mono_ns":618590186838250,"raw":{"market":"0x8032d8355d335c6ccbfc2508d99fbc87eb13f437bd275c93ee56fd1558e517ff","asset_id":"20773614133833886322101538939702011175545796528197617633926164254913649353392","bids":[{"price":"0.01","size":"30799.91"},{"price":"0.02","size":"8970.38"}],"asks":[{"price":"0.99","size":"30822.26"},{"price":"0.98","size":"12559.04"},{"price":"0.97","size":"7433.03"},{"price":"0.96","size":"5453.8"},{"price":"0.95","size":"6815.8"},{"price":"0.94","size":"5105"},{"price":"0.93","size":"5421.38"},{"price":"0.92","size":"5139.4"},{"price":"0.91","size":"5225.8"},{"price":"0.9","size":"5102.8"},{"price":"0.89","size":"120.6"},{"price":"0.88","size":"63.6"},{"price":"0.87","size":"63"},{"price":"0.86","size":"61.6"},{"price":"0.85","size":"107.39"},{"price":"0.84","size":"69.39"},{"price":"0.83","size":"58.39"},{"price":"0.82","size":"66.71"},{"price":"0.81","size":"56.8"},{"price":"0.8","size":"92.14"},{"price":"0.79","size":"60.8"},{"price":"0.78","size":"55.2"},{"price":"0.77","size":"64.48"},{"price":"0.76","size":"54.2"},{"price":"0.75","size":"375.8"},{"price":"0.74","size":"68.6"},{"price":"0.73","size":"53.2"},{"price":"0.72","size":"63.26"},{"price":"0.71","size":"52.6"},{"price":"0.7","size":"402.4"},{"price":"0.69","size":"72.2"},{"price":"0.68","size":"87.88"},{"price":"0.67","size":"188.46"},{"price":"0.66","size":"123.6"},{"price":"0.65","size":"317.03"},{"price":"0.64","size":"582.36"},{"price":"0.63","size":"559.2"},{"price":"0.62","size":"559"},{"price":"0.61","size":"594"},{"price":"0.6","size":"2915.41"},{"price":"0.59","size":"576.8"},{"price":"0.58","size":"575.5"},{"price":"0.57","size":"558.6"},{"price":"0.56","size":"572.68"},{"price":"0.55","size":"566.4"},{"price":"0.54","size":"561.94"},{"price":"0.53","size":"631.57"},{"price":"0.52","size":"611.4"},{"price":"0.51","size":"705.2"},{"price":"0.5","size":"1011.55"},{"price":"0.49","size":"692.4"},{"price":"0.48","size":"628.4"},{"price":"0.47","size":"633.4"},{"price":"0.46","size":"711.65"},{"price":"0.45","size":"866.59"},{"price":"0.44","size":"905.69"},{"price":"0.43","size":"641.6"},{"price":"0.42","size":"645.58"},{"price":"0.41","size":"564"},{"price":"0.4","size":"20642.9"},{"price":"0.39","size":"650.23"},{"price":"0.38","size":"593"},{"price":"0.37","size":"755.73"},{"price":"0.36","size":"558"},{"price":"0.35","size":"1144.32"},{"price":"0.34","size":"649.59"},{"price":"0.33","size":"624.8"},{"price":"0.32","size":"574"},{"price":"0.31","size":"594.2"},{"price":"0.3","size":"735.66"},{"price":"0.29","size":"624.6"},{"price":"0.28","size":"356.8"},{"price":"0.27","size":"869.2"},{"price":"0.26","size":"967.6"},{"price":"0.25","size":"1673.8"},{"price":"0.24","size":"869.2"},{"price":"0.23","size":"864.6"},{"price":"0.22","size":"870.2"},{"price":"0.21","size":"891.6"},{"price":"0.2","size":"987.2"},{"price":"0.19","size":"876.8"},{"price":"0.18","size":"1096.55"},{"price":"0.17","size":"958.39"},{"price":"0.16","size":"1119.39"},{"price":"0.15","size":"1149.13"},{"price":"0.14","size":"962.6"},{"price":"0.13","size":"1041.8"},{"price":"0.12","size":"1060.55"},{"price":"0.11","size":"1124.49"},{"price":"0.1","size":"1306.79"},{"price":"0.09","size":"759.6"},{"price":"0.08","size":"3379.35"},{"price":"0.07","size":"3360.43"},{"price":"0.06","size":"3140.34"},{"price":"0.05","size":"3314.45"},{"price":"0.04","size":"3678.17"},{"price":"0.03","size":"641.4"}],"hash":"ee1a1c49b382f1f1dfd948fa2bea8281a9169e17","timestamp":"1770839724928","event_type":"book","_sub_state":"active","_subscription_id":1,"_active_subscription_id":1},"parse_warnings":[],"out_of_order":false}
{"run_id":"29526913bab7446286864a321c124486","channel":"market","event_type":"book","market":"0x8032d8355d335c6ccbfc2508d99fbc87eb13f437bd275c93ee56fd1558e517ff","asset_id":"40652734036737240317526188612064032143639112324786051284480877037991580442979","source":"market_ws:sub:active:1","t_event_ms":1770839724928,"t_recv_wall_ms":1770839724846,"t_recv_wall_iso":"2026-02-11T19:55:24.846Z","t_recv_mono_ns":618590187273041,"raw":{"market":"0x8032d8355d335c6ccbfc2508d99fbc87eb13f437bd275c93ee56fd1558e517ff","asset_id":"40652734036737240317526188612064032143639112324786051284480877037991580442979","bids":[{"price":"0.01","size":"30822.26"},{"price":"0.02","size":"12559.04"},{"price":"0.03","size":"7433.03"},{"price":"0.04","size":"5453.8"},{"price":"0.05","size":"6815.8"},{"price":"0.06","size":"5105"},{"price":"0.07","size":"5421.38"},{"price":"0.08","size":"5139.4"},{"price":"0.09","size":"5225.8"},{"price":"0.1","size":"5102.8"},{"price":"0.11","size":"120.6"},{"price":"0.12","size":"63.6"},{"price":"0.13","size":"63"},{"price":"0.14","size":"61.6"},{"price":"0.15","size":"107.39"},{"price":"0.16","size":"69.39"},{"price":"0.17","size":"58.39"},{"price":"0.18","size":"66.71"},{"price":"0.19","size":"56.8"},{"price":"0.2","size":"92.14"},{"price":"0.21","size":"60.8"},{"price":"0.22","size":"55.2"},{"price":"0.23","size":"64.48"},{"price":"0.24","size":"54.2"},{"price":"0.25","size":"375.8"},{"price":"0.26","size":"68.6"},{"price":"0.27","size":"53.2"},{"price":"0.28","size":"63.26"},{"price":"0.29","size":"52.6"},{"price":"0.3","size":"402.4"},{"price":"0.31","size":"72.2"},{"price":"0.32","size":"87.88"},{"price":"0.33","size":"188.46"},{"price":"0.34","size":"123.6"},{"price":"0.35","size":"317.03"},{"price":"0.36","size":"582.36"},{"price":"0.37","size":"559.2"},{"price":"0.38","size":"559"},{"price":"0.39","size":"594"},{"price":"0.4","size":"2915.41"},{"price":"0.41","size":"576.8"},{"price":"0.42","size":"575.5"},{"price":"0.43","size":"558.6"},{"price":"0.44","size":"572.68"},{"price":"0.45","size":"566.4"},{"price":"0.46","size":"561.94"},{"price":"0.47","size":"631.57"},{"price":"0.48","size":"611.4"},{"price":"0.49","size":"705.2"},{"price":"0.5","size":"1011.55"},{"price":"0.51","size":"692.4"},{"price":"0.52","size":"628.4"},{"price":"0.53","size":"633.4"},{"price":"0.54","size":"711.65"},{"price":"0.55","size":"866.59"},{"price":"0.56","size":"905.69"},{"price":"0.57","size":"641.6"},{"price":"0.58","size":"645.58"},{"price":"0.59","size":"564"},{"price":"0.6","size":"20642.9"},{"price":"0.61","size":"650.23"},{"price":"0.62","size":"593"},{"price":"0.63","size":"755.73"},{"price":"0.64","size":"558"},{"price":"0.65","size":"1144.32"},{"price":"0.66","size":"649.59"},{"price":"0.67","size":"624.8"},{"price":"0.68","size":"574"},{"price":"0.69","size":"594.2"},{"price":"0.7","size":"735.66"},{"price":"0.71","size":"624.6"},{"price":"0.72","size":"356.8"},{"price":"0.73","size":"869.2"},{"price":"0.74","size":"967.6"},{"price":"0.75","size":"1673.8"},{"price":"0.76","size":"869.2"},{"price":"0.77","size":"864.6"},{"price":"0.78","size":"870.2"},{"price":"0.79","size":"891.6"},{"price":"0.8","size":"987.2"},{"price":"0.81","size":"876.8"},{"price":"0.82","size":"1096.55"},{"price":"0.83","size":"958.39"},{"price":"0.84","size":"1119.39"},{"price":"0.85","size":"1149.13"},{"price":"0.86","size":"962.6"},{"price":"0.87","size":"1041.8"},{"price":"0.88","size":"1060.55"},{"price":"0.89","size":"1124.49"},{"price":"0.9","size":"1306.79"},{"price":"0.91","size":"759.6"},{"price":"0.92","size":"3379.35"},{"price":"0.93","size":"3360.43"},{"price":"0.94","size":"3140.34"},{"price":"0.95","size":"3314.45"},{"price":"0.96","size":"3678.17"},{"price":"0.97","size":"641.4"}],"asks":[{"price":"0.99","size":"30799.91"},{"price":"0.98","size":"8970.38"}],"hash":"5d516ce0a0ca12366cc75ba0d62dc68ed1aacc5c","timestamp":"1770839724928","event_type":"book","_sub_state":"active","_subscription_id":1,"_active_subscription_id":1},"parse_warnings":[],"out_of_order":false}
{"run_id":"29526913bab7446286864a321c124486","channel":"market","event_type":"price_change","market":"0x8032d8355d335c6ccbfc2508d99fbc87eb13f437bd275c93ee56fd1558e517ff","asset_id":null,"source":"market_ws:sub:active:1","t_event_ms":1770839724931,"t_recv_wall_ms":1770839724846,"t_recv_wall_iso":"2026-02-11T19:55:24.846Z","t_recv_mono_ns":618590187681791,"raw":{"market":"0x8032d8355d335c6ccbfc2508d99fbc87eb13f437bd275c93ee56fd1558e517ff","price_changes":[{"asset_id":"20773614133833886322101538939702011175545796528197617633926164254913649353392","price":"0.01","size":"30809.91","side":"BUY","hash":"a11245155413eb2023f70c9bd43c41cc3988ff20","best_bid":"0.02","best_ask":"0.03"},{"asset_id":"40652734036737240317526188612064032143639112324786051284480877037991580442979","price":"0.99","size":"30809.91","side":"SELL","hash":"8a8e4134de6ddb24b95420c480564e9161aa1d5e","best_bid":"0.97","best_ask":"0.98"}],"timestamp":"1770839724931","event_type":"price_change","_sub_state":"active","_subscription_id":1,"_active_subscription_id":1},"parse_warnings":[],"out_of_order":false}
{"run_id":"29526913bab7446286864a321c124486","channel":"market","event_type":"last_trade_price","market":"0x8032d8355d335c6ccbfc2508d99fbc87eb13f437bd275c93ee56fd1558e517ff","asset_id":"40652734036737240317526188612064032143639112324786051284480877037991580442979","source":"market_ws:sub:unknown","t_event_ms":1770839724942,"t_recv_wall_ms":1770839724870,"t_recv_wall_iso":"2026-02-11T19:55:24.870Z","t_recv_mono_ns":618590211586375,"raw":{"market":"0x8032d8355d335c6ccbfc2508d99fbc87eb13f437bd275c93ee56fd1558e517ff","asset_id":"40652734036737240317526188612064032143639112324786051284480877037991580442979","price":"0.98","size":"7.76","fee_rate_bps":"1000","side":"BUY","timestamp":"1770839724942","event_type":"last_trade_price","transaction_hash":"0xa7729202bedee81fd3b492b583cf5506d9de1000e83f023a88fb9eac1670a284","_sub_state":"unknown","_subscription_id":null,"_active_subscription_id":1},"parse_warnings":["unknown_message_schema"],"out_of_order":false}
{"run_id":"29526913bab7446286864a321c124486","channel":"market","event_type":"price_change","market":"0x8032d8355d335c6ccbfc2508d99fbc87eb13f437bd275c93ee56fd1558e517ff","asset_id":null,"source":"market_ws:sub:active:1","t_event_ms":1770839724947,"t_recv_wall_ms":1770839724871,"t_recv_wall_iso":"2026-02-11T19:55:24.871Z","t_recv_mono_ns":618590211960416,"raw":{"market":"0x8032d8355d335c6ccbfc2508d99fbc87eb13f437bd275c93ee56fd1558e517ff","price_changes":[{"asset_id":"20773614133833886322101538939702011175545796528197617633926164254913649353392","price":"0.02","size":"8963.23","side":"BUY","hash":"eada770c89fef1edbfb0b2544885929f4844dadf","best_bid":"0.02","best_ask":"0.03"},{"asset_id":"40652734036737240317526188612064032143639112324786051284480877037991580442979","price":"0.98","size":"8963.23","side":"SELL","hash":"dda709f9eca44e434c0d7e2fc5ba856ca78436c3","best_bid":"0.97","best_ask":"0.98"}],"timestamp":"1770839724947","event_type":"price_change","_sub_state":"active","_subscription_id":1,"_active_subscription_id":1},"parse_warnings":[],"out_of_order":false}
{"run_id":"29526913bab7446286864a321c124486","channel":"market","event_type":"book","market":"0x8032d8355d335c6ccbfc2508d99fbc87eb13f437bd275c93ee56fd1558e517ff","asset_id":"20773614133833886322101538939702011175545796528197617633926164254913649353392","source":"market_ws:sub:active:1","t_event_ms":1770839724947,"t_recv_wall_ms":1770839724871,"t_recv_wall_iso":"2026-02-11T19:55:24.871Z","t_recv_mono_ns":618590212215875,"raw":{"market":"0x8032d8355d335c6ccbfc2508d99fbc87eb13f437bd275c93ee56fd1558e517ff","asset_id":"20773614133833886322101538939702011175545796528197617633926164254913649353392","bids":[{"price":"0.01","size":"30809.91"},{"price":"0.02","size":"8963.23"}],"asks":[{"price":"0.99","size":"30822.26"},{"price":"0.98","size":"12559.04"},{"price":"0.97","size":"7433.03"},{"price":"0.96","size":"5453.8"},{"price":"0.95","size":"6815.8"},{"price":"0.94","size":"5105"},{"price":"0.93","size":"5421.38"},{"price":"0.92","size":"5139.4"},{"price":"0.91","size":"5225.8"},{"price":"0.9","size":"5102.8"},{"price":"0.89","size":"120.6"},{"price":"0.88","size":"63.6"},{"price":"0.87","size":"63"},{"price":"0.86","size":"61.6"},{"price":"0.85","size":"107.39"},{"price":"0.84","size":"69.39"},{"price":"0.83","size":"58.39"},{"price":"0.82","size":"66.71"},{"price":"0.81","size":"56.8"},{"price":"0.8","size":"92.14"},{"price":"0.79","size":"60.8"},{"price":"0.78","size":"55.2"},{"price":"0.77","size":"64.48"},{"price":"0.76","size":"54.2"},{"price":"0.75","size":"375.8"},{"price":"0.74","size":"68.6"},{"price":"0.73","size":"53.2"},{"price":"0.72","size":"63.26"},{"price":"0.71","size":"52.6"},{"price":"0.7","size":"402.4"},{"price":"0.69","size":"72.2"},{"price":"0.68","size":"87.88"},{"price":"0.67","size":"188.46"},{"price":"0.66","size":"123.6"},{"price":"0.65","size":"317.03"},{"price":"0.64","size":"582.36"},{"price":"0.63","size":"559.2"},{"price":"0.62","size":"559"},{"price":"0.61","size":"594"},{"price":"0.6","size":"2915.41"},{"price":"0.59","size":"576.8"},{"price":"0.58","size":"575.5"},{"price":"0.57","size":"558.6"},{"price":"0.56","size":"572.68"},{"price":"0.55","size":"566.4"},{"price":"0.54","size":"561.94"},{"price":"0.53","size":"631.57"},{"price":"0.52","size":"611.4"},{"price":"0.51","size":"705.2"},{"price":"0.5","size":"1011.55"},{"price":"0.49","size":"692.4"},{"price":"0.48","size":"628.4"},{"price":"0.47","size":"633.4"},{"price":"0.46","size":"711.65"},{"price":"0.45","size":"866.59"},{"price":"0.44","size":"905.69"},{"price":"0.43","size":"641.6"},{"price":"0.42","size":"645.58"},{"price":"0.41","size":"564"},{"price":"0.4","size":"20642.9"},{"price":"0.39","size":"650.23"},{"price":"0.38","size":"593"},{"price":"0.37","size":"755.73"},{"price":"0.36","size":"558"},{"price":"0.35","size":"1144.32"},{"price":"0.34","size":"649.59"},{"price":"0.33","size":"624.8"},{"price":"0.32","size":"574"},{"price":"0.31","size":"594.2"},{"price":"0.3","size":"735.66"},{"price":"0.29","size":"624.6"},{"price":"0.28","size":"356.8"},{"price":"0.27","size":"869.2"},{"price":"0.26","size":"967.6"},{"price":"0.25","size":"1673.8"},{"price":"0.24","size":"869.2"},{"price":"0.23","size":"864.6"},{"price":"0.22","size":"870.2"},{"price":"0.21","size":"891.6"},{"price":"0.2","size":"987.2"},{"price":"0.19","size":"876.8"},{"price":"0.18","size":"1096.55"},{"price":"0.17","size":"958.39"},{"price":"0.16","size":"1119.39"},{"price":"0.15","size":"1149.13"},{"price":"0.14","size":"962.6"},{"price":"0.13","size":"1041.8"},{"price":"0.12","size":"1060.55"},{"price":"0.11","size":"1124.49"},{"price":"0.1","size":"1306.79"},{"price":"0.09","size":"759.6"},{"price":"0.08","size":"3379.35"},{"price":"0.07","size":"3360.43"},{"price":"0.06","size":"3140.34"},{"price":"0.05","size":"3314.45"},{"price":"0.04","size":"3678.17"},{"price":"0.03","size":"641.4"}],"hash":"eada770c89fef1edbfb0b2544885929f4844dadf","timestamp":"1770839724947","event_type":"book","_sub_state":"active","_subscription_id":1,"_active_subscription_id":1},"parse_warnings":[],"out_of_order":false}
{"run_id":"29526913bab7446286864a321c124486","channel":"market","event_type":"book","market":"0x8032d8355d335c6ccbfc2508d99fbc87eb13f437bd275c93ee56fd1558e517ff","asset_id":"40652734036737240317526188612064032143639112324786051284480877037991580442979","source":"market_ws:sub:active:1","t_event_ms":1770839724947,"t_recv_wall_ms":1770839724872,"t_recv_wall_iso":"2026-02-11T19:55:24.872Z","t_recv_mono_ns":618590212774291,"raw":{"market":"0x8032d8355d335c6ccbfc2508d99fbc87eb13f437bd275c93ee56fd1558e517ff","asset_id":"40652734036737240317526188612064032143639112324786051284480877037991580442979","bids":[{"price":"0.01","size":"30822.26"},{"price":"0.02","size":"12559.04"},{"price":"0.03","size":"7433.03"},{"price":"0.04","size":"5453.8"},{"price":"0.05","size":"6815.8"},{"price":"0.06","size":"5105"},{"price":"0.07","size":"5421.38"},{"price":"0.08","size":"5139.4"},{"price":"0.09","size":"5225.8"},{"price":"0.1","size":"5102.8"},{"price":"0.11","size":"120.6"},{"price":"0.12","size":"63.6"},{"price":"0.13","size":"63"},{"price":"0.14","size":"61.6"},{"price":"0.15","size":"107.39"},{"price":"0.16","size":"69.39"},{"price":"0.17","size":"58.39"},{"price":"0.18","size":"66.71"},{"price":"0.19","size":"56.8"},{"price":"0.2","size":"92.14"},{"price":"0.21","size":"60.8"},{"price":"0.22","size":"55.2"},{"price":"0.23","size":"64.48"},{"price":"0.24","size":"54.2"},{"price":"0.25","size":"375.8"},{"price":"0.26","size":"68.6"},{"price":"0.27","size":"53.2"},{"price":"0.28","size":"63.26"},{"price":"0.29","size":"52.6"},{"price":"0.3","size":"402.4"},{"price":"0.31","size":"72.2"},{"price":"0.32","size":"87.88"},{"price":"0.33","size":"188.46"},{"price":"0.34","size":"123.6"},{"price":"0.35","size":"317.03"},{"price":"0.36","size":"582.36"},{"price":"0.37","size":"559.2"},{"price":"0.38","size":"559"},{"price":"0.39","size":"594"},{"price":"0.4","size":"2915.41"},{"price":"0.41","size":"576.8"},{"price":"0.42","size":"575.5"},{"price":"0.43","size":"558.6"},{"price":"0.44","size":"572.68"},{"price":"0.45","size":"566.4"},{"price":"0.46","size":"561.94"},{"price":"0.47","size":"631.57"},{"price":"0.48","size":"611.4"},{"price":"0.49","size":"705.2"},{"price":"0.5","size":"1011.55"},{"price":"0.51","size":"692.4"},{"price":"0.52","size":"628.4"},{"price":"0.53","size":"633.4"},{"price":"0.54","size":"711.65"},{"price":"0.55","size":"866.59"},{"price":"0.56","size":"905.69"},{"price":"0.57","size":"641.6"},{"price":"0.58","size":"645.58"},{"price":"0.59","size":"564"},{"price":"0.6","size":"20642.9"},{"price":"0.61","size":"650.23"},{"price":"0.62","size":"593"},{"price":"0.63","size":"755.73"},{"price":"0.64","size":"558"},{"price":"0.65","size":"1144.32"},{"price":"0.66","size":"649.59"},{"price":"0.67","size":"624.8"},{"price":"0.68","size":"574"},{"price":"0.69","size":"594.2"},{"price":"0.7","size":"735.66"},{"price":"0.71","size":"624.6"},{"price":"0.72","size":"356.8"},{"price":"0.73","size":"869.2"},{"price":"0.74","size":"967.6"},{"price":"0.75","size":"1673.8"},{"price":"0.76","size":"869.2"},{"price":"0.77","size":"864.6"},{"price":"0.78","size":"870.2"},{"price":"0.79","size":"891.6"},{"price":"0.8","size":"987.2"},{"price":"0.81","size":"876.8"},{"price":"0.82","size":"1096.55"},{"price":"0.83","size":"958.39"},{"price":"0.84","size":"1119.39"},{"price":"0.85","size":"1149.13"},{"price":"0.86","size":"962.6"},{"price":"0.87","size":"1041.8"},{"price":"0.88","size":"1060.55"},{"price":"0.89","size":"1124.49"},{"price":"0.9","size":"1306.79"},{"price":"0.91","size":"759.6"},{"price":"0.92","size":"3379.35"},{"price":"0.93","size":"3360.43"},{"price":"0.94","size":"3140.34"},{"price":"0.95","size":"3314.45"},{"price":"0.96","size":"3678.17"},{"price":"0.97","size":"641.4"}],"asks":[{"price":"0.99","size":"30809.91"},{"price":"0.98","size":"8963.23"}],"hash":"dda709f9eca44e434c0d7e2fc5ba856ca78436c3","timestamp":"1770839724947","event_type":"book","_sub_state":"active","_subscription_id":1,"_active_subscription_id":1},"parse_warnings":[],"out_of_order":false}
{"run_id":"29526913bab7446286864a321c124486","channel":"market","event_type":"price_change","market":"0x8032d8355d335c6ccbfc2508d99fbc87eb13f437bd275c93ee56fd1558e517ff","asset_id":null,"source":"market_ws:sub:active:1","t_event_ms":1770839724951,"t_recv_wall_ms":1770839724872,"t_recv_wall_iso":"2026-02-11T19:55:24.872Z","t_recv_mono_ns":618590213415416,"raw":{"market":"0x8032d8355d335c6ccbfc2508d99fbc87eb13f437bd275c93ee56fd1558e517ff","price_changes":[{"asset_id":"40652734036737240317526188612064032143639112324786051284480877037991580442979","price":"0.92","size":"3389.35","side":"BUY","hash":"55e175da9624694d5a47495e57a43d6fc303a9ad","best_bid":"0.97","best_ask":"0.98"},{"asset_id":"20773614133833886322101538939702011175545796528197617633926164254913649353392","price":"0.08","size":"3389.35","side":"SELL","hash":"1db30313eadc90a746c51ede556d1692d48bd693","best_bid":"0.02","best_ask":"0.03"}],"timestamp":"1770839724951","event_type":"price_change","_sub_state":"active","_subscription_id":1,"_active_subscription_id":1},"parse_warnings":[],"out_of_order":false}
{"run_id":"29526913bab7446286864a321c124486","channel":"market","event_type":"last_trade_price","market":"0x8032d8355d335c6ccbfc2508d99fbc87eb13f437bd275c93ee56fd1558e517ff","asset_id":"40652734036737240317526188612064032143639112324786051284480877037991580442979","source":"market_ws:sub:unknown","t_event_ms":1770839724958,"t_recv_wall_ms":1770839724872,"t_recv_wall_iso":"2026-02-11T19:55:24.872Z","t_recv_mono_ns":618590213650208,"raw":{"market":"0x8032d8355d335c6ccbfc2508d99fbc87eb13f437bd275c93ee56fd1558e517ff","asset_id":"40652734036737240317526188612064032143639112324786051284480877037991580442979","price":"0.98","size":"9.19","fee_rate_bps":"1000","side":"BUY","timestamp":"1770839724958","event_type":"last_trade_price","transaction_hash":"0xd9f5524ce37fc930d7afb56be4afc62fe8f8305a05f7c0760d4b1c38df45e237","_sub_state":"unknown","_subscription_id":null,"_active_subscription_id":1},"parse_warnings":["unknown_message_schema"],"out_of_order":false}
{"run_id":"29526913bab7446286864a321c124486","channel":"market","event_type":"price_change","market":"0x8032d8355d335c6ccbfc2508d99fbc87eb13f437bd275c93ee56fd1558e517ff","asset_id":null,"source":"market_ws:sub:active:1","t_event_ms":1770839724967,"t_recv_wall_ms":1770839724886,"t_recv_wall_iso":"2026-02-11T19:55:24.886Z","t_recv_mono_ns":618590227165291,"raw":{"market":"0x8032d8355d335c6ccbfc2508d99fbc87eb13f437bd275c93ee56fd1558e517ff","price_changes":[{"asset_id":"20773614133833886322101538939702011175545796528197617633926164254913649353392","price":"0.02","size":"8959.14","side":"BUY","hash":"666b1ec17a44caf9944a3d692e6f8a17364e7719","best_bid":"0.02","best_ask":"0.03"},{"asset_id":"40652734036737240317526188612064032143639112324786051284480877037991580442979","price":"0.98","size":"8959.14","side":"SELL","hash":"f6afecf2636154931621be1705d63b57407867ed","best_bid":"0.97","best_ask":"0.98"}],"timestamp":"1770839724967","event_type":"price_change","_sub_state":"active","_subscription_id":1,"_active_subscription_id":1},"parse_warnings":[],"out_of_order":false}
{"run_id":"29526913bab7446286864a321c124486","channel":"market","event_type":"book","market":"0x8032d8355d335c6ccbfc2508d99fbc87eb13f437bd275c93ee56fd1558e517ff","asset_id":"20773614133833886322101538939702011175545796528197617633926164254913649353392","source":"market_ws:sub:active:1","t_event_ms":1770839724967,"t_recv_wall_ms":1770839724886,"t_recv_wall_iso":"2026-02-11T19:55:24.886Z","t_recv_mono_ns":618590227559750,"raw":{"market":"0x8032d8355d335c6ccbfc2508d99fbc87eb13f437bd275c93ee56fd1558e517ff","asset_id":"20773614133833886322101538939702011175545796528197617633926164254913649353392","bids":[{"price":"0.01","size":"30809.91"},{"price":"0.02","size":"8959.14"}],"asks":[{"price":"0.99","size":"30822.26"},{"price":"0.98","size":"12559.04"},{"price":"0.97","size":"7433.03"},{"price":"0.96","size":"5453.8"},{"price":"0.95","size":"6815.8"},{"price":"0.94","size":"5105"},{"price":"0.93","size":"5421.38"},{"price":"0.92","size":"5139.4"},{"price":"0.91","size":"5225.8"},{"price":"0.9","size":"5102.8"},{"price":"0.89","size":"120.6"},{"price":"0.88","size":"63.6"},{"price":"0.87","size":"63"},{"price":"0.86","size":"61.6"},{"price":"0.85","size":"107.39"},{"price":"0.84","size":"69.39"},{"price":"0.83","size":"58.39"},{"price":"0.82","size":"66.71"},{"price":"0.81","size":"56.8"},{"price":"0.8","size":"92.14"},{"price":"0.79","size":"60.8"},{"price":"0.78","size":"55.2"},{"price":"0.77","size":"64.48"},{"price":"0.76","size":"54.2"},{"price":"0.75","size":"375.8"},{"price":"0.74","size":"68.6"},{"price":"0.73","size":"53.2"},{"price":"0.72","size":"63.26"},{"price":"0.71","size":"52.6"},{"price":"0.7","size":"402.4"},{"price":"0.69","size":"72.2"},{"price":"0.68","size":"87.88"},{"price":"0.67","size":"188.46"},{"price":"0.66","size":"123.6"},{"price":"0.65","size":"317.03"},{"price":"0.64","size":"582.36"},{"price":"0.63","size":"559.2"},{"price":"0.62","size":"559"},{"price":"0.61","size":"594"},{"price":"0.6","size":"2915.41"},{"price":"0.59","size":"576.8"},{"price":"0.58","size":"575.5"},{"price":"0.57","size":"558.6"},{"price":"0.56","size":"572.68"},{"price":"0.55","size":"566.4"},{"price":"0.54","size":"561.94"},{"price":"0.53","size":"631.57"},{"price":"0.52","size":"611.4"},{"price":"0.51","size":"705.2"},{"price":"0.5","size":"1011.55"},{"price":"0.49","size":"692.4"},{"price":"0.48","size":"628.4"},{"price":"0.47","size":"633.4"},{"price":"0.46","size":"711.65"},{"price":"0.45","size":"866.59"},{"price":"0.44","size":"905.69"},{"price":"0.43","size":"641.6"},{"price":"0.42","size":"645.58"},{"price":"0.41","size":"564"},{"price":"0.4","size":"20642.9"},{"price":"0.39","size":"650.23"},{"price":"0.38","size":"593"},{"price":"0.37","size":"755.73"},{"price":"0.36","size":"558"},{"price":"0.35","size":"1144.32"},{"price":"0.34","size":"649.59"},{"price":"0.33","size":"624.8"},{"price":"0.32","size":"574"},{"price":"0.31","size":"594.2"},{"price":"0.3","size":"735.66"},{"price":"0.29","size":"624.6"},{"price":"0.28","size":"356.8"},{"price":"0.27","size":"869.2"},{"price":"0.26","size":"967.6"},{"price":"0.25","size":"1673.8"},{"price":"0.24","size":"869.2"},{"price":"0.23","size":"864.6"},{"price":"0.22","size":"870.2"},{"price":"0.21","size":"891.6"},{"price":"0.2","size":"987.2"},{"price":"0.19","size":"876.8"},{"price":"0.18","size":"1096.55"},{"price":"0.17","size":"958.39"},{"price":"0.16","size":"1119.39"},{"price":"0.15","size":"1149.13"},{"price":"0.14","size":"962.6"},{"price":"0.13","size":"1041.8"},{"price":"0.12","size":"1060.55"},{"price":"0.11","size":"1124.49"},{"price":"0.1","size":"1306.79"},{"price":"0.09","size":"759.6"},{"price":"0.08","size":"3389.35"},{"price":"0.07","size":"3360.43"},{"price":"0.06","size":"3140.34"},{"price":"0.05","size":"3314.45"},{"price":"0.04","size":"3678.17"},{"price":"0.03","size":"641.4"}],"hash":"666b1ec17a44caf9944a3d692e6f8a17364e7719","timestamp":"1770839724967","event_type":"book","_sub_state":"active","_subscription_id":1,"_active_subscription_id":1},"parse_warnings":[],"out_of_order":false}
{"run_id":"29526913bab7446286864a321c124486","channel":"market","event_type":"book","market":"0x8032d8355d335c6ccbfc2508d99fbc87eb13f437bd275c93ee56fd1558e517ff","asset_id":"40652734036737240317526188612064032143639112324786051284480877037991580442979","source":"market_ws:sub:active:1","t_event_ms":1770839724967,"t_recv_wall_ms":1770839724887,"t_recv_wall_iso":"2026-02-11T19:55:24.887Z","t_recv_mono_ns":618590228440583,"raw":{"market":"0x8032d8355d335c6ccbfc2508d99fbc87eb13f437bd275c93ee56fd1558e517ff","asset_id":"40652734036737240317526188612064032143639112324786051284480877037991580442979","bids":[{"price":"0.01","size":"30822.26"},{"price":"0.02","size":"12559.04"},{"price":"0.03","size":"7433.03"},{"price":"0.04","size":"5453.8"},{"price":"0.05","size":"6815.8"},{"price":"0.06","size":"5105"},{"price":"0.07","size":"5421.38"},{"price":"0.08","size":"5139.4"},{"price":"0.09","size":"5225.8"},{"price":"0.1","size":"5102.8"},{"price":"0.11","size":"120.6"},{"price":"0.12","size":"63.6"},{"price":"0.13","size":"63"},{"price":"0.14","size":"61.6"},{"price":"0.15","size":"107.39"},{"price":"0.16","size":"69.39"},{"price":"0.17","size":"58.39"},{"price":"0.18","size":"66.71"},{"price":"0.19","size":"56.8"},{"price":"0.2","size":"92.14"},{"price":"0.21","size":"60.8"},{"price":"0.22","size":"55.2"},{"price":"0.23","size":"64.48"},{"price":"0.24","size":"54.2"},{"price":"0.25","size":"375.8"},{"price":"0.26","size":"68.6"},{"price":"0.27","size":"53.2"},{"price":"0.28","size":"63.26"},{"price":"0.29","size":"52.6"},{"price":"0.3","size":"402.4"},{"price":"0.31","size":"72.2"},{"price":"0.32","size":"87.88"},{"price":"0.33","size":"188.46"},{"price":"0.34","size":"123.6"},{"price":"0.35","size":"317.03"},{"price":"0.36","size":"582.36"},{"price":"0.37","size":"559.2"},{"price":"0.38","size":"559"},{"price":"0.39","size":"594"},{"price":"0.4","size":"2915.41"},{"price":"0.41","size":"576.8"},{"price":"0.42","size":"575.5"},{"price":"0.43","size":"558.6"},{"price":"0.44","size":"572.68"},{"price":"0.45","size":"566.4"},{"price":"0.46","size":"561.94"},{"price":"0.47","size":"631.57"},{"price":"0.48","size":"611.4"},{"price":"0.49","size":"705.2"},{"price":"0.5","size":"1011.55"},{"price":"0.51","size":"692.4"},{"price":"0.52","size":"628.4"},{"price":"0.53","size":"633.4"},{"price":"0.54","size":"711.65"},{"price":"0.55","size":"866.59"},{"price":"0.56","size":"905.69"},{"price":"0.57","size":"641.6"},{"price":"0.58","size":"645.58"},{"price":"0.59","size":"564"},{"price":"0.6","size":"20642.9"},{"price":"0.61","size":"650.23"},{"price":"0.62","size":"593"},{"price":"0.63","size":"755.73"},{"price":"0.64","size":"558"},{"price":"0.65","size":"1144.32"},{"price":"0.66","size":"649.59"},{"price":"0.67","size":"624.8"},{"price":"0.68","size":"574"},{"price":"0.69","size":"594.2"},{"price":"0.7","size":"735.66"},{"price":"0.71","size":"624.6"},{"price":"0.72","size":"356.8"},{"price":"0.73","size":"869.2"},{"price":"0.74","size":"967.6"},{"price":"0.75","size":"1673.8"},{"price":"0.76","size":"869.2"},{"price":"0.77","size":"864.6"},{"price":"0.78","size":"870.2"},{"price":"0.79","size":"891.6"},{"price":"0.8","size":"987.2"},{"price":"0.81","size":"876.8"},{"price":"0.82","size":"1096.55"},{"price":"0.83","size":"958.39"},{"price":"0.84","size":"1119.39"},{"price":"0.85","size":"1149.13"},{"price":"0.86","size":"962.6"},{"price":"0.87","size":"1041.8"},{"price":"0.88","size":"1060.55"},{"price":"0.89","size":"1124.49"},{"price":"0.9","size":"1306.79"},{"price":"0.91","size":"759.6"},{"price":"0.92","size":"3389.35"},{"price":"0.93","size":"3360.43"},{"price":"0.94","size":"3140.34"},{"price":"0.95","size":"3314.45"},{"price":"0.96","size":"3678.17"},{"price":"0.97","size":"641.4"}],"asks":[{"price":"0.99","size":"30809.91"},{"price":"0.98","size":"8959.14"}],"hash":"f6afecf2636154931621be1705d63b57407867ed","timestamp":"1770839724967","event_type":"book","_sub_state":"active","_subscription_id":1,"_active_subscription_id":1},"parse_warnings":[],"out_of_order":false}
{"run_id":"29526913bab7446286864a321c124486","channel":"market","event_type":"last_trade_price","market":"0x8032d8355d335c6ccbfc2508d99fbc87eb13f437bd275c93ee56fd1558e517ff","asset_id":"40652734036737240317526188612064032143639112324786051284480877037991580442979","source":"market_ws:sub:unknown","t_event_ms":1770839724978,"t_recv_wall_ms":1770839724888,"t_recv_wall_iso":"2026-02-11T19:55:24.888Z","t_recv_mono_ns":618590229084708,"raw":{"market":"0x8032d8355d335c6ccbfc2508d99fbc87eb13f437bd275c93ee56fd1558e517ff","asset_id":"40652734036737240317526188612064032143639112324786051284480877037991580442979","price":"0.98","size":"7.15","fee_rate_bps":"1000","side":"BUY","timestamp":"1770839724978","event_type":"last_trade_price","transaction_hash":"0xd2b969d3d25280227df71ac1963ecbefeae6d792e7b08d4a1090323d96c15de8","_sub_state":"unknown","_subscription_id":null,"_active_subscription_id":1},"parse_warnings":["unknown_message_schema"],"out_of_order":false}
{"run_id":"29526913bab7446286864a321c124486","channel":"market","event_type":"price_change","market":"0x8032d8355d335c6ccbfc2508d99fbc87eb13f437bd275c93ee56fd1558e517ff","asset_id":null,"source":"market_ws:sub:active:1","t_event_ms":1770839724991,"t_recv_wall_ms":1770839724910,"t_recv_wall_iso":"2026-02-11T19:55:24.910Z","t_recv_mono_ns":618590250962333,"raw":{"market":"0x8032d8355d335c6ccbfc2508d99fbc87eb13f437bd275c93ee56fd1558e517ff","price_changes":[{"asset_id":"20773614133833886322101538939702011175545796528197617633926164254913649353392","price":"0.02","size":"8954.03","side":"BUY","hash":"98851381fa59e51e2f1881091ce64f68f5e4c53a","best_bid":"0.02","best_ask":"0.03"},{"asset_id":"40652734036737240317526188612064032143639112324786051284480877037991580442979","price":"0.98","size":"8954.03","side":"SELL","hash":"b04cacc2b0228d78d6d11a0dfcf77f826e4463d5","best_bid":"0.97","best_ask":"0.98"}],"timestamp":"1770839724991","event_type":"price_change","_sub_state":"active","_subscription_id":1,"_active_subscription_id":1},"parse_warnings":[],"out_of_order":false}
